{
  "version": 8,
  "blockIdVersion": 11,
  "anchorX": 0,
  "anchorY": 0,
  "anchorZ": 0,
  "blocks": [
    {
      "x": -3,
      "y": 3,
      "z": -3,
      "name": "Wood_Giantwood_Trunk_Full",
      "support": 15,
      "rotation": 4
    },
    {
      "x": -3,
      "y": 3,
      "z": -2,
      "name": "Wood_Giantwood_Trunk_Full",
      "support": 15,
      "rotation": 4
    },
    {
      "x": -3,
      "y": 3,
      "z": -1,
      "name": "Wood_Giantwood_Trunk_Full",
      "support": 15,
      "rotation": 4
    },
    {
      "x": -3,
      "y": 3,
      "z": 0,
      "name": "Wood_Giantwood_Trunk_Full",
      "support": 15,
      "rotation": 4
    },
    {
      "x": -3,
      "y": 3,
      "z": 1,
      "name": "Wood_Giantwood_Trunk_Full",
      "support": 15,
      "rotation": 4
    },
    {
      "x": -3,
      "y": 2,
      "z": 2,
      "name": "Wood_Giantwood_Trunk_Full",
      "support": 15,
      "rotation": 5
    },
    {
      "x": -3,
      "y": 3,
      "z": 2,
      "name": "Wood_Giantwood_Trunk_Full",
      "support": 15,
      "rotation": 4
    },
    {
      "x": -2,
      "y": 2,
      "z": -5,
      "name": "Wood_Giantwood_Trunk_Full",
      "support": 15,
      "rotation": 5
    },
    {
      "x": -2,
      "y": 3,
      "z": -5,
      "name": "Plant_Crop_Mushroom_Glowing_Orange"
    },
    {
      "x": -2,
      "y": 2,
      "z": -4,
      "name": "Wood_Giantwood_Trunk_Full",
      "support": 15,
      "rotation": 4
    },
    {
      "x": -2,
      "y": 3,
      "z": -4,
      "name": "Wood_Giantwood_Trunk_Full",
      "support": 15,
      "rotation": 4
    },
    {
      "x": -2,
      "y": 2,
      "z": -3,
      "name": "Wood_Giantwood_Roots"
    },
    {
      "x": -2,
      "y": 3,
      "z": -3,
      "name": "Wood_Giantwood_Trunk_Full",
      "support": 15,
      "rotation": 4
    },
    {
      "x": -2,
      "y": 2,
      "z": 2,
      "name": "Wood_Giantwood_Trunk_Full",
      "support": 15,
      "rotation": 5
    },
    {
      "x": -2,
      "y": 3,
      "z": 2,
      "name": "Plant_Crop_Mushroom_Glowing_Orange"
    },
    {
      "x": -2,
      "y": 2,
      "z": 3,
      "name": "Wood_Giantwood_Trunk_Full",
      "support": 15,
      "rotation": 4
    },
    {
      "x": -2,
      "y": 2,
      "z": 4,
      "name": "Wood_Giantwood_Trunk_Full",
      "support": 15,
      "rotation": 5
    },
    {
      "x": -1,
      "y": 2,
      "z": -5,
      "name": "Wood_Giantwood_Trunk_Full",
      "support": 15,
      "rotation": 5
    },
    {
      "x": -1,
      "y": 1,
      "z": 4,
      "name": "Wood_Giantwood_Trunk_Full",
      "support": 15
    },
    {
      "x": -1,
      "y": 2,
      "z": 4,
      "name": "Wood_Giantwood_Trunk_Full",
      "support": 15
    },
    {
      "x": 0,
      "y": 1,
      "z": -6,
      "name": "Wood_Giantwood_Roots"
    },
    {
      "x": 0,
      "y": 2,
      "z": -6,
      "name": "Wood_Giantwood_Trunk_Full",
      "support": 15,
      "rotation": 5
    },
    {
      "x": 0,
      "y": 2,
      "z": -5,
      "name": "Wood_Giantwood_Trunk_Full",
      "support": 15,
      "rotation": 5
    },
    {
      "x": 0,
      "y": 0,
      "z": 5,
      "name": "Wood_Giantwood_Trunk_Full",
      "support": 15
    },
    {
      "x": 0,
      "y": 1,
      "z": 5,
      "name": "Wood_Giantwood_Trunk_Full",
      "support": 15
    },
    {
      "x": 0,
      "y": 0,
      "z": 6,
      "name": "Wood_Giantwood_Trunk_Full",
      "support": 15,
      "rotation": 4
    },
    {
      "x": 1,
      "y": 1,
      "z": -6,
      "name": "Wood_Giantwood_Trunk_Full",
      "support": 15
    },
    {
      "x": 1,
      "y": 2,
      "z": -6,
      "name": "Wood_Giantwood_Trunk_Full",
      "support": 15,
      "rotation": 5
    },
    {
      "x": 2,
      "y": 0,
      "z": -6,
      "name": "Wood_Giantwood_Trunk_Full",
      "support": 15
    },
    {
      "x": 2,
      "y": 1,
      "z": -6,
      "name": "Wood_Giantwood_Trunk_Full",
      "support": 15
    },
    {
      "x": 3,
      "y": 0,
      "z": -6,
      "name": "Wood_Giantwood_Trunk_Full",
      "support": 15,
      "rotation": 5
    },
    {
      "x": 4,
      "y": 0,
      "z": -6,
      "name": "Wood_Giantwood_Trunk_Full",
      "support": 15,
      "rotation": 5
    }
  ],
  "fluids": [
    {
      "x": -3,
      "y": 3,
      "z": -3,
      "name": "Empty",
      "level": 0
    },
    {
      "x": -3,
      "y": 3,
      "z": -2,
      "name": "Empty",
      "level": 0
    },
    {
      "x": -3,
      "y": 3,
      "z": -1,
      "name": "Empty",
      "level": 0
    },
    {
      "x": -3,
      "y": 3,
      "z": 0,
      "name": "Empty",
      "level": 0
    },
    {
      "x": -3,
      "y": 3,
      "z": 1,
      "name": "Empty",
      "level": 0
    },
    {
      "x": -3,
      "y": 2,
      "z": 2,
      "name": "Empty",
      "level": 0
    },
    {
      "x": -3,
      "y": 3,
      "z": 2,
      "name": "Empty",
      "level": 0
    },
    {
      "x": -2,
      "y": 2,
      "z": -5,
      "name": "Empty",
      "level": 0
    },
    {
      "x": -2,
      "y": 3,
      "z": -5,
      "name": "Empty",
      "level": 0
    },
    {
      "x": -2,
      "y": 2,
      "z": -4,
      "name": "Empty",
      "level": 0
    },
    {
      "x": -2,
      "y": 3,
      "z": -4,
      "name": "Empty",
      "level": 0
    },
    {
      "x": -2,
      "y": 2,
      "z": -3,
      "name": "Empty",
      "level": 0
    },
    {
      "x": -2,
      "y": 3,
      "z": -3,
      "name": "Empty",
      "level": 0
    },
    {
      "x": -2,
      "y": 2,
      "z": 2,
      "name": "Empty",
      "level": 0
    },
    {
      "x": -2,
      "y": 3,
      "z": 2,
      "name": "Empty",
      "level": 0
    },
    {
      "x": -2,
      "y": 2,
      "z": 3,
      "name": "Empty",
      "level": 0
    },
    {
      "x": -2,
      "y": 2,
      "z": 4,
      "name": "Empty",
      "level": 0
    },
    {
      "x": -1,
      "y": 2,
      "z": -5,
      "name": "Empty",
      "level": 0
    },
    {
      "x": -1,
      "y": 1,
      "z": 4,
      "name": "Empty",
      "level": 0
    },
    {
      "x": -1,
      "y": 2,
      "z": 4,
      "name": "Empty",
      "level": 0
    },
    {
      "x": 0,
      "y": 1,
      "z": -6,
      "name": "Empty",
      "level": 0
    },
    {
      "x": 0,
      "y": 2,
      "z": -6,
      "name": "Empty",
      "level": 0
    },
    {
      "x": 0,
      "y": 2,
      "z": -5,
      "name": "Empty",
      "level": 0
    },
    {
      "x": 0,
      "y": 0,
      "z": 5,
      "name": "Empty",
      "level": 0
    },
    {
      "x": 0,
      "y": 1,
      "z": 5,
      "name": "Empty",
      "level": 0
    },
    {
      "x": 0,
      "y": 0,
      "z": 6,
      "name": "Empty",
      "level": 0
    },
    {
      "x": 1,
      "y": 1,
      "z": -6,
      "name": "Empty",
      "level": 0
    },
    {
      "x": 1,
      "y": 2,
      "z": -6,
      "name": "Empty",
      "level": 0
    },
    {
      "x": 2,
      "y": 0,
      "z": -6,
      "name": "Empty",
      "level": 0
    },
    {
      "x": 2,
      "y": 1,
      "z": -6,
      "name": "Empty",
      "level": 0
    },
    {
      "x": 3,
      "y": 0,
      "z": -6,
      "name": "Empty",
      "level": 0
    },
    {
      "x": 4,
      "y": 0,
      "z": -6,
      "name": "Empty",
      "level": 0
    }
  ]
}