{
  "version": 8,
  "blockIdVersion": 11,
  "anchorX": 0,
  "anchorY": 0,
  "anchorZ": 0,
  "blocks": [
    {
      "x": -61,
      "y": 202,
      "z": -5,
      "name": "Plant_Leaves_Giantwood"
    },
    {
      "x": -61,
      "y": 201,
      "z": -3,
      "name": "Plant_Leaves_Giantwood"
    },
    {
      "x": -61,
      "y": 202,
      "z": -2,
      "name": "Plant_Leaves_Giantwood"
    },
    {
      "x": -61,
      "y": 202,
      "z": 0,
      "name": "Plant_Leaves_Giantwood"
    },
    {
      "x": -61,
      "y": 201,
      "z": 1,
      "name": "Plant_Leaves_Giantwood"
    },
    {
      "x": -61,
      "y": 201,
      "z": 3,
      "name": "Plant_Leaves_Giantwood"
    },
    {
      "x": -61,
      "y": 201,
      "z": 4,
      "name": "Plant_Leaves_Giantwood"
    },
    {
      "x": -60,
      "y": 201,
      "z": -8,
      "name": "Plant_Leaves_Giantwood"
    },
    {
      "x": -60,
      "y": 202,
      "z": -8,
      "name": "Plant_Leaves_Giantwood"
    },
    {
      "x": -60,
      "y": 202,
      "z": -7,
      "name": "Plant_Leaves_Giantwood"
    },
    {
      "x": -60,
      "y": 200,
      "z": -5,
      "name": "Plant_Leaves_Giantwood"
    },
    {
      "x": -60,
      "y": 202,
      "z": -5,
      "name": "Plant_Leaves_Giantwood"
    },
    {
      "x": -60,
      "y": 203,
      "z": -4,
      "name": "Plant_Leaves_Giantwood"
    },
    {
      "x": -60,
      "y": 202,
      "z": -3,
      "name": "Plant_Leaves_Giantwood"
    },
    {
      "x": -60,
      "y": 203,
      "z": -3,
      "name": "Plant_Leaves_Giantwood"
    },
    {
      "x": -60,
      "y": 199,
      "z": -2,
      "name": "Plant_Leaves_Giantwood"
    },
    {
      "x": -60,
      "y": 201,
      "z": -2,
      "name": "Plant_Leaves_Giantwood"
    },
    {
      "x": -60,
      "y": 202,
      "z": -2,
      "name": "Plant_Leaves_Giantwood"
    },
    {
      "x": -60,
      "y": 203,
      "z": -2,
      "name": "Plant_Leaves_Giantwood"
    },
    {
      "x": -60,
      "y": 199,
      "z": -1,
      "name": "Plant_Leaves_Giantwood"
    },
    {
      "x": -60,
      "y": 201,
      "z": -1,
      "name": "Plant_Leaves_Giantwood"
    },
    {
      "x": -60,
      "y": 203,
      "z": -1,
      "name": "Plant_Leaves_Giantwood"
    },
    {
      "x": -60,
      "y": 203,
      "z": 0,
      "name": "Plant_Leaves_Giantwood"
    },
    {
      "x": -60,
      "y": 200,
      "z": 1,
      "name": "Plant_Leaves_Giantwood"
    },
    {
      "x": -60,
      "y": 200,
      "z": 2,
      "name": "Plant_Leaves_Giantwood"
    },
    {
      "x": -60,
      "y": 202,
      "z": 2,
      "name": "Plant_Leaves_Giantwood"
    },
    {
      "x": -60,
      "y": 201,
      "z": 4,
      "name": "Plant_Leaves_Giantwood"
    },
    {
      "x": -60,
      "y": 200,
      "z": 5,
      "name": "Plant_Leaves_Giantwood"
    },
    {
      "x": -60,
      "y": 202,
      "z": 5,
      "name": "Plant_Leaves_Giantwood"
    },
    {
      "x": -60,
      "y": 203,
      "z": 5,
      "name": "Plant_Leaves_Giantwood"
    },
    {
      "x": -60,
      "y": 200,
      "z": 6,
      "name": "Plant_Leaves_Giantwood"
    },
    {
      "x": -60,
      "y": 201,
      "z": 7,
      "name": "Plant_Leaves_Giantwood"
    },
    {
      "x": -60,
      "y": 202,
      "z": 7,
      "name": "Plant_Leaves_Giantwood"
    },
    {
      "x": -59,
      "y": 201,
      "z": -11,
      "name": "Plant_Leaves_Giantwood"
    },
    {
      "x": -59,
      "y": 203,
      "z": -10,
      "name": "Plant_Leaves_Giantwood"
    },
    {
      "x": -59,
      "y": 203,
      "z": -8,
      "name": "Plant_Leaves_Giantwood"
    },
    {
      "x": -59,
      "y": 200,
      "z": -7,
      "name": "Plant_Leaves_Giantwood"
    },
    {
      "x": -59,
      "y": 201,
      "z": -7,
      "name": "Plant_Leaves_Giantwood"
    },
    {
      "x": -59,
      "y": 203,
      "z": -7,
      "name": "Plant_Leaves_Giantwood"
    },
    {
      "x": -59,
      "y": 200,
      "z": -6,
      "name": "Plant_Leaves_Giantwood"
    },
    {
      "x": -59,
      "y": 202,
      "z": -6,
      "name": "Plant_Leaves_Giantwood"
    },
    {
      "x": -59,
      "y": 199,
      "z": -5,
      "name": "Plant_Leaves_Giantwood"
    },
    {
      "x": -59,
      "y": 201,
      "z": -5,
      "name": "Plant_Leaves_Giantwood"
    },
    {
      "x": -59,
      "y": 202,
      "z": -3,
      "name": "Plant_Leaves_Giantwood"
    },
    {
      "x": -59,
      "y": 199,
      "z": -2,
      "name": "Plant_Leaves_Giantwood"
    },
    {
      "x": -59,
      "y": 202,
      "z": -2,
      "name": "Plant_Leaves_Giantwood"
    },
    {
      "x": -59,
      "y": 201,
      "z": 1,
      "name": "Plant_Leaves_Giantwood"
    },
    {
      "x": -59,
      "y": 199,
      "z": 2,
      "name": "Plant_Leaves_Giantwood"
    },
    {
      "x": -59,
      "y": 201,
      "z": 2,
      "name": "Plant_Leaves_Giantwood"
    },
    {
      "x": -59,
      "y": 204,
      "z": 2,
      "name": "Plant_Leaves_Giantwood"
    },
    {
      "x": -59,
      "y": 199,
      "z": 3,
      "name": "Plant_Leaves_Giantwood"
    },
    {
      "x": -59,
      "y": 201,
      "z": 3,
      "name": "Plant_Leaves_Giantwood"
    },
    {
      "x": -59,
      "y": 203,
      "z": 3,
      "name": "Plant_Leaves_Giantwood"
    },
    {
      "x": -59,
      "y": 201,
      "z": 5,
      "name": "Plant_Leaves_Giantwood"
    },
    {
      "x": -59,
      "y": 203,
      "z": 5,
      "name": "Plant_Leaves_Giantwood"
    },
    {
      "x": -59,
      "y": 199,
      "z": 6,
      "name": "Plant_Leaves_Giantwood"
    },
    {
      "x": -59,
      "y": 203,
      "z": 8,
      "name": "Plant_Leaves_Giantwood"
    },
    {
      "x": -59,
      "y": 202,
      "z": 9,
      "name": "Plant_Leaves_Giantwood"
    },
    {
      "x": -58,
      "y": 200,
      "z": -12,
      "name": "Plant_Leaves_Giantwood"
    },
    {
      "x": -58,
      "y": 200,
      "z": -11,
      "name": "Plant_Leaves_Giantwood"
    },
    {
      "x": -58,
      "y": 202,
      "z": -11,
      "name": "Plant_Leaves_Giantwood"
    },
    {
      "x": -58,
      "y": 201,
      "z": -10,
      "name": "Plant_Leaves_Giantwood"
    },
    {
      "x": -58,
      "y": 199,
      "z": -8,
      "name": "Plant_Leaves_Giantwood"
    },
    {
      "x": -58,
      "y": 201,
      "z": -7,
      "name": "Plant_Leaves_Giantwood"
    },
    {
      "x": -58,
      "y": 202,
      "z": -7,
      "name": "Plant_Leaves_Giantwood"
    },
    {
      "x": -58,
      "y": 203,
      "z": -7,
      "name": "Plant_Leaves_Giantwood"
    },
    {
      "x": -58,
      "y": 198,
      "z": -6,
      "name": "Plant_Leaves_Giantwood"
    },
    {
      "x": -58,
      "y": 200,
      "z": -5,
      "name": "Plant_Leaves_Giantwood"
    },
    {
      "x": -58,
      "y": 201,
      "z": -5,
      "name": "Plant_Leaves_Giantwood"
    },
    {
      "x": -58,
      "y": 201,
      "z": -4,
      "name": "Plant_Leaves_Giantwood"
    },
    {
      "x": -58,
      "y": 204,
      "z": -4,
      "name": "Plant_Leaves_Giantwood"
    },
    {
      "x": -58,
      "y": 198,
      "z": -3,
      "name": "Plant_Leaves_Giantwood"
    },
    {
      "x": -58,
      "y": 199,
      "z": -3,
      "name": "Plant_Leaves_Giantwood"
    },
    {
      "x": -58,
      "y": 203,
      "z": -3,
      "name": "Plant_Leaves_Giantwood"
    },
    {
      "x": -58,
      "y": 200,
      "z": -2,
      "name": "Plant_Leaves_Giantwood"
    },
    {
      "x": -58,
      "y": 202,
      "z": -2,
      "name": "Plant_Leaves_Giantwood"
    },
    {
      "x": -58,
      "y": 204,
      "z": -2,
      "name": "Plant_Leaves_Giantwood"
    },
    {
      "x": -58,
      "y": 199,
      "z": -1,
      "name": "Plant_Leaves_Giantwood"
    },
    {
      "x": -58,
      "y": 200,
      "z": -1,
      "name": "Plant_Leaves_Giantwood"
    },
    {
      "x": -58,
      "y": 204,
      "z": -1,
      "name": "Plant_Leaves_Giantwood"
    },
    {
      "x": -58,
      "y": 205,
      "z": -1,
      "name": "Plant_Leaves_Giantwood"
    },
    {
      "x": -58,
      "y": 202,
      "z": 0,
      "name": "Plant_Leaves_Giantwood"
    },
    {
      "x": -58,
      "y": 203,
      "z": 0,
      "name": "Plant_Leaves_Giantwood"
    },
    {
      "x": -58,
      "y": 204,
      "z": 0,
      "name": "Plant_Leaves_Giantwood"
    },
    {
      "x": -58,
      "y": 205,
      "z": 0,
      "name": "Plant_Leaves_Giantwood"
    },
    {
      "x": -58,
      "y": 201,
      "z": 1,
      "name": "Plant_Leaves_Giantwood"
    },
    {
      "x": -58,
      "y": 198,
      "z": 2,
      "name": "Plant_Leaves_Giantwood"
    },
    {
      "x": -58,
      "y": 201,
      "z": 2,
      "name": "Plant_Leaves_Giantwood"
    },
    {
      "x": -58,
      "y": 204,
      "z": 2,
      "name": "Plant_Leaves_Giantwood"
    },
    {
      "x": -58,
      "y": 202,
      "z": 3,
      "name": "Plant_Leaves_Giantwood"
    },
    {
      "x": -58,
      "y": 203,
      "z": 3,
      "name": "Plant_Leaves_Giantwood"
    },
    {
      "x": -58,
      "y": 204,
      "z": 3,
      "name": "Plant_Leaves_Giantwood"
    },
    {
      "x": -58,
      "y": 199,
      "z": 4,
      "name": "Plant_Leaves_Giantwood"
    },
    {
      "x": -58,
      "y": 202,
      "z": 4,
      "name": "Plant_Leaves_Giantwood"
    },
    {
      "x": -58,
      "y": 200,
      "z": 5,
      "name": "Plant_Leaves_Giantwood"
    },
    {
      "x": -58,
      "y": 202,
      "z": 5,
      "name": "Plant_Leaves_Giantwood"
    },
    {
      "x": -58,
      "y": 204,
      "z": 5,
      "name": "Plant_Leaves_Giantwood"
    },
    {
      "x": -58,
      "y": 199,
      "z": 6,
      "name": "Plant_Leaves_Giantwood"
    },
    {
      "x": -58,
      "y": 201,
      "z": 6,
      "name": "Plant_Leaves_Giantwood"
    },
    {
      "x": -58,
      "y": 202,
      "z": 6,
      "name": "Plant_Leaves_Giantwood"
    },
    {
      "x": -58,
      "y": 203,
      "z": 6,
      "name": "Plant_Leaves_Giantwood"
    },
    {
      "x": -58,
      "y": 204,
      "z": 6,
      "name": "Plant_Leaves_Giantwood"
    },
    {
      "x": -58,
      "y": 200,
      "z": 8,
      "name": "Plant_Leaves_Giantwood"
    },
    {
      "x": -58,
      "y": 202,
      "z": 9,
      "name": "Plant_Leaves_Giantwood"
    },
    {
      "x": -57,
      "y": 200,
      "z": -13,
      "name": "Plant_Leaves_Giantwood"
    },
    {
      "x": -57,
      "y": 200,
      "z": -10,
      "name": "Plant_Leaves_Giantwood"
    },
    {
      "x": -57,
      "y": 202,
      "z": -10,
      "name": "Plant_Leaves_Giantwood"
    },
    {
      "x": -57,
      "y": 203,
      "z": -10,
      "name": "Plant_Leaves_Giantwood"
    },
    {
      "x": -57,
      "y": 202,
      "z": -8,
      "name": "Plant_Leaves_Giantwood"
    },
    {
      "x": -57,
      "y": 203,
      "z": -8,
      "name": "Plant_Leaves_Giantwood"
    },
    {
      "x": -57,
      "y": 204,
      "z": -7,
      "name": "Plant_Leaves_Giantwood"
    },
    {
      "x": -57,
      "y": 198,
      "z": -6,
      "name": "Plant_Leaves_Giantwood"
    },
    {
      "x": -57,
      "y": 199,
      "z": -5,
      "name": "Plant_Leaves_Giantwood"
    },
    {
      "x": -57,
      "y": 200,
      "z": -5,
      "name": "Plant_Leaves_Giantwood"
    },
    {
      "x": -57,
      "y": 201,
      "z": -5,
      "name": "Plant_Leaves_Giantwood"
    },
    {
      "x": -57,
      "y": 202,
      "z": -5,
      "name": "Plant_Leaves_Giantwood"
    },
    {
      "x": -57,
      "y": 203,
      "z": -5,
      "name": "Plant_Leaves_Giantwood"
    },
    {
      "x": -57,
      "y": 204,
      "z": -5,
      "name": "Plant_Leaves_Giantwood"
    },
    {
      "x": -57,
      "y": 205,
      "z": -5,
      "name": "Plant_Leaves_Giantwood"
    },
    {
      "x": -57,
      "y": 198,
      "z": -3,
      "name": "Plant_Leaves_Giantwood"
    },
    {
      "x": -57,
      "y": 202,
      "z": -3,
      "name": "Plant_Leaves_Giantwood"
    },
    {
      "x": -57,
      "y": 203,
      "z": -3,
      "name": "Plant_Leaves_Giantwood"
    },
    {
      "x": -57,
      "y": 204,
      "z": -2,
      "name": "Plant_Leaves_Giantwood"
    },
    {
      "x": -57,
      "y": 198,
      "z": -1,
      "name": "Plant_Leaves_Giantwood"
    },
    {
      "x": -57,
      "y": 199,
      "z": -1,
      "name": "Plant_Leaves_Giantwood"
    },
    {
      "x": -57,
      "y": 203,
      "z": -1,
      "name": "Plant_Leaves_Giantwood"
    },
    {
      "x": -57,
      "y": 205,
      "z": -1,
      "name": "Plant_Leaves_Giantwood"
    },
    {
      "x": -57,
      "y": 198,
      "z": 1,
      "name": "Plant_Leaves_Giantwood"
    },
    {
      "x": -57,
      "y": 199,
      "z": 1,
      "name": "Plant_Leaves_Giantwood"
    },
    {
      "x": -57,
      "y": 205,
      "z": 1,
      "name": "Plant_Leaves_Giantwood"
    },
    {
      "x": -57,
      "y": 203,
      "z": 2,
      "name": "Plant_Leaves_Giantwood"
    },
    {
      "x": -57,
      "y": 199,
      "z": 3,
      "name": "Plant_Leaves_Giantwood"
    },
    {
      "x": -57,
      "y": 199,
      "z": 4,
      "name": "Plant_Leaves_Giantwood"
    },
    {
      "x": -57,
      "y": 205,
      "z": 4,
      "name": "Plant_Leaves_Giantwood"
    },
    {
      "x": -57,
      "y": 203,
      "z": 5,
      "name": "Plant_Leaves_Giantwood"
    },
    {
      "x": -57,
      "y": 199,
      "z": 6,
      "name": "Plant_Leaves_Giantwood"
    },
    {
      "x": -57,
      "y": 201,
      "z": 6,
      "name": "Plant_Leaves_Giantwood"
    },
    {
      "x": -57,
      "y": 204,
      "z": 6,
      "name": "Plant_Leaves_Giantwood"
    },
    {
      "x": -57,
      "y": 205,
      "z": 6,
      "name": "Plant_Leaves_Giantwood"
    },
    {
      "x": -57,
      "y": 199,
      "z": 7,
      "name": "Plant_Leaves_Giantwood"
    },
    {
      "x": -57,
      "y": 201,
      "z": 7,
      "name": "Plant_Leaves_Giantwood"
    },
    {
      "x": -57,
      "y": 202,
      "z": 7,
      "name": "Plant_Leaves_Giantwood"
    },
    {
      "x": -57,
      "y": 203,
      "z": 7,
      "name": "Plant_Leaves_Giantwood"
    },
    {
      "x": -57,
      "y": 200,
      "z": 8,
      "name": "Plant_Leaves_Giantwood"
    },
    {
      "x": -57,
      "y": 201,
      "z": 8,
      "name": "Plant_Leaves_Giantwood"
    },
    {
      "x": -57,
      "y": 202,
      "z": 8,
      "name": "Plant_Leaves_Giantwood"
    },
    {
      "x": -57,
      "y": 202,
      "z": 9,
      "name": "Plant_Leaves_Giantwood"
    },
    {
      "x": -57,
      "y": 203,
      "z": 9,
      "name": "Plant_Leaves_Giantwood"
    },
    {
      "x": -57,
      "y": 204,
      "z": 9,
      "name": "Plant_Leaves_Giantwood"
    },
    {
      "x": -57,
      "y": 202,
      "z": 10,
      "name": "Plant_Leaves_Giantwood"
    },
    {
      "x": -57,
      "y": 203,
      "z": 10,
      "name": "Plant_Leaves_Giantwood"
    },
    {
      "x": -57,
      "y": 202,
      "z": 11,
      "name": "Plant_Leaves_Giantwood"
    },
    {
      "x": -56,
      "y": 202,
      "z": -15,
      "name": "Plant_Leaves_Giantwood"
    },
    {
      "x": -56,
      "y": 200,
      "z": -13,
      "name": "Plant_Leaves_Giantwood"
    },
    {
      "x": -56,
      "y": 200,
      "z": -12,
      "name": "Plant_Leaves_Giantwood"
    },
    {
      "x": -56,
      "y": 203,
      "z": -12,
      "name": "Plant_Leaves_Giantwood"
    },
    {
      "x": -56,
      "y": 204,
      "z": -12,
      "name": "Plant_Leaves_Giantwood"
    },
    {
      "x": -56,
      "y": 200,
      "z": -11,
      "name": "Plant_Leaves_Giantwood"
    },
    {
      "x": -56,
      "y": 201,
      "z": -11,
      "name": "Plant_Leaves_Giantwood"
    },
    {
      "x": -56,
      "y": 203,
      "z": -10,
      "name": "Plant_Leaves_Giantwood"
    },
    {
      "x": -56,
      "y": 204,
      "z": -10,
      "name": "Plant_Leaves_Giantwood"
    },
    {
      "x": -56,
      "y": 198,
      "z": -9,
      "name": "Plant_Leaves_Giantwood"
    },
    {
      "x": -56,
      "y": 202,
      "z": -9,
      "name": "Plant_Leaves_Giantwood"
    },
    {
      "x": -56,
      "y": 203,
      "z": -9,
      "name": "Plant_Leaves_Giantwood"
    },
    {
      "x": -56,
      "y": 198,
      "z": -8,
      "name": "Plant_Leaves_Giantwood"
    },
    {
      "x": -56,
      "y": 199,
      "z": -8,
      "name": "Plant_Leaves_Giantwood"
    },
    {
      "x": -56,
      "y": 205,
      "z": -8,
      "name": "Plant_Leaves_Giantwood"
    },
    {
      "x": -56,
      "y": 199,
      "z": -7,
      "name": "Plant_Leaves_Giantwood"
    },
    {
      "x": -56,
      "y": 199,
      "z": -6,
      "name": "Plant_Leaves_Giantwood"
    },
    {
      "x": -56,
      "y": 203,
      "z": -6,
      "name": "Plant_Leaves_Giantwood"
    },
    {
      "x": -56,
      "y": 201,
      "z": -5,
      "name": "Plant_Leaves_Giantwood"
    },
    {
      "x": -56,
      "y": 202,
      "z": -5,
      "name": "Plant_Leaves_Giantwood"
    },
    {
      "x": -56,
      "y": 204,
      "z": -5,
      "name": "Plant_Leaves_Giantwood"
    },
    {
      "x": -56,
      "y": 205,
      "z": -5,
      "name": "Plant_Leaves_Giantwood"
    },
    {
      "x": -56,
      "y": 199,
      "z": -4,
      "name": "Plant_Leaves_Giantwood"
    },
    {
      "x": -56,
      "y": 201,
      "z": -4,
      "name": "Plant_Leaves_Giantwood"
    },
    {
      "x": -56,
      "y": 203,
      "z": -4,
      "name": "Plant_Leaves_Giantwood"
    },
    {
      "x": -56,
      "y": 204,
      "z": -4,
      "name": "Plant_Leaves_Giantwood"
    },
    {
      "x": -56,
      "y": 203,
      "z": -3,
      "name": "Plant_Leaves_Giantwood"
    },
    {
      "x": -56,
      "y": 204,
      "z": -3,
      "name": "Plant_Leaves_Giantwood"
    },
    {
      "x": -56,
      "y": 200,
      "z": -2,
      "name": "Plant_Leaves_Giantwood"
    },
    {
      "x": -56,
      "y": 202,
      "z": -2,
      "name": "Plant_Leaves_Giantwood"
    },
    {
      "x": -56,
      "y": 201,
      "z": -1,
      "name": "Plant_Leaves_Giantwood"
    },
    {
      "x": -56,
      "y": 203,
      "z": -1,
      "name": "Plant_Leaves_Giantwood"
    },
    {
      "x": -56,
      "y": 204,
      "z": -1,
      "name": "Plant_Leaves_Giantwood"
    },
    {
      "x": -56,
      "y": 198,
      "z": 0,
      "name": "Plant_Leaves_Giantwood"
    },
    {
      "x": -56,
      "y": 199,
      "z": 0,
      "name": "Plant_Leaves_Giantwood"
    },
    {
      "x": -56,
      "y": 198,
      "z": 1,
      "name": "Plant_Leaves_Giantwood"
    },
    {
      "x": -56,
      "y": 200,
      "z": 1,
      "name": "Plant_Leaves_Giantwood"
    },
    {
      "x": -56,
      "y": 201,
      "z": 1,
      "name": "Plant_Leaves_Giantwood"
    },
    {
      "x": -56,
      "y": 204,
      "z": 1,
      "name": "Plant_Leaves_Giantwood"
    },
    {
      "x": -56,
      "y": 205,
      "z": 1,
      "name": "Plant_Leaves_Giantwood"
    },
    {
      "x": -56,
      "y": 199,
      "z": 2,
      "name": "Plant_Leaves_Giantwood"
    },
    {
      "x": -56,
      "y": 202,
      "z": 2,
      "name": "Plant_Leaves_Giantwood"
    },
    {
      "x": -56,
      "y": 203,
      "z": 2,
      "name": "Plant_Leaves_Giantwood"
    },
    {
      "x": -56,
      "y": 202,
      "z": 3,
      "name": "Plant_Leaves_Giantwood"
    },
    {
      "x": -56,
      "y": 199,
      "z": 4,
      "name": "Plant_Leaves_Giantwood"
    },
    {
      "x": -56,
      "y": 205,
      "z": 4,
      "name": "Plant_Leaves_Giantwood"
    },
    {
      "x": -56,
      "y": 198,
      "z": 5,
      "name": "Plant_Leaves_Giantwood"
    },
    {
      "x": -56,
      "y": 199,
      "z": 5,
      "name": "Plant_Leaves_Giantwood"
    },
    {
      "x": -56,
      "y": 201,
      "z": 5,
      "name": "Plant_Leaves_Giantwood"
    },
    {
      "x": -56,
      "y": 203,
      "z": 5,
      "name": "Plant_Leaves_Giantwood"
    },
    {
      "x": -56,
      "y": 198,
      "z": 6,
      "name": "Plant_Leaves_Giantwood"
    },
    {
      "x": -56,
      "y": 204,
      "z": 6,
      "name": "Plant_Leaves_Giantwood"
    },
    {
      "x": -56,
      "y": 205,
      "z": 6,
      "name": "Plant_Leaves_Giantwood"
    },
    {
      "x": -56,
      "y": 198,
      "z": 7,
      "name": "Plant_Leaves_Giantwood"
    },
    {
      "x": -56,
      "y": 199,
      "z": 7,
      "name": "Plant_Leaves_Giantwood"
    },
    {
      "x": -56,
      "y": 199,
      "z": 8,
      "name": "Plant_Leaves_Giantwood"
    },
    {
      "x": -56,
      "y": 201,
      "z": 8,
      "name": "Plant_Leaves_Giantwood"
    },
    {
      "x": -56,
      "y": 203,
      "z": 8,
      "name": "Plant_Leaves_Giantwood"
    },
    {
      "x": -56,
      "y": 203,
      "z": 9,
      "name": "Plant_Leaves_Giantwood"
    },
    {
      "x": -56,
      "y": 200,
      "z": 10,
      "name": "Plant_Leaves_Giantwood"
    },
    {
      "x": -56,
      "y": 201,
      "z": 10,
      "name": "Plant_Leaves_Giantwood"
    },
    {
      "x": -56,
      "y": 204,
      "z": 10,
      "name": "Plant_Leaves_Giantwood"
    },
    {
      "x": -56,
      "y": 202,
      "z": 11,
      "name": "Plant_Leaves_Giantwood"
    },
    {
      "x": -55,
      "y": 201,
      "z": -16,
      "name": "Plant_Leaves_Giantwood"
    },
    {
      "x": -55,
      "y": 199,
      "z": -14,
      "name": "Plant_Leaves_Giantwood"
    },
    {
      "x": -55,
      "y": 200,
      "z": -14,
      "name": "Plant_Leaves_Giantwood"
    },
    {
      "x": -55,
      "y": 203,
      "z": -14,
      "name": "Plant_Leaves_Giantwood"
    },
    {
      "x": -55,
      "y": 200,
      "z": -13,
      "name": "Plant_Leaves_Giantwood"
    },
    {
      "x": -55,
      "y": 201,
      "z": -13,
      "name": "Plant_Leaves_Giantwood"
    },
    {
      "x": -55,
      "y": 203,
      "z": -13,
      "name": "Plant_Leaves_Giantwood"
    },
    {
      "x": -55,
      "y": 200,
      "z": -12,
      "name": "Plant_Leaves_Giantwood"
    },
    {
      "x": -55,
      "y": 204,
      "z": -12,
      "name": "Plant_Leaves_Giantwood"
    },
    {
      "x": -55,
      "y": 201,
      "z": -11,
      "name": "Plant_Leaves_Giantwood"
    },
    {
      "x": -55,
      "y": 204,
      "z": -11,
      "name": "Plant_Leaves_Giantwood"
    },
    {
      "x": -55,
      "y": 199,
      "z": -10,
      "name": "Plant_Leaves_Giantwood"
    },
    {
      "x": -55,
      "y": 200,
      "z": -10,
      "name": "Plant_Leaves_Giantwood"
    },
    {
      "x": -55,
      "y": 201,
      "z": -10,
      "name": "Plant_Leaves_Giantwood"
    },
    {
      "x": -55,
      "y": 204,
      "z": -10,
      "name": "Plant_Leaves_Giantwood"
    },
    {
      "x": -55,
      "y": 199,
      "z": -9,
      "name": "Plant_Leaves_Giantwood"
    },
    {
      "x": -55,
      "y": 200,
      "z": -8,
      "name": "Plant_Leaves_Giantwood"
    },
    {
      "x": -55,
      "y": 201,
      "z": -8,
      "name": "Plant_Leaves_Giantwood"
    },
    {
      "x": -55,
      "y": 204,
      "z": -8,
      "name": "Plant_Leaves_Giantwood"
    },
    {
      "x": -55,
      "y": 198,
      "z": -7,
      "name": "Plant_Leaves_Giantwood"
    },
    {
      "x": -55,
      "y": 199,
      "z": -7,
      "name": "Plant_Leaves_Giantwood"
    },
    {
      "x": -55,
      "y": 201,
      "z": -7,
      "name": "Plant_Leaves_Giantwood"
    },
    {
      "x": -55,
      "y": 204,
      "z": -7,
      "name": "Plant_Leaves_Giantwood"
    },
    {
      "x": -55,
      "y": 203,
      "z": -5,
      "name": "Plant_Leaves_Giantwood"
    },
    {
      "x": -55,
      "y": 197,
      "z": -4,
      "name": "Plant_Leaves_Giantwood"
    },
    {
      "x": -55,
      "y": 198,
      "z": -4,
      "name": "Plant_Leaves_Giantwood"
    },
    {
      "x": -55,
      "y": 199,
      "z": -4,
      "name": "Plant_Leaves_Giantwood"
    },
    {
      "x": -55,
      "y": 200,
      "z": -4,
      "name": "Plant_Leaves_Giantwood"
    },
    {
      "x": -55,
      "y": 204,
      "z": -4,
      "name": "Plant_Leaves_Giantwood"
    },
    {
      "x": -55,
      "y": 198,
      "z": -3,
      "name": "Plant_Leaves_Giantwood"
    },
    {
      "x": -55,
      "y": 199,
      "z": -3,
      "name": "Plant_Leaves_Giantwood"
    },
    {
      "x": -55,
      "y": 201,
      "z": -3,
      "name": "Plant_Leaves_Giantwood"
    },
    {
      "x": -55,
      "y": 203,
      "z": -3,
      "name": "Plant_Leaves_Giantwood"
    },
    {
      "x": -55,
      "y": 199,
      "z": -2,
      "name": "Plant_Leaves_Giantwood"
    },
    {
      "x": -55,
      "y": 200,
      "z": -2,
      "name": "Plant_Leaves_Giantwood"
    },
    {
      "x": -55,
      "y": 201,
      "z": -2,
      "name": "Plant_Leaves_Giantwood"
    },
    {
      "x": -55,
      "y": 203,
      "z": -2,
      "name": "Plant_Leaves_Giantwood"
    },
    {
      "x": -55,
      "y": 204,
      "z": -2,
      "name": "Plant_Leaves_Giantwood"
    },
    {
      "x": -55,
      "y": 205,
      "z": -2,
      "name": "Plant_Leaves_Giantwood"
    },
    {
      "x": -55,
      "y": 197,
      "z": -1,
      "name": "Plant_Leaves_Giantwood"
    },
    {
      "x": -55,
      "y": 198,
      "z": -1,
      "name": "Plant_Leaves_Giantwood"
    },
    {
      "x": -55,
      "y": 199,
      "z": -1,
      "name": "Plant_Leaves_Giantwood"
    },
    {
      "x": -55,
      "y": 203,
      "z": -1,
      "name": "Plant_Leaves_Giantwood"
    },
    {
      "x": -55,
      "y": 204,
      "z": -1,
      "name": "Plant_Leaves_Giantwood"
    },
    {
      "x": -55,
      "y": 206,
      "z": -1,
      "name": "Plant_Leaves_Giantwood"
    },
    {
      "x": -55,
      "y": 201,
      "z": 0,
      "name": "Plant_Leaves_Giantwood"
    },
    {
      "x": -55,
      "y": 203,
      "z": 0,
      "name": "Plant_Leaves_Giantwood"
    },
    {
      "x": -55,
      "y": 198,
      "z": 1,
      "name": "Plant_Leaves_Giantwood"
    },
    {
      "x": -55,
      "y": 200,
      "z": 1,
      "name": "Plant_Leaves_Giantwood"
    },
    {
      "x": -55,
      "y": 202,
      "z": 1,
      "name": "Plant_Leaves_Giantwood"
    },
    {
      "x": -55,
      "y": 205,
      "z": 1,
      "name": "Plant_Leaves_Giantwood"
    },
    {
      "x": -55,
      "y": 200,
      "z": 2,
      "name": "Plant_Leaves_Giantwood"
    },
    {
      "x": -55,
      "y": 201,
      "z": 2,
      "name": "Plant_Leaves_Giantwood"
    },
    {
      "x": -55,
      "y": 204,
      "z": 2,
      "name": "Plant_Leaves_Giantwood"
    },
    {
      "x": -55,
      "y": 205,
      "z": 2,
      "name": "Plant_Leaves_Giantwood"
    },
    {
      "x": -55,
      "y": 201,
      "z": 3,
      "name": "Plant_Leaves_Giantwood"
    },
    {
      "x": -55,
      "y": 205,
      "z": 3,
      "name": "Plant_Leaves_Giantwood"
    },
    {
      "x": -55,
      "y": 206,
      "z": 3,
      "name": "Plant_Leaves_Giantwood"
    },
    {
      "x": -55,
      "y": 202,
      "z": 5,
      "name": "Plant_Leaves_Giantwood"
    },
    {
      "x": -55,
      "y": 203,
      "z": 5,
      "name": "Plant_Leaves_Giantwood"
    },
    {
      "x": -55,
      "y": 205,
      "z": 5,
      "name": "Plant_Leaves_Giantwood"
    },
    {
      "x": -55,
      "y": 198,
      "z": 6,
      "name": "Plant_Leaves_Giantwood"
    },
    {
      "x": -55,
      "y": 203,
      "z": 6,
      "name": "Plant_Leaves_Giantwood"
    },
    {
      "x": -55,
      "y": 198,
      "z": 7,
      "name": "Plant_Leaves_Giantwood"
    },
    {
      "x": -55,
      "y": 199,
      "z": 7,
      "name": "Plant_Leaves_Giantwood"
    },
    {
      "x": -55,
      "y": 200,
      "z": 7,
      "name": "Plant_Leaves_Giantwood"
    },
    {
      "x": -55,
      "y": 201,
      "z": 8,
      "name": "Plant_Leaves_Giantwood"
    },
    {
      "x": -55,
      "y": 202,
      "z": 8,
      "name": "Plant_Leaves_Giantwood"
    },
    {
      "x": -55,
      "y": 203,
      "z": 8,
      "name": "Plant_Leaves_Giantwood"
    },
    {
      "x": -55,
      "y": 199,
      "z": 9,
      "name": "Plant_Leaves_Giantwood"
    },
    {
      "x": -55,
      "y": 202,
      "z": 9,
      "name": "Plant_Leaves_Giantwood"
    },
    {
      "x": -55,
      "y": 199,
      "z": 11,
      "name": "Plant_Leaves_Giantwood"
    },
    {
      "x": -55,
      "y": 202,
      "z": 12,
      "name": "Plant_Leaves_Giantwood"
    },
    {
      "x": -55,
      "y": 201,
      "z": 13,
      "name": "Plant_Leaves_Giantwood"
    },
    {
      "x": -54,
      "y": 202,
      "z": -17,
      "name": "Plant_Leaves_Giantwood"
    },
    {
      "x": -54,
      "y": 201,
      "z": -16,
      "name": "Plant_Leaves_Giantwood"
    },
    {
      "x": -54,
      "y": 202,
      "z": -16,
      "name": "Plant_Leaves_Giantwood"
    },
    {
      "x": -54,
      "y": 203,
      "z": -15,
      "name": "Plant_Leaves_Giantwood"
    },
    {
      "x": -54,
      "y": 200,
      "z": -13,
      "name": "Plant_Leaves_Giantwood"
    },
    {
      "x": -54,
      "y": 204,
      "z": -13,
      "name": "Plant_Leaves_Giantwood"
    },
    {
      "x": -54,
      "y": 200,
      "z": -12,
      "name": "Plant_Leaves_Giantwood"
    },
    {
      "x": -54,
      "y": 205,
      "z": -12,
      "name": "Plant_Leaves_Giantwood"
    },
    {
      "x": -54,
      "y": 201,
      "z": -11,
      "name": "Plant_Leaves_Giantwood"
    },
    {
      "x": -54,
      "y": 204,
      "z": -11,
      "name": "Plant_Leaves_Giantwood"
    },
    {
      "x": -54,
      "y": 204,
      "z": -10,
      "name": "Plant_Leaves_Giantwood"
    },
    {
      "x": -54,
      "y": 205,
      "z": -10,
      "name": "Plant_Leaves_Giantwood"
    },
    {
      "x": -54,
      "y": 198,
      "z": -9,
      "name": "Plant_Leaves_Giantwood"
    },
    {
      "x": -54,
      "y": 203,
      "z": -9,
      "name": "Plant_Leaves_Giantwood"
    },
    {
      "x": -54,
      "y": 205,
      "z": -9,
      "name": "Plant_Leaves_Giantwood"
    },
    {
      "x": -54,
      "y": 199,
      "z": -8,
      "name": "Plant_Leaves_Giantwood"
    },
    {
      "x": -54,
      "y": 203,
      "z": -8,
      "name": "Plant_Leaves_Giantwood"
    },
    {
      "x": -54,
      "y": 205,
      "z": -8,
      "name": "Plant_Leaves_Giantwood"
    },
    {
      "x": -54,
      "y": 204,
      "z": -7,
      "name": "Plant_Leaves_Giantwood"
    },
    {
      "x": -54,
      "y": 205,
      "z": -7,
      "name": "Plant_Leaves_Giantwood"
    },
    {
      "x": -54,
      "y": 199,
      "z": -6,
      "name": "Plant_Leaves_Giantwood"
    },
    {
      "x": -54,
      "y": 205,
      "z": -6,
      "name": "Plant_Leaves_Giantwood"
    },
    {
      "x": -54,
      "y": 206,
      "z": -6,
      "name": "Plant_Leaves_Giantwood"
    },
    {
      "x": -54,
      "y": 197,
      "z": -5,
      "name": "Plant_Leaves_Giantwood"
    },
    {
      "x": -54,
      "y": 204,
      "z": -5,
      "name": "Plant_Leaves_Giantwood"
    },
    {
      "x": -54,
      "y": 205,
      "z": -5,
      "name": "Plant_Leaves_Giantwood"
    },
    {
      "x": -54,
      "y": 198,
      "z": -4,
      "name": "Plant_Leaves_Giantwood"
    },
    {
      "x": -54,
      "y": 206,
      "z": -4,
      "name": "Plant_Leaves_Giantwood"
    },
    {
      "x": -54,
      "y": 204,
      "z": -3,
      "name": "Plant_Leaves_Giantwood"
    },
    {
      "x": -54,
      "y": 206,
      "z": -3,
      "name": "Plant_Leaves_Giantwood"
    },
    {
      "x": -54,
      "y": 197,
      "z": -2,
      "name": "Plant_Leaves_Giantwood"
    },
    {
      "x": -54,
      "y": 204,
      "z": -2,
      "name": "Plant_Leaves_Giantwood"
    },
    {
      "x": -54,
      "y": 197,
      "z": -1,
      "name": "Plant_Leaves_Giantwood"
    },
    {
      "x": -54,
      "y": 203,
      "z": -1,
      "name": "Plant_Leaves_Giantwood"
    },
    {
      "x": -54,
      "y": 206,
      "z": -1,
      "name": "Plant_Leaves_Giantwood"
    },
    {
      "x": -54,
      "y": 203,
      "z": 0,
      "name": "Plant_Leaves_Giantwood"
    },
    {
      "x": -54,
      "y": 204,
      "z": 0,
      "name": "Plant_Leaves_Giantwood"
    },
    {
      "x": -54,
      "y": 198,
      "z": 1,
      "name": "Plant_Leaves_Giantwood"
    },
    {
      "x": -54,
      "y": 203,
      "z": 1,
      "name": "Plant_Leaves_Giantwood"
    },
    {
      "x": -54,
      "y": 199,
      "z": 2,
      "name": "Plant_Leaves_Giantwood"
    },
    {
      "x": -54,
      "y": 200,
      "z": 2,
      "name": "Plant_Leaves_Giantwood"
    },
    {
      "x": -54,
      "y": 201,
      "z": 2,
      "name": "Plant_Leaves_Giantwood"
    },
    {
      "x": -54,
      "y": 203,
      "z": 2,
      "name": "Plant_Leaves_Giantwood"
    },
    {
      "x": -54,
      "y": 198,
      "z": 3,
      "name": "Plant_Leaves_Giantwood"
    },
    {
      "x": -54,
      "y": 203,
      "z": 3,
      "name": "Plant_Leaves_Giantwood"
    },
    {
      "x": -54,
      "y": 204,
      "z": 3,
      "name": "Plant_Leaves_Giantwood"
    },
    {
      "x": -54,
      "y": 197,
      "z": 4,
      "name": "Plant_Leaves_Giantwood"
    },
    {
      "x": -54,
      "y": 201,
      "z": 4,
      "name": "Plant_Leaves_Giantwood"
    },
    {
      "x": -54,
      "y": 205,
      "z": 4,
      "name": "Plant_Leaves_Giantwood"
    },
    {
      "x": -54,
      "y": 206,
      "z": 4,
      "name": "Plant_Leaves_Giantwood"
    },
    {
      "x": -54,
      "y": 201,
      "z": 5,
      "name": "Plant_Leaves_Giantwood"
    },
    {
      "x": -54,
      "y": 205,
      "z": 5,
      "name": "Plant_Leaves_Giantwood"
    },
    {
      "x": -54,
      "y": 198,
      "z": 6,
      "name": "Plant_Leaves_Giantwood"
    },
    {
      "x": -54,
      "y": 200,
      "z": 6,
      "name": "Plant_Leaves_Giantwood"
    },
    {
      "x": -54,
      "y": 201,
      "z": 6,
      "name": "Plant_Leaves_Giantwood"
    },
    {
      "x": -54,
      "y": 203,
      "z": 6,
      "name": "Plant_Leaves_Giantwood"
    },
    {
      "x": -54,
      "y": 204,
      "z": 6,
      "name": "Plant_Leaves_Giantwood"
    },
    {
      "x": -54,
      "y": 200,
      "z": 7,
      "name": "Plant_Leaves_Giantwood"
    },
    {
      "x": -54,
      "y": 203,
      "z": 7,
      "name": "Plant_Leaves_Giantwood"
    },
    {
      "x": -54,
      "y": 204,
      "z": 7,
      "name": "Plant_Leaves_Giantwood"
    },
    {
      "x": -54,
      "y": 205,
      "z": 7,
      "name": "Plant_Leaves_Giantwood"
    },
    {
      "x": -54,
      "y": 198,
      "z": 8,
      "name": "Plant_Leaves_Giantwood"
    },
    {
      "x": -54,
      "y": 200,
      "z": 8,
      "name": "Plant_Leaves_Giantwood"
    },
    {
      "x": -54,
      "y": 204,
      "z": 8,
      "name": "Plant_Leaves_Giantwood"
    },
    {
      "x": -54,
      "y": 205,
      "z": 8,
      "name": "Plant_Leaves_Giantwood"
    },
    {
      "x": -54,
      "y": 201,
      "z": 9,
      "name": "Plant_Leaves_Giantwood"
    },
    {
      "x": -54,
      "y": 204,
      "z": 9,
      "name": "Plant_Leaves_Giantwood"
    },
    {
      "x": -54,
      "y": 201,
      "z": 10,
      "name": "Plant_Leaves_Giantwood"
    },
    {
      "x": -54,
      "y": 202,
      "z": 10,
      "name": "Plant_Leaves_Giantwood"
    },
    {
      "x": -54,
      "y": 204,
      "z": 11,
      "name": "Plant_Leaves_Giantwood"
    },
    {
      "x": -54,
      "y": 203,
      "z": 12,
      "name": "Plant_Leaves_Giantwood"
    },
    {
      "x": -54,
      "y": 203,
      "z": 13,
      "name": "Plant_Leaves_Giantwood"
    },
    {
      "x": -53,
      "y": 202,
      "z": -18,
      "name": "Plant_Leaves_Giantwood"
    },
    {
      "x": -53,
      "y": 201,
      "z": -17,
      "name": "Plant_Leaves_Giantwood"
    },
    {
      "x": -53,
      "y": 202,
      "z": -17,
      "name": "Plant_Leaves_Giantwood"
    },
    {
      "x": -53,
      "y": 204,
      "z": -17,
      "name": "Plant_Leaves_Giantwood"
    },
    {
      "x": -53,
      "y": 200,
      "z": -16,
      "name": "Plant_Leaves_Giantwood"
    },
    {
      "x": -53,
      "y": 202,
      "z": -16,
      "name": "Plant_Leaves_Giantwood"
    },
    {
      "x": -53,
      "y": 203,
      "z": -16,
      "name": "Plant_Leaves_Giantwood"
    },
    {
      "x": -53,
      "y": 201,
      "z": -15,
      "name": "Plant_Leaves_Giantwood"
    },
    {
      "x": -53,
      "y": 204,
      "z": -15,
      "name": "Plant_Leaves_Giantwood"
    },
    {
      "x": -53,
      "y": 202,
      "z": -14,
      "name": "Plant_Leaves_Giantwood"
    },
    {
      "x": -53,
      "y": 203,
      "z": -14,
      "name": "Plant_Leaves_Giantwood"
    },
    {
      "x": -53,
      "y": 199,
      "z": -13,
      "name": "Plant_Leaves_Giantwood"
    },
    {
      "x": -53,
      "y": 202,
      "z": -13,
      "name": "Plant_Leaves_Giantwood"
    },
    {
      "x": -53,
      "y": 203,
      "z": -12,
      "name": "Plant_Leaves_Giantwood"
    },
    {
      "x": -53,
      "y": 204,
      "z": -12,
      "name": "Plant_Leaves_Giantwood"
    },
    {
      "x": -53,
      "y": 199,
      "z": -11,
      "name": "Plant_Leaves_Giantwood"
    },
    {
      "x": -53,
      "y": 204,
      "z": -11,
      "name": "Plant_Leaves_Giantwood"
    },
    {
      "x": -53,
      "y": 200,
      "z": -10,
      "name": "Plant_Leaves_Giantwood"
    },
    {
      "x": -53,
      "y": 201,
      "z": -10,
      "name": "Plant_Leaves_Giantwood"
    },
    {
      "x": -53,
      "y": 201,
      "z": -9,
      "name": "Plant_Leaves_Giantwood"
    },
    {
      "x": -53,
      "y": 200,
      "z": -7,
      "name": "Plant_Leaves_Giantwood"
    },
    {
      "x": -53,
      "y": 202,
      "z": -7,
      "name": "Plant_Leaves_Giantwood"
    },
    {
      "x": -53,
      "y": 198,
      "z": -6,
      "name": "Plant_Leaves_Giantwood"
    },
    {
      "x": -53,
      "y": 204,
      "z": -6,
      "name": "Plant_Leaves_Giantwood"
    },
    {
      "x": -53,
      "y": 205,
      "z": -6,
      "name": "Plant_Leaves_Giantwood"
    },
    {
      "x": -53,
      "y": 199,
      "z": -5,
      "name": "Plant_Leaves_Giantwood"
    },
    {
      "x": -53,
      "y": 202,
      "z": -5,
      "name": "Plant_Leaves_Giantwood"
    },
    {
      "x": -53,
      "y": 198,
      "z": -4,
      "name": "Plant_Leaves_Giantwood"
    },
    {
      "x": -53,
      "y": 206,
      "z": -4,
      "name": "Plant_Leaves_Giantwood"
    },
    {
      "x": -53,
      "y": 200,
      "z": -3,
      "name": "Plant_Leaves_Giantwood"
    },
    {
      "x": -53,
      "y": 201,
      "z": -3,
      "name": "Plant_Leaves_Giantwood"
    },
    {
      "x": -53,
      "y": 197,
      "z": -2,
      "name": "Plant_Leaves_Giantwood"
    },
    {
      "x": -53,
      "y": 201,
      "z": -2,
      "name": "Plant_Leaves_Giantwood"
    },
    {
      "x": -53,
      "y": 202,
      "z": -2,
      "name": "Plant_Leaves_Giantwood"
    },
    {
      "x": -53,
      "y": 205,
      "z": -2,
      "name": "Plant_Leaves_Giantwood"
    },
    {
      "x": -53,
      "y": 200,
      "z": -1,
      "name": "Plant_Leaves_Giantwood"
    },
    {
      "x": -53,
      "y": 206,
      "z": -1,
      "name": "Plant_Leaves_Giantwood"
    },
    {
      "x": -53,
      "y": 200,
      "z": 0,
      "name": "Plant_Leaves_Giantwood"
    },
    {
      "x": -53,
      "y": 202,
      "z": 0,
      "name": "Plant_Leaves_Giantwood"
    },
    {
      "x": -53,
      "y": 205,
      "z": 0,
      "name": "Plant_Leaves_Giantwood"
    },
    {
      "x": -53,
      "y": 203,
      "z": 1,
      "name": "Plant_Leaves_Giantwood"
    },
    {
      "x": -53,
      "y": 201,
      "z": 2,
      "name": "Plant_Leaves_Giantwood"
    },
    {
      "x": -53,
      "y": 206,
      "z": 2,
      "name": "Plant_Leaves_Giantwood"
    },
    {
      "x": -53,
      "y": 199,
      "z": 3,
      "name": "Plant_Leaves_Giantwood"
    },
    {
      "x": -53,
      "y": 200,
      "z": 3,
      "name": "Plant_Leaves_Giantwood"
    },
    {
      "x": -53,
      "y": 202,
      "z": 3,
      "name": "Plant_Leaves_Giantwood"
    },
    {
      "x": -53,
      "y": 203,
      "z": 3,
      "name": "Plant_Leaves_Giantwood"
    },
    {
      "x": -53,
      "y": 205,
      "z": 3,
      "name": "Plant_Leaves_Giantwood"
    },
    {
      "x": -53,
      "y": 197,
      "z": 5,
      "name": "Plant_Leaves_Giantwood"
    },
    {
      "x": -53,
      "y": 199,
      "z": 5,
      "name": "Plant_Leaves_Giantwood"
    },
    {
      "x": -53,
      "y": 202,
      "z": 5,
      "name": "Plant_Leaves_Giantwood"
    },
    {
      "x": -53,
      "y": 206,
      "z": 5,
      "name": "Plant_Leaves_Giantwood"
    },
    {
      "x": -53,
      "y": 198,
      "z": 6,
      "name": "Plant_Leaves_Giantwood"
    },
    {
      "x": -53,
      "y": 199,
      "z": 6,
      "name": "Plant_Leaves_Giantwood"
    },
    {
      "x": -53,
      "y": 203,
      "z": 6,
      "name": "Plant_Leaves_Giantwood"
    },
    {
      "x": -53,
      "y": 205,
      "z": 6,
      "name": "Plant_Leaves_Giantwood"
    },
    {
      "x": -53,
      "y": 200,
      "z": 7,
      "name": "Plant_Leaves_Giantwood"
    },
    {
      "x": -53,
      "y": 202,
      "z": 7,
      "name": "Plant_Leaves_Giantwood"
    },
    {
      "x": -53,
      "y": 199,
      "z": 8,
      "name": "Plant_Leaves_Giantwood"
    },
    {
      "x": -53,
      "y": 204,
      "z": 8,
      "name": "Plant_Leaves_Giantwood"
    },
    {
      "x": -53,
      "y": 205,
      "z": 8,
      "name": "Plant_Leaves_Giantwood"
    },
    {
      "x": -53,
      "y": 204,
      "z": 9,
      "name": "Plant_Leaves_Giantwood"
    },
    {
      "x": -53,
      "y": 200,
      "z": 10,
      "name": "Plant_Leaves_Giantwood"
    },
    {
      "x": -53,
      "y": 201,
      "z": 10,
      "name": "Plant_Leaves_Giantwood"
    },
    {
      "x": -53,
      "y": 204,
      "z": 11,
      "name": "Plant_Leaves_Giantwood"
    },
    {
      "x": -53,
      "y": 199,
      "z": 12,
      "name": "Plant_Leaves_Giantwood"
    },
    {
      "x": -53,
      "y": 203,
      "z": 12,
      "name": "Plant_Leaves_Giantwood"
    },
    {
      "x": -53,
      "y": 204,
      "z": 12,
      "name": "Plant_Leaves_Giantwood"
    },
    {
      "x": -53,
      "y": 203,
      "z": 13,
      "name": "Plant_Leaves_Giantwood"
    },
    {
      "x": -52,
      "y": 203,
      "z": -19,
      "name": "Plant_Leaves_Giantwood"
    },
    {
      "x": -52,
      "y": 204,
      "z": -19,
      "name": "Plant_Leaves_Giantwood"
    },
    {
      "x": -52,
      "y": 205,
      "z": -19,
      "name": "Plant_Leaves_Giantwood"
    },
    {
      "x": -52,
      "y": 205,
      "z": -18,
      "name": "Plant_Leaves_Giantwood"
    },
    {
      "x": -52,
      "y": 205,
      "z": -17,
      "name": "Plant_Leaves_Giantwood"
    },
    {
      "x": -52,
      "y": 202,
      "z": -15,
      "name": "Plant_Leaves_Giantwood"
    },
    {
      "x": -52,
      "y": 203,
      "z": -15,
      "name": "Plant_Leaves_Giantwood"
    },
    {
      "x": -52,
      "y": 200,
      "z": -14,
      "name": "Plant_Leaves_Giantwood"
    },
    {
      "x": -52,
      "y": 199,
      "z": -12,
      "name": "Plant_Leaves_Giantwood"
    },
    {
      "x": -52,
      "y": 200,
      "z": -12,
      "name": "Plant_Leaves_Giantwood"
    },
    {
      "x": -52,
      "y": 199,
      "z": -11,
      "name": "Plant_Leaves_Giantwood"
    },
    {
      "x": -52,
      "y": 202,
      "z": -11,
      "name": "Plant_Leaves_Giantwood"
    },
    {
      "x": -52,
      "y": 204,
      "z": -11,
      "name": "Plant_Leaves_Giantwood"
    },
    {
      "x": -52,
      "y": 198,
      "z": -9,
      "name": "Plant_Leaves_Giantwood"
    },
    {
      "x": -52,
      "y": 203,
      "z": -9,
      "name": "Plant_Leaves_Giantwood"
    },
    {
      "x": -52,
      "y": 203,
      "z": -8,
      "name": "Plant_Leaves_Giantwood"
    },
    {
      "x": -52,
      "y": 206,
      "z": -8,
      "name": "Plant_Leaves_Giantwood"
    },
    {
      "x": -52,
      "y": 202,
      "z": -7,
      "name": "Plant_Leaves_Giantwood"
    },
    {
      "x": -52,
      "y": 200,
      "z": -6,
      "name": "Plant_Leaves_Giantwood"
    },
    {
      "x": -52,
      "y": 201,
      "z": -6,
      "name": "Plant_Leaves_Giantwood"
    },
    {
      "x": -52,
      "y": 204,
      "z": -6,
      "name": "Plant_Leaves_Giantwood"
    },
    {
      "x": -52,
      "y": 197,
      "z": -5,
      "name": "Plant_Leaves_Giantwood"
    },
    {
      "x": -52,
      "y": 199,
      "z": -5,
      "name": "Plant_Leaves_Giantwood"
    },
    {
      "x": -52,
      "y": 203,
      "z": -5,
      "name": "Plant_Leaves_Giantwood"
    },
    {
      "x": -52,
      "y": 204,
      "z": -5,
      "name": "Plant_Leaves_Giantwood"
    },
    {
      "x": -52,
      "y": 205,
      "z": -5,
      "name": "Plant_Leaves_Giantwood"
    },
    {
      "x": -52,
      "y": 199,
      "z": -4,
      "name": "Plant_Leaves_Giantwood"
    },
    {
      "x": -52,
      "y": 202,
      "z": -4,
      "name": "Plant_Leaves_Giantwood"
    },
    {
      "x": -52,
      "y": 203,
      "z": -4,
      "name": "Plant_Leaves_Giantwood"
    },
    {
      "x": -52,
      "y": 199,
      "z": -3,
      "name": "Plant_Leaves_Giantwood"
    },
    {
      "x": -52,
      "y": 199,
      "z": -2,
      "name": "Plant_Leaves_Giantwood"
    },
    {
      "x": -52,
      "y": 204,
      "z": -2,
      "name": "Plant_Leaves_Giantwood"
    },
    {
      "x": -52,
      "y": 205,
      "z": -2,
      "name": "Plant_Leaves_Giantwood"
    },
    {
      "x": -52,
      "y": 201,
      "z": -1,
      "name": "Plant_Leaves_Giantwood"
    },
    {
      "x": -52,
      "y": 202,
      "z": -1,
      "name": "Plant_Leaves_Giantwood"
    },
    {
      "x": -52,
      "y": 201,
      "z": 0,
      "name": "Plant_Leaves_Giantwood"
    },
    {
      "x": -52,
      "y": 203,
      "z": 0,
      "name": "Plant_Leaves_Giantwood"
    },
    {
      "x": -52,
      "y": 197,
      "z": 1,
      "name": "Plant_Leaves_Giantwood"
    },
    {
      "x": -52,
      "y": 199,
      "z": 1,
      "name": "Plant_Leaves_Giantwood"
    },
    {
      "x": -52,
      "y": 203,
      "z": 1,
      "name": "Plant_Leaves_Giantwood"
    },
    {
      "x": -52,
      "y": 203,
      "z": 2,
      "name": "Plant_Leaves_Giantwood"
    },
    {
      "x": -52,
      "y": 197,
      "z": 3,
      "name": "Plant_Leaves_Giantwood"
    },
    {
      "x": -52,
      "y": 204,
      "z": 3,
      "name": "Plant_Leaves_Giantwood"
    },
    {
      "x": -52,
      "y": 205,
      "z": 3,
      "name": "Plant_Leaves_Giantwood"
    },
    {
      "x": -52,
      "y": 198,
      "z": 4,
      "name": "Plant_Leaves_Giantwood"
    },
    {
      "x": -52,
      "y": 204,
      "z": 4,
      "name": "Plant_Leaves_Giantwood"
    },
    {
      "x": -52,
      "y": 199,
      "z": 5,
      "name": "Plant_Leaves_Giantwood"
    },
    {
      "x": -52,
      "y": 206,
      "z": 5,
      "name": "Plant_Leaves_Giantwood"
    },
    {
      "x": -52,
      "y": 197,
      "z": 6,
      "name": "Plant_Leaves_Giantwood"
    },
    {
      "x": -52,
      "y": 198,
      "z": 6,
      "name": "Plant_Leaves_Giantwood"
    },
    {
      "x": -52,
      "y": 201,
      "z": 6,
      "name": "Plant_Leaves_Giantwood"
    },
    {
      "x": -52,
      "y": 203,
      "z": 6,
      "name": "Plant_Leaves_Giantwood"
    },
    {
      "x": -52,
      "y": 205,
      "z": 6,
      "name": "Plant_Leaves_Giantwood"
    },
    {
      "x": -52,
      "y": 197,
      "z": 7,
      "name": "Plant_Leaves_Giantwood"
    },
    {
      "x": -52,
      "y": 199,
      "z": 7,
      "name": "Plant_Leaves_Giantwood"
    },
    {
      "x": -52,
      "y": 203,
      "z": 7,
      "name": "Plant_Leaves_Giantwood"
    },
    {
      "x": -52,
      "y": 206,
      "z": 7,
      "name": "Plant_Leaves_Giantwood"
    },
    {
      "x": -52,
      "y": 200,
      "z": 8,
      "name": "Plant_Leaves_Giantwood"
    },
    {
      "x": -52,
      "y": 201,
      "z": 8,
      "name": "Plant_Leaves_Giantwood"
    },
    {
      "x": -52,
      "y": 203,
      "z": 8,
      "name": "Plant_Leaves_Giantwood"
    },
    {
      "x": -52,
      "y": 204,
      "z": 8,
      "name": "Plant_Leaves_Giantwood"
    },
    {
      "x": -52,
      "y": 199,
      "z": 9,
      "name": "Plant_Leaves_Giantwood"
    },
    {
      "x": -52,
      "y": 202,
      "z": 9,
      "name": "Plant_Leaves_Giantwood"
    },
    {
      "x": -52,
      "y": 198,
      "z": 11,
      "name": "Plant_Leaves_Giantwood"
    },
    {
      "x": -52,
      "y": 199,
      "z": 11,
      "name": "Plant_Leaves_Giantwood"
    },
    {
      "x": -52,
      "y": 202,
      "z": 12,
      "name": "Plant_Leaves_Giantwood"
    },
    {
      "x": -52,
      "y": 201,
      "z": 13,
      "name": "Plant_Leaves_Giantwood"
    },
    {
      "x": -52,
      "y": 204,
      "z": 13,
      "name": "Plant_Leaves_Giantwood"
    },
    {
      "x": -52,
      "y": 198,
      "z": 29,
      "name": "Plant_Leaves_Giantwood"
    },
    {
      "x": -52,
      "y": 199,
      "z": 29,
      "name": "Plant_Leaves_Giantwood"
    },
    {
      "x": -52,
      "y": 198,
      "z": 30,
      "name": "Plant_Leaves_Giantwood"
    },
    {
      "x": -52,
      "y": 199,
      "z": 30,
      "name": "Plant_Leaves_Giantwood"
    },
    {
      "x": -52,
      "y": 199,
      "z": 31,
      "name": "Plant_Leaves_Giantwood"
    },
    {
      "x": -52,
      "y": 199,
      "z": 32,
      "name": "Plant_Leaves_Giantwood"
    },
    {
      "x": -52,
      "y": 200,
      "z": 34,
      "name": "Plant_Leaves_Giantwood"
    },
    {
      "x": -51,
      "y": 204,
      "z": -22,
      "name": "Plant_Leaves_Giantwood"
    },
    {
      "x": -51,
      "y": 205,
      "z": -21,
      "name": "Plant_Leaves_Giantwood"
    },
    {
      "x": -51,
      "y": 204,
      "z": -19,
      "name": "Plant_Leaves_Giantwood"
    },
    {
      "x": -51,
      "y": 205,
      "z": -19,
      "name": "Plant_Leaves_Giantwood"
    },
    {
      "x": -51,
      "y": 203,
      "z": -18,
      "name": "Plant_Leaves_Giantwood"
    },
    {
      "x": -51,
      "y": 205,
      "z": -18,
      "name": "Plant_Leaves_Giantwood"
    },
    {
      "x": -51,
      "y": 205,
      "z": -17,
      "name": "Plant_Leaves_Giantwood"
    },
    {
      "x": -51,
      "y": 206,
      "z": -17,
      "name": "Plant_Leaves_Giantwood"
    },
    {
      "x": -51,
      "y": 200,
      "z": -15,
      "name": "Plant_Leaves_Giantwood"
    },
    {
      "x": -51,
      "y": 204,
      "z": -15,
      "name": "Plant_Leaves_Giantwood"
    },
    {
      "x": -51,
      "y": 205,
      "z": -15,
      "name": "Plant_Leaves_Giantwood"
    },
    {
      "x": -51,
      "y": 201,
      "z": -14,
      "name": "Plant_Leaves_Giantwood"
    },
    {
      "x": -51,
      "y": 202,
      "z": -14,
      "name": "Plant_Leaves_Giantwood"
    },
    {
      "x": -51,
      "y": 203,
      "z": -14,
      "name": "Plant_Leaves_Giantwood"
    },
    {
      "x": -51,
      "y": 205,
      "z": -14,
      "name": "Plant_Leaves_Giantwood"
    },
    {
      "x": -51,
      "y": 203,
      "z": -12,
      "name": "Plant_Leaves_Giantwood"
    },
    {
      "x": -51,
      "y": 206,
      "z": -12,
      "name": "Plant_Leaves_Giantwood"
    },
    {
      "x": -51,
      "y": 204,
      "z": -11,
      "name": "Plant_Leaves_Giantwood"
    },
    {
      "x": -51,
      "y": 206,
      "z": -11,
      "name": "Plant_Leaves_Giantwood"
    },
    {
      "x": -51,
      "y": 201,
      "z": -9,
      "name": "Plant_Leaves_Giantwood"
    },
    {
      "x": -51,
      "y": 203,
      "z": -9,
      "name": "Plant_Leaves_Giantwood"
    },
    {
      "x": -51,
      "y": 205,
      "z": -9,
      "name": "Plant_Leaves_Giantwood"
    },
    {
      "x": -51,
      "y": 206,
      "z": -9,
      "name": "Plant_Leaves_Giantwood"
    },
    {
      "x": -51,
      "y": 201,
      "z": -8,
      "name": "Plant_Leaves_Giantwood"
    },
    {
      "x": -51,
      "y": 206,
      "z": -8,
      "name": "Plant_Leaves_Giantwood"
    },
    {
      "x": -51,
      "y": 198,
      "z": -7,
      "name": "Plant_Leaves_Giantwood"
    },
    {
      "x": -51,
      "y": 204,
      "z": -7,
      "name": "Plant_Leaves_Giantwood"
    },
    {
      "x": -51,
      "y": 198,
      "z": -6,
      "name": "Plant_Leaves_Giantwood"
    },
    {
      "x": -51,
      "y": 204,
      "z": -5,
      "name": "Plant_Leaves_Giantwood"
    },
    {
      "x": -51,
      "y": 205,
      "z": -5,
      "name": "Plant_Leaves_Giantwood"
    },
    {
      "x": -51,
      "y": 199,
      "z": -4,
      "name": "Plant_Leaves_Giantwood"
    },
    {
      "x": -51,
      "y": 201,
      "z": -4,
      "name": "Plant_Leaves_Giantwood"
    },
    {
      "x": -51,
      "y": 203,
      "z": -4,
      "name": "Plant_Leaves_Giantwood"
    },
    {
      "x": -51,
      "y": 205,
      "z": -4,
      "name": "Plant_Leaves_Giantwood"
    },
    {
      "x": -51,
      "y": 199,
      "z": -3,
      "name": "Plant_Leaves_Giantwood"
    },
    {
      "x": -51,
      "y": 201,
      "z": -2,
      "name": "Plant_Leaves_Giantwood"
    },
    {
      "x": -51,
      "y": 206,
      "z": -2,
      "name": "Plant_Leaves_Giantwood"
    },
    {
      "x": -51,
      "y": 200,
      "z": -1,
      "name": "Plant_Leaves_Giantwood"
    },
    {
      "x": -51,
      "y": 203,
      "z": -1,
      "name": "Plant_Leaves_Giantwood"
    },
    {
      "x": -51,
      "y": 204,
      "z": -1,
      "name": "Plant_Leaves_Giantwood"
    },
    {
      "x": -51,
      "y": 206,
      "z": 0,
      "name": "Plant_Leaves_Giantwood"
    },
    {
      "x": -51,
      "y": 198,
      "z": 1,
      "name": "Plant_Leaves_Giantwood"
    },
    {
      "x": -51,
      "y": 202,
      "z": 1,
      "name": "Plant_Leaves_Giantwood"
    },
    {
      "x": -51,
      "y": 204,
      "z": 1,
      "name": "Plant_Leaves_Giantwood"
    },
    {
      "x": -51,
      "y": 197,
      "z": 2,
      "name": "Plant_Leaves_Giantwood"
    },
    {
      "x": -51,
      "y": 198,
      "z": 2,
      "name": "Plant_Leaves_Giantwood"
    },
    {
      "x": -51,
      "y": 201,
      "z": 2,
      "name": "Plant_Leaves_Giantwood"
    },
    {
      "x": -51,
      "y": 204,
      "z": 2,
      "name": "Plant_Leaves_Giantwood"
    },
    {
      "x": -51,
      "y": 200,
      "z": 3,
      "name": "Plant_Leaves_Giantwood"
    },
    {
      "x": -51,
      "y": 202,
      "z": 3,
      "name": "Plant_Leaves_Giantwood"
    },
    {
      "x": -51,
      "y": 205,
      "z": 3,
      "name": "Plant_Leaves_Giantwood"
    },
    {
      "x": -51,
      "y": 201,
      "z": 4,
      "name": "Plant_Leaves_Giantwood"
    },
    {
      "x": -51,
      "y": 206,
      "z": 4,
      "name": "Plant_Leaves_Giantwood"
    },
    {
      "x": -51,
      "y": 200,
      "z": 5,
      "name": "Plant_Leaves_Giantwood"
    },
    {
      "x": -51,
      "y": 204,
      "z": 5,
      "name": "Plant_Leaves_Giantwood"
    },
    {
      "x": -51,
      "y": 201,
      "z": 6,
      "name": "Plant_Leaves_Giantwood"
    },
    {
      "x": -51,
      "y": 197,
      "z": 7,
      "name": "Plant_Leaves_Giantwood"
    },
    {
      "x": -51,
      "y": 198,
      "z": 7,
      "name": "Plant_Leaves_Giantwood"
    },
    {
      "x": -51,
      "y": 199,
      "z": 7,
      "name": "Plant_Leaves_Giantwood"
    },
    {
      "x": -51,
      "y": 201,
      "z": 7,
      "name": "Plant_Leaves_Giantwood"
    },
    {
      "x": -51,
      "y": 203,
      "z": 7,
      "name": "Plant_Leaves_Giantwood"
    },
    {
      "x": -51,
      "y": 205,
      "z": 7,
      "name": "Plant_Leaves_Giantwood"
    },
    {
      "x": -51,
      "y": 206,
      "z": 7,
      "name": "Plant_Leaves_Giantwood"
    },
    {
      "x": -51,
      "y": 197,
      "z": 8,
      "name": "Plant_Leaves_Giantwood"
    },
    {
      "x": -51,
      "y": 200,
      "z": 8,
      "name": "Plant_Leaves_Giantwood"
    },
    {
      "x": -51,
      "y": 205,
      "z": 8,
      "name": "Plant_Leaves_Giantwood"
    },
    {
      "x": -51,
      "y": 198,
      "z": 9,
      "name": "Plant_Leaves_Giantwood"
    },
    {
      "x": -51,
      "y": 202,
      "z": 9,
      "name": "Plant_Leaves_Giantwood"
    },
    {
      "x": -51,
      "y": 203,
      "z": 9,
      "name": "Plant_Leaves_Giantwood"
    },
    {
      "x": -51,
      "y": 198,
      "z": 10,
      "name": "Plant_Leaves_Giantwood"
    },
    {
      "x": -51,
      "y": 201,
      "z": 10,
      "name": "Plant_Leaves_Giantwood"
    },
    {
      "x": -51,
      "y": 202,
      "z": 10,
      "name": "Plant_Leaves_Giantwood"
    },
    {
      "x": -51,
      "y": 198,
      "z": 11,
      "name": "Plant_Leaves_Giantwood"
    },
    {
      "x": -51,
      "y": 200,
      "z": 12,
      "name": "Plant_Leaves_Giantwood"
    },
    {
      "x": -51,
      "y": 200,
      "z": 13,
      "name": "Plant_Leaves_Giantwood"
    },
    {
      "x": -51,
      "y": 203,
      "z": 13,
      "name": "Plant_Leaves_Giantwood"
    },
    {
      "x": -51,
      "y": 200,
      "z": 14,
      "name": "Plant_Leaves_Giantwood"
    },
    {
      "x": -51,
      "y": 201,
      "z": 14,
      "name": "Plant_Leaves_Giantwood"
    },
    {
      "x": -51,
      "y": 199,
      "z": 26,
      "name": "Plant_Leaves_Giantwood"
    },
    {
      "x": -51,
      "y": 197,
      "z": 27,
      "name": "Plant_Leaves_Giantwood"
    },
    {
      "x": -51,
      "y": 198,
      "z": 27,
      "name": "Plant_Leaves_Giantwood"
    },
    {
      "x": -51,
      "y": 197,
      "z": 28,
      "name": "Plant_Leaves_Giantwood"
    },
    {
      "x": -51,
      "y": 199,
      "z": 28,
      "name": "Plant_Leaves_Giantwood"
    },
    {
      "x": -51,
      "y": 199,
      "z": 30,
      "name": "Plant_Leaves_Giantwood"
    },
    {
      "x": -51,
      "y": 198,
      "z": 31,
      "name": "Plant_Leaves_Giantwood"
    },
    {
      "x": -51,
      "y": 197,
      "z": 32,
      "name": "Plant_Leaves_Giantwood"
    },
    {
      "x": -51,
      "y": 200,
      "z": 32,
      "name": "Plant_Leaves_Giantwood"
    },
    {
      "x": -51,
      "y": 197,
      "z": 33,
      "name": "Plant_Leaves_Giantwood"
    },
    {
      "x": -51,
      "y": 198,
      "z": 33,
      "name": "Plant_Leaves_Giantwood"
    },
    {
      "x": -51,
      "y": 199,
      "z": 33,
      "name": "Plant_Leaves_Giantwood"
    },
    {
      "x": -51,
      "y": 200,
      "z": 33,
      "name": "Plant_Leaves_Giantwood"
    },
    {
      "x": -51,
      "y": 201,
      "z": 33,
      "name": "Plant_Leaves_Giantwood"
    },
    {
      "x": -51,
      "y": 199,
      "z": 34,
      "name": "Plant_Leaves_Giantwood"
    },
    {
      "x": -51,
      "y": 201,
      "z": 34,
      "name": "Plant_Leaves_Giantwood"
    },
    {
      "x": -51,
      "y": 199,
      "z": 35,
      "name": "Plant_Leaves_Giantwood"
    },
    {
      "x": -51,
      "y": 197,
      "z": 36,
      "name": "Plant_Leaves_Giantwood"
    },
    {
      "x": -51,
      "y": 199,
      "z": 36,
      "name": "Plant_Leaves_Giantwood"
    },
    {
      "x": -51,
      "y": 200,
      "z": 36,
      "name": "Plant_Leaves_Giantwood"
    },
    {
      "x": -51,
      "y": 197,
      "z": 38,
      "name": "Plant_Leaves_Giantwood"
    },
    {
      "x": -51,
      "y": 200,
      "z": 38,
      "name": "Plant_Leaves_Giantwood"
    },
    {
      "x": -51,
      "y": 198,
      "z": 39,
      "name": "Plant_Leaves_Giantwood"
    },
    {
      "x": -50,
      "y": 204,
      "z": -23,
      "name": "Plant_Leaves_Giantwood"
    },
    {
      "x": -50,
      "y": 205,
      "z": -23,
      "name": "Plant_Leaves_Giantwood"
    },
    {
      "x": -50,
      "y": 203,
      "z": -22,
      "name": "Plant_Leaves_Giantwood"
    },
    {
      "x": -50,
      "y": 205,
      "z": -22,
      "name": "Plant_Leaves_Giantwood"
    },
    {
      "x": -50,
      "y": 203,
      "z": -21,
      "name": "Plant_Leaves_Giantwood"
    },
    {
      "x": -50,
      "y": 205,
      "z": -20,
      "name": "Plant_Leaves_Giantwood"
    },
    {
      "x": -50,
      "y": 204,
      "z": -17,
      "name": "Plant_Leaves_Giantwood"
    },
    {
      "x": -50,
      "y": 204,
      "z": -16,
      "name": "Plant_Leaves_Giantwood"
    },
    {
      "x": -50,
      "y": 199,
      "z": -15,
      "name": "Plant_Leaves_Giantwood"
    },
    {
      "x": -50,
      "y": 201,
      "z": -15,
      "name": "Plant_Leaves_Giantwood"
    },
    {
      "x": -50,
      "y": 207,
      "z": -15,
      "name": "Plant_Leaves_Giantwood"
    },
    {
      "x": -50,
      "y": 199,
      "z": -14,
      "name": "Plant_Leaves_Giantwood"
    },
    {
      "x": -50,
      "y": 203,
      "z": -14,
      "name": "Plant_Leaves_Giantwood"
    },
    {
      "x": -50,
      "y": 205,
      "z": -14,
      "name": "Plant_Leaves_Giantwood"
    },
    {
      "x": -50,
      "y": 206,
      "z": -14,
      "name": "Plant_Leaves_Giantwood"
    },
    {
      "x": -50,
      "y": 199,
      "z": -13,
      "name": "Plant_Leaves_Giantwood"
    },
    {
      "x": -50,
      "y": 200,
      "z": -13,
      "name": "Plant_Leaves_Giantwood"
    },
    {
      "x": -50,
      "y": 202,
      "z": -13,
      "name": "Plant_Leaves_Giantwood"
    },
    {
      "x": -50,
      "y": 203,
      "z": -13,
      "name": "Plant_Leaves_Giantwood"
    },
    {
      "x": -50,
      "y": 199,
      "z": -12,
      "name": "Plant_Leaves_Giantwood"
    },
    {
      "x": -50,
      "y": 200,
      "z": -12,
      "name": "Plant_Leaves_Giantwood"
    },
    {
      "x": -50,
      "y": 205,
      "z": -12,
      "name": "Plant_Leaves_Giantwood"
    },
    {
      "x": -50,
      "y": 207,
      "z": -12,
      "name": "Plant_Leaves_Giantwood"
    },
    {
      "x": -50,
      "y": 198,
      "z": -11,
      "name": "Plant_Leaves_Giantwood"
    },
    {
      "x": -50,
      "y": 199,
      "z": -11,
      "name": "Plant_Leaves_Giantwood"
    },
    {
      "x": -50,
      "y": 202,
      "z": -11,
      "name": "Plant_Leaves_Giantwood"
    },
    {
      "x": -50,
      "y": 203,
      "z": -11,
      "name": "Plant_Leaves_Giantwood"
    },
    {
      "x": -50,
      "y": 207,
      "z": -11,
      "name": "Plant_Leaves_Giantwood"
    },
    {
      "x": -50,
      "y": 200,
      "z": -10,
      "name": "Plant_Leaves_Giantwood"
    },
    {
      "x": -50,
      "y": 206,
      "z": -10,
      "name": "Plant_Leaves_Giantwood"
    },
    {
      "x": -50,
      "y": 197,
      "z": -9,
      "name": "Plant_Leaves_Giantwood"
    },
    {
      "x": -50,
      "y": 201,
      "z": -9,
      "name": "Plant_Leaves_Giantwood"
    },
    {
      "x": -50,
      "y": 203,
      "z": -9,
      "name": "Plant_Leaves_Giantwood"
    },
    {
      "x": -50,
      "y": 206,
      "z": -9,
      "name": "Plant_Leaves_Giantwood"
    },
    {
      "x": -50,
      "y": 197,
      "z": -8,
      "name": "Plant_Leaves_Giantwood"
    },
    {
      "x": -50,
      "y": 198,
      "z": -8,
      "name": "Plant_Leaves_Giantwood"
    },
    {
      "x": -50,
      "y": 201,
      "z": -8,
      "name": "Plant_Leaves_Giantwood"
    },
    {
      "x": -50,
      "y": 204,
      "z": -8,
      "name": "Plant_Leaves_Giantwood"
    },
    {
      "x": -50,
      "y": 199,
      "z": -7,
      "name": "Plant_Leaves_Giantwood"
    },
    {
      "x": -50,
      "y": 203,
      "z": -7,
      "name": "Plant_Leaves_Giantwood"
    },
    {
      "x": -50,
      "y": 199,
      "z": -6,
      "name": "Plant_Leaves_Giantwood"
    },
    {
      "x": -50,
      "y": 203,
      "z": -6,
      "name": "Plant_Leaves_Giantwood"
    },
    {
      "x": -50,
      "y": 197,
      "z": -5,
      "name": "Plant_Leaves_Giantwood"
    },
    {
      "x": -50,
      "y": 198,
      "z": -5,
      "name": "Plant_Leaves_Giantwood"
    },
    {
      "x": -50,
      "y": 202,
      "z": -5,
      "name": "Plant_Leaves_Giantwood"
    },
    {
      "x": -50,
      "y": 205,
      "z": -5,
      "name": "Plant_Leaves_Giantwood"
    },
    {
      "x": -50,
      "y": 198,
      "z": -4,
      "name": "Plant_Leaves_Giantwood"
    },
    {
      "x": -50,
      "y": 202,
      "z": -4,
      "name": "Plant_Leaves_Giantwood"
    },
    {
      "x": -50,
      "y": 198,
      "z": -3,
      "name": "Plant_Leaves_Giantwood"
    },
    {
      "x": -50,
      "y": 200,
      "z": -3,
      "name": "Plant_Leaves_Giantwood"
    },
    {
      "x": -50,
      "y": 201,
      "z": -3,
      "name": "Plant_Leaves_Giantwood"
    },
    {
      "x": -50,
      "y": 205,
      "z": -3,
      "name": "Plant_Leaves_Giantwood"
    },
    {
      "x": -50,
      "y": 206,
      "z": -3,
      "name": "Plant_Leaves_Giantwood"
    },
    {
      "x": -50,
      "y": 197,
      "z": -2,
      "name": "Plant_Leaves_Giantwood"
    },
    {
      "x": -50,
      "y": 198,
      "z": -1,
      "name": "Plant_Leaves_Giantwood"
    },
    {
      "x": -50,
      "y": 199,
      "z": -1,
      "name": "Plant_Leaves_Giantwood"
    },
    {
      "x": -50,
      "y": 202,
      "z": -1,
      "name": "Plant_Leaves_Giantwood"
    },
    {
      "x": -50,
      "y": 203,
      "z": -1,
      "name": "Plant_Leaves_Giantwood"
    },
    {
      "x": -50,
      "y": 204,
      "z": -1,
      "name": "Plant_Leaves_Giantwood"
    },
    {
      "x": -50,
      "y": 197,
      "z": 0,
      "name": "Plant_Leaves_Giantwood"
    },
    {
      "x": -50,
      "y": 204,
      "z": 0,
      "name": "Plant_Leaves_Giantwood"
    },
    {
      "x": -50,
      "y": 205,
      "z": 0,
      "name": "Plant_Leaves_Giantwood"
    },
    {
      "x": -50,
      "y": 206,
      "z": 0,
      "name": "Plant_Leaves_Giantwood"
    },
    {
      "x": -50,
      "y": 199,
      "z": 1,
      "name": "Plant_Leaves_Giantwood"
    },
    {
      "x": -50,
      "y": 200,
      "z": 1,
      "name": "Plant_Leaves_Giantwood"
    },
    {
      "x": -50,
      "y": 205,
      "z": 1,
      "name": "Plant_Leaves_Giantwood"
    },
    {
      "x": -50,
      "y": 200,
      "z": 2,
      "name": "Plant_Leaves_Giantwood"
    },
    {
      "x": -50,
      "y": 201,
      "z": 2,
      "name": "Plant_Leaves_Giantwood"
    },
    {
      "x": -50,
      "y": 202,
      "z": 2,
      "name": "Plant_Leaves_Giantwood"
    },
    {
      "x": -50,
      "y": 203,
      "z": 2,
      "name": "Plant_Leaves_Giantwood"
    },
    {
      "x": -50,
      "y": 200,
      "z": 3,
      "name": "Plant_Leaves_Giantwood"
    },
    {
      "x": -50,
      "y": 205,
      "z": 3,
      "name": "Plant_Leaves_Giantwood"
    },
    {
      "x": -50,
      "y": 203,
      "z": 4,
      "name": "Plant_Leaves_Giantwood"
    },
    {
      "x": -50,
      "y": 197,
      "z": 5,
      "name": "Plant_Leaves_Giantwood"
    },
    {
      "x": -50,
      "y": 200,
      "z": 5,
      "name": "Plant_Leaves_Giantwood"
    },
    {
      "x": -50,
      "y": 202,
      "z": 5,
      "name": "Plant_Leaves_Giantwood"
    },
    {
      "x": -50,
      "y": 198,
      "z": 6,
      "name": "Plant_Leaves_Giantwood"
    },
    {
      "x": -50,
      "y": 199,
      "z": 6,
      "name": "Plant_Leaves_Giantwood"
    },
    {
      "x": -50,
      "y": 200,
      "z": 6,
      "name": "Plant_Leaves_Giantwood"
    },
    {
      "x": -50,
      "y": 201,
      "z": 6,
      "name": "Plant_Leaves_Giantwood"
    },
    {
      "x": -50,
      "y": 203,
      "z": 6,
      "name": "Plant_Leaves_Giantwood"
    },
    {
      "x": -50,
      "y": 199,
      "z": 7,
      "name": "Plant_Leaves_Giantwood"
    },
    {
      "x": -50,
      "y": 200,
      "z": 7,
      "name": "Plant_Leaves_Giantwood"
    },
    {
      "x": -50,
      "y": 202,
      "z": 7,
      "name": "Plant_Leaves_Giantwood"
    },
    {
      "x": -50,
      "y": 199,
      "z": 8,
      "name": "Plant_Leaves_Giantwood"
    },
    {
      "x": -50,
      "y": 201,
      "z": 8,
      "name": "Plant_Leaves_Giantwood"
    },
    {
      "x": -50,
      "y": 203,
      "z": 8,
      "name": "Plant_Leaves_Giantwood"
    },
    {
      "x": -50,
      "y": 205,
      "z": 8,
      "name": "Plant_Leaves_Giantwood"
    },
    {
      "x": -50,
      "y": 200,
      "z": 9,
      "name": "Plant_Leaves_Giantwood"
    },
    {
      "x": -50,
      "y": 201,
      "z": 9,
      "name": "Plant_Leaves_Giantwood"
    },
    {
      "x": -50,
      "y": 205,
      "z": 9,
      "name": "Plant_Leaves_Giantwood"
    },
    {
      "x": -50,
      "y": 199,
      "z": 11,
      "name": "Plant_Leaves_Giantwood"
    },
    {
      "x": -50,
      "y": 200,
      "z": 11,
      "name": "Plant_Leaves_Giantwood"
    },
    {
      "x": -50,
      "y": 201,
      "z": 12,
      "name": "Plant_Leaves_Giantwood"
    },
    {
      "x": -50,
      "y": 202,
      "z": 12,
      "name": "Plant_Leaves_Giantwood"
    },
    {
      "x": -50,
      "y": 205,
      "z": 12,
      "name": "Plant_Leaves_Giantwood"
    },
    {
      "x": -50,
      "y": 200,
      "z": 13,
      "name": "Plant_Leaves_Giantwood"
    },
    {
      "x": -50,
      "y": 201,
      "z": 13,
      "name": "Plant_Leaves_Giantwood"
    },
    {
      "x": -50,
      "y": 204,
      "z": 13,
      "name": "Plant_Leaves_Giantwood"
    },
    {
      "x": -50,
      "y": 200,
      "z": 14,
      "name": "Plant_Leaves_Giantwood"
    },
    {
      "x": -50,
      "y": 201,
      "z": 14,
      "name": "Plant_Leaves_Giantwood"
    },
    {
      "x": -50,
      "y": 202,
      "z": 14,
      "name": "Plant_Leaves_Giantwood"
    },
    {
      "x": -50,
      "y": 200,
      "z": 25,
      "name": "Plant_Leaves_Giantwood"
    },
    {
      "x": -50,
      "y": 197,
      "z": 26,
      "name": "Plant_Leaves_Giantwood"
    },
    {
      "x": -50,
      "y": 198,
      "z": 28,
      "name": "Plant_Leaves_Giantwood"
    },
    {
      "x": -50,
      "y": 199,
      "z": 28,
      "name": "Plant_Leaves_Giantwood"
    },
    {
      "x": -50,
      "y": 199,
      "z": 29,
      "name": "Plant_Leaves_Giantwood"
    },
    {
      "x": -50,
      "y": 201,
      "z": 30,
      "name": "Plant_Leaves_Giantwood"
    },
    {
      "x": -50,
      "y": 196,
      "z": 31,
      "name": "Plant_Leaves_Giantwood"
    },
    {
      "x": -50,
      "y": 197,
      "z": 31,
      "name": "Plant_Leaves_Giantwood"
    },
    {
      "x": -50,
      "y": 200,
      "z": 32,
      "name": "Plant_Leaves_Giantwood"
    },
    {
      "x": -50,
      "y": 201,
      "z": 32,
      "name": "Plant_Leaves_Giantwood"
    },
    {
      "x": -50,
      "y": 197,
      "z": 33,
      "name": "Plant_Leaves_Giantwood"
    },
    {
      "x": -50,
      "y": 200,
      "z": 33,
      "name": "Plant_Leaves_Giantwood"
    },
    {
      "x": -50,
      "y": 196,
      "z": 34,
      "name": "Plant_Leaves_Giantwood"
    },
    {
      "x": -50,
      "y": 201,
      "z": 34,
      "name": "Plant_Leaves_Giantwood"
    },
    {
      "x": -50,
      "y": 198,
      "z": 35,
      "name": "Plant_Leaves_Giantwood"
    },
    {
      "x": -50,
      "y": 200,
      "z": 35,
      "name": "Plant_Leaves_Giantwood"
    },
    {
      "x": -50,
      "y": 199,
      "z": 36,
      "name": "Plant_Leaves_Giantwood"
    },
    {
      "x": -50,
      "y": 199,
      "z": 38,
      "name": "Plant_Leaves_Giantwood"
    },
    {
      "x": -50,
      "y": 201,
      "z": 38,
      "name": "Plant_Leaves_Giantwood"
    },
    {
      "x": -50,
      "y": 200,
      "z": 39,
      "name": "Plant_Leaves_Giantwood"
    },
    {
      "x": -50,
      "y": 200,
      "z": 41,
      "name": "Plant_Leaves_Giantwood"
    },
    {
      "x": -49,
      "y": 205,
      "z": -24,
      "name": "Plant_Leaves_Giantwood"
    },
    {
      "x": -49,
      "y": 202,
      "z": -21,
      "name": "Plant_Leaves_Giantwood"
    },
    {
      "x": -49,
      "y": 203,
      "z": -21,
      "name": "Plant_Leaves_Giantwood"
    },
    {
      "x": -49,
      "y": 204,
      "z": -20,
      "name": "Plant_Leaves_Giantwood"
    },
    {
      "x": -49,
      "y": 203,
      "z": -19,
      "name": "Plant_Leaves_Giantwood"
    },
    {
      "x": -49,
      "y": 200,
      "z": -18,
      "name": "Plant_Leaves_Giantwood"
    },
    {
      "x": -49,
      "y": 201,
      "z": -18,
      "name": "Plant_Leaves_Giantwood"
    },
    {
      "x": -49,
      "y": 204,
      "z": -18,
      "name": "Plant_Leaves_Giantwood"
    },
    {
      "x": -49,
      "y": 199,
      "z": -17,
      "name": "Plant_Leaves_Giantwood"
    },
    {
      "x": -49,
      "y": 200,
      "z": -17,
      "name": "Plant_Leaves_Giantwood"
    },
    {
      "x": -49,
      "y": 203,
      "z": -17,
      "name": "Plant_Leaves_Giantwood"
    },
    {
      "x": -49,
      "y": 206,
      "z": -17,
      "name": "Plant_Leaves_Giantwood"
    },
    {
      "x": -49,
      "y": 199,
      "z": -16,
      "name": "Plant_Leaves_Giantwood"
    },
    {
      "x": -49,
      "y": 207,
      "z": -16,
      "name": "Plant_Leaves_Giantwood"
    },
    {
      "x": -49,
      "y": 205,
      "z": -15,
      "name": "Plant_Leaves_Giantwood"
    },
    {
      "x": -49,
      "y": 206,
      "z": -15,
      "name": "Plant_Leaves_Giantwood"
    },
    {
      "x": -49,
      "y": 198,
      "z": -14,
      "name": "Plant_Leaves_Giantwood"
    },
    {
      "x": -49,
      "y": 200,
      "z": -14,
      "name": "Plant_Leaves_Giantwood"
    },
    {
      "x": -49,
      "y": 203,
      "z": -14,
      "name": "Plant_Leaves_Giantwood"
    },
    {
      "x": -49,
      "y": 204,
      "z": -14,
      "name": "Plant_Leaves_Giantwood"
    },
    {
      "x": -49,
      "y": 206,
      "z": -14,
      "name": "Plant_Leaves_Giantwood"
    },
    {
      "x": -49,
      "y": 200,
      "z": -13,
      "name": "Plant_Leaves_Giantwood"
    },
    {
      "x": -49,
      "y": 201,
      "z": -13,
      "name": "Plant_Leaves_Giantwood"
    },
    {
      "x": -49,
      "y": 204,
      "z": -13,
      "name": "Plant_Leaves_Giantwood"
    },
    {
      "x": -49,
      "y": 198,
      "z": -12,
      "name": "Plant_Leaves_Giantwood"
    },
    {
      "x": -49,
      "y": 199,
      "z": -12,
      "name": "Plant_Leaves_Giantwood"
    },
    {
      "x": -49,
      "y": 200,
      "z": -12,
      "name": "Plant_Leaves_Giantwood"
    },
    {
      "x": -49,
      "y": 202,
      "z": -12,
      "name": "Plant_Leaves_Giantwood"
    },
    {
      "x": -49,
      "y": 203,
      "z": -11,
      "name": "Plant_Leaves_Giantwood"
    },
    {
      "x": -49,
      "y": 205,
      "z": -11,
      "name": "Plant_Leaves_Giantwood"
    },
    {
      "x": -49,
      "y": 207,
      "z": -11,
      "name": "Plant_Leaves_Giantwood"
    },
    {
      "x": -49,
      "y": 202,
      "z": -10,
      "name": "Plant_Leaves_Giantwood"
    },
    {
      "x": -49,
      "y": 203,
      "z": -10,
      "name": "Plant_Leaves_Giantwood"
    },
    {
      "x": -49,
      "y": 206,
      "z": -10,
      "name": "Plant_Leaves_Giantwood"
    },
    {
      "x": -49,
      "y": 207,
      "z": -10,
      "name": "Plant_Leaves_Giantwood"
    },
    {
      "x": -49,
      "y": 200,
      "z": -9,
      "name": "Plant_Leaves_Giantwood"
    },
    {
      "x": -49,
      "y": 202,
      "z": -9,
      "name": "Plant_Leaves_Giantwood"
    },
    {
      "x": -49,
      "y": 203,
      "z": -9,
      "name": "Plant_Leaves_Giantwood"
    },
    {
      "x": -49,
      "y": 197,
      "z": -8,
      "name": "Plant_Leaves_Giantwood"
    },
    {
      "x": -49,
      "y": 198,
      "z": -8,
      "name": "Plant_Leaves_Giantwood"
    },
    {
      "x": -49,
      "y": 200,
      "z": -8,
      "name": "Plant_Leaves_Giantwood"
    },
    {
      "x": -49,
      "y": 201,
      "z": -8,
      "name": "Plant_Leaves_Giantwood"
    },
    {
      "x": -49,
      "y": 202,
      "z": -8,
      "name": "Plant_Leaves_Giantwood"
    },
    {
      "x": -49,
      "y": 203,
      "z": -8,
      "name": "Plant_Leaves_Giantwood"
    },
    {
      "x": -49,
      "y": 204,
      "z": -8,
      "name": "Plant_Leaves_Giantwood"
    },
    {
      "x": -49,
      "y": 204,
      "z": -7,
      "name": "Plant_Leaves_Giantwood"
    },
    {
      "x": -49,
      "y": 205,
      "z": -7,
      "name": "Plant_Leaves_Giantwood"
    },
    {
      "x": -49,
      "y": 207,
      "z": -7,
      "name": "Plant_Leaves_Giantwood"
    },
    {
      "x": -49,
      "y": 197,
      "z": -6,
      "name": "Plant_Leaves_Giantwood"
    },
    {
      "x": -49,
      "y": 198,
      "z": -6,
      "name": "Plant_Leaves_Giantwood"
    },
    {
      "x": -49,
      "y": 201,
      "z": -6,
      "name": "Plant_Leaves_Giantwood"
    },
    {
      "x": -49,
      "y": 198,
      "z": -5,
      "name": "Plant_Leaves_Giantwood"
    },
    {
      "x": -49,
      "y": 204,
      "z": -5,
      "name": "Plant_Leaves_Giantwood"
    },
    {
      "x": -49,
      "y": 205,
      "z": -5,
      "name": "Plant_Leaves_Giantwood"
    },
    {
      "x": -49,
      "y": 200,
      "z": -4,
      "name": "Plant_Leaves_Giantwood"
    },
    {
      "x": -49,
      "y": 204,
      "z": -4,
      "name": "Plant_Leaves_Giantwood"
    },
    {
      "x": -49,
      "y": 206,
      "z": -4,
      "name": "Plant_Leaves_Giantwood"
    },
    {
      "x": -49,
      "y": 205,
      "z": -3,
      "name": "Plant_Leaves_Giantwood"
    },
    {
      "x": -49,
      "y": 197,
      "z": -2,
      "name": "Plant_Leaves_Giantwood"
    },
    {
      "x": -49,
      "y": 202,
      "z": -2,
      "name": "Plant_Leaves_Giantwood"
    },
    {
      "x": -49,
      "y": 197,
      "z": -1,
      "name": "Plant_Leaves_Giantwood"
    },
    {
      "x": -49,
      "y": 198,
      "z": -1,
      "name": "Plant_Leaves_Giantwood"
    },
    {
      "x": -49,
      "y": 197,
      "z": 0,
      "name": "Plant_Leaves_Giantwood"
    },
    {
      "x": -49,
      "y": 198,
      "z": 0,
      "name": "Plant_Leaves_Giantwood"
    },
    {
      "x": -49,
      "y": 202,
      "z": 0,
      "name": "Plant_Leaves_Giantwood"
    },
    {
      "x": -49,
      "y": 206,
      "z": 0,
      "name": "Plant_Leaves_Giantwood"
    },
    {
      "x": -49,
      "y": 197,
      "z": 1,
      "name": "Plant_Leaves_Giantwood"
    },
    {
      "x": -49,
      "y": 198,
      "z": 1,
      "name": "Plant_Leaves_Giantwood"
    },
    {
      "x": -49,
      "y": 199,
      "z": 1,
      "name": "Plant_Leaves_Giantwood"
    },
    {
      "x": -49,
      "y": 202,
      "z": 1,
      "name": "Plant_Leaves_Giantwood"
    },
    {
      "x": -49,
      "y": 205,
      "z": 2,
      "name": "Plant_Leaves_Giantwood"
    },
    {
      "x": -49,
      "y": 199,
      "z": 3,
      "name": "Plant_Leaves_Giantwood"
    },
    {
      "x": -49,
      "y": 205,
      "z": 3,
      "name": "Plant_Leaves_Giantwood"
    },
    {
      "x": -49,
      "y": 206,
      "z": 3,
      "name": "Plant_Leaves_Giantwood"
    },
    {
      "x": -49,
      "y": 198,
      "z": 4,
      "name": "Plant_Leaves_Giantwood"
    },
    {
      "x": -49,
      "y": 200,
      "z": 4,
      "name": "Plant_Leaves_Giantwood"
    },
    {
      "x": -49,
      "y": 203,
      "z": 4,
      "name": "Plant_Leaves_Giantwood"
    },
    {
      "x": -49,
      "y": 197,
      "z": 5,
      "name": "Plant_Leaves_Giantwood"
    },
    {
      "x": -49,
      "y": 198,
      "z": 5,
      "name": "Plant_Leaves_Giantwood"
    },
    {
      "x": -49,
      "y": 201,
      "z": 5,
      "name": "Plant_Leaves_Giantwood"
    },
    {
      "x": -49,
      "y": 205,
      "z": 5,
      "name": "Plant_Leaves_Giantwood"
    },
    {
      "x": -49,
      "y": 197,
      "z": 6,
      "name": "Plant_Leaves_Giantwood"
    },
    {
      "x": -49,
      "y": 198,
      "z": 6,
      "name": "Plant_Leaves_Giantwood"
    },
    {
      "x": -49,
      "y": 200,
      "z": 6,
      "name": "Plant_Leaves_Giantwood"
    },
    {
      "x": -49,
      "y": 203,
      "z": 6,
      "name": "Plant_Leaves_Giantwood"
    },
    {
      "x": -49,
      "y": 205,
      "z": 6,
      "name": "Plant_Leaves_Giantwood"
    },
    {
      "x": -49,
      "y": 206,
      "z": 6,
      "name": "Plant_Leaves_Giantwood"
    },
    {
      "x": -49,
      "y": 197,
      "z": 7,
      "name": "Plant_Leaves_Giantwood"
    },
    {
      "x": -49,
      "y": 198,
      "z": 7,
      "name": "Plant_Leaves_Giantwood"
    },
    {
      "x": -49,
      "y": 199,
      "z": 7,
      "name": "Plant_Leaves_Giantwood"
    },
    {
      "x": -49,
      "y": 200,
      "z": 7,
      "name": "Plant_Leaves_Giantwood"
    },
    {
      "x": -49,
      "y": 203,
      "z": 7,
      "name": "Plant_Leaves_Giantwood"
    },
    {
      "x": -49,
      "y": 204,
      "z": 7,
      "name": "Plant_Leaves_Giantwood"
    },
    {
      "x": -49,
      "y": 204,
      "z": 8,
      "name": "Plant_Leaves_Giantwood"
    },
    {
      "x": -49,
      "y": 205,
      "z": 8,
      "name": "Plant_Leaves_Giantwood"
    },
    {
      "x": -49,
      "y": 197,
      "z": 9,
      "name": "Plant_Leaves_Giantwood"
    },
    {
      "x": -49,
      "y": 206,
      "z": 9,
      "name": "Plant_Leaves_Giantwood"
    },
    {
      "x": -49,
      "y": 200,
      "z": 10,
      "name": "Plant_Leaves_Giantwood"
    },
    {
      "x": -49,
      "y": 202,
      "z": 10,
      "name": "Plant_Leaves_Giantwood"
    },
    {
      "x": -49,
      "y": 203,
      "z": 10,
      "name": "Plant_Leaves_Giantwood"
    },
    {
      "x": -49,
      "y": 198,
      "z": 11,
      "name": "Plant_Leaves_Giantwood"
    },
    {
      "x": -49,
      "y": 204,
      "z": 11,
      "name": "Plant_Leaves_Giantwood"
    },
    {
      "x": -49,
      "y": 205,
      "z": 11,
      "name": "Plant_Leaves_Giantwood"
    },
    {
      "x": -49,
      "y": 203,
      "z": 12,
      "name": "Plant_Leaves_Giantwood"
    },
    {
      "x": -49,
      "y": 200,
      "z": 13,
      "name": "Plant_Leaves_Giantwood"
    },
    {
      "x": -49,
      "y": 200,
      "z": 14,
      "name": "Plant_Leaves_Giantwood"
    },
    {
      "x": -49,
      "y": 201,
      "z": 15,
      "name": "Plant_Leaves_Giantwood"
    },
    {
      "x": -49,
      "y": 197,
      "z": 27,
      "name": "Plant_Leaves_Giantwood"
    },
    {
      "x": -49,
      "y": 196,
      "z": 28,
      "name": "Plant_Leaves_Giantwood"
    },
    {
      "x": -49,
      "y": 199,
      "z": 28,
      "name": "Plant_Leaves_Giantwood"
    },
    {
      "x": -49,
      "y": 198,
      "z": 29,
      "name": "Plant_Leaves_Giantwood"
    },
    {
      "x": -49,
      "y": 201,
      "z": 29,
      "name": "Plant_Leaves_Giantwood"
    },
    {
      "x": -49,
      "y": 199,
      "z": 30,
      "name": "Plant_Leaves_Giantwood"
    },
    {
      "x": -49,
      "y": 195,
      "z": 31,
      "name": "Plant_Leaves_Giantwood"
    },
    {
      "x": -49,
      "y": 197,
      "z": 31,
      "name": "Plant_Leaves_Giantwood"
    },
    {
      "x": -49,
      "y": 201,
      "z": 31,
      "name": "Plant_Leaves_Giantwood"
    },
    {
      "x": -49,
      "y": 202,
      "z": 31,
      "name": "Plant_Leaves_Giantwood"
    },
    {
      "x": -49,
      "y": 197,
      "z": 32,
      "name": "Plant_Leaves_Giantwood"
    },
    {
      "x": -49,
      "y": 195,
      "z": 33,
      "name": "Plant_Leaves_Giantwood"
    },
    {
      "x": -49,
      "y": 200,
      "z": 33,
      "name": "Plant_Leaves_Giantwood"
    },
    {
      "x": -49,
      "y": 202,
      "z": 33,
      "name": "Plant_Leaves_Giantwood"
    },
    {
      "x": -49,
      "y": 195,
      "z": 34,
      "name": "Plant_Leaves_Giantwood"
    },
    {
      "x": -49,
      "y": 199,
      "z": 34,
      "name": "Plant_Leaves_Giantwood"
    },
    {
      "x": -49,
      "y": 200,
      "z": 34,
      "name": "Plant_Leaves_Giantwood"
    },
    {
      "x": -49,
      "y": 202,
      "z": 34,
      "name": "Plant_Leaves_Giantwood"
    },
    {
      "x": -49,
      "y": 196,
      "z": 35,
      "name": "Plant_Leaves_Giantwood"
    },
    {
      "x": -49,
      "y": 197,
      "z": 35,
      "name": "Plant_Leaves_Giantwood"
    },
    {
      "x": -49,
      "y": 199,
      "z": 35,
      "name": "Plant_Leaves_Giantwood"
    },
    {
      "x": -49,
      "y": 200,
      "z": 35,
      "name": "Plant_Leaves_Giantwood"
    },
    {
      "x": -49,
      "y": 202,
      "z": 35,
      "name": "Plant_Leaves_Giantwood"
    },
    {
      "x": -49,
      "y": 197,
      "z": 36,
      "name": "Plant_Leaves_Giantwood"
    },
    {
      "x": -49,
      "y": 196,
      "z": 37,
      "name": "Plant_Leaves_Giantwood"
    },
    {
      "x": -49,
      "y": 197,
      "z": 37,
      "name": "Plant_Leaves_Giantwood"
    },
    {
      "x": -49,
      "y": 197,
      "z": 38,
      "name": "Plant_Leaves_Giantwood"
    },
    {
      "x": -49,
      "y": 197,
      "z": 39,
      "name": "Plant_Leaves_Giantwood"
    },
    {
      "x": -49,
      "y": 199,
      "z": 40,
      "name": "Plant_Leaves_Giantwood"
    },
    {
      "x": -49,
      "y": 198,
      "z": 41,
      "name": "Plant_Leaves_Giantwood"
    },
    {
      "x": -49,
      "y": 201,
      "z": 41,
      "name": "Plant_Leaves_Giantwood"
    },
    {
      "x": -49,
      "y": 198,
      "z": 42,
      "name": "Plant_Leaves_Giantwood"
    },
    {
      "x": -49,
      "y": 200,
      "z": 42,
      "name": "Plant_Leaves_Giantwood"
    },
    {
      "x": -49,
      "y": 199,
      "z": 43,
      "name": "Plant_Leaves_Giantwood"
    },
    {
      "x": -48,
      "y": 202,
      "z": -22,
      "name": "Plant_Leaves_Giantwood"
    },
    {
      "x": -48,
      "y": 205,
      "z": -22,
      "name": "Plant_Leaves_Giantwood"
    },
    {
      "x": -48,
      "y": 205,
      "z": -21,
      "name": "Plant_Leaves_Giantwood"
    },
    {
      "x": -48,
      "y": 203,
      "z": -20,
      "name": "Plant_Leaves_Giantwood"
    },
    {
      "x": -48,
      "y": 204,
      "z": -20,
      "name": "Plant_Leaves_Giantwood"
    },
    {
      "x": -48,
      "y": 203,
      "z": -19,
      "name": "Plant_Leaves_Giantwood"
    },
    {
      "x": -48,
      "y": 203,
      "z": -18,
      "name": "Plant_Leaves_Giantwood"
    },
    {
      "x": -48,
      "y": 207,
      "z": -17,
      "name": "Plant_Leaves_Giantwood"
    },
    {
      "x": -48,
      "y": 199,
      "z": -16,
      "name": "Plant_Leaves_Giantwood"
    },
    {
      "x": -48,
      "y": 202,
      "z": -16,
      "name": "Plant_Leaves_Giantwood"
    },
    {
      "x": -48,
      "y": 208,
      "z": -16,
      "name": "Plant_Leaves_Giantwood"
    },
    {
      "x": -48,
      "y": 199,
      "z": -15,
      "name": "Plant_Leaves_Giantwood"
    },
    {
      "x": -48,
      "y": 200,
      "z": -15,
      "name": "Plant_Leaves_Giantwood"
    },
    {
      "x": -48,
      "y": 203,
      "z": -15,
      "name": "Plant_Leaves_Giantwood"
    },
    {
      "x": -48,
      "y": 206,
      "z": -15,
      "name": "Plant_Leaves_Giantwood"
    },
    {
      "x": -48,
      "y": 207,
      "z": -15,
      "name": "Plant_Leaves_Giantwood"
    },
    {
      "x": -48,
      "y": 206,
      "z": -14,
      "name": "Plant_Leaves_Giantwood"
    },
    {
      "x": -48,
      "y": 198,
      "z": -13,
      "name": "Plant_Leaves_Giantwood"
    },
    {
      "x": -48,
      "y": 202,
      "z": -13,
      "name": "Plant_Leaves_Giantwood"
    },
    {
      "x": -48,
      "y": 204,
      "z": -13,
      "name": "Plant_Leaves_Giantwood"
    },
    {
      "x": -48,
      "y": 206,
      "z": -13,
      "name": "Plant_Leaves_Giantwood"
    },
    {
      "x": -48,
      "y": 207,
      "z": -13,
      "name": "Plant_Leaves_Giantwood"
    },
    {
      "x": -48,
      "y": 208,
      "z": -13,
      "name": "Plant_Leaves_Giantwood"
    },
    {
      "x": -48,
      "y": 202,
      "z": -12,
      "name": "Plant_Leaves_Giantwood"
    },
    {
      "x": -48,
      "y": 205,
      "z": -12,
      "name": "Plant_Leaves_Giantwood"
    },
    {
      "x": -48,
      "y": 198,
      "z": -11,
      "name": "Plant_Leaves_Giantwood"
    },
    {
      "x": -48,
      "y": 200,
      "z": -11,
      "name": "Plant_Leaves_Giantwood"
    },
    {
      "x": -48,
      "y": 204,
      "z": -11,
      "name": "Plant_Leaves_Giantwood"
    },
    {
      "x": -48,
      "y": 205,
      "z": -11,
      "name": "Plant_Leaves_Giantwood"
    },
    {
      "x": -48,
      "y": 206,
      "z": -11,
      "name": "Plant_Leaves_Giantwood"
    },
    {
      "x": -48,
      "y": 208,
      "z": -11,
      "name": "Plant_Leaves_Giantwood"
    },
    {
      "x": -48,
      "y": 198,
      "z": -9,
      "name": "Plant_Leaves_Giantwood"
    },
    {
      "x": -48,
      "y": 200,
      "z": -9,
      "name": "Plant_Leaves_Giantwood"
    },
    {
      "x": -48,
      "y": 197,
      "z": -8,
      "name": "Plant_Leaves_Giantwood"
    },
    {
      "x": -48,
      "y": 203,
      "z": -8,
      "name": "Plant_Leaves_Giantwood"
    },
    {
      "x": -48,
      "y": 204,
      "z": -8,
      "name": "Plant_Leaves_Giantwood"
    },
    {
      "x": -48,
      "y": 207,
      "z": -8,
      "name": "Plant_Leaves_Giantwood"
    },
    {
      "x": -48,
      "y": 198,
      "z": -7,
      "name": "Plant_Leaves_Giantwood"
    },
    {
      "x": -48,
      "y": 199,
      "z": -7,
      "name": "Plant_Leaves_Giantwood"
    },
    {
      "x": -48,
      "y": 204,
      "z": -7,
      "name": "Plant_Leaves_Giantwood"
    },
    {
      "x": -48,
      "y": 205,
      "z": -7,
      "name": "Plant_Leaves_Giantwood"
    },
    {
      "x": -48,
      "y": 206,
      "z": -7,
      "name": "Plant_Leaves_Giantwood"
    },
    {
      "x": -48,
      "y": 197,
      "z": -6,
      "name": "Plant_Leaves_Giantwood"
    },
    {
      "x": -48,
      "y": 203,
      "z": -6,
      "name": "Plant_Leaves_Giantwood"
    },
    {
      "x": -48,
      "y": 198,
      "z": -5,
      "name": "Plant_Leaves_Giantwood"
    },
    {
      "x": -48,
      "y": 202,
      "z": -5,
      "name": "Plant_Leaves_Giantwood"
    },
    {
      "x": -48,
      "y": 203,
      "z": -5,
      "name": "Plant_Leaves_Giantwood"
    },
    {
      "x": -48,
      "y": 206,
      "z": -5,
      "name": "Plant_Leaves_Giantwood"
    },
    {
      "x": -48,
      "y": 199,
      "z": -4,
      "name": "Plant_Leaves_Giantwood"
    },
    {
      "x": -48,
      "y": 200,
      "z": -4,
      "name": "Plant_Leaves_Giantwood"
    },
    {
      "x": -48,
      "y": 202,
      "z": -4,
      "name": "Plant_Leaves_Giantwood"
    },
    {
      "x": -48,
      "y": 203,
      "z": -4,
      "name": "Plant_Leaves_Giantwood"
    },
    {
      "x": -48,
      "y": 204,
      "z": -4,
      "name": "Plant_Leaves_Giantwood"
    },
    {
      "x": -48,
      "y": 207,
      "z": -4,
      "name": "Plant_Leaves_Giantwood"
    },
    {
      "x": -48,
      "y": 197,
      "z": -3,
      "name": "Plant_Leaves_Giantwood"
    },
    {
      "x": -48,
      "y": 198,
      "z": -3,
      "name": "Plant_Leaves_Giantwood"
    },
    {
      "x": -48,
      "y": 203,
      "z": -3,
      "name": "Plant_Leaves_Giantwood"
    },
    {
      "x": -48,
      "y": 204,
      "z": -3,
      "name": "Plant_Leaves_Giantwood"
    },
    {
      "x": -48,
      "y": 205,
      "z": -3,
      "name": "Plant_Leaves_Giantwood"
    },
    {
      "x": -48,
      "y": 200,
      "z": -2,
      "name": "Plant_Leaves_Giantwood"
    },
    {
      "x": -48,
      "y": 202,
      "z": -2,
      "name": "Plant_Leaves_Giantwood"
    },
    {
      "x": -48,
      "y": 203,
      "z": -1,
      "name": "Plant_Leaves_Giantwood"
    },
    {
      "x": -48,
      "y": 205,
      "z": -1,
      "name": "Plant_Leaves_Giantwood"
    },
    {
      "x": -48,
      "y": 197,
      "z": 0,
      "name": "Plant_Leaves_Giantwood"
    },
    {
      "x": -48,
      "y": 202,
      "z": 0,
      "name": "Plant_Leaves_Giantwood"
    },
    {
      "x": -48,
      "y": 203,
      "z": 0,
      "name": "Plant_Leaves_Giantwood"
    },
    {
      "x": -48,
      "y": 205,
      "z": 0,
      "name": "Plant_Leaves_Giantwood"
    },
    {
      "x": -48,
      "y": 199,
      "z": 2,
      "name": "Plant_Leaves_Giantwood"
    },
    {
      "x": -48,
      "y": 200,
      "z": 2,
      "name": "Plant_Leaves_Giantwood"
    },
    {
      "x": -48,
      "y": 206,
      "z": 2,
      "name": "Plant_Leaves_Giantwood"
    },
    {
      "x": -48,
      "y": 200,
      "z": 3,
      "name": "Plant_Leaves_Giantwood"
    },
    {
      "x": -48,
      "y": 204,
      "z": 3,
      "name": "Plant_Leaves_Giantwood"
    },
    {
      "x": -48,
      "y": 199,
      "z": 4,
      "name": "Plant_Leaves_Giantwood"
    },
    {
      "x": -48,
      "y": 201,
      "z": 4,
      "name": "Plant_Leaves_Giantwood"
    },
    {
      "x": -48,
      "y": 202,
      "z": 4,
      "name": "Plant_Leaves_Giantwood"
    },
    {
      "x": -48,
      "y": 205,
      "z": 4,
      "name": "Plant_Leaves_Giantwood"
    },
    {
      "x": -48,
      "y": 197,
      "z": 5,
      "name": "Plant_Leaves_Giantwood"
    },
    {
      "x": -48,
      "y": 200,
      "z": 5,
      "name": "Plant_Leaves_Giantwood"
    },
    {
      "x": -48,
      "y": 203,
      "z": 5,
      "name": "Plant_Leaves_Giantwood"
    },
    {
      "x": -48,
      "y": 201,
      "z": 6,
      "name": "Plant_Leaves_Giantwood"
    },
    {
      "x": -48,
      "y": 205,
      "z": 6,
      "name": "Plant_Leaves_Giantwood"
    },
    {
      "x": -48,
      "y": 197,
      "z": 7,
      "name": "Plant_Leaves_Giantwood"
    },
    {
      "x": -48,
      "y": 202,
      "z": 7,
      "name": "Plant_Leaves_Giantwood"
    },
    {
      "x": -48,
      "y": 203,
      "z": 7,
      "name": "Plant_Leaves_Giantwood"
    },
    {
      "x": -48,
      "y": 197,
      "z": 8,
      "name": "Plant_Leaves_Giantwood"
    },
    {
      "x": -48,
      "y": 199,
      "z": 8,
      "name": "Plant_Leaves_Giantwood"
    },
    {
      "x": -48,
      "y": 201,
      "z": 8,
      "name": "Plant_Leaves_Giantwood"
    },
    {
      "x": -48,
      "y": 204,
      "z": 8,
      "name": "Plant_Leaves_Giantwood"
    },
    {
      "x": -48,
      "y": 206,
      "z": 8,
      "name": "Plant_Leaves_Giantwood"
    },
    {
      "x": -48,
      "y": 204,
      "z": 9,
      "name": "Plant_Leaves_Giantwood"
    },
    {
      "x": -48,
      "y": 206,
      "z": 9,
      "name": "Plant_Leaves_Giantwood"
    },
    {
      "x": -48,
      "y": 197,
      "z": 10,
      "name": "Plant_Leaves_Giantwood"
    },
    {
      "x": -48,
      "y": 199,
      "z": 10,
      "name": "Plant_Leaves_Giantwood"
    },
    {
      "x": -48,
      "y": 206,
      "z": 10,
      "name": "Plant_Leaves_Giantwood"
    },
    {
      "x": -48,
      "y": 199,
      "z": 11,
      "name": "Plant_Leaves_Giantwood"
    },
    {
      "x": -48,
      "y": 204,
      "z": 11,
      "name": "Plant_Leaves_Giantwood"
    },
    {
      "x": -48,
      "y": 200,
      "z": 12,
      "name": "Plant_Leaves_Giantwood"
    },
    {
      "x": -48,
      "y": 202,
      "z": 12,
      "name": "Plant_Leaves_Giantwood"
    },
    {
      "x": -48,
      "y": 202,
      "z": 13,
      "name": "Plant_Leaves_Giantwood"
    },
    {
      "x": -48,
      "y": 203,
      "z": 13,
      "name": "Plant_Leaves_Giantwood"
    },
    {
      "x": -48,
      "y": 204,
      "z": 13,
      "name": "Plant_Leaves_Giantwood"
    },
    {
      "x": -48,
      "y": 203,
      "z": 14,
      "name": "Plant_Leaves_Giantwood"
    },
    {
      "x": -48,
      "y": 200,
      "z": 15,
      "name": "Plant_Leaves_Giantwood"
    },
    {
      "x": -48,
      "y": 201,
      "z": 15,
      "name": "Plant_Leaves_Giantwood"
    },
    {
      "x": -48,
      "y": 202,
      "z": 15,
      "name": "Plant_Leaves_Giantwood"
    },
    {
      "x": -48,
      "y": 197,
      "z": 25,
      "name": "Plant_Leaves_Giantwood"
    },
    {
      "x": -48,
      "y": 199,
      "z": 26,
      "name": "Plant_Leaves_Giantwood"
    },
    {
      "x": -48,
      "y": 201,
      "z": 26,
      "name": "Plant_Leaves_Giantwood"
    },
    {
      "x": -48,
      "y": 196,
      "z": 27,
      "name": "Plant_Leaves_Giantwood"
    },
    {
      "x": -48,
      "y": 197,
      "z": 27,
      "name": "Plant_Leaves_Giantwood"
    },
    {
      "x": -48,
      "y": 198,
      "z": 27,
      "name": "Plant_Leaves_Giantwood"
    },
    {
      "x": -48,
      "y": 200,
      "z": 27,
      "name": "Plant_Leaves_Giantwood"
    },
    {
      "x": -48,
      "y": 198,
      "z": 28,
      "name": "Plant_Leaves_Giantwood"
    },
    {
      "x": -48,
      "y": 199,
      "z": 28,
      "name": "Plant_Leaves_Giantwood"
    },
    {
      "x": -48,
      "y": 195,
      "z": 29,
      "name": "Plant_Leaves_Giantwood"
    },
    {
      "x": -48,
      "y": 200,
      "z": 29,
      "name": "Plant_Leaves_Giantwood"
    },
    {
      "x": -48,
      "y": 196,
      "z": 30,
      "name": "Plant_Leaves_Giantwood"
    },
    {
      "x": -48,
      "y": 198,
      "z": 30,
      "name": "Plant_Leaves_Giantwood"
    },
    {
      "x": -48,
      "y": 201,
      "z": 30,
      "name": "Plant_Leaves_Giantwood"
    },
    {
      "x": -48,
      "y": 202,
      "z": 31,
      "name": "Plant_Leaves_Giantwood"
    },
    {
      "x": -48,
      "y": 196,
      "z": 32,
      "name": "Plant_Leaves_Giantwood"
    },
    {
      "x": -48,
      "y": 196,
      "z": 33,
      "name": "Plant_Leaves_Giantwood"
    },
    {
      "x": -48,
      "y": 200,
      "z": 33,
      "name": "Plant_Leaves_Giantwood"
    },
    {
      "x": -48,
      "y": 202,
      "z": 34,
      "name": "Plant_Leaves_Giantwood"
    },
    {
      "x": -48,
      "y": 197,
      "z": 35,
      "name": "Plant_Leaves_Giantwood"
    },
    {
      "x": -48,
      "y": 200,
      "z": 35,
      "name": "Plant_Leaves_Giantwood"
    },
    {
      "x": -48,
      "y": 201,
      "z": 35,
      "name": "Plant_Leaves_Giantwood"
    },
    {
      "x": -48,
      "y": 195,
      "z": 36,
      "name": "Plant_Leaves_Giantwood"
    },
    {
      "x": -48,
      "y": 200,
      "z": 36,
      "name": "Plant_Leaves_Giantwood"
    },
    {
      "x": -48,
      "y": 197,
      "z": 37,
      "name": "Plant_Leaves_Giantwood"
    },
    {
      "x": -48,
      "y": 201,
      "z": 37,
      "name": "Plant_Leaves_Giantwood"
    },
    {
      "x": -48,
      "y": 197,
      "z": 38,
      "name": "Plant_Leaves_Giantwood"
    },
    {
      "x": -48,
      "y": 201,
      "z": 38,
      "name": "Plant_Leaves_Giantwood"
    },
    {
      "x": -48,
      "y": 202,
      "z": 38,
      "name": "Plant_Leaves_Giantwood"
    },
    {
      "x": -48,
      "y": 195,
      "z": 39,
      "name": "Plant_Leaves_Giantwood"
    },
    {
      "x": -48,
      "y": 201,
      "z": 39,
      "name": "Plant_Leaves_Giantwood"
    },
    {
      "x": -48,
      "y": 198,
      "z": 40,
      "name": "Plant_Leaves_Giantwood"
    },
    {
      "x": -48,
      "y": 200,
      "z": 40,
      "name": "Plant_Leaves_Giantwood"
    },
    {
      "x": -48,
      "y": 198,
      "z": 41,
      "name": "Plant_Leaves_Giantwood"
    },
    {
      "x": -48,
      "y": 200,
      "z": 41,
      "name": "Plant_Leaves_Giantwood"
    },
    {
      "x": -48,
      "y": 197,
