{
  "version": 8,
  "blockIdVersion": 11,
  "anchorX": 0,
  "anchorY": 0,
  "anchorZ": 0,
  "blocks": [
    {
      "x": -35,
      "y": 21,
      "z": -19,
      "name": "Rock_Stone"
    },
    {
      "x": -35,
      "y": 22,
      "z": -19,
      "name": "Rock_Stone"
    },
    {
      "x": -35,
      "y": 23,
      "z": -19,
      "name": "Rock_Stone"
    },
    {
      "x": -35,
      "y": 20,
      "z": -18,
      "name": "Rock_Stone"
    },
    {
      "x": -35,
      "y": 21,
      "z": -18,
      "name": "Rock_Stone"
    },
    {
      "x": -35,
      "y": 22,
      "z": -18,
      "name": "Rock_Stone"
    },
    {
      "x": -35,
      "y": 23,
      "z": -18,
      "name": "Rock_Stone"
    },
    {
      "x": -35,
      "y": 24,
      "z": -18,
      "name": "Rock_Stone"
    },
    {
      "x": -35,
      "y": 20,
      "z": -17,
      "name": "Rock_Stone"
    },
    {
      "x": -35,
      "y": 21,
      "z": -17,
      "name": "Rock_Stone"
    },
    {
      "x": -35,
      "y": 22,
      "z": -17,
      "name": "Rock_Stone"
    },
    {
      "x": -35,
      "y": 23,
      "z": -17,
      "name": "Rock_Stone"
    },
    {
      "x": -35,
      "y": 24,
      "z": -17,
      "name": "Rock_Stone"
    },
    {
      "x": -35,
      "y": 22,
      "z": -16,
      "name": "Rock_Stone"
    },
    {
      "x": -35,
      "y": 23,
      "z": -16,
      "name": "Rock_Stone"
    },
    {
      "x": -34,
      "y": 21,
      "z": -21,
      "name": "Rock_Stone"
    },
    {
      "x": -34,
      "y": 22,
      "z": -21,
      "name": "Rock_Stone"
    },
    {
      "x": -34,
      "y": 23,
      "z": -21,
      "name": "Rock_Stone"
    },
    {
      "x": -34,
      "y": 20,
      "z": -20,
      "name": "Rock_Stone"
    },
    {
      "x": -34,
      "y": 21,
      "z": -20,
      "name": "Rock_Stone"
    },
    {
      "x": -34,
      "y": 22,
      "z": -20,
      "name": "Rock_Stone"
    },
    {
      "x": -34,
      "y": 23,
      "z": -20,
      "name": "Rock_Stone"
    },
    {
      "x": -34,
      "y": 24,
      "z": -20,
      "name": "Rock_Stone"
    },
    {
      "x": -34,
      "y": 18,
      "z": -19,
      "name": "Rock_Stone"
    },
    {
      "x": -34,
      "y": 19,
      "z": -19,
      "name": "Rock_Stone"
    },
    {
      "x": -34,
      "y": 20,
      "z": -19,
      "name": "Rock_Stone"
    },
    {
      "x": -34,
      "y": 21,
      "z": -19,
      "name": "Rock_Stone"
    },
    {
      "x": -34,
      "y": 22,
      "z": -19,
      "name": "Rock_Stone"
    },
    {
      "x": -34,
      "y": 23,
      "z": -19,
      "name": "Rock_Stone"
    },
    {
      "x": -34,
      "y": 24,
      "z": -19,
      "name": "Rock_Stone"
    },
    {
      "x": -34,
      "y": 25,
      "z": -19,
      "name": "Rock_Stone"
    },
    {
      "x": -34,
      "y": 19,
      "z": -18,
      "name": "Rock_Stone"
    },
    {
      "x": -34,
      "y": 20,
      "z": -18,
      "name": "Rock_Stone"
    },
    {
      "x": -34,
      "y": 21,
      "z": -18,
      "name": "Rock_Stone"
    },
    {
      "x": -34,
      "y": 22,
      "z": -18,
      "name": "Rock_Stone"
    },
    {
      "x": -34,
      "y": 23,
      "z": -18,
      "name": "Rock_Stone"
    },
    {
      "x": -34,
      "y": 24,
      "z": -18,
      "name": "Rock_Stone"
    },
    {
      "x": -34,
      "y": 25,
      "z": -18,
      "name": "Rock_Stone"
    },
    {
      "x": -34,
      "y": 26,
      "z": -18,
      "name": "Rock_Stone"
    },
    {
      "x": -34,
      "y": 18,
      "z": -17,
      "name": "Rock_Stone"
    },
    {
      "x": -34,
      "y": 19,
      "z": -17,
      "name": "Rock_Stone"
    },
    {
      "x": -34,
      "y": 20,
      "z": -17,
      "name": "Rock_Stone"
    },
    {
      "x": -34,
      "y": 21,
      "z": -17,
      "name": "Rock_Stone"
    },
    {
      "x": -34,
      "y": 22,
      "z": -17,
      "name": "Rock_Stone"
    },
    {
      "x": -34,
      "y": 23,
      "z": -17,
      "name": "Rock_Stone"
    },
    {
      "x": -34,
      "y": 24,
      "z": -17,
      "name": "Rock_Stone"
    },
    {
      "x": -34,
      "y": 25,
      "z": -17,
      "name": "Rock_Stone"
    },
    {
      "x": -34,
      "y": 26,
      "z": -17,
      "name": "Rock_Stone"
    },
    {
      "x": -34,
      "y": 19,
      "z": -16,
      "name": "Rock_Stone"
    },
    {
      "x": -34,
      "y": 20,
      "z": -16,
      "name": "Rock_Stone"
    },
    {
      "x": -34,
      "y": 21,
      "z": -16,
      "name": "Rock_Stone"
    },
    {
      "x": -34,
      "y": 22,
      "z": -16,
      "name": "Rock_Stone"
    },
    {
      "x": -34,
      "y": 23,
      "z": -16,
      "name": "Rock_Stone"
    },
    {
      "x": -34,
      "y": 24,
      "z": -16,
      "name": "Rock_Stone"
    },
    {
      "x": -34,
      "y": 25,
      "z": -16,
      "name": "Rock_Stone"
    },
    {
      "x": -34,
      "y": 26,
      "z": -16,
      "name": "Rock_Stone"
    },
    {
      "x": -34,
      "y": 20,
      "z": -15,
      "name": "Rock_Stone"
    },
    {
      "x": -34,
      "y": 21,
      "z": -15,
      "name": "Rock_Stone"
    },
    {
      "x": -34,
      "y": 22,
      "z": -15,
      "name": "Rock_Stone"
    },
    {
      "x": -34,
      "y": 23,
      "z": -15,
      "name": "Rock_Stone"
    },
    {
      "x": -34,
      "y": 24,
      "z": -15,
      "name": "Rock_Stone"
    },
    {
      "x": -34,
      "y": 25,
      "z": -15,
      "name": "Rock_Stone"
    },
    {
      "x": -34,
      "y": 26,
      "z": -15,
      "name": "Rock_Stone"
    },
    {
      "x": -34,
      "y": 22,
      "z": -14,
      "name": "Rock_Stone"
    },
    {
      "x": -34,
      "y": 23,
      "z": -14,
      "name": "Rock_Stone"
    },
    {
      "x": -34,
      "y": 24,
      "z": -14,
      "name": "Rock_Stone"
    },
    {
      "x": -34,
      "y": 25,
      "z": -14,
      "name": "Rock_Stone"
    },
    {
      "x": -34,
      "y": 26,
      "z": -14,
      "name": "Rock_Stone"
    },
    {
      "x": -34,
      "y": 197,
      "z": -2,
      "name": "Rock_Stone"
    },
    {
      "x": -33,
      "y": 21,
      "z": -22,
      "name": "Rock_Stone"
    },
    {
      "x": -33,
      "y": 22,
      "z": -22,
      "name": "Rock_Stone"
    },
    {
      "x": -33,
      "y": 19,
      "z": -21,
      "name": "Rock_Stone"
    },
    {
      "x": -33,
      "y": 20,
      "z": -21,
      "name": "Rock_Stone"
    },
    {
      "x": -33,
      "y": 21,
      "z": -21,
      "name": "Rock_Stone"
    },
    {
      "x": -33,
      "y": 22,
      "z": -21,
      "name": "Rock_Stone"
    },
    {
      "x": -33,
      "y": 23,
      "z": -21,
      "name": "Rock_Stone"
    },
    {
      "x": -33,
      "y": 24,
      "z": -21,
      "name": "Rock_Stone"
    },
    {
      "x": -33,
      "y": 18,
      "z": -20,
      "name": "Rock_Stone"
    },
    {
      "x": -33,
      "y": 19,
      "z": -20,
      "name": "Rock_Stone"
    },
    {
      "x": -33,
      "y": 20,
      "z": -20,
      "name": "Rock_Stone"
    },
    {
      "x": -33,
      "y": 21,
      "z": -20,
      "name": "Rock_Stone"
    },
    {
      "x": -33,
      "y": 22,
      "z": -20,
      "name": "Rock_Stone"
    },
    {
      "x": -33,
      "y": 23,
      "z": -20,
      "name": "Rock_Stone"
    },
    {
      "x": -33,
      "y": 24,
      "z": -20,
      "name": "Rock_Stone"
    },
    {
      "x": -33,
      "y": 25,
      "z": -20,
      "name": "Rock_Stone"
    },
    {
      "x": -33,
      "y": 26,
      "z": -20,
      "name": "Rock_Stone"
    },
    {
      "x": -33,
      "y": 17,
      "z": -19,
      "name": "Rock_Stone"
    },
    {
      "x": -33,
      "y": 18,
      "z": -19,
      "name": "Rock_Stone"
    },
    {
      "x": -33,
      "y": 19,
      "z": -19,
      "name": "Rock_Stone"
    },
    {
      "x": -33,
      "y": 20,
      "z": -19,
      "name": "Rock_Stone"
    },
    {
      "x": -33,
      "y": 21,
      "z": -19,
      "name": "Rock_Stone"
    },
    {
      "x": -33,
      "y": 22,
      "z": -19,
      "name": "Rock_Stone"
    },
    {
      "x": -33,
      "y": 23,
      "z": -19,
      "name": "Rock_Stone"
    },
    {
      "x": -33,
      "y": 24,
      "z": -19,
      "name": "Rock_Stone"
    },
    {
      "x": -33,
      "y": 25,
      "z": -19,
      "name": "Rock_Stone"
    },
    {
      "x": -33,
      "y": 26,
      "z": -19,
      "name": "Rock_Stone"
    },
    {
      "x": -33,
      "y": 17,
      "z": -18,
      "name": "Rock_Stone"
    },
    {
      "x": -33,
      "y": 18,
      "z": -18,
      "name": "Rock_Stone"
    },
    {
      "x": -33,
      "y": 19,
      "z": -18,
      "name": "Rock_Stone"
    },
    {
      "x": -33,
      "y": 20,
      "z": -18,
      "name": "Rock_Stone"
    },
    {
      "x": -33,
      "y": 21,
      "z": -18,
      "name": "Rock_Stone"
    },
    {
      "x": -33,
      "y": 22,
      "z": -18,
      "name": "Rock_Stone"
    },
    {
      "x": -33,
      "y": 23,
      "z": -18,
      "name": "Rock_Stone"
    },
    {
      "x": -33,
      "y": 24,
      "z": -18,
      "name": "Rock_Stone"
    },
    {
      "x": -33,
      "y": 25,
      "z": -18,
      "name": "Rock_Stone"
    },
    {
      "x": -33,
      "y": 26,
      "z": -18,
      "name": "Rock_Stone"
    },
    {
      "x": -33,
      "y": 27,
      "z": -18,
      "name": "Rock_Stone"
    },
    {
      "x": -33,
      "y": 17,
      "z": -17,
      "name": "Rock_Stone"
    },
    {
      "x": -33,
      "y": 18,
      "z": -17,
      "name": "Rock_Stone"
    },
    {
      "x": -33,
      "y": 19,
      "z": -17,
      "name": "Rock_Stone"
    },
    {
      "x": -33,
      "y": 20,
      "z": -17,
      "name": "Rock_Stone"
    },
    {
      "x": -33,
      "y": 21,
      "z": -17,
      "name": "Rock_Stone"
    },
    {
      "x": -33,
      "y": 22,
      "z": -17,
      "name": "Rock_Stone"
    },
    {
      "x": -33,
      "y": 23,
      "z": -17,
      "name": "Rock_Stone"
    },
    {
      "x": -33,
      "y": 24,
      "z": -17,
      "name": "Rock_Stone"
    },
    {
      "x": -33,
      "y": 25,
      "z": -17,
      "name": "Rock_Stone"
    },
    {
      "x": -33,
      "y": 26,
      "z": -17,
      "name": "Rock_Stone"
    },
    {
      "x": -33,
      "y": 27,
      "z": -17,
      "name": "Rock_Stone"
    },
    {
      "x": -33,
      "y": 18,
      "z": -16,
      "name": "Rock_Stone"
    },
    {
      "x": -33,
      "y": 19,
      "z": -16,
      "name": "Rock_Stone"
    },
    {
      "x": -33,
      "y": 20,
      "z": -16,
      "name": "Rock_Stone"
    },
    {
      "x": -33,
      "y": 21,
      "z": -16,
      "name": "Rock_Stone"
    },
    {
      "x": -33,
      "y": 22,
      "z": -16,
      "name": "Rock_Stone"
    },
    {
      "x": -33,
      "y": 23,
      "z": -16,
      "name": "Rock_Stone"
    },
    {
      "x": -33,
      "y": 24,
      "z": -16,
      "name": "Rock_Stone"
    },
    {
      "x": -33,
      "y": 25,
      "z": -16,
      "name": "Rock_Stone"
    },
    {
      "x": -33,
      "y": 26,
      "z": -16,
      "name": "Rock_Stone"
    },
    {
      "x": -33,
      "y": 27,
      "z": -16,
      "name": "Rock_Stone"
    },
    {
      "x": -33,
      "y": 18,
      "z": -15,
      "name": "Rock_Stone"
    },
    {
      "x": -33,
      "y": 19,
      "z": -15,
      "name": "Rock_Stone"
    },
    {
      "x": -33,
      "y": 20,
      "z": -15,
      "name": "Rock_Stone"
    },
    {
      "x": -33,
      "y": 21,
      "z": -15,
      "name": "Rock_Stone"
    },
    {
      "x": -33,
      "y": 22,
      "z": -15,
      "name": "Rock_Stone"
    },
    {
      "x": -33,
      "y": 23,
      "z": -15,
      "name": "Rock_Stone"
    },
    {
      "x": -33,
      "y": 24,
      "z": -15,
      "name": "Rock_Stone"
    },
    {
      "x": -33,
      "y": 25,
      "z": -15,
      "name": "Rock_Stone"
    },
    {
      "x": -33,
      "y": 26,
      "z": -15,
      "name": "Rock_Stone"
    },
    {
      "x": -33,
      "y": 27,
      "z": -15,
      "name": "Rock_Stone"
    },
    {
      "x": -33,
      "y": 20,
      "z": -14,
      "name": "Rock_Stone"
    },
    {
      "x": -33,
      "y": 21,
      "z": -14,
      "name": "Rock_Stone"
    },
    {
      "x": -33,
      "y": 22,
      "z": -14,
      "name": "Rock_Stone"
    },
    {
      "x": -33,
      "y": 23,
      "z": -14,
      "name": "Rock_Stone"
    },
    {
      "x": -33,
      "y": 24,
      "z": -14,
      "name": "Rock_Stone"
    },
    {
      "x": -33,
      "y": 25,
      "z": -14,
      "name": "Rock_Stone"
    },
    {
      "x": -33,
      "y": 26,
      "z": -14,
      "name": "Rock_Stone"
    },
    {
      "x": -33,
      "y": 27,
      "z": -14,
      "name": "Rock_Stone"
    },
    {
      "x": -33,
      "y": 22,
      "z": -13,
      "name": "Rock_Stone"
    },
    {
      "x": -33,
      "y": 23,
      "z": -13,
      "name": "Rock_Stone"
    },
    {
      "x": -33,
      "y": 24,
      "z": -13,
      "name": "Rock_Stone"
    },
    {
      "x": -33,
      "y": 25,
      "z": -13,
      "name": "Rock_Stone"
    },
    {
      "x": -33,
      "y": 26,
      "z": -13,
      "name": "Rock_Stone"
    },
    {
      "x": -33,
      "y": 197,
      "z": -2,
      "name": "Rock_Stone"
    },
    {
      "x": -32,
      "y": 20,
      "z": -22,
      "name": "Rock_Stone"
    },
    {
      "x": -32,
      "y": 21,
      "z": -22,
      "name": "Rock_Stone"
    },
    {
      "x": -32,
      "y": 22,
      "z": -22,
      "name": "Rock_Stone"
    },
    {
      "x": -32,
      "y": 23,
      "z": -22,
      "name": "Rock_Stone"
    },
    {
      "x": -32,
      "y": 19,
      "z": -21,
      "name": "Rock_Stone"
    },
    {
      "x": -32,
      "y": 20,
      "z": -21,
      "name": "Rock_Stone"
    },
    {
      "x": -32,
      "y": 21,
      "z": -21,
      "name": "Rock_Stone"
    },
    {
      "x": -32,
      "y": 22,
      "z": -21,
      "name": "Rock_Stone"
    },
    {
      "x": -32,
      "y": 23,
      "z": -21,
      "name": "Rock_Stone"
    },
    {
      "x": -32,
      "y": 24,
      "z": -21,
      "name": "Rock_Stone"
    },
    {
      "x": -32,
      "y": 25,
      "z": -21,
      "name": "Rock_Stone"
    },
    {
      "x": -32,
      "y": 26,
      "z": -21,
      "name": "Rock_Stone"
    },
    {
      "x": -32,
      "y": 17,
      "z": -20,
      "name": "Rock_Stone"
    },
    {
      "x": -32,
      "y": 18,
      "z": -20,
      "name": "Rock_Stone"
    },
    {
      "x": -32,
      "y": 19,
      "z": -20,
      "name": "Rock_Stone"
    },
    {
      "x": -32,
      "y": 20,
      "z": -20,
      "name": "Rock_Stone"
    },
    {
      "x": -32,
      "y": 21,
      "z": -20,
      "name": "Rock_Stone"
    },
    {
      "x": -32,
      "y": 22,
      "z": -20,
      "name": "Rock_Stone"
    },
    {
      "x": -32,
      "y": 23,
      "z": -20,
      "name": "Rock_Stone"
    },
    {
      "x": -32,
      "y": 24,
      "z": -20,
      "name": "Rock_Stone"
    },
    {
      "x": -32,
      "y": 25,
      "z": -20,
      "name": "Rock_Stone"
    },
    {
      "x": -32,
      "y": 26,
      "z": -20,
      "name": "Rock_Stone"
    },
    {
      "x": -32,
      "y": 16,
      "z": -19,
      "name": "Rock_Stone"
    },
    {
      "x": -32,
      "y": 17,
      "z": -19,
      "name": "Rock_Stone"
    },
    {
      "x": -32,
      "y": 18,
      "z": -19,
      "name": "Rock_Stone"
    },
    {
      "x": -32,
      "y": 19,
      "z": -19,
      "name": "Rock_Stone"
    },
    {
      "x": -32,
      "y": 20,
      "z": -19,
      "name": "Rock_Stone"
    },
    {
      "x": -32,
      "y": 21,
      "z": -19,
      "name": "Rock_Stone"
    },
    {
      "x": -32,
      "y": 22,
      "z": -19,
      "name": "Rock_Stone"
    },
    {
      "x": -32,
      "y": 23,
      "z": -19,
      "name": "Rock_Stone"
    },
    {
      "x": -32,
      "y": 24,
      "z": -19,
      "name": "Rock_Stone"
    },
    {
      "x": -32,
      "y": 25,
      "z": -19,
      "name": "Rock_Stone"
    },
    {
      "x": -32,
      "y": 26,
      "z": -19,
      "name": "Rock_Stone"
    },
    {
      "x": -32,
      "y": 27,
      "z": -19,
      "name": "Rock_Stone"
    },
    {
      "x": -32,
      "y": 16,
      "z": -18,
      "name": "Rock_Stone"
    },
    {
      "x": -32,
      "y": 17,
      "z": -18,
      "name": "Rock_Stone"
    },
    {
      "x": -32,
      "y": 18,
      "z": -18,
      "name": "Rock_Stone"
    },
    {
      "x": -32,
      "y": 19,
      "z": -18,
      "name": "Rock_Stone"
    },
    {
      "x": -32,
      "y": 20,
      "z": -18,
      "name": "Rock_Stone"
    },
    {
      "x": -32,
      "y": 21,
      "z": -18,
      "name": "Rock_Stone"
    },
    {
      "x": -32,
      "y": 22,
      "z": -18,
      "name": "Rock_Stone"
    },
    {
      "x": -32,
      "y": 23,
      "z": -18,
      "name": "Rock_Stone"
    },
    {
      "x": -32,
      "y": 24,
      "z": -18,
      "name": "Rock_Stone"
    },
    {
      "x": -32,
      "y": 25,
      "z": -18,
      "name": "Rock_Stone"
    },
    {
      "x": -32,
      "y": 26,
      "z": -18,
      "name": "Rock_Stone"
    },
    {
      "x": -32,
      "y": 27,
      "z": -18,
      "name": "Rock_Stone"
    },
    {
      "x": -32,
      "y": 28,
      "z": -18,
      "name": "Rock_Stone"
    },
    {
      "x": -32,
      "y": 16,
      "z": -17,
      "name": "Rock_Stone"
    },
    {
      "x": -32,
      "y": 17,
      "z": -17,
      "name": "Rock_Stone"
    },
    {
      "x": -32,
      "y": 18,
      "z": -17,
      "name": "Rock_Stone"
    },
    {
      "x": -32,
      "y": 19,
      "z": -17,
      "name": "Rock_Stone"
    },
    {
      "x": -32,
      "y": 20,
      "z": -17,
      "name": "Rock_Stone"
    },
    {
      "x": -32,
      "y": 21,
      "z": -17,
      "name": "Rock_Stone"
    },
    {
      "x": -32,
      "y": 22,
      "z": -17,
      "name": "Rock_Stone"
    },
    {
      "x": -32,
      "y": 23,
      "z": -17,
      "name": "Rock_Stone"
    },
    {
      "x": -32,
      "y": 24,
      "z": -17,
      "name": "Rock_Stone"
    },
    {
      "x": -32,
      "y": 25,
      "z": -17,
      "name": "Rock_Stone"
    },
    {
      "x": -32,
      "y": 26,
      "z": -17,
      "name": "Rock_Stone"
    },
    {
      "x": -32,
      "y": 27,
      "z": -17,
      "name": "Rock_Stone"
    },
    {
      "x": -32,
      "y": 28,
      "z": -17,
      "name": "Rock_Stone"
    },
    {
      "x": -32,
      "y": 16,
      "z": -16,
      "name": "Rock_Stone"
    },
    {
      "x": -32,
      "y": 17,
      "z": -16,
      "name": "Rock_Stone"
    },
    {
      "x": -32,
      "y": 18,
      "z": -16,
      "name": "Rock_Stone"
    },
    {
      "x": -32,
      "y": 19,
      "z": -16,
      "name": "Rock_Stone"
    },
    {
      "x": -32,
      "y": 20,
      "z": -16,
      "name": "Rock_Stone"
    },
    {
      "x": -32,
      "y": 21,
      "z": -16,
      "name": "Rock_Stone"
    },
    {
      "x": -32,
      "y": 22,
      "z": -16,
      "name": "Rock_Stone"
    },
    {
      "x": -32,
      "y": 23,
      "z": -16,
      "name": "Rock_Stone"
    },
    {
      "x": -32,
      "y": 24,
      "z": -16,
      "name": "Rock_Stone"
    },
    {
      "x": -32,
      "y": 25,
      "z": -16,
      "name": "Rock_Stone"
    },
    {
      "x": -32,
      "y": 26,
      "z": -16,
      "name": "Rock_Stone"
    },
    {
      "x": -32,
      "y": 27,
      "z": -16,
      "name": "Rock_Stone"
    },
    {
      "x": -32,
      "y": 28,
      "z": -16,
      "name": "Rock_Stone"
    },
    {
      "x": -32,
      "y": 17,
      "z": -15,
      "name": "Rock_Stone"
    },
    {
      "x": -32,
      "y": 18,
      "z": -15,
      "name": "Rock_Stone"
    },
    {
      "x": -32,
      "y": 19,
      "z": -15,
      "name": "Rock_Stone"
    },
    {
      "x": -32,
      "y": 20,
      "z": -15,
      "name": "Rock_Stone"
    },
    {
      "x": -32,
      "y": 21,
      "z": -15,
      "name": "Rock_Stone"
    },
    {
      "x": -32,
      "y": 22,
      "z": -15,
      "name": "Rock_Stone"
    },
    {
      "x": -32,
      "y": 23,
      "z": -15,
      "name": "Rock_Stone"
    },
    {
      "x": -32,
      "y": 24,
      "z": -15,
      "name": "Rock_Stone"
    },
    {
      "x": -32,
      "y": 25,
      "z": -15,
      "name": "Rock_Stone"
    },
    {
      "x": -32,
      "y": 26,
      "z": -15,
      "name": "Rock_Stone"
    },
    {
      "x": -32,
      "y": 27,
      "z": -15,
      "name": "Rock_Stone"
    },
    {
      "x": -32,
      "y": 28,
      "z": -15,
      "name": "Rock_Stone"
    },
    {
      "x": -32,
      "y": 18,
      "z": -14,
      "name": "Rock_Stone"
    },
    {
      "x": -32,
      "y": 19,
      "z": -14,
      "name": "Rock_Stone"
    },
    {
      "x": -32,
      "y": 20,
      "z": -14,
      "name": "Rock_Stone"
    },
    {
      "x": -32,
      "y": 21,
      "z": -14,
      "name": "Rock_Stone"
    },
    {
      "x": -32,
      "y": 22,
      "z": -14,
      "name": "Rock_Stone"
    },
    {
      "x": -32,
      "y": 23,
      "z": -14,
      "name": "Rock_Stone"
    },
    {
      "x": -32,
      "y": 24,
      "z": -14,
      "name": "Rock_Stone"
    },
    {
      "x": -32,
      "y": 25,
      "z": -14,
      "name": "Rock_Stone"
    },
    {
      "x": -32,
      "y": 26,
      "z": -14,
      "name": "Rock_Stone"
    },
    {
      "x": -32,
      "y": 27,
      "z": -14,
      "name": "Rock_Stone"
    },
    {
      "x": -32,
      "y": 28,
      "z": -14,
      "name": "Rock_Stone"
    },
    {
      "x": -32,
      "y": 21,
      "z": -13,
      "name": "Rock_Stone"
    },
    {
      "x": -32,
      "y": 22,
      "z": -13,
      "name": "Rock_Stone"
    },
    {
      "x": -32,
      "y": 23,
      "z": -13,
      "name": "Rock_Stone"
    },
    {
      "x": -32,
      "y": 24,
      "z": -13,
      "name": "Rock_Stone"
    },
    {
      "x": -32,
      "y": 25,
      "z": -13,
      "name": "Rock_Stone"
    },
    {
      "x": -32,
      "y": 26,
      "z": -13,
      "name": "Rock_Stone"
    },
    {
      "x": -32,
      "y": 27,
      "z": -13,
      "name": "Rock_Stone"
    },
    {
      "x": -32,
      "y": 196,
      "z": -2,
      "name": "Rock_Stone"
    },
    {
      "x": -32,
      "y": 197,
      "z": -2,
      "name": "Rock_Stone"
    },
    {
      "x": -31,
      "y": 20,
      "z": -22,
      "name": "Rock_Stone"
    },
    {
      "x": -31,
      "y": 21,
      "z": -22,
      "name": "Rock_Stone"
    },
    {
      "x": -31,
      "y": 22,
      "z": -22,
      "name": "Rock_Stone"
    },
    {
      "x": -31,
      "y": 23,
      "z": -22,
      "name": "Rock_Stone"
    },
    {
      "x": -31,
      "y": 24,
      "z": -22,
      "name": "Rock_Stone"
    },
    {
      "x": -31,
      "y": 25,
      "z": -22,
      "name": "Rock_Stone"
    },
    {
      "x": -31,
      "y": 17,
      "z": -21,
      "name": "Rock_Stone"
    },
    {
      "x": -31,
      "y": 18,
      "z": -21,
      "name": "Rock_Stone"
    },
    {
      "x": -31,
      "y": 19,
      "z": -21,
      "name": "Rock_Stone"
    },
    {
      "x": -31,
      "y": 20,
      "z": -21,
      "name": "Rock_Stone"
    },
    {
      "x": -31,
      "y": 21,
      "z": -21,
      "name": "Rock_Stone"
    },
    {
      "x": -31,
      "y": 22,
      "z": -21,
      "name": "Rock_Stone"
    },
    {
      "x": -31,
      "y": 23,
      "z": -21,
      "name": "Rock_Stone"
    },
    {
      "x": -31,
      "y": 24,
      "z": -21,
      "name": "Rock_Stone"
    },
    {
      "x": -31,
      "y": 25,
      "z": -21,
      "name": "Rock_Stone"
    },
    {
      "x": -31,
      "y": 26,
      "z": -21,
      "name": "Rock_Stone"
    },
    {
      "x": -31,
      "y": 17,
      "z": -20,
      "name": "Rock_Stone"
    },
    {
      "x": -31,
      "y": 18,
      "z": -20,
      "name": "Rock_Stone"
    },
    {
      "x": -31,
      "y": 19,
      "z": -20,
      "name": "Rock_Stone"
    },
    {
      "x": -31,
      "y": 20,
      "z": -20,
      "name": "Rock_Stone"
    },
    {
      "x": -31,
      "y": 21,
      "z": -20,
      "name": "Rock_Stone"
    },
    {
      "x": -31,
      "y": 22,
      "z": -20,
      "name": "Rock_Stone"
    },
    {
      "x": -31,
      "y": 23,
      "z": -20,
      "name": "Rock_Stone"
    },
    {
      "x": -31,
      "y": 24,
      "z": -20,
      "name": "Rock_Stone"
    },
    {
      "x": -31,
      "y": 25,
      "z": -20,
      "name": "Rock_Stone"
    },
    {
      "x": -31,
      "y": 26,
      "z": -20,
      "name": "Rock_Stone"
    },
    {
      "x": -31,
      "y": 27,
      "z": -20,
      "name": "Rock_Stone"
    },
    {
      "x": -31,
      "y": 16,
      "z": -19,
      "name": "Rock_Stone"
    },
    {
      "x": -31,
      "y": 17,
      "z": -19,
      "name": "Rock_Stone"
    },
    {
      "x": -31,
      "y": 18,
      "z": -19,
      "name": "Rock_Stone"
    },
    {
      "x": -31,
      "y": 19,
      "z": -19,
      "name": "Rock_Stone"
    },
    {
      "x": -31,
      "y": 20,
      "z": -19,
      "name": "Rock_Stone"
    },
    {
      "x": -31,
      "y": 21,
      "z": -19,
      "name": "Rock_Stone"
    },
    {
      "x": -31,
      "y": 22,
      "z": -19,
      "name": "Rock_Stone"
    },
    {
      "x": -31,
      "y": 23,
      "z": -19,
      "name": "Rock_Stone"
    },
    {
      "x": -31,
      "y": 24,
      "z": -19,
      "name": "Rock_Stone"
    },
    {
      "x": -31,
      "y": 25,
      "z": -19,
      "name": "Rock_Stone"
    },
    {
      "x": -31,
      "y": 26,
      "z": -19,
      "name": "Rock_Stone"
    },
    {
      "x": -31,
      "y": 27,
      "z": -19,
      "name": "Rock_Stone"
    },
    {
      "x": -31,
      "y": 28,
      "z": -19,
      "name": "Rock_Stone"
    },
    {
      "x": -31,
      "y": 15,
      "z": -18,
      "name": "Rock_Stone"
    },
    {
      "x": -31,
      "y": 16,
      "z": -18,
      "name": "Rock_Stone"
    },
    {
      "x": -31,
      "y": 17,
      "z": -18,
      "name": "Rock_Stone"
    },
    {
      "x": -31,
      "y": 18,
      "z": -18,
      "name": "Rock_Stone"
    },
    {
      "x": -31,
      "y": 19,
      "z": -18,
      "name": "Rock_Stone"
    },
    {
      "x": -31,
      "y": 20,
      "z": -18,
      "name": "Rock_Stone"
    },
    {
      "x": -31,
      "y": 21,
      "z": -18,
      "name": "Rock_Stone"
    },
    {
      "x": -31,
      "y": 22,
      "z": -18,
      "name": "Rock_Stone"
    },
    {
      "x": -31,
      "y": 23,
      "z": -18,
      "name": "Rock_Stone"
    },
    {
      "x": -31,
      "y": 24,
      "z": -18,
      "name": "Rock_Stone"
    },
    {
      "x": -31,
      "y": 25,
      "z": -18,
      "name": "Rock_Stone"
    },
    {
      "x": -31,
      "y": 26,
      "z": -18,
      "name": "Rock_Stone"
    },
    {
      "x": -31,
      "y": 27,
      "z": -18,
      "name": "Rock_Stone"
    },
    {
      "x": -31,
      "y": 28,
      "z": -18,
      "name": "Rock_Stone"
    },
    {
      "x": -31,
      "y": 29,
      "z": -18,
      "name": "Rock_Stone"
    },
    {
      "x": -31,
      "y": 15,
      "z": -17,
      "name": "Rock_Stone"
    },
    {
      "x": -31,
      "y": 16,
      "z": -17,
      "name": "Rock_Stone"
    },
    {
      "x": -31,
      "y": 17,
      "z": -17,
      "name": "Rock_Stone"
    },
    {
      "x": -31,
      "y": 18,
      "z": -17,
      "name": "Rock_Stone"
    },
    {
      "x": -31,
      "y": 19,
      "z": -17,
      "name": "Rock_Stone"
    },
    {
      "x": -31,
      "y": 20,
      "z": -17,
      "name": "Rock_Stone"
    },
    {
      "x": -31,
      "y": 21,
      "z": -17,
      "name": "Rock_Stone"
    },
    {
      "x": -31,
      "y": 22,
      "z": -17,
      "name": "Rock_Stone"
    },
    {
      "x": -31,
      "y": 23,
      "z": -17,
      "name": "Rock_Stone"
    },
    {
      "x": -31,
      "y": 24,
      "z": -17,
      "name": "Rock_Stone"
    },
    {
      "x": -31,
      "y": 25,
      "z": -17,
      "name": "Rock_Stone"
    },
    {
      "x": -31,
      "y": 26,
      "z": -17,
      "name": "Rock_Stone"
    },
    {
      "x": -31,
      "y": 27,
      "z": -17,
      "name": "Rock_Stone"
    },
    {
      "x": -31,
      "y": 28,
      "z": -17,
      "name": "Rock_Stone"
    },
    {
      "x": -31,
      "y": 29,
      "z": -17,
      "name": "Rock_Stone"
    },
    {
      "x": -31,
      "y": 15,
      "z": -16,
      "name": "Rock_Stone"
    },
    {
      "x": -31,
      "y": 16,
      "z": -16,
      "name": "Rock_Stone"
    },
    {
      "x": -31,
      "y": 17,
      "z": -16,
      "name": "Rock_Stone"
    },
    {
      "x": -31,
      "y": 18,
      "z": -16,
      "name": "Rock_Stone"
    },
    {
      "x": -31,
      "y": 19,
      "z": -16,
      "name": "Rock_Stone"
    },
    {
      "x": -31,
      "y": 20,
      "z": -16,
      "name": "Rock_Stone"
    },
    {
      "x": -31,
      "y": 21,
      "z": -16,
      "name": "Rock_Stone"
    },
    {
      "x": -31,
      "y": 22,
      "z": -16,
      "name": "Rock_Stone"
    },
    {
      "x": -31,
      "y": 23,
      "z": -16,
      "name": "Rock_Stone"
    },
    {
      "x": -31,
      "y": 24,
      "z": -16,
      "name": "Rock_Stone"
    },
    {
      "x": -31,
      "y": 25,
      "z": -16,
      "name": "Rock_Stone"
    },
    {
      "x": -31,
      "y": 26,
      "z": -16,
      "name": "Rock_Stone"
    },
    {
      "x": -31,
      "y": 27,
      "z": -16,
      "name": "Rock_Stone"
    },
    {
      "x": -31,
      "y": 28,
      "z": -16,
      "name": "Rock_Stone"
    },
    {
      "x": -31,
      "y": 29,
      "z": -16,
      "name": "Rock_Stone"
    },
    {
      "x": -31,
      "y": 202,
      "z": -16,
      "name": "Rock_Stone"
    },
    {
      "x": -31,
      "y": 16,
      "z": -15,
      "name": "Rock_Stone"
    },
    {
      "x": -31,
      "y": 17,
      "z": -15,
      "name": "Rock_Stone"
    },
    {
      "x": -31,
      "y": 18,
      "z": -15,
      "name": "Rock_Stone"
    },
    {
      "x": -31,
      "y": 19,
      "z": -15,
      "name": "Rock_Stone"
    },
    {
      "x": -31,
      "y": 20,
      "z": -15,
      "name": "Rock_Stone"
    },
    {
      "x": -31,
      "y": 21,
      "z": -15,
      "name": "Rock_Stone"
    },
    {
      "x": -31,
      "y": 22,
      "z": -15,
      "name": "Rock_Stone"
    },
    {
      "x": -31,
      "y": 23,
      "z": -15,
      "name": "Rock_Stone"
    },
    {
      "x": -31,
      "y": 24,
      "z": -15,
      "name": "Rock_Stone"
    },
    {
      "x": -31,
      "y": 25,
      "z": -15,
      "name": "Rock_Stone"
    },
    {
      "x": -31,
      "y": 26,
      "z": -15,
      "name": "Rock_Stone"
    },
    {
      "x": -31,
      "y": 27,
      "z": -15,
      "name": "Rock_Stone"
    },
    {
      "x": -31,
      "y": 28,
      "z": -15,
      "name": "Rock_Stone"
    },
    {
      "x": -31,
      "y": 29,
      "z": -15,
      "name": "Rock_Stone"
    },
    {
      "x": -31,
      "y": 17,
      "z": -14,
      "name": "Rock_Stone"
    },
    {
      "x": -31,
      "y": 18,
      "z": -14,
      "name": "Rock_Stone"
    },
    {
      "x": -31,
      "y": 19,
      "z": -14,
      "name": "Rock_Stone"
    },
    {
      "x": -31,
      "y": 20,
      "z": -14,
      "name": "Rock_Stone"
    },
    {
      "x": -31,
      "y": 21,
      "z": -14,
      "name": "Rock_Stone"
    },
    {
      "x": -31,
      "y": 22,
      "z": -14,
      "name": "Rock_Stone"
    },
    {
      "x": -31,
      "y": 23,
      "z": -14,
      "name": "Rock_Stone"
    },
    {
      "x": -31,
      "y": 24,
      "z": -14,
      "name": "Rock_Stone"
    },
    {
      "x": -31,
      "y": 25,
      "z": -14,
      "name": "Rock_Stone"
    },
    {
      "x": -31,
      "y": 26,
      "z": -14,
      "name": "Rock_Stone"
    },
    {
      "x": -31,
      "y": 27,
      "z": -14,
      "name": "Rock_Stone"
    },
    {
      "x": -31,
      "y": 28,
      "z": -14,
      "name": "Rock_Stone"
    },
    {
      "x": -31,
      "y": 29,
      "z": -14,
      "name": "Rock_Stone"
    },
    {
      "x": -31,
      "y": 19,
      "z": -13,
      "name": "Rock_Stone"
    },
    {
      "x": -31,
      "y": 20,
      "z": -13,
      "name": "Rock_Stone"
    },
    {
      "x": -31,
      "y": 21,
      "z": -13,
      "name": "Rock_Stone"
    },
    {
      "x": -31,
      "y": 22,
      "z": -13,
      "name": "Rock_Stone"
    },
    {
      "x": -31,
      "y": 23,
      "z": -13,
      "name": "Rock_Stone"
    },
    {
      "x": -31,
      "y": 24,
      "z": -13,
      "name": "Rock_Stone"
    },
    {
      "x": -31,
      "y": 25,
      "z": -13,
      "name": "Rock_Stone"
    },
    {
      "x": -31,
      "y": 26,
      "z": -13,
      "name": "Rock_Stone"
    },
    {
      "x": -31,
      "y": 27,
      "z": -13,
      "name": "Rock_Stone"
    },
    {
      "x": -31,
      "y": 28,
      "z": -13,
      "name": "Rock_Stone"
    },
    {
      "x": -31,
      "y": 23,
      "z": -12,
      "name": "Rock_Stone"
    },
    {
      "x": -31,
      "y": 24,
      "z": -12,
      "name": "Rock_Stone"
    },
    {
      "x": -31,
      "y": 25,
      "z": -12,
      "name": "Rock_Stone"
    },
    {
      "x": -31,
      "y": 26,
      "z": -12,
      "name": "Rock_Stone"
    },
    {
      "x": -31,
      "y": 27,
      "z": -12,
      "name": "Rock_Stone"
    },
    {
      "x": -31,
      "y": 196,
      "z": -2,
      "name": "Rock_Stone"
    },
    {
      "x": -31,
      "y": 197,
      "z": -2,
      "name": "Rock_Stone"
    },
    {
      "x": -30,
      "y": 20,
      "z": -22,
      "name": "Rock_Stone"
    },
    {
      "x": -30,
      "y": 21,
      "z": -22,
      "name": "Rock_Stone"
    },
    {
      "x": -30,
      "y": 22,
      "z": -22,
      "name": "Rock_Stone"
    },
    {
      "x": -30,
      "y": 23,
      "z": -22,
      "name": "Rock_Stone"
    },
    {
      "x": -30,
      "y": 24,
      "z": -22,
      "name": "Rock_Stone"
    },
    {
      "x": -30,
      "y": 25,
      "z": -22,
      "name": "Rock_Stone"
    },
    {
      "x": -30,
      "y": 26,
      "z": -22,
      "name": "Rock_Stone"
    },
    {
      "x": -30,
      "y": 18,
      "z": -21,
      "name": "Rock_Stone"
    },
    {
      "x": -30,
      "y": 19,
      "z": -21,
      "name": "Rock_Stone"
    },
    {
      "x": -30,
      "y": 20,
      "z": -21,
      "name": "Rock_Stone"
    },
    {
      "x": -30,
      "y": 21,
      "z": -21,
      "name": "Rock_Stone"
    },
    {
      "x": -30,
      "y": 22,
      "z": -21,
      "name": "Rock_Stone"
    },
    {
      "x": -30,
      "y": 23,
      "z": -21,
      "name": "Rock_Stone"
    },
    {
      "x": -30,
      "y": 24,
      "z": -21,
      "name": "Rock_Stone"
    },
    {
      "x": -30,
      "y": 25,
      "z": -21,
      "name": "Rock_Stone"
    },
    {
      "x": -30,
      "y": 26,
      "z": -21,
      "name": "Rock_Stone"
    },
    {
      "x": -30,
      "y": 27,
      "z": -21,
      "name": "Rock_Stone"
    },
    {
      "x": -30,
      "y": 16,
      "z": -20,
      "name": "Rock_Stone"
    },
    {
      "x": -30,
      "y": 17,
      "z": -20,
      "name": "Rock_Stone"
    },
    {
      "x": -30,
      "y": 18,
      "z": -20,
      "name": "Rock_Stone"
    },
    {
      "x": -30,
      "y": 19,
      "z": -20,
      "name": "Rock_Stone"
    },
    {
      "x": -30,
      "y": 20,
      "z": -20,
      "name": "Rock_Stone"
    },
    {
      "x": -30,
      "y": 21,
      "z": -20,
      "name": "Rock_Stone"
    },
    {
      "x": -30,
      "y": 22,
      "z": -20,
      "name": "Rock_Stone"
    },
    {
      "x": -30,
      "y": 23,
      "z": -20,
      "name": "Rock_Stone"
    },
    {
      "x": -30,
      "y": 24,
      "z": -20,
      "name": "Rock_Stone"
    },
    {
      "x": -30,
      "y": 25,
      "z": -20,
      "name": "Rock_Stone"
    },
    {
      "x": -30,
      "y": 26,
      "z": -20,
      "name": "Rock_Stone"
    },
    {
      "x": -30,
      "y": 27,
      "z": -20,
      "name": "Rock_Stone"
    },
    {
      "x": -30,
      "y": 28,
      "z": -20,
      "name": "Rock_Stone"
    },
    {
      "x": -30,
      "y": 15,
      "z": -19,
      "name": "Rock_Stone"
    },
    {
      "x": -30,
      "y": 16,
      "z": -19,
      "name": "Rock_Stone"
    },
    {
      "x": -30,
      "y": 17,
      "z": -19,
      "name": "Rock_Stone"
    },
    {
      "x": -30,
      "y": 18,
      "z": -19,
      "name": "Rock_Stone"
    },
    {
      "x": -30,
      "y": 19,
      "z": -19,
      "name": "Rock_Stone"
    },
    {
      "x": -30,
      "y": 20,
      "z": -19,
      "name": "Rock_Stone"
    },
    {
      "x": -30,
      "y": 21,
      "z": -19,
      "name": "Rock_Stone"
    },
    {
      "x": -30,
      "y": 22,
      "z": -19,
      "name": "Rock_Stone"
    },
    {
      "x": -30,
      "y": 23,
      "z": -19,
      "name": "Rock_Stone"
    },
    {
      "x": -30,
      "y": 24,
      "z": -19,
      "name": "Rock_Stone"
    },
    {
      "x": -30,
      "y": 25,
      "z": -19,
      "name": "Rock_Stone"
    },
    {
      "x": -30,
      "y": 26,
      "z": -19,
      "name": "Rock_Stone"
    },
    {
      "x": -30,
      "y": 27,
      "z": -19,
      "name": "Rock_Stone"
    },
    {
      "x": -30,
      "y": 28,
      "z": -19,
      "name": "Rock_Stone"
    },
    {
      "x": -30,
      "y": 29,
      "z": -19,
      "name": "Rock_Stone"
    },
    {
      "x": -30,
      "y": 14,
      "z": -18,
      "name": "Rock_Stone"
    },
    {
      "x": -30,
      "y": 15,
      "z": -18,
      "name": "Rock_Stone"
    },
    {
      "x": -30,
      "y": 16,
      "z": -18,
      "name": "Rock_Stone"
    },
    {
      "x": -30,
      "y": 17,
      "z": -18,
      "name": "Rock_Stone"
    },
    {
      "x": -30,
      "y": 18,
      "z": -18,
      "name": "Rock_Stone"
    },
    {
      "x": -30,
      "y": 19,
      "z": -18,
      "name": "Rock_Stone"
    },
    {
      "x": -30,
      "y": 20,
      "z": -18,
      "name": "Rock_Stone"
    },
    {
      "x": -30,
      "y": 21,
      "z": -18,
      "name": "Rock_Stone"
    },
    {
      "x": -30,
      "y": 22,
      "z": -18,
      "name": "Rock_Stone"
    },
    {
      "x": -30,
      "y": 23,
      "z": -18,
      "name": "Rock_Stone"
    },
    {
      "x": -30,
      "y": 24,
      "z": -18,
      "name": "Rock_Stone"
    },
    {
      "x": -30,
      "y": 25,
      "z": -18,
      "name": "Rock_Stone"
    },
    {
      "x": -30,
      "y": 26,
      "z": -18,
      "name": "Rock_Stone"
    },
    {
      "x": -30,
      "y": 27,
      "z": -18,
      "name": "Rock_Stone"
    },
    {
      "x": -30,
      "y": 28,
      "z": -18,
      "name": "Rock_Stone"
    },
    {
      "x": -30,
      "y": 29,
      "z": -18,
      "name": "Rock_Stone"
    },
    {
      "x": -30,
      "y": 14,
      "z": -17,
      "name": "Rock_Stone"
    },
    {
      "x": -30,
      "y": 15,
      "z": -17,
      "name": "Rock_Stone"
    },
    {
      "x": -30,
      "y": 16,
      "z": -17,
      "name": "Rock_Stone"
    },
    {
      "x": -30,
      "y": 17,
      "z": -17,
      "name": "Rock_Stone"
    },
    {
      "x": -30,
      "y": 18,
      "z": -17,
      "name": "Rock_Stone"
    },
    {
      "x": -30,
      "y": 19,
      "z": -17,
      "name": "Rock_Stone"
    },
    {
      "x": -30,
      "y": 20,
      "z": -17,
      "name": "Rock_Stone"
    },
    {
      "x": -30,
      "y": 21,
      "z": -17,
      "name": "Rock_Stone"
    },
    {
      "x": -30,
      "y": 22,
      "z": -17,
      "name": "Rock_Stone"
    },
    {
      "x": -30,
      "y": 23,
      "z": -17,
      "name": "Rock_Stone"
    },
    {
      "x": -30,
      "y": 24,
      "z": -17,
      "name": "Rock_Stone"
    },
    {
      "x": -30,
      "y": 25,
      "z": -17,
      "name": "Rock_Stone"
    },
    {
      "x": -30,
      "y": 26,
      "z": -17,
      "name": "Rock_Stone"
    },
    {
      "x": -30,
      "y": 27,
      "z": -17,
      "name": "Rock_Stone"
    },
    {
      "x": -30,
      "y": 28,
      "z": -17,
      "name": "Rock_Stone"
    },
    {
      "x": -30,
      "y": 29,
      "z": -17,
      "name": "Rock_Stone"
    },
    {
      "x": -30,
      "y": 30,
      "z": -17,
      "name": "Rock_Stone"
    },
    {
      "x": -30,
      "y": 14,
      "z": -16,
      "name": "Rock_Stone"
    },
    {
      "x": -30,
      "y": 15,
      "z": -16,
      "name": "Rock_Stone"
    },
    {
      "x": -30,
      "y": 16,
      "z": -16,
      "name": "Rock_Stone"
    },
    {
      "x": -30,
      "y": 17,
      "z": -16,
      "name": "Rock_Stone"
    },
    {
      "x": -30,
      "y": 18,
      "z": -16,
      "name": "Rock_Stone"
    },
    {
      "x": -30,
      "y": 19,
      "z": -16,
      "name": "Rock_Stone"
    },
    {
      "x": -30,
      "y": 20,
      "z": -16,
      "name": "Rock_Stone"
    },
    {
      "x": -30,
      "y": 21,
      "z": -16,
      "name": "Rock_Stone"
    },
    {
      "x": -30,
      "y": 22,
      "z": -16,
      "name": "Rock_Stone"
    },
    {
      "x": -30,
      "y": 23,
      "z": -16,
      "name": "Rock_Stone"
    },
    {
      "x": -30,
      "y": 24,
      "z": -16,
      "name": "Rock_Stone"
    },
    {
      "x": -30,
      "y": 25,
      "z": -16,
      "name": "Rock_Stone"
    },
    {
      "x": -30,
      "y": 26,
      "z": -16,
      "name": "Rock_Stone"
    },
    {
      "x": -30,
      "y": 27,
      "z": -16,
      "name": "Rock_Stone"
    },
    {
      "x": -30,
      "y": 28,
      "z": -16,
      "name": "Rock_Stone"
    },
    {
      "x": -30,
      "y": 29,
      "z": -16,
      "name": "Rock_Stone"
    },
    {
      "x": -30,
      "y": 30,
      "z": -16,
      "name": "Rock_Stone"
    },
    {
      "x": -30,
      "y": 14,
      "z": -15,
      "name": "Rock_Stone"
    },
    {
      "x": -30,
      "y": 15,
      "z": -15,
      "name": "Rock_Stone"
    },
    {
      "x": -30,
      "y": 16,
      "z": -15,
      "name": "Rock_Stone"
    },
    {
      "x": -30,
      "y": 17,
      "z": -15,
      "name": "Rock_Stone"
    },
    {
      "x": -30,
      "y": 18,
      "z": -15,
      "name": "Rock_Stone"
    },
    {
      "x": -30,
      "y": 19,
      "z": -15,
      "name": "Rock_Stone"
    },
    {
      "x": -30,
      "y": 20,
      "z": -15,
      "name": "Rock_Stone"
    },
    {
      "x": -30,
      "y": 21,
      "z": -15,
      "name": "Rock_Stone"
    },
    {
      "x": -30,
      "y": 22,
      "z": -15,
      "name": "Rock_Stone"
    },
    {
      "x": -30,
      "y": 23,
      "z": -15,
      "name": "Rock_Stone"
    },
    {
      "x": -30,
      "y": 24,
      "z": -15,
      "name": "Rock_Stone"
    },
    {
      "x": -30,
      "y": 25,
      "z": -15,
      "name": "Rock_Stone"
    },
    {
      "x": -30,
      "y": 26,
      "z": -15,
      "name": "Rock_Stone"
    },
    {
      "x": -30,
      "y": 27,
      "z": -15,
      "name": "Rock_Stone"
    },
    {
      "x": -30,
      "y": 28,
      "z": -15,
      "name": "Rock_Stone"
    },
    {
      "x": -30,
      "y": 29,
      "z": -15,
      "name": "Rock_Stone"
    },
    {
      "x": -30,
      "y": 202,
      "z": -15,
      "name": "Rock_Stone"
    },
    {
      "x": -30,
      "y": 15,
      "z": -14,
      "name": "Rock_Stone"
    },
    {
      "x": -30,
      "y": 16,
      "z": -14,
      "name": "Rock_Stone"
    },
    {
      "x": -30,
      "y": 17,
      "z": -14,
      "name": "Rock_Stone"
    },
    {
      "x": -30,
      "y": 18,
      "z": -14,
      "name": "Rock_Stone"
    },
    {
      "x": -30,
      "y": 19,
      "z": -14,
      "name": "Rock_Stone"
    },
    {
      "x": -30,
      "y": 20,
      "z": -14,
      "name": "Rock_Stone"
    },
    {
      "x": -30,
      "y": 21,
      "z": -14,
      "name": "Rock_Stone"
    },
    {
      "x": -30,
      "y": 22,
      "z": -14,
      "name": "Rock_Stone"
    },
    {
      "x": -30,
      "y": 23,
      "z": -14,
      "name": "Rock_Stone"
    },
    {
      "x": -30,
      "y": 24,
      "z": -14,
      "name": "Rock_Stone"
    },
    {
      "x": -30,
      "y": 25,
      "z": -14,
      "name": "Rock_Stone"
    },
    {
      "x": -30,
      "y": 26,
      "z": -14,
      "name": "Rock_Stone"
    },
    {
      "x": -30,
      "y": 27,
      "z": -14,
      "name": "Rock_Stone"
    },
    {
      "x": -30,
      "y": 28,
      "z": -14,
      "name": "Rock_Stone"
    },
    {
      "x": -30,
      "y": 29,
      "z": -14,
      "name": "Rock_Stone"
    },
    {
      "x": -30,
      "y": 18,
      "z": -13,
      "name": "Rock_Stone"
    },
    {
      "x": -30,
      "y": 19,
      "z": -13,
      "name": "Rock_Stone"
    },
    {
      "x": -30,
      "y": 20,
      "z": -13,
      "name": "Rock_Stone"
    },
    {
      "x": -30,
      "y": 21,
      "z": -13,
      "name": "Rock_Stone"
    },
    {
      "x": -30,
      "y": 22,
      "z": -13,
      "name": "Rock_Stone"
    },
    {
      "x": -30,
      "y": 23,
      "z": -13,
      "name": "Rock_Stone"
    },
    {
      "x": -30,
      "y": 24,
      "z": -13,
      "name": "Rock_Stone"
    },
    {
      "x": -30,
      "y": 25,
      "z": -13,
      "name": "Rock_Stone"
    },
    {
      "x": -30,
      "y": 26,
      "z": -13,
      "name": "Rock_Stone"
    },
    {
      "x": -30,
      "y": 27,
      "z": -13,
      "name": "Rock_Stone"
    },
    {
      "x": -30,
      "y": 28,
      "z": -13,
      "name": "Rock_Stone"
    },
    {
      "x": -30,
      "y": 29,
      "z": -13,
      "name": "Rock_Stone"
    },
    {
      "x": -30,
      "y": 22,
      "z": -12,
      "name": "Rock_Stone"
    },
    {
      "x": -30,
      "y": 23,
      "z": -12,
      "name": "Rock_Stone"
    },
    {
      "x": -30,
      "y": 24,
      "z": -12,
      "name": "Rock_Stone"
    },
    {
      "x": -30,
      "y": 25,
      "z": -12,
      "name": "Rock_Stone"
    },
    {
      "x": -30,
      "y": 26,
      "z": -12,
      "name": "Rock_Stone"
    },
    {
      "x": -30,
      "y": 27,
      "z": -12,
      "name": "Rock_Stone"
    },
    {
      "x": -30,
      "y": 28,
      "z": -12,
      "name": "Rock_Stone"
    },
    {
      "x": -30,
      "y": 25,
      "z": -11,
      "name": "Rock_Stone"
    },
    {
      "x": -30,
      "y": 26,
      "z": -11,
      "name": "Rock_Stone"
    },
    {
      "x": -30,
      "y": 196,
      "z": -2,
      "name": "Rock_Stone"
    },
    {
      "x": -29,
      "y": 21,
      "z": -22,
      "name": "Rock_Stone"
    },
    {
      "x": -29,
      "y": 22,
      "z": -22,
      "name": "Rock_Stone"
    },
    {
      "x": -29,
      "y": 23,
      "z": -22,
      "name": "Rock_Stone"
    },
    {
      "x": -29,
      "y": 24,
      "z": -22,
      "name": "Rock_Stone"
    },
    {
      "x": -29,
      "y": 25,
      "z": -22,
      "name": "Rock_Stone"
    },
    {
      "x": -29,
      "y": 26,
      "z": -22,
      "name": "Rock_Stone"
    },
    {
      "x": -29,
      "y": 18,
      "z": -21,
      "name": "Rock_Stone"
    },
    {
      "x": -29,
      "y": 19,
      "z": -21,
      "name": "Rock_Stone"
    },
    {
      "x": -29,
      "y": 20,
      "z": -21,
      "name": "Rock_Stone"
    },
    {
      "x": -29,
      "y": 21,
      "z": -21,
      "name": "Rock_Stone"
    },
    {
      "x": -29,
      "y": 22,
      "z": -21,
      "name": "Rock_Stone"
    },
    {
      "x": -29,
      "y": 23,
      "z": -21,
      "name": "Rock_Stone"
    },
    {
      "x": -29,
      "y": 24,
      "z": -21,
      "name": "Rock_Stone"
    },
    {
      "x": -29,
      "y": 25,
      "z": -21,
      "name": "Rock_Stone"
    },
    {
      "x": -29,
      "y": 26,
      "z": -21,
      "name": "Rock_Stone"
    },
    {
      "x": -29,
      "y": 27,
      "z": -21,
      "name": "Rock_Stone"
    },
    {
      "x": -29,
      "y": 16,
      "z": -20,
      "name": "Rock_Stone"
    },
    {
      "x": -29,
      "y": 17,
      "z": -20,
      "name": "Rock_Stone"
    },
    {
      "x": -29,
      "y": 18,
      "z": -20,
      "name": "Rock_Stone"
    },
    {
      "x": -29,
      "y": 19,
      "z": -20,
      "name": "Rock_Stone"
    },
    {
      "x": -29,
      "y": 20,
      "z": -20,
      "name": "Rock_Stone"
    },
    {
      "x": -29,
      "y": 21,
      "z": -20,
      "name": "Rock_Stone"
    },
    {
      "x": -29,
      "y": 22,
      "z": -20,
      "name": "Rock_Stone"
    },
    {
      "x": -29,
      "y": 23,
      "z": -20,
      "name": "Rock_Stone"
    },
    {
      "x": -29,
      "y": 24,
      "z": -20,
      "name": "Rock_Stone"
    },
    {
      "x": -29,
      "y": 25,
      "z": -20,
      "name": "Rock_Stone"
    },
    {
      "x": -29,
      "y": 26,
      "z": -20,
      "name": "Rock_Stone"
    },
    {
      "x": -29,
      "y": 27,
      "z": -20,
      "name": "Rock_Stone"
    },
    {
      "x": -29,
      "y": 28,
      "z": -20,
      "name": "Rock_Stone"
    },
    {
      "x": -29,
      "y": 15,
      "z": -19,
      "name": "Rock_Stone"
    },
    {
      "x": -29,
      "y": 16,
      "z": -19,
      "name": "Rock_Stone"
    },
    {
      "x": -29,
      "y": 17,
      "z": -19,
      "name": "Rock_Stone"
    },
    {
      "x": -29,
      "y": 18,
      "z": -19,
      "name": "Rock_Stone"
    },
    {
      "x": -29,
      "y": 19,
      "z": -19,
      "name": "Rock_Stone"
    },
    {
      "x": -29,
      "y": 20,
      "z": -19,
      "name": "Rock_Stone"
    },
    {
      "x": -29,
      "y": 21,
      "z": -19,
      "name": "Rock_Stone"
    },
    {
      "x": -29,
      "y": 22,
      "z": -19,
      "name": "Rock_Stone"
    },
    {
      "x": -29,
      "y": 23,
      "z": -19,
      "name": "Rock_Stone"
    },
    {
      "x": -29,
      "y": 24,
      "z": -19,
      "name": "Rock_Stone"
    },
    {
      "x": -29,
      "y": 25,
      "z": -19,
      "name": "Rock_Stone"
    },
    {
      "x": -29,
      "y": 26,
      "z": -19,
      "name": "Rock_Stone"
    },
    {
      "x": -29,
      "y": 27,
      "z": -19,
      "name": "Rock_Stone"
    },
    {
      "x": -29,
      "y": 28,
      "z": -19,
      "name": "Rock_Stone"
    },
    {
      "x": -29,
      "y": 29,
      "z": -19,
      "name": "Rock_Stone"
    },
    {
      "x": -29,
      "y": 14,
      "z": -18,
      "name": "Rock_Stone"
    },
    {
      "x": -29,
      "y": 15,
      "z": -18,
      "name": "Rock_Stone"
    },
    {
      "x": -29,
      "y": 16,
      "z": -18,
      "name": "Rock_Stone"
    },
    {
      "x": -29,
      "y": 17,
      "z": -18,
      "name": "Rock_Stone"
    },
    {
      "x": -29,
      "y": 18,
      "z": -18,
      "name": "Rock_Stone"
    },
    {
      "x": -29,
      "y": 19,
      "z": -18,
      "name": "Rock_Stone"
    },
    {
      "x": -29,
      "y": 20,
      "z": -18,
      "name": "Rock_Stone"
    },
    {
      "x": -29,
      "y": 21,
      "z": -18,
      "name": "Rock_Stone"
    },
    {
      "x": -29,
      "y": 22,
      "z": -18,
      "name": "Rock_Stone"
    },
    {
      "x": -29,
      "y": 23,
      "z": -18,
      "name": "Rock_Stone"
    },
    {
      "x": -29,
      "y": 24,
      "z": -18,
      "name": "Rock_Stone"
    },
    {
      "x": -29,
      "y": 25,
      "z": -18,
      "name": "Rock_Stone"
    },
    {
      "x": -29,
      "y": 26,
      "z": -18,
      "name": "Rock_Stone"
    },
    {
      "x": -29,
      "y": 27,
      "z": -18,
      "name": "Rock_Stone"
    },
    {
      "x": -29,
      "y": 28,
      "z": -18,
      "name": "Rock_Stone"
    },
    {
      "x": -29,
      "y": 29,
      "z": -18,
      "name": "Rock_Stone"
    },
    {
      "x": -29,
      "y": 30,
      "z": -18,
      "name": "Rock_Stone"
    },
    {
      "x": -29,
      "y": 14,
      "z": -17,
      "name": "Rock_Stone"
    },
    {
      "x": -29,
      "y": 15,
      "z": -17,
      "name": "Rock_Stone"
    },
    {
      "x": -29,
      "y": 16,
      "z": -17,
      "name": "Rock_Stone"
    },
    {
      "x": -29,
      "y": 17,
      "z": -17,
      "name": "Rock_Stone"
    },
    {
      "x": -29,
      "y": 18,
      "z": -17,
      "name": "Rock_Stone"
    },
    {
      "x": -29,
      "y": 19,
      "z": -17,
      "name": "Rock_Stone"
    },
    {
      "x": -29,
      "y": 20,
      "z": -17,
      "name": "Rock_Stone"
    },
    {
      "x": -29,
      "y": 21,
      "z": -17,
      "name": "Rock_Stone"
    },
    {
      "x": -29,
      "y": 22,
      "z": -17,
      "name": "Rock_Stone"
    },
    {
      "x": -29,
      "y": 23,
      "z": -17,
      "name": "Rock_Stone"
    },
    {
      "x": -29,
      "y": 24,
      "z": -17,
      "name": "Rock_Stone"
    },
    {
      "x": -29,
      "y": 25,
      "z": -17,
      "name": "Rock_Stone"
    },
    {
      "x": -29,
      "y": 26,
      "z": -17,
      "name": "Rock_Stone"
    },
    {
      "x": -29,
      "y": 27,
      "z": -17,
      "name": "Rock_Stone"
    },
    {
      "x": -29,
      "y": 28,
      "z": -17,
      "name": "Rock_Stone"
    },
    {
      "x": -29,
      "y": 29,
      "z": -17,
      "name": "Rock_Stone"
    },
    {
      "x": -29,
      "y": 30,
      "z": -17,
      "name": "Rock_Stone"
    },
    {
      "x": -29,
      "y": 13,
      "z": -16,
      "name": "Rock_Stone"
    },
    {
      "x": -29,
      "y": 14,
      "z": -16,
      "name": "Rock_Stone"
    },
    {
      "x": -29,
      "y": 15,
      "z": -16,
      "name": "Rock_Stone"
    },
    {
      "x": -29,
      "y": 16,
      "z": -16,
      "name": "Rock_Stone"
    },
    {
      "x": -29,
      "y": 17,
      "z": -16,
      "name": "Rock_Stone"
    },
    {
      "x": -29,
      "y": 18,
      "z": -16,
      "name": "Rock_Stone"
    },
    {
      "x": -29,
      "y": 19,
      "z": -16,
      "name": "Rock_Stone"
    },
    {
      "x": -29,
      "y": 20,
      "z": -16,
      "name": "Rock_Stone"
    },
    {
      "x": -29,
      "y": 21,
      "z": -16,
      "name": "Rock_Stone"
    },
    {
      "x": -29,
      "y": 22,
      "z": -16,
      "name": "Rock_Stone"
    },
    {
      "x": -29,
      "y": 23,
      "z": -16,
      "name": "Rock_Stone"
    },
    {
      "x": -29,
      "y": 24,
      "z": -16,
      "name": "Rock_Stone"
    },
    {
      "x": -29,
      "y": 25,
      "z": -16,
      "name": "Rock_Stone"
    },
    {
      "x": -29,
      "y": 26,
      "z": -16,
      "name": "Rock_Stone"
    },
    {
      "x": -29,
      "y": 27,
      "z": -16,
      "name": "Rock_Stone"
    },
    {
      "x": -29,
      "y": 28,
      "z": -16,
      "name": "Rock_Stone"
    },
    {
      "x": -29,
      "y": 29,
      "z": -16,
      "name": "Rock_Stone"
    },
    {
      "x": -29,
      "y": 30,
      "z": -16,
      "name": "Rock_Stone"
    },
    {
      "x": -29,
      "y": 14,
      "z": -15,
      "name": "Rock_Stone"
    },
    {
      "x": -29,
      "y": 15,
      "z": -15,
      "name": "Rock_Stone"
    },
    {
      "x": -29,
      "y": 16,
      "z": -15,
      "name": "Rock_Stone"
    },
    {
      "x": -29,
      "y": 17,
      "z": -15,
      "name": "Rock_Stone"
    },
    {
      "x": -29,
      "y": 18,
      "z": -15,
      "name": "Rock_Stone"
    },
    {
      "x": -29,
      "y": 19,
      "z": -15,
      "name": "Rock_Stone"
    },
    {
      "x": -29,
      "y": 20,
      "z": -15,
      "name": "Rock_Stone"
    },
    {
      "x": -29,
      "y": 21,
      "z": -15,
      "name": "Rock_Stone"
    },
    {
      "x": -29,
      "y": 22,
      "z": -15,
      "name": "Rock_Stone"
    },
    {
      "x": -29,
      "y": 23,
      "z": -15,
      "name": "Rock_Stone"
    },
    {
      "x": -29,
      "y": 24,
      "z": -15,
      "name": "Rock_Stone"
    },
    {
      "x": -29,
      "y": 25,
      "z": -15,
      "name": "Rock_Stone"
    },
    {
      "x": -29,
      "y": 26,
      "z": -15,
      "name": "Rock_Stone"
    },
    {
      "x": -29,
      "y": 27,
      "z": -15,
      "name": "Rock_Stone"
    },
    {
      "x": -29,
      "y": 28,
      "z": -15,
      "name": "Rock_Stone"
    },
    {
      "x": -29,
      "y": 29,
      "z": -15,
      "name": "Rock_Stone"
    },
    {
      "x": -29,
      "y": 30,
      "z": -15,
      "name": "Rock_Stone"
    },
    {
      "x": -29,
      "y": 14,
      "z": -14,
      "name": "Rock_Stone"
    },
    {
      "x": -29,
      "y": 15,
      "z": -14,
      "name": "Rock_Stone"
    },
    {
      "x": -29,
      "y": 16,
      "z": -14,
      "name": "Rock_Stone"
    },
    {
      "x": -29,
      "y": 17,
      "z": -14,
      "name": "Rock_Stone"
    },
    {
      "x": -29,
      "y": 18,
      "z": -14,
      "name": "Rock_Stone"
    },
    {
      "x": -29,
      "y": 19,
      "z": -14,
      "name": "Rock_Stone"
    },
    {
      "x": -29,
      "y": 20,
      "z": -14,
      "name": "Rock_Stone"
    },
    {
      "x": -29,
      "y": 21,
      "z": -14,
      "name": "Rock_Stone"
    },
    {
      "x": -29,
      "y": 22,
      "z": -14,
      "name": "Rock_Stone"
    },
    {
      "x": -29,
      "y": 23,
      "z": -14,
      "name": "Rock_Stone"
    },
    {
      "x": -29,
      "y": 24,
      "z": -14,
      "name": "Rock_Stone"
    },
    {
      "x": -29,
      "y": 25,
      "z": -14,
      "name": "Rock_Stone"
    },
    {
      "x": -29,
      "y": 26,
      "z": -14,
      "name": "Rock_Stone"
    },
    {
      "x": -29,
      "y": 27,
      "z": -14,
      "name": "Rock_Stone"
    },
    {
      "x": -29,
      "y": 28,
      "z": -14,
      "name": "Rock_Stone"
    },
    {
      "x": -29,
      "y": 29,
      "z": -14,
      "name": "Rock_Stone"
    },
    {
      "x": -29,
      "y": 30,
      "z": -14,
      "name": "Rock_Stone"
    },
    {
      "x": -29,
      "y": 201,
      "z": -14,
      "name": "Rock_Stone"
    },
    {
      "x": -29,
      "y": 202,
      "z": -14,
      "name": "Rock_Stone"
    },
    {
      "x": -29,
      "y": 15,
      "z": -13,
      "name": "Rock_Stone"
    },
    {
      "x": -29,
      "y": 16,
      "z": -13,
      "name": "Rock_Stone"
    },
    {
      "x": -29,
      "y": 17,
      "z": -13,
      "name": "Rock_Stone"
    },
    {
      "x": -29,
      "y": 18,
      "z": -13,
      "name": "Rock_Stone"
    },
    {
      "x": -29,
      "y": 19,
      "z": -13,
      "name": "Rock_Stone"
    },
    {
      "x": -29,
      "y": 20,
      "z": -13,
      "name": "Rock_Stone"
    },
    {
      "x": -29,
      "y": 21,
      "z": -13,
      "name": "Rock_Stone"
    },
    {
      "x": -29,
      "y": 22,
      "z": -13,
      "name": "Rock_Stone"
    },
    {
      "x": -29,
      "y": 23,
      "z": -13,
      "name": "Rock_Stone"
    },
    {
      "x": -29,
      "y": 24,
      "z": -13,
      "name": "Rock_Stone"
    },
    {
      "x": -29,
      "y": 25,
      "z": -13,
      "name": "Rock_Stone"
    },
    {
      "x": -29,
      "y": 26,
      "z": -13,
      "name": "Rock_Stone"
    },
    {
      "x": -29,
      "y": 27,
      "z": -13,
      "name": "Rock_Stone"
    },
    {
      "x": -29,
      "y": 28,
      "z": -13,
      "name": "Rock_Stone"
    },
    {
      "x": -29,
      "y": 29,
      "z": -13,
      "name": "Rock_Stone"
    },
    {
      "x": -29,
      "y": 200,
      "z": -13,
      "name": "Rock_Stone"
    },
    {
      "x": -29,
      "y": 19,
      "z": -12,
      "name": "Rock_Stone"
    },
    {
      "x": -29,
      "y": 20,
      "z": -12,
      "name": "Rock_Stone"
    },
    {
      "x": -29,
      "y": 21,
      "z": -12,
      "name": "Rock_Stone"
    },
    {
      "x": -29,
      "y": 22,
      "z": -12,
      "name": "Rock_Stone"
    },
    {
      "x": -29,
      "y": 23,
      "z": -12,
      "name": "Rock_Stone"
    },
    {
      "x": -29,
      "y": 24,
      "z": -12,
      "name": "Rock_Stone"
    },
    {
      "x": -29,
      "y": 25,
      "z": -12,
      "name": "Rock_Stone"
    },
    {
      "x": -29,
      "y": 26,
      "z": -12,
      "name": "Rock_Stone"
    },
    {
      "x": -29,
      "y": 27,
      "z": -12,
      "name": "Rock_Stone"
    },
    {
      "x": -29,
      "y": 28,
      "z": -12,
      "name": "Rock_Stone"
    },
    {
      "x": -29,
      "y": 29,
      "z": -12,
      "name": "Rock_Stone"
    },
    {
      "x": -29,
      "y": 23,
      "z": -11,
      "name": "Rock_Stone"
    },
    {
      "x": -29,
      "y": 24,
      "z": -11,
      "name": "Rock_Stone"
    },
    {
      "x": -29,
      "y": 25,
      "z": -11,
      "name": "Rock_Stone"
    },
    {
      "x": -29,
      "y": 26,
      "z": -11,
      "name": "Rock_Stone"
    },
    {
      "x": -29,
      "y": 27,
      "z": -11,
      "name": "Rock_Stone"
    },
    {
      "x": -29,
      "y": 195,
      "z": -2,
      "name": "Rock_Stone"
    },
    {
      "x": -29,
      "y": 196,
      "z": -2,
      "name": "Rock_Stone"
    },
    {
      "x": -29,
      "y": 196,
      "z": -1,
      "name": "Rock_Stone"
    },
    {
      "x": -28,
      "y": 22,
      "z": -22,
      "name": "Rock_Stone"
    },
    {
      "x": -28,
      "y": 23,
      "z": -22,
      "name": "Rock_Stone"
    },
    {
      "x": -28,
      "y": 24,
      "z": -22,
      "name": "Rock_Stone"
    },
    {
      "x": -28,
      "y": 25,
      "z": -22,
      "name": "Rock_Stone"
    },
    {
      "x": -28,
      "y": 26,
      "z": -22,
      "name": "Rock_Stone"
    },
    {
      "x": -28,
      "y": 20,
      "z": -21,
      "name": "Rock_Stone"
    },
    {
      "x": -28,
      "y": 21,
      "z": -21,
      "name": "Rock_Stone"
    },
    {
      "x": -28,
      "y": 22,
      "z": -21,
      "name": "Rock_Stone"
    },
    {
      "x": -28,
      "y": 23,
      "z": -21,
      "name": "Rock_Stone"
    },
    {
      "x": -28,
      "y": 24,
      "z": -21,
      "name": "Rock_Stone"
    },
    {
      "x": -28,
      "y": 25,
      "z": -21,
      "name": "Rock_Stone"
    },
    {
      "x": -28,
      "y": 26,
      "z": -21,
      "name": "Rock_Stone"
    },
    {
      "x": -28,
      "y": 27,
      "z": -21,
      "name": "Rock_Stone"
    },
    {
      "x": -28,
      "y": 17,
      "z": -20,
      "name": "Rock_Stone"
    },
    {
      "x": -28,
      "y": 18,
      "z": -20,
      "name": "Rock_Stone"
    },
    {
      "x": -28,
      "y": 19,
      "z": -20,
      "name": "Rock_Stone"
    },
    {
      "x": -28,
      "y": 20,
      "z": -20,
      "name": "Rock_Stone"
    },
    {
      "x": -28,
      "y": 21,
      "z": -20,
      "name": "Rock_Stone"
    },
    {
      "x": -28,
      "y": 22,
      "z": -20,
      "name": "Rock_Stone"
    },
    {
      "x": -28,
      "y": 23,
      "z": -20,
      "name": "Rock_Stone"
    },
    {
      "x": -28,
      "y": 24,
      "z": -20,
      "name": "Rock_Stone"
    },
    {
      "x": -28,
      "y": 25,
      "z": -20,
      "name": "Rock_Stone"
    },
    {
      "x": -28,
      "y": 26,
      "z": -20,
      "name": "Rock_Stone"
    },
    {
      "x": -28,
      "y": 27,
      "z": -20,
      "name": "Rock_Stone"
    },
    {
      "x": -28,
      "y": 28,
      "z": -20,
      "name": "Rock_Stone"
    },
    {
      "x": -28,
      "y": 15,
      "z": -19,
      "name": "Rock_Stone"
    },
    {
      "x": -28,
      "y": 16,
      "z": -19,
      "name": "Rock_Stone"
    },
    {
      "x": -28,
      "y": 17,
      "z": -19,
      "name": "Rock_Stone"
    },
    {
      "x": -28,
      "y": 18,
      "z": -19,
      "name": "Rock_Stone"
    },
    {
      "x": -28,
      "y": 19,
      "z": -19,
      "name": "Rock_Stone"
    },
    {
      "x": -28,
      "y": 20,
      "z": -19,
      "name": "Rock_Stone"
    },
    {
      "x": -28,
      "y": 21,
      "z": -19,
      "name": "Rock_Stone"
    },
    {
      "x": -28,
      "y": 22,
      "z": -19,
      "name": "Rock_Stone"
    },
    {
      "x": -28,
      "y": 23,
      "z": -19,
      "name": "Rock_Stone"
    },
    {
      "x": -28,
      "y": 24,
      "z": -19,
      "name": "Rock_Stone"
    },
    {
      "x": -28,
      "y": 25,
      "z": -19,
      "name": "Rock_Stone"
    },
    {
      "x": -28,
      "y": 26,
      "z": -19,
      "name": "Rock_Stone"
    },
    {
      "x": -28,
      "y": 27,
      "z": -19,
      "name": "Rock_Stone"
    },
    {
      "x": -28,
      "y": 28,
      "z": -19,
      "name": "Rock_Stone"
    },
    {
      "x": -28,
      "y": 29,
      "z": -19,
      "name": "Rock_Stone"
    },
    {
      "x": -28,
      "y": 14,
      "z": -18,
      "name": "Rock_Stone"
    },
    {
      "x": -28,
      "y": 15,
      "z": -18,
      "name": "Rock_Stone"
    },
    {
      "x": -28,
      "y": 16,
      "z": -18,
      "name": "Rock_Stone"
    },
    {
      "x": -28,
      "y": 17,
      "z": -18,
      "name": "Rock_Stone"
    },
    {
      "x": -28,
      "y": 18,
      "z": -18,
      "name": "Rock_Stone"
    },
    {
      "x": -28,
      "y": 19,
      "z": -18,
      "name": "Rock_Stone"
    },
    {
      "x": -28,
      "y": 20,
      "z": -18,
      "name": "Rock_Stone"
    },
    {
      "x": -28,
      "y": 21,
      "z": -18,
      "name": "Rock_Stone"
    },
    {
      "x": -28,
      "y": 22,
      "z": -18,
      "name": "Rock_Stone"
    },
    {
      "x": -28,
      "y": 23,
      "z": -18,
      "name": "Rock_Stone"
    },
    {
      "x": -28,
      "y": 24,
      "z": -18,
      "name": "Rock_Stone"
    },
    {
      "x": -28,
      "y": 25,
      "z": -18,
      "name": "Rock_Stone"
    },
    {
      "x": -28,
      "y": 26,
      "z": -18,
      "name": "Rock_Stone"
    },
    {
      "x": -28,
      "y": 27,
      "z": -18,
      "name": "Rock_Stone"
    },
    {
      "x": -28,
      "y": 28,
      "z": -18,
      "name": "Rock_Stone"
    },
    {
      "x": -28,
      "y": 29,
      "z": -18,
      "name": "Rock_Stone"
    },
    {
      "x": -28,
      "y": 30,
      "z": -18,
      "name": "Rock_Stone"
    },
    {
      "x": -28,
      "y": 14,
      "z": -17,
      "name": "Rock_Stone"
    },
    {
      "x": -28,
      "y": 15,
      "z": -17,
      "name": "Rock_Stone"
    },
    {
      "x": -28,
      "y": 16,
      "z": -17,
      "name": "Rock_Stone"
    },
    {
      "x": -28,
      "y": 17,
      "z": -17,
      "name": "Rock_Stone"
    },
    {
      "x": -28,
      "y": 18,
      "z": -17,
      "name": "Rock_Stone"
    },
    {
      "x": -28,
      "y": 19,
      "z": -17,
      "name": "Rock_Stone"
    },
    {
      "x": -28,
      "y": 20,
      "z": -17,
      "name": "Rock_Stone"
    },
    {
      "x": -28,
      "y": 21,
      "z": -17,
      "name": "Rock_Stone"
    },
    {
      "x": -28,
      "y": 22,
      "z": -17,
      "name": "Rock_Stone"
    },
    {
      "x": -28,
      "y": 23,
      "z": -17,
      "name": "Rock_Stone"
    },
    {
      "x": -28,
      "y": 24,
      "z": -17,
      "name": "Rock_Stone"
    },
    {
      "x": -28,
      "y": 25,
      "z": -17,
      "name": "Rock_Stone"
    },
    {
      "x": -28,
      "y": 26,
      "z": -17,
      "name": "Rock_Stone"
    },
    {
      "x": -28,
      "y": 27,
      "z": -17,
      "name": "Rock_Stone"
    },
    {
      "x": -28,
      "y": 28,
      "z": -17,
      "name": "Rock_Stone"
    },
    {
      "x": -28,
      "y": 29,
      "z": -17,
      "name": "Rock_Stone"
    },
    {
      "x": -28,
      "y": 30,
      "z": -17,
      "name": "Rock_Stone"
    },
    {
      "x": -28,
      "y": 13,
      "z": -16,
      "name": "Rock_Stone"
    },
    {
      "x": -28,
      "y": 14,
      "z": -16,
      "name": "Rock_Stone"
    },
    {
      "x": -28,
      "y": 15,
      "z": -16,
      "name": "Rock_Stone"
    },
    {
      "x": -28,
      "y": 16,
      "z": -16,
      "name": "Rock_Stone"
    },
    {
      "x": -28,
      "y": 17,
      "z": -16,
      "name": "Rock_Stone"
    },
    {
      "x": -28,
      "y": 18,
      "z": -16,
      "name": "Rock_Stone"
    },
    {
      "x": -28,
      "y": 19,
      "z": -16,
      "name": "Rock_Stone"
    },
    {
      "x": -28,
      "y": 20,
      "z": -16,
      "name": "Rock_Stone"
    },
    {
      "x": -28,
      "y": 21,
      "z": -16,
      "name": "Rock_Stone"
    },
    {
      "x": -28,
      "y": 22,
      "z": -16,
      "name": "Rock_Stone"
    },
    {
      "x": -28,
      "y": 23,
      "z": -16,
      "name": "Rock_Stone"
    },
    {
      "x": -28,
      "y": 24,
      "z": -16,
      "name": "Rock_Stone"
    },
    {
      "x": -28,
      "y": 25,
      "z": -16,
      "name": "Rock_Stone"
    },
    {
      "x": -28,
      "y": 26,
      "z": -16,
      "name": "Rock_Stone"
    },
    {
      "x": -28,
      "y": 27,
      "z": -16,
      "name": "Rock_Stone"
    },
    {
      "x": -28,
      "y": 28,
      "z": -16,
      "name": "Rock_Stone"
    },
    {
      "x": -28,
      "y": 29,
      "z": -16,
      "name": "Rock_Stone"
    },
    {
      "x": -28,
      "y": 30,
      "z": -16,
      "name": "Rock_Stone"
    },
    {
      "x": -28,
      "y": 13,
      "z": -15,
      "name": "Rock_Stone"
    },
    {
      "x": -28,
      "y": 14,
      "z": -15,
      "name": "Rock_Stone"
    },
    {
      "x": -28,
      "y": 15,
      "z": -15,
      "name": "Rock_Stone"
    },
    {
      "x": -28,
      "y": 16,
      "z": -15,
      "name": "Rock_Stone"
    },
    {
      "x": -28,
      "y": 17,
      "z": -15,
      "name": "Rock_Stone"
    },
    {
      "x": -28,
      "y": 18,
      "z": -15,
      "name": "Rock_Stone"
    },
    {
      "x": -28,
      "y": 19,
      "z": -15,
      "name": "Rock_Stone"
    },
    {
      "x": -28,
      "y": 20,
      "z": -15,
      "name": "Rock_Stone"
    },
    {
      "x": -28,
      "y": 21,
      "z": -15,
      "name": "Rock_Stone"
    },
    {
      "x": -28,
      "y": 22,
      "z": -15,
      "name": "Rock_Stone"
    },
    {
      "x": -28,
      "y": 23,
      "z": -15,
      "name": "Rock_Stone"
    },
    {
      "x": -28,
      "y": 24,
      "z": -15,
      "name": "Rock_Stone"
    },
    {
      "x": -28,
      "y": 25,
      "z": -15,
      "name": "Rock_Stone"
    },
    {
      "x": -28,
      "y": 26,
      "z": -15,
      "name": "Rock_Stone"
    },
    {
      "x": -28,
      "y": 27,
      "z": -15,
      "name": "Rock_Stone"
    },
    {
      "x": -28,
      "y": 28,
      "z": -15,
      "name": "Rock_Stone"
    },
    {
      "x": -28,
      "y": 29,
      "z": -15,
      "name": "Rock_Stone"
    },
    {
      "x": -28,
      "y": 30,
      "z": -15,
      "name": "Rock_Stone"
    },
    {
      "x": -28,
      "y": 13,
      "z": -14,
      "name": "Rock_Stone"
    },
    {
      "x": -28,
      "y": 14,
      "z": -14,
      "name": "Rock_Stone"
    },
    {
      "x": -28,
      "y": 15,
      "z": -14,
      "name": "Rock_Stone"
    },
    {
      "x": -28,
      "y": 16,
      "z": -14,
      "name": "Rock_Stone"
    },
    {
      "x": -28,
      "y": 17,
      "z": -14,
      "name": "Rock_Stone"
    },
    {
      "x": -28,
      "y": 18,
      "z": -14,
      "name": "Rock_Stone"
    },
    {
      "x": -28,
      "y": 19,
      "z": -14,
      "name": "Rock_Stone"
    },
    {
      "x": -28,
      "y": 20,
      "z": -14,
      "name": "Rock_Stone"
    },
    {
      "x": -28,
      "y": 21,
      "z": -14,
      "name": "Rock_Stone"
    },
    {
      "x": -28,
      "y": 22,
      "z": -14,
      "name": "Rock_Stone"
    },
    {
      "x": -28,
      "y": 23,
      "z": -14,
      "name": "Rock_Stone"
    },
    {
      "x": -28,
      "y": 24,
      "z": -14,
      "name": "Rock_Stone"
    },
    {
      "x": -28,
      "y": 25,
      "z": -14,
      "name": "Rock_Stone"
    },
    {
      "x": -28,
      "y": 26,
      "z": -14,
      "name": "Rock_Stone"
    },
    {
      "x": -28,
      "y": 27,
      "z": -14,
      "name": "Rock_Stone"
    },
    {
      "x": -28,
      "y": 28,
      "z": -14,
      "name": "Rock_Stone"
    },
    {
      "x": -28,
      "y": 29,
      "z": -14,
      "name": "Rock_Stone"
    },
    {
      "x": -28,
      "y": 30,
      "z": -14,
      "name": "Rock_Stone"
    },
    {
      "x": -28,
      "y": 201,
      "z": -14,
      "name": "Rock_Stone"
    },
    {
      "x": -28,
      "y": 13,
      "z": -13,
      "name": "Rock_Stone"
    },
    {
      "x": -28,
      "y": 14,
      "z": -13,
      "name": "Rock_Stone"
    },
    {
      "x": -28,
      "y": 15,
      "z": -13,
      "name": "Rock_Stone"
    },
    {
      "x": -28,
      "y": 16,
      "z": -13,
      "name": "Rock_Stone"
    },
    {
      "x": -28,
      "y": 17,
      "z": -13,
      "name": "Rock_Stone"
    },
    {
      "x": -28,
      "y": 18,
      "z": -13,
      "name": "Rock_Stone"
    },
    {
      "x": -28,
      "y": 19,
      "z": -13,
      "name": "Rock_Stone"
    },
    {
      "x": -28,
      "y": 20,
      "z": -13,
      "name": "Rock_Stone"
    },
    {
      "x": -28,
      "y": 21,
      "z": -13,
      "name": "Rock_Stone"
    },
    {
      "x": -28,
      "y": 22,
      "z": -13,
      "name": "Rock_Stone"
    },
    {
      "x": -28,
      "y": 23,
      "z": -13,
      "name": "Rock_Stone"
    },
    {
      "x": -28,
      "y": 24,
      "z": -13,
      "name": "Rock_Stone"
    },
    {
      "x": -28,
      "y": 25,
      "z": -13,
      "name": "Rock_Stone"
    },
    {
      "x": -28,
      "y": 26,
      "z": -13,
      "name": "Rock_Stone"
    },
    {
      "x": -28,
      "y": 27,
      "z": -13,
      "name": "Rock_Stone"
    },
    {
      "x": -28,
      "y": 28,
      "z": -13,
      "name": "Rock_Stone"
    },
    {
      "x": -28,
      "y": 29,
      "z": -13,
      "name": "Rock_Stone"
    },
    {
      "x": -28,
      "y": 30,
      "z": -13,
      "name": "Rock_Stone"
    },
    {
      "x": -28,
      "y": 200,
      "z": -13,
      "name": "Rock_Stone"
    },
    {
      "x": -28,
      "y": 201,
      "z": -13,
      "name": "Rock_Stone"
    },
    {
      "x": -28,
      "y": 15,
      "z": -12,
      "name": "Rock_Stone"
    },
    {
      "x": -28,
      "y": 16,
      "z": -12,
      "name": "Rock_Stone"
    },
    {
      "x": -28,
      "y": 17,
      "z": -12,
      "name": "Rock_Stone"
    },
    {
      "x": -28,
      "y": 18,
      "z": -12,
      "name": "Rock_Stone"
    },
    {
      "x": -28,
      "y": 19,
      "z": -12,
      "name": "Rock_Stone"
    },
    {
      "x": -28,
      "y": 20,
      "z": -12,
      "name": "Rock_Stone"
    },
    {
      "x": -28,
      "y": 21,
      "z": -12,
      "name": "Rock_Stone"
    },
    {
      "x": -28,
      "y": 22,
      "z": -12,
      "name": "Rock_Stone"
    },
    {
      "x": -28,
      "y": 23,
      "z": -12,
      "name": "Rock_Stone"
    },
    {
      "x": -28,
      "y": 24,
      "z": -12,
      "name": "Rock_Stone"
    },
    {
      "x": -28,
      "y": 25,
      "z": -12,
      "name": "Rock_Stone"
    },
    {
      "x": -28,
      "y": 26,
      "z": -12,
      "name": "Rock_Stone"
    },
    {
      "x": -28,
      "y": 27,
      "z": -12,
      "name": "Rock_Stone"
    },
    {
      "x": -28,
      "y": 28,
      "z": -12,
      "name": "Rock_Stone"
    },
    {
      "x": -28,
      "y": 29,
      "z": -12,
      "name": "Rock_Stone"
    },
    {
      "x": -28,
      "y": 30,
      "z": -12,
      "name": "Rock_Stone"
    },
    {
      "x": -28,
      "y": 199,
      "z": -12,
      "name": "Rock_Stone"
    },
    {
      "x": -28,
      "y": 201,
      "z": -12,
      "name": "Rock_Stone"
    },
    {
      "x": -28,
      "y": 21,
      "z": -11,
      "name": "Rock_Stone"
    },
    {
      "x": -28,
      "y": 22,
      "z": -11,
      "name": "Rock_Stone"
    },
    {
      "x": -28,
      "y": 23,
      "z": -11,
      "name": "Rock_Stone"
    },
    {
      "x": -28,
      "y": 24,
      "z": -11,
      "name": "Rock_Stone"
    },
    {
      "x": -28,
      "y": 25,
      "z": -11,
      "name": "Rock_Stone"
    },
    {
      "x": -28,
      "y": 26,
      "z": -11,
      "name": "Rock_Stone"
    },
    {
      "x": -28,
      "y": 27,
      "z": -11,
      "name": "Rock_Stone"
    },
    {
      "x": -28,
      "y": 28,
      "z": -11,
      "name": "Rock_Stone"
    },
    {
      "x": -28,
      "y": 29,
      "z": -11,
      "name": "Rock_Stone"
    },
    {
      "x": -28,
      "y": 23,
      "z": -10,
      "name": "Rock_Stone"
    },
    {
      "x": -28,
      "y": 24,
      "z": -10,
      "name": "Rock_Stone"
    },
    {
      "x": -28,
      "y": 25,
      "z": -10,
      "name": "Rock_Stone"
    },
    {
      "x": -28,
      "y": 26,
      "z": -10,
      "name": "Rock_Stone"
    },
    {
      "x": -28,
      "y": 27,
      "z": -10,
      "name": "Rock_Stone"
    },
    {
      "x": -28,
      "y": 195,
      "z": -2,
      "name": "Rock_Stone"
    },
    {
      "x": -28,
      "y": 196,
      "z": -2,
      "name": "Rock_Stone"
    },
    {
      "x": -28,
      "y": 196,
      "z": -1,
      "name": "Rock_Stone"
    },
    {
      "x": -28,
      "y": 197,
      "z": 10,
      "name": "Rock_Stone"
    },
    {
      "x": -27,
      "y": 23,
      "z": -22,
      "name": "Rock_Stone"
    },
    {
      "x": -27,
      "y": 24,
      "z": -22,
      "name": "Rock_Stone"
    },
    {
      "x": -27,
      "y": 25,
      "z": -22,
      "name": "Rock_Stone"
    },
    {
      "x": -27,
      "y": 21,
      "z": -21,
      "name": "Rock_Stone"
    },
    {
      "x": -27,
      "y": 22,
      "z": -21,
      "name": "Rock_Stone"
    },
    {
      "x": -27,
      "y": 23,
      "z": -21,
      "name": "Rock_Stone"
    },
    {
      "x": -27,
      "y": 24,
      "z": -21,
      "name": "Rock_Stone"
    },
    {
      "x": -27,
      "y": 25,
      "z": -21,
      "name": "Rock_Stone"
    },
    {
      "x": -27,
      "y": 26,
      "z": -21,
      "name": "Rock_Stone"
    },
    {
      "x": -27,
      "y": 27,
      "z": -21,
      "name": "Rock_Stone"
    },
    {
      "x": -27,
      "y": 19,
      "z": -20,
      "name": "Rock_Stone"
    },
    {
      "x": -27,
      "y": 20,
      "z": -20,
      "name": "Rock_Stone"
    },
    {
      "x": -27,
      "y": 21,
      "z": -20,
      "name": "Rock_Stone"
    },
    {
      "x": -27,
      "y": 22,
      "z": -20,
      "name": "Rock_Stone"
    },
    {
      "x": -27,
      "y": 23,
      "z": -20,
      "name": "Rock_Stone"
    },
    {
      "x": -27,
      "y": 24,
      "z": -20,
      "name": "Rock_Stone"
    },
    {
      "x": -27,
      "y": 25,
      "z": -20,
      "name": "Rock_Stone"
    },
    {
      "x": -27,
      "y": 26,
      "z": -20,
      "name": "Rock_Stone"
    },
    {
      "x": -27,
      "y": 27,
      "z": -20,
      "name": "Rock_Stone"
    },
    {
      "x": -27,
      "y": 28,
      "z": -20,
      "name": "Rock_Stone"
    },
    {
      "x": -27,
      "y": 16,
      "z": -19,
      "name": "Rock_Stone"
    },
    {
      "x": -27,
      "y": 17,
      "z": -19,
      "name": "Rock_Stone"
    },
    {
      "x": -27,
      "y": 18,
      "z": -19,
      "name": "Rock_Stone"
    },
    {
      "x": -27,
      "y": 19,
      "z": -19,
      "name": "Rock_Stone"
    },
    {
      "x": -27,
      "y": 20,
      "z": -19,
      "name": "Rock_Stone"
    },
    {
      "x": -27,
      "y": 21,
      "z": -19,
      "name": "Rock_Stone"
    },
    {
      "x": -27,
      "y": 22,
      "z": -19,
      "name": "Rock_Stone"
    },
    {
      "x": -27,
      "y": 23,
      "z": -19,
      "name": "Rock_Stone"
    },
    {
      "x": -27,
      "y": 24,
      "z": -19,
      "name": "Rock_Stone"
    },
    {
      "x": -27,
      "y": 25,
      "z": -19,
      "name": "Rock_Stone"
    },
    {
      "x": -27,
      "y": 26,
      "z": -19,
      "name": "Rock_Stone"
    },
    {
      "x": -27,
      "y": 27,
      "z": -19,
      "name": "Rock_Stone"
    },
    {
      "x": -27,
      "y": 28,
      "z": -19,
      "name": "Rock_Stone"
    },
    {
      "x": -27,
      "y": 29,
      "z": -19,
      "name": "Rock_Stone"
    },
    {
      "x": -27,
      "y": 15,
      "z": -18,
      "name": "Rock_Stone"
    },
    {
      "x": -27,
      "y": 16,
      "z": -18,
      "name": "Rock_Stone"
    },
    {
      "x": -27,
      "y": 17,
      "z": -18,
      "name": "Rock_Stone"
    },
    {
      "x": -27,
      "y": 18,
      "z": -18,
      "name": "Rock_Stone"
    },
    {
      "x": -27,
      "y": 19,
      "z": -18,
      "name": "Rock_Stone"
    },
    {
      "x": -27,
      "y": 20,
      "z": -18,
      "name": "Rock_Stone"
    },
    {
      "x": -27,
      "y": 21,
      "z": -18,
      "name": "Rock_Stone"
    },
    {
      "x": -27,
      "y": 22,
      "z": -18,
      "name": "Rock_Stone"
    },
    {
      "x": -27,
      "y": 23,
      "z": -18,
      "name": "Rock_Stone"
    },
    {
      "x": -27,
      "y": 24,
      "z": -18,
      "name": "Rock_Stone"
    },
    {
      "x": -27,
      "y": 25,
      "z": -18,
      "name": "Rock_Stone"
    },
    {
      "x": -27,
      "y": 26,
      "z": -18,
      "name": "Rock_Stone"
    },
    {
      "x": -27,
      "y": 27,
      "z": -18,
      "name": "Rock_Stone"
    },
    {
      "x": -27,
      "y": 28,
      "z": -18,
      "name": "Rock_Stone"
    },
    {
      "x": -27,
      "y": 29,
      "z": -18,
      "name": "Rock_Stone"
    },
    {
      "x": -27,
      "y": 30,
      "z": -18,
      "name": "Rock_Stone"
    },
    {
      "x": -27,
      "y": 14,
      "z": -17,
      "name": "Rock_Stone"
    },
    {
      "x": -27,
      "y": 15,
      "z": -17,
      "name": "Rock_Stone"
    },
    {
      "x": -27,
      "y": 16,
      "z": -17,
      "name": "Rock_Stone"
    },
    {
      "x": -27,
      "y": 17,
      "z": -17,
      "name": "Rock_Stone"
    },
    {
      "x": -27,
      "y": 18,
      "z": -17,
      "name": "Rock_Stone"
    },
    {
      "x": -27,
      "y": 19,
      "z": -17,
      "name": "Rock_Stone"
    },
    {
      "x": -27,
      "y": 20,
      "z": -17,
      "name": "Rock_Stone"
    },
    {
      "x": -27,
      "y": 21,
      "z": -17,
      "name": "Rock_Stone"
    },
    {
      "x": -27,
      "y": 22,
      "z": -17,
      "name": "Rock_Stone"
    },
    {
      "x": -27,
      "y": 23,
      "z": -17,
      "name": "Rock_Stone"
    },
    {
      "x": -27,
      "y": 24,
      "z": -17,
      "name": "Rock_Stone"
    },
    {
      "x": -27,
      "y": 25,
      "z": -17,
      "name": "Rock_Stone"
    },
    {
      "x": -27,
      "y": 26,
      "z": -17,
      "name": "Rock_Stone"
    },
    {
      "x": -27,
      "y": 27,
      "z": -17,
      "name": "Rock_Stone"
    },
    {
      "x": -27,
      "y": 28,
      "z": -17,
      "name": "Rock_Stone"
    },
    {
      "x": -27,
      "y": 29,
      "z": -17,
      "name": "Rock_Stone"
    },
    {
      "x": -27,
      "y": 30,
      "z": -17,
      "name": "Rock_Stone"
    },
    {
      "x": -27,
      "y": 13,
      "z": -16,
      "name": "Rock_Stone"
    },
    {
      "x": -27,
      "y": 14,
      "z": -16,
      "name": "Rock_Stone"
    },
    {
      "x": -27,
      "y": 15,
      "z": -16,
      "name": "Rock_Stone"
    },
    {
      "x": -27,
      "y": 16,
      "z": -16,
      "name": "Rock_Stone"
    },
    {
      "x": -27,
      "y": 17,
      "z": -16,
      "name": "Rock_Stone"
    },
    {
      "x": -27,
      "y": 18,
      "z": -16,
      "name": "Rock_Stone"
    },
    {
      "x": -27,
      "y": 19,
      "z": -16,
      "name": "Rock_Stone"
    },
    {
      "x": -27,
      "y": 20,
      "z": -16,
      "name": "Rock_Stone"
    },
    {
      "x": -27,
      "y": 21,
      "z": -16,
      "name": "Rock_Stone"
    },
    {
      "x": -27,
      "y": 22,
      "z": -16,
      "name": "Rock_Stone"
    },
    {
      "x": -27,
      "y": 23,
      "z": -16,
      "name": "Rock_Stone"
    },
    {
      "x": -27,
      "y": 24,
      "z": -16,
      "name": "Rock_Stone"
    },
    {
      "x": -27,
      "y": 25,
      "z": -16,
      "name": "Rock_Stone"
    },
    {
      "x": -27,
      "y": 26,
      "z": -16,
      "name": "Rock_Stone"
    },
    {
      "x": -27,
      "y": 27,
      "z": -16,
      "name": "Rock_Stone"
    },
    {
      "x": -27,
      "y": 28,
      "z": -16,
      "name": "Rock_Stone"
    },
    {
      "x": -27,
      "y": 29,
      "z": -16,
      "name": "Rock_Stone"
    },
    {
      "x": -27,
      "y": 30,
      "z": -16,
      "name": "Rock_Stone"
    },
    {
      "x": -27,
      "y": 31,
      "z": -16,
      "name": "Rock_Stone"
    },
    {
      "x": -27,
      "y": 12,
      "z": -15,
      "name": "Rock_Stone"
    },
    {
      "x": -27,
      "y": 13,
      "z": -15,
      "name": "Rock_Stone"
    },
    {
      "x": -27,
      "y": 14,
      "z": -15,
      "name": "Rock_Stone"
    },
    {
      "x": -27,
      "y": 15,
      "z": -15,
      "name": "Rock_Stone"
    },
    {
      "x": -27,
      "y": 16,
      "z": -15,
      "name": "Rock_Stone"
    },
    {
      "x": -27,
      "y": 17,
      "z": -15,
      "name": "Rock_Stone"
    },
    {
      "x": -27,
      "y": 18,
      "z": -15,
      "name": "Rock_Stone"
    },
    {
      "x": -27,
      "y": 19,
      "z": -15,
      "name": "Rock_Stone"
    },
    {
      "x": -27,
      "y": 20,
      "z": -15,
      "name": "Rock_Stone"
    },
    {
      "x": -27,
      "y": 21,
      "z": -15,
      "name": "Rock_Stone"
    },
    {
      "x": -27,
      "y": 22,
      "z": -15,
      "name": "Rock_Stone"
    },
    {
      "x": -27,
      "y": 23,
      "z": -15,
      "name": "Rock_Stone"
    },
    {
      "x": -27,
      "y": 24,
      "z": -15,
      "name": "Rock_Stone"
    },
    {
      "x": -27,
      "y": 25,
      "z": -15,
      "name": "Rock_Stone"
    },
    {
      "x": -27,
      "y": 26,
      "z": -15,
      "name": "Rock_Stone"
    },
    {
      "x": -27,
      "y": 27,
      "z": -15,
      "name": "Rock_Stone"
    },
    {
      "x": -27,
      "y": 28,
      "z": -15,
      "name": "Rock_Stone"
    },
    {
      "x": -27,
      "y": 29,
      "z": -15,
      "name": "Rock_Stone"
    },
    {
      "x": -27,
      "y": 30,
      "z": -15,
      "name": "Rock_Stone"
    },
    {
      "x": -27,
      "y": 31,
      "z": -15,
      "name": "Rock_Stone"
    },
    {
      "x": -27,
      "y": 12,
      "z": -14,
      "name": "Rock_Stone"
    },
    {
      "x": -27,
      "y": 13,
      "z": -14,
      "name": "Rock_Stone"
    },
    {
      "x": -27,
      "y": 14,
      "z": -14,
      "name": "Rock_Stone"
    },
    {
      "x": -27,
      "y": 15,
      "z": -14,
      "name": "Rock_Stone"
    },
    {
      "x": -27,
      "y": 16,
      "z": -14,
      "name": "Rock_Stone"
    },
    {
      "x": -27,
      "y": 17,
      "z": -14,
      "name": "Rock_Stone"
    },
    {
      "x": -27,
      "y": 18,
      "z": -14,
      "name": "Rock_Stone"
    },
    {
      "x": -27,
      "y": 19,
      "z": -14,
      "name": "Rock_Stone"
    },
    {
      "x": -27,
      "y": 20,
      "z": -14,
      "name": "Rock_Stone"
    },
    {
      "x": -27,
      "y": 21,
      "z": -14,
      "name": "Rock_Stone"
    },
    {
      "x": -27,
      "y": 22,
      "z": -14,
      "name": "Rock_Stone"
    },
    {
      "x": -27,
      "y": 23,
      "z": -14,
      "name": "Rock_Stone"
    },
    {
      "x": -27,
      "y": 24,
      "z": -14,
      "name": "Rock_Stone"
    },
    {
      "x": -27,
      "y": 25,
      "z": -14,
      "name": "Rock_Stone"
    },
    {
      "x": -27,
      "y": 26,
      "z": -14,
      "name": "Rock_Stone"
    },
    {
      "x": -27,
      "y": 27,
      "z": -14,
      "name": "Rock_Stone"
    },
    {
      "x": -27,
      "y": 28,
      "z": -14,
      "name": "Rock_Stone"
    },
    {
      "x": -27,
      "y": 29,
      "z": -14,
      "name": "Rock_Stone"
    },
    {
      "x": -27,
      "y": 30,
      "z": -14,
      "name": "Rock_Stone"
    },
    {
      "x": -27,
      "y": 31,
      "z": -14,
      "name": "Rock_Stone"
    },
    {
      "x": -27,
      "y": 12,
      "z": -13,
      "name": "Rock_Stone"
    },
    {
      "x": -27,
      "y": 13,
      "z": -13,
      "name": "Rock_Stone"
    },
    {
      "x": -27,
      "y": 14,
      "z": -13,
      "name": "Rock_Stone"
    },
    {
      "x": -27,
      "y": 15,
      "z": -13,
      "name": "Rock_Stone"
    },
    {
      "x": -27,
      "y": 16,
      "z": -13,
      "name": "Rock_Stone"
    },
    {
      "x": -27,
      "y": 17,
      "z": -13,
      "name": "Rock_Stone"
    },
    {
      "x": -27,
      "y": 18,
      "z": -13,
      "name": "Rock_Stone"
    },
    {
      "x": -27,
      "y": 19,
      "z": -13,
      "name": "Rock_Stone"
    },
    {
      "x": -27,
      "y": 20,
      "z": -13,
      "name": "Rock_Stone"
    },
    {
      "x": -27,
      "y": 21,
      "z": -13,
      "name": "Rock_Stone"
    },
    {
      "x": -27,
      "y": 22,
      "z": -13,
      "name": "Rock_Stone"
    },
    {
      "x": -27,
      "y": 23,
      "z": -13,
      "name": "Rock_Stone"
    },
    {
      "x": -27,
      "y": 24,
      "z": -13,
      "name": "Rock_Stone"
    },
    {
      "x": -27,
      "y": 25,
      "z": -13,
      "name": "Rock_Stone"
    },
    {
      "x": -27,
      "y": 26,
      "z": -13,
      "name": "Rock_Stone"
    },
    {
      "x": -27,
      "y": 27,
      "z": -13,
      "name": "Rock_Stone"
    },
    {
      "x": -27,
      "y": 28,
      "z": -13,
      "name": "Rock_Stone"
    },
    {
      "x": -27,
      "y": 29,
      "z": -13,
      "name": "Rock_Stone"
    },
    {
      "x": -27,
      "y": 30,
      "z": -13,
      "name": "Rock_Stone"
    },
    {
      "x": -27,
      "y": 31,
      "z": -13,
      "name": "Rock_Stone"
    },
    {
      "x": -27,
      "y": 200,
      "z": -13,
      "name": "Rock_Stone"
    },
    {
      "x": -27,
      "y": 13,
      "z": -12,
      "name": "Rock_Stone"
    },
    {
      "x": -27,
      "y": 14,
      "z": -12,
      "name": "Rock_Stone"
    },
    {
      "x": -27,
      "y": 15,
      "z": -12,
      "name": "Rock_Stone"
    },
    {
      "x": -27,
      "y": 16,
      "z": -12,
      "name": "Rock_Stone"
    },
    {
      "x": -27,
      "y": 17,
      "z": -12,
      "name": "Rock_Stone"
    },
    {
      "x": -27,
      "y": 18,
      "z": -12,
      "name": "Rock_Stone"
    },
    {
      "x": -27,
      "y": 19,
      "z": -12,
      "name": "Rock_Stone"
    },
    {
      "x": -27,
      "y": 20,
      "z": -12,
      "name": "Rock_Stone"
    },
    {
      "x": -27,
      "y": 21,
      "z": -12,
      "name": "Rock_Stone"
    },
    {
      "x": -27,
      "y": 22,
      "z": -12,
      "name": "Rock_Stone"
    },
    {
      "x": -27,
      "y": 23,
      "z": -12,
      "name": "Rock_Stone"
    },
    {
      "x": -27,
      "y": 24,
      "z": -12,
      "name": "Rock_Stone"
    },
    {
      "x": -27,
      "y": 25,
      "z": -12,
      "name": "Rock_Stone"
    },
    {
      "x": -27,
      "y": 26,
      "z": -12,
      "name": "Rock_Stone"
    },
    {
      "x": -27,
      "y": 27,
      "z": -12,
      "name": "Rock_Stone"
    },
    {
      "x": -27,
      "y": 28,
      "z": -12,
      "name": "Rock_Stone"
    },
    {
      "x": -27,
      "y": 29,
      "z": -12,
      "name": "Rock_Stone"
    },
    {
      "x": -27,
      "y": 30,
      "z": -12,
      "name": "Rock_Stone"
    },
    {
      "x": -27,
      "y": 31,
      "z": -12,
      "name": "Rock_Stone"
    },
    {
      "x": -27,
      "y": 199,
      "z": -12,
      "name": "Rock_Stone"
    },
    {
      "x": -27,
      "y": 200,
      "z": -12,
      "name": "Rock_Stone"
    },
    {
      "x": -27,
      "y": 20,
      "z": -11,
      "name": "Rock_Stone"
    },
    {
      "x": -27,
      "y": 21,
      "z": -11,
      "name": "Rock_Stone"
    },
    {
      "x": -27,
      "y": 22,
      "z": -11,
      "name": "Rock_Stone"
    },
    {
      "x": -27,
      "y": 23,
      "z": -11,
      "name": "Rock_Stone"
    },
    {
      "x": -27,
      "y": 24,
      "z": -11,
      "name": "Rock_Stone"
    },
    {
      "x": -27,
      "y": 25,
      "z": -11,
      "name": "Rock_Stone"
    },
    {
      "x": -27,
      "y": 26,
      "z": -11,
      "name": "Rock_Stone"
    },
    {
      "x": -27,
      "y": 27,
      "z": -11,
      "name": "Rock_Stone"
    },
    {
      "x": -27,
      "y": 28,
      "z": -11,
      "name": "Rock_Stone"
    },
    {
      "x": -27,
      "y": 29,
      "z": -11,
      "name": "Rock_Stone"
    },
    {
      "x": -27,
      "y": 30,
      "z": -11,
      "name": "Rock_Stone"
    },
    {
      "x": -27,
      "y": 198,
      "z": -11,
      "name": "Rock_Stone"
    },
    {
      "x": -27,
      "y": 200,
      "z": -11,
      "name": "Rock_Stone"
    },
    {
      "x": -27,
      "y": 22,
      "z": -10,
      "name": "Rock_Stone"
    },
    {
      "x": -27,
      "y": 23,
      "z": -10,
      "name": "Rock_Stone"
    },
    {
      "x": -27,
      "y": 24,
      "z": -10,
      "name": "Rock_Stone"
    },
    {
      "x": -27,
      "y": 25,
      "z": -10,
      "name": "Rock_Stone"
    },
    {
      "x": -27,
      "y": 26,
      "z": -10,
      "name": "Rock_Stone"
    },
    {
      "x": -27,
      "y": 27,
      "z": -10,
      "name": "Rock_Stone"
    },
    {
      "x": -27,
      "y": 28,
      "z": -10,
      "name": "Rock_Stone"
    },
    {
      "x": -27,
      "y": 29,
      "z": -10,
      "name": "Rock_Stone"
    },
    {
      "x": -27,
      "y": 24,
      "z": -9,
      "name": "Rock_Stone"
    },
    {
      "x": -27,
      "y": 25,
      "z": -9,
      "name": "Rock_Stone"
    },
    {
      "x": -27,
      "y": 26,
      "z": -9,
      "name": "Rock_Stone"
    },
    {
      "x": -27,
      "y": 27,
      "z": -9,
      "name": "Rock_Stone"
    },
    {
      "x": -27,
      "y": 194,
      "z": -2,
      "name": "Rock_Stone"
    },
    {
      "x": -27,
      "y": 195,
      "z": -2,
      "name": "Rock_Stone"
    },
    {
      "x": -27,
      "y": 196,
      "z": -2,
      "name": "Rock_Stone"
    },
    {
      "x": -27,
      "y": 195,
      "z": -1,
      "name": "Rock_Stone"
    },
    {
      "x": -27,
      "y": 196,
      "z": 10,
      "name": "Rock_Stone"
    },
    {
      "x": -27,
      "y": 197,
      "z": 10,
      "name": "Rock_Stone"
    },
    {
      "x": -26,
      "y": 22,
      "z": -21,
      "name": "Rock_Stone"
    },
    {
      "x": -26,
      "y": 23,
      "z": -21,
      "name": "Rock_Stone"
    },
    {
      "x": -26,
      "y": 24,
      "z": -21,
      "name": "Rock_Stone"
    },
    {
      "x": -26,
      "y": 25,
      "z": -21,
      "name": "Rock_Stone"
    },
    {
      "x": -26,
      "y": 26,
      "z": -21,
      "name": "Rock_Stone"
    },
    {
      "x": -26,
      "y": 27,
      "z": -21,
      "name": "Rock_Stone"
    },
    {
      "x": -26,
      "y": 20,
      "z": -20,
      "name": "Rock_Stone"
    },
    {
      "x": -26,
      "y": 21,
      "z": -20,
      "name": "Rock_Stone"
    },
    {
      "x": -26,
      "y": 22,
      "z": -20,
      "name": "Rock_Stone"
    },
    {
      "x": -26,
      "y": 23,
      "z": -20,
      "name": "Rock_Stone"
    },
    {
      "x": -26,
      "y": 24,
      "z": -20,
      "name": "Rock_Stone"
    },
    {
      "x": -26,
      "y": 25,
      "z": -20,
      "name": "Rock_Stone"
    },
    {
      "x": -26,
      "y": 26,
      "z": -20,
      "name": "Rock_Stone"
    },
    {
      "x": -26,
      "y": 27,
      "z": -20,
      "name": "Rock_Stone"
    },
    {
      "x": -26,
      "y": 28,
      "z": -20,
      "name": "Rock_Stone"
    },
    {
      "x": -26,
      "y": 19,
      "z": -19,
      "name": "Rock_Stone"
    },
    {
      "x": -26,
      "y": 20,
      "z": -19,
      "name": "Rock_Stone"
    },
    {
      "x": -26,
      "y": 21,
      "z": -19,
      "name": "Rock_Stone"
    },
    {
      "x": -26,
      "y": 22,
      "z": -19,
      "name": "Rock_Stone"
    },
    {
      "x": -26,
      "y": 23,
      "z": -19,
      "name": "Rock_Stone"
    },
    {
      "x": -26,
      "y": 24,
      "z": -19,
      "name": "Rock_Stone"
    },
    {
      "x": -26,
      "y": 25,
      "z": -19,
      "name": "Rock_Stone"
    },
    {
      "x": -26,
      "y": 26,
      "z": -19,
      "name": "Rock_Stone"
    },
    {
      "x": -26,
      "y": 27,
      "z": -19,
      "name": "Rock_Stone"
    },
    {
      "x": -26,
      "y": 28,
      "z": -19,
      "name": "Rock_Stone"
    },
    {
      "x": -26,
      "y": 29,
      "z": -19,
      "name": "Rock_Stone"
    },
    {
      "x": -26,
      "y": 16,
      "z": -18,
      "name": "Rock_Stone"
    },
    {
      "x": -26,
      "y": 17,
      "z": -18,
      "name": "Rock_Stone"
    },
    {
      "x": -26,
      "y": 18,
      "z": -18,
      "name": "Rock_Stone"
    },
    {
      "x": -26,
      "y": 19,
      "z": -18,
      "name": "Rock_Stone"
    },
    {
      "x": -26,
      "y": 20,
      "z": -18,
      "name": "Rock_Stone"
    },
    {
      "x": -26,
      "y": 21,
      "z": -18,
      "name": "Rock_Stone"
    },
    {
      "x": -26,
      "y": 22,
      "z": -18,
      "name": "Rock_Stone"
    },
    {
      "x": -26,
      "y": 23,
      "z": -18,
      "name": "Rock_Stone"
    },
    {
      "x": -26,
      "y": 24,
      "z": -18,
      "name": "Rock_Stone"
    },
    {
      "x": -26,
      "y": 25,
      "z": -18,
      "name": "Rock_Stone"
    },
    {
      "x": -26,
      "y": 26,
      "z": -18,
      "name": "Rock_Stone"
    },
    {
      "x": -26,
      "y": 27,
      "z": -18,
      "name": "Rock_Stone"
    },
    {
      "x": -26,
      "y": 28,
      "z": -18,
      "name": "Rock_Stone"
    },
    {
      "x": -26,
      "y": 29,
      "z": -18,
      "name": "Rock_Stone"
    },
    {
      "x": -26,
      "y": 30,
      "z": -18,
      "name": "Rock_Stone"
    },
    {
      "x": -26,
      "y": 14,
      "z": -17,
      "name": "Rock_Stone"
    },
    {
      "x": -26,
      "y": 15,
      "z": -17,
      "name": "Rock_Stone"
    },
    {
      "x": -26,
      "y": 16,
      "z": -17,
      "name": "Rock_Stone"
    },
    {
      "x": -26,
      "y": 17,
      "z": -17,
      "name": "Rock_Stone"
    },
    {
      "x": -26,
      "y": 18,
      "z": -17,
      "name": "Rock_Stone"
    },
    {
      "x": -26,
      "y": 19,
      "z": -17,
      "name": "Rock_Stone"
    },
    {
      "x": -26,
      "y": 20,
      "z": -17,
      "name": "Rock_Stone"
    },
    {
      "x": -26,
      "y": 21,
      "z": -17,
      "name": "Rock_Stone"
    },
    {
      "x": -26,
      "y": 22,
      "z": -17,
      "name": "Rock_Stone"
    },
    {
      "x": -26,
      "y": 23,
      "z": -17,
      "name": "Rock_Stone"
    },
    {
      "x": -26,
      "y": 24,
      "z": -17,
      "name": "Rock_Stone"
    },
    {
      "x": -26,
      "y": 25,
      "z": -17,
      "name": "Rock_Stone"
    },
    {
      "x": -26,
      "y": 26,
      "z": -17,
      "name": "Rock_Stone"
    },
    {
      "x": -26,
      "y": 27,
      "z": -17,
      "name": "Rock_Stone"
    },
    {
      "x": -26,
      "y": 28,
      "z": -17,
      "name": "Rock_Stone"
    },
    {
      "x": -26,
      "y": 29,
      "z": -17,
      "name": "Rock_Stone"
    },
    {
      "x": -26,
      "y": 30,
      "z": -17,
      "name": "Rock_Stone"
    },
    {
      "x": -26,
      "y": 31,
      "z": -17,
      "name": "Rock_Stone"
    },
    {
      "x": -26,
      "y": 13,
      "z": -16,
      "name": "Rock_Stone"
    },
    {
      "x": -26,
      "y": 14,
      "z": -16,
      "name": "Rock_Stone"
    },
    {
