{
  "version": 8,
  "blockIdVersion": 11,
  "anchorX": 0,
  "anchorY": 0,
  "anchorZ": 0,
  "blocks": [
    {
      "x": -34,
      "y": -3,
      "z": -20,
      "name": "Rock_Stone"
    },
    {
      "x": -34,
      "y": -2,
      "z": -20,
      "name": "Rock_Stone"
    },
    {
      "x": -34,
      "y": -1,
      "z": -20,
      "name": "Rock_Stone"
    },
    {
      "x": -34,
      "y": -4,
      "z": -19,
      "name": "Rock_Stone"
    },
    {
      "x": -34,
      "y": -3,
      "z": -19,
      "name": "Rock_Stone"
    },
    {
      "x": -34,
      "y": -2,
      "z": -19,
      "name": "Rock_Stone"
    },
    {
      "x": -34,
      "y": -1,
      "z": -19,
      "name": "Rock_Stone"
    },
    {
      "x": -34,
      "y": 0,
      "z": -19,
      "name": "Rock_Stone"
    },
    {
      "x": -34,
      "y": -4,
      "z": -18,
      "name": "Rock_Stone"
    },
    {
      "x": -34,
      "y": -3,
      "z": -18,
      "name": "Rock_Stone"
    },
    {
      "x": -34,
      "y": -2,
      "z": -18,
      "name": "Rock_Stone"
    },
    {
      "x": -34,
      "y": -1,
      "z": -18,
      "name": "Rock_Stone"
    },
    {
      "x": -34,
      "y": 0,
      "z": -18,
      "name": "Rock_Stone"
    },
    {
      "x": -34,
      "y": -2,
      "z": -17,
      "name": "Rock_Stone"
    },
    {
      "x": -34,
      "y": -1,
      "z": -17,
      "name": "Rock_Stone"
    },
    {
      "x": -33,
      "y": -3,
      "z": -22,
      "name": "Rock_Stone"
    },
    {
      "x": -33,
      "y": -2,
      "z": -22,
      "name": "Rock_Stone"
    },
    {
      "x": -33,
      "y": -1,
      "z": -22,
      "name": "Rock_Stone"
    },
    {
      "x": -33,
      "y": -4,
      "z": -21,
      "name": "Rock_Stone"
    },
    {
      "x": -33,
      "y": -3,
      "z": -21,
      "name": "Rock_Stone"
    },
    {
      "x": -33,
      "y": -2,
      "z": -21,
      "name": "Rock_Stone"
    },
    {
      "x": -33,
      "y": -1,
      "z": -21,
      "name": "Rock_Stone"
    },
    {
      "x": -33,
      "y": 0,
      "z": -21,
      "name": "Rock_Stone"
    },
    {
      "x": -33,
      "y": -6,
      "z": -20,
      "name": "Rock_Stone"
    },
    {
      "x": -33,
      "y": -5,
      "z": -20,
      "name": "Rock_Stone"
    },
    {
      "x": -33,
      "y": -4,
      "z": -20,
      "name": "Rock_Stone"
    },
    {
      "x": -33,
      "y": -3,
      "z": -20,
      "name": "Rock_Stone"
    },
    {
      "x": -33,
      "y": -2,
      "z": -20,
      "name": "Rock_Stone"
    },
    {
      "x": -33,
      "y": -1,
      "z": -20,
      "name": "Rock_Stone"
    },
    {
      "x": -33,
      "y": 0,
      "z": -20,
      "name": "Rock_Stone"
    },
    {
      "x": -33,
      "y": 1,
      "z": -20,
      "name": "Rock_Stone"
    },
    {
      "x": -33,
      "y": -5,
      "z": -19,
      "name": "Rock_Stone"
    },
    {
      "x": -33,
      "y": -4,
      "z": -19,
      "name": "Rock_Stone"
    },
    {
      "x": -33,
      "y": -3,
      "z": -19,
      "name": "Rock_Stone"
    },
    {
      "x": -33,
      "y": -2,
      "z": -19,
      "name": "Rock_Stone"
    },
    {
      "x": -33,
      "y": -1,
      "z": -19,
      "name": "Rock_Stone"
    },
    {
      "x": -33,
      "y": 0,
      "z": -19,
      "name": "Rock_Stone"
    },
    {
      "x": -33,
      "y": 1,
      "z": -19,
      "name": "Rock_Stone"
    },
    {
      "x": -33,
      "y": 2,
      "z": -19,
      "name": "Rock_Stone"
    },
    {
      "x": -33,
      "y": -6,
      "z": -18,
      "name": "Rock_Stone"
    },
    {
      "x": -33,
      "y": -5,
      "z": -18,
      "name": "Rock_Stone"
    },
    {
      "x": -33,
      "y": -4,
      "z": -18,
      "name": "Rock_Stone"
    },
    {
      "x": -33,
      "y": -3,
      "z": -18,
      "name": "Rock_Stone"
    },
    {
      "x": -33,
      "y": -2,
      "z": -18,
      "name": "Rock_Stone"
    },
    {
      "x": -33,
      "y": -1,
      "z": -18,
      "name": "Rock_Stone"
    },
    {
      "x": -33,
      "y": 0,
      "z": -18,
      "name": "Rock_Stone"
    },
    {
      "x": -33,
      "y": 1,
      "z": -18,
      "name": "Rock_Stone"
    },
    {
      "x": -33,
      "y": 2,
      "z": -18,
      "name": "Rock_Stone"
    },
    {
      "x": -33,
      "y": -5,
      "z": -17,
      "name": "Rock_Stone"
    },
    {
      "x": -33,
      "y": -4,
      "z": -17,
      "name": "Rock_Stone"
    },
    {
      "x": -33,
      "y": -3,
      "z": -17,
      "name": "Rock_Stone"
    },
    {
      "x": -33,
      "y": -2,
      "z": -17,
      "name": "Rock_Stone"
    },
    {
      "x": -33,
      "y": -1,
      "z": -17,
      "name": "Rock_Stone"
    },
    {
      "x": -33,
      "y": 0,
      "z": -17,
      "name": "Rock_Stone"
    },
    {
      "x": -33,
      "y": 1,
      "z": -17,
      "name": "Rock_Stone"
    },
    {
      "x": -33,
      "y": 2,
      "z": -17,
      "name": "Rock_Stone"
    },
    {
      "x": -33,
      "y": -4,
      "z": -16,
      "name": "Rock_Stone"
    },
    {
      "x": -33,
      "y": -3,
      "z": -16,
      "name": "Rock_Stone"
    },
    {
      "x": -33,
      "y": -2,
      "z": -16,
      "name": "Rock_Stone"
    },
    {
      "x": -33,
      "y": -1,
      "z": -16,
      "name": "Rock_Stone"
    },
    {
      "x": -33,
      "y": 0,
      "z": -16,
      "name": "Rock_Stone"
    },
    {
      "x": -33,
      "y": 1,
      "z": -16,
      "name": "Rock_Stone"
    },
    {
      "x": -33,
      "y": 2,
      "z": -16,
      "name": "Rock_Stone"
    },
    {
      "x": -33,
      "y": -2,
      "z": -15,
      "name": "Rock_Stone"
    },
    {
      "x": -33,
      "y": -1,
      "z": -15,
      "name": "Rock_Stone"
    },
    {
      "x": -33,
      "y": 0,
      "z": -15,
      "name": "Rock_Stone"
    },
    {
      "x": -33,
      "y": 1,
      "z": -15,
      "name": "Rock_Stone"
    },
    {
      "x": -33,
      "y": 2,
      "z": -15,
      "name": "Rock_Stone"
    },
    {
      "x": -33,
      "y": 173,
      "z": -3,
      "name": "Rock_Stone"
    },
    {
      "x": -32,
      "y": -3,
      "z": -23,
      "name": "Rock_Stone"
    },
    {
      "x": -32,
      "y": -2,
      "z": -23,
      "name": "Rock_Stone"
    },
    {
      "x": -32,
      "y": -5,
      "z": -22,
      "name": "Rock_Stone"
    },
    {
      "x": -32,
      "y": -4,
      "z": -22,
      "name": "Rock_Stone"
    },
    {
      "x": -32,
      "y": -3,
      "z": -22,
      "name": "Rock_Stone"
    },
    {
      "x": -32,
      "y": -2,
      "z": -22,
      "name": "Rock_Stone"
    },
    {
      "x": -32,
      "y": -1,
      "z": -22,
      "name": "Rock_Stone"
    },
    {
      "x": -32,
      "y": 0,
      "z": -22,
      "name": "Rock_Stone"
    },
    {
      "x": -32,
      "y": -6,
      "z": -21,
      "name": "Rock_Stone"
    },
    {
      "x": -32,
      "y": -5,
      "z": -21,
      "name": "Rock_Stone"
    },
    {
      "x": -32,
      "y": -4,
      "z": -21,
      "name": "Rock_Stone"
    },
    {
      "x": -32,
      "y": -3,
      "z": -21,
      "name": "Rock_Stone"
    },
    {
      "x": -32,
      "y": -2,
      "z": -21,
      "name": "Rock_Stone"
    },
    {
      "x": -32,
      "y": -1,
      "z": -21,
      "name": "Rock_Stone"
    },
    {
      "x": -32,
      "y": 0,
      "z": -21,
      "name": "Rock_Stone"
    },
    {
      "x": -32,
      "y": 1,
      "z": -21,
      "name": "Rock_Stone"
    },
    {
      "x": -32,
      "y": 2,
      "z": -21,
      "name": "Rock_Stone"
    },
    {
      "x": -32,
      "y": -7,
      "z": -20,
      "name": "Rock_Stone"
    },
    {
      "x": -32,
      "y": -6,
      "z": -20,
      "name": "Rock_Stone"
    },
    {
      "x": -32,
      "y": -5,
      "z": -20,
      "name": "Rock_Stone"
    },
    {
      "x": -32,
      "y": -4,
      "z": -20,
      "name": "Rock_Stone"
    },
    {
      "x": -32,
      "y": -3,
      "z": -20,
      "name": "Rock_Stone"
    },
    {
      "x": -32,
      "y": -2,
      "z": -20,
      "name": "Rock_Stone"
    },
    {
      "x": -32,
      "y": -1,
      "z": -20,
      "name": "Rock_Stone"
    },
    {
      "x": -32,
      "y": 0,
      "z": -20,
      "name": "Rock_Stone"
    },
    {
      "x": -32,
      "y": 1,
      "z": -20,
      "name": "Rock_Stone"
    },
    {
      "x": -32,
      "y": 2,
      "z": -20,
      "name": "Rock_Stone"
    },
    {
      "x": -32,
      "y": -7,
      "z": -19,
      "name": "Rock_Stone"
    },
    {
      "x": -32,
      "y": -6,
      "z": -19,
      "name": "Rock_Stone"
    },
    {
      "x": -32,
      "y": -5,
      "z": -19,
      "name": "Rock_Stone"
    },
    {
      "x": -32,
      "y": -4,
      "z": -19,
      "name": "Rock_Stone"
    },
    {
      "x": -32,
      "y": -3,
      "z": -19,
      "name": "Rock_Stone"
    },
    {
      "x": -32,
      "y": -2,
      "z": -19,
      "name": "Rock_Stone"
    },
    {
      "x": -32,
      "y": -1,
      "z": -19,
      "name": "Rock_Stone"
    },
    {
      "x": -32,
      "y": 0,
      "z": -19,
      "name": "Rock_Stone"
    },
    {
      "x": -32,
      "y": 1,
      "z": -19,
      "name": "Rock_Stone"
    },
    {
      "x": -32,
      "y": 2,
      "z": -19,
      "name": "Rock_Stone"
    },
    {
      "x": -32,
      "y": 3,
      "z": -19,
      "name": "Rock_Stone"
    },
    {
      "x": -32,
      "y": -7,
      "z": -18,
      "name": "Rock_Stone"
    },
    {
      "x": -32,
      "y": -6,
      "z": -18,
      "name": "Rock_Stone"
    },
    {
      "x": -32,
      "y": -5,
      "z": -18,
      "name": "Rock_Stone"
    },
    {
      "x": -32,
      "y": -4,
      "z": -18,
      "name": "Rock_Stone"
    },
    {
      "x": -32,
      "y": -3,
      "z": -18,
      "name": "Rock_Stone"
    },
    {
      "x": -32,
      "y": -2,
      "z": -18,
      "name": "Rock_Stone"
    },
    {
      "x": -32,
      "y": -1,
      "z": -18,
      "name": "Rock_Stone"
    },
    {
      "x": -32,
      "y": 0,
      "z": -18,
      "name": "Rock_Stone"
    },
    {
      "x": -32,
      "y": 1,
      "z": -18,
      "name": "Rock_Stone"
    },
    {
      "x": -32,
      "y": 2,
      "z": -18,
      "name": "Rock_Stone"
    },
    {
      "x": -32,
      "y": 3,
      "z": -18,
      "name": "Rock_Stone"
    },
    {
      "x": -32,
      "y": -6,
      "z": -17,
      "name": "Rock_Stone"
    },
    {
      "x": -32,
      "y": -5,
      "z": -17,
      "name": "Rock_Stone"
    },
    {
      "x": -32,
      "y": -4,
      "z": -17,
      "name": "Rock_Stone"
    },
    {
      "x": -32,
      "y": -3,
      "z": -17,
      "name": "Rock_Stone"
    },
    {
      "x": -32,
      "y": -2,
      "z": -17,
      "name": "Rock_Stone"
    },
    {
      "x": -32,
      "y": -1,
      "z": -17,
      "name": "Rock_Stone"
    },
    {
      "x": -32,
      "y": 0,
      "z": -17,
      "name": "Rock_Stone"
    },
    {
      "x": -32,
      "y": 1,
      "z": -17,
      "name": "Rock_Stone"
    },
    {
      "x": -32,
      "y": 2,
      "z": -17,
      "name": "Rock_Stone"
    },
    {
      "x": -32,
      "y": 3,
      "z": -17,
      "name": "Rock_Stone"
    },
    {
      "x": -32,
      "y": -6,
      "z": -16,
      "name": "Rock_Stone"
    },
    {
      "x": -32,
      "y": -5,
      "z": -16,
      "name": "Rock_Stone"
    },
    {
      "x": -32,
      "y": -4,
      "z": -16,
      "name": "Rock_Stone"
    },
    {
      "x": -32,
      "y": -3,
      "z": -16,
      "name": "Rock_Stone"
    },
    {
      "x": -32,
      "y": -2,
      "z": -16,
      "name": "Rock_Stone"
    },
    {
      "x": -32,
      "y": -1,
      "z": -16,
      "name": "Rock_Stone"
    },
    {
      "x": -32,
      "y": 0,
      "z": -16,
      "name": "Rock_Stone"
    },
    {
      "x": -32,
      "y": 1,
      "z": -16,
      "name": "Rock_Stone"
    },
    {
      "x": -32,
      "y": 2,
      "z": -16,
      "name": "Rock_Stone"
    },
    {
      "x": -32,
      "y": 3,
      "z": -16,
      "name": "Rock_Stone"
    },
    {
      "x": -32,
      "y": -4,
      "z": -15,
      "name": "Rock_Stone"
    },
    {
      "x": -32,
      "y": -3,
      "z": -15,
      "name": "Rock_Stone"
    },
    {
      "x": -32,
      "y": -2,
      "z": -15,
      "name": "Rock_Stone"
    },
    {
      "x": -32,
      "y": -1,
      "z": -15,
      "name": "Rock_Stone"
    },
    {
      "x": -32,
      "y": 0,
      "z": -15,
      "name": "Rock_Stone"
    },
    {
      "x": -32,
      "y": 1,
      "z": -15,
      "name": "Rock_Stone"
    },
    {
      "x": -32,
      "y": 2,
      "z": -15,
      "name": "Rock_Stone"
    },
    {
      "x": -32,
      "y": 3,
      "z": -15,
      "name": "Rock_Stone"
    },
    {
      "x": -32,
      "y": -2,
      "z": -14,
      "name": "Rock_Stone"
    },
    {
      "x": -32,
      "y": -1,
      "z": -14,
      "name": "Rock_Stone"
    },
    {
      "x": -32,
      "y": 0,
      "z": -14,
      "name": "Rock_Stone"
    },
    {
      "x": -32,
      "y": 1,
      "z": -14,
      "name": "Rock_Stone"
    },
    {
      "x": -32,
      "y": 2,
      "z": -14,
      "name": "Rock_Stone"
    },
    {
      "x": -32,
      "y": 173,
      "z": -3,
      "name": "Rock_Stone"
    },
    {
      "x": -31,
      "y": -4,
      "z": -23,
      "name": "Rock_Stone"
    },
    {
      "x": -31,
      "y": -3,
      "z": -23,
      "name": "Rock_Stone"
    },
    {
      "x": -31,
      "y": -2,
      "z": -23,
      "name": "Rock_Stone"
    },
    {
      "x": -31,
      "y": -1,
      "z": -23,
      "name": "Rock_Stone"
    },
    {
      "x": -31,
      "y": -5,
      "z": -22,
      "name": "Rock_Stone"
    },
    {
      "x": -31,
      "y": -4,
      "z": -22,
      "name": "Rock_Stone"
    },
    {
      "x": -31,
      "y": -3,
      "z": -22,
      "name": "Rock_Stone"
    },
    {
      "x": -31,
      "y": -2,
      "z": -22,
      "name": "Rock_Stone"
    },
    {
      "x": -31,
      "y": -1,
      "z": -22,
      "name": "Rock_Stone"
    },
    {
      "x": -31,
      "y": 0,
      "z": -22,
      "name": "Rock_Stone"
    },
    {
      "x": -31,
      "y": 1,
      "z": -22,
      "name": "Rock_Stone"
    },
    {
      "x": -31,
      "y": 2,
      "z": -22,
      "name": "Rock_Stone"
    },
    {
      "x": -31,
      "y": -7,
      "z": -21,
      "name": "Rock_Stone"
    },
    {
      "x": -31,
      "y": -6,
      "z": -21,
      "name": "Rock_Stone"
    },
    {
      "x": -31,
      "y": -5,
      "z": -21,
      "name": "Rock_Stone"
    },
    {
      "x": -31,
      "y": -4,
      "z": -21,
      "name": "Rock_Stone"
    },
    {
      "x": -31,
      "y": -3,
      "z": -21,
      "name": "Rock_Stone"
    },
    {
      "x": -31,
      "y": -2,
      "z": -21,
      "name": "Rock_Stone"
    },
    {
      "x": -31,
      "y": -1,
      "z": -21,
      "name": "Rock_Stone"
    },
    {
      "x": -31,
      "y": 0,
      "z": -21,
      "name": "Rock_Stone"
    },
    {
      "x": -31,
      "y": 1,
      "z": -21,
      "name": "Rock_Stone"
    },
    {
      "x": -31,
      "y": 2,
      "z": -21,
      "name": "Rock_Stone"
    },
    {
      "x": -31,
      "y": -8,
      "z": -20,
      "name": "Rock_Stone"
    },
    {
      "x": -31,
      "y": -7,
      "z": -20,
      "name": "Rock_Stone"
    },
    {
      "x": -31,
      "y": -6,
      "z": -20,
      "name": "Rock_Stone"
    },
    {
      "x": -31,
      "y": -5,
      "z": -20,
      "name": "Rock_Stone"
    },
    {
      "x": -31,
      "y": -4,
      "z": -20,
      "name": "Rock_Stone"
    },
    {
      "x": -31,
      "y": -3,
      "z": -20,
      "name": "Rock_Stone"
    },
    {
      "x": -31,
      "y": -2,
      "z": -20,
      "name": "Rock_Stone"
    },
    {
      "x": -31,
      "y": -1,
      "z": -20,
      "name": "Rock_Stone"
    },
    {
      "x": -31,
      "y": 0,
      "z": -20,
      "name": "Rock_Stone"
    },
    {
      "x": -31,
      "y": 1,
      "z": -20,
      "name": "Rock_Stone"
    },
    {
      "x": -31,
      "y": 2,
      "z": -20,
      "name": "Rock_Stone"
    },
    {
      "x": -31,
      "y": 3,
      "z": -20,
      "name": "Rock_Stone"
    },
    {
      "x": -31,
      "y": -8,
      "z": -19,
      "name": "Rock_Stone"
    },
    {
      "x": -31,
      "y": -7,
      "z": -19,
      "name": "Rock_Stone"
    },
    {
      "x": -31,
      "y": -6,
      "z": -19,
      "name": "Rock_Stone"
    },
    {
      "x": -31,
      "y": -5,
      "z": -19,
      "name": "Rock_Stone"
    },
    {
      "x": -31,
      "y": -4,
      "z": -19,
      "name": "Rock_Stone"
    },
    {
      "x": -31,
      "y": -3,
      "z": -19,
      "name": "Rock_Stone"
    },
    {
      "x": -31,
      "y": -2,
      "z": -19,
      "name": "Rock_Stone"
    },
    {
      "x": -31,
      "y": -1,
      "z": -19,
      "name": "Rock_Stone"
    },
    {
      "x": -31,
      "y": 0,
      "z": -19,
      "name": "Rock_Stone"
    },
    {
      "x": -31,
      "y": 1,
      "z": -19,
      "name": "Rock_Stone"
    },
    {
      "x": -31,
      "y": 2,
      "z": -19,
      "name": "Rock_Stone"
    },
    {
      "x": -31,
      "y": 3,
      "z": -19,
      "name": "Rock_Stone"
    },
    {
      "x": -31,
      "y": 4,
      "z": -19,
      "name": "Rock_Stone"
    },
    {
      "x": -31,
      "y": -8,
      "z": -18,
      "name": "Rock_Stone"
    },
    {
      "x": -31,
      "y": -7,
      "z": -18,
      "name": "Rock_Stone"
    },
    {
      "x": -31,
      "y": -6,
      "z": -18,
      "name": "Rock_Stone"
    },
    {
      "x": -31,
      "y": -5,
      "z": -18,
      "name": "Rock_Stone"
    },
    {
      "x": -31,
      "y": -4,
      "z": -18,
      "name": "Rock_Stone"
    },
    {
      "x": -31,
      "y": -3,
      "z": -18,
      "name": "Rock_Stone"
    },
    {
      "x": -31,
      "y": -2,
      "z": -18,
      "name": "Rock_Stone"
    },
    {
      "x": -31,
      "y": -1,
      "z": -18,
      "name": "Rock_Stone"
    },
    {
      "x": -31,
      "y": 0,
      "z": -18,
      "name": "Rock_Stone"
    },
    {
      "x": -31,
      "y": 1,
      "z": -18,
      "name": "Rock_Stone"
    },
    {
      "x": -31,
      "y": 2,
      "z": -18,
      "name": "Rock_Stone"
    },
    {
      "x": -31,
      "y": 3,
      "z": -18,
      "name": "Rock_Stone"
    },
    {
      "x": -31,
      "y": 4,
      "z": -18,
      "name": "Rock_Stone"
    },
    {
      "x": -31,
      "y": -8,
      "z": -17,
      "name": "Rock_Stone"
    },
    {
      "x": -31,
      "y": -7,
      "z": -17,
      "name": "Rock_Stone"
    },
    {
      "x": -31,
      "y": -6,
      "z": -17,
      "name": "Rock_Stone"
    },
    {
      "x": -31,
      "y": -5,
      "z": -17,
      "name": "Rock_Stone"
    },
    {
      "x": -31,
      "y": -4,
      "z": -17,
      "name": "Rock_Stone"
    },
    {
      "x": -31,
      "y": -3,
      "z": -17,
      "name": "Rock_Stone"
    },
    {
      "x": -31,
      "y": -2,
      "z": -17,
      "name": "Rock_Stone"
    },
    {
      "x": -31,
      "y": -1,
      "z": -17,
      "name": "Rock_Stone"
    },
    {
      "x": -31,
      "y": 0,
      "z": -17,
      "name": "Rock_Stone"
    },
    {
      "x": -31,
      "y": 1,
      "z": -17,
      "name": "Rock_Stone"
    },
    {
      "x": -31,
      "y": 2,
      "z": -17,
      "name": "Rock_Stone"
    },
    {
      "x": -31,
      "y": 3,
      "z": -17,
      "name": "Rock_Stone"
    },
    {
      "x": -31,
      "y": 4,
      "z": -17,
      "name": "Rock_Stone"
    },
    {
      "x": -31,
      "y": -7,
      "z": -16,
      "name": "Rock_Stone"
    },
    {
      "x": -31,
      "y": -6,
      "z": -16,
      "name": "Rock_Stone"
    },
    {
      "x": -31,
      "y": -5,
      "z": -16,
      "name": "Rock_Stone"
    },
    {
      "x": -31,
      "y": -4,
      "z": -16,
      "name": "Rock_Stone"
    },
    {
      "x": -31,
      "y": -3,
      "z": -16,
      "name": "Rock_Stone"
    },
    {
      "x": -31,
      "y": -2,
      "z": -16,
      "name": "Rock_Stone"
    },
    {
      "x": -31,
      "y": -1,
      "z": -16,
      "name": "Rock_Stone"
    },
    {
      "x": -31,
      "y": 0,
      "z": -16,
      "name": "Rock_Stone"
    },
    {
      "x": -31,
      "y": 1,
      "z": -16,
      "name": "Rock_Stone"
    },
    {
      "x": -31,
      "y": 2,
      "z": -16,
      "name": "Rock_Stone"
    },
    {
      "x": -31,
      "y": 3,
      "z": -16,
      "name": "Rock_Stone"
    },
    {
      "x": -31,
      "y": 4,
      "z": -16,
      "name": "Rock_Stone"
    },
    {
      "x": -31,
      "y": -6,
      "z": -15,
      "name": "Rock_Stone"
    },
    {
      "x": -31,
      "y": -5,
      "z": -15,
      "name": "Rock_Stone"
    },
    {
      "x": -31,
      "y": -4,
      "z": -15,
      "name": "Rock_Stone"
    },
    {
      "x": -31,
      "y": -3,
      "z": -15,
      "name": "Rock_Stone"
    },
    {
      "x": -31,
      "y": -2,
      "z": -15,
      "name": "Rock_Stone"
    },
    {
      "x": -31,
      "y": -1,
      "z": -15,
      "name": "Rock_Stone"
    },
    {
      "x": -31,
      "y": 0,
      "z": -15,
      "name": "Rock_Stone"
    },
    {
      "x": -31,
      "y": 1,
      "z": -15,
      "name": "Rock_Stone"
    },
    {
      "x": -31,
      "y": 2,
      "z": -15,
      "name": "Rock_Stone"
    },
    {
      "x": -31,
      "y": 3,
      "z": -15,
      "name": "Rock_Stone"
    },
    {
      "x": -31,
      "y": 4,
      "z": -15,
      "name": "Rock_Stone"
    },
    {
      "x": -31,
      "y": -3,
      "z": -14,
      "name": "Rock_Stone"
    },
    {
      "x": -31,
      "y": -2,
      "z": -14,
      "name": "Rock_Stone"
    },
    {
      "x": -31,
      "y": -1,
      "z": -14,
      "name": "Rock_Stone"
    },
    {
      "x": -31,
      "y": 0,
      "z": -14,
      "name": "Rock_Stone"
    },
    {
      "x": -31,
      "y": 1,
      "z": -14,
      "name": "Rock_Stone"
    },
    {
      "x": -31,
      "y": 2,
      "z": -14,
      "name": "Rock_Stone"
    },
    {
      "x": -31,
      "y": 3,
      "z": -14,
      "name": "Rock_Stone"
    },
    {
      "x": -31,
      "y": 172,
      "z": -3,
      "name": "Rock_Stone"
    },
    {
      "x": -31,
      "y": 173,
      "z": -3,
      "name": "Rock_Stone"
    },
    {
      "x": -30,
      "y": -4,
      "z": -23,
      "name": "Rock_Stone"
    },
    {
      "x": -30,
      "y": -3,
      "z": -23,
      "name": "Rock_Stone"
    },
    {
      "x": -30,
      "y": -2,
      "z": -23,
      "name": "Rock_Stone"
    },
    {
      "x": -30,
      "y": -1,
      "z": -23,
      "name": "Rock_Stone"
    },
    {
      "x": -30,
      "y": 0,
      "z": -23,
      "name": "Rock_Stone"
    },
    {
      "x": -30,
      "y": 1,
      "z": -23,
      "name": "Rock_Stone"
    },
    {
      "x": -30,
      "y": -7,
      "z": -22,
      "name": "Rock_Stone"
    },
    {
      "x": -30,
      "y": -6,
      "z": -22,
      "name": "Rock_Stone"
    },
    {
      "x": -30,
      "y": -5,
      "z": -22,
      "name": "Rock_Stone"
    },
    {
      "x": -30,
      "y": -4,
      "z": -22,
      "name": "Rock_Stone"
    },
    {
      "x": -30,
      "y": -3,
      "z": -22,
      "name": "Rock_Stone"
    },
    {
      "x": -30,
      "y": -2,
      "z": -22,
      "name": "Rock_Stone"
    },
    {
      "x": -30,
      "y": -1,
      "z": -22,
      "name": "Rock_Stone"
    },
    {
      "x": -30,
      "y": 0,
      "z": -22,
      "name": "Rock_Stone"
    },
    {
      "x": -30,
      "y": 1,
      "z": -22,
      "name": "Rock_Stone"
    },
    {
      "x": -30,
      "y": 2,
      "z": -22,
      "name": "Rock_Stone"
    },
    {
      "x": -30,
      "y": -7,
      "z": -21,
      "name": "Rock_Stone"
    },
    {
      "x": -30,
      "y": -6,
      "z": -21,
      "name": "Rock_Stone"
    },
    {
      "x": -30,
      "y": -5,
      "z": -21,
      "name": "Rock_Stone"
    },
    {
      "x": -30,
      "y": -4,
      "z": -21,
      "name": "Rock_Stone"
    },
    {
      "x": -30,
      "y": -3,
      "z": -21,
      "name": "Rock_Stone"
    },
    {
      "x": -30,
      "y": -2,
      "z": -21,
      "name": "Rock_Stone"
    },
    {
      "x": -30,
      "y": -1,
      "z": -21,
      "name": "Rock_Stone"
    },
    {
      "x": -30,
      "y": 0,
      "z": -21,
      "name": "Rock_Stone"
    },
    {
      "x": -30,
      "y": 1,
      "z": -21,
      "name": "Rock_Stone"
    },
    {
      "x": -30,
      "y": 2,
      "z": -21,
      "name": "Rock_Stone"
    },
    {
      "x": -30,
      "y": 3,
      "z": -21,
      "name": "Rock_Stone"
    },
    {
      "x": -30,
      "y": -8,
      "z": -20,
      "name": "Rock_Stone"
    },
    {
      "x": -30,
      "y": -7,
      "z": -20,
      "name": "Rock_Stone"
    },
    {
      "x": -30,
      "y": -6,
      "z": -20,
      "name": "Rock_Stone"
    },
    {
      "x": -30,
      "y": -5,
      "z": -20,
      "name": "Rock_Stone"
    },
    {
      "x": -30,
      "y": -4,
      "z": -20,
      "name": "Rock_Stone"
    },
    {
      "x": -30,
      "y": -3,
      "z": -20,
      "name": "Rock_Stone"
    },
    {
      "x": -30,
      "y": -2,
      "z": -20,
      "name": "Rock_Stone"
    },
    {
      "x": -30,
      "y": -1,
      "z": -20,
      "name": "Rock_Stone"
    },
    {
      "x": -30,
      "y": 0,
      "z": -20,
      "name": "Rock_Stone"
    },
    {
      "x": -30,
      "y": 1,
      "z": -20,
      "name": "Rock_Stone"
    },
    {
      "x": -30,
      "y": 2,
      "z": -20,
      "name": "Rock_Stone"
    },
    {
      "x": -30,
      "y": 3,
      "z": -20,
      "name": "Rock_Stone"
    },
    {
      "x": -30,
      "y": 4,
      "z": -20,
      "name": "Rock_Stone"
    },
    {
      "x": -30,
      "y": -9,
      "z": -19,
      "name": "Rock_Stone"
    },
    {
      "x": -30,
      "y": -8,
      "z": -19,
      "name": "Rock_Stone"
    },
    {
      "x": -30,
      "y": -7,
      "z": -19,
      "name": "Rock_Stone"
    },
    {
      "x": -30,
      "y": -6,
      "z": -19,
      "name": "Rock_Stone"
    },
    {
      "x": -30,
      "y": -5,
      "z": -19,
      "name": "Rock_Stone"
    },
    {
      "x": -30,
      "y": -4,
      "z": -19,
      "name": "Rock_Stone"
    },
    {
      "x": -30,
      "y": -3,
      "z": -19,
      "name": "Rock_Stone"
    },
    {
      "x": -30,
      "y": -2,
      "z": -19,
      "name": "Rock_Stone"
    },
    {
      "x": -30,
      "y": -1,
      "z": -19,
      "name": "Rock_Stone"
    },
    {
      "x": -30,
      "y": 0,
      "z": -19,
      "name": "Rock_Stone"
    },
    {
      "x": -30,
      "y": 1,
      "z": -19,
      "name": "Rock_Stone"
    },
    {
      "x": -30,
      "y": 2,
      "z": -19,
      "name": "Rock_Stone"
    },
    {
      "x": -30,
      "y": 3,
      "z": -19,
      "name": "Rock_Stone"
    },
    {
      "x": -30,
      "y": 4,
      "z": -19,
      "name": "Rock_Stone"
    },
    {
      "x": -30,
      "y": 5,
      "z": -19,
      "name": "Rock_Stone"
    },
    {
      "x": -30,
      "y": -9,
      "z": -18,
      "name": "Rock_Stone"
    },
    {
      "x": -30,
      "y": -8,
      "z": -18,
      "name": "Rock_Stone"
    },
    {
      "x": -30,
      "y": -7,
      "z": -18,
      "name": "Rock_Stone"
    },
    {
      "x": -30,
      "y": -6,
      "z": -18,
      "name": "Rock_Stone"
    },
    {
      "x": -30,
      "y": -5,
      "z": -18,
      "name": "Rock_Stone"
    },
    {
      "x": -30,
      "y": -4,
      "z": -18,
      "name": "Rock_Stone"
    },
    {
      "x": -30,
      "y": -3,
      "z": -18,
      "name": "Rock_Stone"
    },
    {
      "x": -30,
      "y": -2,
      "z": -18,
      "name": "Rock_Stone"
    },
    {
      "x": -30,
      "y": -1,
      "z": -18,
      "name": "Rock_Stone"
    },
    {
      "x": -30,
      "y": 0,
      "z": -18,
      "name": "Rock_Stone"
    },
    {
      "x": -30,
      "y": 1,
      "z": -18,
      "name": "Rock_Stone"
    },
    {
      "x": -30,
      "y": 2,
      "z": -18,
      "name": "Rock_Stone"
    },
    {
      "x": -30,
      "y": 3,
      "z": -18,
      "name": "Rock_Stone"
    },
    {
      "x": -30,
      "y": 4,
      "z": -18,
      "name": "Rock_Stone"
    },
    {
      "x": -30,
      "y": 5,
      "z": -18,
      "name": "Rock_Stone"
    },
    {
      "x": -30,
      "y": -9,
      "z": -17,
      "name": "Rock_Stone"
    },
    {
      "x": -30,
      "y": -8,
      "z": -17,
      "name": "Rock_Stone"
    },
    {
      "x": -30,
      "y": -7,
      "z": -17,
      "name": "Rock_Stone"
    },
    {
      "x": -30,
      "y": -6,
      "z": -17,
      "name": "Rock_Stone"
    },
    {
      "x": -30,
      "y": -5,
      "z": -17,
      "name": "Rock_Stone"
    },
    {
      "x": -30,
      "y": -4,
      "z": -17,
      "name": "Rock_Stone"
    },
    {
      "x": -30,
      "y": -3,
      "z": -17,
      "name": "Rock_Stone"
    },
    {
      "x": -30,
      "y": -2,
      "z": -17,
      "name": "Rock_Stone"
    },
    {
      "x": -30,
      "y": -1,
      "z": -17,
      "name": "Rock_Stone"
    },
    {
      "x": -30,
      "y": 0,
      "z": -17,
      "name": "Rock_Stone"
    },
    {
      "x": -30,
      "y": 1,
      "z": -17,
      "name": "Rock_Stone"
    },
    {
      "x": -30,
      "y": 2,
      "z": -17,
      "name": "Rock_Stone"
    },
    {
      "x": -30,
      "y": 3,
      "z": -17,
      "name": "Rock_Stone"
    },
    {
      "x": -30,
      "y": 4,
      "z": -17,
      "name": "Rock_Stone"
    },
    {
      "x": -30,
      "y": 5,
      "z": -17,
      "name": "Rock_Stone"
    },
    {
      "x": -30,
      "y": 178,
      "z": -17,
      "name": "Rock_Stone"
    },
    {
      "x": -30,
      "y": -8,
      "z": -16,
      "name": "Rock_Stone"
    },
    {
      "x": -30,
      "y": -7,
      "z": -16,
      "name": "Rock_Stone"
    },
    {
      "x": -30,
      "y": -6,
      "z": -16,
      "name": "Rock_Stone"
    },
    {
      "x": -30,
      "y": -5,
      "z": -16,
      "name": "Rock_Stone"
    },
    {
      "x": -30,
      "y": -4,
      "z": -16,
      "name": "Rock_Stone"
    },
    {
      "x": -30,
      "y": -3,
      "z": -16,
      "name": "Rock_Stone"
    },
    {
      "x": -30,
      "y": -2,
      "z": -16,
      "name": "Rock_Stone"
    },
    {
      "x": -30,
      "y": -1,
      "z": -16,
      "name": "Rock_Stone"
    },
    {
      "x": -30,
      "y": 0,
      "z": -16,
      "name": "Rock_Stone"
    },
    {
      "x": -30,
      "y": 1,
      "z": -16,
      "name": "Rock_Stone"
    },
    {
      "x": -30,
      "y": 2,
      "z": -16,
      "name": "Rock_Stone"
    },
    {
      "x": -30,
      "y": 3,
      "z": -16,
      "name": "Rock_Stone"
    },
    {
      "x": -30,
      "y": 4,
      "z": -16,
      "name": "Rock_Stone"
    },
    {
      "x": -30,
      "y": 5,
      "z": -16,
      "name": "Rock_Stone"
    },
    {
      "x": -30,
      "y": -7,
      "z": -15,
      "name": "Rock_Stone"
    },
    {
      "x": -30,
      "y": -6,
      "z": -15,
      "name": "Rock_Stone"
    },
    {
      "x": -30,
      "y": -5,
      "z": -15,
      "name": "Rock_Stone"
    },
    {
      "x": -30,
      "y": -4,
      "z": -15,
      "name": "Rock_Stone"
    },
    {
      "x": -30,
      "y": -3,
      "z": -15,
      "name": "Rock_Stone"
    },
    {
      "x": -30,
      "y": -2,
      "z": -15,
      "name": "Rock_Stone"
    },
    {
      "x": -30,
      "y": -1,
      "z": -15,
      "name": "Rock_Stone"
    },
    {
      "x": -30,
      "y": 0,
      "z": -15,
      "name": "Rock_Stone"
    },
    {
      "x": -30,
      "y": 1,
      "z": -15,
      "name": "Rock_Stone"
    },
    {
      "x": -30,
      "y": 2,
      "z": -15,
      "name": "Rock_Stone"
    },
    {
      "x": -30,
      "y": 3,
      "z": -15,
      "name": "Rock_Stone"
    },
    {
      "x": -30,
      "y": 4,
      "z": -15,
      "name": "Rock_Stone"
    },
    {
      "x": -30,
      "y": 5,
      "z": -15,
      "name": "Rock_Stone"
    },
    {
      "x": -30,
      "y": -5,
      "z": -14,
      "name": "Rock_Stone"
    },
    {
      "x": -30,
      "y": -4,
      "z": -14,
      "name": "Rock_Stone"
    },
    {
      "x": -30,
      "y": -3,
      "z": -14,
      "name": "Rock_Stone"
    },
    {
      "x": -30,
      "y": -2,
      "z": -14,
      "name": "Rock_Stone"
    },
    {
      "x": -30,
      "y": -1,
      "z": -14,
      "name": "Rock_Stone"
    },
    {
      "x": -30,
      "y": 0,
      "z": -14,
      "name": "Rock_Stone"
    },
    {
      "x": -30,
      "y": 1,
      "z": -14,
      "name": "Rock_Stone"
    },
    {
      "x": -30,
      "y": 2,
      "z": -14,
      "name": "Rock_Stone"
    },
    {
      "x": -30,
      "y": 3,
      "z": -14,
      "name": "Rock_Stone"
    },
    {
      "x": -30,
      "y": 4,
      "z": -14,
      "name": "Rock_Stone"
    },
    {
      "x": -30,
      "y": -1,
      "z": -13,
      "name": "Rock_Stone"
    },
    {
      "x": -30,
      "y": 0,
      "z": -13,
      "name": "Rock_Stone"
    },
    {
      "x": -30,
      "y": 1,
      "z": -13,
      "name": "Rock_Stone"
    },
    {
      "x": -30,
      "y": 2,
      "z": -13,
      "name": "Rock_Stone"
    },
    {
      "x": -30,
      "y": 3,
      "z": -13,
      "name": "Rock_Stone"
    },
    {
      "x": -30,
      "y": 172,
      "z": -3,
      "name": "Rock_Stone"
    },
    {
      "x": -30,
      "y": 173,
      "z": -3,
      "name": "Rock_Stone"
    },
    {
      "x": -29,
      "y": -4,
      "z": -23,
      "name": "Rock_Stone"
    },
    {
      "x": -29,
      "y": -3,
      "z": -23,
      "name": "Rock_Stone"
    },
    {
      "x": -29,
      "y": -2,
      "z": -23,
      "name": "Rock_Stone"
    },
    {
      "x": -29,
      "y": -1,
      "z": -23,
      "name": "Rock_Stone"
    },
    {
      "x": -29,
      "y": 0,
      "z": -23,
      "name": "Rock_Stone"
    },
    {
      "x": -29,
      "y": 1,
      "z": -23,
      "name": "Rock_Stone"
    },
    {
      "x": -29,
      "y": 2,
      "z": -23,
      "name": "Rock_Stone"
    },
    {
      "x": -29,
      "y": -6,
      "z": -22,
      "name": "Rock_Stone"
    },
    {
      "x": -29,
      "y": -5,
      "z": -22,
      "name": "Rock_Stone"
    },
    {
      "x": -29,
      "y": -4,
      "z": -22,
      "name": "Rock_Stone"
    },
    {
      "x": -29,
      "y": -3,
      "z": -22,
      "name": "Rock_Stone"
    },
    {
      "x": -29,
      "y": -2,
      "z": -22,
      "name": "Rock_Stone"
    },
    {
      "x": -29,
      "y": -1,
      "z": -22,
      "name": "Rock_Stone"
    },
    {
      "x": -29,
      "y": 0,
      "z": -22,
      "name": "Rock_Stone"
    },
    {
      "x": -29,
      "y": 1,
      "z": -22,
      "name": "Rock_Stone"
    },
    {
      "x": -29,
      "y": 2,
      "z": -22,
      "name": "Rock_Stone"
    },
    {
      "x": -29,
      "y": 3,
      "z": -22,
      "name": "Rock_Stone"
    },
    {
      "x": -29,
      "y": -8,
      "z": -21,
      "name": "Rock_Stone"
    },
    {
      "x": -29,
      "y": -7,
      "z": -21,
      "name": "Rock_Stone"
    },
    {
      "x": -29,
      "y": -6,
      "z": -21,
      "name": "Rock_Stone"
    },
    {
      "x": -29,
      "y": -5,
      "z": -21,
      "name": "Rock_Stone"
    },
    {
      "x": -29,
      "y": -4,
      "z": -21,
      "name": "Rock_Stone"
    },
    {
      "x": -29,
      "y": -3,
      "z": -21,
      "name": "Rock_Stone"
    },
    {
      "x": -29,
      "y": -2,
      "z": -21,
      "name": "Rock_Stone"
    },
    {
      "x": -29,
      "y": -1,
      "z": -21,
      "name": "Rock_Stone"
    },
    {
      "x": -29,
      "y": 0,
      "z": -21,
      "name": "Rock_Stone"
    },
    {
      "x": -29,
      "y": 1,
      "z": -21,
      "name": "Rock_Stone"
    },
    {
      "x": -29,
      "y": 2,
      "z": -21,
      "name": "Rock_Stone"
    },
    {
      "x": -29,
      "y": 3,
      "z": -21,
      "name": "Rock_Stone"
    },
    {
      "x": -29,
      "y": 4,
      "z": -21,
      "name": "Rock_Stone"
    },
    {
      "x": -29,
      "y": -9,
      "z": -20,
      "name": "Rock_Stone"
    },
    {
      "x": -29,
      "y": -8,
      "z": -20,
      "name": "Rock_Stone"
    },
    {
      "x": -29,
      "y": -7,
      "z": -20,
      "name": "Rock_Stone"
    },
    {
      "x": -29,
      "y": -6,
      "z": -20,
      "name": "Rock_Stone"
    },
    {
      "x": -29,
      "y": -5,
      "z": -20,
      "name": "Rock_Stone"
    },
    {
      "x": -29,
      "y": -4,
      "z": -20,
      "name": "Rock_Stone"
    },
    {
      "x": -29,
      "y": -3,
      "z": -20,
      "name": "Rock_Stone"
    },
    {
      "x": -29,
      "y": -2,
      "z": -20,
      "name": "Rock_Stone"
    },
    {
      "x": -29,
      "y": -1,
      "z": -20,
      "name": "Rock_Stone"
    },
    {
      "x": -29,
      "y": 0,
      "z": -20,
      "name": "Rock_Stone"
    },
    {
      "x": -29,
      "y": 1,
      "z": -20,
      "name": "Rock_Stone"
    },
    {
      "x": -29,
      "y": 2,
      "z": -20,
      "name": "Rock_Stone"
    },
    {
      "x": -29,
      "y": 3,
      "z": -20,
      "name": "Rock_Stone"
    },
    {
      "x": -29,
      "y": 4,
      "z": -20,
      "name": "Rock_Stone"
    },
    {
      "x": -29,
      "y": 5,
      "z": -20,
      "name": "Rock_Stone"
    },
    {
      "x": -29,
      "y": -10,
      "z": -19,
      "name": "Rock_Stone"
    },
    {
      "x": -29,
      "y": -9,
      "z": -19,
      "name": "Rock_Stone"
    },
    {
      "x": -29,
      "y": -8,
      "z": -19,
      "name": "Rock_Stone"
    },
    {
      "x": -29,
      "y": -7,
      "z": -19,
      "name": "Rock_Stone"
    },
    {
      "x": -29,
      "y": -6,
      "z": -19,
      "name": "Rock_Stone"
    },
    {
      "x": -29,
      "y": -5,
      "z": -19,
      "name": "Rock_Stone"
    },
    {
      "x": -29,
      "y": -4,
      "z": -19,
      "name": "Rock_Stone"
    },
    {
      "x": -29,
      "y": -3,
      "z": -19,
      "name": "Rock_Stone"
    },
    {
      "x": -29,
      "y": -2,
      "z": -19,
      "name": "Rock_Stone"
    },
    {
      "x": -29,
      "y": -1,
      "z": -19,
      "name": "Rock_Stone"
    },
    {
      "x": -29,
      "y": 0,
      "z": -19,
      "name": "Rock_Stone"
    },
    {
      "x": -29,
      "y": 1,
      "z": -19,
      "name": "Rock_Stone"
    },
    {
      "x": -29,
      "y": 2,
      "z": -19,
      "name": "Rock_Stone"
    },
    {
      "x": -29,
      "y": 3,
      "z": -19,
      "name": "Rock_Stone"
    },
    {
      "x": -29,
      "y": 4,
      "z": -19,
      "name": "Rock_Stone"
    },
    {
      "x": -29,
      "y": 5,
      "z": -19,
      "name": "Rock_Stone"
    },
    {
      "x": -29,
      "y": -10,
      "z": -18,
      "name": "Rock_Stone"
    },
    {
      "x": -29,
      "y": -9,
      "z": -18,
      "name": "Rock_Stone"
    },
    {
      "x": -29,
      "y": -8,
      "z": -18,
      "name": "Rock_Stone"
    },
    {
      "x": -29,
      "y": -7,
      "z": -18,
      "name": "Rock_Stone"
    },
    {
      "x": -29,
      "y": -6,
      "z": -18,
      "name": "Rock_Stone"
    },
    {
      "x": -29,
      "y": -5,
      "z": -18,
      "name": "Rock_Stone"
    },
    {
      "x": -29,
      "y": -4,
      "z": -18,
      "name": "Rock_Stone"
    },
    {
      "x": -29,
      "y": -3,
      "z": -18,
      "name": "Rock_Stone"
    },
    {
      "x": -29,
      "y": -2,
      "z": -18,
      "name": "Rock_Stone"
    },
    {
      "x": -29,
      "y": -1,
      "z": -18,
      "name": "Rock_Stone"
    },
    {
      "x": -29,
      "y": 0,
      "z": -18,
      "name": "Rock_Stone"
    },
    {
      "x": -29,
      "y": 1,
      "z": -18,
      "name": "Rock_Stone"
    },
    {
      "x": -29,
      "y": 2,
      "z": -18,
      "name": "Rock_Stone"
    },
    {
      "x": -29,
      "y": 3,
      "z": -18,
      "name": "Rock_Stone"
    },
    {
      "x": -29,
      "y": 4,
      "z": -18,
      "name": "Rock_Stone"
    },
    {
      "x": -29,
      "y": 5,
      "z": -18,
      "name": "Rock_Stone"
    },
    {
      "x": -29,
      "y": 6,
      "z": -18,
      "name": "Rock_Stone"
    },
    {
      "x": -29,
      "y": -10,
      "z": -17,
      "name": "Rock_Stone"
    },
    {
      "x": -29,
      "y": -9,
      "z": -17,
      "name": "Rock_Stone"
    },
    {
      "x": -29,
      "y": -8,
      "z": -17,
      "name": "Rock_Stone"
    },
    {
      "x": -29,
      "y": -7,
      "z": -17,
      "name": "Rock_Stone"
    },
    {
      "x": -29,
      "y": -6,
      "z": -17,
      "name": "Rock_Stone"
    },
    {
      "x": -29,
      "y": -5,
      "z": -17,
      "name": "Rock_Stone"
    },
    {
      "x": -29,
      "y": -4,
      "z": -17,
      "name": "Rock_Stone"
    },
    {
      "x": -29,
      "y": -3,
      "z": -17,
      "name": "Rock_Stone"
    },
    {
      "x": -29,
      "y": -2,
      "z": -17,
      "name": "Rock_Stone"
    },
    {
      "x": -29,
      "y": -1,
      "z": -17,
      "name": "Rock_Stone"
    },
    {
      "x": -29,
      "y": 0,
      "z": -17,
      "name": "Rock_Stone"
    },
    {
      "x": -29,
      "y": 1,
      "z": -17,
      "name": "Rock_Stone"
    },
    {
      "x": -29,
      "y": 2,
      "z": -17,
      "name": "Rock_Stone"
    },
    {
      "x": -29,
      "y": 3,
      "z": -17,
      "name": "Rock_Stone"
    },
    {
      "x": -29,
      "y": 4,
      "z": -17,
      "name": "Rock_Stone"
    },
    {
      "x": -29,
      "y": 5,
      "z": -17,
      "name": "Rock_Stone"
    },
    {
      "x": -29,
      "y": 6,
      "z": -17,
      "name": "Rock_Stone"
    },
    {
      "x": -29,
      "y": -10,
      "z": -16,
      "name": "Rock_Stone"
    },
    {
      "x": -29,
      "y": -9,
      "z": -16,
      "name": "Rock_Stone"
    },
    {
      "x": -29,
      "y": -8,
      "z": -16,
      "name": "Rock_Stone"
    },
    {
      "x": -29,
      "y": -7,
      "z": -16,
      "name": "Rock_Stone"
    },
    {
      "x": -29,
      "y": -6,
      "z": -16,
      "name": "Rock_Stone"
    },
    {
      "x": -29,
      "y": -5,
      "z": -16,
      "name": "Rock_Stone"
    },
    {
      "x": -29,
      "y": -4,
      "z": -16,
      "name": "Rock_Stone"
    },
    {
      "x": -29,
      "y": -3,
      "z": -16,
      "name": "Rock_Stone"
    },
    {
      "x": -29,
      "y": -2,
      "z": -16,
      "name": "Rock_Stone"
    },
    {
      "x": -29,
      "y": -1,
      "z": -16,
      "name": "Rock_Stone"
    },
    {
      "x": -29,
      "y": 0,
      "z": -16,
      "name": "Rock_Stone"
    },
    {
      "x": -29,
      "y": 1,
      "z": -16,
      "name": "Rock_Stone"
    },
    {
      "x": -29,
      "y": 2,
      "z": -16,
      "name": "Rock_Stone"
    },
    {
      "x": -29,
      "y": 3,
      "z": -16,
      "name": "Rock_Stone"
    },
    {
      "x": -29,
      "y": 4,
      "z": -16,
      "name": "Rock_Stone"
    },
    {
      "x": -29,
      "y": 5,
      "z": -16,
      "name": "Rock_Stone"
    },
    {
      "x": -29,
      "y": 178,
      "z": -16,
      "name": "Rock_Stone"
    },
    {
      "x": -29,
      "y": -9,
      "z": -15,
      "name": "Rock_Stone"
    },
    {
      "x": -29,
      "y": -8,
      "z": -15,
      "name": "Rock_Stone"
    },
    {
      "x": -29,
      "y": -7,
      "z": -15,
      "name": "Rock_Stone"
    },
    {
      "x": -29,
      "y": -6,
      "z": -15,
      "name": "Rock_Stone"
    },
    {
      "x": -29,
      "y": -5,
      "z": -15,
      "name": "Rock_Stone"
    },
    {
      "x": -29,
      "y": -4,
      "z": -15,
      "name": "Rock_Stone"
    },
    {
      "x": -29,
      "y": -3,
      "z": -15,
      "name": "Rock_Stone"
    },
    {
      "x": -29,
      "y": -2,
      "z": -15,
      "name": "Rock_Stone"
    },
    {
      "x": -29,
      "y": -1,
      "z": -15,
      "name": "Rock_Stone"
    },
    {
      "x": -29,
      "y": 0,
      "z": -15,
      "name": "Rock_Stone"
    },
    {
      "x": -29,
      "y": 1,
      "z": -15,
      "name": "Rock_Stone"
    },
    {
      "x": -29,
      "y": 2,
      "z": -15,
      "name": "Rock_Stone"
    },
    {
      "x": -29,
      "y": 3,
      "z": -15,
      "name": "Rock_Stone"
    },
    {
      "x": -29,
      "y": 4,
      "z": -15,
      "name": "Rock_Stone"
    },
    {
      "x": -29,
      "y": 5,
      "z": -15,
      "name": "Rock_Stone"
    },
    {
      "x": -29,
      "y": -6,
      "z": -14,
      "name": "Rock_Stone"
    },
    {
      "x": -29,
      "y": -5,
      "z": -14,
      "name": "Rock_Stone"
    },
    {
      "x": -29,
      "y": -4,
      "z": -14,
      "name": "Rock_Stone"
    },
    {
      "x": -29,
      "y": -3,
      "z": -14,
      "name": "Rock_Stone"
    },
    {
      "x": -29,
      "y": -2,
      "z": -14,
      "name": "Rock_Stone"
    },
    {
      "x": -29,
      "y": -1,
      "z": -14,
      "name": "Rock_Stone"
    },
    {
      "x": -29,
      "y": 0,
      "z": -14,
      "name": "Rock_Stone"
    },
    {
      "x": -29,
      "y": 1,
      "z": -14,
      "name": "Rock_Stone"
    },
    {
      "x": -29,
      "y": 2,
      "z": -14,
      "name": "Rock_Stone"
    },
    {
      "x": -29,
      "y": 3,
      "z": -14,
      "name": "Rock_Stone"
    },
    {
      "x": -29,
      "y": 4,
      "z": -14,
      "name": "Rock_Stone"
    },
    {
      "x": -29,
      "y": 5,
      "z": -14,
      "name": "Rock_Stone"
    },
    {
      "x": -29,
      "y": -2,
      "z": -13,
      "name": "Rock_Stone"
    },
    {
      "x": -29,
      "y": -1,
      "z": -13,
      "name": "Rock_Stone"
    },
    {
      "x": -29,
      "y": 0,
      "z": -13,
      "name": "Rock_Stone"
    },
    {
      "x": -29,
      "y": 1,
      "z": -13,
      "name": "Rock_Stone"
    },
    {
      "x": -29,
      "y": 2,
      "z": -13,
      "name": "Rock_Stone"
    },
    {
      "x": -29,
      "y": 3,
      "z": -13,
      "name": "Rock_Stone"
    },
    {
      "x": -29,
      "y": 4,
      "z": -13,
      "name": "Rock_Stone"
    },
    {
      "x": -29,
      "y": 1,
      "z": -12,
      "name": "Rock_Stone"
    },
    {
      "x": -29,
      "y": 2,
      "z": -12,
      "name": "Rock_Stone"
    },
    {
      "x": -29,
      "y": 172,
      "z": -3,
      "name": "Rock_Stone"
    },
    {
      "x": -28,
      "y": -3,
      "z": -23,
      "name": "Rock_Stone"
    },
    {
      "x": -28,
      "y": -2,
      "z": -23,
      "name": "Rock_Stone"
    },
    {
      "x": -28,
      "y": -1,
      "z": -23,
      "name": "Rock_Stone"
    },
    {
      "x": -28,
      "y": 0,
      "z": -23,
      "name": "Rock_Stone"
    },
    {
      "x": -28,
      "y": 1,
      "z": -23,
      "name": "Rock_Stone"
    },
    {
      "x": -28,
      "y": 2,
      "z": -23,
      "name": "Rock_Stone"
    },
    {
      "x": -28,
      "y": -6,
      "z": -22,
      "name": "Rock_Stone"
    },
    {
      "x": -28,
      "y": -5,
      "z": -22,
      "name": "Rock_Stone"
    },
    {
      "x": -28,
      "y": -4,
      "z": -22,
      "name": "Rock_Stone"
    },
    {
      "x": -28,
      "y": -3,
      "z": -22,
      "name": "Rock_Stone"
    },
    {
      "x": -28,
      "y": -2,
      "z": -22,
      "name": "Rock_Stone"
    },
    {
      "x": -28,
      "y": -1,
      "z": -22,
      "name": "Rock_Stone"
    },
    {
      "x": -28,
      "y": 0,
      "z": -22,
      "name": "Rock_Stone"
    },
    {
      "x": -28,
      "y": 1,
      "z": -22,
      "name": "Rock_Stone"
    },
    {
      "x": -28,
      "y": 2,
      "z": -22,
      "name": "Rock_Stone"
    },
    {
      "x": -28,
      "y": 3,
      "z": -22,
      "name": "Rock_Stone"
    },
    {
      "x": -28,
      "y": -8,
      "z": -21,
      "name": "Rock_Stone"
    },
    {
      "x": -28,
      "y": -7,
      "z": -21,
      "name": "Rock_Stone"
    },
    {
      "x": -28,
      "y": -6,
      "z": -21,
      "name": "Rock_Stone"
    },
    {
      "x": -28,
      "y": -5,
      "z": -21,
      "name": "Rock_Stone"
    },
    {
      "x": -28,
      "y": -4,
      "z": -21,
      "name": "Rock_Stone"
    },
    {
      "x": -28,
      "y": -3,
      "z": -21,
      "name": "Rock_Stone"
    },
    {
      "x": -28,
      "y": -2,
      "z": -21,
      "name": "Rock_Stone"
    },
    {
      "x": -28,
      "y": -1,
      "z": -21,
      "name": "Rock_Stone"
    },
    {
      "x": -28,
      "y": 0,
      "z": -21,
      "name": "Rock_Stone"
    },
    {
      "x": -28,
      "y": 1,
      "z": -21,
      "name": "Rock_Stone"
    },
    {
      "x": -28,
      "y": 2,
      "z": -21,
      "name": "Rock_Stone"
    },
    {
      "x": -28,
      "y": 3,
      "z": -21,
      "name": "Rock_Stone"
    },
    {
      "x": -28,
      "y": 4,
      "z": -21,
      "name": "Rock_Stone"
    },
    {
      "x": -28,
      "y": -9,
      "z": -20,
      "name": "Rock_Stone"
    },
    {
      "x": -28,
      "y": -8,
      "z": -20,
      "name": "Rock_Stone"
    },
    {
      "x": -28,
      "y": -7,
      "z": -20,
      "name": "Rock_Stone"
    },
    {
      "x": -28,
      "y": -6,
      "z": -20,
      "name": "Rock_Stone"
    },
    {
      "x": -28,
      "y": -5,
      "z": -20,
      "name": "Rock_Stone"
    },
    {
      "x": -28,
      "y": -4,
      "z": -20,
      "name": "Rock_Stone"
    },
    {
      "x": -28,
      "y": -3,
      "z": -20,
      "name": "Rock_Stone"
    },
    {
      "x": -28,
      "y": -2,
      "z": -20,
      "name": "Rock_Stone"
    },
    {
      "x": -28,
      "y": -1,
      "z": -20,
      "name": "Rock_Stone"
    },
    {
      "x": -28,
      "y": 0,
      "z": -20,
      "name": "Rock_Stone"
    },
    {
      "x": -28,
      "y": 1,
      "z": -20,
      "name": "Rock_Stone"
    },
    {
      "x": -28,
      "y": 2,
      "z": -20,
      "name": "Rock_Stone"
    },
    {
      "x": -28,
      "y": 3,
      "z": -20,
      "name": "Rock_Stone"
    },
    {
      "x": -28,
      "y": 4,
      "z": -20,
      "name": "Rock_Stone"
    },
    {
      "x": -28,
      "y": 5,
      "z": -20,
      "name": "Rock_Stone"
    },
    {
      "x": -28,
      "y": -10,
      "z": -19,
      "name": "Rock_Stone"
    },
    {
      "x": -28,
      "y": -9,
      "z": -19,
      "name": "Rock_Stone"
    },
    {
      "x": -28,
      "y": -8,
      "z": -19,
      "name": "Rock_Stone"
    },
    {
      "x": -28,
      "y": -7,
      "z": -19,
      "name": "Rock_Stone"
    },
    {
      "x": -28,
      "y": -6,
      "z": -19,
      "name": "Rock_Stone"
    },
    {
      "x": -28,
      "y": -5,
      "z": -19,
      "name": "Rock_Stone"
    },
    {
      "x": -28,
      "y": -4,
      "z": -19,
      "name": "Rock_Stone"
    },
    {
      "x": -28,
      "y": -3,
      "z": -19,
      "name": "Rock_Stone"
    },
    {
      "x": -28,
      "y": -2,
      "z": -19,
      "name": "Rock_Stone"
    },
    {
      "x": -28,
      "y": -1,
      "z": -19,
      "name": "Rock_Stone"
    },
    {
      "x": -28,
      "y": 0,
      "z": -19,
      "name": "Rock_Stone"
    },
    {
      "x": -28,
      "y": 1,
      "z": -19,
      "name": "Rock_Stone"
    },
    {
      "x": -28,
      "y": 2,
      "z": -19,
      "name": "Rock_Stone"
    },
    {
      "x": -28,
      "y": 3,
      "z": -19,
      "name": "Rock_Stone"
    },
    {
      "x": -28,
      "y": 4,
      "z": -19,
      "name": "Rock_Stone"
    },
    {
      "x": -28,
      "y": 5,
      "z": -19,
      "name": "Rock_Stone"
    },
    {
      "x": -28,
      "y": 6,
      "z": -19,
      "name": "Rock_Stone"
    },
    {
      "x": -28,
      "y": -10,
      "z": -18,
      "name": "Rock_Stone"
    },
    {
      "x": -28,
      "y": -9,
      "z": -18,
      "name": "Rock_Stone"
    },
    {
      "x": -28,
      "y": -8,
      "z": -18,
      "name": "Rock_Stone"
    },
    {
      "x": -28,
      "y": -7,
      "z": -18,
      "name": "Rock_Stone"
    },
    {
      "x": -28,
      "y": -6,
      "z": -18,
      "name": "Rock_Stone"
    },
    {
      "x": -28,
      "y": -5,
      "z": -18,
      "name": "Rock_Stone"
    },
    {
      "x": -28,
      "y": -4,
      "z": -18,
      "name": "Rock_Stone"
    },
    {
      "x": -28,
      "y": -3,
      "z": -18,
      "name": "Rock_Stone"
    },
    {
      "x": -28,
      "y": -2,
      "z": -18,
      "name": "Rock_Stone"
    },
    {
      "x": -28,
      "y": -1,
      "z": -18,
      "name": "Rock_Stone"
    },
    {
      "x": -28,
      "y": 0,
      "z": -18,
      "name": "Rock_Stone"
    },
    {
      "x": -28,
      "y": 1,
      "z": -18,
      "name": "Rock_Stone"
    },
    {
      "x": -28,
      "y": 2,
      "z": -18,
      "name": "Rock_Stone"
    },
    {
      "x": -28,
      "y": 3,
      "z": -18,
      "name": "Rock_Stone"
    },
    {
      "x": -28,
      "y": 4,
      "z": -18,
      "name": "Rock_Stone"
    },
    {
      "x": -28,
      "y": 5,
      "z": -18,
      "name": "Rock_Stone"
    },
    {
      "x": -28,
      "y": 6,
      "z": -18,
      "name": "Rock_Stone"
    },
    {
      "x": -28,
      "y": -11,
      "z": -17,
      "name": "Rock_Stone"
    },
    {
      "x": -28,
      "y": -10,
      "z": -17,
      "name": "Rock_Stone"
    },
    {
      "x": -28,
      "y": -9,
      "z": -17,
      "name": "Rock_Stone"
    },
    {
      "x": -28,
      "y": -8,
      "z": -17,
      "name": "Rock_Stone"
    },
    {
      "x": -28,
      "y": -7,
      "z": -17,
      "name": "Rock_Stone"
    },
    {
      "x": -28,
      "y": -6,
      "z": -17,
      "name": "Rock_Stone"
    },
    {
      "x": -28,
      "y": -5,
      "z": -17,
      "name": "Rock_Stone"
    },
    {
      "x": -28,
      "y": -4,
      "z": -17,
      "name": "Rock_Stone"
    },
    {
      "x": -28,
      "y": -3,
      "z": -17,
      "name": "Rock_Stone"
    },
    {
      "x": -28,
      "y": -2,
      "z": -17,
      "name": "Rock_Stone"
    },
    {
      "x": -28,
      "y": -1,
      "z": -17,
      "name": "Rock_Stone"
    },
    {
      "x": -28,
      "y": 0,
      "z": -17,
      "name": "Rock_Stone"
    },
    {
      "x": -28,
      "y": 1,
      "z": -17,
      "name": "Rock_Stone"
    },
    {
      "x": -28,
      "y": 2,
      "z": -17,
      "name": "Rock_Stone"
    },
    {
      "x": -28,
      "y": 3,
      "z": -17,
      "name": "Rock_Stone"
    },
    {
      "x": -28,
      "y": 4,
      "z": -17,
      "name": "Rock_Stone"
    },
    {
      "x": -28,
      "y": 5,
      "z": -17,
      "name": "Rock_Stone"
    },
    {
      "x": -28,
      "y": 6,
      "z": -17,
      "name": "Rock_Stone"
    },
    {
      "x": -28,
      "y": -10,
      "z": -16,
      "name": "Rock_Stone"
    },
    {
      "x": -28,
      "y": -9,
      "z": -16,
      "name": "Rock_Stone"
    },
    {
      "x": -28,
      "y": -8,
      "z": -16,
      "name": "Rock_Stone"
    },
    {
      "x": -28,
      "y": -7,
      "z": -16,
      "name": "Rock_Stone"
    },
    {
      "x": -28,
      "y": -6,
      "z": -16,
      "name": "Rock_Stone"
    },
    {
      "x": -28,
      "y": -5,
      "z": -16,
      "name": "Rock_Stone"
    },
    {
      "x": -28,
      "y": -4,
      "z": -16,
      "name": "Rock_Stone"
    },
    {
      "x": -28,
      "y": -3,
      "z": -16,
      "name": "Rock_Stone"
    },
    {
      "x": -28,
      "y": -2,
      "z": -16,
      "name": "Rock_Stone"
    },
    {
      "x": -28,
      "y": -1,
      "z": -16,
      "name": "Rock_Stone"
    },
    {
      "x": -28,
      "y": 0,
      "z": -16,
      "name": "Rock_Stone"
    },
    {
      "x": -28,
      "y": 1,
      "z": -16,
      "name": "Rock_Stone"
    },
    {
      "x": -28,
      "y": 2,
      "z": -16,
      "name": "Rock_Stone"
    },
    {
      "x": -28,
      "y": 3,
      "z": -16,
      "name": "Rock_Stone"
    },
    {
      "x": -28,
      "y": 4,
      "z": -16,
      "name": "Rock_Stone"
    },
    {
      "x": -28,
      "y": 5,
      "z": -16,
      "name": "Rock_Stone"
    },
    {
      "x": -28,
      "y": 6,
      "z": -16,
      "name": "Rock_Stone"
    },
    {
      "x": -28,
      "y": -10,
      "z": -15,
      "name": "Rock_Stone"
    },
    {
      "x": -28,
      "y": -9,
      "z": -15,
      "name": "Rock_Stone"
    },
    {
      "x": -28,
      "y": -8,
      "z": -15,
      "name": "Rock_Stone"
    },
    {
      "x": -28,
      "y": -7,
      "z": -15,
      "name": "Rock_Stone"
    },
    {
      "x": -28,
      "y": -6,
      "z": -15,
      "name": "Rock_Stone"
    },
    {
      "x": -28,
      "y": -5,
      "z": -15,
      "name": "Rock_Stone"
    },
    {
      "x": -28,
      "y": -4,
      "z": -15,
      "name": "Rock_Stone"
    },
    {
      "x": -28,
      "y": -3,
      "z": -15,
      "name": "Rock_Stone"
    },
    {
      "x": -28,
      "y": -2,
      "z": -15,
      "name": "Rock_Stone"
    },
    {
      "x": -28,
      "y": -1,
      "z": -15,
      "name": "Rock_Stone"
    },
    {
      "x": -28,
      "y": 0,
      "z": -15,
      "name": "Rock_Stone"
    },
    {
      "x": -28,
      "y": 1,
      "z": -15,
      "name": "Rock_Stone"
    },
    {
      "x": -28,
      "y": 2,
      "z": -15,
      "name": "Rock_Stone"
    },
    {
      "x": -28,
      "y": 3,
      "z": -15,
      "name": "Rock_Stone"
    },
    {
      "x": -28,
      "y": 4,
      "z": -15,
      "name": "Rock_Stone"
    },
    {
      "x": -28,
      "y": 5,
      "z": -15,
      "name": "Rock_Stone"
    },
    {
      "x": -28,
      "y": 6,
      "z": -15,
      "name": "Rock_Stone"
    },
    {
      "x": -28,
      "y": 177,
      "z": -15,
      "name": "Rock_Stone"
    },
    {
      "x": -28,
      "y": 178,
      "z": -15,
      "name": "Rock_Stone"
    },
    {
      "x": -28,
      "y": -9,
      "z": -14,
      "name": "Rock_Stone"
    },
    {
      "x": -28,
      "y": -8,
      "z": -14,
      "name": "Rock_Stone"
    },
    {
      "x": -28,
      "y": -7,
      "z": -14,
      "name": "Rock_Stone"
    },
    {
      "x": -28,
      "y": -6,
      "z": -14,
      "name": "Rock_Stone"
    },
    {
      "x": -28,
      "y": -5,
      "z": -14,
      "name": "Rock_Stone"
    },
    {
      "x": -28,
      "y": -4,
      "z": -14,
      "name": "Rock_Stone"
    },
    {
      "x": -28,
      "y": -3,
      "z": -14,
      "name": "Rock_Stone"
    },
    {
      "x": -28,
      "y": -2,
      "z": -14,
      "name": "Rock_Stone"
    },
    {
      "x": -28,
      "y": -1,
      "z": -14,
      "name": "Rock_Stone"
    },
    {
      "x": -28,
      "y": 0,
      "z": -14,
      "name": "Rock_Stone"
    },
    {
      "x": -28,
      "y": 1,
      "z": -14,
      "name": "Rock_Stone"
    },
    {
      "x": -28,
      "y": 2,
      "z": -14,
      "name": "Rock_Stone"
    },
    {
      "x": -28,
      "y": 3,
      "z": -14,
      "name": "Rock_Stone"
    },
    {
      "x": -28,
      "y": 4,
      "z": -14,
      "name": "Rock_Stone"
    },
    {
      "x": -28,
      "y": 5,
      "z": -14,
      "name": "Rock_Stone"
    },
    {
      "x": -28,
      "y": 176,
      "z": -14,
      "name": "Rock_Stone"
    },
    {
      "x": -28,
      "y": -5,
      "z": -13,
      "name": "Rock_Stone"
    },
    {
      "x": -28,
      "y": -4,
      "z": -13,
      "name": "Rock_Stone"
    },
    {
      "x": -28,
      "y": -3,
      "z": -13,
      "name": "Rock_Stone"
    },
    {
      "x": -28,
      "y": -2,
      "z": -13,
      "name": "Rock_Stone"
    },
    {
      "x": -28,
      "y": -1,
      "z": -13,
      "name": "Rock_Stone"
    },
    {
      "x": -28,
      "y": 0,
      "z": -13,
      "name": "Rock_Stone"
    },
    {
      "x": -28,
      "y": 1,
      "z": -13,
      "name": "Rock_Stone"
    },
    {
      "x": -28,
      "y": 2,
      "z": -13,
      "name": "Rock_Stone"
    },
    {
      "x": -28,
      "y": 3,
      "z": -13,
      "name": "Rock_Stone"
    },
    {
      "x": -28,
      "y": 4,
      "z": -13,
      "name": "Rock_Stone"
    },
    {
      "x": -28,
      "y": 5,
      "z": -13,
      "name": "Rock_Stone"
    },
    {
      "x": -28,
      "y": -1,
      "z": -12,
      "name": "Rock_Stone"
    },
    {
      "x": -28,
      "y": 0,
      "z": -12,
      "name": "Rock_Stone"
    },
    {
      "x": -28,
      "y": 1,
      "z": -12,
      "name": "Rock_Stone"
    },
    {
      "x": -28,
      "y": 2,
      "z": -12,
      "name": "Rock_Stone"
    },
    {
      "x": -28,
      "y": 3,
      "z": -12,
      "name": "Rock_Stone"
    },
    {
      "x": -28,
      "y": 171,
      "z": -3,
      "name": "Rock_Stone"
    },
    {
      "x": -28,
      "y": 172,
      "z": -3,
      "name": "Rock_Stone"
    },
    {
      "x": -28,
      "y": 172,
      "z": -2,
      "name": "Rock_Stone"
    },
    {
      "x": -27,
      "y": -2,
      "z": -23,
      "name": "Rock_Stone"
    },
    {
      "x": -27,
      "y": -1,
      "z": -23,
      "name": "Rock_Stone"
    },
    {
      "x": -27,
      "y": 0,
      "z": -23,
      "name": "Rock_Stone"
    },
    {
      "x": -27,
      "y": 1,
      "z": -23,
      "name": "Rock_Stone"
    },
    {
      "x": -27,
      "y": 2,
      "z": -23,
      "name": "Rock_Stone"
    },
    {
      "x": -27,
      "y": -4,
      "z": -22,
      "name": "Rock_Stone"
    },
    {
      "x": -27,
      "y": -3,
      "z": -22,
      "name": "Rock_Stone"
    },
    {
      "x": -27,
      "y": -2,
      "z": -22,
      "name": "Rock_Stone"
    },
    {
      "x": -27,
      "y": -1,
      "z": -22,
      "name": "Rock_Stone"
    },
    {
      "x": -27,
      "y": 0,
      "z": -22,
      "name": "Rock_Stone"
    },
    {
      "x": -27,
      "y": 1,
      "z": -22,
      "name": "Rock_Stone"
    },
    {
      "x": -27,
      "y": 2,
      "z": -22,
      "name": "Rock_Stone"
    },
    {
      "x": -27,
      "y": 3,
      "z": -22,
      "name": "Rock_Stone"
    },
    {
      "x": -27,
      "y": -7,
      "z": -21,
      "name": "Rock_Stone"
    },
    {
      "x": -27,
      "y": -6,
      "z": -21,
      "name": "Rock_Stone"
    },
    {
      "x": -27,
      "y": -5,
      "z": -21,
      "name": "Rock_Stone"
    },
    {
      "x": -27,
      "y": -4,
      "z": -21,
      "name": "Rock_Stone"
    },
    {
      "x": -27,
      "y": -3,
      "z": -21,
      "name": "Rock_Stone"
    },
    {
      "x": -27,
      "y": -2,
      "z": -21,
      "name": "Rock_Stone"
    },
    {
      "x": -27,
      "y": -1,
      "z": -21,
      "name": "Rock_Stone"
    },
    {
      "x": -27,
      "y": 0,
      "z": -21,
      "name": "Rock_Stone"
    },
    {
      "x": -27,
      "y": 1,
      "z": -21,
      "name": "Rock_Stone"
    },
    {
      "x": -27,
      "y": 2,
      "z": -21,
      "name": "Rock_Stone"
    },
    {
      "x": -27,
      "y": 3,
      "z": -21,
      "name": "Rock_Stone"
    },
    {
      "x": -27,
      "y": 4,
      "z": -21,
      "name": "Rock_Stone"
    },
    {
      "x": -27,
      "y": -9,
      "z": -20,
      "name": "Rock_Stone"
    },
    {
      "x": -27,
      "y": -8,
      "z": -20,
      "name": "Rock_Stone"
    },
    {
      "x": -27,
      "y": -7,
      "z": -20,
      "name": "Rock_Stone"
    },
    {
      "x": -27,
      "y": -6,
      "z": -20,
      "name": "Rock_Stone"
    },
    {
      "x": -27,
      "y": -5,
      "z": -20,
      "name": "Rock_Stone"
    },
    {
      "x": -27,
      "y": -4,
      "z": -20,
      "name": "Rock_Stone"
    },
    {
      "x": -27,
      "y": -3,
      "z": -20,
      "name": "Rock_Stone"
    },
    {
      "x": -27,
      "y": -2,
      "z": -20,
      "name": "Rock_Stone"
    },
    {
      "x": -27,
      "y": -1,
      "z": -20,
      "name": "Rock_Stone"
    },
    {
      "x": -27,
      "y": 0,
      "z": -20,
      "name": "Rock_Stone"
    },
    {
      "x": -27,
      "y": 1,
      "z": -20,
      "name": "Rock_Stone"
    },
    {
      "x": -27,
      "y": 2,
      "z": -20,
      "name": "Rock_Stone"
    },
    {
      "x": -27,
      "y": 3,
      "z": -20,
      "name": "Rock_Stone"
    },
    {
      "x": -27,
      "y": 4,
      "z": -20,
      "name": "Rock_Stone"
    },
    {
      "x": -27,
      "y": 5,
      "z": -20,
      "name": "Rock_Stone"
    },
    {
      "x": -27,
      "y": -10,
      "z": -19,
      "name": "Rock_Stone"
    },
    {
      "x": -27,
      "y": -9,
      "z": -19,
      "name": "Rock_Stone"
    },
    {
      "x": -27,
      "y": -8,
      "z": -19,
      "name": "Rock_Stone"
    },
    {
      "x": -27,
      "y": -7,
      "z": -19,
      "name": "Rock_Stone"
    },
    {
      "x": -27,
      "y": -6,
      "z": -19,
      "name": "Rock_Stone"
    },
    {
      "x": -27,
      "y": -5,
      "z": -19,
      "name": "Rock_Stone"
    },
    {
      "x": -27,
      "y": -4,
      "z": -19,
      "name": "Rock_Stone"
    },
    {
      "x": -27,
      "y": -3,
      "z": -19,
      "name": "Rock_Stone"
    },
    {
      "x": -27,
      "y": -2,
      "z": -19,
      "name": "Rock_Stone"
    },
    {
      "x": -27,
      "y": -1,
      "z": -19,
      "name": "Rock_Stone"
    },
    {
      "x": -27,
      "y": 0,
      "z": -19,
      "name": "Rock_Stone"
    },
    {
      "x": -27,
      "y": 1,
      "z": -19,
      "name": "Rock_Stone"
    },
    {
      "x": -27,
      "y": 2,
      "z": -19,
      "name": "Rock_Stone"
    },
    {
      "x": -27,
      "y": 3,
      "z": -19,
      "name": "Rock_Stone"
    },
    {
      "x": -27,
      "y": 4,
      "z": -19,
      "name": "Rock_Stone"
    },
    {
      "x": -27,
      "y": 5,
      "z": -19,
      "name": "Rock_Stone"
    },
    {
      "x": -27,
      "y": 6,
      "z": -19,
      "name": "Rock_Stone"
    },
    {
      "x": -27,
      "y": -10,
      "z": -18,
      "name": "Rock_Stone"
    },
    {
      "x": -27,
      "y": -9,
      "z": -18,
      "name": "Rock_Stone"
    },
    {
      "x": -27,
      "y": -8,
      "z": -18,
      "name": "Rock_Stone"
    },
    {
      "x": -27,
      "y": -7,
      "z": -18,
      "name": "Rock_Stone"
    },
    {
      "x": -27,
      "y": -6,
      "z": -18,
      "name": "Rock_Stone"
    },
    {
      "x": -27,
      "y": -5,
      "z": -18,
      "name": "Rock_Stone"
    },
    {
      "x": -27,
      "y": -4,
      "z": -18,
      "name": "Rock_Stone"
    },
    {
      "x": -27,
      "y": -3,
      "z": -18,
      "name": "Rock_Stone"
    },
    {
      "x": -27,
      "y": -2,
      "z": -18,
      "name": "Rock_Stone"
    },
    {
      "x": -27,
      "y": -1,
      "z": -18,
      "name": "Rock_Stone"
    },
    {
      "x": -27,
      "y": 0,
      "z": -18,
      "name": "Rock_Stone"
    },
    {
      "x": -27,
      "y": 1,
      "z": -18,
      "name": "Rock_Stone"
    },
    {
      "x": -27,
      "y": 2,
      "z": -18,
      "name": "Rock_Stone"
    },
    {
      "x": -27,
      "y": 3,
      "z": -18,
      "name": "Rock_Stone"
    },
    {
      "x": -27,
      "y": 4,
      "z": -18,
      "name": "Rock_Stone"
    },
    {
      "x": -27,
      "y": 5,
      "z": -18,
      "name": "Rock_Stone"
    },
    {
      "x": -27,
      "y": 6,
      "z": -18,
      "name": "Rock_Stone"
    },
    {
      "x": -27,
      "y": -11,
      "z": -17,
      "name": "Rock_Stone"
    },
    {
      "x": -27,
      "y": -10,
      "z": -17,
      "name": "Rock_Stone"
    },
    {
      "x": -27,
      "y": -9,
      "z": -17,
      "name": "Rock_Stone"
    },
    {
      "x": -27,
      "y": -8,
      "z": -17,
      "name": "Rock_Stone"
    },
    {
      "x": -27,
      "y": -7,
      "z": -17,
      "name": "Rock_Stone"
    },
    {
      "x": -27,
      "y": -6,
      "z": -17,
      "name": "Rock_Stone"
    },
    {
      "x": -27,
      "y": -5,
      "z": -17,
      "name": "Rock_Stone"
    },
    {
      "x": -27,
      "y": -4,
      "z": -17,
      "name": "Rock_Stone"
    },
    {
      "x": -27,
      "y": -3,
      "z": -17,
      "name": "Rock_Stone"
    },
    {
      "x": -27,
      "y": -2,
      "z": -17,
      "name": "Rock_Stone"
    },
    {
      "x": -27,
      "y": -1,
      "z": -17,
      "name": "Rock_Stone"
    },
    {
      "x": -27,
      "y": 0,
      "z": -17,
      "name": "Rock_Stone"
    },
    {
      "x": -27,
      "y": 1,
      "z": -17,
      "name": "Rock_Stone"
    },
    {
      "x": -27,
      "y": 2,
      "z": -17,
      "name": "Rock_Stone"
    },
    {
      "x": -27,
      "y": 3,
      "z": -17,
      "name": "Rock_Stone"
    },
    {
      "x": -27,
      "y": 4,
      "z": -17,
      "name": "Rock_Stone"
    },
    {
      "x": -27,
      "y": 5,
      "z": -17,
      "name": "Rock_Stone"
    },
    {
      "x": -27,
      "y": 6,
      "z": -17,
      "name": "Rock_Stone"
    },
    {
      "x": -27,
      "y": -11,
      "z": -16,
      "name": "Rock_Stone"
    },
    {
      "x": -27,
      "y": -10,
      "z": -16,
      "name": "Rock_Stone"
    },
    {
      "x": -27,
      "y": -9,
      "z": -16,
      "name": "Rock_Stone"
    },
    {
      "x": -27,
      "y": -8,
      "z": -16,
      "name": "Rock_Stone"
    },
    {
      "x": -27,
      "y": -7,
      "z": -16,
      "name": "Rock_Stone"
    },
    {
      "x": -27,
      "y": -6,
      "z": -16,
      "name": "Rock_Stone"
    },
    {
      "x": -27,
      "y": -5,
      "z": -16,
      "name": "Rock_Stone"
    },
    {
      "x": -27,
      "y": -4,
      "z": -16,
      "name": "Rock_Stone"
    },
    {
      "x": -27,
      "y": -3,
      "z": -16,
      "name": "Rock_Stone"
    },
    {
      "x": -27,
      "y": -2,
      "z": -16,
      "name": "Rock_Stone"
    },
    {
      "x": -27,
      "y": -1,
      "z": -16,
      "name": "Rock_Stone"
    },
    {
      "x": -27,
      "y": 0,
      "z": -16,
      "name": "Rock_Stone"
    },
    {
      "x": -27,
      "y": 1,
      "z": -16,
      "name": "Rock_Stone"
    },
    {
      "x": -27,
      "y": 2,
      "z": -16,
      "name": "Rock_Stone"
    },
    {
      "x": -27,
      "y": 3,
      "z": -16,
      "name": "Rock_Stone"
    },
    {
      "x": -27,
      "y": 4,
      "z": -16,
      "name": "Rock_Stone"
    },
    {
      "x": -27,
      "y": 5,
      "z": -16,
      "name": "Rock_Stone"
    },
    {
      "x": -27,
      "y": 6,
      "z": -16,
      "name": "Rock_Stone"
    },
    {
      "x": -27,
      "y": -11,
      "z": -15,
      "name": "Rock_Stone"
    },
    {
      "x": -27,
      "y": -10,
      "z": -15,
      "name": "Rock_Stone"
    },
    {
      "x": -27,
      "y": -9,
      "z": -15,
      "name": "Rock_Stone"
    },
    {
      "x": -27,
      "y": -8,
      "z": -15,
      "name": "Rock_Stone"
    },
    {
      "x": -27,
      "y": -7,
      "z": -15,
      "name": "Rock_Stone"
    },
    {
      "x": -27,
      "y": -6,
      "z": -15,
      "name": "Rock_Stone"
    },
    {
      "x": -27,
      "y": -5,
      "z": -15,
      "name": "Rock_Stone"
    },
    {
      "x": -27,
      "y": -4,
      "z": -15,
      "name": "Rock_Stone"
    },
    {
      "x": -27,
      "y": -3,
      "z": -15,
      "name": "Rock_Stone"
    },
    {
      "x": -27,
      "y": -2,
      "z": -15,
      "name": "Rock_Stone"
    },
    {
      "x": -27,
      "y": -1,
      "z": -15,
      "name": "Rock_Stone"
    },
    {
      "x": -27,
      "y": 0,
      "z": -15,
      "name": "Rock_Stone"
    },
    {
      "x": -27,
      "y": 1,
      "z": -15,
      "name": "Rock_Stone"
    },
    {
      "x": -27,
      "y": 2,
      "z": -15,
      "name": "Rock_Stone"
    },
    {
      "x": -27,
      "y": 3,
      "z": -15,
      "name": "Rock_Stone"
    },
    {
      "x": -27,
      "y": 4,
      "z": -15,
      "name": "Rock_Stone"
    },
    {
      "x": -27,
      "y": 5,
      "z": -15,
      "name": "Rock_Stone"
    },
    {
      "x": -27,
      "y": 6,
      "z": -15,
      "name": "Rock_Stone"
    },
    {
      "x": -27,
      "y": 177,
      "z": -15,
      "name": "Rock_Stone"
    },
    {
      "x": -27,
      "y": -11,
      "z": -14,
      "name": "Rock_Stone"
    },
    {
      "x": -27,
      "y": -10,
      "z": -14,
      "name": "Rock_Stone"
    },
    {
      "x": -27,
      "y": -9,
      "z": -14,
      "name": "Rock_Stone"
    },
    {
      "x": -27,
      "y": -8,
      "z": -14,
      "name": "Rock_Stone"
    },
    {
      "x": -27,
      "y": -7,
      "z": -14,
      "name": "Rock_Stone"
    },
    {
      "x": -27,
      "y": -6,
      "z": -14,
      "name": "Rock_Stone"
    },
    {
      "x": -27,
      "y": -5,
      "z": -14,
      "name": "Rock_Stone"
    },
    {
      "x": -27,
      "y": -4,
      "z": -14,
      "name": "Rock_Stone"
    },
    {
      "x": -27,
      "y": -3,
      "z": -14,
      "name": "Rock_Stone"
    },
    {
      "x": -27,
      "y": -2,
      "z": -14,
      "name": "Rock_Stone"
    },
    {
      "x": -27,
      "y": -1,
      "z": -14,
      "name": "Rock_Stone"
    },
    {
      "x": -27,
      "y": 0,
      "z": -14,
      "name": "Rock_Stone"
    },
    {
      "x": -27,
      "y": 1,
      "z": -14,
      "name": "Rock_Stone"
    },
    {
      "x": -27,
      "y": 2,
      "z": -14,
      "name": "Rock_Stone"
    },
    {
      "x": -27,
      "y": 3,
      "z": -14,
      "name": "Rock_Stone"
    },
    {
      "x": -27,
      "y": 4,
      "z": -14,
      "name": "Rock_Stone"
    },
    {
      "x": -27,
      "y": 5,
      "z": -14,
      "name": "Rock_Stone"
    },
    {
      "x": -27,
      "y": 6,
      "z": -14,
      "name": "Rock_Stone"
    },
    {
      "x": -27,
      "y": 176,
      "z": -14,
      "name": "Rock_Stone"
    },
    {
      "x": -27,
      "y": 177,
      "z": -14,
      "name": "Rock_Stone"
    },
    {
      "x": -27,
      "y": -9,
      "z": -13,
      "name": "Rock_Stone"
    },
    {
      "x": -27,
      "y": -8,
      "z": -13,
      "name": "Rock_Stone"
    },
    {
      "x": -27,
      "y": -7,
      "z": -13,
      "name": "Rock_Stone"
    },
    {
      "x": -27,
      "y": -6,
      "z": -13,
      "name": "Rock_Stone"
    },
    {
      "x": -27,
      "y": -5,
      "z": -13,
      "name": "Rock_Stone"
    },
    {
      "x": -27,
      "y": -4,
      "z": -13,
      "name": "Rock_Stone"
    },
    {
      "x": -27,
      "y": -3,
      "z": -13,
      "name": "Rock_Stone"
    },
    {
      "x": -27,
      "y": -2,
      "z": -13,
      "name": "Rock_Stone"
    },
    {
      "x": -27,
      "y": -1,
      "z": -13,
      "name": "Rock_Stone"
    },
    {
      "x": -27,
      "y": 0,
      "z": -13,
      "name": "Rock_Stone"
    },
    {
      "x": -27,
      "y": 1,
      "z": -13,
      "name": "Rock_Stone"
    },
    {
      "x": -27,
      "y": 2,
      "z": -13,
      "name": "Rock_Stone"
    },
    {
      "x": -27,
      "y": 3,
      "z": -13,
      "name": "Rock_Stone"
    },
    {
      "x": -27,
      "y": 4,
      "z": -13,
      "name": "Rock_Stone"
    },
    {
      "x": -27,
      "y": 5,
      "z": -13,
      "name": "Rock_Stone"
    },
    {
      "x": -27,
      "y": 6,
      "z": -13,
      "name": "Rock_Stone"
    },
    {
      "x": -27,
      "y": 175,
      "z": -13,
      "name": "Rock_Stone"
    },
    {
      "x": -27,
      "y": 177,
      "z": -13,
      "name": "Rock_Stone"
    },
    {
      "x": -27,
      "y": -3,
      "z": -12,
      "name": "Rock_Stone"
    },
    {
      "x": -27,
      "y": -2,
      "z": -12,
      "name": "Rock_Stone"
    },
    {
      "x": -27,
      "y": -1,
      "z": -12,
      "name": "Rock_Stone"
    },
    {
      "x": -27,
      "y": 0,
      "z": -12,
      "name": "Rock_Stone"
    },
    {
      "x": -27,
      "y": 1,
      "z": -12,
      "name": "Rock_Stone"
    },
    {
      "x": -27,
      "y": 2,
      "z": -12,
      "name": "Rock_Stone"
    },
    {
      "x": -27,
      "y": 3,
      "z": -12,
      "name": "Rock_Stone"
    },
    {
      "x": -27,
      "y": 4,
      "z": -12,
      "name": "Rock_Stone"
    },
    {
      "x": -27,
      "y": 5,
      "z": -12,
      "name": "Rock_Stone"
    },
    {
      "x": -27,
      "y": -1,
      "z": -11,
      "name": "Rock_Stone"
    },
    {
      "x": -27,
      "y": 0,
      "z": -11,
      "name": "Rock_Stone"
    },
    {
      "x": -27,
      "y": 1,
      "z": -11,
      "name": "Rock_Stone"
    },
    {
      "x": -27,
      "y": 2,
      "z": -11,
      "name": "Rock_Stone"
    },
    {
      "x": -27,
      "y": 3,
      "z": -11,
      "name": "Rock_Stone"
    },
    {
      "x": -27,
      "y": 171,
      "z": -3,
      "name": "Rock_Stone"
    },
    {
      "x": -27,
      "y": 172,
      "z": -3,
      "name": "Rock_Stone"
    },
    {
      "x": -27,
      "y": 172,
      "z": -2,
      "name": "Rock_Stone"
    },
    {
      "x": -27,
      "y": 173,
      "z": 9,
      "name": "Rock_Stone"
    },
    {
      "x": -26,
      "y": -1,
      "z": -23,
      "name": "Rock_Stone"
    },
    {
      "x": -26,
      "y": 0,
      "z": -23,
      "name": "Rock_Stone"
    },
    {
      "x": -26,
      "y": 1,
      "z": -23,
      "name": "Rock_Stone"
    },
    {
      "x": -26,
      "y": -3,
      "z": -22,
      "name": "Rock_Stone"
    },
    {
      "x": -26,
      "y": -2,
      "z": -22,
      "name": "Rock_Stone"
    },
    {
      "x": -26,
      "y": -1,
      "z": -22,
      "name": "Rock_Stone"
    },
    {
      "x": -26,
      "y": 0,
      "z": -22,
      "name": "Rock_Stone"
    },
    {
      "x": -26,
      "y": 1,
      "z": -22,
      "name": "Rock_Stone"
    },
    {
      "x": -26,
      "y": 2,
      "z": -22,
      "name": "Rock_Stone"
    },
    {
      "x": -26,
      "y": 3,
      "z": -22,
      "name": "Rock_Stone"
    },
    {
      "x": -26,
      "y": -5,
      "z": -21,
      "name": "Rock_Stone"
    },
    {
      "x": -26,
      "y": -4,
      "z": -21,
      "name": "Rock_Stone"
    },
    {
      "x": -26,
      "y": -3,
      "z": -21,
      "name": "Rock_Stone"
    },
    {
      "x": -26,
      "y": -2,
      "z": -21,
      "name": "Rock_Stone"
    },
    {
      "x": -26,
      "y": -1,
      "z": -21,
      "name": "Rock_Stone"
    },
    {
      "x": -26,
      "y": 0,
      "z": -21,
      "name": "Rock_Stone"
    },
    {
      "x": -26,
      "y": 1,
      "z": -21,
      "name": "Rock_Stone"
    },
    {
      "x": -26,
      "y": 2,
      "z": -21,
      "name": "Rock_Stone"
    },
    {
      "x": -26,
      "y": 3,
      "z": -21,
      "name": "Rock_Stone"
    },
    {
      "x": -26,
      "y": 4,
      "z": -21,
      "name": "Rock_Stone"
    },
    {
      "x": -26,
      "y": -8,
      "z": -20,
      "name": "Rock_Stone"
    },
    {
      "x": -26,
      "y": -7,
      "z": -20,
      "name": "Rock_Stone"
    },
    {
      "x": -26,
      "y": -6,
      "z": -20,
      "name": "Rock_Stone"
    },
    {
      "x": -26,
      "y": -5,
      "z": -20,
      "name": "Rock_Stone"
    },
    {
      "x": -26,
      "y": -4,
      "z": -20,
      "name": "Rock_Stone"
    },
    {
      "x": -26,
      "y": -3,
      "z": -20,
      "name": "Rock_Stone"
    },
    {
      "x": -26,
      "y": -2,
      "z": -20,
      "name": "Rock_Stone"
    },
    {
      "x": -26,
      "y": -1,
      "z": -20,
      "name": "Rock_Stone"
    },
    {
      "x": -26,
      "y": 0,
      "z": -20,
      "name": "Rock_Stone"
    },
    {
      "x": -26,
      "y": 1,
      "z": -20,
      "name": "Rock_Stone"
    },
    {
      "x": -26,
      "y": 2,
      "z": -20,
      "name": "Rock_Stone"
    },
    {
      "x": -26,
      "y": 3,
      "z": -20,
      "name": "Rock_Stone"
    },
    {
      "x": -26,
      "y": 4,
      "z": -20,
      "name": "Rock_Stone"
    },
    {
      "x": -26,
      "y": 5,
      "z": -20,
      "name": "Rock_Stone"
    },
    {
      "x": -26,
      "y": -9,
      "z": -19,
      "name": "Rock_Stone"
    },
    {
      "x": -26,
      "y": -8,
      "z": -19,
      "name": "Rock_Stone"
    },
    {
      "x": -26,
      "y": -7,
      "z": -19,
      "name": "Rock_Stone"
    },
    {
      "x": -26,
      "y": -6,
      "z": -19,
      "name": "Rock_Stone"
    },
    {
      "x": -26,
      "y": -5,
      "z": -19,
      "name": "Rock_Stone"
    },
    {
      "x": -26,
      "y": -4,
      "z": -19,
      "name": "Rock_Stone"
    },
    {
      "x": -26,
      "y": -3,
      "z": -19,
      "name": "Rock_Stone"
    },
    {
      "x": -26,
      "y": -2,
      "z": -19,
      "name": "Rock_Stone"
    },
    {
      "x": -26,
      "y": -1,
      "z": -19,
      "name": "Rock_Stone"
    },
    {
      "x": -26,
      "y": 0,
      "z": -19,
      "name": "Rock_Stone"
    },
    {
      "x": -26,
      "y": 1,
      "z": -19,
      "name": "Rock_Stone"
    },
    {
      "x": -26,
      "y": 2,
      "z": -19,
      "name": "Rock_Stone"
    },
    {
      "x": -26,
      "y": 3,
      "z": -19,
      "name": "Rock_Stone"
    },
    {
      "x": -26,
      "y": 4,
      "z": -19,
      "name": "Rock_Stone"
    },
    {
      "x": -26,
      "y": 5,
      "z": -19,
      "name": "Rock_Stone"
    },
    {
      "x": -26,
      "y": 6,
      "z": -19,
      "name": "Rock_Stone"
    },
    {
      "x": -26,
      "y": -10,
      "z": -18,
      "name": "Rock_Stone"
    },
    {
      "x": -26,
      "y": -9,
      "z": -18,
      "name": "Rock_Stone"
    },
    {
      "x": -26,
      "y": -8,
      "z": -18,
      "name": "Rock_Stone"
    },
    {
      "x": -26,
      "y": -7,
      "z": -18,
      "name": "Rock_Stone"
    },
    {
      "x": -26,
      "y": -6,
      "z": -18,
      "name": "Rock_Stone"
    },
    {
      "x": -26,
      "y": -5,
      "z": -18,
      "name": "Rock_Stone"
    },
    {
      "x": -26,
      "y": -4,
      "z": -18,
      "name": "Rock_Stone"
    },
    {
      "x": -26,
      "y": -3,
      "z": -18,
      "name": "Rock_Stone"
    },
    {
      "x": -26,
      "y": -2,
      "z": -18,
      "name": "Rock_Stone"
    },
    {
      "x": -26,
      "y": -1,
      "z": -18,
      "name": "Rock_Stone"
    },
    {
      "x": -26,
      "y": 0,
      "z": -18,
      "name": "Rock_Stone"
    },
    {
      "x": -26,
      "y": 1,
      "z": -18,
      "name": "Rock_Stone"
    },
    {
      "x": -26,
      "y": 2,
      "z": -18,
      "name": "Rock_Stone"
    },
    {
      "x": -26,
      "y": 3,
      "z": -18,
      "name": "Rock_Stone"
    },
    {
      "x": -26,
      "y": 4,
      "z": -18,
      "name": "Rock_Stone"
    },
    {
      "x": -26,
      "y": 5,
      "z": -18,
      "name": "Rock_Stone"
    },
    {
      "x": -26,
      "y": 6,
      "z": -18,
      "name": "Rock_Stone"
    },
    {
      "x": -26,
      "y": -11,
      "z": -17,
      "name": "Rock_Stone"
    },
    {
      "x": -26,
      "y": -10,
      "z": -17,
      "name": "Rock_Stone"
    },
    {
      "x": -26,
      "y": -9,
      "z": -17,
      "name": "Rock_Stone"
    },
    {
      "x": -26,
      "y": -8,
      "z": -17,
      "name": "Rock_Stone"
    },
    {
      "x": -26,
      "y": -7,
      "z": -17,
      "name": "Rock_Stone"
    },
    {
      "x": -26,
      "y": -6,
      "z": -17,
      "name": "Rock_Stone"
    },
    {
      "x": -26,
      "y": -5,
      "z": -17,
      "name": "Rock_Stone"
    },
    {
      "x": -26,
      "y": -4,
      "z": -17,
      "name": "Rock_Stone"
    },
    {
      "x": -26,
      "y": -3,
      "z": -17,
      "name": "Rock_Stone"
    },
    {
      "x": -26,
      "y": -2,
      "z": -17,
      "name": "Rock_Stone"
    },
    {
      "x": -26,
      "y": -1,
      "z": -17,
      "name": "Rock_Stone"
    },
    {
      "x": -26,
      "y": 0,
      "z": -17,
      "name": "Rock_Stone"
    },
    {
      "x": -26,
      "y": 1,
      "z": -17,
      "name": "Rock_Stone"
    },
    {
      "x": -26,
      "y": 2,
      "z": -17,
      "name": "Rock_Stone"
    },
    {
      "x": -26,
      "y": 3,
      "z": -17,
      "name": "Rock_Stone"
    },
    {
      "x": -26,
      "y": 4,
      "z": -17,
      "name": "Rock_Stone"
    },
    {
      "x": -26,
      "y": 5,
      "z": -17,
      "name": "Rock_Stone"
    },
    {
      "x": -26,
      "y": 6,
      "z": -17,
      "name": "Rock_Stone"
    },
    {
      "x": -26,
      "y": 7,
      "z": -17,
      "name": "Rock_Stone"
    },
    {
      "x": -26,
      "y": -12,
      "z": -16,
      "name": "Rock_Stone"
    },
    {
      "x": -26,
      "y": -11,
      "z": -16,
      "name": "Rock_Stone"
    },
    {
      "x": -26,
      "y": -10,
      "z": -16,
      "name": "Rock_Stone"
    },
    {
      "x": -26,
      "y": -9,
      "z": -16,
      "name": "Rock_Stone"
    },
    {
      "x": -26,
      "y": -8,
      "z": -16,
      "name": "Rock_Stone"
    },
    {
      "x": -26,
      "y": -7,
      "z": -16,
      "name": "Rock_Stone"
    },
    {
      "x": -26,
      "y": -6,
      "z": -16,
      "name": "Rock_Stone"
    },
    {
      "x": -26,
      "y": -5,
      "z": -16,
      "name": "Rock_Stone"
    },
    {
      "x": -26,
      "y": -4,
      "z": -16,
      "name": "Rock_Stone"
    },
    {
      "x": -26,
      "y": -3,
      "z": -16,
      "name": "Rock_Stone"
    },
    {
      "x": -26,
      "y": -2,
      "z": -16,
      "name": "Rock_Stone"
    },
    {
      "x": -26,
      "y": -1,
      "z": -16,
      "name": "Rock_Stone"
    },
    {
      "x": -26,
      "y": 0,
      "z": -16,
      "name": "Rock_Stone"
    },
    {
      "x": -26,
      "y": 1,
      "z": -16,
      "name": "Rock_Stone"
    },
    {
      "x": -26,
      "y": 2,
      "z": -16,
      "name": "Rock_Stone"
    },
    {
      "x": -26,
      "y": 3,
      "z": -16,
      "name": "Rock_Stone"
    },
    {
      "x": -26,
      "y": 4,
      "z": -16,
      "name": "Rock_Stone"
    },
    {
      "x": -26,
      "y": 5,
      "z": -16,
      "name": "Rock_Stone"
    },
    {
      "x": -26,
      "y": 6,
      "z": -16,
      "name": "Rock_Stone"
    },
    {
      "x": -26,
      "y": 7,
      "z": -16,
      "name": "Rock_Stone"
    },
    {
      "x": -26,
      "y": -12,
      "z": -15,
      "name": "Rock_Stone"
    },
    {
      "x": -26,
      "y": -11,
      "z": -15,
      "name": "Rock_Stone"
    },
    {
      "x": -26,
      "y": -10,
      "z": -15,
      "name": "Rock_Stone"
    },
    {
      "x": -26,
      "y": -9,
      "z": -15,
      "name": "Rock_Stone"
    },
    {
      "x": -26,
      "y": -8,
      "z": -15,
      "name": "Rock_Stone"
    },
    {
      "x": -26,
      "y": -7,
      "z": -15,
      "name": "Rock_Stone"
    },
    {
      "x": -26,
      "y": -6,
      "z": -15,
      "name": "Rock_Stone"
    },
    {
      "x": -26,
      "y": -5,
      "z": -15,
      "name": "Rock_Stone"
    },
    {
      "x": -26,
      "y": -4,
      "z": -15,
      "name": "Rock_Stone"
    },
    {
      "x": -26,
      "y": -3,
      "z": -15,
      "name": "Rock_Stone"
    },
    {
      "x": -26,
      "y": -2,
      "z": -15,
      "name": "Rock_Stone"
    },
    {
      "x": -26,
      "y": -1,
      "z": -15,
      "name": "Rock_Stone"
    },
    {
      "x": -26,
      "y": 0,
      "z": -15,
      "name": "Rock_Stone"
    },
    {
      "x": -26,
      "y": 1,
      "z": -15,
      "name": "Rock_Stone"
    },
    {
      "x": -26,
      "y": 2,
      "z": -15,
      "name": "Rock_Stone"
    },
    {
      "x": -26,
      "y": 3,
      "z": -15,
      "name": "Rock_Stone"
    },
    {
      "x": -26,
      "y": 4,
      "z": -15,
      "name": "Rock_Stone"
    },
    {
      "x": -26,
      "y": 5,
      "z": -15,
      "name": "Rock_Stone"
    },
    {
      "x": -26,
      "y": 6,
      "z": -15,
      "name": "Rock_Stone"
    },
    {
      "x": -26,
      "y": 7,
      "z": -15,
      "name": "Rock_Stone"
    },
    {
      "x": -26,
      "y": -12,
      "z": -14,
      "name": "Rock_Stone"
    },
    {
      "x": -26,
      "y": -11,
      "z": -14,
      "name": "Rock_Stone"
    },
    {
      "x": -26,
      "y": -10,
      "z": -14,
      "name": "Rock_Stone"
    },
    {
      "x": -26,
      "y": -9,
      "z": -14,
      "name": "Rock_Stone"
    },
    {
      "x": -26,
      "y": -8,
      "z": -14,
      "name": "Rock_Stone"
    },
    {
      "x": -26,
      "y": -7,
      "z": -14,
      "name": "Rock_Stone"
    },
    {
      "x": -26,
      "y": -6,
      "z": -14,
      "name": "Rock_Stone"
    },
    {
      "x": -26,
      "y": -5,
      "z": -14,
      "name": "Rock_Stone"
    },
    {
      "x": -26,
      "y": -4,
      "z": -14,
      "name": "Rock_Stone"
    },
    {
      "x": -26,
      "y": -3,
      "z": -14,
      "name": "Rock_Stone"
    },
    {
      "x": -26,
      "y": -2,
      "z": -14,
      "name": "Rock_Stone"
    },
    {
      "x": -26,
      "y": -1,
      "z": -14,
      "name": "Rock_Stone"
    },
    {
      "x": -26,
      "y": 0,
      "z": -14,
      "name": "Rock_Stone"
    },
    {
      "x": -26,
      "y": 1,
      "z": -14,
      "name": "Rock_Stone"
    },
    {
      "x": -26,
      "y": 2,
      "z": -14,
      "name": "Rock_Stone"
    },
    {
      "x": -26,
      "y": 3,
      "z": -14,
      "name": "Rock_Stone"
    },
    {
      "x": -26,
      "y": 4,
      "z": -14,
      "name": "Rock_Stone"
    },
    {
      "x": -26,
      "y": 5,
      "z": -14,
      "name": "Rock_Stone"
    },
    {
      "x": -26,
      "y": 6,
      "z": -14,
      "name": "Rock_Stone"
    },
    {
      "x": -26,
      "y": 7,
      "z": -14,
      "name": "Rock_Stone"
    },
    {
      "x": -26,
      "y": 176,
      "z": -14,
      "name": "Rock_Stone"
    },
    {
      "x": -26,
      "y": -11,
      "z": -13,
      "name": "Rock_Stone"
    },
    {
      "x": -26,
      "y": -10,
      "z": -13,
      "name": "Rock_Stone"
    },
    {
      "x": -26,
      "y": -9,
      "z": -13,
      "name": "Rock_Stone"
    },
    {
      "x": -26,
      "y": -8,
      "z": -13,
      "name": "Rock_Stone"
    },
    {
      "x": -26,
      "y": -7,
      "z": -13,
      "name": "Rock_Stone"
    },
    {
      "x": -26,
      "y": -6,
      "z": -13,
      "name": "Rock_Stone"
    },
    {
      "x": -26,
      "y": -5,
      "z": -13,
      "name": "Rock_Stone"
    },
    {
      "x": -26,
      "y": -4,
      "z": -13,
      "name": "Rock_Stone"
    },
    {
      "x": -26,
      "y": -3,
      "z": -13,
      "name": "Rock_Stone"
    },
    {
      "x": -26,
      "y": -2,
      "z": -13,
      "name": "Rock_Stone"
    },
    {
      "x": -26,
      "y": -1,
      "z": -13,
      "name": "Rock_Stone"
    },
    {
      "x": -26,
      "y": 0,
      "z": -13,
      "name": "Rock_Stone"
    },
    {
      "x": -26,
      "y": 1,
      "z": -13,
      "name": "Rock_Stone"
    },
    {
      "x": -26,
      "y": 2,
      "z": -13,
      "name": "Rock_Stone"
    },
    {
      "x": -26,
      "y": 3,
      "z": -13,
      "name": "Rock_Stone"
    },
    {
      "x": -26,
      "y": 4,
      "z": -13,
      "name": "Rock_Stone"
    },
    {
      "x": -26,
      "y": 5,
      "z": -13,
      "name": "Rock_Stone"
    },
    {
      "x": -26,
      "y": 6,
      "z": -13,
      "name": "Rock_Stone"
    },
    {
      "x": -26,
      "y": 7,
      "z": -13,
      "name": "Rock_Stone"
    },
    {
      "x": -26,
      "y": 175,
      "z": -13,
      "name": "Rock_Stone"
    },
    {
      "x": -26,
      "y": 176,
      "z": -13,
      "name": "Rock_Stone"
    },
    {
      "x": -26,
      "y": -4,
      "z": -12,
      "name": "Rock_Stone"
    },
    {
      "x": -26,
      "y": -3,
      "z": -12,
      "name": "Rock_Stone"
    },
    {
      "x": -26,
      "y": -2,
      "z": -12,
      "name": "Rock_Stone"
    },
    {
      "x": -26,
      "y": -1,
      "z": -12,
      "name": "Rock_Stone"
    },
    {
      "x": -26,
      "y": 0,
      "z": -12,
      "name": "Rock_Stone"
    },
    {
      "x": -26,
      "y": 1,
      "z": -12,
      "name": "Rock_Stone"
    },
    {
      "x": -26,
      "y": 2,
      "z": -12,
      "name": "Rock_Stone"
    },
    {
      "x": -26,
      "y": 3,
      "z": -12,
      "name": "Rock_Stone"
    },
    {
      "x": -26,
      "y": 4,
      "z": -12,
      "name": "Rock_Stone"
    },
    {
      "x": -26,
      "y": 5,
      "z": -12,
      "name": "Rock_Stone"
    },
    {
      "x": -26,
      "y": 6,
      "z": -12,
      "name": "Rock_Stone"
    },
    {
      "x": -26,
      "y": 174,
      "z": -12,
      "name": "Rock_Stone"
    },
    {
      "x": -26,
      "y": 176,
      "z": -12,
      "name": "Rock_Stone"
    },
    {
      "x": -26,
      "y": -2,
      "z": -11,
      "name": "Rock_Stone"
    },
    {
      "x": -26,
      "y": -1,
      "z": -11,
      "name": "Rock_Stone"
    },
    {
      "x": -26,
      "y": 0,
      "z": -11,
      "name": "Rock_Stone"
    },
    {
      "x": -26,
      "y": 1,
      "z": -11,
      "name": "Rock_Stone"
    },
    {
      "x": -26,
      "y": 2,
      "z": -11,
      "name": "Rock_Stone"
    },
    {
      "x": -26,
      "y": 3,
      "z": -11,
      "name": "Rock_Stone"
    },
    {
      "x": -26,
      "y": 4,
      "z": -11,
      "name": "Rock_Stone"
    },
    {
      "x": -26,
      "y": 5,
      "z": -11,
      "name": "Rock_Stone"
    },
    {
      "x": -26,
      "y": 0,
      "z": -10,
      "name": "Rock_Stone"
    },
    {
      "x": -26,
      "y": 1,
      "z": -10,
      "name": "Rock_Stone"
    },
    {
      "x": -26,
      "y": 2,
      "z": -10,
      "name": "Rock_Stone"
    },
    {
      "x": -26,
      "y": 3,
      "z": -10,
      "name": "Rock_Stone"
    },
    {
      "x": -26,
      "y": 170,
      "z": -3,
      "name": "Rock_Stone"
    },
    {
      "x": -26,
      "y": 171,
      "z": -3,
      "name": "Rock_Stone"
    },
    {
      "x": -26,
      "y": 172,
      "z": -3,
      "name": "Rock_Stone"
    },
    {
      "x": -26,
      "y": 171,
      "z": -2,
      "name": "Rock_Stone"
    },
    {
      "x": -26,
      "y": 172,
      "z": 9,
      "name": "Rock_Stone"
    },
    {
      "x": -26,
      "y": 173,
      "z": 9,
      "name": "Rock_Stone"
    },
    {
      "x": -25,
      "y": -2,
      "z": -22,
      "name": "Rock_Stone"
    },
    {
      "x": -25,
      "y": -1,
      "z": -22,
      "name": "Rock_Stone"
    },
    {
      "x": -25,
      "y": 0,
      "z": -22,
      "name": "Rock_Stone"
    },
    {
      "x": -25,
      "y": 1,
      "z": -22,
      "name": "Rock_Stone"
    },
    {
      "x": -25,
      "y": 2,
      "z": -22,
      "name": "Rock_Stone"
    },
    {
      "x": -25,
      "y": 3,
      "z": -22,
      "name": "Rock_Stone"
    },
    {
      "x": -25,
      "y": -4,
      "z": -21,
      "name": "Rock_Stone"
    },
    {
      "x": -25,
      "y": -3,
      "z": -21,
      "name": "Rock_Stone"
    },
    {
      "x": -25,
      "y": -2,
      "z": -21,
      "name": "Rock_Stone"
    },
    {
      "x": -25,
      "y": -1,
      "z": -21,
      "name": "Rock_Stone"
    },
    {
      "x": -25,
      "y": 0,
      "z": -21,
      "name": "Rock_Stone"
    },
    {
      "x": -25,
      "y": 1,
      "z": -21,
      "name": "Rock_Stone"
    },
    {
      "x": -25,
      "y": 2,
      "z": -21,
      "name": "Rock_Stone"
    },
    {
      "x": -25,
      "y": 3,
      "z": -21,
      "name": "Rock_Stone"
    },
    {
      "x": -25,
      "y": 4,
      "z": -21,
      "name": "Rock_Stone"
    },
    {
      "x": -25,
      "y": -5,
      "z": -20,
      "name": "Rock_Stone"
    },
    {
      "x": -25,
      "y": -4,
      "z": -20,
      "name": "Rock_Stone"
    },
    {
      "x": -25,
      "y": -3,
      "z": -20,
      "name": "Rock_Stone"
    },
    {
      "x": -25,
      "y": -2,
      "z": -20,
      "name": "Rock_Stone"
    },
    {
      "x": -25,
      "y": -1,
      "z": -20,
      "name": "Rock_Stone"
    },
    {
      "x": -25,
      "y": 0,
      "z": -20,
      "name": "Rock_Stone"
    },
    {
      "x": -25,
      "y": 1,
      "z": -20,
      "name": "Rock_Stone"
    },
    {
      "x": -25,
      "y": 2,
      "z": -20,
      "name": "Rock_Stone"
    },
    {
      "x": -25,
      "y": 3,
      "z": -20,
      "name": "Rock_Stone"
    },
    {
      "x": -25,
      "y": 4,
      "z": -20,
      "name": "Rock_Stone"
    },
    {
      "x": -25,
      "y": 5,
      "z": -20,
      "name": "Rock_Stone"
    },
    {
      "x": -25,
      "y": -8,
      "z": -19,
      "name": "Rock_Stone"
    },
    {
      "x": -25,
      "y": -7,
      "z": -19,
      "name": "Rock_Stone"
    },
    {
      "x": -25,
      "y": -6,
      "z": -19,
      "name": "Rock_Stone"
    },
    {
      "x": -25,
      "y": -5,
      "z": -19,
      "name": "Rock_Stone"
    },
    {
      "x": -25,
      "y": -4,
      "z": -19,
      "name": "Rock_Stone"
    },
    {
      "x": -25,
      "y": -3,
      "z": -19,
      "name": "Rock_Stone"
    },
    {
      "x": -25,
      "y": -2,
      "z": -19,
      "name": "Rock_Stone"
    },
    {
      "x": -25,
      "y": -1,
      "z": -19,
      "name": "Rock_Stone"
    },
    {
      "x": -25,
      "y": 0,
      "z": -19,
      "name": "Rock_Stone"
    },
    {
      "x": -25,
      "y": 1,
      "z": -19,
      "name": "Rock_Stone"
    },
    {
      "x": -25,
      "y": 2,
      "z": -19,
      "name": "Rock_Stone"
    },
    {
      "x": -25,
      "y": 3,
      "z": -19,
      "name": "Rock_Stone"
    },
    {
      "x": -25,
      "y": 4,
      "z": -19,
      "name": "Rock_Stone"
    },
    {
      "x": -25,
      "y": 5,
      "z": -19,
      "name": "Rock_Stone"
    },
    {
      "x": -25,
      "y": 6,
      "z": -19,
      "name": "Rock_Stone"
    },
    {
      "x": -25,
      "y": -10,
      "z": -18,
      "name": "Rock_Stone"
    },
    {
      "x": -25,
      "y": -9,
      "z": -18,
      "name": "Rock_Stone"
    },
    {
      "x": -25,
      "y": -8,
      "z": -18,
      "name": "Rock_Stone"
    },
    {
      "x": -25,
      "y": -7,
      "z": -18,
      "name": "Rock_Stone"
    },
    {
      "x": -25,
      "y": -6,
      "z": -18,
      "name": "Rock_Stone"
    },
    {
      "x": -25,
      "y": -5,
      "z": -18,
      "name": "Rock_Stone"
    },
    {
      "x": -25,
      "y": -4,
      "z": -18,
      "name": "Rock_Stone"
    },
    {
      "x": -25,
      "y": -3,
      "z": -18,
      "name": "Rock_Stone"
    },
    {
      "x": -25,
      "y": -2,
      "z": -18,
      "name": "Rock_Stone"
    },
    {
      "x": -25,
      "y": -1,
      "z": -18,
      "name": "Rock_Stone"
    },
    {
      "x": -25,
      "y": 0,
      "z": -18,
      "name": "Rock_Stone"
    },
    {
      "x": -25,
      "y": 1,
      "z": -18,
      "name": "Rock_Stone"
    },
    {
      "x": -25,
      "y": 2,
      "z": -18,
      "name": "Rock_Stone"
    },
    {
      "x": -25,
      "y": 3,
      "z": -18,
      "name": "Rock_Stone"
    },
    {
      "x": -25,
      "y": 4,
      "z": -18,
      "name": "Rock_Stone"
    },
    {
      "x": -25,
      "y": 5,
      "z": -18,
      "name": "Rock_Stone"
    },
    {
      "x": -25,
      "y": 6,
      "z": -18,
      "name": "Rock_Stone"
    },
    {
      "x": -25,
      "y": 7,
      "z": -18,
      "name": "Rock_Stone"
    },
    {
      "x": -25,
      "y": -11,
      "z": -17,
      "name": "Rock_Stone"
    },
    {
      "x": -25,
      "y": -10,
      "z": -17,
      "name": "Rock_Stone"
    },
    {
      "x": -25,
      "y": -9,
      "z": -17,
      "name": "Rock_Stone"
    },
    {
      "x": -25,
      "y": -8,
      "z": -17,
      "name": "Rock_Stone"
    },
    {
      "x": -25,
      "y": -7,
      "z": -17,
      "name": "Rock_Stone"
    },
    {
      "x": -25,
      "y": -6,
      "z": -17,
      "name": "Rock_Stone"
    },
    {
      "x": -25,
      "y": -5,
      "z": -17,
      "name": "Rock_Stone"
    },
