{
  "version": 8,
  "blockIdVersion": 11,
  "anchorX": 0,
  "anchorY": 0,
  "anchorZ": 0,
  "blocks": [
    {
      "x": -47,
      "y": 174,
      "z": -2,
      "name": "Rock_Stone_Mossy"
    },
    {
      "x": -47,
      "y": 174,
      "z": 0,
      "name": "Rock_Stone_Mossy"
    },
    {
      "x": -46,
      "y": 173,
      "z": -7,
      "name": "Rock_Stone_Mossy"
    },
    {
      "x": -46,
      "y": 175,
      "z": -7,
      "name": "Rock_Stone_Mossy"
    },
    {
      "x": -46,
      "y": 173,
      "z": -5,
      "name": "Rock_Stone_Mossy"
    },
    {
      "x": -46,
      "y": 174,
      "z": -5,
      "name": "Rock_Stone_Mossy"
    },
    {
      "x": -46,
      "y": 175,
      "z": -4,
      "name": "Rock_Stone_Mossy"
    },
    {
      "x": -46,
      "y": 173,
      "z": -2,
      "name": "Rock_Stone_Mossy"
    },
    {
      "x": -46,
      "y": 174,
      "z": -1,
      "name": "Rock_Stone_Mossy"
    },
    {
      "x": -46,
      "y": 175,
      "z": -1,
      "name": "Rock_Stone_Mossy"
    },
    {
      "x": -46,
      "y": 174,
      "z": 0,
      "name": "Rock_Stone_Mossy"
    },
    {
      "x": -46,
      "y": 173,
      "z": 1,
      "name": "Rock_Stone_Mossy"
    },
    {
      "x": -46,
      "y": 175,
      "z": 1,
      "name": "Rock_Stone_Mossy"
    },
    {
      "x": -46,
      "y": 173,
      "z": 2,
      "name": "Rock_Stone_Mossy"
    },
    {
      "x": -46,
      "y": 174,
      "z": 3,
      "name": "Rock_Stone_Mossy"
    },
    {
      "x": -45,
      "y": 179,
      "z": -17,
      "name": "Rock_Stone_Mossy"
    },
    {
      "x": -45,
      "y": 179,
      "z": -14,
      "name": "Rock_Stone_Mossy"
    },
    {
      "x": -45,
      "y": 175,
      "z": -10,
      "name": "Rock_Stone_Mossy"
    },
    {
      "x": -45,
      "y": 173,
      "z": -8,
      "name": "Rock_Stone_Mossy"
    },
    {
      "x": -45,
      "y": 172,
      "z": -6,
      "name": "Rock_Stone_Mossy"
    },
    {
      "x": -45,
      "y": 175,
      "z": -5,
      "name": "Rock_Stone_Mossy"
    },
    {
      "x": -45,
      "y": 174,
      "z": -4,
      "name": "Rock_Stone_Mossy"
    },
    {
      "x": -45,
      "y": 172,
      "z": -3,
      "name": "Rock_Stone_Mossy"
    },
    {
      "x": -45,
      "y": 174,
      "z": -3,
      "name": "Rock_Stone_Mossy"
    },
    {
      "x": -45,
      "y": 175,
      "z": -1,
      "name": "Rock_Stone_Mossy"
    },
    {
      "x": -45,
      "y": 173,
      "z": 0,
      "name": "Rock_Stone_Mossy"
    },
    {
      "x": -45,
      "y": 176,
      "z": 0,
      "name": "Rock_Stone_Mossy"
    },
    {
      "x": -45,
      "y": 175,
      "z": 2,
      "name": "Rock_Stone_Mossy"
    },
    {
      "x": -45,
      "y": 174,
      "z": 3,
      "name": "Rock_Stone_Mossy"
    },
    {
      "x": -45,
      "y": 173,
      "z": 4,
      "name": "Rock_Stone_Mossy"
    },
    {
      "x": -44,
      "y": 179,
      "z": -21,
      "name": "Rock_Stone_Mossy"
    },
    {
      "x": -44,
      "y": 179,
      "z": -14,
      "name": "Rock_Stone_Mossy"
    },
    {
      "x": -44,
      "y": 173,
      "z": -12,
      "name": "Rock_Stone_Mossy"
    },
    {
      "x": -44,
      "y": 179,
      "z": -11,
      "name": "Rock_Stone_Mossy"
    },
    {
      "x": -44,
      "y": 172,
      "z": -9,
      "name": "Rock_Stone_Mossy"
    },
    {
      "x": -44,
      "y": 175,
      "z": -9,
      "name": "Rock_Stone_Mossy"
    },
    {
      "x": -44,
      "y": 173,
      "z": -8,
      "name": "Rock_Stone_Mossy"
    },
    {
      "x": -44,
      "y": 173,
      "z": -6,
      "name": "Rock_Stone_Mossy"
    },
    {
      "x": -44,
      "y": 173,
      "z": -3,
      "name": "Rock_Stone_Mossy"
    },
    {
      "x": -44,
      "y": 174,
      "z": -3,
      "name": "Rock_Stone_Mossy"
    },
    {
      "x": -44,
      "y": 172,
      "z": -2,
      "name": "Rock_Stone_Mossy"
    },
    {
      "x": -44,
      "y": 173,
      "z": -2,
      "name": "Rock_Stone_Mossy"
    },
    {
      "x": -44,
      "y": 174,
      "z": -2,
      "name": "Rock_Stone_Mossy"
    },
    {
      "x": -44,
      "y": 175,
      "z": -2,
      "name": "Rock_Stone_Mossy"
    },
    {
      "x": -44,
      "y": 173,
      "z": 0,
      "name": "Rock_Stone_Mossy"
    },
    {
      "x": -44,
      "y": 175,
      "z": 0,
      "name": "Rock_Stone_Mossy"
    },
    {
      "x": -44,
      "y": 175,
      "z": 2,
      "name": "Rock_Stone_Mossy"
    },
    {
      "x": -44,
      "y": 172,
      "z": 3,
      "name": "Rock_Stone_Mossy"
    },
    {
      "x": -44,
      "y": 173,
      "z": 3,
      "name": "Rock_Stone_Mossy"
    },
    {
      "x": -44,
      "y": 175,
      "z": 3,
      "name": "Rock_Stone_Mossy"
    },
    {
      "x": -44,
      "y": 174,
      "z": 4,
      "name": "Rock_Stone_Mossy"
    },
    {
      "x": -44,
      "y": 175,
      "z": 4,
      "name": "Rock_Stone_Mossy"
    },
    {
      "x": -44,
      "y": 174,
      "z": 5,
      "name": "Rock_Stone_Mossy"
    },
    {
      "x": -44,
      "y": 173,
      "z": 6,
      "name": "Rock_Stone_Mossy"
    },
    {
      "x": -43,
      "y": 179,
      "z": -25,
      "name": "Rock_Stone_Mossy"
    },
    {
      "x": -43,
      "y": 178,
      "z": -24,
      "name": "Rock_Stone_Mossy"
    },
    {
      "x": -43,
      "y": 178,
      "z": -23,
      "name": "Rock_Stone_Mossy"
    },
    {
      "x": -43,
      "y": 178,
      "z": -22,
      "name": "Rock_Stone_Mossy"
    },
    {
      "x": -43,
      "y": 177,
      "z": -19,
      "name": "Rock_Stone_Mossy"
    },
    {
      "x": -43,
      "y": 179,
      "z": -17,
      "name": "Rock_Stone_Mossy"
    },
    {
      "x": -43,
      "y": 179,
      "z": -16,
      "name": "Rock_Stone_Mossy"
    },
    {
      "x": -43,
      "y": 181,
      "z": -16,
      "name": "Rock_Stone_Mossy"
    },
    {
      "x": -43,
      "y": 178,
      "z": -15,
      "name": "Rock_Stone_Mossy"
    },
    {
      "x": -43,
      "y": 179,
      "z": -15,
      "name": "Rock_Stone_Mossy"
    },
    {
      "x": -43,
      "y": 180,
      "z": -14,
      "name": "Rock_Stone_Mossy"
    },
    {
      "x": -43,
      "y": 181,
      "z": -14,
      "name": "Rock_Stone_Mossy"
    },
    {
      "x": -43,
      "y": 173,
      "z": -13,
      "name": "Rock_Stone_Mossy"
    },
    {
      "x": -43,
      "y": 174,
      "z": -13,
      "name": "Rock_Stone_Mossy"
    },
    {
      "x": -43,
      "y": 174,
      "z": -12,
      "name": "Rock_Stone_Mossy"
    },
    {
      "x": -43,
      "y": 174,
      "z": -11,
      "name": "Rock_Stone_Mossy"
    },
    {
      "x": -43,
      "y": 180,
      "z": -11,
      "name": "Rock_Stone_Mossy"
    },
    {
      "x": -43,
      "y": 173,
      "z": -10,
      "name": "Rock_Stone_Mossy"
    },
    {
      "x": -43,
      "y": 172,
      "z": -9,
      "name": "Rock_Stone_Mossy"
    },
    {
      "x": -43,
      "y": 173,
      "z": -8,
      "name": "Rock_Stone_Mossy"
    },
    {
      "x": -43,
      "y": 174,
      "z": -8,
      "name": "Rock_Stone_Mossy"
    },
    {
      "x": -43,
      "y": 175,
      "z": -7,
      "name": "Rock_Stone_Mossy"
    },
    {
      "x": -43,
      "y": 173,
      "z": -6,
      "name": "Rock_Stone_Mossy"
    },
    {
      "x": -43,
      "y": 177,
      "z": -5,
      "name": "Rock_Stone_Mossy"
    },
    {
      "x": -43,
      "y": 171,
      "z": -4,
      "name": "Rock_Stone_Mossy"
    },
    {
      "x": -43,
      "y": 174,
      "z": -4,
      "name": "Rock_Stone_Mossy"
    },
    {
      "x": -43,
      "y": 172,
      "z": -3,
      "name": "Rock_Stone_Mossy"
    },
    {
      "x": -43,
      "y": 175,
      "z": -3,
      "name": "Rock_Stone_Mossy"
    },
    {
      "x": -43,
      "y": 177,
      "z": -3,
      "name": "Rock_Stone_Mossy"
    },
    {
      "x": -43,
      "y": 171,
      "z": -2,
      "name": "Rock_Stone_Mossy"
    },
    {
      "x": -43,
      "y": 172,
      "z": -2,
      "name": "Rock_Stone_Mossy"
    },
    {
      "x": -43,
      "y": 173,
      "z": -1,
      "name": "Rock_Stone_Mossy"
    },
    {
      "x": -43,
      "y": 176,
      "z": -1,
      "name": "Rock_Stone_Mossy"
    },
    {
      "x": -43,
      "y": 173,
      "z": 0,
      "name": "Rock_Stone_Mossy"
    },
    {
      "x": -43,
      "y": 173,
      "z": 1,
      "name": "Rock_Stone_Mossy"
    },
    {
      "x": -43,
      "y": 175,
      "z": 1,
      "name": "Rock_Stone_Mossy"
    },
    {
      "x": -43,
      "y": 173,
      "z": 2,
      "name": "Rock_Stone_Mossy"
    },
    {
      "x": -43,
      "y": 176,
      "z": 2,
      "name": "Rock_Stone_Mossy"
    },
    {
      "x": -43,
      "y": 173,
      "z": 5,
      "name": "Rock_Stone_Mossy"
    },
    {
      "x": -43,
      "y": 173,
      "z": 7,
      "name": "Rock_Stone_Mossy"
    },
    {
      "x": -42,
      "y": 178,
      "z": -24,
      "name": "Rock_Stone_Mossy"
    },
    {
      "x": -42,
      "y": 181,
      "z": -22,
      "name": "Rock_Stone_Mossy"
    },
    {
      "x": -42,
      "y": 180,
      "z": -19,
      "name": "Rock_Stone_Mossy"
    },
    {
      "x": -42,
      "y": 178,
      "z": -17,
      "name": "Rock_Stone_Mossy"
    },
    {
      "x": -42,
      "y": 179,
      "z": -16,
      "name": "Rock_Stone_Mossy"
    },
    {
      "x": -42,
      "y": 173,
      "z": -14,
      "name": "Rock_Stone_Mossy"
    },
    {
      "x": -42,
      "y": 175,
      "z": -14,
      "name": "Rock_Stone_Mossy"
    },
    {
      "x": -42,
      "y": 177,
      "z": -13,
      "name": "Rock_Stone_Mossy"
    },
    {
      "x": -42,
      "y": 179,
      "z": -13,
      "name": "Rock_Stone_Mossy"
    },
    {
      "x": -42,
      "y": 176,
      "z": -12,
      "name": "Rock_Stone_Mossy"
    },
    {
      "x": -42,
      "y": 177,
      "z": -12,
      "name": "Rock_Stone_Mossy"
    },
    {
      "x": -42,
      "y": 179,
      "z": -12,
      "name": "Rock_Stone_Mossy"
    },
    {
      "x": -42,
      "y": 181,
      "z": -12,
      "name": "Rock_Stone_Mossy"
    },
    {
      "x": -42,
      "y": 172,
      "z": -11,
      "name": "Rock_Stone_Mossy"
    },
    {
      "x": -42,
      "y": 173,
      "z": -11,
      "name": "Rock_Stone_Mossy"
    },
    {
      "x": -42,
      "y": 178,
      "z": -11,
      "name": "Rock_Stone_Mossy"
    },
    {
      "x": -42,
      "y": 172,
      "z": -10,
      "name": "Rock_Stone_Mossy"
    },
    {
      "x": -42,
      "y": 178,
      "z": -9,
      "name": "Rock_Stone_Mossy"
    },
    {
      "x": -42,
      "y": 176,
      "z": -8,
      "name": "Rock_Stone_Mossy"
    },
    {
      "x": -42,
      "y": 179,
      "z": -8,
      "name": "Rock_Stone_Mossy"
    },
    {
      "x": -42,
      "y": 171,
      "z": -7,
      "name": "Rock_Stone_Mossy"
    },
    {
      "x": -42,
      "y": 172,
      "z": -7,
      "name": "Rock_Stone_Mossy"
    },
    {
      "x": -42,
      "y": 175,
      "z": -7,
      "name": "Rock_Stone_Mossy"
    },
    {
      "x": -42,
      "y": 171,
      "z": -5,
      "name": "Rock_Stone_Mossy"
    },
    {
      "x": -42,
      "y": 171,
      "z": -4,
      "name": "Rock_Stone_Mossy"
    },
    {
      "x": -42,
      "y": 174,
      "z": -4,
      "name": "Rock_Stone_Mossy"
    },
    {
      "x": -42,
      "y": 175,
      "z": -4,
      "name": "Rock_Stone_Mossy"
    },
    {
      "x": -42,
      "y": 177,
      "z": -4,
      "name": "Rock_Stone_Mossy"
    },
    {
      "x": -42,
      "y": 176,
      "z": -3,
      "name": "Rock_Stone_Mossy"
    },
    {
      "x": -42,
      "y": 177,
      "z": -3,
      "name": "Rock_Stone_Mossy"
    },
    {
      "x": -42,
      "y": 175,
      "z": -2,
      "name": "Rock_Stone_Mossy"
    },
    {
      "x": -42,
      "y": 176,
      "z": -1,
      "name": "Rock_Stone_Mossy"
    },
    {
      "x": -42,
      "y": 173,
      "z": 0,
      "name": "Rock_Stone_Mossy"
    },
    {
      "x": -42,
      "y": 176,
      "z": 0,
      "name": "Rock_Stone_Mossy"
    },
    {
      "x": -42,
      "y": 175,
      "z": 4,
      "name": "Rock_Stone_Mossy"
    },
    {
      "x": -42,
      "y": 173,
      "z": 5,
      "name": "Rock_Stone_Mossy"
    },
    {
      "x": -42,
      "y": 172,
      "z": 6,
      "name": "Rock_Stone_Mossy"
    },
    {
      "x": -42,
      "y": 175,
      "z": 7,
      "name": "Rock_Stone_Mossy"
    },
    {
      "x": -42,
      "y": 173,
      "z": 8,
      "name": "Rock_Stone_Mossy"
    },
    {
      "x": -42,
      "y": 175,
      "z": 8,
      "name": "Rock_Stone_Mossy"
    },
    {
      "x": -42,
      "y": 174,
      "z": 10,
      "name": "Rock_Stone_Mossy"
    },
    {
      "x": -41,
      "y": 180,
      "z": -26,
      "name": "Rock_Stone_Mossy"
    },
    {
      "x": -41,
      "y": 177,
      "z": -25,
      "name": "Rock_Stone_Mossy"
    },
    {
      "x": -41,
      "y": 178,
      "z": -25,
      "name": "Rock_Stone_Mossy"
    },
    {
      "x": -41,
      "y": 178,
      "z": -22,
      "name": "Rock_Stone_Mossy"
    },
    {
      "x": -41,
      "y": 179,
      "z": -22,
      "name": "Rock_Stone_Mossy"
    },
    {
      "x": -41,
      "y": 177,
      "z": -21,
      "name": "Rock_Stone_Mossy"
    },
    {
      "x": -41,
      "y": 178,
      "z": -21,
      "name": "Rock_Stone_Mossy"
    },
    {
      "x": -41,
      "y": 181,
      "z": -21,
      "name": "Rock_Stone_Mossy"
    },
    {
      "x": -41,
      "y": 181,
      "z": -19,
      "name": "Rock_Stone_Mossy"
    },
    {
      "x": -41,
      "y": 177,
      "z": -18,
      "name": "Rock_Stone_Mossy"
    },
    {
      "x": -41,
      "y": 178,
      "z": -18,
      "name": "Rock_Stone_Mossy"
    },
    {
      "x": -41,
      "y": 176,
      "z": -17,
      "name": "Rock_Stone_Mossy"
    },
    {
      "x": -41,
      "y": 181,
      "z": -16,
      "name": "Rock_Stone_Mossy"
    },
    {
      "x": -41,
      "y": 173,
      "z": -15,
      "name": "Rock_Stone_Mossy"
    },
    {
      "x": -41,
      "y": 173,
      "z": -13,
      "name": "Rock_Stone_Mossy"
    },
    {
      "x": -41,
      "y": 175,
      "z": -12,
      "name": "Rock_Stone_Mossy"
    },
    {
      "x": -41,
      "y": 173,
      "z": -11,
      "name": "Rock_Stone_Mossy"
    },
    {
      "x": -41,
      "y": 176,
      "z": -11,
      "name": "Rock_Stone_Mossy"
    },
    {
      "x": -41,
      "y": 177,
      "z": -11,
      "name": "Rock_Stone_Mossy"
    },
    {
      "x": -41,
      "y": 180,
      "z": -11,
      "name": "Rock_Stone_Mossy"
    },
    {
      "x": -41,
      "y": 173,
      "z": -10,
      "name": "Rock_Stone_Mossy"
    },
    {
      "x": -41,
      "y": 175,
      "z": -10,
      "name": "Rock_Stone_Mossy"
    },
    {
      "x": -41,
      "y": 181,
      "z": -10,
      "name": "Rock_Stone_Mossy"
    },
    {
      "x": -41,
      "y": 171,
      "z": -9,
      "name": "Rock_Stone_Mossy"
    },
    {
      "x": -41,
      "y": 173,
      "z": -9,
      "name": "Rock_Stone_Mossy"
    },
    {
      "x": -41,
      "y": 175,
      "z": -9,
      "name": "Rock_Stone_Mossy"
    },
    {
      "x": -41,
      "y": 176,
      "z": -9,
      "name": "Rock_Stone_Mossy"
    },
    {
      "x": -41,
      "y": 171,
      "z": -8,
      "name": "Rock_Stone_Mossy"
    },
    {
      "x": -41,
      "y": 175,
      "z": -8,
      "name": "Rock_Stone_Mossy"
    },
    {
      "x": -41,
      "y": 179,
      "z": -8,
      "name": "Rock_Stone_Mossy"
    },
    {
      "x": -41,
      "y": 171,
      "z": -7,
      "name": "Rock_Stone_Mossy"
    },
    {
      "x": -41,
      "y": 175,
      "z": -7,
      "name": "Rock_Stone_Mossy"
    },
    {
      "x": -41,
      "y": 177,
      "z": -7,
      "name": "Rock_Stone_Mossy"
    },
    {
      "x": -41,
      "y": 174,
      "z": -6,
      "name": "Rock_Stone_Mossy"
    },
    {
      "x": -41,
      "y": 176,
      "z": -6,
      "name": "Rock_Stone_Mossy"
    },
    {
      "x": -41,
      "y": 177,
      "z": -6,
      "name": "Rock_Stone_Mossy"
    },
    {
      "x": -41,
      "y": 172,
      "z": -5,
      "name": "Rock_Stone_Mossy"
    },
    {
      "x": -41,
      "y": 174,
      "z": -5,
      "name": "Rock_Stone_Mossy"
    },
    {
      "x": -41,
      "y": 175,
      "z": -5,
      "name": "Rock_Stone_Mossy"
    },
    {
      "x": -41,
      "y": 176,
      "z": -5,
      "name": "Rock_Stone_Mossy"
    },
    {
      "x": -41,
      "y": 177,
      "z": -5,
      "name": "Rock_Stone_Mossy"
    },
    {
      "x": -41,
      "y": 173,
      "z": -4,
      "name": "Rock_Stone_Mossy"
    },
    {
      "x": -41,
      "y": 175,
      "z": -4,
      "name": "Rock_Stone_Mossy"
    },
    {
      "x": -41,
      "y": 171,
      "z": -3,
      "name": "Rock_Stone_Mossy"
    },
    {
      "x": -41,
      "y": 172,
      "z": -3,
      "name": "Rock_Stone_Mossy"
    },
    {
      "x": -41,
      "y": 174,
      "z": -3,
      "name": "Rock_Stone_Mossy"
    },
    {
      "x": -41,
      "y": 175,
      "z": -3,
      "name": "Rock_Stone_Mossy"
    },
    {
      "x": -41,
      "y": 172,
      "z": -2,
      "name": "Rock_Stone_Mossy"
    },
    {
      "x": -41,
      "y": 171,
      "z": -1,
      "name": "Rock_Stone_Mossy"
    },
    {
      "x": -41,
      "y": 172,
      "z": -1,
      "name": "Rock_Stone_Mossy"
    },
    {
      "x": -41,
      "y": 174,
      "z": -1,
      "name": "Rock_Stone_Mossy"
    },
    {
      "x": -41,
      "y": 177,
      "z": -1,
      "name": "Rock_Stone_Mossy"
    },
    {
      "x": -41,
      "y": 173,
      "z": 0,
      "name": "Rock_Stone_Mossy"
    },
    {
      "x": -41,
      "y": 176,
      "z": 0,
      "name": "Rock_Stone_Mossy"
    },
    {
      "x": -41,
      "y": 175,
      "z": 1,
      "name": "Rock_Stone_Mossy"
    },
    {
      "x": -41,
      "y": 171,
      "z": 2,
      "name": "Rock_Stone_Mossy"
    },
    {
      "x": -41,
      "y": 171,
      "z": 3,
      "name": "Rock_Stone_Mossy"
    },
    {
      "x": -41,
      "y": 175,
      "z": 3,
      "name": "Rock_Stone_Mossy"
    },
    {
      "x": -41,
      "y": 173,
      "z": 4,
      "name": "Rock_Stone_Mossy"
    },
    {
      "x": -41,
      "y": 174,
      "z": 4,
      "name": "Rock_Stone_Mossy"
    },
    {
      "x": -41,
      "y": 175,
      "z": 4,
      "name": "Rock_Stone_Mossy"
    },
    {
      "x": -41,
      "y": 175,
      "z": 5,
      "name": "Rock_Stone_Mossy"
    },
    {
      "x": -41,
      "y": 176,
      "z": 5,
      "name": "Rock_Stone_Mossy"
    },
    {
      "x": -41,
      "y": 175,
      "z": 6,
      "name": "Rock_Stone_Mossy"
    },
    {
      "x": -41,
      "y": 173,
      "z": 7,
      "name": "Rock_Stone_Mossy"
    },
    {
      "x": -41,
      "y": 175,
      "z": 7,
      "name": "Rock_Stone_Mossy"
    },
    {
      "x": -41,
      "y": 176,
      "z": 7,
      "name": "Rock_Stone_Mossy"
    },
    {
      "x": -41,
      "y": 175,
      "z": 8,
      "name": "Rock_Stone_Mossy"
    },
    {
      "x": -41,
      "y": 173,
      "z": 9,
      "name": "Rock_Stone_Mossy"
    },
    {
      "x": -41,
      "y": 174,
      "z": 9,
      "name": "Rock_Stone_Mossy"
    },
    {
      "x": -41,
      "y": 175,
      "z": 9,
      "name": "Rock_Stone_Mossy"
    },
    {
      "x": -41,
      "y": 174,
      "z": 11,
      "name": "Rock_Stone_Mossy"
    },
    {
      "x": -41,
      "y": 175,
      "z": 14,
      "name": "Rock_Stone_Mossy"
    },
    {
      "x": -41,
      "y": 174,
      "z": 15,
      "name": "Rock_Stone_Mossy"
    },
    {
      "x": -40,
      "y": 178,
      "z": -28,
      "name": "Rock_Stone_Mossy"
    },
    {
      "x": -40,
      "y": 179,
      "z": -27,
      "name": "Rock_Stone_Mossy"
    },
    {
      "x": -40,
      "y": 179,
      "z": -26,
      "name": "Rock_Stone_Mossy"
    },
    {
      "x": -40,
      "y": 180,
      "z": -20,
      "name": "Rock_Stone_Mossy"
    },
    {
      "x": -40,
      "y": 180,
      "z": -18,
      "name": "Rock_Stone_Mossy"
    },
    {
      "x": -40,
      "y": 180,
      "z": -17,
      "name": "Rock_Stone_Mossy"
    },
    {
      "x": -40,
      "y": 182,
      "z": -17,
      "name": "Rock_Stone_Mossy"
    },
    {
      "x": -40,
      "y": 178,
      "z": -15,
      "name": "Rock_Stone_Mossy"
    },
    {
      "x": -40,
      "y": 180,
      "z": -15,
      "name": "Rock_Stone_Mossy"
    },
    {
      "x": -40,
      "y": 177,
      "z": -14,
      "name": "Rock_Stone_Mossy"
    },
    {
      "x": -40,
      "y": 178,
      "z": -14,
      "name": "Rock_Stone_Mossy"
    },
    {
      "x": -40,
      "y": 172,
      "z": -13,
      "name": "Rock_Stone_Mossy"
    },
    {
      "x": -40,
      "y": 175,
      "z": -13,
      "name": "Rock_Stone_Mossy"
    },
    {
      "x": -40,
      "y": 178,
      "z": -13,
      "name": "Rock_Stone_Mossy"
    },
    {
      "x": -40,
      "y": 176,
      "z": -12,
      "name": "Rock_Stone_Mossy"
    },
    {
      "x": -40,
      "y": 173,
      "z": -11,
      "name": "Rock_Stone_Mossy"
    },
    {
      "x": -40,
      "y": 172,
      "z": -10,
      "name": "Rock_Stone_Mossy"
    },
    {
      "x": -40,
      "y": 178,
      "z": -10,
      "name": "Rock_Stone_Mossy"
    },
    {
      "x": -40,
      "y": 179,
      "z": -10,
      "name": "Rock_Stone_Mossy"
    },
    {
      "x": -40,
      "y": 171,
      "z": -9,
      "name": "Rock_Stone_Mossy"
    },
    {
      "x": -40,
      "y": 177,
      "z": -9,
      "name": "Rock_Stone_Mossy"
    },
    {
      "x": -40,
      "y": 179,
      "z": -9,
      "name": "Rock_Stone_Mossy"
    },
    {
      "x": -40,
      "y": 174,
      "z": -8,
      "name": "Rock_Stone_Mossy"
    },
    {
      "x": -40,
      "y": 177,
      "z": -8,
      "name": "Rock_Stone_Mossy"
    },
    {
      "x": -40,
      "y": 171,
      "z": -7,
      "name": "Rock_Stone_Mossy"
    },
    {
      "x": -40,
      "y": 175,
      "z": -7,
      "name": "Rock_Stone_Mossy"
    },
    {
      "x": -40,
      "y": 177,
      "z": -7,
      "name": "Rock_Stone_Mossy"
    },
    {
      "x": -40,
      "y": 176,
      "z": -6,
      "name": "Rock_Stone_Mossy"
    },
    {
      "x": -40,
      "y": 180,
      "z": -6,
      "name": "Rock_Stone_Mossy"
    },
    {
      "x": -40,
      "y": 172,
      "z": -5,
      "name": "Rock_Stone_Mossy"
    },
    {
      "x": -40,
      "y": 174,
      "z": -4,
      "name": "Rock_Stone_Mossy"
    },
    {
      "x": -40,
      "y": 175,
      "z": -4,
      "name": "Rock_Stone_Mossy"
    },
    {
      "x": -40,
      "y": 172,
      "z": -3,
      "name": "Rock_Stone_Mossy"
    },
    {
      "x": -40,
      "y": 175,
      "z": -3,
      "name": "Rock_Stone_Mossy"
    },
    {
      "x": -40,
      "y": 177,
      "z": -2,
      "name": "Rock_Stone_Mossy"
    },
    {
      "x": -40,
      "y": 171,
      "z": -1,
      "name": "Rock_Stone_Mossy"
    },
    {
      "x": -40,
      "y": 174,
      "z": -1,
      "name": "Rock_Stone_Mossy"
    },
    {
      "x": -40,
      "y": 172,
      "z": 0,
      "name": "Rock_Stone_Mossy"
    },
    {
      "x": -40,
      "y": 175,
      "z": 0,
      "name": "Rock_Stone_Mossy"
    },
    {
      "x": -40,
      "y": 171,
      "z": 1,
      "name": "Rock_Stone_Mossy"
    },
    {
      "x": -40,
      "y": 176,
      "z": 1,
      "name": "Rock_Stone_Mossy"
    },
    {
      "x": -40,
      "y": 177,
      "z": 1,
      "name": "Rock_Stone_Mossy"
    },
    {
      "x": -40,
      "y": 173,
      "z": 2,
      "name": "Rock_Stone_Mossy"
    },
    {
      "x": -40,
      "y": 174,
      "z": 2,
      "name": "Rock_Stone_Mossy"
    },
    {
      "x": -40,
      "y": 175,
      "z": 2,
      "name": "Rock_Stone_Mossy"
    },
    {
      "x": -40,
      "y": 172,
      "z": 3,
      "name": "Rock_Stone_Mossy"
    },
    {
      "x": -40,
      "y": 173,
      "z": 3,
      "name": "Rock_Stone_Mossy"
    },
    {
      "x": -40,
      "y": 174,
      "z": 3,
      "name": "Rock_Stone_Mossy"
    },
    {
      "x": -40,
      "y": 175,
      "z": 3,
      "name": "Rock_Stone_Mossy"
    },
    {
      "x": -40,
      "y": 176,
      "z": 3,
      "name": "Rock_Stone_Mossy"
    },
    {
      "x": -40,
      "y": 174,
      "z": 4,
      "name": "Rock_Stone_Mossy"
    },
    {
      "x": -40,
      "y": 175,
      "z": 4,
      "name": "Rock_Stone_Mossy"
    },
    {
      "x": -40,
      "y": 175,
      "z": 5,
      "name": "Rock_Stone_Mossy"
    },
    {
      "x": -40,
      "y": 172,
      "z": 6,
      "name": "Rock_Stone_Mossy"
    },
    {
      "x": -40,
      "y": 174,
      "z": 6,
      "name": "Rock_Stone_Mossy"
    },
    {
      "x": -40,
      "y": 176,
      "z": 6,
      "name": "Rock_Stone_Mossy"
    },
    {
      "x": -40,
      "y": 172,
      "z": 7,
      "name": "Rock_Stone_Mossy"
    },
    {
      "x": -40,
      "y": 173,
      "z": 7,
      "name": "Rock_Stone_Mossy"
    },
    {
      "x": -40,
      "y": 172,
      "z": 8,
      "name": "Rock_Stone_Mossy"
    },
    {
      "x": -40,
      "y": 173,
      "z": 8,
      "name": "Rock_Stone_Mossy"
    },
    {
      "x": -40,
      "y": 174,
      "z": 8,
      "name": "Rock_Stone_Mossy"
    },
    {
      "x": -40,
      "y": 175,
      "z": 8,
      "name": "Rock_Stone_Mossy"
    },
    {
      "x": -40,
      "y": 175,
      "z": 9,
      "name": "Rock_Stone_Mossy"
    },
    {
      "x": -40,
      "y": 174,
      "z": 10,
      "name": "Rock_Stone_Mossy"
    },
    {
      "x": -40,
      "y": 172,
      "z": 11,
      "name": "Rock_Stone_Mossy"
    },
    {
      "x": -40,
      "y": 174,
      "z": 11,
      "name": "Rock_Stone_Mossy"
    },
    {
      "x": -40,
      "y": 173,
      "z": 12,
      "name": "Rock_Stone_Mossy"
    },
    {
      "x": -40,
      "y": 174,
      "z": 12,
      "name": "Rock_Stone_Mossy"
    },
    {
      "x": -40,
      "y": 173,
      "z": 13,
      "name": "Rock_Stone_Mossy"
    },
    {
      "x": -40,
      "y": 175,
      "z": 13,
      "name": "Rock_Stone_Mossy"
    },
    {
      "x": -40,
      "y": 173,
      "z": 15,
      "name": "Rock_Stone_Mossy"
    },
    {
      "x": -39,
      "y": 181,
      "z": -26,
      "name": "Rock_Stone_Mossy"
    },
    {
      "x": -39,
      "y": 177,
      "z": -25,
      "name": "Rock_Stone_Mossy"
    },
    {
      "x": -39,
      "y": 179,
      "z": -24,
      "name": "Rock_Stone_Mossy"
    },
    {
      "x": -39,
      "y": 177,
      "z": -23,
      "name": "Rock_Stone_Mossy"
    },
    {
      "x": -39,
      "y": 179,
      "z": -23,
      "name": "Rock_Stone_Mossy"
    },
    {
      "x": -39,
      "y": 176,
      "z": -22,
      "name": "Rock_Stone_Mossy"
    },
    {
      "x": -39,
      "y": 182,
      "z": -21,
      "name": "Rock_Stone_Mossy"
    },
    {
      "x": -39,
      "y": 176,
      "z": -20,
      "name": "Rock_Stone_Mossy"
    },
    {
      "x": -39,
      "y": 177,
      "z": -18,
      "name": "Rock_Stone_Mossy"
    },
    {
      "x": -39,
      "y": 174,
      "z": -16,
      "name": "Rock_Stone_Mossy"
    },
    {
      "x": -39,
      "y": 181,
      "z": -16,
      "name": "Rock_Stone_Mossy"
    },
    {
      "x": -39,
      "y": 182,
      "z": -16,
      "name": "Rock_Stone_Mossy"
    },
    {
      "x": -39,
      "y": 174,
      "z": -15,
      "name": "Rock_Stone_Mossy"
    },
    {
      "x": -39,
      "y": 174,
      "z": -14,
      "name": "Rock_Stone_Mossy"
    },
    {
      "x": -39,
      "y": 178,
      "z": -14,
      "name": "Rock_Stone_Mossy"
    },
    {
      "x": -39,
      "y": 182,
      "z": -14,
      "name": "Rock_Stone_Mossy"
    },
    {
      "x": -39,
      "y": 174,
      "z": -13,
      "name": "Rock_Stone_Mossy"
    },
    {
      "x": -39,
      "y": 181,
      "z": -13,
      "name": "Rock_Stone_Mossy"
    },
    {
      "x": -39,
      "y": 174,
      "z": -12,
      "name": "Rock_Stone_Mossy"
    },
    {
      "x": -39,
      "y": 173,
      "z": -11,
      "name": "Rock_Stone_Mossy"
    },
    {
      "x": -39,
      "y": 174,
      "z": -11,
      "name": "Rock_Stone_Mossy"
    },
    {
      "x": -39,
      "y": 175,
      "z": -11,
      "name": "Rock_Stone_Mossy"
    },
    {
      "x": -39,
      "y": 177,
      "z": -11,
      "name": "Rock_Stone_Mossy"
    },
    {
      "x": -39,
      "y": 171,
      "z": -10,
      "name": "Rock_Stone_Mossy"
    },
    {
      "x": -39,
      "y": 172,
      "z": -10,
      "name": "Rock_Stone_Mossy"
    },
    {
      "x": -39,
      "y": 173,
      "z": -10,
      "name": "Rock_Stone_Mossy"
    },
    {
      "x": -39,
      "y": 174,
      "z": -10,
      "name": "Rock_Stone_Mossy"
    },
    {
      "x": -39,
      "y": 175,
      "z": -10,
      "name": "Rock_Stone_Mossy"
    },
    {
      "x": -39,
      "y": 179,
      "z": -10,
      "name": "Rock_Stone_Mossy"
    },
    {
      "x": -39,
      "y": 171,
      "z": -9,
      "name": "Rock_Stone_Mossy"
    },
    {
      "x": -39,
      "y": 172,
      "z": -9,
      "name": "Rock_Stone_Mossy"
    },
    {
      "x": -39,
      "y": 176,
      "z": -9,
      "name": "Rock_Stone_Mossy"
    },
    {
      "x": -39,
      "y": 178,
      "z": -9,
      "name": "Rock_Stone_Mossy"
    },
    {
      "x": -39,
      "y": 171,
      "z": -8,
      "name": "Rock_Stone_Mossy"
    },
    {
      "x": -39,
      "y": 177,
      "z": -8,
      "name": "Rock_Stone_Mossy"
    },
    {
      "x": -39,
      "y": 180,
      "z": -8,
      "name": "Rock_Stone_Mossy"
    },
    {
      "x": -39,
      "y": 181,
      "z": -8,
      "name": "Rock_Stone_Mossy"
    },
    {
      "x": -39,
      "y": 172,
      "z": -7,
      "name": "Rock_Stone_Mossy"
    },
    {
      "x": -39,
      "y": 174,
      "z": -7,
      "name": "Rock_Stone_Mossy"
    },
    {
      "x": -39,
      "y": 179,
      "z": -7,
      "name": "Rock_Stone_Mossy"
    },
    {
      "x": -39,
      "y": 173,
      "z": -6,
      "name": "Rock_Stone_Mossy"
    },
    {
      "x": -39,
      "y": 174,
      "z": -6,
      "name": "Rock_Stone_Mossy"
    },
    {
      "x": -39,
      "y": 177,
      "z": -6,
      "name": "Rock_Stone_Mossy"
    },
    {
      "x": -39,
      "y": 180,
      "z": -6,
      "name": "Rock_Stone_Mossy"
    },
    {
      "x": -39,
      "y": 172,
      "z": -5,
      "name": "Rock_Stone_Mossy"
    },
    {
      "x": -39,
      "y": 173,
      "z": -5,
      "name": "Rock_Stone_Mossy"
    },
    {
      "x": -39,
      "y": 175,
      "z": -5,
      "name": "Rock_Stone_Mossy"
    },
    {
      "x": -39,
      "y": 178,
      "z": -5,
      "name": "Rock_Stone_Mossy"
    },
    {
      "x": -39,
      "y": 175,
      "z": -4,
      "name": "Rock_Stone_Mossy"
    },
    {
      "x": -39,
      "y": 176,
      "z": -3,
      "name": "Rock_Stone_Mossy"
    },
    {
      "x": -39,
      "y": 177,
      "z": -3,
      "name": "Rock_Stone_Mossy"
    },
    {
      "x": -39,
      "y": 174,
      "z": -2,
      "name": "Rock_Stone_Mossy"
    },
    {
      "x": -39,
      "y": 177,
      "z": -2,
      "name": "Rock_Stone_Mossy"
    },
    {
      "x": -39,
      "y": 173,
      "z": -1,
      "name": "Rock_Stone_Mossy"
    },
    {
      "x": -39,
      "y": 171,
      "z": 0,
      "name": "Rock_Stone_Mossy"
    },
    {
      "x": -39,
      "y": 174,
      "z": 0,
      "name": "Rock_Stone_Mossy"
    },
    {
      "x": -39,
      "y": 176,
      "z": 0,
      "name": "Rock_Stone_Mossy"
    },
    {
      "x": -39,
      "y": 172,
      "z": 1,
      "name": "Rock_Stone_Mossy"
    },
    {
      "x": -39,
      "y": 173,
      "z": 1,
      "name": "Rock_Stone_Mossy"
    },
    {
      "x": -39,
      "y": 174,
      "z": 1,
      "name": "Rock_Stone_Mossy"
    },
    {
      "x": -39,
      "y": 177,
      "z": 1,
      "name": "Rock_Stone_Mossy"
    },
    {
      "x": -39,
      "y": 171,
      "z": 2,
      "name": "Rock_Stone_Mossy"
    },
    {
      "x": -39,
      "y": 172,
      "z": 2,
      "name": "Rock_Stone_Mossy"
    },
    {
      "x": -39,
      "y": 173,
      "z": 3,
      "name": "Rock_Stone_Mossy"
    },
    {
      "x": -39,
      "y": 176,
      "z": 4,
      "name": "Rock_Stone_Mossy"
    },
    {
      "x": -39,
      "y": 177,
      "z": 4,
      "name": "Rock_Stone_Mossy"
    },
    {
      "x": -39,
      "y": 173,
      "z": 5,
      "name": "Rock_Stone_Mossy"
    },
    {
      "x": -39,
      "y": 176,
      "z": 5,
      "name": "Rock_Stone_Mossy"
    },
    {
      "x": -39,
      "y": 173,
      "z": 6,
      "name": "Rock_Stone_Mossy"
    },
    {
      "x": -39,
      "y": 176,
      "z": 6,
      "name": "Rock_Stone_Mossy"
    },
    {
      "x": -39,
      "y": 172,
      "z": 7,
      "name": "Rock_Stone_Mossy"
    },
    {
      "x": -39,
      "y": 173,
      "z": 7,
      "name": "Rock_Stone_Mossy"
    },
    {
      "x": -39,
      "y": 174,
      "z": 7,
      "name": "Rock_Stone_Mossy"
    },
    {
      "x": -39,
      "y": 176,
      "z": 7,
      "name": "Rock_Stone_Mossy"
    },
    {
      "x": -39,
      "y": 173,
      "z": 8,
      "name": "Rock_Stone_Mossy"
    },
    {
      "x": -39,
      "y": 174,
      "z": 8,
      "name": "Rock_Stone_Mossy"
    },
    {
      "x": -39,
      "y": 176,
      "z": 8,
      "name": "Rock_Stone_Mossy"
    },
    {
      "x": -39,
      "y": 173,
      "z": 9,
      "name": "Rock_Stone_Mossy"
    },
    {
      "x": -39,
      "y": 174,
      "z": 9,
      "name": "Rock_Stone_Mossy"
    },
    {
      "x": -39,
      "y": 174,
      "z": 10,
      "name": "Rock_Stone_Mossy"
    },
    {
      "x": -39,
      "y": 173,
      "z": 11,
      "name": "Rock_Stone_Mossy"
    },
    {
      "x": -39,
      "y": 172,
      "z": 12,
      "name": "Rock_Stone_Mossy"
    },
    {
      "x": -39,
      "y": 174,
      "z": 12,
      "name": "Rock_Stone_Mossy"
    },
    {
      "x": -39,
      "y": 175,
      "z": 12,
      "name": "Rock_Stone_Mossy"
    },
    {
      "x": -39,
      "y": 176,
      "z": 12,
      "name": "Rock_Stone_Mossy"
    },
    {
      "x": -39,
      "y": 175,
      "z": 13,
      "name": "Rock_Stone_Mossy"
    },
    {
      "x": -39,
      "y": 176,
      "z": 13,
      "name": "Rock_Stone_Mossy"
    },
    {
      "x": -39,
      "y": 176,
      "z": 14,
      "name": "Rock_Stone_Mossy"
    },
    {
      "x": -38,
      "y": 178,
      "z": -28,
      "name": "Rock_Stone_Mossy"
    },
    {
      "x": -38,
      "y": 181,
      "z": -28,
      "name": "Rock_Stone_Mossy"
    },
    {
      "x": -38,
      "y": 180,
      "z": -25,
      "name": "Rock_Stone_Mossy"
    },
    {
      "x": -38,
      "y": 176,
      "z": -24,
      "name": "Rock_Stone_Mossy"
    },
    {
      "x": -38,
      "y": 180,
      "z": -22,
      "name": "Rock_Stone_Mossy"
    },
    {
      "x": -38,
      "y": 182,
      "z": -22,
      "name": "Rock_Stone_Mossy"
    },
    {
      "x": -38,
      "y": 181,
      "z": -21,
      "name": "Rock_Stone_Mossy"
    },
    {
      "x": -38,
      "y": 179,
      "z": -20,
      "name": "Rock_Stone_Mossy"
    },
    {
      "x": -38,
      "y": 182,
      "z": -20,
      "name": "Rock_Stone_Mossy"
    },
    {
      "x": -38,
      "y": 177,
      "z": -18,
      "name": "Rock_Stone_Mossy"
    },
    {
      "x": -38,
      "y": 182,
      "z": -17,
      "name": "Rock_Stone_Mossy"
    },
    {
      "x": -38,
      "y": 173,
      "z": -16,
      "name": "Rock_Stone_Mossy"
    },
    {
      "x": -38,
      "y": 174,
      "z": -16,
      "name": "Rock_Stone_Mossy"
    },
    {
      "x": -38,
      "y": 176,
      "z": -15,
      "name": "Rock_Stone_Mossy"
    },
    {
      "x": -38,
      "y": 172,
      "z": -14,
      "name": "Rock_Stone_Mossy"
    },
    {
      "x": -38,
      "y": 179,
      "z": -14,
      "name": "Rock_Stone_Mossy"
    },
    {
      "x": -38,
      "y": 180,
      "z": -14,
      "name": "Rock_Stone_Mossy"
    },
    {
      "x": -38,
      "y": 176,
      "z": -13,
      "name": "Rock_Stone_Mossy"
    },
    {
      "x": -38,
      "y": 178,
      "z": -13,
      "name": "Rock_Stone_Mossy"
    },
    {
      "x": -38,
      "y": 171,
      "z": -12,
      "name": "Rock_Stone_Mossy"
    },
    {
      "x": -38,
      "y": 172,
      "z": -12,
      "name": "Rock_Stone_Mossy"
    },
    {
      "x": -38,
      "y": 173,
      "z": -12,
      "name": "Rock_Stone_Mossy"
    },
    {
      "x": -38,
      "y": 175,
      "z": -12,
      "name": "Rock_Stone_Mossy"
    },
    {
      "x": -38,
      "y": 176,
      "z": -12,
      "name": "Rock_Stone_Mossy"
    },
    {
      "x": -38,
      "y": 172,
      "z": -11,
      "name": "Rock_Stone_Mossy"
    },
    {
      "x": -38,
      "y": 173,
      "z": -11,
      "name": "Rock_Stone_Mossy"
    },
    {
      "x": -38,
      "y": 174,
      "z": -11,
      "name": "Rock_Stone_Mossy"
    },
    {
      "x": -38,
      "y": 180,
      "z": -11,
      "name": "Rock_Stone_Mossy"
    },
    {
      "x": -38,
      "y": 172,
      "z": -10,
      "name": "Rock_Stone_Mossy"
    },
    {
      "x": -38,
      "y": 174,
      "z": -10,
      "name": "Rock_Stone_Mossy"
    },
    {
      "x": -38,
      "y": 175,
      "z": -10,
      "name": "Rock_Stone_Mossy"
    },
    {
      "x": -38,
      "y": 176,
      "z": -10,
      "name": "Rock_Stone_Mossy"
    },
    {
      "x": -38,
      "y": 173,
      "z": -9,
      "name": "Rock_Stone_Mossy"
    },
    {
      "x": -38,
      "y": 175,
      "z": -9,
      "name": "Rock_Stone_Mossy"
    },
    {
      "x": -38,
      "y": 177,
      "z": -9,
      "name": "Rock_Stone_Mossy"
    },
    {
      "x": -38,
      "y": 180,
      "z": -9,
      "name": "Rock_Stone_Mossy"
    },
    {
      "x": -38,
      "y": 175,
      "z": -8,
      "name": "Rock_Stone_Mossy"
    },
    {
      "x": -38,
      "y": 176,
      "z": -8,
      "name": "Rock_Stone_Mossy"
    },
    {
      "x": -38,
      "y": 177,
      "z": -8,
      "name": "Rock_Stone_Mossy"
    },
    {
      "x": -38,
      "y": 171,
      "z": -7,
      "name": "Rock_Stone_Mossy"
    },
    {
      "x": -38,
      "y": 175,
      "z": -7,
      "name": "Rock_Stone_Mossy"
    },
    {
      "x": -38,
      "y": 176,
      "z": -7,
      "name": "Rock_Stone_Mossy"
    },
    {
      "x": -38,
      "y": 177,
      "z": -7,
      "name": "Rock_Stone_Mossy"
    },
    {
      "x": -38,
      "y": 175,
      "z": -6,
      "name": "Rock_Stone_Mossy"
    },
    {
      "x": -38,
      "y": 176,
      "z": -6,
      "name": "Rock_Stone_Mossy"
    },
    {
      "x": -38,
      "y": 177,
      "z": -6,
      "name": "Rock_Stone_Mossy"
    },
    {
      "x": -38,
      "y": 171,
      "z": -5,
      "name": "Rock_Stone_Mossy"
    },
    {
      "x": -38,
      "y": 175,
      "z": -5,
      "name": "Rock_Stone_Mossy"
    },
    {
      "x": -38,
      "y": 177,
      "z": -5,
      "name": "Rock_Stone_Mossy"
    },
    {
      "x": -38,
      "y": 170,
      "z": -4,
      "name": "Rock_Stone_Mossy"
    },
    {
      "x": -38,
      "y": 175,
      "z": -4,
      "name": "Rock_Stone_Mossy"
    },
    {
      "x": -38,
      "y": 170,
      "z": -2,
      "name": "Rock_Stone_Mossy"
    },
    {
      "x": -38,
      "y": 171,
      "z": -2,
      "name": "Rock_Stone_Mossy"
    },
    {
      "x": -38,
      "y": 172,
      "z": -2,
      "name": "Rock_Stone_Mossy"
    },
    {
      "x": -38,
      "y": 174,
      "z": -1,
      "name": "Rock_Stone_Mossy"
    },
    {
      "x": -38,
      "y": 171,
      "z": 0,
      "name": "Rock_Stone_Mossy"
    },
    {
      "x": -38,
      "y": 175,
      "z": 1,
      "name": "Rock_Stone_Mossy"
    },
    {
      "x": -38,
      "y": 173,
      "z": 2,
      "name": "Rock_Stone_Mossy"
    },
    {
      "x": -38,
      "y": 174,
      "z": 2,
      "name": "Rock_Stone_Mossy"
    },
    {
      "x": -38,
      "y": 172,
      "z": 4,
      "name": "Rock_Stone_Mossy"
    },
    {
      "x": -38,
      "y": 175,
      "z": 4,
      "name": "Rock_Stone_Mossy"
    },
    {
      "x": -38,
      "y": 176,
      "z": 4,
      "name": "Rock_Stone_Mossy"
    },
    {
      "x": -38,
      "y": 177,
      "z": 4,
      "name": "Rock_Stone_Mossy"
    },
    {
      "x": -38,
      "y": 174,
      "z": 5,
      "name": "Rock_Stone_Mossy"
    },
    {
      "x": -38,
      "y": 176,
      "z": 6,
      "name": "Rock_Stone_Mossy"
    },
    {
      "x": -38,
      "y": 173,
      "z": 7,
      "name": "Rock_Stone_Mossy"
    },
    {
      "x": -38,
      "y": 174,
      "z": 7,
      "name": "Rock_Stone_Mossy"
    },
    {
      "x": -38,
      "y": 177,
      "z": 7,
      "name": "Rock_Stone_Mossy"
    },
    {
      "x": -38,
      "y": 172,
      "z": 8,
      "name": "Rock_Stone_Mossy"
    },
    {
      "x": -38,
      "y": 173,
      "z": 8,
      "name": "Rock_Stone_Mossy"
    },
    {
      "x": -38,
      "y": 174,
      "z": 8,
      "name": "Rock_Stone_Mossy"
    },
    {
      "x": -38,
      "y": 176,
      "z": 8,
      "name": "Rock_Stone_Mossy"
    },
    {
      "x": -38,
      "y": 177,
      "z": 8,
      "name": "Rock_Stone_Mossy"
    },
    {
      "x": -38,
      "y": 173,
      "z": 9,
      "name": "Rock_Stone_Mossy"
    },
    {
      "x": -38,
      "y": 175,
      "z": 9,
      "name": "Rock_Stone_Mossy"
    },
    {
      "x": -38,
      "y": 175,
      "z": 10,
      "name": "Rock_Stone_Mossy"
    },
    {
      "x": -38,
      "y": 177,
      "z": 10,
      "name": "Rock_Stone_Mossy"
    },
    {
      "x": -38,
      "y": 175,
      "z": 11,
      "name": "Rock_Stone_Mossy"
    },
    {
      "x": -38,
      "y": 177,
      "z": 11,
      "name": "Rock_Stone_Mossy"
    },
    {
      "x": -38,
      "y": 173,
      "z": 13,
      "name": "Rock_Stone_Mossy"
    },
    {
      "x": -38,
      "y": 175,
      "z": 13,
      "name": "Rock_Stone_Mossy"
    },
    {
      "x": -38,
      "y": 175,
      "z": 17,
      "name": "Rock_Stone_Mossy"
    },
    {
      "x": -38,
      "y": 174,
      "z": 19,
      "name": "Rock_Stone_Mossy"
    },
    {
      "x": -37,
      "y": 178,
      "z": -25,
      "name": "Rock_Stone_Mossy"
    },
    {
      "x": -37,
      "y": 178,
      "z": -22,
      "name": "Rock_Stone_Mossy"
    },
    {
      "x": -37,
      "y": 179,
      "z": -22,
      "name": "Rock_Stone_Mossy"
    },
    {
      "x": -37,
      "y": 182,
      "z": -22,
      "name": "Rock_Stone_Mossy"
    },
    {
      "x": -37,
      "y": 178,
      "z": -21,
      "name": "Rock_Stone_Mossy"
    },
    {
      "x": -37,
      "y": 176,
      "z": -20,
      "name": "Rock_Stone_Mossy"
    },
    {
      "x": -37,
      "y": 180,
      "z": -20,
      "name": "Rock_Stone_Mossy"
    },
    {
      "x": -37,
      "y": 181,
      "z": -20,
      "name": "Rock_Stone_Mossy"
    },
    {
      "x": -37,
      "y": 176,
      "z": -19,
      "name": "Rock_Stone_Mossy"
    },
    {
      "x": -37,
      "y": 176,
      "z": -18,
      "name": "Rock_Stone_Mossy"
    },
    {
      "x": -37,
      "y": 182,
      "z": -18,
      "name": "Rock_Stone_Mossy"
    },
    {
      "x": -37,
      "y": 173,
      "z": -17,
      "name": "Rock_Stone_Mossy"
    },
    {
      "x": -37,
      "y": 175,
      "z": -17,
      "name": "Rock_Stone_Mossy"
    },
    {
      "x": -37,
      "y": 179,
      "z": -17,
      "name": "Rock_Stone_Mossy"
    },
    {
      "x": -37,
      "y": 173,
      "z": -16,
      "name": "Rock_Stone_Mossy"
    },
    {
      "x": -37,
      "y": 175,
      "z": -16,
      "name": "Rock_Stone_Mossy"
    },
    {
      "x": -37,
      "y": 176,
      "z": -15,
      "name": "Rock_Stone_Mossy"
    },
    {
      "x": -37,
      "y": 178,
      "z": -15,
      "name": "Rock_Stone_Mossy"
    },
    {
      "x": -37,
      "y": 172,
      "z": -14,
      "name": "Rock_Stone_Mossy"
    },
    {
      "x": -37,
      "y": 174,
      "z": -14,
      "name": "Rock_Stone_Mossy"
    },
    {
      "x": -37,
      "y": 178,
      "z": -14,
      "name": "Rock_Stone_Mossy"
    },
    {
      "x": -37,
      "y": 182,
      "z": -14,
      "name": "Rock_Stone_Mossy"
    },
    {
      "x": -37,
      "y": 171,
      "z": -13,
      "name": "Rock_Stone_Mossy"
    },
    {
      "x": -37,
      "y": 173,
      "z": -13,
      "name": "Rock_Stone_Mossy"
    },
    {
      "x": -37,
      "y": 174,
      "z": -13,
      "name": "Rock_Stone_Mossy"
    },
    {
      "x": -37,
      "y": 175,
      "z": -13,
      "name": "Rock_Stone_Mossy"
    },
    {
      "x": -37,
      "y": 176,
      "z": -13,
      "name": "Rock_Stone_Mossy"
    },
    {
      "x": -37,
      "y": 181,
      "z": -12,
      "name": "Rock_Stone_Mossy"
    },
    {
      "x": -37,
      "y": 176,
      "z": -11,
      "name": "Rock_Stone_Mossy"
    },
    {
      "x": -37,
      "y": 181,
      "z": -11,
      "name": "Rock_Stone_Mossy"
    },
    {
      "x": -37,
      "y": 177,
      "z": -10,
      "name": "Rock_Stone_Mossy"
    },
    {
      "x": -37,
      "y": 174,
      "z": -9,
      "name": "Rock_Stone_Mossy"
    },
    {
      "x": -37,
      "y": 179,
      "z": -9,
      "name": "Rock_Stone_Mossy"
    },
    {
      "x": -37,
      "y": 171,
      "z": -8,
      "name": "Rock_Stone_Mossy"
    },
    {
      "x": -37,
      "y": 172,
      "z": -8,
      "name": "Rock_Stone_Mossy"
    },
    {
      "x": -37,
      "y": 177,
      "z": -8,
      "name": "Rock_Stone_Mossy"
    },
    {
      "x": -37,
      "y": 170,
      "z": -6,
      "name": "Rock_Stone_Mossy"
    },
    {
      "x": -37,
      "y": 173,
      "z": -6,
      "name": "Rock_Stone_Mossy"
    },
    {
      "x": -37,
      "y": 177,
      "z": -6,
      "name": "Rock_Stone_Mossy"
    },
    {
      "x": -37,
      "y": 178,
      "z": -6,
      "name": "Rock_Stone_Mossy"
    },
    {
      "x": -37,
      "y": 181,
      "z": -6,
      "name": "Rock_Stone_Mossy"
    },
    {
      "x": -37,
      "y": 170,
      "z": -5,
      "name": "Rock_Stone_Mossy"
    },
    {
      "x": -37,
      "y": 173,
      "z": -5,
      "name": "Rock_Stone_Mossy"
    },
    {
      "x": -37,
      "y": 178,
      "z": -5,
      "name": "Rock_Stone_Mossy"
    },
    {
      "x": -37,
      "y": 173,
      "z": -4,
      "name": "Rock_Stone_Mossy"
    },
    {
      "x": -37,
      "y": 178,
      "z": -4,
      "name": "Rock_Stone_Mossy"
    },
    {
      "x": -37,
      "y": 171,
      "z": -3,
      "name": "Rock_Stone_Mossy"
    },
    {
      "x": -37,
      "y": 173,
      "z": -2,
      "name": "Rock_Stone_Mossy"
    },
    {
      "x": -37,
      "y": 174,
      "z": -2,
      "name": "Rock_Stone_Mossy"
    },
    {
      "x": -37,
      "y": 178,
      "z": -2,
      "name": "Rock_Stone_Mossy"
    },
    {
      "x": -37,
      "y": 170,
      "z": -1,
      "name": "Rock_Stone_Mossy"
    },
    {
      "x": -37,
      "y": 171,
      "z": -1,
      "name": "Rock_Stone_Mossy"
    },
    {
      "x": -37,
      "y": 172,
      "z": -1,
      "name": "Rock_Stone_Mossy"
    },
    {
      "x": -37,
      "y": 173,
      "z": -1,
      "name": "Rock_Stone_Mossy"
    },
    {
      "x": -37,
      "y": 170,
      "z": 0,
      "name": "Rock_Stone_Mossy"
    },
    {
      "x": -37,
      "y": 172,
      "z": 0,
      "name": "Rock_Stone_Mossy"
    },
    {
      "x": -37,
      "y": 177,
      "z": 0,
      "name": "Rock_Stone_Mossy"
    },
    {
      "x": -37,
      "y": 172,
      "z": 1,
      "name": "Rock_Stone_Mossy"
    },
    {
      "x": -37,
      "y": 173,
      "z": 1,
      "name": "Rock_Stone_Mossy"
    },
    {
      "x": -37,
      "y": 174,
      "z": 1,
      "name": "Rock_Stone_Mossy"
    },
    {
      "x": -37,
      "y": 175,
      "z": 1,
      "name": "Rock_Stone_Mossy"
    },
    {
      "x": -37,
      "y": 176,
      "z": 1,
      "name": "Rock_Stone_Mossy"
    },
    {
      "x": -37,
      "y": 176,
      "z": 2,
      "name": "Rock_Stone_Mossy"
    },
    {
      "x": -37,
      "y": 173,
      "z": 3,
      "name": "Rock_Stone_Mossy"
    },
    {
      "x": -37,
      "y": 174,
      "z": 3,
      "name": "Rock_Stone_Mossy"
    },
    {
      "x": -37,
      "y": 175,
      "z": 3,
      "name": "Rock_Stone_Mossy"
    },
    {
      "x": -37,
      "y": 172,
      "z": 4,
      "name": "Rock_Stone_Mossy"
    },
    {
      "x": -37,
      "y": 171,
      "z": 5,
      "name": "Rock_Stone_Mossy"
    },
    {
      "x": -37,
      "y": 172,
      "z": 5,
      "name": "Rock_Stone_Mossy"
    },
    {
      "x": -37,
      "y": 174,
      "z": 5,
      "name": "Rock_Stone_Mossy"
    },
    {
      "x": -37,
      "y": 175,
      "z": 5,
      "name": "Rock_Stone_Mossy"
    },
    {
      "x": -37,
      "y": 176,
      "z": 5,
      "name": "Rock_Stone_Mossy"
    },
    {
      "x": -37,
      "y": 176,
      "z": 6,
      "name": "Rock_Stone_Mossy"
    },
    {
      "x": -37,
      "y": 177,
      "z": 6,
      "name": "Rock_Stone_Mossy"
    },
    {
      "x": -37,
      "y": 173,
      "z": 7,
      "name": "Rock_Stone_Mossy"
    },
    {
      "x": -37,
      "y": 174,
      "z": 7,
      "name": "Rock_Stone_Mossy"
    },
    {
      "x": -37,
      "y": 173,
      "z": 8,
      "name": "Rock_Stone_Mossy"
    },
    {
      "x": -37,
      "y": 175,
      "z": 8,
      "name": "Rock_Stone_Mossy"
    },
    {
      "x": -37,
      "y": 172,
      "z": 9,
      "name": "Rock_Stone_Mossy"
    },
    {
      "x": -37,
      "y": 175,
      "z": 9,
      "name": "Rock_Stone_Mossy"
    },
    {
      "x": -37,
      "y": 176,
      "z": 9,
      "name": "Rock_Stone_Mossy"
    },
    {
      "x": -37,
      "y": 173,
      "z": 10,
      "name": "Rock_Stone_Mossy"
    },
    {
      "x": -37,
      "y": 175,
      "z": 10,
      "name": "Rock_Stone_Mossy"
    },
    {
      "x": -37,
      "y": 176,
      "z": 10,
      "name": "Rock_Stone_Mossy"
    },
    {
      "x": -37,
      "y": 171,
      "z": 11,
      "name": "Rock_Stone_Mossy"
    },
    {
      "x": -37,
      "y": 172,
      "z": 11,
      "name": "Rock_Stone_Mossy"
    },
    {
      "x": -37,
      "y": 173,
      "z": 11,
      "name": "Rock_Stone_Mossy"
    },
    {
      "x": -37,
      "y": 175,
      "z": 11,
      "name": "Rock_Stone_Mossy"
    },
    {
      "x": -37,
      "y": 171,
      "z": 12,
      "name": "Rock_Stone_Mossy"
    },
    {
      "x": -37,
      "y": 176,
      "z": 12,
      "name": "Rock_Stone_Mossy"
    },
    {
      "x": -37,
      "y": 173,
      "z": 13,
      "name": "Rock_Stone_Mossy"
    },
    {
      "x": -37,
      "y": 173,
      "z": 14,
      "name": "Rock_Stone_Mossy"
    },
    {
      "x": -37,
      "y": 172,
      "z": 15,
      "name": "Rock_Stone_Mossy"
    },
    {
      "x": -37,
      "y": 175,
      "z": 15,
      "name": "Rock_Stone_Mossy"
    },
    {
      "x": -37,
      "y": 176,
      "z": 15,
      "name": "Rock_Stone_Mossy"
    },
    {
      "x": -37,
      "y": 173,
      "z": 16,
      "name": "Rock_Stone_Mossy"
    },
    {
      "x": -37,
      "y": 174,
      "z": 17,
      "name": "Rock_Stone_Mossy"
    },
    {
      "x": -37,
      "y": 175,
      "z": 19,
      "name": "Rock_Stone_Mossy"
    },
    {
      "x": -37,
      "y": 174,
      "z": 20,
      "name": "Rock_Stone_Mossy"
    },
    {
      "x": -36,
      "y": 179,
      "z": -30,
      "name": "Rock_Stone_Mossy"
    },
    {
      "x": -36,
      "y": 178,
      "z": -29,
      "name": "Rock_Stone_Mossy"
    },
    {
      "x": -36,
      "y": 178,
      "z": -28,
      "name": "Rock_Stone_Mossy"
    },
    {
      "x": -36,
      "y": 180,
      "z": -28,
      "name": "Rock_Stone_Mossy"
    },
    {
      "x": -36,
      "y": 177,
      "z": -27,
      "name": "Rock_Stone_Mossy"
    },
    {
      "x": -36,
      "y": 177,
      "z": -26,
      "name": "Rock_Stone_Mossy"
    },
    {
      "x": -36,
      "y": 181,
      "z": -26,
      "name": "Rock_Stone_Mossy"
    },
    {
      "x": -36,
      "y": 176,
      "z": -25,
      "name": "Rock_Stone_Mossy"
    },
    {
      "x": -36,
      "y": 180,
      "z": -25,
      "name": "Rock_Stone_Mossy"
    },
    {
      "x": -36,
      "y": 181,
      "z": -21,
      "name": "Rock_Stone_Mossy"
    },
    {
      "x": -36,
      "y": 181,
      "z": -20,
      "name": "Rock_Stone_Mossy"
    },
    {
      "x": -36,
      "y": 179,
      "z": -18,
      "name": "Rock_Stone_Mossy"
    },
    {
      "x": -36,
      "y": 181,
      "z": -18,
      "name": "Rock_Stone_Mossy"
    },
    {
      "x": -36,
      "y": 174,
      "z": -17,
      "name": "Rock_Stone_Mossy"
    },
    {
      "x": -36,
      "y": 183,
      "z": -17,
      "name": "Rock_Stone_Mossy"
    },
    {
      "x": -36,
      "y": 175,
      "z": -16,
      "name": "Rock_Stone_Mossy"
    },
    {
      "x": -36,
      "y": 176,
      "z": -16,
      "name": "Rock_Stone_Mossy"
    },
    {
      "x": -36,
      "y": 180,
      "z": -16,
      "name": "Rock_Stone_Mossy"
    },
    {
      "x": -36,
      "y": 175,
      "z": -15,
      "name": "Rock_Stone_Mossy"
    },
    {
      "x": -36,
      "y": 178,
      "z": -15,
      "name": "Rock_Stone_Mossy"
    },
    {
      "x": -36,
      "y": 182,
      "z": -14,
      "name": "Rock_Stone_Mossy"
    },
    {
      "x": -36,
      "y": 172,
      "z": -13,
      "name": "Rock_Stone_Mossy"
    },
    {
      "x": -36,
      "y": 173,
      "z": -13,
      "name": "Rock_Stone_Mossy"
    },
    {
      "x": -36,
      "y": 175,
      "z": -13,
      "name": "Rock_Stone_Mossy"
    },
    {
      "x": -36,
      "y": 176,
      "z": -13,
      "name": "Rock_Stone_Mossy"
    },
    {
      "x": -36,
      "y": 177,
      "z": -13,
      "name": "Rock_Stone_Mossy"
    },
    {
      "x": -36,
      "y": 178,
      "z": -13,
      "name": "Rock_Stone_Mossy"
    },
    {
      "x": -36,
      "y": 177,
      "z": -12,
      "name": "Rock_Stone_Mossy"
    },
    {
      "x": -36,
      "y": 171,
      "z": -11,
      "name": "Rock_Stone_Mossy"
    },
    {
      "x": -36,
      "y": 172,
      "z": -11,
      "name": "Rock_Stone_Mossy"
    },
    {
      "x": -36,
      "y": 176,
      "z": -11,
      "name": "Rock_Stone_Mossy"
    },
    {
      "x": -36,
      "y": 177,
      "z": -11,
      "name": "Rock_Stone_Mossy"
    },
    {
      "x": -36,
      "y": 172,
      "z": -9,
      "name": "Rock_Stone_Mossy"
    },
    {
      "x": -36,
      "y": 173,
      "z": -9,
      "name": "Rock_Stone_Mossy"
    },
    {
      "x": -36,
      "y": 177,
      "z": -9,
      "name": "Rock_Stone_Mossy"
    },
    {
      "x": -36,
      "y": 182,
      "z": -9,
      "name": "Rock_Stone_Mossy"
    },
    {
      "x": -36,
      "y": 170,
      "z": -7,
      "name": "Rock_Stone_Mossy"
    },
    {
      "x": -36,
      "y": 171,
      "z": -7,
      "name": "Rock_Stone_Mossy"
    },
    {
      "x": -36,
      "y": 174,
      "z": -7,
      "name": "Rock_Stone_Mossy"
    },
    {
      "x": -36,
      "y": 175,
      "z": -7,
      "name": "Rock_Stone_Mossy"
    },
    {
      "x": -36,
      "y": 177,
      "z": -7,
      "name": "Rock_Stone_Mossy"
    },
    {
      "x": -36,
      "y": 178,
      "z": -7,
      "name": "Rock_Stone_Mossy"
    },
    {
      "x": -36,
      "y": 170,
      "z": -6,
      "name": "Rock_Stone_Mossy"
    },
    {
      "x": -36,
      "y": 173,
      "z": -6,
      "name": "Rock_Stone_Mossy"
    },
    {
      "x": -36,
      "y": 175,
      "z": -6,
      "name": "Rock_Stone_Mossy"
    },
    {
      "x": -36,
      "y": 177,
      "z": -6,
      "name": "Rock_Stone_Mossy"
    },
    {
      "x": -36,
      "y": 174,
      "z": -5,
      "name": "Rock_Stone_Mossy"
    },
    {
      "x": -36,
      "y": 175,
      "z": -5,
      "name": "Rock_Stone_Mossy"
    },
    {
      "x": -36,
      "y": 176,
      "z": -5,
      "name": "Rock_Stone_Mossy"
    },
    {
      "x": -36,
      "y": 170,
      "z": -4,
      "name": "Rock_Stone_Mossy"
    },
    {
      "x": -36,
      "y": 172,
      "z": -4,
      "name": "Rock_Stone_Mossy"
    },
    {
      "x": -36,
      "y": 180,
      "z": -4,
      "name": "Rock_Stone_Mossy"
    },
    {
      "x": -36,
      "y": 171,
      "z": -3,
      "name": "Rock_Stone_Mossy"
    },
    {
      "x": -36,
      "y": 172,
      "z": -3,
      "name": "Rock_Stone_Mossy"
    },
    {
      "x": -36,
      "y": 174,
      "z": -3,
      "name": "Rock_Stone_Mossy"
    },
    {
      "x": -36,
      "y": 175,
      "z": -3,
      "name": "Rock_Stone_Mossy"
    },
    {
      "x": -36,
      "y": 179,
      "z": -3,
      "name": "Rock_Stone_Mossy"
    },
    {
      "x": -36,
      "y": 173,
      "z": -2,
      "name": "Rock_Stone_Mossy"
    },
    {
      "x": -36,
      "y": 174,
      "z": -2,
      "name": "Rock_Stone_Mossy"
    },
    {
      "x": -36,
      "y": 176,
      "z": -2,
      "name": "Rock_Stone_Mossy"
    },
    {
      "x": -36,
      "y": 178,
      "z": -2,
      "name": "Rock_Stone_Mossy"
    },
    {
      "x": -36,
      "y": 170,
      "z": -1,
      "name": "Rock_Stone_Mossy"
    },
    {
      "x": -36,
      "y": 173,
      "z": -1,
      "name": "Rock_Stone_Mossy"
    },
    {
      "x": -36,
      "y": 173,
      "z": 0,
      "name": "Rock_Stone_Mossy"
    },
    {
      "x": -36,
      "y": 174,
      "z": 0,
      "name": "Rock_Stone_Mossy"
    },
    {
      "x": -36,
      "y": 176,
      "z": 0,
      "name": "Rock_Stone_Mossy"
    },
    {
      "x": -36,
      "y": 177,
      "z": 0,
      "name": "Rock_Stone_Mossy"
    },
    {
      "x": -36,
      "y": 170,
      "z": 1,
      "name": "Rock_Stone_Mossy"
    },
    {
      "x": -36,
      "y": 173,
      "z": 1,
      "name": "Rock_Stone_Mossy"
    },
    {
      "x": -36,
      "y": 174,
      "z": 1,
      "name": "Rock_Stone_Mossy"
    },
    {
      "x": -36,
      "y": 172,
      "z": 2,
      "name": "Rock_Stone_Mossy"
    },
    {
      "x": -36,
      "y": 174,
      "z": 2,
      "name": "Rock_Stone_Mossy"
    },
    {
      "x": -36,
      "y": 175,
      "z": 2,
      "name": "Rock_Stone_Mossy"
    },
    {
      "x": -36,
      "y": 178,
      "z": 2,
      "name": "Rock_Stone_Mossy"
    },
    {
      "x": -36,
      "y": 171,
      "z": 3,
      "name": "Rock_Stone_Mossy"
    },
    {
      "x": -36,
      "y": 175,
      "z": 3,
      "name": "Rock_Stone_Mossy"
    },
    {
      "x": -36,
      "y": 176,
      "z": 3,
      "name": "Rock_Stone_Mossy"
    },
    {
      "x": -36,
      "y": 177,
      "z": 3,
      "name": "Rock_Stone_Mossy"
    },
    {
      "x": -36,
      "y": 171,
      "z": 4,
      "name": "Rock_Stone_Mossy"
    },
    {
      "x": -36,
      "y": 173,
      "z": 4,
      "name": "Rock_Stone_Mossy"
    },
    {
      "x": -36,
      "y": 174,
      "z": 4,
      "name": "Rock_Stone_Mossy"
    },
    {
      "x": -36,
      "y": 175,
      "z": 4,
      "name": "Rock_Stone_Mossy"
    },
    {
      "x": -36,
      "y": 177,
      "z": 4,
      "name": "Rock_Stone_Mossy"
    },
    {
      "x": -36,
      "y": 171,
      "z": 5,
      "name": "Rock_Stone_Mossy"
    },
    {
      "x": -36,
      "y": 172,
      "z": 5,
      "name": "Rock_Stone_Mossy"
    },
    {
      "x": -36,
      "y": 173,
      "z": 5,
      "name": "Rock_Stone_Mossy"
    },
    {
      "x": -36,
      "y": 176,
      "z": 5,
      "name": "Rock_Stone_Mossy"
    },
    {
      "x": -36,
      "y": 175,
      "z": 6,
      "name": "Rock_Stone_Mossy"
    },
    {
      "x": -36,
      "y": 176,
      "z": 6,
      "name": "Rock_Stone_Mossy"
    },
    {
      "x": -36,
      "y": 172,
      "z": 7,
      "name": "Rock_Stone_Mossy"
    },
    {
      "x": -36,
      "y": 174,
      "z": 7,
      "name": "Rock_Stone_Mossy"
    },
    {
      "x": -36,
      "y": 175,
      "z": 7,
      "name": "Rock_Stone_Mossy"
    },
    {
      "x": -36,
      "y": 176,
      "z": 7,
      "name": "Rock_Stone_Mossy"
    },
    {
      "x": -36,
      "y": 174,
      "z": 8,
      "name": "Rock_Stone_Mossy"
    },
    {
      "x": -36,
      "y": 172,
      "z": 9,
      "name": "Rock_Stone_Mossy"
    },
    {
      "x": -36,
      "y": 173,
      "z": 9,
      "name": "Rock_Stone_Mossy"
    },
    {
      "x": -36,
      "y": 173,
      "z": 10,
      "name": "Rock_Stone_Mossy"
    },
    {
      "x": -36,
      "y": 174,
      "z": 10,
      "name": "Rock_Stone_Mossy"
    },
    {
      "x": -36,
      "y": 175,
      "z": 10,
      "name": "Rock_Stone_Mossy"
    },
    {
      "x": -36,
      "y": 172,
      "z": 12,
      "name": "Rock_Stone_Mossy"
    },
    {
      "x": -36,
      "y": 175,
      "z": 13,
      "name": "Rock_Stone_Mossy"
    },
    {
      "x": -36,
      "y": 176,
      "z": 13,
      "name": "Rock_Stone_Mossy"
    },
    {
      "x": -36,
      "y": 171,
      "z": 14,
      "name": "Rock_Stone_Mossy"
    },
    {
      "x": -36,
      "y": 175,
      "z": 15,
      "name": "Rock_Stone_Mossy"
    },
    {
      "x": -36,
      "y": 175,
      "z": 17,
      "name": "Rock_Stone_Mossy"
    },
    {
      "x": -36,
      "y": 175,
      "z": 18,
      "name": "Rock_Stone_Mossy"
    },
    {
      "x": -36,
      "y": 173,
      "z": 19,
      "name": "Rock_Stone_Mossy"
    },
    {
      "x": -36,
      "y": 175,
      "z": 21,
      "name": "Rock_Stone_Mossy"
    },
    {
      "x": -35,
      "y": 178,
      "z": -30,
      "name": "Rock_Stone_Mossy"
    },
    {
      "x": -35,
      "y": 179,
      "z": -30,
      "name": "Rock_Stone_Mossy"
    },
    {
      "x": -35,
      "y": 180,
      "z": -30,
      "name": "Rock_Stone_Mossy"
    },
    {
      "x": -35,
      "y": 181,
      "z": -29,
      "name": "Rock_Stone_Mossy"
    },
    {
      "x": -35,
      "y": 178,
      "z": -26,
      "name": "Rock_Stone_Mossy"
    },
    {
      "x": -35,
      "y": 177,
      "z": -25,
      "name": "Rock_Stone_Mossy"
    },
    {
      "x": -35,
      "y": 180,
      "z": -23,
      "name": "Rock_Stone_Mossy"
    },
    {
      "x": -35,
      "y": 181,
      "z": -21,
      "name": "Rock_Stone_Mossy"
    },
    {
      "x": -35,
      "y": 176,
      "z": -20,
      "name": "Rock_Stone_Mossy"
    },
    {
      "x": -35,
      "y": 182,
      "z": -20,
      "name": "Rock_Stone_Mossy"
    },
    {
      "x": -35,
      "y": 181,
      "z": -19,
      "name": "Rock_Stone_Mossy"
    },
    {
      "x": -35,
      "y": 175,
      "z": -18,
      "name": "Rock_Stone_Mossy"
    },
    {
      "x": -35,
      "y": 176,
      "z": -18,
      "name": "Rock_Stone_Mossy"
    },
    {
      "x": -35,
      "y": 183,
      "z": -18,
      "name": "Rock_Stone_Mossy"
    },
    {
      "x": -35,
      "y": 174,
      "z": -17,
      "name": "Rock_Stone_Mossy"
    },
    {
      "x": -35,
      "y": 176,
      "z": -16,
      "name": "Rock_Stone_Mossy"
    },
    {
      "x": -35,
      "y": 181,
      "z": -16,
      "name": "Rock_Stone_Mossy"
    },
    {
      "x": -35,
      "y": 172,
      "z": -15,
      "name": "Rock_Stone_Mossy"
    },
    {
      "x": -35,
      "y": 174,
      "z": -15,
      "name": "Rock_Stone_Mossy"
    },
    {
      "x": -35,
      "y": 172,
      "z": -14,
      "name": "Rock_Stone_Mossy"
    },
    {
      "x": -35,
      "y": 176,
      "z": -14,
      "name": "Rock_Stone_Mossy"
    },
    {
      "x": -35,
      "y": 177,
      "z": -14,
      "name": "Rock_Stone_Mossy"
    },
    {
      "x": -35,
      "y": 182,
      "z": -14,
      "name": "Rock_Stone_Mossy"
    },
    {
      "x": -35,
      "y": 173,
      "z": -13,
      "name": "Rock_Stone_Mossy"
    },
    {
      "x": -35,
      "y": 176,
      "z": -13,
      "name": "Rock_Stone_Mossy"
    },
    {
      "x": -35,
      "y": 177,
      "z": -13,
      "name": "Rock_Stone_Mossy"
    },
    {
      "x": -35,
      "y": 176,
      "z": -12,
      "name": "Rock_Stone_Mossy"
    },
    {
      "x": -35,
      "y": 177,
      "z": -12,
      "name": "Rock_Stone_Mossy"
    },
    {
      "x": -35,
      "y": 175,
      "z": -11,
      "name": "Rock_Stone_Mossy"
    },
    {
      "x": -35,
      "y": 173,
      "z": -10,
      "name": "Rock_Stone_Mossy"
    },
    {
      "x": -35,
      "y": 176,
      "z": -10,
      "name": "Rock_Stone_Mossy"
    },
    {
      "x": -35,
      "y": 174,
      "z": -9,
      "name": "Rock_Stone_Mossy"
    },
    {
      "x": -35,
      "y": 175,
      "z": -9,
      "name": "Rock_Stone_Mossy"
    },
    {
      "x": -35,
      "y": 176,
      "z": -9,
      "name": "Rock_Stone_Mossy"
    },
    {
      "x": -35,
      "y": 171,
      "z": -8,
      "name": "Rock_Stone_Mossy"
    },
    {
      "x": -35,
      "y": 174,
      "z": -8,
      "name": "Rock_Stone_Mossy"
    },
    {
      "x": -35,
      "y": 170,
      "z": -7,
      "name": "Rock_Stone_Mossy"
    },
    {
      "x": -35,
      "y": 172,
      "z": -7,
      "name": "Rock_Stone_Mossy"
    },
    {
      "x": -35,
      "y": 176,
      "z": -7,
      "name": "Rock_Stone_Mossy"
    },
    {
      "x": -35,
      "y": 177,
      "z": -7,
      "name": "Rock_Stone_Mossy"
    },
    {
      "x": -35,
      "y": 172,
      "z": -6,
      "name": "Rock_Stone_Mossy"
    },
    {
      "x": -35,
      "y": 173,
      "z": -6,
      "name": "Rock_Stone_Mossy"
    },
    {
      "x": -35,
      "y": 172,
      "z": -5,
      "name": "Rock_Stone_Mossy"
    },
    {
      "x": -35,
      "y": 175,
      "z": -5,
      "name": "Rock_Stone_Mossy"
    },
    {
      "x": -35,
      "y": 177,
      "z": -5,
      "name": "Rock_Stone_Mossy"
    },
    {
      "x": -35,
      "y": 170,
      "z": -4,
      "name": "Rock_Stone_Mossy"
    },
    {
      "x": -35,
      "y": 173,
      "z": -4,
      "name": "Rock_Stone_Mossy"
    },
    {
      "x": -35,
      "y": 176,
      "z": -4,
      "name": "Rock_Stone_Mossy"
    },
    {
      "x": -35,
      "y": 175,
      "z": -3,
      "name": "Rock_Stone_Mossy"
    },
    {
      "x": -35,
      "y": 176,
      "z": -3,
      "name": "Rock_Stone_Mossy"
    },
    {
      "x": -35,
      "y": 177,
      "z": -3,
      "name": "Rock_Stone_Mossy"
    },
    {
      "x": -35,
      "y": 180,
      "z": -3,
      "name": "Rock_Stone_Mossy"
    },
    {
      "x": -35,
      "y": 171,
      "z": -2,
      "name": "Rock_Stone_Mossy"
    },
    {
      "x": -35,
      "y": 172,
      "z": -2,
      "name": "Rock_Stone_Mossy"
    },
    {
      "x": -35,
      "y": 175,
      "z": -2,
      "name": "Rock_Stone_Mossy"
    },
    {
      "x": -35,
      "y": 178,
      "z": -2,
      "name": "Rock_Stone_Mossy"
    },
    {
      "x": -35,
      "y": 171,
      "z": -1,
      "name": "Rock_Stone_Mossy"
    },
    {
      "x": -35,
      "y": 172,
      "z": -1,
      "name": "Rock_Stone_Mossy"
    },
    {
      "x": -35,
      "y": 174,
      "z": -1,
      "name": "Rock_Stone_Mossy"
    },
    {
      "x": -35,
      "y": 175,
      "z": -1,
      "name": "Rock_Stone_Mossy"
    },
    {
      "x": -35,
      "y": 170,
      "z": 0,
      "name": "Rock_Stone_Mossy"
    },
    {
      "x": -35,
      "y": 173,
      "z": 0,
      "name": "Rock_Stone_Mossy"
    },
    {
      "x": -35,
      "y": 174,
      "z": 0,
      "name": "Rock_Stone_Mossy"
    },
    {
      "x": -35,
      "y": 170,
      "z": 1,
      "name": "Rock_Stone_Mossy"
    },
    {
      "x": -35,
      "y": 173,
      "z": 1,
      "name": "Rock_Stone_Mossy"
    },
    {
      "x": -35,
      "y": 177,
      "z": 1,
      "name": "Rock_Stone_Mossy"
    },
    {
      "x": -35,
      "y": 171,
      "z": 2,
      "name": "Rock_Stone_Mossy"
    },
    {
      "x": -35,
      "y": 173,
      "z": 2,
      "name": "Rock_Stone_Mossy"
    },
    {
      "x": -35,
      "y": 175,
      "z": 2,
      "name": "Rock_Stone_Mossy"
    },
    {
      "x": -35,
      "y": 177,
      "z": 2,
      "name": "Rock_Stone_Mossy"
    },
    {
      "x": -35,
      "y": 178,
      "z": 2,
      "name": "Rock_Stone_Mossy"
    },
    {
      "x": -35,
      "y": 172,
      "z": 3,
      "name": "Rock_Stone_Mossy"
    },
    {
      "x": -35,
      "y": 173,
      "z": 3,
      "name": "Rock_Stone_Mossy"
    },
    {
      "x": -35,
      "y": 171,
      "z": 4,
      "name": "Rock_Stone_Mossy"
    },
    {
      "x": -35,
      "y": 172,
      "z": 4,
      "name": "Rock_Stone_Mossy"
    },
    {
      "x": -35,
      "y": 175,
      "z": 4,
      "name": "Rock_Stone_Mossy"
    },
    {
      "x": -35,
      "y": 176,
      "z": 4,
      "name": "Rock_Stone_Mossy"
    },
    {
      "x": -35,
      "y": 177,
      "z": 4,
      "name": "Rock_Stone_Mossy"
    },
    {
      "x": -35,
      "y": 172,
      "z": 5,
      "name": "Rock_Stone_Mossy"
    },
    {
      "x": -35,
      "y": 175,
      "z": 5,
      "name": "Rock_Stone_Mossy"
    },
    {
      "x": -35,
      "y": 176,
      "z": 5,
      "name": "Rock_Stone_Mossy"
    },
    {
      "x": -35,
      "y": 172,
      "z": 6,
      "name": "Rock_Stone_Mossy"
    },
    {
      "x": -35,
      "y": 174,
      "z": 6,
      "name": "Rock_Stone_Mossy"
    },
    {
      "x": -35,
      "y": 176,
      "z": 6,
      "name": "Rock_Stone_Mossy"
    },
    {
      "x": -35,
      "y": 172,
      "z": 7,
      "name": "Rock_Stone_Mossy"
    },
    {
      "x": -35,
      "y": 173,
      "z": 7,
      "name": "Rock_Stone_Mossy"
    },
    {
      "x": -35,
      "y": 175,
      "z": 7,
      "name": "Rock_Stone_Mossy"
    },
    {
      "x": -35,
      "y": 176,
      "z": 7,
      "name": "Rock_Stone_Mossy"
    },
    {
      "x": -35,
      "y": 177,
      "z": 7,
      "name": "Rock_Stone_Mossy"
    },
    {
      "x": -35,
      "y": 173,
      "z": 8,
      "name": "Rock_Stone_Mossy"
    },
    {
      "x": -35,
      "y": 176,
      "z": 8,
      "name": "Rock_Stone_Mossy"
    },
    {
      "x": -35,
      "y": 174,
      "z": 9,
      "name": "Rock_Stone_Mossy"
    },
    {
      "x": -35,
      "y": 177,
      "z": 9,
      "name": "Rock_Stone_Mossy"
    },
    {
      "x": -35,
      "y": 173,
      "z": 10,
      "name": "Rock_Stone_Mossy"
    },
    {
      "x": -35,
      "y": 175,
      "z": 10,
      "name": "Rock_Stone_Mossy"
    },
    {
      "x": -35,
      "y": 177,
      "z": 10,
      "name": "Rock_Stone_Mossy"
    },
    {
      "x": -35,
      "y": 175,
      "z": 11,
      "name": "Rock_Stone_Mossy"
    },
    {
      "x": -35,
      "y": 173,
      "z": 12,
      "name": "Rock_Stone_Mossy"
    },
    {
      "x": -35,
      "y": 174,
      "z": 12,
      "name": "Rock_Stone_Mossy"
    },
    {
      "x": -35,
      "y": 174,
      "z": 13,
      "name": "Rock_Stone_Mossy"
    },
    {
      "x": -35,
      "y": 177,
      "z": 13,
      "name": "Rock_Stone_Mossy"
    },
    {
      "x": -35,
      "y": 173,
      "z": 15,
      "name": "Rock_Stone_Mossy"
    },
    {
      "x": -35,
      "y": 174,
      "z": 15,
      "name": "Rock_Stone_Mossy"
    },
    {
      "x": -35,
      "y": 176,
      "z": 16,
      "name": "Rock_Stone_Mossy"
    },
    {
      "x": -35,
      "y": 173,
      "z": 17,
      "name": "Rock_Stone_Mossy"
    },
    {
      "x": -35,
      "y": 175,
      "z": 17,
      "name": "Rock_Stone_Mossy"
    },
    {
      "x": -35,
      "y": 176,
      "z": 20,
      "name": "Rock_Stone_Mossy"
    },
    {
      "x": -35,
      "y": 173,
      "z": 21,
      "name": "Rock_Stone_Mossy"
    },
    {
      "x": -35,
      "y": 175,
      "z": 21,
      "name": "Rock_Stone_Mossy"
    },
    {
      "x": -34,
      "y": 178,
      "z": -30,
      "name": "Rock_Stone_Mossy"
    },
    {
      "x": -34,
      "y": 180,
      "z": -30,
      "name": "Rock_Stone_Mossy"
    },
    {
      "x": -34,
      "y": 180,
      "z": -29,
      "name": "Rock_Stone_Mossy"
    },
    {
      "x": -34,
      "y": 178,
      "z": -28,
      "name": "Rock_Stone_Mossy"
    },
    {
      "x": -34,
      "y": 176,
      "z": -26,
      "name": "Rock_Stone_Mossy"
    },
    {
      "x": -34,
      "y": 176,
      "z": -25,
      "name": "Rock_Stone_Mossy"
    },
    {
      "x": -34,
      "y": 177,
      "z": -24,
      "name": "Rock_Stone_Mossy"
    },
    {
      "x": -34,
      "y": 182,
      "z": -24,
      "name": "Rock_Stone_Mossy"
    },
    {
      "x": -34,
      "y": 176,
      "z": -23,
      "name": "Rock_Stone_Mossy"
    },
    {
      "x": -34,
      "y": 177,
      "z": -23,
      "name": "Rock_Stone_Mossy"
    },
    {
      "x": -34,
      "y": 177,
      "z": -22,
      "name": "Rock_Stone_Mossy"
    },
    {
      "x": -34,
      "y": 179,
      "z": -22,
      "name": "Rock_Stone_Mossy"
    },
    {
      "x": -34,
      "y": 180,
      "z": -22,
      "name": "Rock_Stone_Mossy"
    },
    {
      "x": -34,
      "y": 182,
      "z": -22,
      "name": "Rock_Stone_Mossy"
    },
    {
      "x": -34,
      "y": 177,
      "z": -21,
      "name": "Rock_Stone_Mossy"
    },
    {
      "x": -34,
      "y": 178,
      "z": -21,
      "name": "Rock_Stone_Mossy"
    },
    {
      "x": -34,
      "y": 181,
      "z": -21,
      "name": "Rock_Stone_Mossy"
    },
    {
      "x": -34,
      "y": -2,
      "z": -20,
      "name": "Wood_Giantwood_Trunk_Full"
    },
    {
      "x": -34,
      "y": -1,
      "z": -20,
      "name": "Wood_Giantwood_Trunk_Full"
    },
    {
      "x": -34,
      "y": 0,
      "z": -20,
      "name": "Wood_Giantwood_Trunk_Full"
    },
    {
      "x": -34,
      "y": -3,
      "z": -19,
      "name": "Wood_Giantwood_Trunk_Full"
    },
    {
      "x": -34,
      "y": -2,
      "z": -19,
      "name": "Wood_Giantwood_Trunk_Full"
    },
    {
      "x": -34,
      "y": -1,
      "z": -19,
      "name": "Wood_Giantwood_Trunk_Full"
    },
    {
      "x": -34,
      "y": 0,
      "z": -19,
      "name": "Wood_Giantwood_Trunk_Full"
    },
    {
      "x": -34,
      "y": 1,
      "z": -19,
      "name": "Wood_Giantwood_Trunk_Full",
      "support": 2
    },
    {
      "x": -34,
      "y": -3,
      "z": -18,
      "name": "Wood_Giantwood_Trunk_Full"
    },
    {
      "x": -34,
      "y": -2,
      "z": -18,
      "name": "Wood_Giantwood_Trunk_Full"
    },
    {
      "x": -34,
      "y": -1,
      "z": -18,
      "name": "Wood_Giantwood_Trunk_Full"
    },
    {
      "x": -34,
      "y": 0,
      "z": -18,
      "name": "Wood_Giantwood_Trunk_Full"
    },
    {
      "x": -34,
      "y": 1,
      "z": -18,
      "name": "Wood_Giantwood_Trunk_Full",
      "support": 1
    },
    {
      "x": -34,
      "y": -1,
      "z": -17,
      "name": "Wood_Giantwood_Trunk_Full"
    },
    {
      "x": -34,
      "y": 0,
      "z": -17,
      "name": "Wood_Giantwood_Trunk_Full"
    },
    {
      "x": -34,
      "y": 173,
      "z": -17,
      "name": "Rock_Stone_Mossy"
    },
    {
      "x": -34,
      "y": 175,
      "z": -17,
      "name": "Rock_Stone_Mossy"
    },
    {
      "x": -34,
      "y": 177,
      "z": -17,
      "name": "Rock_Stone_Mossy"
    },
    {
      "x": -34,
      "y": 172,
      "z": -16,
      "name": "Rock_Stone_Mossy"
    },
    {
      "x": -34,
      "y": 175,
      "z": -16,
      "name": "Rock_Stone_Mossy"
    },
    {
      "x": -34,
      "y": 173,
      "z": -14,
      "name": "Rock_Stone_Mossy"
    },
    {
      "x": -34,
      "y": 178,
      "z": -14,
      "name": "Rock_Stone_Mossy"
    },
    {
      "x": -34,
      "y": 183,
      "z": -14,
      "name": "Rock_Stone_Mossy"
    },
    {
      "x": -34,
      "y": 173,
      "z": -13,
      "name": "Rock_Stone_Mossy"
    },
    {
      "x": -34,
      "y": 174,
      "z": -13,
      "name": "Rock_Stone_Mossy"
    },
    {
      "x": -34,
      "y": 175,
      "z": -13,
      "name": "Rock_Stone_Mossy"
    },
    {
      "x": -34,
      "y": 176,
      "z": -13,
      "name": "Rock_Stone_Mossy"
    },
    {
      "x": -34,
      "y": 175,
      "z": -12,
      "name": "Rock_Stone_Mossy"
    },
    {
      "x": -34,
      "y": 176,
      "z": -12,
      "name": "Rock_Stone_Mossy"
    },
    {
      "x": -34,
      "y": 177,
      "z": -12,
      "name": "Rock_Stone_Mossy"
    },
    {
      "x": -34,
      "y": 178,
      "z": -12,
      "name": "Rock_Stone_Mossy"
    },
    {
      "x": -34,
      "y": 182,
      "z": -12,
      "name": "Rock_Stone_Mossy"
    },
    {
      "x": -34,
      "y": 172,
      "z": -11,
      "name": "Rock_Stone_Mossy"
    },
    {
      "x": -34,
      "y": 173,
      "z": -11,
      "name": "Rock_Stone_Mossy"
    },
    {
      "x": -34,
      "y": 174,
      "z": -11,
      "name": "Rock_Stone_Mossy"
    },
    {
      "x": -34,
      "y": 175,
      "z": -11,
      "name": "Rock_Stone_Mossy"
    },
    {
      "x": -34,
      "y": 180,
      "z": -11,
      "name": "Rock_Stone_Mossy"
    },
    {
      "x": -34,
      "y": 182,
      "z": -11,
      "name": "Rock_Stone_Mossy"
    },
    {
      "x": -34,
      "y": 172,
      "z": -10,
      "name": "Rock_Stone_Mossy"
    },
    {
      "x": -34,
      "y": 174,
      "z": -10,
      "name": "Rock_Stone_Mossy"
    },
    {
      "x": -34,
      "y": 176,
      "z": -10,
      "name": "Rock_Stone_Mossy"
    },
    {
      "x": -34,
      "y": 175,
      "z": -9,
      "name": "Rock_Stone_Mossy"
    },
    {
      "x": -34,
      "y": 170,
      "z": -8,
      "name": "Rock_Stone_Mossy"
    },
    {
      "x": -34,
      "y": 172,
      "z": -8,
      "name": "Rock_Stone_Mossy"
    },
    {
      "x": -34,
      "y": 174,
      "z": -8,
      "name": "Rock_Stone_Mossy"
    },
    {
      "x": -34,
      "y": 177,
      "z": -8,
      "name": "Rock_Stone_Mossy"
    },
    {
      "x": -34,
      "y": 178,
      "z": -8,
      "name": "Rock_Stone_Mossy"
    },
    {
      "x": -34,
      "y": 173,
      "z": -7,
      "name": "Rock_Stone_Mossy"
    },
    {
      "x": -34,
      "y": 176,
      "z": -7,
      "name": "Rock_Stone_Mossy"
    },
    {
      "x": -34,
      "y": 178,
      "z": -7,
      "name": "Rock_Stone_Mossy"
    },
    {
      "x": -34,
      "y": 171,
      "z": -6,
      "name": "Rock_Stone_Mossy"
    },
    {
      "x": -34,
      "y": 177,
      "z": -6,
      "name": "Rock_Stone_Mossy"
    },
    {
      "x": -34,
      "y": 180,
      "z": -6,
      "name": "Rock_Stone_Mossy"
    },
    {
      "x": -34,
      "y": 181,
      "z": -6,
      "name": "Rock_Stone_Mossy"
    },
    {
      "x": -34,
      "y": 170,
      "z": -5,
      "name": "Rock_Stone_Mossy"
    },
    {
      "x": -34,
      "y": 173,
      "z": -5,
      "name": "Rock_Stone_Mossy"
    },
    {
      "x": -34,
      "y": 174,
      "z": -5,
      "name": "Rock_Stone_Mossy"
    },
    {
      "x": -34,
      "y": 175,
      "z": -5,
      "name": "Rock_Stone_Mossy"
    },
    {
      "x": -34,
      "y": 178,
      "z": -5,
      "name": "Rock_Stone_Mossy"
    },
    {
      "x": -34,
      "y": 174,
      "z": -4,
      "name": "Rock_Stone_Mossy"
    },
    {
      "x": -34,
      "y": 175,
      "z": -4,
      "name": "Rock_Stone_Mossy"
    },
    {
      "x": -34,
      "y": 176,
      "z": -4,
      "name": "Rock_Stone_Mossy"
    },
    {
      "x": -34,
      "y": 180,
      "z": -4,
      "name": "Rock_Stone_Mossy"
    },
    {
      "x": -34,
      "y": 171,
      "z": -3,
      "name": "Rock_Stone_Mossy"
    },
    {
      "x": -34,
      "y": 173,
      "z": -3,
      "name": "Rock_Stone_Mossy"
    },
    {
      "x": -34,
      "y": 176,
      "z": -3,
      "name": "Rock_Stone_Mossy"
    },
    {
      "x": -34,
      "y": 179,
      "z": -3,
      "name": "Rock_Stone_Mossy"
    },
    {
      "x": -34,
      "y": 175,
      "z": -2,
      "name": "Rock_Stone_Mossy"
    },
    {
      "x": -34,
      "y": 172,
      "z": -1,
      "name": "Rock_Stone_Mossy"
    },
    {
      "x": -34,
      "y": 174,
      "z": -1,
      "name": "Rock_Stone_Mossy"
    },
    {
      "x": -34,
      "y": 175,
      "z": -1,
      "name": "Rock_Stone_Mossy"
    },
    {
      "x": -34,
      "y": 176,
      "z": -1,
      "name": "Rock_Stone_Mossy"
    },
    {
      "x": -34,
      "y": 178,
      "z": 0,
      "name": "Rock_Stone_Mossy"
    },
    {
      "x": -34,
      "y": 173,
      "z": 1,
      "name": "Rock_Stone_Mossy"
    },
    {
      "x": -34,
      "y": 177,
      "z": 1,
      "name": "Rock_Stone_Mossy"
    },
    {
      "x": -34,
      "y": 171,
      "z": 2,
      "name": "Rock_Stone_Mossy"
    },
    {
      "x": -34,
      "y": 172,
      "z": 2,
      "name": "Rock_Stone_Mossy"
    },
    {
      "x": -34,
      "y": 173,
      "z": 2,
      "name": "Rock_Stone_Mossy"
    },
    {
      "x": -34,
      "y": 175,
      "z": 2,
      "name": "Rock_Stone_Mossy"
    },
    {
      "x": -34,
      "y": 176,
      "z": 2,
      "name": "Rock_Stone_Mossy"
    },
    {
      "x": -34,
      "y": 174,
      "z": 3,
      "name": "Rock_Stone_Mossy"
    },
    {
      "x": -34,
      "y": 175,
      "z": 3,
      "name": "Rock_Stone_Mossy"
    },
    {
      "x": -34,
      "y": 176,
      "z": 3,
      "name": "Rock_Stone_Mossy"
    },
    {
      "x": -34,
      "y": 177,
      "z": 3,
      "name": "Rock_Stone_Mossy"
    },
    {
      "x": -34,
      "y": 172,
      "z": 4,
      "name": "Rock_Stone_Mossy"
    },
    {
      "x": -34,
      "y": 177,
      "z": 4,
      "name": "Rock_Stone_Mossy"
    },
    {
      "x": -34,
      "y": 173,
      "z": 5,
      "name": "Rock_Stone_Mossy"
    },
    {
      "x": -34,
      "y": 174,
      "z": 5,
      "name": "Rock_Stone_Mossy"
    },
    {
      "x": -34,
      "y": 176,
      "z": 5,
      "name": "Rock_Stone_Mossy"
    },
    {
      "x": -34,
      "y": 177,
      "z": 5,
      "name": "Rock_Stone_Mossy"
    },
    {
      "x": -34,
      "y": 172,
      "z": 6,
      "name": "Rock_Stone_Mossy"
    },
    {
      "x": -34,
      "y": 175,
      "z": 6,
      "name": "Rock_Stone_Mossy"
    },
    {
      "x": -34,
      "y": 171,
      "z": 7,
      "name": "Rock_Stone_Mossy"
    },
    {
      "x": -34,
      "y": 176,
      "z": 7,
      "name": "Rock_Stone_Mossy"
    },
    {
      "x": -34,
      "y": 173,
      "z": 8,
      "name": "Rock_Stone_Mossy"
    },
    {
      "x": -34,
      "y": 175,
      "z": 8,
      "name": "Rock_Stone_Mossy"
    },
    {
      "x": -34,
      "y": 176,
      "z": 8,
      "name": "Rock_Stone_Mossy"
    },
    {
      "x": -34,
      "y": 177,
      "z": 8,
      "name": "Rock_Stone_Mossy"
    },
    {
      "x": -34,
      "y": 172,
      "z": 9,
      "name": "Rock_Stone_Mossy"
    },
    {
      "x": -34,
      "y": 174,
      "z": 9,
      "name": "Rock_Stone_Mossy"
    },
    {
      "x": -34,
      "y": 176,
      "z": 9,
      "name": "Rock_Stone_Mossy"
    },
    {
      "x": -34,
      "y": 174,
      "z": 10,
      "name": "Rock_Stone_Mossy"
    },
    {
      "x": -34,
      "y": 175,
      "z": 11,
      "name": "Rock_Stone_Mossy"
    },
    {
      "x": -34,
      "y": 177,
      "z": 11,
      "name": "Rock_Stone_Mossy"
    },
    {
      "x": -34,
      "y": 174,
      "z": 12,
      "name": "Rock_Stone_Mossy"
    },
    {
      "x": -34,
      "y": 172,
      "z": 13,
      "name": "Rock_Stone_Mossy"
    },
    {
      "x": -34,
      "y": 172,
      "z": 14,
      "name": "Rock_Stone_Mossy"
    },
    {
      "x": -34,
      "y": 174,
      "z": 14,
      "name": "Rock_Stone_Mossy"
    },
    {
      "x": -34,
      "y": 176,
      "z": 15,
      "name": "Rock_Stone_Mossy"
    },
    {
      "x": -34,
      "y": 177,
      "z": 15,
      "name": "Rock_Stone_Mossy"
    },
    {
      "x": -34,
      "y": 172,
      "z": 16,
      "name": "Rock_Stone_Mossy"
    },
    {
      "x": -34,
      "y": 172,
      "z": 18,
      "name": "Rock_Stone_Mossy"
    },
    {
      "x": -34,
      "y": 172,
      "z": 19,
      "name": "Rock_Stone_Mossy"
    },
    {
      "x": -34,
      "y": 173,
      "z": 20,
      "name": "Rock_Stone_Mossy"
    },
    {
      "x": -34,
      "y": 176,
      "z": 20,
      "name": "Rock_Stone_Mossy"
    },
    {
      "x": -34,
      "y": 175,
      "z": 21,
      "name": "Rock_Stone_Mossy"
    },
    {
      "x": -33,
      "y": 177,
      "z": -30,
      "name": "Rock_Stone_Mossy"
    },
    {
      "x": -33,
      "y": 179,
      "z": -29,
      "name": "Rock_Stone_Mossy"
    },
    {
      "x": -33,
      "y": 177,
      "z": -28,
      "name": "Rock_Stone_Mossy"
    },
    {
      "x": -33,
      "y": 182,
      "z": -27,
      "name": "Rock_Stone_Mossy"
    },
    {
      "x": -33,
      "y": 182,
      "z": -26,
      "name": "Rock_Stone_Mossy"
    },
    {
      "x": -33,
      "y": 176,
      "z": -25,
      "name": "Rock_Stone_Mossy"
    },
    {
      "x": -33,
      "y": 178,
      "z": -25,
      "name": "Rock_Stone_Mossy"
    },
    {
      "x": -33,
      "y": 179,
      "z": -25,
      "name": "Rock_Stone_Mossy"
    },
    {
      "x": -33,
      "y": -2,
      "z": -22,
      "name": "Wood_Giantwood_Trunk_Full"
    },
    {
      "x": -33,
      "y": -1,
      "z": -22,
      "name": "Wood_Giantwood_Trunk"
    },
    {
      "x": -33,
      "y": 0,
      "z": -22,
      "name": "Wood_Giantwood_Trunk_Full"
    },
    {
      "x": -33,
      "y": -3,
      "z": -21,
      "name": "Wood_Giantwood_Trunk_Full"
    },
    {
      "x": -33,
      "y": -2,
      "z": -21,
      "name": "Wood_Giantwood_Trunk_Full"
    },
    {
      "x": -33,
      "y": -1,
      "z": -21,
      "name": "Wood_Giantwood_Trunk_Full"
    },
    {
      "x": -33,
      "y": 0,
      "z": -21,
      "name": "Wood_Giantwood_Trunk",
      "support": 1
    },
    {
      "x": -33,
      "y": 1,
      "z": -21,
      "name": "Wood_Giantwood_Trunk_Full"
    },
    {
      "x": -33,
      "y": 179,
      "z": -21,
      "name": "Rock_Stone_Mossy"
    },
    {
      "x": -33,
      "y": -5,
      "z": -20,
      "name": "Wood_Giantwood_Trunk_Full"
    },
    {
      "x": -33,
      "y": -4,
      "z": -20,
      "name": "Wood_Giantwood_Trunk_Full"
    },
    {
      "x": -33,
      "y": -3,
      "z": -20,
      "name": "Wood_Giantwood_Trunk_Full"
    },
    {
      "x": -33,
      "y": -2,
      "z": -20,
      "name": "Wood_Giantwood_Trunk_Full"
    },
    {
      "x": -33,
      "y": -1,
      "z": -20,
      "name": "Wood_Giantwood_Trunk"
    },
    {
      "x": -33,
      "y": 0,
      "z": -20,
      "name": "Wood_Giantwood_Trunk_Full"
    },
    {
      "x": -33,
      "y": 1,
      "z": -20,
      "name": "Wood_Giantwood_Trunk_Full"
    },
    {
      "x": -33,
      "y": 2,
      "z": -20,
      "name": "Wood_Giantwood_Trunk_Full"
    },
    {
      "x": -33,
      "y": 181,
      "z": -20,
      "name": "Rock_Stone_Mossy"
    },
    {
      "x": -33,
      "y": -4,
      "z": -19,
      "name": "Wood_Giantwood_Trunk_Full"
    },
    {
      "x": -33,
      "y": -3,
      "z": -19,
      "name": "Wood_Giantwood_Trunk_Full"
    },
    {
      "x": -33,
      "y": -2,
      "z": -19,
      "name": "Wood_Giantwood_Trunk"
    },
    {
      "x": -33,
      "y": -1,
      "z": -19,
      "name": "Wood_Giantwood_Trunk"
    },
    {
      "x": -33,
      "y": 0,
      "z": -19,
      "name": "Wood_Giantwood_Trunk"
    },
    {
      "x": -33,
      "y": 1,
      "z": -19,
      "name": "Wood_Giantwood_Trunk_Full"
    },
    {
      "x": -33,
      "y": 2,
      "z": -19,
      "name": "Wood_Giantwood_Trunk_Full"
    },
    {
      "x": -33,
      "y": 3,
      "z": -19,
      "name": "Wood_Giantwood_Trunk_Full"
    },
    {
      "x": -33,
      "y": -5,
      "z": -18,
      "name": "Wood_Giantwood_Trunk_Full"
    },
    {
      "x": -33,
      "y": -4,
      "z": -18,
      "name": "Wood_Giantwood_Trunk_Full"
    },
    {
      "x": -33,
      "y": -3,
      "z": -18,
      "name": "Wood_Giantwood_Trunk_Full"
    },
    {
      "x": -33,
      "y": -2,
      "z": -18,
      "name": "Wood_Giantwood_Trunk_Full"
    },
    {
      "x": -33,
      "y": -1,
      "z": -18,
      "name": "Wood_Giantwood_Trunk_Full"
    },
    {
      "x": -33,
      "y": 0,
      "z": -18,
      "name": "Wood_Giantwood_Trunk"
    },
    {
      "x": -33,
      "y": 1,
      "z": -18,
      "name": "Wood_Giantwood_Trunk_Full"
    },
    {
      "x": -33,
      "y": 2,
      "z": -18,
      "name": "Wood_Giantwood_Trunk_Full"
    },
    {
      "x": -33,
      "y": 3,
      "z": -18,
      "name": "Wood_Giantwood_Trunk_Full"
    },
    {
      "x": -33,
      "y": 174,
      "z": -18,
      "name": "Rock_Stone_Mossy"
    },
    {
      "x": -33,
      "y": 180,
      "z": -18,
      "name": "Rock_Stone_Mossy"
    },
    {
      "x": -33,
      "y": -4,
      "z": -17,
      "name": "Wood_Giantwood_Trunk_Full"
    },
    {
      "x": -33,
      "y": -3,
      "z": -17,
      "name": "Wood_Giantwood_Trunk_Full"
    },
    {
      "x": -33,
      "y": -2,
      "z": -17,
      "name": "Wood_Giantwood_Trunk_Full"
    },
    {
      "x": -33,
      "y": -1,
      "z": -17,
      "name": "Wood_Giantwood_Trunk_Full",
      "support": 3
    },
    {
      "x": -33,
      "y": 0,
      "z": -17,
      "name": "Wood_Giantwood_Trunk"
    },
    {
      "x": -33,
      "y": 1,
      "z": -17,
      "name": "Wood_Giantwood_Trunk_Full"
    },
    {
      "x": -33,
      "y": 2,
      "z": -17,
      "name": "Wood_Giantwood_Trunk_Full"
    },
    {
      "x": -33,
      "y": 3,
      "z": -17,
      "name": "Wood_Giantwood_Trunk_Full"
    },
    {
      "x": -33,
      "y": 173,
      "z": -17,
      "name": "Rock_Stone_Mossy"
    },
    {
      "x": -33,
      "y": 174,
      "z": -17,
      "name": "Rock_Stone_Mossy"
    },
    {
      "x": -33,
      "y": 176,
      "z": -17,
      "name": "Rock_Stone_Mossy"
    },
    {
      "x": -33,
      "y": -3,
      "z": -16,
      "name": "Wood_Giantwood_Trunk_Full"
    },
    {
      "x": -33,
      "y": -2,
      "z": -16,
      "name": "Wood_Giantwood_Trunk_Full"
    },
    {
      "x": -33,
      "y": -1,
      "z": -16,
      "name": "Wood_Giantwood_Trunk_Full"
    },
    {
      "x": -33,
      "y": 0,
      "z": -16,
      "name": "Wood_Giantwood_Trunk_Full",
      "support": 1
    },
    {
      "x": -33,
      "y": 1,
      "z": -16,
      "name": "Wood_Giantwood_Trunk_Full"
    },
    {
      "x": -33,
      "y": 2,
      "z": -16,
      "name": "Wood_Giantwood_Trunk_Full"
    },
    {
      "x": -33,
      "y": 3,
      "z": -16,
      "name": "Wood_Giantwood_Trunk_Full"
    },
    {
      "x": -33,
      "y": 173,
      "z": -16,
      "name": "Rock_Stone_Mossy"
    },
    {
      "x": -33,
      "y": 175,
      "z": -16,
      "name": "Rock_Stone_Mossy"
    },
    {
      "x": -33,
      "y": -1,
      "z": -15,
      "name": "Wood_Giantwood_Trunk_Full"
    },
    {
      "x": -33,
      "y": 0,
      "z": -15,
      "name": "Wood_Giantwood_Trunk_Full"
    },
    {
      "x": -33,
      "y": 1,
      "z": -15,
      "name": "Wood_Giantwood_Trunk_Full"
    },
    {
      "x": -33,
      "y": 2,
      "z": -15,
      "name": "Wood_Giantwood_Trunk_Full",
      "support": 1
    },
    {
      "x": -33,
      "y": 3,
      "z": -15,
      "name": "Wood_Giantwood_Trunk_Full"
    },
    {
      "x": -33,
      "y": 173,
      "z": -15,
      "name": "Rock_Stone_Mossy"
    },
    {
      "x": -33,
      "y": 179,
      "z": -15,
      "name": "Rock_Stone_Mossy"
    },
    {
      "x": -33,
      "y": 182,
      "z": -15,
      "name": "Rock_Stone_Mossy"
    },
    {
      "x": -33,
      "y": 183,
      "z": -15,
      "name": "Rock_Stone_Mossy"
    },
    {
      "x": -33,
      "y": 175,
      "z": -14,
      "name": "Rock_Stone_Mossy"
    },
    {
      "x": -33,
      "y": 171,
      "z": -13,
      "name": "Rock_Stone_Mossy"
    },
    {
      "x": -33,
      "y": 172,
      "z": -13,
      "name": "Rock_Stone_Mossy"
    },
    {
      "x": -33,
      "y": 175,
      "z": -13,
      "name": "Rock_Stone_Mossy"
    },
    {
      "x": -33,
      "y": 177,
      "z": -13,
      "name": "Rock_Stone_Mossy"
    },
    {
      "x": -33,
      "y": 180,
      "z": -13,
      "name": "Rock_Stone_Mossy"
    },
    {
      "x": -33,
      "y": 172,
      "z": -11,
      "name": "Rock_Stone_Mossy"
    },
    {
      "x": -33,
      "y": 176,
      "z": -11,
      "name": "Rock_Stone_Mossy"
    },
    {
      "x": -33,
      "y": 177,
      "z": -11,
      "name": "Rock_Stone_Mossy"
    },
    {
      "x": -33,
      "y": 178,
      "z": -11,
      "name": "Rock_Stone_Mossy"
    },
    {
      "x": -33,
      "y": 180,
      "z": -11,
      "name": "Rock_Stone_Mossy"
    },
    {
      "x": -33,
      "y": 174,
      "z": -10,
      "name": "Rock_Stone_Mossy"
    },
    {
      "x": -33,
      "y": 178,
      "z": -10,
      "name": "Rock_Stone_Mossy"
    },
    {
      "x": -33,
      "y": 181,
      "z": -10,
      "name": "Rock_Stone_Mossy"
    },
    {
      "x": -33,
      "y": 171,
      "z": -9,
      "name": "Rock_Stone_Mossy"
    },
    {
      "x": -33,
      "y": 172,
      "z": -9,
      "name": "Rock_Stone_Mossy"
    },
    {
      "x": -33,
      "y": 178,
      "z": -9,
      "name": "Rock_Stone_Mossy"
    },
    {
      "x": -33,
      "y": 171,
      "z": -8,
      "name": "Rock_Stone_Mossy"
    },
    {
      "x": -33,
      "y": 173,
      "z": -8,
      "name": "Rock_Stone_Mossy"
    },
    {
      "x": -33,
      "y": 176,
      "z": -8,
      "name": "Rock_Stone_Mossy"
    },
    {
      "x": -33,
      "y": 178,
      "z": -8,
      "name": "Rock_Stone_Mossy"
    },
    {
      "x": -33,
      "y": 173,
      "z": -7,
      "name": "Rock_Stone_Mossy"
    },
    {
      "x": -33,
      "y": 175,
      "z": -7,
      "name": "Rock_Stone_Mossy"
    },
    {
      "x": -33,
      "y": 176,
      "z": -7,
      "name": "Rock_Stone_Mossy"
    },
    {
      "x": -33,
      "y": 178,
      "z": -7,
      "name": "Rock_Stone_Mossy"
    },
    {
      "x": -33,
      "y": 170,
      "z": -6,
      "name": "Rock_Stone_Mossy"
    },
    {
      "x": -33,
      "y": 172,
      "z": -6,
      "name": "Rock_Stone_Mossy"
    },
    {
      "x": -33,
      "y": 177,
      "z": -6,
      "name": "Rock_Stone_Mossy"
    },
    {
      "x": -33,
      "y": 181,
      "z": -6,
      "name": "Rock_Stone_Mossy"
    },
    {
      "x": -33,
      "y": 170,
      "z": -5,
      "name": "Rock_Stone_Mossy"
    },
    {
      "x": -33,
      "y": 171,
      "z": -5,
      "name": "Rock_Stone_Mossy"
    },
    {
      "x": -33,
      "y": 173,
      "z": -5,
      "name": "Rock_Stone_Mossy"
    },
    {
      "x": -33,
      "y": 174,
      "z": -5,
      "name": "Rock_Stone_Mossy"
    },
    {
      "x": -33,
      "y": 179,
      "z": -5,
      "name": "Rock_Stone_Mossy"
    },
    {
      "x": -33,
      "y": 170,
      "z": -4,
      "name": "Rock_Stone_Mossy"
    },
    {
      "x": -33,
      "y": 177,
      "z": -4,
      "name": "Rock_Stone_Mossy"
    },
    {
      "x": -33,
      "y": 180,
      "z": -4,
      "name": "Rock_Stone_Mossy"
    },
    {
      "x": -33,
      "y": 174,
      "z": -3,
      "name": "Rock_Stone_Mossy"
    },
    {
      "x": -33,
      "y": 175,
      "z": -3,
      "name": "Rock_Stone_Mossy"
    },
    {
      "x": -33,
      "y": 171,
      "z": -2,
      "name": "Rock_Stone_Mossy"
    },
    {
      "x": -33,
      "y": 172,
      "z": -2,
      "name": "Rock_Stone_Mossy"
    },
    {
      "x": -33,
      "y": 173,
      "z": -2,
      "name": "Rock_Stone_Mossy"
    },
    {
      "x": -33,
      "y": 175,
      "z": -2,
      "name": "Rock_Stone_Mossy"
    },
    {
      "x": -33,
      "y": 176,
      "z": -2,
      "name": "Rock_Stone_Mossy"
    },
    {
      "x": -33,
      "y": 178,
      "z": -2,
      "name": "Rock_Stone_Mossy"
    },
    {
      "x": -33,
      "y": 171,
      "z": -1,
      "name": "Rock_Stone_Mossy"
    },
    {
      "x": -33,
      "y": 173,
      "z": -1,
      "name": "Rock_Stone_Mossy"
    },
    {
      "x": -33,
      "y": 174,
      "z": -1,
      "name": "Rock_Stone_Mossy"
    },
    {
      "x": -33,
      "y": 175,
      "z": -1,
      "name": "Rock_Stone_Mossy"
    },
    {
      "x": -33,
      "y": 176,
      "z": -1,
      "name": "Rock_Stone_Mossy"
    },
    {
      "x": -33,
      "y": 170,
      "z": 0,
      "name": "Rock_Stone_Mossy"
    },
    {
      "x": -33,
      "y": 173,
      "z": 0,
      "name": "Rock_Stone_Mossy"
    },
    {
      "x": -33,
      "y": 174,
      "z": 0,
      "name": "Rock_Stone_Mossy"
    },
    {
      "x": -33,
      "y": 175,
      "z": 0,
      "name": "Rock_Stone_Mossy"
    },
    {
      "x": -33,
      "y": 176,
      "z": 0,
      "name": "Rock_Stone_Mossy"
    },
    {
      "x": -33,
      "y": 178,
      "z": 0,
      "name": "Rock_Stone_Mossy"
    },
    {
      "x": -33,
      "y": 172,
      "z": 1,
      "name": "Rock_Stone_Mossy"
    },
    {
      "x": -33,
      "y": 174,
      "z": 1,
      "name": "Rock_Stone_Mossy"
    },
    {
      "x": -33,
      "y": 175,
      "z": 1,
      "name": "Rock_Stone_Mossy"
    },
    {
      "x": -33,
      "y": 170,
      "z": 2,
      "name": "Rock_Stone_Mossy"
    },
    {
      "x": -33,
      "y": 174,
      "z": 3,
      "name": "Rock_Stone_Mossy"
    },
    {
      "x": -33,
      "y": 177,
      "z": 3,
      "name": "Rock_Stone_Mossy"
    },
    {
      "x": -33,
      "y": 171,
      "z": 4,
      "name": "Rock_Stone_Mossy"
    },
    {
      "x": -33,
      "y": 174,
      "z": 4,
      "name": "Rock_Stone_Mossy"
    },
    {
      "x": -33,
      "y": 174,
      "z": 5,
      "name": "Rock_Stone_Mossy"
    },
    {
      "x": -33,
      "y": 171,
      "z": 6,
      "name": "Rock_Stone_Mossy"
    },
    {
      "x": -33,
      "y": 172,
      "z": 6,
      "name": "Rock_Stone_Mossy"
    },
    {
      "x": -33,
      "y": 176,
      "z": 6,
      "name": "Rock_Stone_Mossy"
    },
    {
      "x": -33,
      "y": 172,
      "z": 7,
      "name": "Rock_Stone_Mossy"
    },
    {
      "x": -33,
      "y": 173,
      "z": 7,
      "name": "Rock_Stone_Mossy"
    },
    {
      "x": -33,
      "y": 175,
      "z": 7,
      "name": "Rock_Stone_Mossy"
    },
    {
      "x": -33,
      "y": 176,
      "z": 7,
      "name": "Rock_Stone_Mossy"
    },
    {
      "x": -33,
      "y": 178,
      "z": 7,
      "name": "Rock_Stone_Mossy"
    },
    {
      "x": -33,
      "y": 172,
      "z": 8,
      "name": "Rock_Stone_Mossy"
    },
    {
      "x": -33,
      "y": 173,
      "z": 8,
      "name": "Rock_Stone_Mossy"
    },
    {
      "x": -33,
      "y": 172,
      "z": 9,
      "name": "Rock_Stone_Mossy"
    },
    {
      "x": -33,
      "y": 174,
      "z": 9,
      "name": "Rock_Stone_Mossy"
    },
    {
      "x": -33,
      "y": 176,
      "z": 9,
      "name": "Rock_Stone_Mossy"
    },
    {
      "x": -33,
      "y": 176,
      "z": 10,
      "name": "Rock_Stone_Mossy"
    },
    {
      "x": -33,
      "y": 173,
      "z": 11,
      "name": "Rock_Stone_Mossy"
    },
    {
      "x": -33,
      "y": 174,
      "z": 11,
      "name": "Rock_Stone_Mossy"
    },
    {
      "x": -33,
      "y": 175,
      "z": 11,
      "name": "Rock_Stone_Mossy"
    },
    {
      "x": -33,
      "y": 172,
      "z": 12,
      "name": "Rock_Stone_Mossy"
    },
    {
      "x": -33,
      "y": 175,
      "z": 13,
      "name": "Rock_Stone_Mossy"
    },
    {
      "x": -33,
      "y": 174,
      "z": 14,
      "name": "Rock_Stone_Mossy"
    },
    {
      "x": -33,
      "y": 176,
      "z": 14,
      "name": "Rock_Stone_Mossy"
    },
    {
      "x": -33,
      "y": 177,
      "z": 14,
      "name": "Rock_Stone_Mossy"
    },
    {
      "x": -33,
      "y": 172,
      "z": 16,
      "name": "Rock_Stone_Mossy"
    },
    {
      "x": -33,
      "y": 175,
      "z": 17,
      "name": "Rock_Stone_Mossy"
    },
    {
      "x": -33,
      "y": 176,
      "z": 17,
      "name": "Rock_Stone_Mossy"
    },
    {
      "x": -33,
      "y": 172,
      "z": 19,
      "name": "Rock_Stone_Mossy"
    },
    {
      "x": -33,
      "y": 174,
      "z": 22,
      "name": "Rock_Stone_Mossy"
    },
    {
      "x": -32,
      "y": 178,
      "z": -30,
