{
  "version": 8,
  "blockIdVersion": 11,
  "anchorX": 0,
  "anchorY": 0,
  "anchorZ": 0,
  "blocks": [
    {
      "x": -43,
      "y": 201,
      "z": -2,
      "name": "Wood_Giantwood_Trunk_Full"
    },
    {
      "x": -42,
      "y": 201,
      "z": -2,
      "name": "Wood_Giantwood_Trunk_Full"
    },
    {
      "x": -41,
      "y": 201,
      "z": -2,
      "name": "Wood_Giantwood_Trunk_Full"
    },
    {
      "x": -40,
      "y": 200,
      "z": -2,
      "name": "Wood_Giantwood_Trunk_Full"
    },
    {
      "x": -40,
      "y": 201,
      "z": -2,
      "name": "Wood_Giantwood_Trunk_Full"
    },
    {
      "x": -39,
      "y": 200,
      "z": -2,
      "name": "Wood_Giantwood_Trunk_Full"
    },
    {
      "x": -39,
      "y": 201,
      "z": -2,
      "name": "Wood_Giantwood_Trunk_Full"
    },
    {
      "x": -38,
      "y": 200,
      "z": -3,
      "name": "Wood_Giantwood_Trunk_Full"
    },
    {
      "x": -38,
      "y": 200,
      "z": -2,
      "name": "Wood_Giantwood_Trunk_Full"
    },
    {
      "x": -38,
      "y": 201,
      "z": -2,
      "name": "Wood_Giantwood_Trunk_Full"
    },
    {
      "x": -37,
      "y": 200,
      "z": -3,
      "name": "Wood_Giantwood_Trunk_Full"
    },
    {
      "x": -37,
      "y": 200,
      "z": -2,
      "name": "Wood_Giantwood_Trunk_Full"
    },
    {
      "x": -37,
      "y": 201,
      "z": -2,
      "name": "Wood_Giantwood_Trunk_Full"
    },
    {
      "x": -37,
      "y": 200,
      "z": -1,
      "name": "Wood_Giantwood_Trunk_Full"
    },
    {
      "x": -36,
      "y": 23,
      "z": -19,
      "name": "Wood_Giantwood_Trunk_Mossy_Full"
    },
    {
      "x": -36,
      "y": 24,
      "z": -19,
      "name": "Wood_Giantwood_Trunk_Mossy_Full"
    },
    {
      "x": -36,
      "y": 25,
      "z": -19,
      "name": "Wood_Giantwood_Trunk_Mossy_Full"
    },
    {
      "x": -36,
      "y": 22,
      "z": -18,
      "name": "Wood_Giantwood_Trunk_Mossy_Full"
    },
    {
      "x": -36,
      "y": 23,
      "z": -18,
      "name": "Wood_Giantwood_Trunk_Mossy_Full"
    },
    {
      "x": -36,
      "y": 24,
      "z": -18,
      "name": "Wood_Giantwood_Trunk_Mossy_Full"
    },
    {
      "x": -36,
      "y": 25,
      "z": -18,
      "name": "Wood_Giantwood_Trunk_Mossy_Full"
    },
    {
      "x": -36,
      "y": 26,
      "z": -18,
      "name": "Wood_Giantwood_Trunk_Mossy_Full"
    },
    {
      "x": -36,
      "y": 22,
      "z": -17,
      "name": "Wood_Giantwood_Trunk_Mossy_Full"
    },
    {
      "x": -36,
      "y": 23,
      "z": -17,
      "name": "Wood_Giantwood_Trunk_Mossy_Full"
    },
    {
      "x": -36,
      "y": 24,
      "z": -17,
      "name": "Wood_Giantwood_Trunk_Mossy_Full"
    },
    {
      "x": -36,
      "y": 25,
      "z": -17,
      "name": "Wood_Giantwood_Trunk_Mossy_Full"
    },
    {
      "x": -36,
      "y": 26,
      "z": -17,
      "name": "Wood_Giantwood_Trunk_Mossy_Full"
    },
    {
      "x": -36,
      "y": 24,
      "z": -16,
      "name": "Wood_Giantwood_Trunk_Mossy_Full"
    },
    {
      "x": -36,
      "y": 25,
      "z": -16,
      "name": "Wood_Giantwood_Trunk_Mossy_Full"
    },
    {
      "x": -36,
      "y": 200,
      "z": -3,
      "name": "Wood_Giantwood_Trunk_Full"
    },
    {
      "x": -36,
      "y": 199,
      "z": -2,
      "name": "Wood_Giantwood_Trunk_Full"
    },
    {
      "x": -36,
      "y": 200,
      "z": -2,
      "name": "Wood_Giantwood_Trunk_Full"
    },
    {
      "x": -36,
      "y": 200,
      "z": -1,
      "name": "Wood_Giantwood_Trunk_Full"
    },
    {
      "x": -35,
      "y": 23,
      "z": -21,
      "name": "Wood_Giantwood_Trunk_Mossy_Full"
    },
    {
      "x": -35,
      "y": 24,
      "z": -21,
      "name": "Wood_Giantwood_Trunk_Mossy_Full"
    },
    {
      "x": -35,
      "y": 25,
      "z": -21,
      "name": "Wood_Giantwood_Trunk_Mossy_Full"
    },
    {
      "x": -35,
      "y": 22,
      "z": -20,
      "name": "Wood_Giantwood_Trunk_Mossy_Full"
    },
    {
      "x": -35,
      "y": 23,
      "z": -20,
      "name": "Wood_Giantwood_Trunk_Mossy_Full"
    },
    {
      "x": -35,
      "y": 24,
      "z": -20,
      "name": "Wood_Giantwood_Trunk_Mossy_Full"
    },
    {
      "x": -35,
      "y": 25,
      "z": -20,
      "name": "Wood_Giantwood_Trunk_Mossy_Full"
    },
    {
      "x": -35,
      "y": 26,
      "z": -20,
      "name": "Wood_Giantwood_Trunk_Mossy_Full"
    },
    {
      "x": -35,
      "y": 20,
      "z": -19,
      "name": "Wood_Giantwood_Trunk_Mossy_Full"
    },
    {
      "x": -35,
      "y": 21,
      "z": -19,
      "name": "Wood_Giantwood_Trunk_Mossy_Full"
    },
    {
      "x": -35,
      "y": 22,
      "z": -19,
      "name": "Wood_Giantwood_Trunk_Mossy_Full"
    },
    {
      "x": -35,
      "y": 23,
      "z": -19,
      "name": "Wood_Giantwood_Trunk_Mossy_Full"
    },
    {
      "x": -35,
      "y": 24,
      "z": -19,
      "name": "Wood_Giantwood_Trunk_Mossy_Full"
    },
    {
      "x": -35,
      "y": 25,
      "z": -19,
      "name": "Wood_Giantwood_Trunk_Mossy_Full"
    },
    {
      "x": -35,
      "y": 26,
      "z": -19,
      "name": "Wood_Giantwood_Trunk_Mossy_Full"
    },
    {
      "x": -35,
      "y": 27,
      "z": -19,
      "name": "Wood_Giantwood_Trunk_Mossy_Full"
    },
    {
      "x": -35,
      "y": 21,
      "z": -18,
      "name": "Wood_Giantwood_Trunk_Mossy_Full"
    },
    {
      "x": -35,
      "y": 22,
      "z": -18,
      "name": "Wood_Giantwood_Trunk"
    },
    {
      "x": -35,
      "y": 23,
      "z": -18,
      "name": "Wood_Giantwood_Trunk"
    },
    {
      "x": -35,
      "y": 24,
      "z": -18,
      "name": "Wood_Giantwood_Trunk"
    },
    {
      "x": -35,
      "y": 25,
      "z": -18,
      "name": "Wood_Giantwood_Trunk"
    },
    {
      "x": -35,
      "y": 26,
      "z": -18,
      "name": "Wood_Giantwood_Trunk_Mossy_Full"
    },
    {
      "x": -35,
      "y": 27,
      "z": -18,
      "name": "Wood_Giantwood_Trunk_Mossy_Full"
    },
    {
      "x": -35,
      "y": 28,
      "z": -18,
      "name": "Wood_Giantwood_Trunk_Mossy_Full"
    },
    {
      "x": -35,
      "y": 20,
      "z": -17,
      "name": "Wood_Giantwood_Trunk_Mossy_Full"
    },
    {
      "x": -35,
      "y": 21,
      "z": -17,
      "name": "Wood_Giantwood_Trunk_Mossy_Full"
    },
    {
      "x": -35,
      "y": 22,
      "z": -17,
      "name": "Wood_Giantwood_Trunk_Mossy_Full"
    },
    {
      "x": -35,
      "y": 23,
      "z": -17,
      "name": "Wood_Giantwood_Trunk_Mossy_Full"
    },
    {
      "x": -35,
      "y": 24,
      "z": -17,
      "name": "Wood_Giantwood_Trunk"
    },
    {
      "x": -35,
      "y": 25,
      "z": -17,
      "name": "Wood_Giantwood_Trunk"
    },
    {
      "x": -35,
      "y": 26,
      "z": -17,
      "name": "Wood_Giantwood_Trunk_Mossy_Full"
    },
    {
      "x": -35,
      "y": 27,
      "z": -17,
      "name": "Wood_Giantwood_Trunk_Mossy_Full"
    },
    {
      "x": -35,
      "y": 28,
      "z": -17,
      "name": "Wood_Giantwood_Trunk_Mossy_Full"
    },
    {
      "x": -35,
      "y": 21,
      "z": -16,
      "name": "Wood_Giantwood_Trunk_Mossy_Full"
    },
    {
      "x": -35,
      "y": 22,
      "z": -16,
      "name": "Wood_Giantwood_Trunk_Mossy_Full"
    },
    {
      "x": -35,
      "y": 23,
      "z": -16,
      "name": "Wood_Giantwood_Trunk_Mossy_Full"
    },
    {
      "x": -35,
      "y": 24,
      "z": -16,
      "name": "Wood_Giantwood_Trunk_Mossy_Full"
    },
    {
      "x": -35,
      "y": 25,
      "z": -16,
      "name": "Wood_Giantwood_Trunk_Mossy_Full"
    },
    {
      "x": -35,
      "y": 26,
      "z": -16,
      "name": "Wood_Giantwood_Trunk_Mossy_Full"
    },
    {
      "x": -35,
      "y": 27,
      "z": -16,
      "name": "Wood_Giantwood_Trunk_Mossy_Full"
    },
    {
      "x": -35,
      "y": 28,
      "z": -16,
      "name": "Wood_Giantwood_Trunk_Mossy_Full"
    },
    {
      "x": -35,
      "y": 22,
      "z": -15,
      "name": "Wood_Giantwood_Trunk_Mossy_Full"
    },
    {
      "x": -35,
      "y": 23,
      "z": -15,
      "name": "Wood_Giantwood_Trunk_Mossy_Full"
    },
    {
      "x": -35,
      "y": 24,
      "z": -15,
      "name": "Wood_Giantwood_Trunk_Mossy_Full"
    },
    {
      "x": -35,
      "y": 25,
      "z": -15,
      "name": "Wood_Giantwood_Trunk_Mossy_Full"
    },
    {
      "x": -35,
      "y": 26,
      "z": -15,
      "name": "Wood_Giantwood_Trunk_Mossy_Full"
    },
    {
      "x": -35,
      "y": 27,
      "z": -15,
      "name": "Wood_Giantwood_Trunk_Mossy_Full"
    },
    {
      "x": -35,
      "y": 28,
      "z": -15,
      "name": "Wood_Giantwood_Trunk_Mossy_Full"
    },
    {
      "x": -35,
      "y": 24,
      "z": -14,
      "name": "Wood_Giantwood_Trunk_Mossy_Full"
    },
    {
      "x": -35,
      "y": 25,
      "z": -14,
      "name": "Wood_Giantwood_Trunk_Mossy_Full"
    },
    {
      "x": -35,
      "y": 26,
      "z": -14,
      "name": "Wood_Giantwood_Trunk_Mossy_Full"
    },
    {
      "x": -35,
      "y": 27,
      "z": -14,
      "name": "Wood_Giantwood_Trunk_Mossy_Full"
    },
    {
      "x": -35,
      "y": 28,
      "z": -14,
      "name": "Wood_Giantwood_Trunk_Mossy_Full"
    },
    {
      "x": -35,
      "y": 200,
      "z": -3,
      "name": "Wood_Giantwood_Trunk_Full"
    },
    {
      "x": -35,
      "y": 199,
      "z": -2,
      "name": "Wood_Giantwood_Trunk_Full"
    },
    {
      "x": -35,
      "y": 200,
      "z": -2,
      "name": "Wood_Giantwood_Trunk_Full"
    },
    {
      "x": -35,
      "y": 200,
      "z": -1,
      "name": "Wood_Giantwood_Trunk_Full"
    },
    {
      "x": -34,
      "y": 23,
      "z": -22,
      "name": "Wood_Giantwood_Trunk_Mossy_Full"
    },
    {
      "x": -34,
      "y": 24,
      "z": -22,
      "name": "Wood_Giantwood_Trunk_Mossy_Full"
    },
    {
      "x": -34,
      "y": 21,
      "z": -21,
      "name": "Wood_Giantwood_Trunk_Mossy_Full"
    },
    {
      "x": -34,
      "y": 22,
      "z": -21,
      "name": "Wood_Giantwood_Trunk_Mossy_Full"
    },
    {
      "x": -34,
      "y": 23,
      "z": -21,
      "name": "Wood_Giantwood_Trunk_Mossy_Full"
    },
    {
      "x": -34,
      "y": 24,
      "z": -21,
      "name": "Wood_Giantwood_Trunk_Mossy_Full"
    },
    {
      "x": -34,
      "y": 25,
      "z": -21,
      "name": "Wood_Giantwood_Trunk_Mossy_Full"
    },
    {
      "x": -34,
      "y": 26,
      "z": -21,
      "name": "Wood_Giantwood_Trunk_Mossy_Full"
    },
    {
      "x": -34,
      "y": 20,
      "z": -20,
      "name": "Wood_Giantwood_Trunk_Mossy_Full"
    },
    {
      "x": -34,
      "y": 21,
      "z": -20,
      "name": "Wood_Giantwood_Trunk_Mossy_Full"
    },
    {
      "x": -34,
      "y": 22,
      "z": -20,
      "name": "Wood_Giantwood_Trunk_Mossy_Full"
    },
    {
      "x": -34,
      "y": 23,
      "z": -20,
      "name": "Wood_Giantwood_Trunk"
    },
    {
      "x": -34,
      "y": 24,
      "z": -20,
      "name": "Wood_Giantwood_Trunk"
    },
    {
      "x": -34,
      "y": 25,
      "z": -20,
      "name": "Wood_Giantwood_Trunk"
    },
    {
      "x": -34,
      "y": 26,
      "z": -20,
      "name": "Wood_Giantwood_Trunk_Mossy_Full"
    },
    {
      "x": -34,
      "y": 27,
      "z": -20,
      "name": "Wood_Giantwood_Trunk_Mossy_Full"
    },
    {
      "x": -34,
      "y": 28,
      "z": -20,
      "name": "Wood_Giantwood_Trunk_Mossy_Full"
    },
    {
      "x": -34,
      "y": 19,
      "z": -19,
      "name": "Wood_Giantwood_Trunk_Mossy_Full"
    },
    {
      "x": -34,
      "y": 20,
      "z": -19,
      "name": "Wood_Giantwood_Trunk_Mossy_Full"
    },
    {
      "x": -34,
      "y": 21,
      "z": -19,
      "name": "Wood_Giantwood_Trunk_Mossy_Full"
    },
    {
      "x": -34,
      "y": 22,
      "z": -19,
      "name": "Wood_Giantwood_Trunk"
    },
    {
      "x": -34,
      "y": 23,
      "z": -19,
      "name": "Wood_Giantwood_Trunk"
    },
    {
      "x": -34,
      "y": 24,
      "z": -19,
      "name": "Wood_Giantwood_Trunk"
    },
    {
      "x": -34,
      "y": 25,
      "z": -19,
      "name": "Wood_Giantwood_Trunk"
    },
    {
      "x": -34,
      "y": 26,
      "z": -19,
      "name": "Wood_Giantwood_Trunk"
    },
    {
      "x": -34,
      "y": 27,
      "z": -19,
      "name": "Wood_Giantwood_Trunk_Mossy_Full"
    },
    {
      "x": -34,
      "y": 28,
      "z": -19,
      "name": "Wood_Giantwood_Trunk_Mossy_Full"
    },
    {
      "x": -34,
      "y": 19,
      "z": -18,
      "name": "Wood_Giantwood_Trunk_Mossy_Full"
    },
    {
      "x": -34,
      "y": 20,
      "z": -18,
      "name": "Wood_Giantwood_Trunk_Mossy_Full"
    },
    {
      "x": -34,
      "y": 21,
      "z": -18,
      "name": "Wood_Giantwood_Trunk"
    },
    {
      "x": -34,
      "y": 22,
      "z": -18,
      "name": "Wood_Giantwood_Trunk"
    },
    {
      "x": -34,
      "y": 23,
      "z": -18,
      "name": "Wood_Giantwood_Trunk"
    },
    {
      "x": -34,
      "y": 24,
      "z": -18,
      "name": "Wood_Giantwood_Trunk"
    },
    {
      "x": -34,
      "y": 25,
      "z": -18,
      "name": "Wood_Giantwood_Trunk"
    },
    {
      "x": -34,
      "y": 26,
      "z": -18,
      "name": "Wood_Giantwood_Trunk"
    },
    {
      "x": -34,
      "y": 27,
      "z": -18,
      "name": "Wood_Giantwood_Trunk"
    },
    {
      "x": -34,
      "y": 28,
      "z": -18,
      "name": "Wood_Giantwood_Trunk_Mossy_Full"
    },
    {
      "x": -34,
      "y": 29,
      "z": -18,
      "name": "Wood_Giantwood_Trunk_Mossy_Full"
    },
    {
      "x": -34,
      "y": 19,
      "z": -17,
      "name": "Wood_Giantwood_Trunk_Mossy_Full"
    },
    {
      "x": -34,
      "y": 20,
      "z": -17,
      "name": "Wood_Giantwood_Trunk_Mossy_Full"
    },
    {
      "x": -34,
      "y": 21,
      "z": -17,
      "name": "Wood_Giantwood_Trunk"
    },
    {
      "x": -34,
      "y": 22,
      "z": -17,
      "name": "Wood_Giantwood_Trunk"
    },
    {
      "x": -34,
      "y": 23,
      "z": -17,
      "name": "Wood_Giantwood_Trunk"
    },
    {
      "x": -34,
      "y": 24,
      "z": -17,
      "name": "Wood_Giantwood_Trunk"
    },
    {
      "x": -34,
      "y": 25,
      "z": -17,
      "name": "Wood_Giantwood_Trunk"
    },
    {
      "x": -34,
      "y": 26,
      "z": -17,
      "name": "Wood_Giantwood_Trunk"
    },
    {
      "x": -34,
      "y": 27,
      "z": -17,
      "name": "Wood_Giantwood_Trunk"
    },
    {
      "x": -34,
      "y": 28,
      "z": -17,
      "name": "Wood_Giantwood_Trunk"
    },
    {
      "x": -34,
      "y": 29,
      "z": -17,
      "name": "Wood_Giantwood_Trunk_Mossy_Full"
    },
    {
      "x": -34,
      "y": 20,
      "z": -16,
      "name": "Wood_Giantwood_Trunk_Mossy_Full"
    },
    {
      "x": -34,
      "y": 21,
      "z": -16,
      "name": "Wood_Giantwood_Trunk_Mossy_Full"
    },
    {
      "x": -34,
      "y": 22,
      "z": -16,
      "name": "Wood_Giantwood_Trunk"
    },
    {
      "x": -34,
      "y": 23,
      "z": -16,
      "name": "Wood_Giantwood_Trunk"
    },
    {
      "x": -34,
      "y": 24,
      "z": -16,
      "name": "Wood_Giantwood_Trunk"
    },
    {
      "x": -34,
      "y": 25,
      "z": -16,
      "name": "Wood_Giantwood_Trunk"
    },
    {
      "x": -34,
      "y": 26,
      "z": -16,
      "name": "Wood_Giantwood_Trunk"
    },
    {
      "x": -34,
      "y": 27,
      "z": -16,
      "name": "Wood_Giantwood_Trunk"
    },
    {
      "x": -34,
      "y": 28,
      "z": -16,
      "name": "Wood_Giantwood_Trunk"
    },
    {
      "x": -34,
      "y": 29,
      "z": -16,
      "name": "Wood_Giantwood_Trunk_Mossy_Full"
    },
    {
      "x": -34,
      "y": 20,
      "z": -15,
      "name": "Wood_Giantwood_Trunk_Mossy_Full"
    },
    {
      "x": -34,
      "y": 21,
      "z": -15,
      "name": "Wood_Giantwood_Trunk_Mossy_Full"
    },
    {
      "x": -34,
      "y": 22,
      "z": -15,
      "name": "Wood_Giantwood_Trunk_Mossy_Full"
    },
    {
      "x": -34,
      "y": 23,
      "z": -15,
      "name": "Wood_Giantwood_Trunk_Mossy_Full"
    },
    {
      "x": -34,
      "y": 24,
      "z": -15,
      "name": "Wood_Giantwood_Trunk"
    },
    {
      "x": -34,
      "y": 25,
      "z": -15,
      "name": "Wood_Giantwood_Trunk"
    },
    {
      "x": -34,
      "y": 26,
      "z": -15,
      "name": "Wood_Giantwood_Trunk"
    },
    {
      "x": -34,
      "y": 27,
      "z": -15,
      "name": "Wood_Giantwood_Trunk"
    },
    {
      "x": -34,
      "y": 28,
      "z": -15,
      "name": "Wood_Giantwood_Trunk"
    },
    {
      "x": -34,
      "y": 29,
      "z": -15,
      "name": "Wood_Giantwood_Trunk_Mossy_Full"
    },
    {
      "x": -34,
      "y": 22,
      "z": -14,
      "name": "Wood_Giantwood_Trunk_Mossy_Full"
    },
    {
      "x": -34,
      "y": 23,
      "z": -14,
      "name": "Wood_Giantwood_Trunk_Mossy_Full"
    },
    {
      "x": -34,
      "y": 24,
      "z": -14,
      "name": "Wood_Giantwood_Trunk_Mossy_Full"
    },
    {
      "x": -34,
      "y": 25,
      "z": -14,
      "name": "Wood_Giantwood_Trunk_Mossy_Full"
    },
    {
      "x": -34,
      "y": 26,
      "z": -14,
      "name": "Wood_Giantwood_Trunk_Mossy_Full"
    },
    {
      "x": -34,
      "y": 27,
      "z": -14,
      "name": "Wood_Giantwood_Trunk_Mossy_Full"
    },
    {
      "x": -34,
      "y": 28,
      "z": -14,
      "name": "Wood_Giantwood_Trunk_Mossy_Full"
    },
    {
      "x": -34,
      "y": 29,
      "z": -14,
      "name": "Wood_Giantwood_Trunk_Mossy_Full"
    },
    {
      "x": -34,
      "y": 24,
      "z": -13,
      "name": "Wood_Giantwood_Trunk_Mossy_Full"
    },
    {
      "x": -34,
      "y": 25,
      "z": -13,
      "name": "Wood_Giantwood_Trunk_Mossy_Full"
    },
    {
      "x": -34,
      "y": 26,
      "z": -13,
      "name": "Wood_Giantwood_Trunk_Mossy_Full"
    },
    {
      "x": -34,
      "y": 27,
      "z": -13,
      "name": "Wood_Giantwood_Trunk_Mossy_Full"
    },
    {
      "x": -34,
      "y": 28,
      "z": -13,
      "name": "Wood_Giantwood_Trunk_Mossy_Full"
    },
    {
      "x": -34,
      "y": 199,
      "z": -3,
      "name": "Wood_Giantwood_Trunk_Full"
    },
    {
      "x": -34,
      "y": 199,
      "z": -2,
      "name": "Wood_Giantwood_Trunk_Full"
    },
    {
      "x": -34,
      "y": 200,
      "z": -2,
      "name": "Wood_Giantwood_Trunk_Full"
    },
    {
      "x": -34,
      "y": 199,
      "z": -1,
      "name": "Wood_Giantwood_Trunk_Full"
    },
    {
      "x": -34,
      "y": 200,
      "z": 10,
      "name": "Wood_Giantwood_Trunk_Full"
    },
    {
      "x": -33,
      "y": 22,
      "z": -22,
      "name": "Wood_Giantwood_Trunk_Mossy_Full"
    },
    {
      "x": -33,
      "y": 23,
      "z": -22,
      "name": "Wood_Giantwood_Trunk_Mossy_Full"
    },
    {
      "x": -33,
      "y": 24,
      "z": -22,
      "name": "Wood_Giantwood_Trunk_Mossy_Full"
    },
    {
      "x": -33,
      "y": 25,
      "z": -22,
      "name": "Wood_Giantwood_Trunk_Mossy_Full"
    },
    {
      "x": -33,
      "y": 21,
      "z": -21,
      "name": "Wood_Giantwood_Trunk_Mossy_Full"
    },
    {
      "x": -33,
      "y": 22,
      "z": -21,
      "name": "Wood_Giantwood_Trunk_Mossy_Full"
    },
    {
      "x": -33,
      "y": 23,
      "z": -21,
      "name": "Wood_Giantwood_Trunk"
    },
    {
      "x": -33,
      "y": 24,
      "z": -21,
      "name": "Wood_Giantwood_Trunk"
    },
    {
      "x": -33,
      "y": 25,
      "z": -21,
      "name": "Wood_Giantwood_Trunk_Mossy_Full"
    },
    {
      "x": -33,
      "y": 26,
      "z": -21,
      "name": "Wood_Giantwood_Trunk_Mossy_Full"
    },
    {
      "x": -33,
      "y": 27,
      "z": -21,
      "name": "Wood_Giantwood_Trunk_Mossy_Full"
    },
    {
      "x": -33,
      "y": 28,
      "z": -21,
      "name": "Wood_Giantwood_Trunk_Mossy_Full"
    },
    {
      "x": -33,
      "y": 19,
      "z": -20,
      "name": "Wood_Giantwood_Trunk_Mossy_Full"
    },
    {
      "x": -33,
      "y": 20,
      "z": -20,
      "name": "Wood_Giantwood_Trunk_Mossy_Full"
    },
    {
      "x": -33,
      "y": 21,
      "z": -20,
      "name": "Wood_Giantwood_Trunk"
    },
    {
      "x": -33,
      "y": 22,
      "z": -20,
      "name": "Wood_Giantwood_Trunk"
    },
    {
      "x": -33,
      "y": 23,
      "z": -20,
      "name": "Wood_Giantwood_Trunk"
    },
    {
      "x": -33,
      "y": 24,
      "z": -20,
      "name": "Wood_Giantwood_Trunk"
    },
    {
      "x": -33,
      "y": 25,
      "z": -20,
      "name": "Wood_Giantwood_Trunk"
    },
    {
      "x": -33,
      "y": 26,
      "z": -20,
      "name": "Wood_Giantwood_Trunk"
    },
    {
      "x": -33,
      "y": 27,
      "z": -20,
      "name": "Wood_Giantwood_Trunk_Mossy_Full"
    },
    {
      "x": -33,
      "y": 28,
      "z": -20,
      "name": "Wood_Giantwood_Trunk_Mossy_Full"
    },
    {
      "x": -33,
      "y": 18,
      "z": -19,
      "name": "Wood_Giantwood_Trunk_Mossy_Full"
    },
    {
      "x": -33,
      "y": 19,
      "z": -19,
      "name": "Wood_Giantwood_Trunk"
    },
    {
      "x": -33,
      "y": 20,
      "z": -19,
      "name": "Wood_Giantwood_Trunk"
    },
    {
      "x": -33,
      "y": 21,
      "z": -19,
      "name": "Wood_Giantwood_Trunk"
    },
    {
      "x": -33,
      "y": 22,
      "z": -19,
      "name": "Wood_Giantwood_Trunk"
    },
    {
      "x": -33,
      "y": 23,
      "z": -19,
      "name": "Wood_Giantwood_Trunk"
    },
    {
      "x": -33,
      "y": 24,
      "z": -19,
      "name": "Wood_Giantwood_Trunk"
    },
    {
      "x": -33,
      "y": 25,
      "z": -19,
      "name": "Wood_Giantwood_Trunk"
    },
    {
      "x": -33,
      "y": 26,
      "z": -19,
      "name": "Wood_Giantwood_Trunk"
    },
    {
      "x": -33,
      "y": 27,
      "z": -19,
      "name": "Wood_Giantwood_Trunk"
    },
    {
      "x": -33,
      "y": 28,
      "z": -19,
      "name": "Wood_Giantwood_Trunk_Mossy_Full"
    },
    {
      "x": -33,
      "y": 29,
      "z": -19,
      "name": "Wood_Giantwood_Trunk_Mossy_Full"
    },
    {
      "x": -33,
      "y": 18,
      "z": -18,
      "name": "Wood_Giantwood_Trunk_Mossy_Full"
    },
    {
      "x": -33,
      "y": 19,
      "z": -18,
      "name": "Wood_Giantwood_Trunk"
    },
    {
      "x": -33,
      "y": 20,
      "z": -18,
      "name": "Wood_Giantwood_Trunk"
    },
    {
      "x": -33,
      "y": 21,
      "z": -18,
      "name": "Wood_Giantwood_Trunk"
    },
    {
      "x": -33,
      "y": 22,
      "z": -18,
      "name": "Wood_Giantwood_Trunk"
    },
    {
      "x": -33,
      "y": 23,
      "z": -18,
      "name": "Wood_Giantwood_Trunk"
    },
    {
      "x": -33,
      "y": 24,
      "z": -18,
      "name": "Wood_Giantwood_Trunk"
    },
    {
      "x": -33,
      "y": 25,
      "z": -18,
      "name": "Wood_Giantwood_Trunk"
    },
    {
      "x": -33,
      "y": 26,
      "z": -18,
      "name": "Wood_Giantwood_Trunk"
    },
    {
      "x": -33,
      "y": 27,
      "z": -18,
      "name": "Wood_Giantwood_Trunk"
    },
    {
      "x": -33,
      "y": 28,
      "z": -18,
      "name": "Wood_Giantwood_Trunk_Mossy_Full"
    },
    {
      "x": -33,
      "y": 29,
      "z": -18,
      "name": "Wood_Giantwood_Trunk_Mossy_Full"
    },
    {
      "x": -33,
      "y": 30,
      "z": -18,
      "name": "Wood_Giantwood_Trunk_Mossy_Full"
    },
    {
      "x": -33,
      "y": 18,
      "z": -17,
      "name": "Wood_Giantwood_Trunk_Mossy_Full"
    },
    {
      "x": -33,
      "y": 19,
      "z": -17,
      "name": "Wood_Giantwood_Trunk_Mossy_Full"
    },
    {
      "x": -33,
      "y": 20,
      "z": -17,
      "name": "Wood_Giantwood_Trunk"
    },
    {
      "x": -33,
      "y": 21,
      "z": -17,
      "name": "Wood_Giantwood_Trunk"
    },
    {
      "x": -33,
      "y": 22,
      "z": -17,
      "name": "Wood_Giantwood_Trunk"
    },
    {
      "x": -33,
      "y": 23,
      "z": -17,
      "name": "Wood_Giantwood_Trunk"
    },
    {
      "x": -33,
      "y": 24,
      "z": -17,
      "name": "Wood_Giantwood_Trunk"
    },
    {
      "x": -33,
      "y": 25,
      "z": -17,
      "name": "Wood_Giantwood_Trunk"
    },
    {
      "x": -33,
      "y": 26,
      "z": -17,
      "name": "Wood_Giantwood_Trunk"
    },
    {
      "x": -33,
      "y": 27,
      "z": -17,
      "name": "Wood_Giantwood_Trunk"
    },
    {
      "x": -33,
      "y": 28,
      "z": -17,
      "name": "Wood_Giantwood_Trunk"
    },
    {
      "x": -33,
      "y": 29,
      "z": -17,
      "name": "Wood_Giantwood_Trunk_Mossy_Full"
    },
    {
      "x": -33,
      "y": 30,
      "z": -17,
      "name": "Wood_Giantwood_Trunk_Mossy_Full"
    },
    {
      "x": -33,
      "y": 18,
      "z": -16,
      "name": "Wood_Giantwood_Trunk_Mossy_Full"
    },
    {
      "x": -33,
      "y": 19,
      "z": -16,
      "name": "Wood_Giantwood_Trunk_Mossy"
    },
    {
      "x": -33,
      "y": 20,
      "z": -16,
      "name": "Wood_Giantwood_Trunk"
    },
    {
      "x": -33,
      "y": 21,
      "z": -16,
      "name": "Wood_Giantwood_Trunk"
    },
    {
      "x": -33,
      "y": 22,
      "z": -16,
      "name": "Wood_Giantwood_Trunk"
    },
    {
      "x": -33,
      "y": 23,
      "z": -16,
      "name": "Wood_Giantwood_Trunk"
    },
    {
      "x": -33,
      "y": 24,
      "z": -16,
      "name": "Wood_Giantwood_Trunk"
    },
    {
      "x": -33,
      "y": 25,
      "z": -16,
      "name": "Wood_Giantwood_Trunk"
    },
    {
      "x": -33,
      "y": 26,
      "z": -16,
      "name": "Wood_Giantwood_Trunk"
    },
    {
      "x": -33,
      "y": 27,
      "z": -16,
      "name": "Wood_Giantwood_Trunk"
    },
    {
      "x": -33,
      "y": 28,
      "z": -16,
      "name": "Wood_Giantwood_Trunk"
    },
    {
      "x": -33,
      "y": 29,
      "z": -16,
      "name": "Wood_Giantwood_Trunk_Mossy_Full"
    },
    {
      "x": -33,
      "y": 30,
      "z": -16,
      "name": "Wood_Giantwood_Trunk_Mossy_Full"
    },
    {
      "x": -33,
      "y": 19,
      "z": -15,
      "name": "Wood_Giantwood_Trunk_Mossy_Full"
    },
    {
      "x": -33,
      "y": 20,
      "z": -15,
      "name": "Wood_Giantwood_Trunk_Mossy_Full"
    },
    {
      "x": -33,
      "y": 21,
      "z": -15,
      "name": "Wood_Giantwood_Trunk_Mossy_Full"
    },
    {
      "x": -33,
      "y": 22,
      "z": -15,
      "name": "Wood_Giantwood_Trunk"
    },
    {
      "x": -33,
      "y": 23,
      "z": -15,
      "name": "Wood_Giantwood_Trunk"
    },
    {
      "x": -33,
      "y": 24,
      "z": -15,
      "name": "Wood_Giantwood_Trunk"
    },
    {
      "x": -33,
      "y": 25,
      "z": -15,
      "name": "Wood_Giantwood_Trunk"
    },
    {
      "x": -33,
      "y": 26,
      "z": -15,
      "name": "Wood_Giantwood_Trunk"
    },
    {
      "x": -33,
      "y": 27,
      "z": -15,
      "name": "Wood_Giantwood_Trunk"
    },
    {
      "x": -33,
      "y": 28,
      "z": -15,
      "name": "Wood_Giantwood_Trunk"
    },
    {
      "x": -33,
      "y": 29,
      "z": -15,
      "name": "Wood_Giantwood_Trunk_Mossy_Full"
    },
    {
      "x": -33,
      "y": 30,
      "z": -15,
      "name": "Wood_Giantwood_Trunk_Mossy_Full"
    },
    {
      "x": -33,
      "y": 20,
      "z": -14,
      "name": "Wood_Giantwood_Trunk_Mossy_Full"
    },
    {
      "x": -33,
      "y": 21,
      "z": -14,
      "name": "Wood_Giantwood_Trunk_Mossy_Full"
    },
    {
      "x": -33,
      "y": 22,
      "z": -14,
      "name": "Wood_Giantwood_Trunk_Mossy_Full"
    },
    {
      "x": -33,
      "y": 23,
      "z": -14,
      "name": "Wood_Giantwood_Trunk_Mossy_Full"
    },
    {
      "x": -33,
      "y": 24,
      "z": -14,
      "name": "Wood_Giantwood_Trunk"
    },
    {
      "x": -33,
      "y": 25,
      "z": -14,
      "name": "Wood_Giantwood_Trunk"
    },
    {
      "x": -33,
      "y": 26,
      "z": -14,
      "name": "Wood_Giantwood_Trunk"
    },
    {
      "x": -33,
      "y": 27,
      "z": -14,
      "name": "Wood_Giantwood_Trunk"
    },
    {
      "x": -33,
      "y": 28,
      "z": -14,
      "name": "Wood_Giantwood_Trunk"
    },
    {
      "x": -33,
      "y": 29,
      "z": -14,
      "name": "Wood_Giantwood_Trunk_Mossy_Full"
    },
    {
      "x": -33,
      "y": 30,
      "z": -14,
      "name": "Wood_Giantwood_Trunk_Mossy_Full"
    },
    {
      "x": -33,
      "y": 23,
      "z": -13,
      "name": "Wood_Giantwood_Trunk_Mossy_Full"
    },
    {
      "x": -33,
      "y": 24,
      "z": -13,
      "name": "Wood_Giantwood_Trunk_Mossy_Full"
    },
    {
      "x": -33,
      "y": 25,
      "z": -13,
      "name": "Wood_Giantwood_Trunk_Mossy_Full"
    },
    {
      "x": -33,
      "y": 26,
      "z": -13,
      "name": "Wood_Giantwood_Trunk_Mossy_Full"
    },
    {
      "x": -33,
      "y": 27,
      "z": -13,
      "name": "Wood_Giantwood_Trunk_Mossy_Full"
    },
    {
      "x": -33,
      "y": 28,
      "z": -13,
      "name": "Wood_Giantwood_Trunk_Mossy_Full"
    },
    {
      "x": -33,
      "y": 29,
      "z": -13,
      "name": "Wood_Giantwood_Trunk_Mossy_Full"
    },
    {
      "x": -33,
      "y": 199,
      "z": -3,
      "name": "Wood_Giantwood_Trunk_Full"
    },
    {
      "x": -33,
      "y": 198,
      "z": -2,
      "name": "Wood_Giantwood_Trunk_Full"
    },
    {
      "x": -33,
      "y": 199,
      "z": -2,
      "name": "Wood_Giantwood_Trunk"
    },
    {
      "x": -33,
      "y": 200,
      "z": -2,
      "name": "Wood_Giantwood_Trunk_Full"
    },
    {
      "x": -33,
      "y": 199,
      "z": -1,
      "name": "Wood_Giantwood_Trunk_Full"
    },
    {
      "x": -33,
      "y": 200,
      "z": 10,
      "name": "Wood_Giantwood_Trunk_Full"
    },
    {
      "x": -32,
      "y": 22,
      "z": -22,
      "name": "Wood_Giantwood_Trunk_Mossy_Full"
    },
    {
      "x": -32,
      "y": 23,
      "z": -22,
      "name": "Wood_Giantwood_Trunk_Mossy_Full"
    },
    {
      "x": -32,
      "y": 24,
      "z": -22,
      "name": "Wood_Giantwood_Trunk_Mossy_Full"
    },
    {
      "x": -32,
      "y": 25,
      "z": -22,
      "name": "Wood_Giantwood_Trunk_Mossy_Full"
    },
    {
      "x": -32,
      "y": 26,
      "z": -22,
      "name": "Wood_Giantwood_Trunk_Mossy_Full"
    },
    {
      "x": -32,
      "y": 27,
      "z": -22,
      "name": "Wood_Giantwood_Trunk_Mossy_Full"
    },
    {
      "x": -32,
      "y": 20,
      "z": -21,
      "name": "Wood_Giantwood_Trunk_Mossy_Full"
    },
    {
      "x": -32,
      "y": 21,
      "z": -21,
      "name": "Wood_Giantwood_Trunk_Mossy_Full"
    },
    {
      "x": -32,
      "y": 22,
      "z": -21,
      "name": "Wood_Giantwood_Trunk"
    },
    {
      "x": -32,
      "y": 23,
      "z": -21,
      "name": "Wood_Giantwood_Trunk"
    },
    {
      "x": -32,
      "y": 24,
      "z": -21,
      "name": "Wood_Giantwood_Trunk"
    },
    {
      "x": -32,
      "y": 25,
      "z": -21,
      "name": "Wood_Giantwood_Trunk"
    },
    {
      "x": -32,
      "y": 26,
      "z": -21,
      "name": "Wood_Giantwood_Trunk_Mossy_Full"
    },
    {
      "x": -32,
      "y": 27,
      "z": -21,
      "name": "Wood_Giantwood_Trunk_Mossy_Full"
    },
    {
      "x": -32,
      "y": 28,
      "z": -21,
      "name": "Wood_Giantwood_Trunk_Mossy_Full"
    },
    {
      "x": -32,
      "y": 19,
      "z": -20,
      "name": "Wood_Giantwood_Trunk_Mossy_Full"
    },
    {
      "x": -32,
      "y": 20,
      "z": -20,
      "name": "Wood_Giantwood_Trunk"
    },
    {
      "x": -32,
      "y": 21,
      "z": -20,
      "name": "Wood_Giantwood_Trunk"
    },
    {
      "x": -32,
      "y": 22,
      "z": -20,
      "name": "Wood_Giantwood_Trunk"
    },
    {
      "x": -32,
      "y": 23,
      "z": -20,
      "name": "Wood_Giantwood_Trunk"
    },
    {
      "x": -32,
      "y": 24,
      "z": -20,
      "name": "Wood_Giantwood_Trunk"
    },
    {
      "x": -32,
      "y": 25,
      "z": -20,
      "name": "Wood_Giantwood_Trunk"
    },
    {
      "x": -32,
      "y": 26,
      "z": -20,
      "name": "Wood_Giantwood_Trunk"
    },
    {
      "x": -32,
      "y": 27,
      "z": -20,
      "name": "Wood_Giantwood_Trunk"
    },
    {
      "x": -32,
      "y": 28,
      "z": -20,
      "name": "Wood_Giantwood_Trunk_Mossy_Full"
    },
    {
      "x": -32,
      "y": 29,
      "z": -20,
      "name": "Wood_Giantwood_Trunk_Mossy_Full"
    },
    {
      "x": -32,
      "y": 18,
      "z": -19,
      "name": "Wood_Giantwood_Trunk_Mossy_Full"
    },
    {
      "x": -32,
      "y": 19,
      "z": -19,
      "name": "Wood_Giantwood_Trunk"
    },
    {
      "x": -32,
      "y": 20,
      "z": -19,
      "name": "Wood_Giantwood_Trunk"
    },
    {
      "x": -32,
      "y": 21,
      "z": -19,
      "name": "Wood_Giantwood_Trunk"
    },
    {
      "x": -32,
      "y": 22,
      "z": -19,
      "name": "Wood_Giantwood_Trunk"
    },
    {
      "x": -32,
      "y": 23,
      "z": -19,
      "name": "Wood_Giantwood_Trunk"
    },
    {
      "x": -32,
      "y": 24,
      "z": -19,
      "name": "Wood_Giantwood_Trunk"
    },
    {
      "x": -32,
      "y": 25,
      "z": -19,
      "name": "Wood_Giantwood_Trunk"
    },
    {
      "x": -32,
      "y": 26,
      "z": -19,
      "name": "Wood_Giantwood_Trunk"
    },
    {
      "x": -32,
      "y": 27,
      "z": -19,
      "name": "Wood_Giantwood_Trunk"
    },
    {
      "x": -32,
      "y": 28,
      "z": -19,
      "name": "Wood_Giantwood_Trunk_Mossy_Full"
    },
    {
      "x": -32,
      "y": 29,
      "z": -19,
      "name": "Wood_Giantwood_Trunk_Mossy_Full"
    },
    {
      "x": -32,
      "y": 30,
      "z": -19,
      "name": "Wood_Giantwood_Trunk_Mossy_Full"
    },
    {
      "x": -32,
      "y": 17,
      "z": -18,
      "name": "Wood_Giantwood_Trunk_Mossy_Full"
    },
    {
      "x": -32,
      "y": 18,
      "z": -18,
      "name": "Wood_Giantwood_Trunk"
    },
    {
      "x": -32,
      "y": 19,
      "z": -18,
      "name": "Wood_Giantwood_Trunk"
    },
    {
      "x": -32,
      "y": 20,
      "z": -18,
      "name": "Wood_Giantwood_Trunk"
    },
    {
      "x": -32,
      "y": 21,
      "z": -18,
      "name": "Wood_Giantwood_Trunk"
    },
    {
      "x": -32,
      "y": 22,
      "z": -18,
      "name": "Wood_Giantwood_Trunk"
    },
    {
      "x": -32,
      "y": 23,
      "z": -18,
      "name": "Wood_Giantwood_Trunk"
    },
    {
      "x": -32,
      "y": 24,
      "z": -18,
      "name": "Wood_Giantwood_Trunk"
    },
    {
      "x": -32,
      "y": 25,
      "z": -18,
      "name": "Wood_Giantwood_Trunk"
    },
    {
      "x": -32,
      "y": 26,
      "z": -18,
      "name": "Wood_Giantwood_Trunk"
    },
    {
      "x": -32,
      "y": 27,
      "z": -18,
      "name": "Wood_Giantwood_Trunk"
    },
    {
      "x": -32,
      "y": 28,
      "z": -18,
      "name": "Wood_Giantwood_Trunk"
    },
    {
      "x": -32,
      "y": 29,
      "z": -18,
      "name": "Wood_Giantwood_Trunk_Mossy_Full"
    },
    {
      "x": -32,
      "y": 30,
      "z": -18,
      "name": "Wood_Giantwood_Trunk_Mossy_Full"
    },
    {
      "x": -32,
      "y": 31,
      "z": -18,
      "name": "Wood_Giantwood_Trunk_Mossy_Full"
    },
    {
      "x": -32,
      "y": 17,
      "z": -17,
      "name": "Wood_Giantwood_Trunk_Mossy"
    },
    {
      "x": -32,
      "y": 18,
      "z": -17,
      "name": "Wood_Giantwood_Trunk"
    },
    {
      "x": -32,
      "y": 19,
      "z": -17,
      "name": "Wood_Giantwood_Trunk"
    },
    {
      "x": -32,
      "y": 20,
      "z": -17,
      "name": "Wood_Giantwood_Trunk"
    },
    {
      "x": -32,
      "y": 21,
      "z": -17,
      "name": "Wood_Giantwood_Trunk"
    },
    {
      "x": -32,
      "y": 22,
      "z": -17,
      "name": "Wood_Giantwood_Trunk"
    },
    {
      "x": -32,
      "y": 23,
      "z": -17,
      "name": "Wood_Giantwood_Trunk"
    },
    {
      "x": -32,
      "y": 24,
      "z": -17,
      "name": "Wood_Giantwood_Trunk"
    },
    {
      "x": -32,
      "y": 25,
      "z": -17,
      "name": "Wood_Giantwood_Trunk"
    },
    {
      "x": -32,
      "y": 26,
      "z": -17,
      "name": "Wood_Giantwood_Trunk"
    },
    {
      "x": -32,
      "y": 27,
      "z": -17,
      "name": "Wood_Giantwood_Trunk"
    },
    {
      "x": -32,
      "y": 28,
      "z": -17,
      "name": "Wood_Giantwood_Trunk"
    },
    {
      "x": -32,
      "y": 29,
      "z": -17,
      "name": "Wood_Giantwood_Trunk"
    },
    {
      "x": -32,
      "y": 30,
      "z": -17,
      "name": "Wood_Giantwood_Trunk_Mossy_Full"
    },
    {
      "x": -32,
      "y": 31,
      "z": -17,
      "name": "Wood_Giantwood_Trunk_Mossy_Full"
    },
    {
      "x": -32,
      "y": 17,
      "z": -16,
      "name": "Wood_Giantwood_Trunk_Mossy_Full"
    },
    {
      "x": -32,
      "y": 18,
      "z": -16,
      "name": "Wood_Giantwood_Trunk_Mossy_Full"
    },
    {
      "x": -32,
      "y": 19,
      "z": -16,
      "name": "Wood_Giantwood_Trunk"
    },
    {
      "x": -32,
      "y": 20,
      "z": -16,
      "name": "Wood_Giantwood_Trunk"
    },
    {
      "x": -32,
      "y": 21,
      "z": -16,
      "name": "Wood_Giantwood_Trunk"
    },
    {
      "x": -32,
      "y": 22,
      "z": -16,
      "name": "Wood_Giantwood_Trunk"
    },
    {
      "x": -32,
      "y": 23,
      "z": -16,
      "name": "Wood_Giantwood_Trunk"
    },
    {
      "x": -32,
      "y": 24,
      "z": -16,
      "name": "Wood_Giantwood_Trunk"
    },
    {
      "x": -32,
      "y": 25,
      "z": -16,
      "name": "Wood_Giantwood_Trunk"
    },
    {
      "x": -32,
      "y": 26,
      "z": -16,
      "name": "Wood_Giantwood_Trunk"
    },
    {
      "x": -32,
      "y": 27,
      "z": -16,
      "name": "Wood_Giantwood_Trunk"
    },
    {
      "x": -32,
      "y": 28,
      "z": -16,
      "name": "Wood_Giantwood_Trunk"
    },
    {
      "x": -32,
      "y": 29,
      "z": -16,
      "name": "Wood_Giantwood_Trunk"
    },
    {
      "x": -32,
      "y": 30,
      "z": -16,
      "name": "Wood_Giantwood_Trunk_Mossy_Full"
    },
    {
      "x": -32,
      "y": 31,
      "z": -16,
      "name": "Wood_Giantwood_Trunk_Mossy_Full"
    },
    {
      "x": -32,
      "y": 204,
      "z": -16,
      "name": "Wood_Giantwood_Trunk_Full"
    },
    {
      "x": -32,
      "y": 18,
      "z": -15,
      "name": "Wood_Giantwood_Trunk_Mossy"
    },
    {
      "x": -32,
      "y": 19,
      "z": -15,
      "name": "Wood_Giantwood_Trunk_Mossy_Full"
    },
    {
      "x": -32,
      "y": 20,
      "z": -15,
      "name": "Wood_Giantwood_Trunk"
    },
    {
      "x": -32,
      "y": 21,
      "z": -15,
      "name": "Wood_Giantwood_Trunk"
    },
    {
      "x": -32,
      "y": 22,
      "z": -15,
      "name": "Wood_Giantwood_Trunk"
    },
    {
      "x": -32,
      "y": 23,
      "z": -15,
      "name": "Wood_Giantwood_Trunk"
    },
    {
      "x": -32,
      "y": 24,
      "z": -15,
      "name": "Wood_Giantwood_Trunk"
    },
    {
      "x": -32,
      "y": 25,
      "z": -15,
      "name": "Wood_Giantwood_Trunk"
    },
    {
      "x": -32,
      "y": 26,
      "z": -15,
      "name": "Wood_Giantwood_Trunk"
    },
    {
      "x": -32,
      "y": 27,
      "z": -15,
      "name": "Wood_Giantwood_Trunk"
    },
    {
      "x": -32,
      "y": 28,
      "z": -15,
      "name": "Wood_Giantwood_Trunk"
    },
    {
      "x": -32,
      "y": 29,
      "z": -15,
      "name": "Wood_Giantwood_Trunk"
    },
    {
      "x": -32,
      "y": 30,
      "z": -15,
      "name": "Wood_Giantwood_Trunk_Mossy_Full"
    },
    {
      "x": -32,
      "y": 31,
      "z": -15,
      "name": "Wood_Giantwood_Trunk_Mossy_Full"
    },
    {
      "x": -32,
      "y": 19,
      "z": -14,
      "name": "Wood_Giantwood_Trunk_Mossy_Full"
    },
    {
      "x": -32,
      "y": 20,
      "z": -14,
      "name": "Wood_Giantwood_Trunk_Mossy_Full"
    },
    {
      "x": -32,
      "y": 21,
      "z": -14,
      "name": "Wood_Giantwood_Trunk_Mossy_Full"
    },
    {
      "x": -32,
      "y": 22,
      "z": -14,
      "name": "Wood_Giantwood_Trunk_Mossy_Full"
    },
    {
      "x": -32,
      "y": 23,
      "z": -14,
      "name": "Wood_Giantwood_Trunk"
    },
    {
      "x": -32,
      "y": 24,
      "z": -14,
      "name": "Wood_Giantwood_Trunk"
    },
    {
      "x": -32,
      "y": 25,
      "z": -14,
      "name": "Wood_Giantwood_Trunk"
    },
    {
      "x": -32,
      "y": 26,
      "z": -14,
      "name": "Wood_Giantwood_Trunk"
    },
    {
      "x": -32,
      "y": 27,
      "z": -14,
      "name": "Wood_Giantwood_Trunk"
    },
    {
      "x": -32,
      "y": 28,
      "z": -14,
      "name": "Wood_Giantwood_Trunk"
    },
    {
      "x": -32,
      "y": 29,
      "z": -14,
      "name": "Wood_Giantwood_Trunk"
    },
    {
      "x": -32,
      "y": 30,
      "z": -14,
      "name": "Wood_Giantwood_Trunk_Mossy_Full"
    },
    {
      "x": -32,
      "y": 31,
      "z": -14,
      "name": "Wood_Giantwood_Trunk_Mossy_Full"
    },
    {
      "x": -32,
      "y": 21,
      "z": -13,
      "name": "Wood_Giantwood_Trunk_Mossy_Full"
    },
    {
      "x": -32,
      "y": 22,
      "z": -13,
      "name": "Wood_Giantwood_Trunk_Mossy_Full"
    },
    {
      "x": -32,
      "y": 23,
      "z": -13,
      "name": "Wood_Giantwood_Trunk_Mossy_Full"
    },
    {
      "x": -32,
      "y": 24,
      "z": -13,
      "name": "Wood_Giantwood_Trunk_Mossy_Full"
    },
    {
      "x": -32,
      "y": 25,
      "z": -13,
      "name": "Wood_Giantwood_Trunk"
    },
    {
      "x": -32,
      "y": 26,
      "z": -13,
      "name": "Wood_Giantwood_Trunk_Mossy_Full"
    },
    {
      "x": -32,
      "y": 27,
      "z": -13,
      "name": "Wood_Giantwood_Trunk_Mossy_Full"
    },
    {
      "x": -32,
      "y": 28,
      "z": -13,
      "name": "Wood_Giantwood_Trunk_Mossy_Full"
    },
    {
      "x": -32,
      "y": 29,
      "z": -13,
      "name": "Wood_Giantwood_Trunk_Mossy_Full"
    },
    {
      "x": -32,
      "y": 30,
      "z": -13,
      "name": "Wood_Giantwood_Trunk_Mossy_Full"
    },
    {
      "x": -32,
      "y": 25,
      "z": -12,
      "name": "Wood_Giantwood_Trunk_Mossy_Full"
    },
    {
      "x": -32,
      "y": 26,
      "z": -12,
      "name": "Wood_Giantwood_Trunk_Mossy_Full"
    },
    {
      "x": -32,
      "y": 27,
      "z": -12,
      "name": "Wood_Giantwood_Trunk_Mossy_Full"
    },
    {
      "x": -32,
      "y": 28,
      "z": -12,
      "name": "Wood_Giantwood_Trunk_Mossy_Full"
    },
    {
      "x": -32,
      "y": 29,
      "z": -12,
      "name": "Wood_Giantwood_Trunk_Mossy_Full"
    },
    {
      "x": -32,
      "y": 199,
      "z": -3,
      "name": "Wood_Giantwood_Trunk_Full"
    },
    {
      "x": -32,
      "y": 198,
      "z": -2,
      "name": "Wood_Giantwood_Trunk_Full"
    },
    {
      "x": -32,
      "y": 199,
      "z": -2,
      "name": "Wood_Giantwood_Trunk_Full"
    },
    {
      "x": -32,
      "y": 200,
      "z": -2,
      "name": "Wood_Giantwood_Trunk_Full"
    },
    {
      "x": -32,
      "y": 199,
      "z": -1,
      "name": "Wood_Giantwood_Trunk_Full"
    },
    {
      "x": -32,
      "y": 200,
      "z": 10,
      "name": "Wood_Giantwood_Trunk_Full"
    },
    {
      "x": -31,
      "y": 22,
      "z": -22,
      "name": "Wood_Giantwood_Trunk_Mossy_Full"
    },
    {
      "x": -31,
      "y": 23,
      "z": -22,
      "name": "Wood_Giantwood_Trunk_Mossy_Full"
    },
    {
      "x": -31,
      "y": 24,
      "z": -22,
      "name": "Wood_Giantwood_Trunk_Mossy_Full"
    },
    {
      "x": -31,
      "y": 25,
      "z": -22,
      "name": "Wood_Giantwood_Trunk_Mossy_Full"
    },
    {
      "x": -31,
      "y": 26,
      "z": -22,
      "name": "Wood_Giantwood_Trunk_Mossy_Full"
    },
    {
      "x": -31,
      "y": 27,
      "z": -22,
      "name": "Wood_Giantwood_Trunk_Mossy_Full"
    },
    {
      "x": -31,
      "y": 28,
      "z": -22,
      "name": "Wood_Giantwood_Trunk_Mossy_Full"
    },
    {
      "x": -31,
      "y": 20,
      "z": -21,
      "name": "Wood_Giantwood_Trunk_Mossy_Full"
    },
    {
      "x": -31,
      "y": 21,
      "z": -21,
      "name": "Wood_Giantwood_Trunk_Mossy_Full"
    },
    {
      "x": -31,
      "y": 22,
      "z": -21,
      "name": "Wood_Giantwood_Trunk"
    },
    {
      "x": -31,
      "y": 23,
      "z": -21,
      "name": "Wood_Giantwood_Trunk"
    },
    {
      "x": -31,
      "y": 24,
      "z": -21,
      "name": "Wood_Giantwood_Trunk"
    },
    {
      "x": -31,
      "y": 25,
      "z": -21,
      "name": "Wood_Giantwood_Trunk"
    },
    {
      "x": -31,
      "y": 26,
      "z": -21,
      "name": "Wood_Giantwood_Trunk"
    },
    {
      "x": -31,
      "y": 27,
      "z": -21,
      "name": "Wood_Giantwood_Trunk"
    },
    {
      "x": -31,
      "y": 28,
      "z": -21,
      "name": "Wood_Giantwood_Trunk_Mossy_Full"
    },
    {
      "x": -31,
      "y": 29,
      "z": -21,
      "name": "Wood_Giantwood_Trunk_Mossy_Full"
    },
    {
      "x": -31,
      "y": 18,
      "z": -20,
      "name": "Wood_Giantwood_Trunk_Mossy_Full"
    },
    {
      "x": -31,
      "y": 19,
      "z": -20,
      "name": "Wood_Giantwood_Trunk_Mossy_Full"
    },
    {
      "x": -31,
      "y": 20,
      "z": -20,
      "name": "Wood_Giantwood_Trunk"
    },
    {
      "x": -31,
      "y": 21,
      "z": -20,
      "name": "Wood_Giantwood_Trunk"
    },
    {
      "x": -31,
      "y": 22,
      "z": -20,
      "name": "Wood_Giantwood_Trunk"
    },
    {
      "x": -31,
      "y": 23,
      "z": -20,
      "name": "Wood_Giantwood_Trunk"
    },
    {
      "x": -31,
      "y": 24,
      "z": -20,
      "name": "Wood_Giantwood_Trunk"
    },
    {
      "x": -31,
      "y": 25,
      "z": -20,
      "name": "Wood_Giantwood_Trunk"
    },
    {
      "x": -31,
      "y": 26,
      "z": -20,
      "name": "Wood_Giantwood_Trunk"
    },
    {
      "x": -31,
      "y": 27,
      "z": -20,
      "name": "Wood_Giantwood_Trunk"
    },
    {
      "x": -31,
      "y": 28,
      "z": -20,
      "name": "Wood_Giantwood_Trunk_Mossy_Full"
    },
    {
      "x": -31,
      "y": 29,
      "z": -20,
      "name": "Wood_Giantwood_Trunk_Mossy_Full"
    },
    {
      "x": -31,
      "y": 30,
      "z": -20,
      "name": "Wood_Giantwood_Trunk_Mossy_Full"
    },
    {
      "x": -31,
      "y": 17,
      "z": -19,
      "name": "Wood_Giantwood_Trunk_Mossy_Full"
    },
    {
      "x": -31,
      "y": 18,
      "z": -19,
      "name": "Wood_Giantwood_Trunk"
    },
    {
      "x": -31,
      "y": 19,
      "z": -19,
      "name": "Wood_Giantwood_Trunk"
    },
    {
      "x": -31,
      "y": 20,
      "z": -19,
      "name": "Wood_Giantwood_Trunk"
    },
    {
      "x": -31,
      "y": 21,
      "z": -19,
      "name": "Wood_Giantwood_Trunk"
    },
    {
      "x": -31,
      "y": 22,
      "z": -19,
      "name": "Wood_Giantwood_Trunk"
    },
    {
      "x": -31,
      "y": 23,
      "z": -19,
      "name": "Wood_Giantwood_Trunk"
    },
    {
      "x": -31,
      "y": 24,
      "z": -19,
      "name": "Wood_Giantwood_Trunk"
    },
    {
      "x": -31,
      "y": 25,
      "z": -19,
      "name": "Wood_Giantwood_Trunk"
    },
    {
      "x": -31,
      "y": 26,
      "z": -19,
      "name": "Wood_Giantwood_Trunk"
    },
    {
      "x": -31,
      "y": 27,
      "z": -19,
      "name": "Wood_Giantwood_Trunk"
    },
    {
      "x": -31,
      "y": 28,
      "z": -19,
      "name": "Wood_Giantwood_Trunk"
    },
    {
      "x": -31,
      "y": 29,
      "z": -19,
      "name": "Wood_Giantwood_Trunk_Mossy_Full"
    },
    {
      "x": -31,
      "y": 30,
      "z": -19,
      "name": "Wood_Giantwood_Trunk_Mossy_Full"
    },
    {
      "x": -31,
      "y": 31,
      "z": -19,
      "name": "Wood_Giantwood_Trunk_Mossy_Full"
    },
    {
      "x": -31,
      "y": 16,
      "z": -18,
      "name": "Wood_Giantwood_Trunk_Mossy"
    },
    {
      "x": -31,
      "y": 17,
      "z": -18,
      "name": "Wood_Giantwood_Trunk"
    },
    {
      "x": -31,
      "y": 18,
      "z": -18,
      "name": "Wood_Giantwood_Trunk"
    },
    {
      "x": -31,
      "y": 19,
      "z": -18,
      "name": "Wood_Giantwood_Trunk"
    },
    {
      "x": -31,
      "y": 20,
      "z": -18,
      "name": "Wood_Giantwood_Trunk"
    },
    {
      "x": -31,
      "y": 21,
      "z": -18,
      "name": "Wood_Giantwood_Trunk"
    },
    {
      "x": -31,
      "y": 22,
      "z": -18,
      "name": "Wood_Giantwood_Trunk"
    },
    {
      "x": -31,
      "y": 23,
      "z": -18,
      "name": "Wood_Giantwood_Trunk"
    },
    {
      "x": -31,
      "y": 24,
      "z": -18,
      "name": "Wood_Giantwood_Trunk"
    },
    {
      "x": -31,
      "y": 25,
      "z": -18,
      "name": "Wood_Giantwood_Trunk"
    },
    {
      "x": -31,
      "y": 26,
      "z": -18,
      "name": "Wood_Giantwood_Trunk"
    },
    {
      "x": -31,
      "y": 27,
      "z": -18,
      "name": "Wood_Giantwood_Trunk"
    },
    {
      "x": -31,
      "y": 28,
      "z": -18,
      "name": "Wood_Giantwood_Trunk"
    },
    {
      "x": -31,
      "y": 29,
      "z": -18,
      "name": "Wood_Giantwood_Trunk"
    },
    {
      "x": -31,
      "y": 30,
      "z": -18,
      "name": "Wood_Giantwood_Trunk_Mossy_Full"
    },
    {
      "x": -31,
      "y": 31,
      "z": -18,
      "name": "Wood_Giantwood_Trunk_Mossy_Full"
    },
    {
      "x": -31,
      "y": 16,
      "z": -17,
      "name": "Wood_Giantwood_Trunk_Mossy"
    },
    {
      "x": -31,
      "y": 17,
      "z": -17,
      "name": "Wood_Giantwood_Trunk"
    },
    {
      "x": -31,
      "y": 18,
      "z": -17,
      "name": "Wood_Giantwood_Trunk"
    },
    {
      "x": -31,
      "y": 19,
      "z": -17,
      "name": "Wood_Giantwood_Trunk"
    },
    {
      "x": -31,
      "y": 20,
      "z": -17,
      "name": "Wood_Giantwood_Trunk"
    },
    {
      "x": -31,
      "y": 21,
      "z": -17,
      "name": "Wood_Giantwood_Trunk"
    },
    {
      "x": -31,
      "y": 22,
      "z": -17,
      "name": "Wood_Giantwood_Trunk"
    },
    {
      "x": -31,
      "y": 23,
      "z": -17,
      "name": "Wood_Giantwood_Trunk"
    },
    {
      "x": -31,
      "y": 24,
      "z": -17,
      "name": "Wood_Giantwood_Trunk"
    },
    {
      "x": -31,
      "y": 25,
      "z": -17,
      "name": "Wood_Giantwood_Trunk"
    },
    {
      "x": -31,
      "y": 26,
      "z": -17,
      "name": "Wood_Giantwood_Trunk"
    },
    {
      "x": -31,
      "y": 27,
      "z": -17,
      "name": "Wood_Giantwood_Trunk"
    },
    {
      "x": -31,
      "y": 28,
      "z": -17,
      "name": "Wood_Giantwood_Trunk"
    },
    {
      "x": -31,
      "y": 29,
      "z": -17,
      "name": "Wood_Giantwood_Trunk"
    },
    {
      "x": -31,
      "y": 30,
      "z": -17,
      "name": "Wood_Giantwood_Trunk"
    },
    {
      "x": -31,
      "y": 31,
      "z": -17,
      "name": "Wood_Giantwood_Trunk_Mossy_Full"
    },
    {
      "x": -31,
      "y": 32,
      "z": -17,
      "name": "Wood_Giantwood_Trunk_Mossy_Full"
    },
    {
      "x": -31,
      "y": 16,
      "z": -16,
      "name": "Wood_Giantwood_Trunk_Mossy_Full"
    },
    {
      "x": -31,
      "y": 17,
      "z": -16,
      "name": "Wood_Giantwood_Trunk_Mossy_Full"
    },
    {
      "x": -31,
      "y": 18,
      "z": -16,
      "name": "Wood_Giantwood_Trunk"
    },
    {
      "x": -31,
      "y": 19,
      "z": -16,
      "name": "Wood_Giantwood_Trunk"
    },
    {
      "x": -31,
      "y": 20,
      "z": -16,
      "name": "Wood_Giantwood_Trunk"
    },
    {
      "x": -31,
      "y": 21,
      "z": -16,
      "name": "Wood_Giantwood_Trunk"
    },
    {
      "x": -31,
      "y": 22,
      "z": -16,
      "name": "Wood_Giantwood_Trunk"
    },
    {
      "x": -31,
      "y": 23,
      "z": -16,
      "name": "Wood_Giantwood_Trunk"
    },
    {
      "x": -31,
      "y": 24,
      "z": -16,
      "name": "Wood_Giantwood_Trunk"
    },
    {
      "x": -31,
      "y": 25,
      "z": -16,
      "name": "Wood_Giantwood_Trunk"
    },
    {
      "x": -31,
      "y": 26,
      "z": -16,
      "name": "Wood_Giantwood_Trunk"
    },
    {
      "x": -31,
      "y": 27,
      "z": -16,
      "name": "Wood_Giantwood_Trunk"
    },
    {
      "x": -31,
      "y": 28,
      "z": -16,
      "name": "Wood_Giantwood_Trunk"
    },
    {
      "x": -31,
      "y": 29,
      "z": -16,
      "name": "Wood_Giantwood_Trunk"
    },
    {
      "x": -31,
      "y": 30,
      "z": -16,
      "name": "Wood_Giantwood_Trunk"
    },
    {
      "x": -31,
      "y": 31,
      "z": -16,
      "name": "Wood_Giantwood_Trunk_Mossy_Full"
    },
    {
      "x": -31,
      "y": 32,
      "z": -16,
      "name": "Wood_Giantwood_Trunk_Mossy_Full"
    },
    {
      "x": -31,
      "y": 16,
      "z": -15,
      "name": "Wood_Giantwood_Trunk_Mossy_Full"
    },
    {
      "x": -31,
      "y": 17,
      "z": -15,
      "name": "Wood_Giantwood_Trunk_Mossy"
    },
    {
      "x": -31,
      "y": 18,
      "z": -15,
      "name": "Wood_Giantwood_Trunk_Mossy_Full"
    },
    {
      "x": -31,
      "y": 19,
      "z": -15,
      "name": "Wood_Giantwood_Trunk"
    },
    {
      "x": -31,
      "y": 20,
      "z": -15,
      "name": "Wood_Giantwood_Trunk"
    },
    {
      "x": -31,
      "y": 21,
      "z": -15,
      "name": "Wood_Giantwood_Trunk"
    },
    {
      "x": -31,
      "y": 22,
      "z": -15,
      "name": "Wood_Giantwood_Trunk"
    },
    {
      "x": -31,
      "y": 23,
      "z": -15,
      "name": "Wood_Giantwood_Trunk"
    },
    {
      "x": -31,
      "y": 24,
      "z": -15,
      "name": "Wood_Giantwood_Trunk"
    },
    {
      "x": -31,
      "y": 25,
      "z": -15,
      "name": "Wood_Giantwood_Trunk"
    },
    {
      "x": -31,
      "y": 26,
      "z": -15,
      "name": "Wood_Giantwood_Trunk"
    },
    {
      "x": -31,
      "y": 27,
      "z": -15,
      "name": "Wood_Giantwood_Trunk"
    },
    {
      "x": -31,
      "y": 28,
      "z": -15,
      "name": "Wood_Giantwood_Trunk"
    },
    {
      "x": -31,
      "y": 29,
      "z": -15,
      "name": "Wood_Giantwood_Trunk"
    },
    {
      "x": -31,
      "y": 30,
      "z": -15,
      "name": "Wood_Giantwood_Trunk"
    },
    {
      "x": -31,
      "y": 31,
      "z": -15,
      "name": "Wood_Giantwood_Trunk_Mossy_Full"
    },
    {
      "x": -31,
      "y": 204,
      "z": -15,
      "name": "Wood_Giantwood_Trunk_Full"
    },
    {
      "x": -31,
      "y": 17,
      "z": -14,
      "name": "Wood_Giantwood_Trunk_Mossy"
    },
    {
      "x": -31,
      "y": 18,
      "z": -14,
      "name": "Wood_Giantwood_Trunk_Mossy_Full"
    },
    {
      "x": -31,
      "y": 19,
      "z": -14,
      "name": "Wood_Giantwood_Trunk_Mossy_Full"
    },
    {
      "x": -31,
      "y": 20,
      "z": -14,
      "name": "Wood_Giantwood_Trunk_Mossy_Full"
    },
    {
      "x": -31,
      "y": 21,
      "z": -14,
      "name": "Wood_Giantwood_Trunk"
    },
    {
      "x": -31,
      "y": 22,
      "z": -14,
      "name": "Wood_Giantwood_Trunk"
    },
    {
      "x": -31,
      "y": 23,
      "z": -14,
      "name": "Wood_Giantwood_Trunk"
    },
    {
      "x": -31,
      "y": 24,
      "z": -14,
      "name": "Wood_Giantwood_Trunk"
    },
    {
      "x": -31,
      "y": 25,
      "z": -14,
      "name": "Wood_Giantwood_Trunk"
    },
    {
      "x": -31,
      "y": 26,
      "z": -14,
      "name": "Wood_Giantwood_Trunk"
    },
    {
      "x": -31,
      "y": 27,
      "z": -14,
      "name": "Wood_Giantwood_Trunk"
    },
    {
      "x": -31,
      "y": 28,
      "z": -14,
      "name": "Wood_Giantwood_Trunk"
    },
    {
      "x": -31,
      "y": 29,
      "z": -14,
      "name": "Wood_Giantwood_Trunk"
    },
    {
      "x": -31,
      "y": 30,
      "z": -14,
      "name": "Wood_Giantwood_Trunk"
    },
    {
      "x": -31,
      "y": 31,
      "z": -14,
      "name": "Wood_Giantwood_Trunk_Mossy_Full"
    },
    {
      "x": -31,
      "y": 20,
      "z": -13,
      "name": "Wood_Giantwood_Trunk_Mossy_Full"
    },
    {
      "x": -31,
      "y": 21,
      "z": -13,
      "name": "Wood_Giantwood_Trunk_Mossy_Full"
    },
    {
      "x": -31,
      "y": 22,
      "z": -13,
      "name": "Wood_Giantwood_Trunk_Mossy_Full"
    },
    {
      "x": -31,
      "y": 23,
      "z": -13,
      "name": "Wood_Giantwood_Trunk_Mossy_Full"
    },
    {
      "x": -31,
      "y": 24,
      "z": -13,
      "name": "Wood_Giantwood_Trunk_Mossy_Full"
    },
    {
      "x": -31,
      "y": 25,
      "z": -13,
      "name": "Wood_Giantwood_Trunk"
    },
    {
      "x": -31,
      "y": 26,
      "z": -13,
      "name": "Wood_Giantwood_Trunk"
    },
    {
      "x": -31,
      "y": 27,
      "z": -13,
      "name": "Wood_Giantwood_Trunk"
    },
    {
      "x": -31,
      "y": 28,
      "z": -13,
      "name": "Wood_Giantwood_Trunk"
    },
    {
      "x": -31,
      "y": 29,
      "z": -13,
      "name": "Wood_Giantwood_Trunk"
    },
    {
      "x": -31,
      "y": 30,
      "z": -13,
      "name": "Wood_Giantwood_Trunk_Mossy_Full"
    },
    {
      "x": -31,
      "y": 31,
      "z": -13,
      "name": "Wood_Giantwood_Trunk_Mossy_Full"
    },
    {
      "x": -31,
      "y": 24,
      "z": -12,
      "name": "Wood_Giantwood_Trunk_Mossy_Full"
    },
    {
      "x": -31,
      "y": 25,
      "z": -12,
      "name": "Wood_Giantwood_Trunk_Mossy_Full"
    },
    {
      "x": -31,
      "y": 26,
      "z": -12,
      "name": "Wood_Giantwood_Trunk_Mossy_Full"
    },
    {
      "x": -31,
      "y": 27,
      "z": -12,
      "name": "Wood_Giantwood_Trunk_Mossy_Full"
    },
    {
      "x": -31,
      "y": 28,
      "z": -12,
      "name": "Wood_Giantwood_Trunk_Mossy_Full"
    },
    {
      "x": -31,
      "y": 29,
      "z": -12,
      "name": "Wood_Giantwood_Trunk_Mossy_Full"
    },
    {
      "x": -31,
      "y": 30,
      "z": -12,
      "name": "Wood_Giantwood_Trunk_Mossy_Full"
    },
    {
      "x": -31,
      "y": 27,
      "z": -11,
      "name": "Wood_Giantwood_Trunk_Mossy_Full"
    },
    {
      "x": -31,
      "y": 28,
      "z": -11,
      "name": "Wood_Giantwood_Trunk_Mossy_Full"
    },
    {
      "x": -31,
      "y": 198,
      "z": -3,
      "name": "Wood_Giantwood_Trunk_Full"
    },
    {
      "x": -31,
      "y": 197,
      "z": -2,
      "name": "Wood_Giantwood_Trunk_Full"
    },
    {
      "x": -31,
      "y": 198,
      "z": -2,
      "name": "Wood_Giantwood_Trunk"
    },
    {
      "x": -31,
      "y": 199,
      "z": -2,
      "name": "Wood_Giantwood_Trunk_Full"
    },
    {
      "x": -31,
      "y": 198,
      "z": -1,
      "name": "Wood_Giantwood_Trunk_Full"
    },
    {
      "x": -31,
      "y": 199,
      "z": 10,
      "name": "Wood_Giantwood_Trunk_Full"
    },
    {
      "x": -31,
      "y": 200,
      "z": 10,
      "name": "Wood_Giantwood_Trunk_Full"
    },
    {
      "x": -30,
      "y": 23,
      "z": -22,
      "name": "Wood_Giantwood_Trunk_Mossy_Full"
    },
    {
      "x": -30,
      "y": 24,
      "z": -22,
      "name": "Wood_Giantwood_Trunk_Mossy_Full"
    },
    {
      "x": -30,
      "y": 25,
      "z": -22,
      "name": "Wood_Giantwood_Trunk_Mossy_Full"
    },
    {
      "x": -30,
      "y": 26,
      "z": -22,
      "name": "Wood_Giantwood_Trunk_Mossy_Full"
    },
    {
      "x": -30,
      "y": 27,
      "z": -22,
      "name": "Wood_Giantwood_Trunk_Mossy_Full"
    },
    {
      "x": -30,
      "y": 28,
      "z": -22,
      "name": "Wood_Giantwood_Trunk_Mossy_Full"
    },
    {
      "x": -30,
      "y": 20,
      "z": -21,
      "name": "Wood_Giantwood_Trunk_Mossy_Full"
    },
    {
      "x": -30,
      "y": 21,
      "z": -21,
      "name": "Wood_Giantwood_Trunk_Mossy_Full"
    },
    {
      "x": -30,
      "y": 22,
      "z": -21,
      "name": "Wood_Giantwood_Trunk_Mossy_Full"
    },
    {
      "x": -30,
      "y": 23,
      "z": -21,
      "name": "Wood_Giantwood_Trunk_Mossy_Full"
    },
    {
      "x": -30,
      "y": 24,
      "z": -21,
      "name": "Wood_Giantwood_Trunk"
    },
    {
      "x": -30,
      "y": 25,
      "z": -21,
      "name": "Wood_Giantwood_Trunk"
    },
    {
      "x": -30,
      "y": 26,
      "z": -21,
      "name": "Wood_Giantwood_Trunk"
    },
    {
      "x": -30,
      "y": 27,
      "z": -21,
      "name": "Wood_Giantwood_Trunk"
    },
    {
      "x": -30,
      "y": 28,
      "z": -21,
      "name": "Wood_Giantwood_Trunk_Full"
    },
    {
      "x": -30,
      "y": 29,
      "z": -21,
      "name": "Wood_Giantwood_Trunk_Mossy_Full"
    },
    {
      "x": -30,
      "y": 18,
      "z": -20,
      "name": "Wood_Giantwood_Trunk_Mossy_Full"
    },
    {
      "x": -30,
      "y": 19,
      "z": -20,
      "name": "Wood_Giantwood_Trunk_Mossy_Full"
    },
    {
      "x": -30,
      "y": 20,
      "z": -20,
      "name": "Wood_Giantwood_Trunk_Mossy_Full"
    },
    {
      "x": -30,
      "y": 21,
      "z": -20,
      "name": "Wood_Giantwood_Trunk_Mossy_Full"
    },
    {
      "x": -30,
      "y": 22,
      "z": -20,
      "name": "Wood_Giantwood_Trunk"
    },
    {
      "x": -30,
      "y": 23,
      "z": -20,
      "name": "Wood_Giantwood_Trunk"
    },
    {
      "x": -30,
      "y": 24,
      "z": -20,
      "name": "Wood_Giantwood_Trunk"
    },
    {
      "x": -30,
      "y": 25,
      "z": -20,
      "name": "Wood_Giantwood_Trunk"
    },
    {
      "x": -30,
      "y": 26,
      "z": -20,
      "name": "Wood_Giantwood_Trunk"
    },
    {
      "x": -30,
      "y": 27,
      "z": -20,
      "name": "Wood_Giantwood_Trunk"
    },
    {
      "x": -30,
      "y": 28,
      "z": -20,
      "name": "Wood_Giantwood_Trunk"
    },
    {
      "x": -30,
      "y": 29,
      "z": -20,
      "name": "Wood_Giantwood_Trunk_Mossy_Full"
    },
    {
      "x": -30,
      "y": 30,
      "z": -20,
      "name": "Wood_Giantwood_Trunk_Mossy_Full"
    },
    {
      "x": -30,
      "y": 17,
      "z": -19,
      "name": "Wood_Giantwood_Trunk_Mossy_Full"
    },
    {
      "x": -30,
      "y": 18,
      "z": -19,
      "name": "Wood_Giantwood_Trunk"
    },
    {
      "x": -30,
      "y": 19,
      "z": -19,
      "name": "Wood_Giantwood_Trunk"
    },
    {
      "x": -30,
      "y": 20,
      "z": -19,
      "name": "Wood_Giantwood_Trunk"
    },
    {
      "x": -30,
      "y": 21,
      "z": -19,
      "name": "Wood_Giantwood_Trunk"
    },
    {
      "x": -30,
      "y": 22,
      "z": -19,
      "name": "Wood_Giantwood_Trunk"
    },
    {
      "x": -30,
      "y": 23,
      "z": -19,
      "name": "Wood_Giantwood_Trunk"
    },
    {
      "x": -30,
      "y": 24,
      "z": -19,
      "name": "Wood_Giantwood_Trunk"
    },
    {
      "x": -30,
      "y": 25,
      "z": -19,
      "name": "Wood_Giantwood_Trunk"
    },
    {
      "x": -30,
      "y": 26,
      "z": -19,
      "name": "Wood_Giantwood_Trunk"
    },
    {
      "x": -30,
      "y": 27,
      "z": -19,
      "name": "Wood_Giantwood_Trunk"
    },
    {
      "x": -30,
      "y": 28,
      "z": -19,
      "name": "Wood_Giantwood_Trunk"
    },
    {
      "x": -30,
      "y": 29,
      "z": -19,
      "name": "Wood_Giantwood_Trunk"
    },
    {
      "x": -30,
      "y": 30,
      "z": -19,
      "name": "Wood_Giantwood_Trunk_Mossy_Full"
    },
    {
      "x": -30,
      "y": 31,
      "z": -19,
      "name": "Wood_Giantwood_Trunk_Mossy_Full"
    },
    {
      "x": -30,
      "y": 15,
      "z": -18,
      "name": "Wood_Giantwood_Roots"
    },
    {
      "x": -30,
      "y": 16,
      "z": -18,
      "name": "Wood_Giantwood_Trunk_Mossy"
    },
    {
      "x": -30,
      "y": 17,
      "z": -18,
      "name": "Wood_Giantwood_Trunk"
    },
    {
      "x": -30,
      "y": 18,
      "z": -18,
      "name": "Wood_Giantwood_Trunk"
    },
    {
      "x": -30,
      "y": 19,
      "z": -18,
      "name": "Wood_Giantwood_Trunk"
    },
    {
      "x": -30,
      "y": 20,
      "z": -18,
      "name": "Wood_Giantwood_Trunk"
    },
    {
      "x": -30,
      "y": 21,
      "z": -18,
      "name": "Wood_Giantwood_Trunk"
    },
    {
      "x": -30,
      "y": 22,
      "z": -18,
      "name": "Wood_Giantwood_Trunk"
    },
    {
      "x": -30,
      "y": 23,
      "z": -18,
      "name": "Wood_Giantwood_Trunk"
    },
    {
      "x": -30,
      "y": 24,
      "z": -18,
      "name": "Wood_Giantwood_Trunk"
    },
    {
      "x": -30,
      "y": 25,
      "z": -18,
      "name": "Wood_Giantwood_Trunk"
    },
    {
      "x": -30,
      "y": 26,
      "z": -18,
      "name": "Wood_Giantwood_Trunk"
    },
    {
      "x": -30,
      "y": 27,
      "z": -18,
      "name": "Wood_Giantwood_Trunk"
    },
    {
      "x": -30,
      "y": 28,
      "z": -18,
      "name": "Wood_Giantwood_Trunk"
    },
    {
      "x": -30,
      "y": 29,
      "z": -18,
      "name": "Wood_Giantwood_Trunk"
    },
    {
      "x": -30,
      "y": 30,
      "z": -18,
      "name": "Wood_Giantwood_Trunk"
    },
    {
      "x": -30,
      "y": 31,
      "z": -18,
      "name": "Wood_Giantwood_Trunk_Mossy_Full"
    },
    {
      "x": -30,
      "y": 32,
      "z": -18,
      "name": "Wood_Giantwood_Trunk_Mossy_Full"
    },
    {
      "x": -30,
      "y": 16,
      "z": -17,
      "name": "Wood_Giantwood_Trunk_Full"
    },
    {
      "x": -30,
      "y": 17,
      "z": -17,
      "name": "Wood_Giantwood_Trunk"
    },
    {
      "x": -30,
      "y": 18,
      "z": -17,
      "name": "Wood_Giantwood_Trunk"
    },
    {
      "x": -30,
      "y": 19,
      "z": -17,
      "name": "Wood_Giantwood_Trunk"
    },
    {
      "x": -30,
      "y": 20,
      "z": -17,
      "name": "Wood_Giantwood_Trunk"
    },
    {
      "x": -30,
      "y": 21,
      "z": -17,
      "name": "Wood_Giantwood_Trunk"
    },
    {
      "x": -30,
      "y": 22,
      "z": -17,
      "name": "Wood_Giantwood_Trunk"
    },
    {
      "x": -30,
      "y": 23,
      "z": -17,
      "name": "Wood_Giantwood_Trunk"
    },
    {
      "x": -30,
      "y": 24,
      "z": -17,
      "name": "Wood_Giantwood_Trunk"
    },
    {
      "x": -30,
      "y": 25,
      "z": -17,
      "name": "Wood_Giantwood_Trunk"
    },
    {
      "x": -30,
      "y": 26,
      "z": -17,
      "name": "Wood_Giantwood_Trunk"
    },
    {
      "x": -30,
      "y": 27,
      "z": -17,
      "name": "Wood_Giantwood_Trunk"
    },
    {
      "x": -30,
      "y": 28,
      "z": -17,
      "name": "Wood_Giantwood_Trunk"
    },
    {
      "x": -30,
      "y": 29,
      "z": -17,
      "name": "Wood_Giantwood_Trunk"
    },
    {
      "x": -30,
      "y": 30,
      "z": -17,
      "name": "Wood_Giantwood_Trunk"
    },
    {
      "x": -30,
      "y": 31,
      "z": -17,
      "name": "Wood_Giantwood_Trunk_Mossy_Full"
    },
    {
      "x": -30,
      "y": 32,
      "z": -17,
      "name": "Wood_Giantwood_Trunk_Mossy_Full"
    },
    {
      "x": -30,
      "y": 15,
      "z": -16,
      "name": "Wood_Giantwood_Trunk_Mossy"
    },
    {
      "x": -30,
      "y": 16,
      "z": -16,
      "name": "Wood_Giantwood_Trunk"
    },
    {
      "x": -30,
      "y": 17,
      "z": -16,
      "name": "Wood_Giantwood_Trunk"
    },
    {
      "x": -30,
      "y": 18,
      "z": -16,
      "name": "Wood_Giantwood_Trunk"
    },
    {
      "x": -30,
      "y": 19,
      "z": -16,
      "name": "Wood_Giantwood_Trunk"
    },
    {
      "x": -30,
      "y": 20,
      "z": -16,
      "name": "Wood_Giantwood_Trunk"
    },
    {
      "x": -30,
      "y": 21,
      "z": -16,
      "name": "Wood_Giantwood_Trunk"
    },
    {
      "x": -30,
      "y": 22,
      "z": -16,
      "name": "Wood_Giantwood_Trunk"
    },
    {
      "x": -30,
      "y": 23,
      "z": -16,
      "name": "Wood_Giantwood_Trunk"
    },
    {
      "x": -30,
      "y": 24,
      "z": -16,
      "name": "Wood_Giantwood_Trunk"
    },
    {
      "x": -30,
      "y": 25,
      "z": -16,
      "name": "Wood_Giantwood_Trunk"
    },
    {
      "x": -30,
      "y": 26,
      "z": -16,
      "name": "Wood_Giantwood_Trunk"
    },
    {
      "x": -30,
      "y": 27,
      "z": -16,
      "name": "Wood_Giantwood_Trunk"
    },
    {
      "x": -30,
      "y": 28,
      "z": -16,
      "name": "Wood_Giantwood_Trunk"
    },
    {
      "x": -30,
      "y": 29,
      "z": -16,
      "name": "Wood_Giantwood_Trunk"
    },
    {
      "x": -30,
      "y": 30,
      "z": -16,
      "name": "Wood_Giantwood_Trunk"
    },
    {
      "x": -30,
      "y": 31,
      "z": -16,
      "name": "Wood_Giantwood_Trunk"
    },
    {
      "x": -30,
      "y": 32,
      "z": -16,
      "name": "Wood_Giantwood_Trunk_Mossy_Full"
    },
    {
      "x": -30,
      "y": 16,
      "z": -15,
      "name": "Wood_Giantwood_Trunk_Mossy_Full"
    },
    {
      "x": -30,
      "y": 17,
      "z": -15,
      "name": "Wood_Giantwood_Trunk"
    },
    {
      "x": -30,
      "y": 18,
      "z": -15,
      "name": "Wood_Giantwood_Trunk"
    },
    {
      "x": -30,
      "y": 19,
      "z": -15,
      "name": "Wood_Giantwood_Trunk"
    },
    {
      "x": -30,
      "y": 20,
      "z": -15,
      "name": "Wood_Giantwood_Trunk"
    },
    {
      "x": -30,
      "y": 21,
      "z": -15,
      "name": "Wood_Giantwood_Trunk"
    },
    {
      "x": -30,
      "y": 22,
      "z": -15,
      "name": "Wood_Giantwood_Trunk"
    },
    {
      "x": -30,
      "y": 23,
      "z": -15,
      "name": "Wood_Giantwood_Trunk"
    },
    {
      "x": -30,
      "y": 24,
      "z": -15,
      "name": "Wood_Giantwood_Trunk"
    },
    {
      "x": -30,
      "y": 25,
      "z": -15,
      "name": "Wood_Giantwood_Trunk"
    },
    {
      "x": -30,
      "y": 26,
      "z": -15,
      "name": "Wood_Giantwood_Trunk"
    },
    {
      "x": -30,
      "y": 27,
      "z": -15,
      "name": "Wood_Giantwood_Trunk"
    },
    {
      "x": -30,
      "y": 28,
      "z": -15,
      "name": "Wood_Giantwood_Trunk"
    },
    {
      "x": -30,
      "y": 29,
      "z": -15,
      "name": "Wood_Giantwood_Trunk"
    },
    {
      "x": -30,
      "y": 30,
      "z": -15,
      "name": "Wood_Giantwood_Trunk"
    },
    {
      "x": -30,
      "y": 31,
      "z": -15,
      "name": "Wood_Giantwood_Trunk_Mossy_Full"
    },
    {
      "x": -30,
      "y": 32,
      "z": -15,
      "name": "Wood_Giantwood_Trunk_Mossy_Full"
    },
    {
      "x": -30,
      "y": 16,
      "z": -14,
      "name": "Wood_Giantwood_Trunk_Mossy_Full"
    },
    {
      "x": -30,
      "y": 17,
      "z": -14,
      "name": "Wood_Giantwood_Trunk_Mossy_Full"
    },
    {
      "x": -30,
      "y": 18,
      "z": -14,
      "name": "Wood_Giantwood_Trunk_Mossy_Full"
    },
    {
      "x": -30,
      "y": 19,
      "z": -14,
      "name": "Wood_Giantwood_Trunk_Mossy_Full"
    },
    {
      "x": -30,
      "y": 20,
      "z": -14,
      "name": "Wood_Giantwood_Trunk"
    },
    {
      "x": -30,
      "y": 21,
      "z": -14,
      "name": "Wood_Giantwood_Trunk"
    },
    {
      "x": -30,
      "y": 22,
      "z": -14,
      "name": "Wood_Giantwood_Trunk"
    },
    {
      "x": -30,
      "y": 23,
      "z": -14,
      "name": "Wood_Giantwood_Trunk"
    },
    {
      "x": -30,
      "y": 24,
      "z": -14,
      "name": "Wood_Giantwood_Trunk"
    },
    {
      "x": -30,
      "y": 25,
      "z": -14,
      "name": "Wood_Giantwood_Trunk"
    },
    {
      "x": -30,
      "y": 26,
      "z": -14,
      "name": "Wood_Giantwood_Trunk"
    },
    {
      "x": -30,
      "y": 27,
      "z": -14,
      "name": "Wood_Giantwood_Trunk"
    },
    {
      "x": -30,
      "y": 28,
      "z": -14,
      "name": "Wood_Giantwood_Trunk"
    },
    {
      "x": -30,
      "y": 29,
      "z": -14,
      "name": "Wood_Giantwood_Trunk"
    },
    {
      "x": -30,
      "y": 30,
      "z": -14,
      "name": "Wood_Giantwood_Trunk"
    },
    {
      "x": -30,
      "y": 31,
      "z": -14,
      "name": "Wood_Giantwood_Trunk_Mossy_Full"
    },
    {
      "x": -30,
      "y": 32,
      "z": -14,
      "name": "Wood_Giantwood_Trunk_Mossy_Full"
    },
    {
      "x": -30,
      "y": 203,
      "z": -14,
      "name": "Wood_Giantwood_Trunk_Full"
    },
    {
      "x": -30,
      "y": 204,
      "z": -14,
      "name": "Wood_Giantwood_Trunk_Full"
    },
    {
      "x": -30,
      "y": 17,
      "z": -13,
      "name": "Wood_Giantwood_Trunk_Mossy_Full"
    },
    {
      "x": -30,
      "y": 18,
      "z": -13,
      "name": "Wood_Giantwood_Trunk_Mossy_Full"
    },
    {
      "x": -30,
      "y": 19,
      "z": -13,
      "name": "Wood_Giantwood_Trunk_Mossy"
    },
    {
      "x": -30,
      "y": 20,
      "z": -13,
      "name": "Wood_Giantwood_Trunk_Mossy_Full"
    },
    {
      "x": -30,
      "y": 21,
      "z": -13,
      "name": "Wood_Giantwood_Trunk_Mossy_Full"
    },
    {
      "x": -30,
      "y": 22,
      "z": -13,
      "name": "Wood_Giantwood_Trunk_Mossy_Full"
    },
    {
      "x": -30,
      "y": 23,
      "z": -13,
      "name": "Wood_Giantwood_Trunk_Mossy_Full"
    },
    {
      "x": -30,
      "y": 24,
      "z": -13,
      "name": "Wood_Giantwood_Trunk"
    },
    {
      "x": -30,
      "y": 25,
      "z": -13,
      "name": "Wood_Giantwood_Trunk"
    },
    {
      "x": -30,
      "y": 26,
      "z": -13,
      "name": "Wood_Giantwood_Trunk"
    },
    {
      "x": -30,
      "y": 27,
      "z": -13,
      "name": "Wood_Giantwood_Trunk"
    },
    {
      "x": -30,
      "y": 28,
      "z": -13,
      "name": "Wood_Giantwood_Trunk"
    },
    {
      "x": -30,
      "y": 29,
      "z": -13,
      "name": "Wood_Giantwood_Trunk"
    },
    {
      "x": -30,
      "y": 30,
      "z": -13,
      "name": "Wood_Giantwood_Trunk"
    },
    {
      "x": -30,
      "y": 31,
      "z": -13,
      "name": "Wood_Giantwood_Trunk_Mossy_Full"
    },
    {
      "x": -30,
      "y": 202,
      "z": -13,
      "name": "Wood_Giantwood_Trunk_Full"
    },
    {
      "x": -30,
      "y": 21,
      "z": -12,
      "name": "Wood_Giantwood_Trunk_Mossy_Full"
    },
    {
      "x": -30,
      "y": 22,
      "z": -12,
      "name": "Wood_Giantwood_Trunk_Mossy_Full"
    },
    {
      "x": -30,
      "y": 23,
      "z": -12,
      "name": "Wood_Giantwood_Trunk_Mossy_Full"
    },
    {
      "x": -30,
      "y": 24,
      "z": -12,
      "name": "Wood_Giantwood_Trunk_Mossy_Full"
    },
    {
      "x": -30,
      "y": 25,
      "z": -12,
      "name": "Wood_Giantwood_Trunk"
    },
    {
      "x": -30,
      "y": 26,
      "z": -12,
      "name": "Wood_Giantwood_Trunk_Mossy_Full"
    },
    {
      "x": -30,
      "y": 27,
      "z": -12,
      "name": "Wood_Giantwood_Trunk"
    },
    {
      "x": -30,
      "y": 28,
      "z": -12,
      "name": "Wood_Giantwood_Trunk"
    },
    {
      "x": -30,
      "y": 29,
      "z": -12,
      "name": "Wood_Giantwood_Trunk_Mossy_Full"
    },
    {
      "x": -30,
      "y": 30,
      "z": -12,
      "name": "Wood_Giantwood_Trunk_Mossy_Full"
    },
    {
      "x": -30,
      "y": 31,
      "z": -12,
      "name": "Wood_Giantwood_Trunk_Mossy_Full"
    },
    {
      "x": -30,
      "y": 25,
      "z": -11,
      "name": "Wood_Giantwood_Trunk_Mossy_Full"
    },
    {
      "x": -30,
      "y": 26,
      "z": -11,
      "name": "Wood_Giantwood_Trunk_Mossy_Full"
    },
    {
      "x": -30,
      "y": 27,
      "z": -11,
      "name": "Wood_Giantwood_Trunk_Mossy_Full"
    },
    {
      "x": -30,
      "y": 28,
      "z": -11,
      "name": "Wood_Giantwood_Trunk_Mossy_Full"
    },
    {
      "x": -30,
      "y": 29,
      "z": -11,
      "name": "Wood_Giantwood_Trunk_Mossy_Full"
    },
    {
      "x": -30,
      "y": 198,
      "z": -3,
      "name": "Wood_Giantwood_Trunk_Full"
    },
    {
      "x": -30,
      "y": 197,
      "z": -2,
      "name": "Wood_Giantwood_Trunk_Full"
    },
    {
      "x": -30,
      "y": 198,
      "z": -2,
      "name": "Wood_Giantwood_Trunk"
    },
    {
      "x": -30,
      "y": 199,
      "z": -2,
      "name": "Wood_Giantwood_Trunk_Full"
    },
    {
      "x": -30,
      "y": 198,
      "z": -1,
      "name": "Wood_Giantwood_Trunk_Full"
    },
    {
      "x": -30,
      "y": 199,
      "z": 10,
      "name": "Wood_Giantwood_Trunk_Full"
    },
    {
      "x": -29,
      "y": 24,
      "z": -22,
      "name": "Wood_Giantwood_Trunk_Mossy_Full"
    },
    {
      "x": -29,
      "y": 25,
      "z": -22,
      "name": "Wood_Giantwood_Trunk_Mossy_Full"
    },
    {
      "x": -29,
      "y": 26,
      "z": -22,
      "name": "Wood_Giantwood_Trunk_Mossy_Full"
    },
    {
      "x": -29,
      "y": 27,
      "z": -22,
      "name": "Wood_Giantwood_Trunk_Mossy_Full"
    },
    {
      "x": -29,
      "y": 28,
      "z": -22,
      "name": "Wood_Giantwood_Trunk_Mossy_Full"
    },
    {
      "x": -29,
      "y": 22,
      "z": -21,
      "name": "Wood_Giantwood_Trunk_Mossy_Full"
    },
    {
      "x": -29,
      "y": 23,
      "z": -21,
      "name": "Wood_Giantwood_Trunk_Mossy_Full"
    },
    {
      "x": -29,
      "y": 24,
      "z": -21,
      "name": "Wood_Giantwood_Trunk_Mossy_Full"
    },
    {
      "x": -29,
      "y": 25,
      "z": -21,
      "name": "Wood_Giantwood_Trunk"
    },
    {
      "x": -29,
      "y": 26,
      "z": -21,
      "name": "Wood_Giantwood_Trunk"
    },
    {
      "x": -29,
      "y": 27,
      "z": -21,
      "name": "Wood_Giantwood_Trunk"
    },
    {
      "x": -29,
      "y": 28,
      "z": -21,
      "name": "Wood_Giantwood_Trunk_Full"
    },
    {
      "x": -29,
      "y": 29,
      "z": -21,
      "name": "Wood_Giantwood_Trunk_Mossy_Full"
    },
    {
      "x": -29,
      "y": 19,
      "z": -20,
      "name": "Wood_Giantwood_Trunk_Mossy_Full"
    },
    {
      "x": -29,
      "y": 20,
      "z": -20,
      "name": "Wood_Giantwood_Trunk_Mossy_Full"
    },
    {
      "x": -29,
      "y": 21,
      "z": -20,
      "name": "Wood_Giantwood_Trunk_Mossy_Full"
    },
    {
      "x": -29,
      "y": 22,
      "z": -20,
      "name": "Wood_Giantwood_Trunk_Mossy_Full"
    },
    {
      "x": -29,
      "y": 23,
      "z": -20,
      "name": "Wood_Giantwood_Trunk"
    },
    {
      "x": -29,
      "y": 24,
      "z": -20,
      "name": "Wood_Giantwood_Trunk"
    },
    {
      "x": -29,
      "y": 25,
      "z": -20,
      "name": "Wood_Giantwood_Trunk"
    },
    {
      "x": -29,
      "y": 26,
      "z": -20,
      "name": "Wood_Giantwood_Trunk"
    },
    {
      "x": -29,
      "y": 27,
      "z": -20,
      "name": "Wood_Giantwood_Trunk"
    },
    {
      "x": -29,
      "y": 28,
      "z": -20,
      "name": "Wood_Giantwood_Trunk"
    },
    {
      "x": -29,
      "y": 29,
      "z": -20,
      "name": "Wood_Giantwood_Trunk_Mossy_Full"
    },
    {
      "x": -29,
      "y": 30,
      "z": -20,
      "name": "Wood_Giantwood_Trunk_Mossy_Full"
    },
    {
      "x": -29,
      "y": 17,
      "z": -19,
      "name": "Wood_Giantwood_Trunk_Mossy_Full"
    },
    {
      "x": -29,
      "y": 18,
      "z": -19,
      "name": "Wood_Giantwood_Trunk_Mossy_Full"
    },
    {
      "x": -29,
      "y": 19,
      "z": -19,
      "name": "Wood_Giantwood_Trunk_Mossy_Full"
    },
    {
      "x": -29,
      "y": 20,
      "z": -19,
      "name": "Wood_Giantwood_Trunk_Mossy_Full"
    },
    {
      "x": -29,
      "y": 21,
      "z": -19,
      "name": "Wood_Giantwood_Trunk"
    },
    {
      "x": -29,
      "y": 22,
      "z": -19,
      "name": "Wood_Giantwood_Trunk"
    },
    {
      "x": -29,
      "y": 23,
      "z": -19,
      "name": "Wood_Giantwood_Trunk"
    },
    {
      "x": -29,
      "y": 24,
      "z": -19,
      "name": "Wood_Giantwood_Trunk"
    },
    {
      "x": -29,
      "y": 25,
      "z": -19,
      "name": "Wood_Giantwood_Trunk"
    },
    {
      "x": -29,
      "y": 26,
      "z": -19,
      "name": "Wood_Giantwood_Trunk"
    },
    {
      "x": -29,
      "y": 27,
      "z": -19,
      "name": "Wood_Giantwood_Trunk"
    },
    {
      "x": -29,
      "y": 28,
      "z": -19,
      "name": "Wood_Giantwood_Trunk"
    },
    {
      "x": -29,
      "y": 29,
      "z": -19,
      "name": "Wood_Giantwood_Trunk"
    },
    {
      "x": -29,
      "y": 30,
      "z": -19,
      "name": "Wood_Giantwood_Trunk_Mossy_Full"
    },
    {
      "x": -29,
      "y": 31,
      "z": -19,
      "name": "Wood_Giantwood_Trunk_Mossy_Full"
    },
    {
      "x": -29,
      "y": 16,
      "z": -18,
      "name": "Wood_Giantwood_Trunk_Full"
    },
    {
      "x": -29,
      "y": 17,
      "z": -18,
      "name": "Wood_Giantwood_Trunk_Mossy"
    },
    {
      "x": -29,
      "y": 18,
      "z": -18,
      "name": "Wood_Giantwood_Trunk"
    },
    {
      "x": -29,
      "y": 19,
      "z": -18,
      "name": "Wood_Giantwood_Trunk"
    },
    {
      "x": -29,
      "y": 20,
      "z": -18,
      "name": "Wood_Giantwood_Trunk"
    },
    {
      "x": -29,
      "y": 21,
      "z": -18,
      "name": "Wood_Giantwood_Trunk"
    },
    {
      "x": -29,
      "y": 22,
      "z": -18,
      "name": "Wood_Giantwood_Trunk"
    },
    {
      "x": -29,
      "y": 23,
      "z": -18,
      "name": "Wood_Giantwood_Trunk"
    },
    {
      "x": -29,
      "y": 24,
      "z": -18,
      "name": "Wood_Giantwood_Trunk"
    },
    {
      "x": -29,
      "y": 25,
      "z": -18,
      "name": "Wood_Giantwood_Trunk"
    },
    {
      "x": -29,
      "y": 26,
      "z": -18,
      "name": "Wood_Giantwood_Trunk"
    },
    {
      "x": -29,
      "y": 27,
      "z": -18,
      "name": "Wood_Giantwood_Trunk"
    },
    {
      "x": -29,
      "y": 28,
      "z": -18,
      "name": "Wood_Giantwood_Trunk"
    },
    {
      "x": -29,
      "y": 29,
      "z": -18,
      "name": "Wood_Giantwood_Trunk"
    },
    {
      "x": -29,
      "y": 30,
      "z": -18,
      "name": "Wood_Giantwood_Trunk"
    },
    {
      "x": -29,
      "y": 31,
      "z": -18,
      "name": "Wood_Giantwood_Trunk_Mossy_Full"
    },
    {
      "x": -29,
      "y": 32,
      "z": -18,
      "name": "Wood_Giantwood_Trunk_Mossy_Full"
    },
    {
      "x": -29,
      "y": 16,
      "z": -17,
      "name": "Wood_Giantwood_Trunk_Mossy"
    },
    {
      "x": -29,
      "y": 17,
      "z": -17,
      "name": "Wood_Giantwood_Trunk"
    },
    {
      "x": -29,
      "y": 18,
      "z": -17,
      "name": "Wood_Giantwood_Trunk"
    },
    {
      "x": -29,
      "y": 19,
      "z": -17,
      "name": "Wood_Giantwood_Trunk"
    },
    {
      "x": -29,
      "y": 20,
      "z": -17,
      "name": "Wood_Giantwood_Trunk"
    },
    {
      "x": -29,
      "y": 21,
      "z": -17,
      "name": "Wood_Giantwood_Trunk"
    },
    {
      "x": -29,
      "y": 22,
      "z": -17,
      "name": "Wood_Giantwood_Trunk"
    },
    {
      "x": -29,
      "y": 23,
      "z": -17,
      "name": "Wood_Giantwood_Trunk"
    },
    {
      "x": -29,
      "y": 24,
      "z": -17,
      "name": "Wood_Giantwood_Trunk"
    },
    {
      "x": -29,
      "y": 25,
      "z": -17,
      "name": "Wood_Giantwood_Trunk"
    },
    {
      "x": -29,
      "y": 26,
      "z": -17,
      "name": "Wood_Giantwood_Trunk"
    },
    {
      "x": -29,
      "y": 27,
      "z": -17,
      "name": "Wood_Giantwood_Trunk"
    },
    {
      "x": -29,
      "y": 28,
      "z": -17,
      "name": "Wood_Giantwood_Trunk"
    },
    {
      "x": -29,
      "y": 29,
      "z": -17,
      "name": "Wood_Giantwood_Trunk"
    },
    {
      "x": -29,
      "y": 30,
      "z": -17,
      "name": "Wood_Giantwood_Trunk"
    },
    {
      "x": -29,
      "y": 31,
      "z": -17,
      "name": "Wood_Giantwood_Trunk"
    },
    {
      "x": -29,
      "y": 32,
      "z": -17,
      "name": "Wood_Giantwood_Trunk_Mossy_Full"
    },
    {
      "x": -29,
      "y": 14,
      "z": -16,
      "name": "Wood_Giantwood_Roots"
    },
    {
      "x": -29,
      "y": 15,
      "z": -16,
      "name": "Wood_Giantwood_Trunk_Full"
    },
    {
      "x": -29,
      "y": 16,
      "z": -16,
      "name": "Wood_Giantwood_Trunk"
    },
    {
      "x": -29,
      "y": 17,
      "z": -16,
      "name": "Wood_Giantwood_Trunk"
    },
    {
      "x": -29,
      "y": 18,
      "z": -16,
      "name": "Wood_Giantwood_Trunk"
    },
    {
      "x": -29,
      "y": 19,
      "z": -16,
      "name": "Wood_Giantwood_Trunk"
    },
    {
      "x": -29,
      "y": 20,
      "z": -16,
      "name": "Wood_Giantwood_Trunk"
    },
    {
      "x": -29,
      "y": 21,
      "z": -16,
      "name": "Wood_Giantwood_Trunk"
    },
    {
      "x": -29,
      "y": 22,
      "z": -16,
      "name": "Wood_Giantwood_Trunk"
    },
    {
      "x": -29,
      "y": 23,
      "z": -16,
      "name": "Wood_Giantwood_Trunk"
    },
    {
      "x": -29,
      "y": 24,
      "z": -16,
      "name": "Wood_Giantwood_Trunk"
    },
    {
      "x": -29,
      "y": 25,
      "z": -16,
      "name": "Wood_Giantwood_Trunk"
    },
    {
      "x": -29,
      "y": 26,
      "z": -16,
      "name": "Wood_Giantwood_Trunk"
    },
    {
      "x": -29,
      "y": 27,
      "z": -16,
      "name": "Wood_Giantwood_Trunk"
    },
    {
      "x": -29,
      "y": 28,
      "z": -16,
      "name": "Wood_Giantwood_Trunk"
    },
    {
      "x": -29,
      "y": 29,
      "z": -16,
      "name": "Wood_Giantwood_Trunk"
    },
    {
      "x": -29,
      "y": 30,
      "z": -16,
      "name": "Wood_Giantwood_Trunk"
    },
    {
      "x": -29,
      "y": 31,
      "z": -16,
      "name": "Wood_Giantwood_Trunk"
    },
    {
      "x": -29,
      "y": 32,
      "z": -16,
      "name": "Wood_Giantwood_Trunk_Mossy_Full"
    },
    {
      "x": -29,
      "y": 15,
      "z": -15,
      "name": "Wood_Giantwood_Trunk_Full"
    },
    {
      "x": -29,
      "y": 16,
      "z": -15,
      "name": "Wood_Giantwood_Trunk"
    },
    {
      "x": -29,
      "y": 17,
      "z": -15,
      "name": "Wood_Giantwood_Trunk"
    },
    {
      "x": -29,
      "y": 18,
      "z": -15,
      "name": "Wood_Giantwood_Trunk"
    },
    {
      "x": -29,
      "y": 19,
      "z": -15,
      "name": "Wood_Giantwood_Trunk"
    },
    {
      "x": -29,
      "y": 20,
      "z": -15,
      "name": "Wood_Giantwood_Trunk"
    },
    {
      "x": -29,
      "y": 21,
      "z": -15,
      "name": "Wood_Giantwood_Trunk"
    },
    {
      "x": -29,
      "y": 22,
      "z": -15,
      "name": "Wood_Giantwood_Trunk"
    },
    {
      "x": -29,
      "y": 23,
      "z": -15,
      "name": "Wood_Giantwood_Trunk"
    },
    {
      "x": -29,
      "y": 24,
      "z": -15,
      "name": "Wood_Giantwood_Trunk"
    },
    {
      "x": -29,
      "y": 25,
      "z": -15,
      "name": "Wood_Giantwood_Trunk"
    },
    {
      "x": -29,
      "y": 26,
      "z": -15,
      "name": "Wood_Giantwood_Trunk"
    },
    {
      "x": -29,
      "y": 27,
      "z": -15,
      "name": "Wood_Giantwood_Trunk"
    },
    {
      "x": -29,
      "y": 28,
      "z": -15,
      "name": "Wood_Giantwood_Trunk"
    },
    {
      "x": -29,
      "y": 29,
      "z": -15,
      "name": "Wood_Giantwood_Trunk"
    },
    {
      "x": -29,
      "y": 30,
      "z": -15,
      "name": "Wood_Giantwood_Trunk"
    },
    {
      "x": -29,
      "y": 31,
      "z": -15,
      "name": "Wood_Giantwood_Trunk"
    },
    {
      "x": -29,
      "y": 32,
      "z": -15,
      "name": "Wood_Giantwood_Trunk_Mossy_Full"
    },
    {
      "x": -29,
      "y": 15,
      "z": -14,
      "name": "Wood_Giantwood_Trunk_Mossy"
    },
    {
      "x": -29,
      "y": 16,
      "z": -14,
      "name": "Wood_Giantwood_Trunk"
    },
    {
      "x": -29,
      "y": 17,
      "z": -14,
      "name": "Wood_Giantwood_Trunk"
    },
    {
      "x": -29,
      "y": 18,
      "z": -14,
      "name": "Wood_Giantwood_Trunk"
    },
    {
      "x": -29,
      "y": 19,
      "z": -14,
      "name": "Wood_Giantwood_Trunk"
    },
    {
      "x": -29,
      "y": 20,
      "z": -14,
      "name": "Wood_Giantwood_Trunk"
    },
    {
      "x": -29,
      "y": 21,
      "z": -14,
      "name": "Wood_Giantwood_Trunk"
    },
    {
      "x": -29,
      "y": 22,
      "z": -14,
      "name": "Wood_Giantwood_Trunk"
    },
    {
      "x": -29,
      "y": 23,
      "z": -14,
      "name": "Wood_Giantwood_Trunk"
    },
    {
      "x": -29,
      "y": 24,
      "z": -14,
      "name": "Wood_Giantwood_Trunk"
    },
    {
      "x": -29,
      "y": 25,
      "z": -14,
      "name": "Wood_Giantwood_Trunk"
    },
    {
      "x": -29,
      "y": 26,
      "z": -14,
      "name": "Wood_Giantwood_Trunk"
    },
    {
      "x": -29,
      "y": 27,
      "z": -14,
      "name": "Wood_Giantwood_Trunk"
    },
    {
      "x": -29,
      "y": 28,
      "z": -14,
      "name": "Wood_Giantwood_Trunk"
    },
    {
      "x": -29,
      "y": 29,
      "z": -14,
      "name": "Wood_Giantwood_Trunk"
    },
    {
      "x": -29,
      "y": 30,
      "z": -14,
      "name": "Wood_Giantwood_Trunk"
    },
    {
      "x": -29,
      "y": 31,
      "z": -14,
      "name": "Wood_Giantwood_Trunk"
    },
    {
      "x": -29,
      "y": 32,
      "z": -14,
      "name": "Wood_Giantwood_Trunk_Mossy_Full"
    },
    {
      "x": -29,
      "y": 203,
      "z": -14,
      "name": "Wood_Giantwood_Trunk_Full"
    },
    {
      "x": -29,
      "y": 15,
      "z": -13,
      "name": "Wood_Giantwood_Trunk_Full"
    },
    {
      "x": -29,
      "y": 16,
      "z": -13,
      "name": "Wood_Giantwood_Trunk"
    },
    {
      "x": -29,
      "y": 17,
      "z": -13,
      "name": "Wood_Giantwood_Trunk_Mossy_Full"
    },
    {
      "x": -29,
      "y": 18,
      "z": -13,
      "name": "Wood_Giantwood_Trunk_Mossy_Full"
    },
    {
      "x": -29,
      "y": 19,
      "z": -13,
      "name": "Wood_Giantwood_Trunk_Mossy_Full"
    },
    {
      "x": -29,
      "y": 20,
      "z": -13,
      "name": "Wood_Giantwood_Trunk_Mossy_Full"
    },
    {
      "x": -29,
      "y": 21,
      "z": -13,
      "name": "Wood_Giantwood_Trunk"
    },
    {
      "x": -29,
      "y": 22,
      "z": -13,
      "name": "Wood_Giantwood_Trunk"
    },
    {
      "x": -29,
      "y": 23,
      "z": -13,
      "name": "Wood_Giantwood_Trunk"
    },
    {
      "x": -29,
      "y": 24,
      "z": -13,
      "name": "Wood_Giantwood_Trunk"
    },
    {
      "x": -29,
      "y": 25,
      "z": -13,
      "name": "Wood_Giantwood_Trunk"
    },
    {
      "x": -29,
      "y": 26,
      "z": -13,
      "name": "Wood_Giantwood_Trunk"
    },
    {
      "x": -29,
      "y": 27,
      "z": -13,
      "name": "Wood_Giantwood_Trunk"
    },
    {
      "x": -29,
      "y": 28,
      "z": -13,
      "name": "Wood_Giantwood_Trunk"
    },
    {
      "x": -29,
      "y": 29,
      "z": -13,
      "name": "Wood_Giantwood_Trunk"
    },
    {
      "x": -29,
      "y": 30,
      "z": -13,
      "name": "Wood_Giantwood_Trunk"
    },
    {
      "x": -29,
      "y": 31,
      "z": -13,
      "name": "Wood_Giantwood_Trunk_Mossy_Full"
    },
    {
      "x": -29,
      "y": 32,
      "z": -13,
      "name": "Wood_Giantwood_Trunk_Mossy_Full"
    },
    {
      "x": -29,
      "y": 202,
      "z": -13,
      "name": "Wood_Giantwood_Trunk_Full"
    },
    {
      "x": -29,
      "y": 203,
      "z": -13,
      "name": "Wood_Giantwood_Trunk_Full"
    },
    {
      "x": -29,
      "y": 16,
      "z": -12,
      "name": "Wood_Giantwood_Roots"
    },
    {
      "x": -29,
      "y": 17,
      "z": -12,
      "name": "Wood_Giantwood_Trunk_Mossy_Full"
    },
    {
      "x": -29,
      "y": 18,
      "z": -12,
      "name": "Wood_Giantwood_Trunk_Mossy"
    },
    {
      "x": -29,
      "y": 19,
      "z": -12,
      "name": "Wood_Giantwood_Trunk_Mossy"
    },
    {
      "x": -29,
      "y": 20,
      "z": -12,
      "name": "Wood_Giantwood_Trunk_Mossy_Full"
    },
    {
      "x": -29,
      "y": 21,
      "z": -12,
      "name": "Wood_Giantwood_Trunk_Mossy_Full"
    },
    {
      "x": -29,
      "y": 22,
      "z": -12,
      "name": "Wood_Giantwood_Trunk_Mossy_Full"
    },
    {
      "x": -29,
      "y": 23,
      "z": -12,
      "name": "Wood_Giantwood_Trunk"
    },
    {
      "x": -29,
      "y": 24,
      "z": -12,
      "name": "Wood_Giantwood_Trunk"
    },
    {
      "x": -29,
      "y": 25,
      "z": -12,
      "name": "Wood_Giantwood_Trunk"
    },
    {
      "x": -29,
      "y": 26,
      "z": -12,
      "name": "Wood_Giantwood_Trunk"
    },
    {
      "x": -29,
      "y": 27,
      "z": -12,
      "name": "Wood_Giantwood_Trunk"
    },
    {
      "x": -29,
      "y": 28,
      "z": -12,
      "name": "Wood_Giantwood_Trunk"
    },
    {
      "x": -29,
      "y": 29,
      "z": -12,
      "name": "Wood_Giantwood_Trunk"
    },
    {
      "x": -29,
      "y": 30,
      "z": -12,
      "name": "Wood_Giantwood_Trunk_Mossy_Full"
    },
    {
      "x": -29,
      "y": 31,
      "z": -12,
      "name": "Wood_Giantwood_Trunk_Mossy_Full"
    },
    {
      "x": -29,
      "y": 32,
      "z": -12,
      "name": "Wood_Giantwood_Trunk_Mossy_Full"
    },
    {
      "x": -29,
      "y": 201,
      "z": -12,
      "name": "Wood_Giantwood_Trunk_Full"
    },
    {
      "x": -29,
      "y": 203,
      "z": -12,
      "name": "Wood_Giantwood_Trunk_Full"
    },
    {
      "x": -29,
      "y": 23,
      "z": -11,
      "name": "Wood_Giantwood_Trunk_Mossy_Full"
    },
    {
      "x": -29,
      "y": 24,
      "z": -11,
      "name": "Wood_Giantwood_Trunk_Mossy_Full"
    },
    {
      "x": -29,
      "y": 25,
      "z": -11,
      "name": "Wood_Giantwood_Trunk"
    },
    {
      "x": -29,
      "y": 26,
      "z": -11,
      "name": "Wood_Giantwood_Trunk"
    },
    {
      "x": -29,
      "y": 27,
      "z": -11,
      "name": "Wood_Giantwood_Trunk_Mossy_Full"
    },
    {
      "x": -29,
      "y": 28,
      "z": -11,
      "name": "Wood_Giantwood_Trunk_Mossy_Full"
    },
    {
      "x": -29,
      "y": 29,
      "z": -11,
      "name": "Wood_Giantwood_Trunk_Mossy_Full"
    },
    {
      "x": -29,
      "y": 30,
      "z": -11,
      "name": "Wood_Giantwood_Trunk_Mossy_Full"
    },
    {
      "x": -29,
      "y": 31,
      "z": -11,
      "name": "Wood_Giantwood_Trunk_Mossy_Full"
    },
    {
      "x": -29,
      "y": 25,
      "z": -10,
      "name": "Wood_Giantwood_Trunk_Mossy_Full"
    },
    {
      "x": -29,
      "y": 26,
      "z": -10,
      "name": "Wood_Giantwood_Trunk_Mossy_Full"
    },
    {
      "x": -29,
      "y": 27,
      "z": -10,
      "name": "Wood_Giantwood_Trunk_Mossy_Full"
    },
    {
      "x": -29,
      "y": 28,
      "z": -10,
      "name": "Wood_Giantwood_Trunk_Mossy_Full"
    },
    {
      "x": -29,
      "y": 29,
      "z": -10,
      "name": "Wood_Giantwood_Trunk_Mossy_Full"
    },
    {
      "x": -29,
      "y": 198,
      "z": -3,
      "name": "Wood_Giantwood_Trunk_Full"
    },
    {
      "x": -29,
      "y": 197,
      "z": -2,
      "name": "Wood_Giantwood_Trunk_Full"
    },
    {
      "x": -29,
      "y": 198,
      "z": -2,
      "name": "Wood_Giantwood_Trunk"
    },
    {
      "x": -29,
      "y": 199,
      "z": -2,
      "name": "Wood_Giantwood_Trunk_Full"
    },
    {
      "x": -29,
      "y": 198,
      "z": -1,
      "name": "Wood_Giantwood_Trunk_Full"
    },
    {
      "x": -29,
      "y": 199,
      "z": 10,
      "name": "Wood_Giantwood_Trunk_Full"
    },
    {
      "x": -28,
      "y": 25,
      "z": -22,
      "name": "Wood_Giantwood_Trunk_Mossy_Full"
    },
    {
      "x": -28,
      "y": 26,
      "z": -22,
      "name": "Wood_Giantwood_Trunk_Mossy_Full"
    },
    {
      "x": -28,
      "y": 27,
      "z": -22,
      "name": "Wood_Giantwood_Trunk_Mossy_Full"
    },
    {
      "x": -28,
      "y": 23,
      "z": -21,
      "name": "Wood_Giantwood_Trunk_Mossy_Full"
    },
    {
      "x": -28,
      "y": 24,
      "z": -21,
      "name": "Wood_Giantwood_Trunk_Mossy_Full"
    },
    {
      "x": -28,
      "y": 25,
      "z": -21,
      "name": "Wood_Giantwood_Trunk_Mossy_Full"
    },
    {
      "x": -28,
      "y": 26,
      "z": -21,
      "name": "Wood_Giantwood_Trunk"
    },
    {
      "x": -28,
      "y": 27,
      "z": -21,
      "name": "Wood_Giantwood_Trunk_Full"
    },
    {
      "x": -28,
      "y": 28,
      "z": -21,
      "name": "Wood_Giantwood_Trunk_Mossy_Full"
    },
    {
      "x": -28,
      "y": 29,
      "z": -21,
      "name": "Wood_Giantwood_Trunk_Mossy_Full"
    },
    {
      "x": -28,
      "y": 21,
      "z": -20,
      "name": "Wood_Giantwood_Trunk_Mossy_Full"
    },
    {
      "x": -28,
      "y": 22,
      "z": -20,
      "name": "Wood_Giantwood_Trunk_Mossy_Full"
    },
    {
      "x": -28,
      "y": 23,
      "z": -20,
      "name": "Wood_Giantwood_Trunk_Mossy_Full"
    },
    {
      "x": -28,
      "y": 24,
      "z": -20,
      "name": "Wood_Giantwood_Trunk"
    },
    {
      "x": -28,
      "y": 25,
      "z": -20,
      "name": "Wood_Giantwood_Trunk"
    },
    {
      "x": -28,
      "y": 26,
      "z": -20,
      "name": "Wood_Giantwood_Trunk"
    },
    {
      "x": -28,
      "y": 27,
      "z": -20,
      "name": "Wood_Giantwood_Trunk"
    },
    {
      "x": -28,
      "y": 28,
      "z": -20,
      "name": "Wood_Giantwood_Trunk"
    },
    {
      "x": -28,
      "y": 29,
      "z": -20,
      "name": "Wood_Giantwood_Trunk_Mossy_Full"
    },
    {
      "x": -28,
      "y": 30,
      "z": -20,
      "name": "Wood_Giantwood_Trunk_Mossy_Full"
    },
    {
      "x": -28,
      "y": 18,
      "z": -19,
      "name": "Wood_Giantwood_Trunk_Mossy_Full"
    },
    {
      "x": -28,
      "y": 19,
      "z": -19,
      "name": "Wood_Giantwood_Trunk_Mossy_Full"
    },
    {
      "x": -28,
      "y": 20,
      "z": -19,
      "name": "Wood_Giantwood_Trunk_Mossy_Full"
    },
    {
      "x": -28,
      "y": 21,
      "z": -19,
      "name": "Wood_Giantwood_Trunk_Mossy_Full"
    },
    {
      "x": -28,
      "y": 22,
      "z": -19,
      "name": "Wood_Giantwood_Trunk"
    },
    {
      "x": -28,
      "y": 23,
      "z": -19,
      "name": "Wood_Giantwood_Trunk"
    },
    {
      "x": -28,
      "y": 24,
      "z": -19,
      "name": "Wood_Giantwood_Trunk"
    },
    {
      "x": -28,
      "y": 25,
      "z": -19,
      "name": "Wood_Giantwood_Trunk"
    },
    {
      "x": -28,
      "y": 26,
      "z": -19,
      "name": "Wood_Giantwood_Trunk"
    },
    {
      "x": -28,
      "y": 27,
      "z": -19,
      "name": "Wood_Giantwood_Trunk"
    },
    {
      "x": -28,
      "y": 28,
      "z": -19,
      "name": "Wood_Giantwood_Trunk"
    },
    {
      "x": -28,
      "y": 29,
      "z": -19,
      "name": "Wood_Giantwood_Trunk"
    },
    {
      "x": -28,
      "y": 30,
      "z": -19,
      "name": "Wood_Giantwood_Trunk_Mossy_Full"
    },
    {
      "x": -28,
      "y": 31,
      "z": -19,
      "name": "Wood_Giantwood_Trunk_Mossy_Full"
    },
    {
      "x": -28,
      "y": 17,
      "z": -18,
      "name": "Wood_Giantwood_Trunk_Mossy"
    },
    {
      "x": -28,
      "y": 18,
      "z": -18,
      "name": "Wood_Giantwood_Trunk_Mossy_Full"
    },
    {
      "x": -28,
      "y": 19,
      "z": -18,
      "name": "Wood_Giantwood_Trunk_Mossy_Full"
    },
    {
      "x": -28,
      "y": 20,
      "z": -18,
      "name": "Wood_Giantwood_Trunk_Mossy_Full"
    },
    {
      "x": -28,
      "y": 21,
      "z": -18,
      "name": "Wood_Giantwood_Trunk"
    },
    {
      "x": -28,
      "y": 22,
      "z": -18,
      "name": "Wood_Giantwood_Trunk"
    },
    {
      "x": -28,
      "y": 23,
      "z": -18,
      "name": "Wood_Giantwood_Trunk"
    },
    {
      "x": -28,
      "y": 24,
      "z": -18,
      "name": "Wood_Giantwood_Trunk"
    },
    {
      "x": -28,
      "y": 25,
      "z": -18,
      "name": "Wood_Giantwood_Trunk"
    },
    {
      "x": -28,
      "y": 26,
      "z": -18,
      "name": "Wood_Giantwood_Trunk"
    },
    {
      "x": -28,
      "y": 27,
      "z": -18,
      "name": "Wood_Giantwood_Trunk"
    },
    {
      "x": -28,
      "y": 28,
      "z": -18,
      "name": "Wood_Giantwood_Trunk"
    },
    {
      "x": -28,
      "y": 29,
      "z": -18,
      "name": "Wood_Giantwood_Trunk"
    },
    {
      "x": -28,
      "y": 30,
