{
  "version": 8,
  "blockIdVersion": 11,
  "anchorX": 0,
  "anchorY": 0,
  "anchorZ": 0,
  "blocks": [
    {
      "x": -61,
      "y": 201,
      "z": -5,
      "name": "Rock_Stone"
    },
    {
      "x": -61,
      "y": 202,
      "z": -5,
      "name": "Rock_Stone"
    },
    {
      "x": -61,
      "y": 201,
      "z": -4,
      "name": "Rock_Stone"
    },
    {
      "x": -61,
      "y": 202,
      "z": -4,
      "name": "Rock_Stone"
    },
    {
      "x": -61,
      "y": 201,
      "z": -3,
      "name": "Rock_Stone"
    },
    {
      "x": -61,
      "y": 202,
      "z": -3,
      "name": "Rock_Stone"
    },
    {
      "x": -61,
      "y": 201,
      "z": -2,
      "name": "Rock_Stone"
    },
    {
      "x": -61,
      "y": 202,
      "z": -2,
      "name": "Rock_Stone"
    },
    {
      "x": -61,
      "y": 201,
      "z": -1,
      "name": "Rock_Stone"
    },
    {
      "x": -61,
      "y": 202,
      "z": -1,
      "name": "Rock_Stone"
    },
    {
      "x": -61,
      "y": 200,
      "z": 0,
      "name": "Rock_Stone"
    },
    {
      "x": -61,
      "y": 201,
      "z": 0,
      "name": "Rock_Stone"
    },
    {
      "x": -61,
      "y": 202,
      "z": 0,
      "name": "Rock_Stone"
    },
    {
      "x": -61,
      "y": 200,
      "z": 1,
      "name": "Rock_Stone"
    },
    {
      "x": -61,
      "y": 201,
      "z": 1,
      "name": "Rock_Stone"
    },
    {
      "x": -61,
      "y": 202,
      "z": 1,
      "name": "Rock_Stone"
    },
    {
      "x": -61,
      "y": 201,
      "z": 2,
      "name": "Rock_Stone"
    },
    {
      "x": -61,
      "y": 202,
      "z": 2,
      "name": "Rock_Stone"
    },
    {
      "x": -61,
      "y": 201,
      "z": 3,
      "name": "Rock_Stone"
    },
    {
      "x": -61,
      "y": 202,
      "z": 3,
      "name": "Rock_Stone"
    },
    {
      "x": -61,
      "y": 201,
      "z": 4,
      "name": "Rock_Stone"
    },
    {
      "x": -61,
      "y": 202,
      "z": 4,
      "name": "Rock_Stone"
    },
    {
      "x": -60,
      "y": 201,
      "z": -8,
      "name": "Rock_Stone"
    },
    {
      "x": -60,
      "y": 202,
      "z": -8,
      "name": "Rock_Stone"
    },
    {
      "x": -60,
      "y": 200,
      "z": -7,
      "name": "Rock_Stone"
    },
    {
      "x": -60,
      "y": 201,
      "z": -7,
      "name": "Rock_Stone"
    },
    {
      "x": -60,
      "y": 202,
      "z": -7,
      "name": "Rock_Stone"
    },
    {
      "x": -60,
      "y": 200,
      "z": -6,
      "name": "Rock_Stone"
    },
    {
      "x": -60,
      "y": 201,
      "z": -6,
      "name": "Rock_Stone"
    },
    {
      "x": -60,
      "y": 202,
      "z": -6,
      "name": "Rock_Stone"
    },
    {
      "x": -60,
      "y": 203,
      "z": -6,
      "name": "Rock_Stone"
    },
    {
      "x": -60,
      "y": 200,
      "z": -5,
      "name": "Rock_Stone"
    },
    {
      "x": -60,
      "y": 201,
      "z": -5,
      "name": "Rock_Stone"
    },
    {
      "x": -60,
      "y": 202,
      "z": -5,
      "name": "Rock_Stone"
    },
    {
      "x": -60,
      "y": 203,
      "z": -5,
      "name": "Rock_Stone"
    },
    {
      "x": -60,
      "y": 199,
      "z": -4,
      "name": "Rock_Stone"
    },
    {
      "x": -60,
      "y": 200,
      "z": -4,
      "name": "Rock_Stone"
    },
    {
      "x": -60,
      "y": 201,
      "z": -4,
      "name": "Rock_Stone"
    },
    {
      "x": -60,
      "y": 202,
      "z": -4,
      "name": "Rock_Stone"
    },
    {
      "x": -60,
      "y": 203,
      "z": -4,
      "name": "Rock_Stone"
    },
    {
      "x": -60,
      "y": 199,
      "z": -3,
      "name": "Rock_Stone"
    },
    {
      "x": -60,
      "y": 200,
      "z": -3,
      "name": "Rock_Stone"
    },
    {
      "x": -60,
      "y": 201,
      "z": -3,
      "name": "Rock_Stone"
    },
    {
      "x": -60,
      "y": 202,
      "z": -3,
      "name": "Rock_Stone"
    },
    {
      "x": -60,
      "y": 203,
      "z": -3,
      "name": "Rock_Stone"
    },
    {
      "x": -60,
      "y": 199,
      "z": -2,
      "name": "Rock_Stone"
    },
    {
      "x": -60,
      "y": 200,
      "z": -2,
      "name": "Rock_Stone"
    },
    {
      "x": -60,
      "y": 201,
      "z": -2,
      "name": "Rock_Stone"
    },
    {
      "x": -60,
      "y": 202,
      "z": -2,
      "name": "Rock_Stone"
    },
    {
      "x": -60,
      "y": 203,
      "z": -2,
      "name": "Rock_Stone"
    },
    {
      "x": -60,
      "y": 199,
      "z": -1,
      "name": "Rock_Stone"
    },
    {
      "x": -60,
      "y": 200,
      "z": -1,
      "name": "Rock_Stone"
    },
    {
      "x": -60,
      "y": 201,
      "z": -1,
      "name": "Rock_Stone"
    },
    {
      "x": -60,
      "y": 202,
      "z": -1,
      "name": "Rock_Stone"
    },
    {
      "x": -60,
      "y": 203,
      "z": -1,
      "name": "Rock_Stone"
    },
    {
      "x": -60,
      "y": 199,
      "z": 0,
      "name": "Rock_Stone"
    },
    {
      "x": -60,
      "y": 200,
      "z": 0,
      "name": "Rock_Stone"
    },
    {
      "x": -60,
      "y": 201,
      "z": 0,
      "name": "Rock_Stone"
    },
    {
      "x": -60,
      "y": 202,
      "z": 0,
      "name": "Rock_Stone"
    },
    {
      "x": -60,
      "y": 203,
      "z": 0,
      "name": "Rock_Stone"
    },
    {
      "x": -60,
      "y": 199,
      "z": 1,
      "name": "Rock_Stone"
    },
    {
      "x": -60,
      "y": 200,
      "z": 1,
      "name": "Rock_Stone"
    },
    {
      "x": -60,
      "y": 201,
      "z": 1,
      "name": "Rock_Stone"
    },
    {
      "x": -60,
      "y": 202,
      "z": 1,
      "name": "Rock_Stone"
    },
    {
      "x": -60,
      "y": 203,
      "z": 1,
      "name": "Rock_Stone"
    },
    {
      "x": -60,
      "y": 199,
      "z": 2,
      "name": "Rock_Stone"
    },
    {
      "x": -60,
      "y": 200,
      "z": 2,
      "name": "Rock_Stone"
    },
    {
      "x": -60,
      "y": 201,
      "z": 2,
      "name": "Rock_Stone"
    },
    {
      "x": -60,
      "y": 202,
      "z": 2,
      "name": "Rock_Stone"
    },
    {
      "x": -60,
      "y": 203,
      "z": 2,
      "name": "Rock_Stone"
    },
    {
      "x": -60,
      "y": 200,
      "z": 3,
      "name": "Rock_Stone"
    },
    {
      "x": -60,
      "y": 201,
      "z": 3,
      "name": "Rock_Stone"
    },
    {
      "x": -60,
      "y": 202,
      "z": 3,
      "name": "Rock_Stone"
    },
    {
      "x": -60,
      "y": 203,
      "z": 3,
      "name": "Rock_Stone"
    },
    {
      "x": -60,
      "y": 200,
      "z": 4,
      "name": "Rock_Stone"
    },
    {
      "x": -60,
      "y": 201,
      "z": 4,
      "name": "Rock_Stone"
    },
    {
      "x": -60,
      "y": 202,
      "z": 4,
      "name": "Rock_Stone"
    },
    {
      "x": -60,
      "y": 203,
      "z": 4,
      "name": "Rock_Stone"
    },
    {
      "x": -60,
      "y": 200,
      "z": 5,
      "name": "Rock_Stone"
    },
    {
      "x": -60,
      "y": 201,
      "z": 5,
      "name": "Rock_Stone"
    },
    {
      "x": -60,
      "y": 202,
      "z": 5,
      "name": "Rock_Stone"
    },
    {
      "x": -60,
      "y": 203,
      "z": 5,
      "name": "Rock_Stone"
    },
    {
      "x": -60,
      "y": 200,
      "z": 6,
      "name": "Rock_Stone"
    },
    {
      "x": -60,
      "y": 201,
      "z": 6,
      "name": "Rock_Stone"
    },
    {
      "x": -60,
      "y": 202,
      "z": 6,
      "name": "Rock_Stone"
    },
    {
      "x": -60,
      "y": 203,
      "z": 6,
      "name": "Rock_Stone"
    },
    {
      "x": -60,
      "y": 201,
      "z": 7,
      "name": "Rock_Stone"
    },
    {
      "x": -60,
      "y": 202,
      "z": 7,
      "name": "Rock_Stone"
    },
    {
      "x": -59,
      "y": 201,
      "z": -11,
      "name": "Rock_Stone"
    },
    {
      "x": -59,
      "y": 202,
      "z": -11,
      "name": "Rock_Stone"
    },
    {
      "x": -59,
      "y": 201,
      "z": -10,
      "name": "Rock_Stone"
    },
    {
      "x": -59,
      "y": 202,
      "z": -10,
      "name": "Rock_Stone"
    },
    {
      "x": -59,
      "y": 203,
      "z": -10,
      "name": "Rock_Stone"
    },
    {
      "x": -59,
      "y": 200,
      "z": -9,
      "name": "Rock_Stone"
    },
    {
      "x": -59,
      "y": 201,
      "z": -9,
      "name": "Rock_Stone"
    },
    {
      "x": -59,
      "y": 202,
      "z": -9,
      "name": "Rock_Stone"
    },
    {
      "x": -59,
      "y": 203,
      "z": -9,
      "name": "Rock_Stone"
    },
    {
      "x": -59,
      "y": 200,
      "z": -8,
      "name": "Rock_Stone"
    },
    {
      "x": -59,
      "y": 201,
      "z": -8,
      "name": "Rock_Stone"
    },
    {
      "x": -59,
      "y": 202,
      "z": -8,
      "name": "Rock_Stone"
    },
    {
      "x": -59,
      "y": 203,
      "z": -8,
      "name": "Rock_Stone"
    },
    {
      "x": -59,
      "y": 199,
      "z": -7,
      "name": "Rock_Stone"
    },
    {
      "x": -59,
      "y": 200,
      "z": -7,
      "name": "Rock_Stone"
    },
    {
      "x": -59,
      "y": 201,
      "z": -7,
      "name": "Rock_Stone"
    },
    {
      "x": -59,
      "y": 202,
      "z": -7,
      "name": "Rock_Stone"
    },
    {
      "x": -59,
      "y": 203,
      "z": -7,
      "name": "Rock_Stone"
    },
    {
      "x": -59,
      "y": 199,
      "z": -6,
      "name": "Rock_Stone"
    },
    {
      "x": -59,
      "y": 200,
      "z": -6,
      "name": "Rock_Stone"
    },
    {
      "x": -59,
      "y": 201,
      "z": -6,
      "name": "Rock_Stone"
    },
    {
      "x": -59,
      "y": 202,
      "z": -6,
      "name": "Rock_Stone"
    },
    {
      "x": -59,
      "y": 203,
      "z": -6,
      "name": "Rock_Stone"
    },
    {
      "x": -59,
      "y": 204,
      "z": -6,
      "name": "Rock_Stone"
    },
    {
      "x": -59,
      "y": 199,
      "z": -5,
      "name": "Rock_Stone"
    },
    {
      "x": -59,
      "y": 200,
      "z": -5,
      "name": "Rock_Stone"
    },
    {
      "x": -59,
      "y": 201,
      "z": -5,
      "name": "Rock_Stone"
    },
    {
      "x": -59,
      "y": 202,
      "z": -5,
      "name": "Rock_Stone"
    },
    {
      "x": -59,
      "y": 203,
      "z": -5,
      "name": "Rock_Stone"
    },
    {
      "x": -59,
      "y": 204,
      "z": -5,
      "name": "Rock_Stone"
    },
    {
      "x": -59,
      "y": 199,
      "z": -4,
      "name": "Rock_Stone"
    },
    {
      "x": -59,
      "y": 200,
      "z": -4,
      "name": "Rock_Stone"
    },
    {
      "x": -59,
      "y": 201,
      "z": -4,
      "name": "Rock_Stone"
    },
    {
      "x": -59,
      "y": 202,
      "z": -4,
      "name": "Rock_Stone"
    },
    {
      "x": -59,
      "y": 203,
      "z": -4,
      "name": "Rock_Stone"
    },
    {
      "x": -59,
      "y": 204,
      "z": -4,
      "name": "Rock_Stone"
    },
    {
      "x": -59,
      "y": 199,
      "z": -3,
      "name": "Rock_Stone"
    },
    {
      "x": -59,
      "y": 200,
      "z": -3,
      "name": "Rock_Stone"
    },
    {
      "x": -59,
      "y": 201,
      "z": -3,
      "name": "Rock_Stone"
    },
    {
      "x": -59,
      "y": 202,
      "z": -3,
      "name": "Rock_Stone"
    },
    {
      "x": -59,
      "y": 203,
      "z": -3,
      "name": "Rock_Stone"
    },
    {
      "x": -59,
      "y": 204,
      "z": -3,
      "name": "Rock_Stone"
    },
    {
      "x": -59,
      "y": 199,
      "z": -2,
      "name": "Rock_Stone"
    },
    {
      "x": -59,
      "y": 200,
      "z": -2,
      "name": "Rock_Stone"
    },
    {
      "x": -59,
      "y": 201,
      "z": -2,
      "name": "Rock_Stone"
    },
    {
      "x": -59,
      "y": 202,
      "z": -2,
      "name": "Rock_Stone"
    },
    {
      "x": -59,
      "y": 203,
      "z": -2,
      "name": "Rock_Stone"
    },
    {
      "x": -59,
      "y": 204,
      "z": -2,
      "name": "Rock_Stone"
    },
    {
      "x": -59,
      "y": 199,
      "z": -1,
      "name": "Rock_Stone"
    },
    {
      "x": -59,
      "y": 200,
      "z": -1,
      "name": "Rock_Stone"
    },
    {
      "x": -59,
      "y": 201,
      "z": -1,
      "name": "Rock_Stone"
    },
    {
      "x": -59,
      "y": 202,
      "z": -1,
      "name": "Rock_Stone"
    },
    {
      "x": -59,
      "y": 203,
      "z": -1,
      "name": "Rock_Stone"
    },
    {
      "x": -59,
      "y": 204,
      "z": -1,
      "name": "Rock_Stone"
    },
    {
      "x": -59,
      "y": 199,
      "z": 0,
      "name": "Rock_Stone"
    },
    {
      "x": -59,
      "y": 200,
      "z": 0,
      "name": "Rock_Stone"
    },
    {
      "x": -59,
      "y": 201,
      "z": 0,
      "name": "Rock_Stone"
    },
    {
      "x": -59,
      "y": 202,
      "z": 0,
      "name": "Rock_Stone"
    },
    {
      "x": -59,
      "y": 203,
      "z": 0,
      "name": "Rock_Stone"
    },
    {
      "x": -59,
      "y": 204,
      "z": 0,
      "name": "Rock_Stone"
    },
    {
      "x": -59,
      "y": 199,
      "z": 1,
      "name": "Rock_Stone"
    },
    {
      "x": -59,
      "y": 200,
      "z": 1,
      "name": "Rock_Stone"
    },
    {
      "x": -59,
      "y": 201,
      "z": 1,
      "name": "Rock_Stone"
    },
    {
      "x": -59,
      "y": 202,
      "z": 1,
      "name": "Rock_Stone"
    },
    {
      "x": -59,
      "y": 203,
      "z": 1,
      "name": "Rock_Stone"
    },
    {
      "x": -59,
      "y": 204,
      "z": 1,
      "name": "Rock_Stone"
    },
    {
      "x": -59,
      "y": 199,
      "z": 2,
      "name": "Rock_Stone"
    },
    {
      "x": -59,
      "y": 200,
      "z": 2,
      "name": "Rock_Stone"
    },
    {
      "x": -59,
      "y": 201,
      "z": 2,
      "name": "Rock_Stone"
    },
    {
      "x": -59,
      "y": 202,
      "z": 2,
      "name": "Rock_Stone"
    },
    {
      "x": -59,
      "y": 203,
      "z": 2,
      "name": "Rock_Stone"
    },
    {
      "x": -59,
      "y": 204,
      "z": 2,
      "name": "Rock_Stone"
    },
    {
      "x": -59,
      "y": 199,
      "z": 3,
      "name": "Rock_Stone"
    },
    {
      "x": -59,
      "y": 200,
      "z": 3,
      "name": "Rock_Stone"
    },
    {
      "x": -59,
      "y": 201,
      "z": 3,
      "name": "Rock_Stone"
    },
    {
      "x": -59,
      "y": 202,
      "z": 3,
      "name": "Rock_Stone"
    },
    {
      "x": -59,
      "y": 203,
      "z": 3,
      "name": "Rock_Stone"
    },
    {
      "x": -59,
      "y": 204,
      "z": 3,
      "name": "Rock_Stone"
    },
    {
      "x": -59,
      "y": 199,
      "z": 4,
      "name": "Rock_Stone"
    },
    {
      "x": -59,
      "y": 200,
      "z": 4,
      "name": "Rock_Stone"
    },
    {
      "x": -59,
      "y": 201,
      "z": 4,
      "name": "Rock_Stone"
    },
    {
      "x": -59,
      "y": 202,
      "z": 4,
      "name": "Rock_Stone"
    },
    {
      "x": -59,
      "y": 203,
      "z": 4,
      "name": "Rock_Stone"
    },
    {
      "x": -59,
      "y": 204,
      "z": 4,
      "name": "Rock_Stone"
    },
    {
      "x": -59,
      "y": 199,
      "z": 5,
      "name": "Rock_Stone"
    },
    {
      "x": -59,
      "y": 200,
      "z": 5,
      "name": "Rock_Stone"
    },
    {
      "x": -59,
      "y": 201,
      "z": 5,
      "name": "Rock_Stone"
    },
    {
      "x": -59,
      "y": 202,
      "z": 5,
      "name": "Rock_Stone"
    },
    {
      "x": -59,
      "y": 203,
      "z": 5,
      "name": "Rock_Stone"
    },
    {
      "x": -59,
      "y": 204,
      "z": 5,
      "name": "Rock_Stone"
    },
    {
      "x": -59,
      "y": 199,
      "z": 6,
      "name": "Rock_Stone"
    },
    {
      "x": -59,
      "y": 200,
      "z": 6,
      "name": "Rock_Stone"
    },
    {
      "x": -59,
      "y": 201,
      "z": 6,
      "name": "Rock_Stone"
    },
    {
      "x": -59,
      "y": 202,
      "z": 6,
      "name": "Rock_Stone"
    },
    {
      "x": -59,
      "y": 203,
      "z": 6,
      "name": "Rock_Stone"
    },
    {
      "x": -59,
      "y": 204,
      "z": 6,
      "name": "Rock_Stone"
    },
    {
      "x": -59,
      "y": 200,
      "z": 7,
      "name": "Rock_Stone"
    },
    {
      "x": -59,
      "y": 201,
      "z": 7,
      "name": "Rock_Stone"
    },
    {
      "x": -59,
      "y": 202,
      "z": 7,
      "name": "Rock_Stone"
    },
    {
      "x": -59,
      "y": 203,
      "z": 7,
      "name": "Rock_Stone"
    },
    {
      "x": -59,
      "y": 201,
      "z": 8,
      "name": "Rock_Stone"
    },
    {
      "x": -59,
      "y": 202,
      "z": 8,
      "name": "Rock_Stone"
    },
    {
      "x": -59,
      "y": 203,
      "z": 8,
      "name": "Rock_Stone"
    },
    {
      "x": -59,
      "y": 201,
      "z": 9,
      "name": "Rock_Stone"
    },
    {
      "x": -59,
      "y": 202,
      "z": 9,
      "name": "Rock_Stone"
    },
    {
      "x": -58,
      "y": 200,
      "z": -12,
      "name": "Rock_Stone"
    },
    {
      "x": -58,
      "y": 201,
      "z": -12,
      "name": "Rock_Stone"
    },
    {
      "x": -58,
      "y": 202,
      "z": -12,
      "name": "Rock_Stone"
    },
    {
      "x": -58,
      "y": 200,
      "z": -11,
      "name": "Rock_Stone"
    },
    {
      "x": -58,
      "y": 201,
      "z": -11,
      "name": "Rock_Stone"
    },
    {
      "x": -58,
      "y": 202,
      "z": -11,
      "name": "Rock_Stone"
    },
    {
      "x": -58,
      "y": 203,
      "z": -11,
      "name": "Rock_Stone"
    },
    {
      "x": -58,
      "y": 200,
      "z": -10,
      "name": "Rock_Stone"
    },
    {
      "x": -58,
      "y": 201,
      "z": -10,
      "name": "Rock_Stone"
    },
    {
      "x": -58,
      "y": 202,
      "z": -10,
      "name": "Rock_Stone"
    },
    {
      "x": -58,
      "y": 203,
      "z": -10,
      "name": "Rock_Stone"
    },
    {
      "x": -58,
      "y": 199,
      "z": -9,
      "name": "Rock_Stone"
    },
    {
      "x": -58,
      "y": 200,
      "z": -9,
      "name": "Rock_Stone"
    },
    {
      "x": -58,
      "y": 201,
      "z": -9,
      "name": "Rock_Stone"
    },
    {
      "x": -58,
      "y": 202,
      "z": -9,
      "name": "Rock_Stone"
    },
    {
      "x": -58,
      "y": 203,
      "z": -9,
      "name": "Rock_Stone"
    },
    {
      "x": -58,
      "y": 199,
      "z": -8,
      "name": "Rock_Stone"
    },
    {
      "x": -58,
      "y": 200,
      "z": -8,
      "name": "Rock_Stone"
    },
    {
      "x": -58,
      "y": 201,
      "z": -8,
      "name": "Rock_Stone"
    },
    {
      "x": -58,
      "y": 202,
      "z": -8,
      "name": "Rock_Stone"
    },
    {
      "x": -58,
      "y": 203,
      "z": -8,
      "name": "Rock_Stone"
    },
    {
      "x": -58,
      "y": 204,
      "z": -8,
      "name": "Rock_Stone"
    },
    {
      "x": -58,
      "y": 199,
      "z": -7,
      "name": "Rock_Stone"
    },
    {
      "x": -58,
      "y": 200,
      "z": -7,
      "name": "Rock_Stone"
    },
    {
      "x": -58,
      "y": 201,
      "z": -7,
      "name": "Rock_Stone"
    },
    {
      "x": -58,
      "y": 202,
      "z": -7,
      "name": "Rock_Stone"
    },
    {
      "x": -58,
      "y": 203,
      "z": -7,
      "name": "Rock_Stone"
    },
    {
      "x": -58,
      "y": 204,
      "z": -7,
      "name": "Rock_Stone"
    },
    {
      "x": -58,
      "y": 198,
      "z": -6,
      "name": "Rock_Stone"
    },
    {
      "x": -58,
      "y": 199,
      "z": -6,
      "name": "Rock_Stone"
    },
    {
      "x": -58,
      "y": 200,
      "z": -6,
      "name": "Rock_Stone"
    },
    {
      "x": -58,
      "y": 201,
      "z": -6,
      "name": "Rock_Stone"
    },
    {
      "x": -58,
      "y": 202,
      "z": -6,
      "name": "Rock_Stone"
    },
    {
      "x": -58,
      "y": 203,
      "z": -6,
      "name": "Rock_Stone"
    },
    {
      "x": -58,
      "y": 204,
      "z": -6,
      "name": "Rock_Stone"
    },
    {
      "x": -58,
      "y": 198,
      "z": -5,
      "name": "Rock_Stone"
    },
    {
      "x": -58,
      "y": 199,
      "z": -5,
      "name": "Rock_Stone"
    },
    {
      "x": -58,
      "y": 200,
      "z": -5,
      "name": "Rock_Stone"
    },
    {
      "x": -58,
      "y": 201,
      "z": -5,
      "name": "Rock_Stone"
    },
    {
      "x": -58,
      "y": 202,
      "z": -5,
      "name": "Rock_Stone"
    },
    {
      "x": -58,
      "y": 203,
      "z": -5,
      "name": "Rock_Stone"
    },
    {
      "x": -58,
      "y": 204,
      "z": -5,
      "name": "Rock_Stone"
    },
    {
      "x": -58,
      "y": 198,
      "z": -4,
      "name": "Rock_Stone"
    },
    {
      "x": -58,
      "y": 199,
      "z": -4,
      "name": "Rock_Stone"
    },
    {
      "x": -58,
      "y": 200,
      "z": -4,
      "name": "Rock_Stone"
    },
    {
      "x": -58,
      "y": 201,
      "z": -4,
      "name": "Rock_Stone"
    },
    {
      "x": -58,
      "y": 202,
      "z": -4,
      "name": "Rock_Stone"
    },
    {
      "x": -58,
      "y": 203,
      "z": -4,
      "name": "Rock_Stone"
    },
    {
      "x": -58,
      "y": 204,
      "z": -4,
      "name": "Rock_Stone"
    },
    {
      "x": -58,
      "y": 198,
      "z": -3,
      "name": "Rock_Stone"
    },
    {
      "x": -58,
      "y": 199,
      "z": -3,
      "name": "Rock_Stone"
    },
    {
      "x": -58,
      "y": 200,
      "z": -3,
      "name": "Rock_Stone"
    },
    {
      "x": -58,
      "y": 201,
      "z": -3,
      "name": "Rock_Stone"
    },
    {
      "x": -58,
      "y": 202,
      "z": -3,
      "name": "Rock_Stone"
    },
    {
      "x": -58,
      "y": 203,
      "z": -3,
      "name": "Rock_Stone"
    },
    {
      "x": -58,
      "y": 204,
      "z": -3,
      "name": "Rock_Stone"
    },
    {
      "x": -58,
      "y": 205,
      "z": -3,
      "name": "Rock_Stone"
    },
    {
      "x": -58,
      "y": 198,
      "z": -2,
      "name": "Rock_Stone"
    },
    {
      "x": -58,
      "y": 199,
      "z": -2,
      "name": "Rock_Stone"
    },
    {
      "x": -58,
      "y": 200,
      "z": -2,
      "name": "Rock_Stone"
    },
    {
      "x": -58,
      "y": 201,
      "z": -2,
      "name": "Rock_Stone"
    },
    {
      "x": -58,
      "y": 202,
      "z": -2,
      "name": "Rock_Stone"
    },
    {
      "x": -58,
      "y": 203,
      "z": -2,
      "name": "Rock_Stone"
    },
    {
      "x": -58,
      "y": 204,
      "z": -2,
      "name": "Rock_Stone"
    },
    {
      "x": -58,
      "y": 205,
      "z": -2,
      "name": "Rock_Stone"
    },
    {
      "x": -58,
      "y": 198,
      "z": -1,
      "name": "Rock_Stone"
    },
    {
      "x": -58,
      "y": 199,
      "z": -1,
      "name": "Rock_Stone"
    },
    {
      "x": -58,
      "y": 200,
      "z": -1,
      "name": "Rock_Stone"
    },
    {
      "x": -58,
      "y": 201,
      "z": -1,
      "name": "Rock_Stone"
    },
    {
      "x": -58,
      "y": 202,
      "z": -1,
      "name": "Rock_Stone"
    },
    {
      "x": -58,
      "y": 203,
      "z": -1,
      "name": "Rock_Stone"
    },
    {
      "x": -58,
      "y": 204,
      "z": -1,
      "name": "Rock_Stone"
    },
    {
      "x": -58,
      "y": 205,
      "z": -1,
      "name": "Rock_Stone"
    },
    {
      "x": -58,
      "y": 198,
      "z": 0,
      "name": "Rock_Stone"
    },
    {
      "x": -58,
      "y": 199,
      "z": 0,
      "name": "Rock_Stone"
    },
    {
      "x": -58,
      "y": 200,
      "z": 0,
      "name": "Rock_Stone"
    },
    {
      "x": -58,
      "y": 201,
      "z": 0,
      "name": "Rock_Stone"
    },
    {
      "x": -58,
      "y": 202,
      "z": 0,
      "name": "Rock_Stone"
    },
    {
      "x": -58,
      "y": 203,
      "z": 0,
      "name": "Rock_Stone"
    },
    {
      "x": -58,
      "y": 204,
      "z": 0,
      "name": "Rock_Stone"
    },
    {
      "x": -58,
      "y": 205,
      "z": 0,
      "name": "Rock_Stone"
    },
    {
      "x": -58,
      "y": 198,
      "z": 1,
      "name": "Rock_Stone"
    },
    {
      "x": -58,
      "y": 199,
      "z": 1,
      "name": "Rock_Stone"
    },
    {
      "x": -58,
      "y": 200,
      "z": 1,
      "name": "Rock_Stone"
    },
    {
      "x": -58,
      "y": 201,
      "z": 1,
      "name": "Rock_Stone"
    },
    {
      "x": -58,
      "y": 202,
      "z": 1,
      "name": "Rock_Stone"
    },
    {
      "x": -58,
      "y": 203,
      "z": 1,
      "name": "Rock_Stone"
    },
    {
      "x": -58,
      "y": 204,
      "z": 1,
      "name": "Rock_Stone"
    },
    {
      "x": -58,
      "y": 205,
      "z": 1,
      "name": "Rock_Stone"
    },
    {
      "x": -58,
      "y": 198,
      "z": 2,
      "name": "Rock_Stone"
    },
    {
      "x": -58,
      "y": 199,
      "z": 2,
      "name": "Rock_Stone"
    },
    {
      "x": -58,
      "y": 200,
      "z": 2,
      "name": "Rock_Stone"
    },
    {
      "x": -58,
      "y": 201,
      "z": 2,
      "name": "Rock_Stone"
    },
    {
      "x": -58,
      "y": 202,
      "z": 2,
      "name": "Rock_Stone"
    },
    {
      "x": -58,
      "y": 203,
      "z": 2,
      "name": "Rock_Stone"
    },
    {
      "x": -58,
      "y": 204,
      "z": 2,
      "name": "Rock_Stone"
    },
    {
      "x": -58,
      "y": 205,
      "z": 2,
      "name": "Rock_Stone"
    },
    {
      "x": -58,
      "y": 198,
      "z": 3,
      "name": "Rock_Stone"
    },
    {
      "x": -58,
      "y": 199,
      "z": 3,
      "name": "Rock_Stone"
    },
    {
      "x": -58,
      "y": 200,
      "z": 3,
      "name": "Rock_Stone"
    },
    {
      "x": -58,
      "y": 201,
      "z": 3,
      "name": "Rock_Stone"
    },
    {
      "x": -58,
      "y": 202,
      "z": 3,
      "name": "Rock_Stone"
    },
    {
      "x": -58,
      "y": 203,
      "z": 3,
      "name": "Rock_Stone"
    },
    {
      "x": -58,
      "y": 204,
      "z": 3,
      "name": "Rock_Stone"
    },
    {
      "x": -58,
      "y": 205,
      "z": 3,
      "name": "Rock_Stone"
    },
    {
      "x": -58,
      "y": 199,
      "z": 4,
      "name": "Rock_Stone"
    },
    {
      "x": -58,
      "y": 200,
      "z": 4,
      "name": "Rock_Stone"
    },
    {
      "x": -58,
      "y": 201,
      "z": 4,
      "name": "Rock_Stone"
    },
    {
      "x": -58,
      "y": 202,
      "z": 4,
      "name": "Rock_Stone"
    },
    {
      "x": -58,
      "y": 203,
      "z": 4,
      "name": "Rock_Stone"
    },
    {
      "x": -58,
      "y": 204,
      "z": 4,
      "name": "Rock_Stone"
    },
    {
      "x": -58,
      "y": 199,
      "z": 5,
      "name": "Rock_Stone"
    },
    {
      "x": -58,
      "y": 200,
      "z": 5,
      "name": "Rock_Stone"
    },
    {
      "x": -58,
      "y": 201,
      "z": 5,
      "name": "Rock_Stone"
    },
    {
      "x": -58,
      "y": 202,
      "z": 5,
      "name": "Rock_Stone"
    },
    {
      "x": -58,
      "y": 203,
      "z": 5,
      "name": "Rock_Stone"
    },
    {
      "x": -58,
      "y": 204,
      "z": 5,
      "name": "Rock_Stone"
    },
    {
      "x": -58,
      "y": 199,
      "z": 6,
      "name": "Rock_Stone"
    },
    {
      "x": -58,
      "y": 200,
      "z": 6,
      "name": "Rock_Stone"
    },
    {
      "x": -58,
      "y": 201,
      "z": 6,
      "name": "Rock_Stone"
    },
    {
      "x": -58,
      "y": 202,
      "z": 6,
      "name": "Rock_Stone"
    },
    {
      "x": -58,
      "y": 203,
      "z": 6,
      "name": "Rock_Stone"
    },
    {
      "x": -58,
      "y": 204,
      "z": 6,
      "name": "Rock_Stone"
    },
    {
      "x": -58,
      "y": 199,
      "z": 7,
      "name": "Rock_Stone"
    },
    {
      "x": -58,
      "y": 200,
      "z": 7,
      "name": "Rock_Stone"
    },
    {
      "x": -58,
      "y": 201,
      "z": 7,
      "name": "Rock_Stone"
    },
    {
      "x": -58,
      "y": 202,
      "z": 7,
      "name": "Rock_Stone"
    },
    {
      "x": -58,
      "y": 203,
      "z": 7,
      "name": "Rock_Stone"
    },
    {
      "x": -58,
      "y": 204,
      "z": 7,
      "name": "Rock_Stone"
    },
    {
      "x": -58,
      "y": 200,
      "z": 8,
      "name": "Rock_Stone"
    },
    {
      "x": -58,
      "y": 201,
      "z": 8,
      "name": "Rock_Stone"
    },
    {
      "x": -58,
      "y": 202,
      "z": 8,
      "name": "Rock_Stone"
    },
    {
      "x": -58,
      "y": 203,
      "z": 8,
      "name": "Rock_Stone"
    },
    {
      "x": -58,
      "y": 204,
      "z": 8,
      "name": "Rock_Stone"
    },
    {
      "x": -58,
      "y": 200,
      "z": 9,
      "name": "Rock_Stone"
    },
    {
      "x": -58,
      "y": 201,
      "z": 9,
      "name": "Rock_Stone"
    },
    {
      "x": -58,
      "y": 202,
      "z": 9,
      "name": "Rock_Stone"
    },
    {
      "x": -58,
      "y": 203,
      "z": 9,
      "name": "Rock_Stone"
    },
    {
      "x": -58,
      "y": 200,
      "z": 10,
      "name": "Rock_Stone"
    },
    {
      "x": -58,
      "y": 201,
      "z": 10,
      "name": "Rock_Stone"
    },
    {
      "x": -58,
      "y": 202,
      "z": 10,
      "name": "Rock_Stone"
    },
    {
      "x": -58,
      "y": 203,
      "z": 10,
      "name": "Rock_Stone"
    },
    {
      "x": -57,
      "y": 200,
      "z": -13,
      "name": "Rock_Stone"
    },
    {
      "x": -57,
      "y": 201,
      "z": -13,
      "name": "Rock_Stone"
    },
    {
      "x": -57,
      "y": 202,
      "z": -13,
      "name": "Rock_Stone"
    },
    {
      "x": -57,
      "y": 200,
      "z": -12,
      "name": "Rock_Stone"
    },
    {
      "x": -57,
      "y": 201,
      "z": -12,
      "name": "Rock_Stone"
    },
    {
      "x": -57,
      "y": 202,
      "z": -12,
      "name": "Rock_Stone"
    },
    {
      "x": -57,
      "y": 203,
      "z": -12,
      "name": "Rock_Stone"
    },
    {
      "x": -57,
      "y": 199,
      "z": -11,
      "name": "Rock_Stone"
    },
    {
      "x": -57,
      "y": 200,
      "z": -11,
      "name": "Rock_Stone"
    },
    {
      "x": -57,
      "y": 201,
      "z": -11,
      "name": "Rock_Stone"
    },
    {
      "x": -57,
      "y": 202,
      "z": -11,
      "name": "Rock_Stone"
    },
    {
      "x": -57,
      "y": 203,
      "z": -11,
      "name": "Rock_Stone"
    },
    {
      "x": -57,
      "y": 204,
      "z": -11,
      "name": "Rock_Stone"
    },
    {
      "x": -57,
      "y": 199,
      "z": -10,
      "name": "Rock_Stone"
    },
    {
      "x": -57,
      "y": 200,
      "z": -10,
      "name": "Rock_Stone"
    },
    {
      "x": -57,
      "y": 201,
      "z": -10,
      "name": "Rock_Stone"
    },
    {
      "x": -57,
      "y": 202,
      "z": -10,
      "name": "Rock_Stone"
    },
    {
      "x": -57,
      "y": 203,
      "z": -10,
      "name": "Rock_Stone"
    },
    {
      "x": -57,
      "y": 204,
      "z": -10,
      "name": "Rock_Stone"
    },
    {
      "x": -57,
      "y": 199,
      "z": -9,
      "name": "Rock_Stone"
    },
    {
      "x": -57,
      "y": 200,
      "z": -9,
      "name": "Rock_Stone"
    },
    {
      "x": -57,
      "y": 201,
      "z": -9,
      "name": "Rock_Stone"
    },
    {
      "x": -57,
      "y": 202,
      "z": -9,
      "name": "Rock_Stone"
    },
    {
      "x": -57,
      "y": 203,
      "z": -9,
      "name": "Rock_Stone"
    },
    {
      "x": -57,
      "y": 204,
      "z": -9,
      "name": "Rock_Stone"
    },
    {
      "x": -57,
      "y": 198,
      "z": -8,
      "name": "Rock_Stone"
    },
    {
      "x": -57,
      "y": 199,
      "z": -8,
      "name": "Rock_Stone"
    },
    {
      "x": -57,
      "y": 200,
      "z": -8,
      "name": "Rock_Stone"
    },
    {
      "x": -57,
      "y": 201,
      "z": -8,
      "name": "Rock_Stone"
    },
    {
      "x": -57,
      "y": 202,
      "z": -8,
      "name": "Rock_Stone"
    },
    {
      "x": -57,
      "y": 203,
      "z": -8,
      "name": "Rock_Stone"
    },
    {
      "x": -57,
      "y": 204,
      "z": -8,
      "name": "Rock_Stone"
    },
    {
      "x": -57,
      "y": 198,
      "z": -7,
      "name": "Rock_Stone"
    },
    {
      "x": -57,
      "y": 199,
      "z": -7,
      "name": "Rock_Stone"
    },
    {
      "x": -57,
      "y": 200,
      "z": -7,
      "name": "Rock_Stone"
    },
    {
      "x": -57,
      "y": 201,
      "z": -7,
      "name": "Rock_Stone"
    },
    {
      "x": -57,
      "y": 202,
      "z": -7,
      "name": "Rock_Stone"
    },
    {
      "x": -57,
      "y": 203,
      "z": -7,
      "name": "Rock_Stone"
    },
    {
      "x": -57,
      "y": 204,
      "z": -7,
      "name": "Rock_Stone"
    },
    {
      "x": -57,
      "y": 198,
      "z": -6,
      "name": "Rock_Stone"
    },
    {
      "x": -57,
      "y": 199,
      "z": -6,
      "name": "Rock_Stone"
    },
    {
      "x": -57,
      "y": 200,
      "z": -6,
      "name": "Rock_Stone"
    },
    {
      "x": -57,
      "y": 201,
      "z": -6,
      "name": "Rock_Stone"
    },
    {
      "x": -57,
      "y": 202,
      "z": -6,
      "name": "Rock_Stone"
    },
    {
      "x": -57,
      "y": 203,
      "z": -6,
      "name": "Rock_Stone"
    },
    {
      "x": -57,
      "y": 204,
      "z": -6,
      "name": "Rock_Stone"
    },
    {
      "x": -57,
      "y": 205,
      "z": -6,
      "name": "Rock_Stone"
    },
    {
      "x": -57,
      "y": 198,
      "z": -5,
      "name": "Rock_Stone"
    },
    {
      "x": -57,
      "y": 199,
      "z": -5,
      "name": "Rock_Stone"
    },
    {
      "x": -57,
      "y": 200,
      "z": -5,
      "name": "Rock_Stone"
    },
    {
      "x": -57,
      "y": 201,
      "z": -5,
      "name": "Rock_Stone"
    },
    {
      "x": -57,
      "y": 202,
      "z": -5,
      "name": "Rock_Stone"
    },
    {
      "x": -57,
      "y": 203,
      "z": -5,
      "name": "Rock_Stone"
    },
    {
      "x": -57,
      "y": 204,
      "z": -5,
      "name": "Rock_Stone"
    },
    {
      "x": -57,
      "y": 205,
      "z": -5,
      "name": "Rock_Stone"
    },
    {
      "x": -57,
      "y": 198,
      "z": -4,
      "name": "Rock_Stone"
    },
    {
      "x": -57,
      "y": 199,
      "z": -4,
      "name": "Rock_Stone"
    },
    {
      "x": -57,
      "y": 200,
      "z": -4,
      "name": "Rock_Stone"
    },
    {
      "x": -57,
      "y": 201,
      "z": -4,
      "name": "Rock_Stone"
    },
    {
      "x": -57,
      "y": 202,
      "z": -4,
      "name": "Rock_Stone"
    },
    {
      "x": -57,
      "y": 203,
      "z": -4,
      "name": "Rock_Stone"
    },
    {
      "x": -57,
      "y": 204,
      "z": -4,
      "name": "Rock_Stone"
    },
    {
      "x": -57,
      "y": 205,
      "z": -4,
      "name": "Rock_Stone"
    },
    {
      "x": -57,
      "y": 198,
      "z": -3,
      "name": "Rock_Stone"
    },
    {
      "x": -57,
      "y": 199,
      "z": -3,
      "name": "Rock_Stone"
    },
    {
      "x": -57,
      "y": 200,
      "z": -3,
      "name": "Rock_Stone"
    },
    {
      "x": -57,
      "y": 201,
      "z": -3,
      "name": "Rock_Stone"
    },
    {
      "x": -57,
      "y": 202,
      "z": -3,
      "name": "Rock_Stone"
    },
    {
      "x": -57,
      "y": 203,
      "z": -3,
      "name": "Rock_Stone"
    },
    {
      "x": -57,
      "y": 204,
      "z": -3,
      "name": "Rock_Stone"
    },
    {
      "x": -57,
      "y": 205,
      "z": -3,
      "name": "Rock_Stone"
    },
    {
      "x": -57,
      "y": 198,
      "z": -2,
      "name": "Rock_Stone"
    },
    {
      "x": -57,
      "y": 199,
      "z": -2,
      "name": "Rock_Stone"
    },
    {
      "x": -57,
      "y": 200,
      "z": -2,
      "name": "Rock_Stone"
    },
    {
      "x": -57,
      "y": 201,
      "z": -2,
      "name": "Rock_Stone"
    },
    {
      "x": -57,
      "y": 202,
      "z": -2,
      "name": "Rock_Stone"
    },
    {
      "x": -57,
      "y": 203,
      "z": -2,
      "name": "Rock_Stone"
    },
    {
      "x": -57,
      "y": 204,
      "z": -2,
      "name": "Rock_Stone"
    },
    {
      "x": -57,
      "y": 205,
      "z": -2,
      "name": "Rock_Stone"
    },
    {
      "x": -57,
      "y": 198,
      "z": -1,
      "name": "Rock_Stone"
    },
    {
      "x": -57,
      "y": 199,
      "z": -1,
      "name": "Rock_Stone"
    },
    {
      "x": -57,
      "y": 200,
      "z": -1,
      "name": "Rock_Stone"
    },
    {
      "x": -57,
      "y": 201,
      "z": -1,
      "name": "Rock_Stone"
    },
    {
      "x": -57,
      "y": 202,
      "z": -1,
      "name": "Rock_Stone"
    },
    {
      "x": -57,
      "y": 203,
      "z": -1,
      "name": "Rock_Stone"
    },
    {
      "x": -57,
      "y": 204,
      "z": -1,
      "name": "Rock_Stone"
    },
    {
      "x": -57,
      "y": 205,
      "z": -1,
      "name": "Rock_Stone"
    },
    {
      "x": -57,
      "y": 198,
      "z": 0,
      "name": "Rock_Stone"
    },
    {
      "x": -57,
      "y": 199,
      "z": 0,
      "name": "Rock_Stone"
    },
    {
      "x": -57,
      "y": 200,
      "z": 0,
      "name": "Rock_Stone"
    },
    {
      "x": -57,
      "y": 201,
      "z": 0,
      "name": "Rock_Stone"
    },
    {
      "x": -57,
      "y": 202,
      "z": 0,
      "name": "Rock_Stone"
    },
    {
      "x": -57,
      "y": 203,
      "z": 0,
      "name": "Rock_Stone"
    },
    {
      "x": -57,
      "y": 204,
      "z": 0,
      "name": "Rock_Stone"
    },
    {
      "x": -57,
      "y": 205,
      "z": 0,
      "name": "Rock_Stone"
    },
    {
      "x": -57,
      "y": 198,
      "z": 1,
      "name": "Rock_Stone"
    },
    {
      "x": -57,
      "y": 199,
      "z": 1,
      "name": "Rock_Stone"
    },
    {
      "x": -57,
      "y": 200,
      "z": 1,
      "name": "Rock_Stone"
    },
    {
      "x": -57,
      "y": 201,
      "z": 1,
      "name": "Rock_Stone"
    },
    {
      "x": -57,
      "y": 202,
      "z": 1,
      "name": "Rock_Stone"
    },
    {
      "x": -57,
      "y": 203,
      "z": 1,
      "name": "Rock_Stone"
    },
    {
      "x": -57,
      "y": 204,
      "z": 1,
      "name": "Rock_Stone"
    },
    {
      "x": -57,
      "y": 205,
      "z": 1,
      "name": "Rock_Stone"
    },
    {
      "x": -57,
      "y": 198,
      "z": 2,
      "name": "Rock_Stone"
    },
    {
      "x": -57,
      "y": 199,
      "z": 2,
      "name": "Rock_Stone"
    },
    {
      "x": -57,
      "y": 200,
      "z": 2,
      "name": "Rock_Stone"
    },
    {
      "x": -57,
      "y": 201,
      "z": 2,
      "name": "Rock_Stone"
    },
    {
      "x": -57,
      "y": 202,
      "z": 2,
      "name": "Rock_Stone"
    },
    {
      "x": -57,
      "y": 203,
      "z": 2,
      "name": "Rock_Stone"
    },
    {
      "x": -57,
      "y": 204,
      "z": 2,
      "name": "Rock_Stone"
    },
    {
      "x": -57,
      "y": 205,
      "z": 2,
      "name": "Rock_Stone"
    },
    {
      "x": -57,
      "y": 198,
      "z": 3,
      "name": "Rock_Stone"
    },
    {
      "x": -57,
      "y": 199,
      "z": 3,
      "name": "Rock_Stone"
    },
    {
      "x": -57,
      "y": 200,
      "z": 3,
      "name": "Rock_Stone"
    },
    {
      "x": -57,
      "y": 201,
      "z": 3,
      "name": "Rock_Stone"
    },
    {
      "x": -57,
      "y": 202,
      "z": 3,
      "name": "Rock_Stone"
    },
    {
      "x": -57,
      "y": 203,
      "z": 3,
      "name": "Rock_Stone"
    },
    {
      "x": -57,
      "y": 204,
      "z": 3,
      "name": "Rock_Stone"
    },
    {
      "x": -57,
      "y": 205,
      "z": 3,
      "name": "Rock_Stone"
    },
    {
      "x": -57,
      "y": 198,
      "z": 4,
      "name": "Rock_Stone"
    },
    {
      "x": -57,
      "y": 199,
      "z": 4,
      "name": "Rock_Stone"
    },
    {
      "x": -57,
      "y": 200,
      "z": 4,
      "name": "Rock_Stone"
    },
    {
      "x": -57,
      "y": 201,
      "z": 4,
      "name": "Rock_Stone"
    },
    {
      "x": -57,
      "y": 202,
      "z": 4,
      "name": "Rock_Stone"
    },
    {
      "x": -57,
      "y": 203,
      "z": 4,
      "name": "Rock_Stone"
    },
    {
      "x": -57,
      "y": 204,
      "z": 4,
      "name": "Rock_Stone"
    },
    {
      "x": -57,
      "y": 205,
      "z": 4,
      "name": "Rock_Stone"
    },
    {
      "x": -57,
      "y": 198,
      "z": 5,
      "name": "Rock_Stone"
    },
    {
      "x": -57,
      "y": 199,
      "z": 5,
      "name": "Rock_Stone"
    },
    {
      "x": -57,
      "y": 200,
      "z": 5,
      "name": "Rock_Stone"
    },
    {
      "x": -57,
      "y": 201,
      "z": 5,
      "name": "Rock_Stone"
    },
    {
      "x": -57,
      "y": 202,
      "z": 5,
      "name": "Rock_Stone"
    },
    {
      "x": -57,
      "y": 203,
      "z": 5,
      "name": "Rock_Stone"
    },
    {
      "x": -57,
      "y": 204,
      "z": 5,
      "name": "Rock_Stone"
    },
    {
      "x": -57,
      "y": 205,
      "z": 5,
      "name": "Rock_Stone"
    },
    {
      "x": -57,
      "y": 198,
      "z": 6,
      "name": "Rock_Stone"
    },
    {
      "x": -57,
      "y": 199,
      "z": 6,
      "name": "Rock_Stone"
    },
    {
      "x": -57,
      "y": 200,
      "z": 6,
      "name": "Rock_Stone"
    },
    {
      "x": -57,
      "y": 201,
      "z": 6,
      "name": "Rock_Stone"
    },
    {
      "x": -57,
      "y": 202,
      "z": 6,
      "name": "Rock_Stone"
    },
    {
      "x": -57,
      "y": 203,
      "z": 6,
      "name": "Rock_Stone"
    },
    {
      "x": -57,
      "y": 204,
      "z": 6,
      "name": "Rock_Stone"
    },
    {
      "x": -57,
      "y": 205,
      "z": 6,
      "name": "Rock_Stone"
    },
    {
      "x": -57,
      "y": 199,
      "z": 7,
      "name": "Rock_Stone"
    },
    {
      "x": -57,
      "y": 200,
      "z": 7,
      "name": "Rock_Stone"
    },
    {
      "x": -57,
      "y": 201,
      "z": 7,
      "name": "Rock_Stone"
    },
    {
      "x": -57,
      "y": 202,
      "z": 7,
      "name": "Rock_Stone"
    },
    {
      "x": -57,
      "y": 203,
      "z": 7,
      "name": "Rock_Stone"
    },
    {
      "x": -57,
      "y": 204,
      "z": 7,
      "name": "Rock_Stone"
    },
    {
      "x": -57,
      "y": 199,
      "z": 8,
      "name": "Rock_Stone"
    },
    {
      "x": -57,
      "y": 200,
      "z": 8,
      "name": "Rock_Stone"
    },
    {
      "x": -57,
      "y": 201,
      "z": 8,
      "name": "Rock_Stone"
    },
    {
      "x": -57,
      "y": 202,
      "z": 8,
      "name": "Rock_Stone"
    },
    {
      "x": -57,
      "y": 203,
      "z": 8,
      "name": "Rock_Stone"
    },
    {
      "x": -57,
      "y": 204,
      "z": 8,
      "name": "Rock_Stone"
    },
    {
      "x": -57,
      "y": 199,
      "z": 9,
      "name": "Rock_Stone"
    },
    {
      "x": -57,
      "y": 200,
      "z": 9,
      "name": "Rock_Stone"
    },
    {
      "x": -57,
      "y": 201,
      "z": 9,
      "name": "Rock_Stone"
    },
    {
      "x": -57,
      "y": 202,
      "z": 9,
      "name": "Rock_Stone"
    },
    {
      "x": -57,
      "y": 203,
      "z": 9,
      "name": "Rock_Stone"
    },
    {
      "x": -57,
      "y": 204,
      "z": 9,
      "name": "Rock_Stone"
    },
    {
      "x": -57,
      "y": 199,
      "z": 10,
      "name": "Rock_Stone"
    },
    {
      "x": -57,
      "y": 200,
      "z": 10,
      "name": "Rock_Stone"
    },
    {
      "x": -57,
      "y": 201,
      "z": 10,
      "name": "Rock_Stone"
    },
    {
      "x": -57,
      "y": 202,
      "z": 10,
      "name": "Rock_Stone"
    },
    {
      "x": -57,
      "y": 203,
      "z": 10,
      "name": "Rock_Stone"
    },
    {
      "x": -57,
      "y": 201,
      "z": 11,
      "name": "Rock_Stone"
    },
    {
      "x": -57,
      "y": 202,
      "z": 11,
      "name": "Rock_Stone"
    },
    {
      "x": -56,
      "y": 201,
      "z": -15,
      "name": "Rock_Stone"
    },
    {
      "x": -56,
      "y": 202,
      "z": -15,
      "name": "Rock_Stone"
    },
    {
      "x": -56,
      "y": 200,
      "z": -14,
      "name": "Rock_Stone"
    },
    {
      "x": -56,
      "y": 201,
      "z": -14,
      "name": "Rock_Stone"
    },
    {
      "x": -56,
      "y": 202,
      "z": -14,
      "name": "Rock_Stone"
    },
    {
      "x": -56,
      "y": 200,
      "z": -13,
      "name": "Rock_Stone"
    },
    {
      "x": -56,
      "y": 201,
      "z": -13,
      "name": "Rock_Stone"
    },
    {
      "x": -56,
      "y": 202,
      "z": -13,
      "name": "Rock_Stone"
    },
    {
      "x": -56,
      "y": 203,
      "z": -13,
      "name": "Rock_Stone"
    },
    {
      "x": -56,
      "y": 199,
      "z": -12,
      "name": "Rock_Stone"
    },
    {
      "x": -56,
      "y": 200,
      "z": -12,
      "name": "Rock_Stone"
    },
    {
      "x": -56,
      "y": 201,
      "z": -12,
      "name": "Rock_Stone"
    },
    {
      "x": -56,
      "y": 202,
      "z": -12,
      "name": "Rock_Stone"
    },
    {
      "x": -56,
      "y": 203,
      "z": -12,
      "name": "Rock_Stone"
    },
    {
      "x": -56,
      "y": 204,
      "z": -12,
      "name": "Rock_Stone"
    },
    {
      "x": -56,
      "y": 199,
      "z": -11,
      "name": "Rock_Stone"
    },
    {
      "x": -56,
      "y": 200,
      "z": -11,
      "name": "Rock_Stone"
    },
    {
      "x": -56,
      "y": 201,
      "z": -11,
      "name": "Rock_Stone"
    },
    {
      "x": -56,
      "y": 202,
      "z": -11,
      "name": "Rock_Stone"
    },
    {
      "x": -56,
      "y": 203,
      "z": -11,
      "name": "Rock_Stone"
    },
    {
      "x": -56,
      "y": 204,
      "z": -11,
      "name": "Rock_Stone"
    },
    {
      "x": -56,
      "y": 198,
      "z": -10,
      "name": "Rock_Stone"
    },
    {
      "x": -56,
      "y": 199,
      "z": -10,
      "name": "Rock_Stone"
    },
    {
      "x": -56,
      "y": 200,
      "z": -10,
      "name": "Rock_Stone"
    },
    {
      "x": -56,
      "y": 201,
      "z": -10,
      "name": "Rock_Stone"
    },
    {
      "x": -56,
      "y": 202,
      "z": -10,
      "name": "Rock_Stone"
    },
    {
      "x": -56,
      "y": 203,
      "z": -10,
      "name": "Rock_Stone"
    },
    {
      "x": -56,
      "y": 204,
      "z": -10,
      "name": "Rock_Stone"
    },
    {
      "x": -56,
      "y": 198,
      "z": -9,
      "name": "Rock_Stone"
    },
    {
      "x": -56,
      "y": 199,
      "z": -9,
      "name": "Rock_Stone"
    },
    {
      "x": -56,
      "y": 200,
      "z": -9,
      "name": "Rock_Stone"
    },
    {
      "x": -56,
      "y": 201,
      "z": -9,
      "name": "Rock_Stone"
    },
    {
      "x": -56,
      "y": 202,
      "z": -9,
      "name": "Rock_Stone"
    },
    {
      "x": -56,
      "y": 203,
      "z": -9,
      "name": "Rock_Stone"
    },
    {
      "x": -56,
      "y": 204,
      "z": -9,
      "name": "Rock_Stone"
    },
    {
      "x": -56,
      "y": 198,
      "z": -8,
      "name": "Rock_Stone"
    },
    {
      "x": -56,
      "y": 199,
      "z": -8,
      "name": "Rock_Stone"
    },
    {
      "x": -56,
      "y": 200,
      "z": -8,
      "name": "Rock_Stone"
    },
    {
      "x": -56,
      "y": 201,
      "z": -8,
      "name": "Rock_Stone"
    },
    {
      "x": -56,
      "y": 202,
      "z": -8,
      "name": "Rock_Stone"
    },
    {
      "x": -56,
      "y": 203,
      "z": -8,
      "name": "Rock_Stone"
    },
    {
      "x": -56,
      "y": 204,
      "z": -8,
      "name": "Rock_Stone"
    },
    {
      "x": -56,
      "y": 205,
      "z": -8,
      "name": "Rock_Stone"
    },
    {
      "x": -56,
      "y": 198,
      "z": -7,
      "name": "Rock_Stone"
    },
    {
      "x": -56,
      "y": 199,
      "z": -7,
      "name": "Rock_Stone"
    },
    {
      "x": -56,
      "y": 200,
      "z": -7,
      "name": "Rock_Stone"
    },
    {
      "x": -56,
      "y": 201,
      "z": -7,
      "name": "Rock_Stone"
    },
    {
      "x": -56,
      "y": 202,
      "z": -7,
      "name": "Rock_Stone"
    },
    {
      "x": -56,
      "y": 203,
      "z": -7,
      "name": "Rock_Stone"
    },
    {
      "x": -56,
      "y": 204,
      "z": -7,
      "name": "Rock_Stone"
    },
    {
      "x": -56,
      "y": 205,
      "z": -7,
      "name": "Rock_Stone"
    },
    {
      "x": -56,
      "y": 198,
      "z": -6,
      "name": "Rock_Stone"
    },
    {
      "x": -56,
      "y": 199,
      "z": -6,
      "name": "Rock_Stone"
    },
    {
      "x": -56,
      "y": 200,
      "z": -6,
      "name": "Rock_Stone"
    },
    {
      "x": -56,
      "y": 201,
      "z": -6,
      "name": "Rock_Stone"
    },
    {
      "x": -56,
      "y": 202,
      "z": -6,
      "name": "Rock_Stone"
    },
    {
      "x": -56,
      "y": 203,
      "z": -6,
      "name": "Rock_Stone"
    },
    {
      "x": -56,
      "y": 204,
      "z": -6,
      "name": "Rock_Stone"
    },
    {
      "x": -56,
      "y": 205,
      "z": -6,
      "name": "Rock_Stone"
    },
    {
      "x": -56,
      "y": 198,
      "z": -5,
      "name": "Rock_Stone"
    },
    {
      "x": -56,
      "y": 199,
      "z": -5,
      "name": "Rock_Stone"
    },
    {
      "x": -56,
      "y": 200,
      "z": -5,
      "name": "Rock_Stone"
    },
    {
      "x": -56,
      "y": 201,
      "z": -5,
      "name": "Rock_Stone"
    },
    {
      "x": -56,
      "y": 202,
      "z": -5,
      "name": "Rock_Stone"
    },
    {
      "x": -56,
      "y": 203,
      "z": -5,
      "name": "Rock_Stone"
    },
    {
      "x": -56,
      "y": 204,
      "z": -5,
      "name": "Rock_Stone"
    },
    {
      "x": -56,
      "y": 205,
      "z": -5,
      "name": "Rock_Stone"
    },
    {
      "x": -56,
      "y": 198,
      "z": -4,
      "name": "Rock_Stone"
    },
    {
      "x": -56,
      "y": 199,
      "z": -4,
      "name": "Rock_Stone"
    },
    {
      "x": -56,
      "y": 200,
      "z": -4,
      "name": "Rock_Stone"
    },
    {
      "x": -56,
      "y": 201,
      "z": -4,
      "name": "Rock_Stone"
    },
    {
      "x": -56,
      "y": 202,
      "z": -4,
      "name": "Rock_Stone"
    },
    {
      "x": -56,
      "y": 203,
      "z": -4,
      "name": "Rock_Stone"
    },
    {
      "x": -56,
      "y": 204,
      "z": -4,
      "name": "Rock_Stone"
    },
    {
      "x": -56,
      "y": 205,
      "z": -4,
      "name": "Rock_Stone"
    },
    {
      "x": -56,
      "y": 198,
      "z": -3,
      "name": "Rock_Stone"
    },
    {
      "x": -56,
      "y": 199,
      "z": -3,
      "name": "Rock_Stone"
    },
    {
      "x": -56,
      "y": 200,
      "z": -3,
      "name": "Rock_Stone"
    },
    {
      "x": -56,
      "y": 201,
      "z": -3,
      "name": "Rock_Stone"
    },
    {
      "x": -56,
      "y": 202,
      "z": -3,
      "name": "Rock_Stone"
    },
    {
      "x": -56,
      "y": 203,
      "z": -3,
      "name": "Rock_Stone"
    },
    {
      "x": -56,
      "y": 204,
      "z": -3,
      "name": "Rock_Stone"
    },
    {
      "x": -56,
      "y": 205,
      "z": -3,
      "name": "Rock_Stone"
    },
    {
      "x": -56,
      "y": 198,
      "z": -2,
      "name": "Rock_Stone"
    },
    {
      "x": -56,
      "y": 199,
      "z": -2,
      "name": "Rock_Stone"
    },
    {
      "x": -56,
      "y": 200,
      "z": -2,
      "name": "Rock_Stone"
    },
    {
      "x": -56,
      "y": 201,
      "z": -2,
      "name": "Rock_Stone"
    },
    {
      "x": -56,
      "y": 202,
      "z": -2,
      "name": "Rock_Stone"
    },
    {
      "x": -56,
      "y": 203,
      "z": -2,
      "name": "Rock_Stone"
    },
    {
      "x": -56,
      "y": 204,
      "z": -2,
      "name": "Rock_Stone"
    },
    {
      "x": -56,
      "y": 205,
      "z": -2,
      "name": "Rock_Stone"
    },
    {
      "x": -56,
      "y": 198,
      "z": -1,
      "name": "Rock_Stone"
    },
    {
      "x": -56,
      "y": 199,
      "z": -1,
      "name": "Rock_Stone"
    },
    {
      "x": -56,
      "y": 200,
      "z": -1,
      "name": "Rock_Stone"
    },
    {
      "x": -56,
      "y": 201,
      "z": -1,
      "name": "Rock_Stone"
    },
    {
      "x": -56,
      "y": 202,
      "z": -1,
      "name": "Rock_Stone"
    },
    {
      "x": -56,
      "y": 203,
      "z": -1,
      "name": "Rock_Stone"
    },
    {
      "x": -56,
      "y": 204,
      "z": -1,
      "name": "Rock_Stone"
    },
    {
      "x": -56,
      "y": 205,
      "z": -1,
      "name": "Rock_Stone"
    },
    {
      "x": -56,
      "y": 198,
      "z": 0,
      "name": "Rock_Stone"
    },
    {
      "x": -56,
      "y": 199,
      "z": 0,
      "name": "Rock_Stone"
    },
    {
      "x": -56,
      "y": 200,
      "z": 0,
      "name": "Rock_Stone"
    },
    {
      "x": -56,
      "y": 201,
      "z": 0,
      "name": "Rock_Stone"
    },
    {
      "x": -56,
      "y": 202,
      "z": 0,
      "name": "Rock_Stone"
    },
    {
      "x": -56,
      "y": 203,
      "z": 0,
      "name": "Rock_Stone"
    },
    {
      "x": -56,
      "y": 204,
      "z": 0,
      "name": "Rock_Stone"
    },
    {
      "x": -56,
      "y": 205,
      "z": 0,
      "name": "Rock_Stone"
    },
    {
      "x": -56,
      "y": 198,
      "z": 1,
      "name": "Rock_Stone"
    },
    {
      "x": -56,
      "y": 199,
      "z": 1,
      "name": "Rock_Stone"
    },
    {
      "x": -56,
      "y": 200,
      "z": 1,
      "name": "Rock_Stone"
    },
    {
      "x": -56,
      "y": 201,
      "z": 1,
      "name": "Rock_Stone"
    },
    {
      "x": -56,
      "y": 202,
      "z": 1,
      "name": "Rock_Stone"
    },
    {
      "x": -56,
      "y": 203,
      "z": 1,
      "name": "Rock_Stone"
    },
    {
      "x": -56,
      "y": 204,
      "z": 1,
      "name": "Rock_Stone"
    },
    {
      "x": -56,
      "y": 205,
      "z": 1,
      "name": "Rock_Stone"
    },
    {
      "x": -56,
      "y": 198,
      "z": 2,
      "name": "Rock_Stone"
    },
    {
      "x": -56,
      "y": 199,
      "z": 2,
      "name": "Rock_Stone"
    },
    {
      "x": -56,
      "y": 200,
      "z": 2,
      "name": "Rock_Stone"
    },
    {
      "x": -56,
      "y": 201,
      "z": 2,
      "name": "Rock_Stone"
    },
    {
      "x": -56,
      "y": 202,
      "z": 2,
      "name": "Rock_Stone"
    },
    {
      "x": -56,
      "y": 203,
      "z": 2,
      "name": "Rock_Stone"
    },
    {
      "x": -56,
      "y": 204,
      "z": 2,
      "name": "Rock_Stone"
    },
    {
      "x": -56,
      "y": 205,
      "z": 2,
      "name": "Rock_Stone"
    },
    {
      "x": -56,
      "y": 198,
      "z": 3,
      "name": "Rock_Stone"
    },
    {
      "x": -56,
      "y": 199,
      "z": 3,
      "name": "Rock_Stone"
    },
    {
      "x": -56,
      "y": 200,
      "z": 3,
      "name": "Rock_Stone"
    },
    {
      "x": -56,
      "y": 201,
      "z": 3,
      "name": "Rock_Stone"
    },
    {
      "x": -56,
      "y": 202,
      "z": 3,
      "name": "Rock_Stone"
    },
    {
      "x": -56,
      "y": 203,
      "z": 3,
      "name": "Rock_Stone"
    },
    {
      "x": -56,
      "y": 204,
      "z": 3,
      "name": "Rock_Stone"
    },
    {
      "x": -56,
      "y": 205,
      "z": 3,
      "name": "Rock_Stone"
    },
    {
      "x": -56,
      "y": 198,
      "z": 4,
      "name": "Rock_Stone"
    },
    {
      "x": -56,
      "y": 199,
      "z": 4,
      "name": "Rock_Stone"
    },
    {
      "x": -56,
      "y": 200,
      "z": 4,
      "name": "Rock_Stone"
    },
    {
      "x": -56,
      "y": 201,
      "z": 4,
      "name": "Rock_Stone"
    },
    {
      "x": -56,
      "y": 202,
      "z": 4,
      "name": "Rock_Stone"
    },
    {
      "x": -56,
      "y": 203,
      "z": 4,
      "name": "Rock_Stone"
    },
    {
      "x": -56,
      "y": 204,
      "z": 4,
      "name": "Rock_Stone"
    },
    {
      "x": -56,
      "y": 205,
      "z": 4,
      "name": "Rock_Stone"
    },
    {
      "x": -56,
      "y": 198,
      "z": 5,
      "name": "Rock_Stone"
    },
    {
      "x": -56,
      "y": 199,
      "z": 5,
      "name": "Rock_Stone"
    },
    {
      "x": -56,
      "y": 200,
      "z": 5,
      "name": "Rock_Stone"
    },
    {
      "x": -56,
      "y": 201,
      "z": 5,
      "name": "Rock_Stone"
    },
    {
      "x": -56,
      "y": 202,
      "z": 5,
      "name": "Rock_Stone"
    },
    {
      "x": -56,
      "y": 203,
      "z": 5,
      "name": "Rock_Stone"
    },
    {
      "x": -56,
      "y": 204,
      "z": 5,
      "name": "Rock_Stone"
    },
    {
      "x": -56,
      "y": 205,
      "z": 5,
      "name": "Rock_Stone"
    },
    {
      "x": -56,
      "y": 198,
      "z": 6,
      "name": "Rock_Stone"
    },
    {
      "x": -56,
      "y": 199,
      "z": 6,
      "name": "Rock_Stone"
    },
    {
      "x": -56,
      "y": 200,
      "z": 6,
      "name": "Rock_Stone"
    },
    {
      "x": -56,
      "y": 201,
      "z": 6,
      "name": "Rock_Stone"
    },
    {
      "x": -56,
      "y": 202,
      "z": 6,
      "name": "Rock_Stone"
    },
    {
      "x": -56,
      "y": 203,
      "z": 6,
      "name": "Rock_Stone"
    },
    {
      "x": -56,
      "y": 204,
      "z": 6,
      "name": "Rock_Stone"
    },
    {
      "x": -56,
      "y": 205,
      "z": 6,
      "name": "Rock_Stone"
    },
    {
      "x": -56,
      "y": 198,
      "z": 7,
      "name": "Rock_Stone"
    },
    {
      "x": -56,
      "y": 199,
      "z": 7,
      "name": "Rock_Stone"
    },
    {
      "x": -56,
      "y": 200,
      "z": 7,
      "name": "Rock_Stone"
    },
    {
      "x": -56,
      "y": 201,
      "z": 7,
      "name": "Rock_Stone"
    },
    {
      "x": -56,
      "y": 202,
      "z": 7,
      "name": "Rock_Stone"
    },
    {
      "x": -56,
      "y": 203,
      "z": 7,
      "name": "Rock_Stone"
    },
    {
      "x": -56,
      "y": 204,
      "z": 7,
      "name": "Rock_Stone"
    },
    {
      "x": -56,
      "y": 205,
      "z": 7,
      "name": "Rock_Stone"
    },
    {
      "x": -56,
      "y": 198,
      "z": 8,
      "name": "Rock_Stone"
    },
    {
      "x": -56,
      "y": 199,
      "z": 8,
      "name": "Rock_Stone"
    },
    {
      "x": -56,
      "y": 200,
      "z": 8,
      "name": "Rock_Stone"
    },
    {
      "x": -56,
      "y": 201,
      "z": 8,
      "name": "Rock_Stone"
    },
    {
      "x": -56,
      "y": 202,
      "z": 8,
      "name": "Rock_Stone"
    },
    {
      "x": -56,
      "y": 203,
      "z": 8,
      "name": "Rock_Stone"
    },
    {
      "x": -56,
      "y": 204,
      "z": 8,
      "name": "Rock_Stone"
    },
    {
      "x": -56,
      "y": 205,
      "z": 8,
      "name": "Rock_Stone"
    },
    {
      "x": -56,
      "y": 199,
      "z": 9,
      "name": "Rock_Stone"
    },
    {
      "x": -56,
      "y": 200,
      "z": 9,
      "name": "Rock_Stone"
    },
    {
      "x": -56,
      "y": 201,
      "z": 9,
      "name": "Rock_Stone"
    },
    {
      "x": -56,
      "y": 202,
      "z": 9,
      "name": "Rock_Stone"
    },
    {
      "x": -56,
      "y": 203,
      "z": 9,
      "name": "Rock_Stone"
    },
    {
      "x": -56,
      "y": 204,
      "z": 9,
      "name": "Rock_Stone"
    },
    {
      "x": -56,
      "y": 199,
      "z": 10,
      "name": "Rock_Stone"
    },
    {
      "x": -56,
      "y": 200,
      "z": 10,
      "name": "Rock_Stone"
    },
    {
      "x": -56,
      "y": 201,
      "z": 10,
      "name": "Rock_Stone"
    },
    {
      "x": -56,
      "y": 202,
      "z": 10,
      "name": "Rock_Stone"
    },
    {
      "x": -56,
      "y": 203,
      "z": 10,
      "name": "Rock_Stone"
    },
    {
      "x": -56,
      "y": 204,
      "z": 10,
      "name": "Rock_Stone"
    },
    {
      "x": -56,
      "y": 200,
      "z": 11,
      "name": "Rock_Stone"
    },
    {
      "x": -56,
      "y": 201,
      "z": 11,
      "name": "Rock_Stone"
    },
    {
      "x": -56,
      "y": 202,
      "z": 11,
      "name": "Rock_Stone"
    },
    {
      "x": -56,
      "y": 203,
      "z": 11,
      "name": "Rock_Stone"
    },
    {
      "x": -56,
      "y": 201,
      "z": 12,
      "name": "Rock_Stone"
    },
    {
      "x": -56,
      "y": 202,
      "z": 12,
      "name": "Rock_Stone"
    },
    {
      "x": -55,
      "y": 201,
      "z": -16,
      "name": "Rock_Stone"
    },
    {
      "x": -55,
      "y": 202,
      "z": -16,
      "name": "Rock_Stone"
    },
    {
      "x": -55,
      "y": 200,
      "z": -15,
      "name": "Rock_Stone"
    },
    {
      "x": -55,
      "y": 201,
      "z": -15,
      "name": "Rock_Stone"
    },
    {
      "x": -55,
      "y": 202,
      "z": -15,
      "name": "Rock_Stone"
    },
    {
      "x": -55,
      "y": 203,
      "z": -15,
      "name": "Rock_Stone"
    },
    {
      "x": -55,
      "y": 199,
      "z": -14,
      "name": "Rock_Stone"
    },
    {
      "x": -55,
      "y": 200,
      "z": -14,
      "name": "Rock_Stone"
    },
    {
      "x": -55,
      "y": 201,
      "z": -14,
      "name": "Rock_Stone"
    },
    {
      "x": -55,
      "y": 202,
      "z": -14,
      "name": "Rock_Stone"
    },
    {
      "x": -55,
      "y": 203,
      "z": -14,
      "name": "Rock_Stone"
    },
    {
      "x": -55,
      "y": 199,
      "z": -13,
      "name": "Rock_Stone"
    },
    {
      "x": -55,
      "y": 200,
      "z": -13,
      "name": "Rock_Stone"
    },
    {
      "x": -55,
      "y": 201,
      "z": -13,
      "name": "Rock_Stone"
    },
    {
      "x": -55,
      "y": 202,
      "z": -13,
      "name": "Rock_Stone"
    },
    {
      "x": -55,
      "y": 203,
      "z": -13,
      "name": "Rock_Stone"
    },
    {
      "x": -55,
      "y": 204,
      "z": -13,
      "name": "Rock_Stone"
    },
    {
      "x": -55,
      "y": 199,
      "z": -12,
      "name": "Rock_Stone"
    },
    {
      "x": -55,
      "y": 200,
      "z": -12,
      "name": "Rock_Stone"
    },
    {
      "x": -55,
      "y": 201,
      "z": -12,
      "name": "Rock_Stone"
    },
    {
      "x": -55,
      "y": 202,
      "z": -12,
      "name": "Rock_Stone"
    },
    {
      "x": -55,
      "y": 203,
      "z": -12,
      "name": "Rock_Stone"
    },
    {
      "x": -55,
      "y": 204,
      "z": -12,
      "name": "Rock_Stone"
    },
    {
      "x": -55,
      "y": 198,
      "z": -11,
      "name": "Rock_Stone"
    },
    {
      "x": -55,
      "y": 199,
      "z": -11,
      "name": "Rock_Stone"
    },
    {
      "x": -55,
      "y": 200,
      "z": -11,
      "name": "Rock_Stone"
    },
    {
      "x": -55,
      "y": 201,
      "z": -11,
      "name": "Rock_Stone"
    },
    {
      "x": -55,
      "y": 202,
      "z": -11,
      "name": "Rock_Stone"
    },
    {
      "x": -55,
      "y": 203,
      "z": -11,
      "name": "Rock_Stone"
    },
    {
      "x": -55,
      "y": 204,
      "z": -11,
      "name": "Rock_Stone"
    },
    {
      "x": -55,
      "y": 198,
      "z": -10,
      "name": "Rock_Stone"
    },
    {
      "x": -55,
      "y": 199,
      "z": -10,
      "name": "Rock_Stone"
    },
    {
      "x": -55,
      "y": 200,
      "z": -10,
      "name": "Rock_Stone"
    },
    {
      "x": -55,
      "y": 201,
      "z": -10,
      "name": "Rock_Stone"
    },
    {
      "x": -55,
      "y": 202,
      "z": -10,
      "name": "Rock_Stone"
    },
    {
      "x": -55,
      "y": 203,
      "z": -10,
      "name": "Rock_Stone"
    },
    {
      "x": -55,
      "y": 204,
      "z": -10,
      "name": "Rock_Stone"
    },
    {
      "x": -55,
      "y": 205,
      "z": -10,
      "name": "Rock_Stone"
    },
    {
      "x": -55,
      "y": 198,
      "z": -9,
      "name": "Rock_Stone"
    },
    {
      "x": -55,
      "y": 199,
      "z": -9,
      "name": "Rock_Stone"
    },
    {
      "x": -55,
      "y": 200,
      "z": -9,
      "name": "Rock_Stone"
    },
    {
      "x": -55,
      "y": 201,
      "z": -9,
      "name": "Rock_Stone"
    },
    {
      "x": -55,
      "y": 202,
      "z": -9,
      "name": "Rock_Stone"
    },
    {
      "x": -55,
      "y": 203,
      "z": -9,
      "name": "Rock_Stone"
    },
    {
      "x": -55,
      "y": 204,
      "z": -9,
      "name": "Rock_Stone"
    },
    {
      "x": -55,
      "y": 205,
      "z": -9,
      "name": "Rock_Stone"
    },
    {
      "x": -55,
      "y": 198,
      "z": -8,
      "name": "Rock_Stone"
    },
    {
      "x": -55,
      "y": 199,
      "z": -8,
      "name": "Rock_Stone"
    },
    {
      "x": -55,
      "y": 200,
      "z": -8,
      "name": "Rock_Stone"
    },
    {
      "x": -55,
      "y": 201,
      "z": -8,
      "name": "Rock_Stone"
    },
    {
      "x": -55,
      "y": 202,
      "z": -8,
      "name": "Rock_Stone"
    },
    {
      "x": -55,
      "y": 203,
      "z": -8,
      "name": "Rock_Stone"
    },
    {
      "x": -55,
      "y": 204,
      "z": -8,
      "name": "Rock_Stone"
    },
    {
      "x": -55,
      "y": 205,
      "z": -8,
      "name": "Rock_Stone"
    },
    {
      "x": -55,
      "y": 198,
      "z": -7,
      "name": "Rock_Stone"
    },
    {
      "x": -55,
      "y": 199,
      "z": -7,
      "name": "Rock_Stone"
    },
    {
      "x": -55,
      "y": 200,
      "z": -7,
      "name": "Rock_Stone"
    },
    {
      "x": -55,
      "y": 201,
      "z": -7,
      "name": "Rock_Stone"
    },
    {
      "x": -55,
      "y": 202,
      "z": -7,
      "name": "Rock_Stone"
    },
    {
      "x": -55,
      "y": 203,
      "z": -7,
      "name": "Rock_Stone"
    },
    {
      "x": -55,
      "y": 204,
      "z": -7,
      "name": "Rock_Stone"
    },
    {
      "x": -55,
      "y": 205,
      "z": -7,
      "name": "Rock_Stone"
    },
    {
      "x": -55,
      "y": 198,
      "z": -6,
      "name": "Rock_Stone"
    },
    {
      "x": -55,
      "y": 199,
      "z": -6,
      "name": "Rock_Stone"
    },
    {
      "x": -55,
      "y": 200,
      "z": -6,
      "name": "Rock_Stone"
    },
    {
      "x": -55,
      "y": 201,
      "z": -6,
      "name": "Rock_Stone"
    },
    {
      "x": -55,
      "y": 202,
      "z": -6,
      "name": "Rock_Stone"
    },
    {
      "x": -55,
      "y": 203,
      "z": -6,
      "name": "Rock_Stone"
    },
    {
      "x": -55,
      "y": 204,
      "z": -6,
      "name": "Rock_Stone"
    },
    {
      "x": -55,
      "y": 205,
      "z": -6,
      "name": "Rock_Stone"
    },
    {
      "x": -55,
      "y": 198,
      "z": -5,
      "name": "Rock_Stone"
    },
    {
      "x": -55,
      "y": 199,
      "z": -5,
      "name": "Rock_Stone"
    },
    {
      "x": -55,
      "y": 200,
      "z": -5,
      "name": "Rock_Stone"
    },
    {
      "x": -55,
      "y": 201,
      "z": -5,
      "name": "Rock_Stone"
    },
    {
      "x": -55,
      "y": 202,
      "z": -5,
      "name": "Rock_Stone"
    },
    {
      "x": -55,
      "y": 203,
      "z": -5,
      "name": "Rock_Stone"
    },
    {
      "x": -55,
      "y": 204,
      "z": -5,
      "name": "Rock_Stone"
    },
    {
      "x": -55,
      "y": 205,
      "z": -5,
      "name": "Rock_Stone"
    },
    {
      "x": -55,
      "y": 197,
      "z": -4,
      "name": "Rock_Stone"
    },
    {
      "x": -55,
      "y": 198,
      "z": -4,
      "name": "Rock_Stone"
    },
    {
      "x": -55,
      "y": 199,
      "z": -4,
      "name": "Rock_Stone"
    },
    {
      "x": -55,
      "y": 200,
      "z": -4,
      "name": "Rock_Stone"
    },
    {
      "x": -55,
      "y": 201,
      "z": -4,
      "name": "Rock_Stone"
    },
    {
      "x": -55,
      "y": 202,
      "z": -4,
      "name": "Rock_Stone"
    },
    {
      "x": -55,
      "y": 203,
      "z": -4,
      "name": "Rock_Stone"
    },
    {
      "x": -55,
      "y": 204,
      "z": -4,
      "name": "Rock_Stone"
    },
    {
      "x": -55,
      "y": 205,
      "z": -4,
      "name": "Rock_Stone"
    },
    {
      "x": -55,
      "y": 206,
      "z": -4,
      "name": "Rock_Stone"
    },
    {
      "x": -55,
      "y": 197,
      "z": -3,
      "name": "Rock_Stone"
    },
    {
      "x": -55,
      "y": 198,
      "z": -3,
      "name": "Rock_Stone"
    },
    {
      "x": -55,
      "y": 199,
      "z": -3,
      "name": "Rock_Stone"
    },
    {
      "x": -55,
      "y": 200,
      "z": -3,
      "name": "Rock_Stone"
    },
    {
      "x": -55,
      "y": 201,
      "z": -3,
      "name": "Rock_Stone"
    },
    {
      "x": -55,
      "y": 202,
      "z": -3,
      "name": "Rock_Stone"
    },
    {
      "x": -55,
      "y": 203,
      "z": -3,
      "name": "Rock_Stone"
    },
    {
      "x": -55,
      "y": 204,
      "z": -3,
      "name": "Rock_Stone"
    },
    {
      "x": -55,
      "y": 205,
      "z": -3,
      "name": "Rock_Stone"
    },
    {
      "x": -55,
      "y": 206,
      "z": -3,
      "name": "Rock_Stone"
    },
    {
      "x": -55,
      "y": 197,
      "z": -2,
      "name": "Rock_Stone"
    },
    {
      "x": -55,
      "y": 198,
      "z": -2,
      "name": "Rock_Stone"
    },
    {
      "x": -55,
      "y": 199,
      "z": -2,
      "name": "Rock_Stone"
    },
    {
      "x": -55,
      "y": 200,
      "z": -2,
      "name": "Rock_Stone"
    },
    {
      "x": -55,
      "y": 201,
      "z": -2,
      "name": "Rock_Stone"
    },
    {
      "x": -55,
      "y": 202,
      "z": -2,
      "name": "Rock_Stone"
    },
    {
      "x": -55,
      "y": 203,
      "z": -2,
      "name": "Rock_Stone"
    },
    {
      "x": -55,
      "y": 204,
      "z": -2,
      "name": "Rock_Stone"
    },
    {
      "x": -55,
      "y": 205,
      "z": -2,
      "name": "Rock_Stone"
    },
    {
      "x": -55,
      "y": 206,
      "z": -2,
      "name": "Rock_Stone"
    },
    {
      "x": -55,
      "y": 197,
      "z": -1,
      "name": "Rock_Stone"
    },
    {
      "x": -55,
      "y": 198,
      "z": -1,
      "name": "Rock_Stone"
    },
    {
      "x": -55,
      "y": 199,
      "z": -1,
      "name": "Rock_Stone"
    },
    {
      "x": -55,
      "y": 200,
      "z": -1,
      "name": "Rock_Stone"
    },
    {
      "x": -55,
      "y": 201,
      "z": -1,
      "name": "Rock_Stone"
    },
    {
      "x": -55,
      "y": 202,
      "z": -1,
      "name": "Rock_Stone"
    },
    {
      "x": -55,
      "y": 203,
      "z": -1,
      "name": "Rock_Stone"
    },
    {
      "x": -55,
      "y": 204,
      "z": -1,
      "name": "Rock_Stone"
    },
    {
      "x": -55,
      "y": 205,
      "z": -1,
      "name": "Rock_Stone"
    },
    {
      "x": -55,
      "y": 206,
      "z": -1,
      "name": "Rock_Stone"
    },
    {
      "x": -55,
      "y": 197,
      "z": 0,
      "name": "Rock_Stone"
    },
    {
      "x": -55,
      "y": 198,
      "z": 0,
      "name": "Rock_Stone"
    },
    {
      "x": -55,
      "y": 199,
      "z": 0,
      "name": "Rock_Stone"
    },
    {
      "x": -55,
      "y": 200,
      "z": 0,
      "name": "Rock_Stone"
    },
    {
      "x": -55,
      "y": 201,
      "z": 0,
      "name": "Rock_Stone"
    },
    {
      "x": -55,
      "y": 202,
      "z": 0,
      "name": "Rock_Stone"
    },
    {
      "x": -55,
      "y": 203,
      "z": 0,
      "name": "Rock_Stone"
    },
    {
      "x": -55,
      "y": 204,
      "z": 0,
      "name": "Rock_Stone"
    },
    {
      "x": -55,
      "y": 205,
      "z": 0,
      "name": "Rock_Stone"
    },
    {
      "x": -55,
      "y": 206,
      "z": 0,
      "name": "Rock_Stone"
    },
    {
      "x": -55,
      "y": 197,
      "z": 1,
      "name": "Rock_Stone"
    },
    {
      "x": -55,
      "y": 198,
      "z": 1,
      "name": "Rock_Stone"
    },
    {
      "x": -55,
      "y": 199,
      "z": 1,
      "name": "Rock_Stone"
    },
    {
      "x": -55,
      "y": 200,
      "z": 1,
      "name": "Rock_Stone"
    },
    {
      "x": -55,
      "y": 201,
      "z": 1,
      "name": "Rock_Stone"
    },
    {
      "x": -55,
      "y": 202,
      "z": 1,
      "name": "Rock_Stone"
    },
    {
      "x": -55,
      "y": 203,
      "z": 1,
      "name": "Rock_Stone"
    },
    {
      "x": -55,
      "y": 204,
      "z": 1,
      "name": "Rock_Stone"
    },
    {
      "x": -55,
      "y": 205,
      "z": 1,
      "name": "Rock_Stone"
    },
    {
      "x": -55,
      "y": 206,
      "z": 1,
      "name": "Rock_Stone"
    },
    {
      "x": -55,
      "y": 197,
      "z": 2,
      "name": "Rock_Stone"
    },
    {
      "x": -55,
      "y": 198,
      "z": 2,
      "name": "Rock_Stone"
    },
    {
      "x": -55,
      "y": 199,
      "z": 2,
      "name": "Rock_Stone"
    },
    {
      "x": -55,
      "y": 200,
      "z": 2,
      "name": "Rock_Stone"
    },
    {
      "x": -55,
      "y": 201,
      "z": 2,
      "name": "Rock_Stone"
    },
    {
      "x": -55,
      "y": 202,
      "z": 2,
      "name": "Rock_Stone"
    },
    {
      "x": -55,
      "y": 203,
      "z": 2,
      "name": "Rock_Stone"
    },
    {
      "x": -55,
      "y": 204,
      "z": 2,
      "name": "Rock_Stone"
    },
    {
      "x": -55,
      "y": 205,
      "z": 2,
      "name": "Rock_Stone"
    },
    {
      "x": -55,
      "y": 206,
      "z": 2,
      "name": "Rock_Stone"
    },
    {
      "x": -55,
      "y": 197,
      "z": 3,
      "name": "Rock_Stone"
    },
    {
      "x": -55,
      "y": 198,
      "z": 3,
      "name": "Rock_Stone"
    },
    {
      "x": -55,
      "y": 199,
      "z": 3,
      "name": "Rock_Stone"
    },
    {
      "x": -55,
      "y": 200,
      "z": 3,
      "name": "Rock_Stone"
    },
    {
      "x": -55,
      "y": 201,
      "z": 3,
      "name": "Rock_Stone"
    },
    {
      "x": -55,
      "y": 202,
      "z": 3,
      "name": "Rock_Stone"
    },
    {
      "x": -55,
      "y": 203,
      "z": 3,
      "name": "Rock_Stone"
    },
    {
      "x": -55,
      "y": 204,
      "z": 3,
      "name": "Rock_Stone"
    },
    {
      "x": -55,
      "y": 205,
      "z": 3,
      "name": "Rock_Stone"
    },
    {
      "x": -55,
      "y": 206,
      "z": 3,
      "name": "Rock_Stone"
    },
    {
      "x": -55,
      "y": 198,
      "z": 4,
      "name": "Rock_Stone"
    },
    {
      "x": -55,
      "y": 199,
      "z": 4,
      "name": "Rock_Stone"
    },
    {
      "x": -55,
      "y": 200,
      "z": 4,
      "name": "Rock_Stone"
    },
    {
      "x": -55,
      "y": 201,
      "z": 4,
      "name": "Rock_Stone"
    },
    {
      "x": -55,
      "y": 202,
      "z": 4,
      "name": "Rock_Stone"
    },
    {
      "x": -55,
      "y": 203,
      "z": 4,
      "name": "Rock_Stone"
    },
    {
      "x": -55,
      "y": 204,
      "z": 4,
      "name": "Rock_Stone"
    },
    {
      "x": -55,
      "y": 205,
      "z": 4,
      "name": "Rock_Stone"
    },
    {
      "x": -55,
      "y": 198,
      "z": 5,
      "name": "Rock_Stone"
    },
    {
      "x": -55,
      "y": 199,
      "z": 5,
      "name": "Rock_Stone"
    },
    {
      "x": -55,
      "y": 200,
      "z": 5,
      "name": "Rock_Stone"
    },
    {
      "x": -55,
      "y": 201,
      "z": 5,
      "name": "Rock_Stone"
    },
    {
      "x": -55,
      "y": 202,
      "z": 5,
      "name": "Rock_Stone"
    },
    {
      "x": -55,
      "y": 203,
      "z": 5,
      "name": "Rock_Stone"
    },
    {
      "x": -55,
      "y": 204,
      "z": 5,
      "name": "Rock_Stone"
    },
    {
      "x": -55,
      "y": 205,
      "z": 5,
      "name": "Rock_Stone"
    },
    {
      "x": -55,
      "y": 198,
      "z": 6,
      "name": "Rock_Stone"
    },
    {
      "x": -55,
      "y": 199,
      "z": 6,
      "name": "Rock_Stone"
    },
    {
      "x": -55,
      "y": 200,
      "z": 6,
      "name": "Rock_Stone"
    },
    {
      "x": -55,
      "y": 201,
      "z": 6,
      "name": "Rock_Stone"
    },
    {
      "x": -55,
      "y": 202,
      "z": 6,
      "name": "Rock_Stone"
    },
    {
      "x": -55,
      "y": 203,
      "z": 6,
      "name": "Rock_Stone"
    },
    {
      "x": -55,
      "y": 204,
      "z": 6,
      "name": "Rock_Stone"
    },
    {
      "x": -55,
      "y": 205,
      "z": 6,
      "name": "Rock_Stone"
    },
    {
      "x": -55,
      "y": 198,
      "z": 7,
      "name": "Rock_Stone"
    },
    {
      "x": -55,
      "y": 199,
      "z": 7,
      "name": "Rock_Stone"
    },
    {
      "x": -55,
      "y": 200,
      "z": 7,
      "name": "Rock_Stone"
    },
    {
      "x": -55,
      "y": 201,
      "z": 7,
      "name": "Rock_Stone"
    },
    {
      "x": -55,
      "y": 202,
      "z": 7,
      "name": "Rock_Stone"
    },
    {
      "x": -55,
      "y": 203,
      "z": 7,
      "name": "Rock_Stone"
    },
    {
      "x": -55,
      "y": 204,
      "z": 7,
      "name": "Rock_Stone"
    },
    {
      "x": -55,
      "y": 205,
      "z": 7,
      "name": "Rock_Stone"
    },
    {
      "x": -55,
      "y": 198,
      "z": 8,
      "name": "Rock_Stone"
    },
    {
      "x": -55,
      "y": 199,
      "z": 8,
      "name": "Rock_Stone"
    },
    {
      "x": -55,
      "y": 200,
      "z": 8,
      "name": "Rock_Stone"
    },
    {
      "x": -55,
      "y": 201,
      "z": 8,
      "name": "Rock_Stone"
    },
    {
      "x": -55,
      "y": 202,
      "z": 8,
      "name": "Rock_Stone"
    },
    {
      "x": -55,
      "y": 203,
      "z": 8,
      "name": "Rock_Stone"
    },
    {
      "x": -55,
      "y": 204,
      "z": 8,
      "name": "Rock_Stone"
    },
    {
      "x": -55,
      "y": 205,
      "z": 8,
      "name": "Rock_Stone"
    },
    {
      "x": -55,
      "y": 198,
      "z": 9,
      "name": "Rock_Stone"
    },
    {
      "x": -55,
      "y": 199,
      "z": 9,
      "name": "Rock_Stone"
    },
    {
      "x": -55,
      "y": 200,
      "z": 9,
      "name": "Rock_Stone"
    },
    {
      "x": -55,
      "y": 201,
      "z": 9,
      "name": "Rock_Stone"
    },
    {
      "x": -55,
      "y": 202,
      "z": 9,
      "name": "Rock_Stone"
    },
    {
      "x": -55,
      "y": 203,
      "z": 9,
      "name": "Rock_Stone"
    },
    {
      "x": -55,
      "y": 204,
      "z": 9,
      "name": "Rock_Stone"
    },
    {
      "x": -55,
      "y": 199,
      "z": 10,
      "name": "Rock_Stone"
    },
    {
      "x": -55,
      "y": 200,
      "z": 10,
      "name": "Rock_Stone"
    },
    {
      "x": -55,
      "y": 201,
      "z": 10,
      "name": "Rock_Stone"
    },
    {
      "x": -55,
      "y": 202,
      "z": 10,
      "name": "Rock_Stone"
    },
    {
      "x": -55,
      "y": 203,
      "z": 10,
      "name": "Rock_Stone"
    },
    {
      "x": -55,
      "y": 204,
      "z": 10,
      "name": "Rock_Stone"
    },
    {
      "x": -55,
      "y": 199,
      "z": 11,
      "name": "Rock_Stone"
    },
    {
      "x": -55,
      "y": 200,
      "z": 11,
      "name": "Rock_Stone"
    },
    {
      "x": -55,
      "y": 201,
      "z": 11,
      "name": "Rock_Stone"
    },
    {
      "x": -55,
      "y": 202,
      "z": 11,
      "name": "Rock_Stone"
    },
    {
      "x": -55,
      "y": 203,
      "z": 11,
      "name": "Rock_Stone"
    },
    {
      "x": -55,
      "y": 204,
      "z": 11,
      "name": "Rock_Stone"
    },
    {
      "x": -55,
      "y": 200,
      "z": 12,
      "name": "Rock_Stone"
    },
    {
      "x": -55,
      "y": 201,
      "z": 12,
      "name": "Rock_Stone"
    },
    {
      "x": -55,
      "y": 202,
      "z": 12,
      "name": "Rock_Stone"
    },
    {
      "x": -55,
      "y": 203,
      "z": 12,
      "name": "Rock_Stone"
    },
    {
      "x": -55,
      "y": 201,
      "z": 13,
      "name": "Rock_Stone"
    },
    {
      "x": -55,
      "y": 202,
      "z": 13,
      "name": "Rock_Stone"
    },
    {
      "x": -54,
      "y": 201,
      "z": -17,
      "name": "Rock_Stone"
    },
    {
      "x": -54,
      "y": 202,
      "z": -17,
      "name": "Rock_Stone"
    },
    {
      "x": -54,
      "y": 203,
      "z": -17,
      "name": "Rock_Stone"
    },
    {
      "x": -54,
      "y": 200,
      "z": -16,
      "name": "Rock_Stone"
    },
    {
      "x": -54,
      "y": 201,
      "z": -16,
      "name": "Rock_Stone"
    },
    {
      "x": -54,
      "y": 202,
      "z": -16,
      "name": "Rock_Stone"
    },
    {
      "x": -54,
      "y": 203,
      "z": -16,
      "name": "Rock_Stone"
    },
    {
      "x": -54,
      "y": 200,
      "z": -15,
      "name": "Rock_Stone"
    },
    {
      "x": -54,
      "y": 201,
      "z": -15,
      "name": "Rock_Stone"
    },
    {
      "x": -54,
      "y": 202,
      "z": -15,
      "name": "Rock_Stone"
    },
    {
      "x": -54,
      "y": 203,
      "z": -15,
      "name": "Rock_Stone"
    },
    {
      "x": -54,
      "y": 204,
      "z": -15,
      "name": "Rock_Stone"
    },
    {
      "x": -54,
      "y": 199,
      "z": -14,
      "name": "Rock_Stone"
    },
    {
      "x": -54,
      "y": 200,
      "z": -14,
      "name": "Rock_Stone"
    },
    {
      "x": -54,
      "y": 201,
      "z": -14,
      "name": "Rock_Stone"
    },
    {
      "x": -54,
      "y": 202,
      "z": -14,
      "name": "Rock_Stone"
    },
    {
      "x": -54,
      "y": 203,
      "z": -14,
      "name": "Rock_Stone"
    },
    {
      "x": -54,
      "y": 204,
      "z": -14,
      "name": "Rock_Stone"
    },
    {
      "x": -54,
      "y": 199,
      "z": -13,
      "name": "Rock_Stone"
    },
    {
      "x": -54,
      "y": 200,
      "z": -13,
      "name": "Rock_Stone"
    },
    {
      "x": -54,
      "y": 201,
      "z": -13,
      "name": "Rock_Stone"
    },
    {
      "x": -54,
      "y": 202,
      "z": -13,
      "name": "Rock_Stone"
    },
    {
      "x": -54,
      "y": 203,
      "z": -13,
      "name": "Rock_Stone"
    },
    {
      "x": -54,
      "y": 204,
      "z": -13,
      "name": "Rock_Stone"
    },
    {
      "x": -54,
      "y": 199,
      "z": -12,
      "name": "Rock_Stone"
    },
    {
      "x": -54,
      "y": 200,
      "z": -12,
      "name": "Rock_Stone"
    },
    {
      "x": -54,
      "y": 201,
      "z": -12,
      "name": "Rock_Stone"
    },
    {
      "x": -54,
      "y": 202,
      "z": -12,
      "name": "Rock_Stone"
    },
    {
      "x": -54,
      "y": 203,
      "z": -12,
      "name": "Rock_Stone"
    },
    {
      "x": -54,
      "y": 204,
      "z": -12,
      "name": "Rock_Stone"
    },
    {
      "x": -54,
      "y": 205,
      "z": -12,
      "name": "Rock_Stone"
    },
    {
      "x": -54,
      "y": 198,
      "z": -11,
      "name": "Rock_Stone"
    },
    {
      "x": -54,
      "y": 199,
      "z": -11,
      "name": "Rock_Stone"
    },
    {
      "x": -54,
      "y": 200,
      "z": -11,
      "name": "Rock_Stone"
    },
    {
      "x": -54,
      "y": 201,
      "z": -11,
      "name": "Rock_Stone"
    },
    {
      "x": -54,
      "y": 202,
      "z": -11,
      "name": "Rock_Stone"
    },
    {
      "x": -54,
      "y": 203,
      "z": -11,
      "name": "Rock_Stone"
    },
    {
      "x": -54,
      "y": 204,
      "z": -11,
      "name": "Rock_Stone"
    },
    {
      "x": -54,
      "y": 205,
      "z": -11,
      "name": "Rock_Stone"
    },
    {
      "x": -54,
      "y": 198,
      "z": -10,
      "name": "Rock_Stone"
    },
    {
      "x": -54,
      "y": 199,
      "z": -10,
      "name": "Rock_Stone"
    },
    {
      "x": -54,
      "y": 200,
      "z": -10,
      "name": "Rock_Stone"
    },
    {
      "x": -54,
      "y": 201,
      "z": -10,
      "name": "Rock_Stone"
    },
    {
      "x": -54,
      "y": 202,
      "z": -10,
      "name": "Rock_Stone"
    },
    {
      "x": -54,
      "y": 203,
      "z": -10,
      "name": "Rock_Stone"
    },
    {
      "x": -54,
      "y": 204,
      "z": -10,
      "name": "Rock_Stone"
    },
    {
      "x": -54,
      "y": 205,
      "z": -10,
      "name": "Rock_Stone"
    },
    {
      "x": -54,
      "y": 198,
      "z": -9,
      "name": "Rock_Stone"
    },
    {
      "x": -54,
      "y": 199,
      "z": -9,
      "name": "Rock_Stone"
    },
    {
      "x": -54,
      "y": 200,
      "z": -9,
      "name": "Rock_Stone"
    },
    {
      "x": -54,
      "y": 201,
      "z": -9,
      "name": "Rock_Stone"
    },
    {
      "x": -54,
      "y": 202,
      "z": -9,
      "name": "Rock_Stone"
    },
    {
      "x": -54,
      "y": 203,
      "z": -9,
      "name": "Rock_Stone"
    },
    {
      "x": -54,
      "y": 204,
      "z": -9,
      "name": "Rock_Stone"
    },
    {
      "x": -54,
      "y": 205,
      "z": -9,
      "name": "Rock_Stone"
    },
    {
      "x": -54,
      "y": 198,
      "z": -8,
      "name": "Rock_Stone"
    },
    {
      "x": -54,
      "y": 199,
      "z": -8,
      "name": "Rock_Stone"
    },
    {
      "x": -54,
      "y": 200,
      "z": -8,
      "name": "Rock_Stone"
    },
    {
      "x": -54,
      "y": 201,
      "z": -8,
      "name": "Rock_Stone"
    },
    {
      "x": -54,
      "y": 202,
      "z": -8,
      "name": "Rock_Stone"
    },
    {
      "x": -54,
      "y": 203,
      "z": -8,
      "name": "Rock_Stone"
    },
    {
      "x": -54,
      "y": 204,
      "z": -8,
      "name": "Rock_Stone"
    },
    {
      "x": -54,
      "y": 205,
      "z": -8,
      "name": "Rock_Stone"
    },
    {
      "x": -54,
      "y": 198,
      "z": -7,
      "name": "Rock_Stone"
    },
    {
      "x": -54,
      "y": 199,
      "z": -7,
      "name": "Rock_Stone"
    },
    {
      "x": -54,
      "y": 200,
      "z": -7,
      "name": "Rock_Stone"
    },
    {
      "x": -54,
      "y": 201,
      "z": -7,
      "name": "Rock_Stone"
    },
    {
      "x": -54,
      "y": 202,
      "z": -7,
      "name": "Rock_Stone"
    },
    {
      "x": -54,
      "y": 203,
      "z": -7,
      "name": "Rock_Stone"
    },
    {
      "x": -54,
      "y": 204,
      "z": -7,
      "name": "Rock_Stone"
    },
    {
      "x": -54,
      "y": 205,
      "z": -7,
      "name": "Rock_Stone"
    },
    {
      "x": -54,
      "y": 197,
      "z": -6,
      "name": "Rock_Stone"
    },
    {
      "x": -54,
      "y": 198,
      "z": -6,
      "name": "Rock_Stone"
    },
    {
      "x": -54,
      "y": 199,
      "z": -6,
      "name": "Rock_Stone"
    },
    {
      "x": -54,
      "y": 200,
      "z": -6,
      "name": "Rock_Stone"
    },
    {
      "x": -54,
      "y": 201,
      "z": -6,
      "name": "Rock_Stone"
    },
    {
      "x": -54,
      "y": 202,
      "z": -6,
      "name": "Rock_Stone"
    },
    {
      "x": -54,
      "y": 203,
      "z": -6,
      "name": "Rock_Stone"
    },
    {
      "x": -54,
      "y": 204,
      "z": -6,
      "name": "Rock_Stone"
    },
    {
      "x": -54,
      "y": 205,
      "z": -6,
      "name": "Rock_Stone"
    },
    {
      "x": -54,
      "y": 206,
      "z": -6,
      "name": "Rock_Stone"
    },
    {
      "x": -54,
      "y": 197,
      "z": -5,
      "name": "Rock_Stone"
    },
    {
      "x": -54,
      "y": 198,
      "z": -5,
      "name": "Rock_Stone"
    },
    {
      "x": -54,
      "y": 199,
      "z": -5,
      "name": "Rock_Stone"
    },
    {
      "x": -54,
      "y": 200,
      "z": -5,
      "name": "Rock_Stone"
    },
    {
      "x": -54,
      "y": 201,
      "z": -5,
      "name": "Rock_Stone"
    },
    {
      "x": -54,
      "y": 202,
      "z": -5,
      "name": "Rock_Stone"
    },
    {
      "x": -54,
      "y": 203,
      "z": -5,
      "name": "Rock_Stone"
    },
    {
      "x": -54,
      "y": 204,
      "z": -5,
      "name": "Rock_Stone"
    },
    {
      "x": -54,
      "y": 205,
      "z": -5,
      "name": "Rock_Stone"
    },
    {
      "x": -54,
      "y": 206,
      "z": -5,
      "name": "Rock_Stone"
    },
    {
      "x": -54,
      "y": 197,
      "z": -4,
      "name": "Rock_Stone"
    },
    {
      "x": -54,
      "y": 198,
      "z": -4,
      "name": "Rock_Stone"
    },
    {
      "x": -54,
      "y": 199,
      "z": -4,
      "name": "Rock_Stone"
    },
    {
      "x": -54,
      "y": 200,
      "z": -4,
      "name": "Rock_Stone"
    },
    {
      "x": -54,
      "y": 201,
      "z": -4,
      "name": "Rock_Stone"
    },
    {
      "x": -54,
      "y": 202,
      "z": -4,
      "name": "Rock_Stone"
    },
    {
      "x": -54,
      "y": 203,
      "z": -4,
      "name": "Rock_Stone"
    },
    {
      "x": -54,
      "y": 204,
      "z": -4,
      "name": "Rock_Stone"
    },
    {
      "x": -54,
      "y": 205,
      "z": -4,
      "name": "Rock_Stone"
    },
    {
      "x": -54,
      "y": 206,
      "z": -4,
      "name": "Rock_Stone"
    },
    {
      "x": -54,
      "y": 197,
      "z": -3,
      "name": "Rock_Stone"
    },
    {
      "x": -54,
      "y": 198,
      "z": -3,
      "name": "Rock_Stone"
    },
    {
      "x": -54,
      "y": 199,
      "z": -3,
      "name": "Rock_Stone"
    },
    {
      "x": -54,
      "y": 200,
      "z": -3,
      "name": "Rock_Stone"
    },
    {
      "x": -54,
      "y": 201,
      "z": -3,
      "name": "Rock_Stone"
    },
    {
      "x": -54,
      "y": 202,
      "z": -3,
      "name": "Rock_Stone"
    },
    {
      "x": -54,
      "y": 203,
      "z": -3,
      "name": "Rock_Stone"
    },
    {
      "x": -54,
      "y": 204,
      "z": -3,
      "name": "Rock_Stone"
    },
    {
      "x": -54,
      "y": 205,
      "z": -3,
      "name": "Rock_Stone"
    },
    {
      "x": -54,
      "y": 206,
      "z": -3,
      "name": "Rock_Stone"
    },
    {
      "x": -54,
      "y": 197,
      "z": -2,
      "name": "Rock_Stone"
    },
    {
      "x": -54,
      "y": 198,
      "z": -2,
      "name": "Rock_Stone"
    },
    {
      "x": -54,
      "y": 199,
      "z": -2,
      "name": "Rock_Stone"
    },
    {
      "x": -54,
      "y": 200,
      "z": -2,
      "name": "Rock_Stone"
    },
    {
      "x": -54,
      "y": 201,
      "z": -2,
      "name": "Rock_Stone"
    },
    {
      "x": -54,
      "y": 202,
      "z": -2,
      "name": "Rock_Stone"
    },
    {
      "x": -54,
      "y": 203,
      "z": -2,
      "name": "Rock_Stone"
    },
    {
      "x": -54,
      "y": 204,
      "z": -2,
      "name": "Rock_Stone"
    },
    {
      "x": -54,
      "y": 205,
      "z": -2,
      "name": "Rock_Stone"
    },
    {
      "x": -54,
      "y": 206,
      "z": -2,
      "name": "Rock_Stone"
    },
    {
      "x": -54,
      "y": 197,
      "z": -1,
      "name": "Rock_Stone"
    },
    {
      "x": -54,
      "y": 198,
      "z": -1,
      "name": "Rock_Stone"
    },
    {
      "x": -54,
      "y": 199,
      "z": -1,
      "name": "Rock_Stone"
    },
    {
      "x": -54,
      "y": 200,
      "z": -1,
      "name": "Rock_Stone"
    },
    {
      "x": -54,
      "y": 201,
      "z": -1,
      "name": "Rock_Stone"
    },
    {
      "x": -54,
      "y": 202,
      "z": -1,
      "name": "Rock_Stone"
    },
    {
      "x": -54,
      "y": 203,
      "z": -1,
      "name": "Rock_Stone"
    },
    {
      "x": -54,
      "y": 204,
      "z": -1,
      "name": "Rock_Stone"
    },
    {
      "x": -54,
      "y": 205,
      "z": -1,
      "name": "Rock_Stone"
    },
    {
      "x": -54,
      "y": 206,
      "z": -1,
      "name": "Rock_Stone"
    },
    {
      "x": -54,
      "y": 197,
      "z": 0,
      "name": "Rock_Stone"
    },
    {
      "x": -54,
      "y": 198,
      "z": 0,
      "name": "Rock_Stone"
    },
    {
      "x": -54,
      "y": 199,
      "z": 0,
      "name": "Rock_Stone"
    },
    {
      "x": -54,
      "y": 200,
      "z": 0,
      "name": "Rock_Stone"
    },
    {
      "x": -54,
      "y": 201,
      "z": 0,
      "name": "Rock_Stone"
    },
    {
      "x": -54,
      "y": 202,
      "z": 0,
      "name": "Rock_Stone"
    },
    {
      "x": -54,
      "y": 203,
      "z": 0,
      "name": "Rock_Stone"
    },
    {
      "x": -54,
      "y": 204,
      "z": 0,
      "name": "Rock_Stone"
    },
    {
      "x": -54,
      "y": 205,
      "z": 0,
      "name": "Rock_Stone"
    },
    {
      "x": -54,
      "y": 206,
      "z": 0,
      "name": "Rock_Stone"
    },
    {
      "x": -54,
      "y": 197,
      "z": 1,
      "name": "Rock_Stone"
    },
    {
      "x": -54,
      "y": 198,
      "z": 1,
      "name": "Rock_Stone"
    },
    {
      "x": -54,
      "y": 199,
      "z": 1,
      "name": "Rock_Stone"
    },
    {
      "x": -54,
      "y": 200,
      "z": 1,
      "name": "Rock_Stone"
    },
    {
      "x": -54,
      "y": 201,
      "z": 1,
      "name": "Rock_Stone"
    },
    {
      "x": -54,
      "y": 202,
      "z": 1,
      "name": "Rock_Stone"
    },
    {
      "x": -54,
      "y": 203,
      "z": 1,
      "name": "Rock_Stone"
    },
    {
      "x": -54,
      "y": 204,
      "z": 1,
      "name": "Rock_Stone"
    },
    {
      "x": -54,
      "y": 205,
      "z": 1,
      "name": "Rock_Stone"
    },
    {
      "x": -54,
      "y": 206,
      "z": 1,
      "name": "Rock_Stone"
    },
    {
      "x": -54,
      "y": 197,
      "z": 2,
      "name": "Rock_Stone"
    },
    {
      "x": -54,
      "y": 198,
      "z": 2,
      "name": "Rock_Stone"
    },
    {
      "x": -54,
      "y": 199,
      "z": 2,
      "name": "Rock_Stone"
    },
    {
      "x": -54,
      "y": 200,
      "z": 2,
      "name": "Rock_Stone"
    },
    {
      "x": -54,
      "y": 201,
      "z": 2,
      "name": "Rock_Stone"
    },
    {
      "x": -54,
      "y": 202,
      "z": 2,
      "name": "Rock_Stone"
    },
    {
      "x": -54,
      "y": 203,
      "z": 2,
      "name": "Rock_Stone"
    },
    {
      "x": -54,
      "y": 204,
      "z": 2,
      "name": "Rock_Stone"
    },
    {
      "x": -54,
      "y": 205,
      "z": 2,
      "name": "Rock_Stone"
    },
    {
      "x": -54,
      "y": 206,
      "z": 2,
      "name": "Rock_Stone"
    },
    {
      "x": -54,
      "y": 197,
      "z": 3,
      "name": "Rock_Stone"
    },
    {
      "x": -54,
      "y": 198,
      "z": 3,
      "name": "Rock_Stone"
    },
    {
      "x": -54,
      "y": 199,
      "z": 3,
      "name": "Rock_Stone"
    },
    {
      "x": -54,
      "y": 200,
      "z": 3,
      "name": "Rock_Stone"
    },
    {
      "x": -54,
      "y": 201,
      "z": 3,
      "name": "Rock_Stone"
    },
    {
      "x": -54,
      "y": 202,
      "z": 3,
      "name": "Rock_Stone"
    },
    {
      "x": -54,
      "y": 203,
      "z": 3,
      "name": "Rock_Stone"
    },
    {
      "x": -54,
      "y": 204,
      "z": 3,
      "name": "Rock_Stone"
    },
    {
      "x": -54,
      "y": 205,
      "z": 3,
      "name": "Rock_Stone"
    },
    {
      "x": -54,
      "y": 206,
      "z": 3,
      "name": "Rock_Stone"
    },
    {
      "x": -54,
      "y": 197,
      "z": 4,
      "name": "Rock_Stone"
    },
    {
      "x": -54,
      "y": 198,
      "z": 4,
      "name": "Rock_Stone"
    },
    {
      "x": -54,
      "y": 199,
      "z": 4,
      "name": "Rock_Stone"
    },
    {
      "x": -54,
      "y": 200,
      "z": 4,
      "name": "Rock_Stone"
    },
    {
      "x": -54,
      "y": 201,
      "z": 4,
      "name": "Rock_Stone"
    },
    {
      "x": -54,
      "y": 202,
      "z": 4,
      "name": "Rock_Stone"
    },
    {
      "x": -54,
      "y": 203,
      "z": 4,
      "name": "Rock_Stone"
    },
    {
      "x": -54,
      "y": 204,
      "z": 4,
      "name": "Rock_Stone"
    },
    {
      "x": -54,
      "y": 205,
      "z": 4,
      "name": "Rock_Stone"
    },
    {
      "x": -54,
      "y": 206,
      "z": 4,
      "name": "Rock_Stone"
    },
    {
      "x": -54,
      "y": 197,
      "z": 5,
      "name": "Rock_Stone"
    },
    {
      "x": -54,
      "y": 198,
      "z": 5,
      "name": "Rock_Stone"
    },
    {
      "x": -54,
      "y": 199,
      "z": 5,
      "name": "Rock_Stone"
    },
    {
      "x": -54,
      "y": 200,
      "z": 5,
      "name": "Rock_Stone"
    },
    {
      "x": -54,
      "y": 201,
      "z": 5,
      "name": "Rock_Stone"
    },
    {
      "x": -54,
      "y": 202,
      "z": 5,
      "name": "Rock_Stone"
    },
    {
      "x": -54,
      "y": 203,
      "z": 5,
      "name": "Rock_Stone"
    },
    {
      "x": -54,
      "y": 204,
      "z": 5,
      "name": "Rock_Stone"
    },
    {
      "x": -54,
      "y": 205,
      "z": 5,
      "name": "Rock_Stone"
    },
    {
      "x": -54,
      "y": 206,
      "z": 5,
      "name": "Rock_Stone"
    },
    {
      "x": -54,
      "y": 198,
      "z": 6,
      "name": "Rock_Stone"
    },
    {
      "x": -54,
      "y": 199,
      "z": 6,
      "name": "Rock_Stone"
    },
    {
      "x": -54,
      "y": 200,
      "z": 6,
      "name": "Rock_Stone"
    },
    {
      "x": -54,
      "y": 201,
      "z": 6,
      "name": "Rock_Stone"
    },
    {
      "x": -54,
      "y": 202,
      "z": 6,
      "name": "Rock_Stone"
    },
    {
      "x": -54,
      "y": 203,
      "z": 6,
      "name": "Rock_Stone"
    },
    {
      "x": -54,
      "y": 204,
      "z": 6,
      "name": "Rock_Stone"
    },
    {
      "x": -54,
      "y": 205,
      "z": 6,
      "name": "Rock_Stone"
    },
    {
      "x": -54,
      "y": 198,
      "z": 7,
      "name": "Rock_Stone"
    },
    {
      "x": -54,
      "y": 199,
      "z": 7,
      "name": "Rock_Stone"
    },
    {
      "x": -54,
      "y": 200,
      "z": 7,
      "name": "Rock_Stone"
    },
    {
      "x": -54,
      "y": 201,
      "z": 7,
      "name": "Rock_Stone"
    },
    {
      "x": -54,
      "y": 202,
      "z": 7,
      "name": "Rock_Stone"
    },
    {
      "x": -54,
      "y": 203,
      "z": 7,
      "name": "Rock_Stone"
    },
    {
      "x": -54,
      "y": 204,
      "z": 7,
      "name": "Rock_Stone"
    },
    {
      "x": -54,
      "y": 205,
      "z": 7,
      "name": "Rock_Stone"
    },
    {
      "x": -54,
      "y": 198,
      "z": 8,
      "name": "Rock_Stone"
    },
    {
      "x": -54,
      "y": 199,
      "z": 8,
      "name": "Rock_Stone"
    },
    {
      "x": -54,
      "y": 200,
      "z": 8,
      "name": "Rock_Stone"
    },
    {
      "x": -54,
      "y": 201,
      "z": 8,
      "name": "Rock_Stone"
    },
    {
      "x": -54,
      "y": 202,
      "z": 8,
      "name": "Rock_Stone"
    },
    {
      "x": -54,
      "y": 203,
      "z": 8,
      "name": "Rock_Stone"
    },
    {
      "x": -54,
      "y": 204,
      "z": 8,
      "name": "Rock_Stone"
    },
    {
      "x": -54,
      "y": 205,
      "z": 8,
      "name": "Rock_Stone"
    },
    {
      "x": -54,
      "y": 198,
      "z": 9,
      "name": "Rock_Stone"
    },
    {
      "x": -54,
      "y": 199,
      "z": 9,
      "name": "Rock_Stone"
    },
    {
      "x": -54,
      "y": 200,
      "z": 9,
      "name": "Rock_Stone"
    },
    {
      "x": -54,
      "y": 201,
      "z": 9,
      "name": "Rock_Stone"
    },
    {
      "x": -54,
      "y": 202,
      "z": 9,
      "name": "Rock_Stone"
    },
    {
      "x": -54,
      "y": 203,
      "z": 9,
      "name": "Rock_Stone"
    },
    {
      "x": -54,
      "y": 204,
      "z": 9,
      "name": "Rock_Stone"
    },
    {
      "x": -54,
      "y": 205,
      "z": 9,
      "name": "Rock_Stone"
    },
    {
      "x": -54,
      "y": 198,
      "z": 10,
      "name": "Rock_Stone"
    },
    {
      "x": -54,
      "y": 199,
      "z": 10,
      "name": "Rock_Stone"
    },
    {
      "x": -54,
      "y": 200,
      "z": 10,
      "name": "Rock_Stone"
    },
    {
      "x": -54,
      "y": 201,
      "z": 10,
      "name": "Rock_Stone"
    },
    {
      "x": -54,
      "y": 202,
      "z": 10,
      "name": "Rock_Stone"
    },
    {
      "x": -54,
      "y": 203,
      "z": 10,
      "name": "Rock_Stone"
    },
    {
      "x": -54,
      "y": 204,
      "z": 10,
      "name": "Rock_Stone"
    },
    {
      "x": -54,
      "y": 199,
      "z": 11,
      "name": "Rock_Stone"
    },
    {
      "x": -54,
      "y": 200,
      "z": 11,
      "name": "Rock_Stone"
    },
    {
      "x": -54,
      "y": 201,
      "z": 11,
      "name": "Rock_Stone"
    },
    {
      "x": -54,
      "y": 202,
      "z": 11,
      "name": "Rock_Stone"
    },
    {
      "x": -54,
      "y": 203,
      "z": 11,
      "name": "Rock_Stone"
    },
    {
      "x": -54,
      "y": 204,
      "z": 11,
      "name": "Rock_Stone"
    },
    {
      "x": -54,
      "y": 199,
      "z": 12,
      "name": "Rock_Stone"
    },
    {
