{
  "version": 8,
  "blockIdVersion": 11,
  "anchorX": 0,
  "anchorY": 0,
  "anchorZ": 0,
  "blocks": [
    {
      "x": -5,
      "y": 16,
      "z": -1,
      "name": "Rock_Shale"
    },
    {
      "x": -5,
      "y": 17,
      "z": -1,
      "name": "Rock_Shale"
    },
    {
      "x": -5,
      "y": 14,
      "z": 0,
      "name": "Rock_Shale"
    },
    {
      "x": -5,
      "y": 15,
      "z": 0,
      "name": "Rock_Shale"
    },
    {
      "x": -5,
      "y": 16,
      "z": 0,
      "name": "Rock_Shale"
    },
    {
      "x": -5,
      "y": 17,
      "z": 0,
      "name": "Rock_Shale"
    },
    {
      "x": -5,
      "y": 18,
      "z": 0,
      "name": "Rock_Shale"
    },
    {
      "x": -5,
      "y": 13,
      "z": 1,
      "name": "Rock_Shale"
    },
    {
      "x": -5,
      "y": 14,
      "z": 1,
      "name": "Rock_Shale"
    },
    {
      "x": -5,
      "y": 15,
      "z": 1,
      "name": "Rock_Shale"
    },
    {
      "x": -5,
      "y": 16,
      "z": 1,
      "name": "Rock_Shale"
    },
    {
      "x": -5,
      "y": 17,
      "z": 1,
      "name": "Rock_Shale"
    },
    {
      "x": -5,
      "y": 18,
      "z": 1,
      "name": "Rock_Shale"
    },
    {
      "x": -5,
      "y": 13,
      "z": 2,
      "name": "Rock_Shale"
    },
    {
      "x": -5,
      "y": 14,
      "z": 2,
      "name": "Rock_Shale"
    },
    {
      "x": -5,
      "y": 15,
      "z": 2,
      "name": "Rock_Shale"
    },
    {
      "x": -5,
      "y": 16,
      "z": 2,
      "name": "Rock_Shale"
    },
    {
      "x": -5,
      "y": 17,
      "z": 2,
      "name": "Rock_Shale"
    },
    {
      "x": -5,
      "y": 18,
      "z": 2,
      "name": "Rock_Shale"
    },
    {
      "x": -5,
      "y": 15,
      "z": 3,
      "name": "Rock_Shale"
    },
    {
      "x": -5,
      "y": 16,
      "z": 3,
      "name": "Rock_Shale"
    },
    {
      "x": -5,
      "y": 17,
      "z": 3,
      "name": "Rock_Shale"
    },
    {
      "x": -4,
      "y": 15,
      "z": -2,
      "name": "Rock_Shale"
    },
    {
      "x": -4,
      "y": 16,
      "z": -2,
      "name": "Rock_Shale"
    },
    {
      "x": -4,
      "y": 17,
      "z": -2,
      "name": "Rock_Shale"
    },
    {
      "x": -4,
      "y": 13,
      "z": -1,
      "name": "Rock_Shale"
    },
    {
      "x": -4,
      "y": 14,
      "z": -1,
      "name": "Rock_Shale"
    },
    {
      "x": -4,
      "y": 15,
      "z": -1,
      "name": "Rock_Shale"
    },
    {
      "x": -4,
      "y": 16,
      "z": -1,
      "name": "Rock_Shale"
    },
    {
      "x": -4,
      "y": 17,
      "z": -1,
      "name": "Rock_Shale"
    },
    {
      "x": -4,
      "y": 18,
      "z": -1,
      "name": "Rock_Shale"
    },
    {
      "x": -4,
      "y": 12,
      "z": 0,
      "name": "Rock_Shale"
    },
    {
      "x": -4,
      "y": 13,
      "z": 0,
      "name": "Rock_Shale"
    },
    {
      "x": -4,
      "y": 14,
      "z": 0,
      "name": "Rock_Shale"
    },
    {
      "x": -4,
      "y": 15,
      "z": 0,
      "name": "Rock_Shale"
    },
    {
      "x": -4,
      "y": 16,
      "z": 0,
      "name": "Rock_Shale"
    },
    {
      "x": -4,
      "y": 17,
      "z": 0,
      "name": "Rock_Shale"
    },
    {
      "x": -4,
      "y": 18,
      "z": 0,
      "name": "Rock_Shale"
    },
    {
      "x": -4,
      "y": 19,
      "z": 0,
      "name": "Rock_Shale"
    },
    {
      "x": -4,
      "y": 12,
      "z": 1,
      "name": "Rock_Shale"
    },
    {
      "x": -4,
      "y": 13,
      "z": 1,
      "name": "Rock_Shale"
    },
    {
      "x": -4,
      "y": 14,
      "z": 1,
      "name": "Rock_Shale"
    },
    {
      "x": -4,
      "y": 15,
      "z": 1,
      "name": "Rock_Shale"
    },
    {
      "x": -4,
      "y": 16,
      "z": 1,
      "name": "Rock_Shale"
    },
    {
      "x": -4,
      "y": 17,
      "z": 1,
      "name": "Rock_Shale"
    },
    {
      "x": -4,
      "y": 18,
      "z": 1,
      "name": "Rock_Shale"
    },
    {
      "x": -4,
      "y": 19,
      "z": 1,
      "name": "Rock_Shale"
    },
    {
      "x": -4,
      "y": 11,
      "z": 2,
      "name": "Rock_Shale_Stalactites_Small",
      "rotation": 8
    },
    {
      "x": -4,
      "y": 12,
      "z": 2,
      "name": "Rock_Shale"
    },
    {
      "x": -4,
      "y": 13,
      "z": 2,
      "name": "Rock_Shale"
    },
    {
      "x": -4,
      "y": 14,
      "z": 2,
      "name": "Rock_Shale"
    },
    {
      "x": -4,
      "y": 15,
      "z": 2,
      "name": "Rock_Shale"
    },
    {
      "x": -4,
      "y": 16,
      "z": 2,
      "name": "Rock_Shale"
    },
    {
      "x": -4,
      "y": 17,
      "z": 2,
      "name": "Rock_Shale"
    },
    {
      "x": -4,
      "y": 18,
      "z": 2,
      "name": "Rock_Shale"
    },
    {
      "x": -4,
      "y": 19,
      "z": 2,
      "name": "Rock_Shale"
    },
    {
      "x": -4,
      "y": 13,
      "z": 3,
      "name": "Rock_Shale"
    },
    {
      "x": -4,
      "y": 14,
      "z": 3,
      "name": "Rock_Shale"
    },
    {
      "x": -4,
      "y": 15,
      "z": 3,
      "name": "Rock_Shale"
    },
    {
      "x": -4,
      "y": 16,
      "z": 3,
      "name": "Rock_Shale"
    },
    {
      "x": -4,
      "y": 17,
      "z": 3,
      "name": "Rock_Shale"
    },
    {
      "x": -4,
      "y": 18,
      "z": 3,
      "name": "Rock_Shale"
    },
    {
      "x": -3,
      "y": 15,
      "z": -3,
      "name": "Rock_Shale"
    },
    {
      "x": -3,
      "y": 16,
      "z": -3,
      "name": "Rock_Shale"
    },
    {
      "x": -3,
      "y": 17,
      "z": -3,
      "name": "Rock_Shale"
    },
    {
      "x": -3,
      "y": 13,
      "z": -2,
      "name": "Rock_Shale"
    },
    {
      "x": -3,
      "y": 14,
      "z": -2,
      "name": "Rock_Shale"
    },
    {
      "x": -3,
      "y": 15,
      "z": -2,
      "name": "Rock_Shale"
    },
    {
      "x": -3,
      "y": 16,
      "z": -2,
      "name": "Rock_Shale"
    },
    {
      "x": -3,
      "y": 17,
      "z": -2,
      "name": "Rock_Shale"
    },
    {
      "x": -3,
      "y": 18,
      "z": -2,
      "name": "Rock_Shale"
    },
    {
      "x": -3,
      "y": 11,
      "z": -1,
      "name": "Rock_Shale"
    },
    {
      "x": -3,
      "y": 12,
      "z": -1,
      "name": "Rock_Shale"
    },
    {
      "x": -3,
      "y": 13,
      "z": -1,
      "name": "Rock_Shale"
    },
    {
      "x": -3,
      "y": 14,
      "z": -1,
      "name": "Rock_Shale"
    },
    {
      "x": -3,
      "y": 15,
      "z": -1,
      "name": "Rock_Shale"
    },
    {
      "x": -3,
      "y": 16,
      "z": -1,
      "name": "Rock_Shale"
    },
    {
      "x": -3,
      "y": 17,
      "z": -1,
      "name": "Rock_Shale"
    },
    {
      "x": -3,
      "y": 18,
      "z": -1,
      "name": "Rock_Shale"
    },
    {
      "x": -3,
      "y": 19,
      "z": -1,
      "name": "Rock_Shale"
    },
    {
      "x": -3,
      "y": 11,
      "z": 0,
      "name": "Rock_Shale"
    },
    {
      "x": -3,
      "y": 12,
      "z": 0,
      "name": "Rock_Shale"
    },
    {
      "x": -3,
      "y": 13,
      "z": 0,
      "name": "Rock_Shale"
    },
    {
      "x": -3,
      "y": 14,
      "z": 0,
      "name": "Rock_Shale"
    },
    {
      "x": -3,
      "y": 15,
      "z": 0,
      "name": "Rock_Shale"
    },
    {
      "x": -3,
      "y": 16,
      "z": 0,
      "name": "Rock_Shale"
    },
    {
      "x": -3,
      "y": 17,
      "z": 0,
      "name": "Rock_Shale"
    },
    {
      "x": -3,
      "y": 18,
      "z": 0,
      "name": "Rock_Shale"
    },
    {
      "x": -3,
      "y": 19,
      "z": 0,
      "name": "Rock_Shale"
    },
    {
      "x": -3,
      "y": 20,
      "z": 0,
      "name": "Rock_Shale"
    },
    {
      "x": -3,
      "y": 10,
      "z": 1,
      "name": "Rock_Shale"
    },
    {
      "x": -3,
      "y": 11,
      "z": 1,
      "name": "Rock_Shale"
    },
    {
      "x": -3,
      "y": 12,
      "z": 1,
      "name": "Rock_Shale"
    },
    {
      "x": -3,
      "y": 13,
      "z": 1,
      "name": "Rock_Shale"
    },
    {
      "x": -3,
      "y": 14,
      "z": 1,
      "name": "Rock_Shale"
    },
    {
      "x": -3,
      "y": 15,
      "z": 1,
      "name": "Rock_Shale"
    },
    {
      "x": -3,
      "y": 16,
      "z": 1,
      "name": "Rock_Shale"
    },
    {
      "x": -3,
      "y": 17,
      "z": 1,
      "name": "Rock_Shale"
    },
    {
      "x": -3,
      "y": 18,
      "z": 1,
      "name": "Rock_Shale"
    },
    {
      "x": -3,
      "y": 19,
      "z": 1,
      "name": "Rock_Shale"
    },
    {
      "x": -3,
      "y": 20,
      "z": 1,
      "name": "Rock_Shale"
    },
    {
      "x": -3,
      "y": 11,
      "z": 2,
      "name": "Rock_Shale"
    },
    {
      "x": -3,
      "y": 12,
      "z": 2,
      "name": "Rock_Shale"
    },
    {
      "x": -3,
      "y": 13,
      "z": 2,
      "name": "Rock_Shale"
    },
    {
      "x": -3,
      "y": 14,
      "z": 2,
      "name": "Rock_Shale"
    },
    {
      "x": -3,
      "y": 15,
      "z": 2,
      "name": "Rock_Shale"
    },
    {
      "x": -3,
      "y": 16,
      "z": 2,
      "name": "Rock_Shale"
    },
    {
      "x": -3,
      "y": 17,
      "z": 2,
      "name": "Rock_Shale"
    },
    {
      "x": -3,
      "y": 18,
      "z": 2,
      "name": "Rock_Shale"
    },
    {
      "x": -3,
      "y": 19,
      "z": 2,
      "name": "Rock_Shale"
    },
    {
      "x": -3,
      "y": 12,
      "z": 3,
      "name": "Rock_Shale"
    },
    {
      "x": -3,
      "y": 13,
      "z": 3,
      "name": "Rock_Shale"
    },
    {
      "x": -3,
      "y": 14,
      "z": 3,
      "name": "Rock_Shale"
    },
    {
      "x": -3,
      "y": 15,
      "z": 3,
      "name": "Rock_Shale"
    },
    {
      "x": -3,
      "y": 16,
      "z": 3,
      "name": "Rock_Shale"
    },
    {
      "x": -3,
      "y": 17,
      "z": 3,
      "name": "Rock_Shale"
    },
    {
      "x": -3,
      "y": 18,
      "z": 3,
      "name": "Rock_Shale"
    },
    {
      "x": -3,
      "y": 19,
      "z": 3,
      "name": "Rock_Shale"
    },
    {
      "x": -3,
      "y": 13,
      "z": 4,
      "name": "Rock_Shale"
    },
    {
      "x": -3,
      "y": 14,
      "z": 4,
      "name": "Rock_Shale"
    },
    {
      "x": -3,
      "y": 15,
      "z": 4,
      "name": "Rock_Shale"
    },
    {
      "x": -3,
      "y": 16,
      "z": 4,
      "name": "Rock_Shale"
    },
    {
      "x": -3,
      "y": 17,
      "z": 4,
      "name": "Rock_Shale"
    },
    {
      "x": -3,
      "y": 13,
      "z": 5,
      "name": "Rock_Shale"
    },
    {
      "x": -3,
      "y": 14,
      "z": 5,
      "name": "Rock_Shale"
    },
    {
      "x": -3,
      "y": 15,
      "z": 5,
      "name": "Rock_Shale"
    },
    {
      "x": -3,
      "y": 16,
      "z": 5,
      "name": "Rock_Shale"
    },
    {
      "x": -3,
      "y": 17,
      "z": 5,
      "name": "Rock_Shale"
    },
    {
      "x": -2,
      "y": 15,
      "z": -3,
      "name": "Rock_Shale"
    },
    {
      "x": -2,
      "y": 16,
      "z": -3,
      "name": "Rock_Shale"
    },
    {
      "x": -2,
      "y": 17,
      "z": -3,
      "name": "Rock_Shale"
    },
    {
      "x": -2,
      "y": 18,
      "z": -3,
      "name": "Rock_Shale"
    },
    {
      "x": -2,
      "y": 11,
      "z": -2,
      "name": "Rock_Shale"
    },
    {
      "x": -2,
      "y": 12,
      "z": -2,
      "name": "Rock_Shale"
    },
    {
      "x": -2,
      "y": 13,
      "z": -2,
      "name": "Rock_Shale"
    },
    {
      "x": -2,
      "y": 14,
      "z": -2,
      "name": "Rock_Shale"
    },
    {
      "x": -2,
      "y": 15,
      "z": -2,
      "name": "Rock_Shale"
    },
    {
      "x": -2,
      "y": 16,
      "z": -2,
      "name": "Rock_Shale"
    },
    {
      "x": -2,
      "y": 17,
      "z": -2,
      "name": "Rock_Shale"
    },
    {
      "x": -2,
      "y": 18,
      "z": -2,
      "name": "Rock_Shale"
    },
    {
      "x": -2,
      "y": 19,
      "z": -2,
      "name": "Rock_Shale"
    },
    {
      "x": -2,
      "y": 9,
      "z": -1,
      "name": "Rock_Shale_Stalactites_Small",
      "rotation": 8
    },
    {
      "x": -2,
      "y": 10,
      "z": -1,
      "name": "Rock_Shale"
    },
    {
      "x": -2,
      "y": 11,
      "z": -1,
      "name": "Rock_Shale"
    },
    {
      "x": -2,
      "y": 12,
      "z": -1,
      "name": "Rock_Shale"
    },
    {
      "x": -2,
      "y": 13,
      "z": -1,
      "name": "Rock_Shale"
    },
    {
      "x": -2,
      "y": 14,
      "z": -1,
      "name": "Rock_Shale"
    },
    {
      "x": -2,
      "y": 15,
      "z": -1,
      "name": "Rock_Shale"
    },
    {
      "x": -2,
      "y": 16,
      "z": -1,
      "name": "Rock_Shale"
    },
    {
      "x": -2,
      "y": 17,
      "z": -1,
      "name": "Rock_Shale"
    },
    {
      "x": -2,
      "y": 18,
      "z": -1,
      "name": "Rock_Shale"
    },
    {
      "x": -2,
      "y": 19,
      "z": -1,
      "name": "Rock_Shale"
    },
    {
      "x": -2,
      "y": 0,
      "z": 0,
      "name": "Rock_Shale"
    },
    {
      "x": -2,
      "y": 1,
      "z": 0,
      "name": "Rock_Shale_Stalactites_Small"
    },
    {
      "x": -2,
      "y": 9,
      "z": 0,
      "name": "Rock_Shale"
    },
    {
      "x": -2,
      "y": 10,
      "z": 0,
      "name": "Rock_Shale"
    },
    {
      "x": -2,
      "y": 11,
      "z": 0,
      "name": "Rock_Shale"
    },
    {
      "x": -2,
      "y": 12,
      "z": 0,
      "name": "Rock_Shale"
    },
    {
      "x": -2,
      "y": 13,
      "z": 0,
      "name": "Rock_Shale"
    },
    {
      "x": -2,
      "y": 14,
      "z": 0,
      "name": "Rock_Shale"
    },
    {
      "x": -2,
      "y": 15,
      "z": 0,
      "name": "Rock_Shale"
    },
    {
      "x": -2,
      "y": 16,
      "z": 0,
      "name": "Rock_Shale"
    },
    {
      "x": -2,
      "y": 17,
      "z": 0,
      "name": "Rock_Shale"
    },
    {
      "x": -2,
      "y": 18,
      "z": 0,
      "name": "Rock_Shale"
    },
    {
      "x": -2,
      "y": 19,
      "z": 0,
      "name": "Rock_Shale"
    },
    {
      "x": -2,
      "y": 20,
      "z": 0,
      "name": "Rock_Shale"
    },
    {
      "x": -2,
      "y": 0,
      "z": 1,
      "name": "Rock_Shale"
    },
    {
      "x": -2,
      "y": 1,
      "z": 1,
      "name": "Plant_Mushroom_Rug_White_Mycelium",
      "support": 15
    },
    {
      "x": -2,
      "y": 8,
      "z": 1,
      "name": "Plant_Mushroom_Wall_White_Mycelium",
      "support": 15,
      "rotation": 3
    },
    {
      "x": -2,
      "y": 9,
      "z": 1,
      "name": "Plant_Mushroom_Wall_White_Mycelium",
      "support": 15,
      "rotation": 3
    },
    {
      "x": -2,
      "y": 10,
      "z": 1,
      "name": "Rock_Shale"
    },
    {
      "x": -2,
      "y": 11,
      "z": 1,
      "name": "Rock_Shale"
    },
    {
      "x": -2,
      "y": 12,
      "z": 1,
      "name": "Rock_Shale"
    },
    {
      "x": -2,
      "y": 13,
      "z": 1,
      "name": "Rock_Shale"
    },
    {
      "x": -2,
      "y": 14,
      "z": 1,
      "name": "Rock_Shale"
    },
    {
      "x": -2,
      "y": 15,
      "z": 1,
      "name": "Rock_Shale"
    },
    {
      "x": -2,
      "y": 16,
      "z": 1,
      "name": "Rock_Shale"
    },
    {
      "x": -2,
      "y": 17,
      "z": 1,
      "name": "Rock_Shale"
    },
    {
      "x": -2,
      "y": 18,
      "z": 1,
      "name": "Rock_Shale"
    },
    {
      "x": -2,
      "y": 19,
      "z": 1,
      "name": "Rock_Shale"
    },
    {
      "x": -2,
      "y": 20,
      "z": 1,
      "name": "Rock_Shale"
    },
    {
      "x": -2,
      "y": 0,
      "z": 2,
      "name": "Rock_Shale"
    },
    {
      "x": -2,
      "y": 1,
      "z": 2,
      "name": "Rock_Shale"
    },
    {
      "x": -2,
      "y": 2,
      "z": 2,
      "name": "Plant_Mushroom_Short_White_Mycelium",
      "support": 15
    },
    {
      "x": -2,
      "y": 9,
      "z": 2,
      "name": "Plant_Mushroom_Wall_White_Mycelium",
      "support": 15,
      "rotation": 3
    },
    {
      "x": -2,
      "y": 10,
      "z": 2,
      "name": "Rock_Shale"
    },
    {
      "x": -2,
      "y": 11,
      "z": 2,
      "name": "Rock_Shale"
    },
    {
      "x": -2,
      "y": 12,
      "z": 2,
      "name": "Rock_Shale"
    },
    {
      "x": -2,
      "y": 13,
      "z": 2,
      "name": "Rock_Shale"
    },
    {
      "x": -2,
      "y": 14,
      "z": 2,
      "name": "Rock_Shale"
    },
    {
      "x": -2,
      "y": 15,
      "z": 2,
      "name": "Rock_Shale"
    },
    {
      "x": -2,
      "y": 16,
      "z": 2,
      "name": "Rock_Shale"
    },
    {
      "x": -2,
      "y": 17,
      "z": 2,
      "name": "Rock_Shale"
    },
    {
      "x": -2,
      "y": 18,
      "z": 2,
      "name": "Rock_Shale"
    },
    {
      "x": -2,
      "y": 19,
      "z": 2,
      "name": "Rock_Shale"
    },
    {
      "x": -2,
      "y": 20,
      "z": 2,
      "name": "Rock_Shale"
    },
    {
      "x": -2,
      "y": 10,
      "z": 3,
      "name": "Rock_Shale"
    },
    {
      "x": -2,
      "y": 11,
      "z": 3,
      "name": "Rock_Shale"
    },
    {
      "x": -2,
      "y": 12,
      "z": 3,
      "name": "Rock_Shale"
    },
    {
      "x": -2,
      "y": 13,
      "z": 3,
      "name": "Rock_Shale"
    },
    {
      "x": -2,
      "y": 14,
      "z": 3,
      "name": "Rock_Shale"
    },
    {
      "x": -2,
      "y": 15,
      "z": 3,
      "name": "Rock_Shale"
    },
    {
      "x": -2,
      "y": 16,
      "z": 3,
      "name": "Rock_Shale"
    },
    {
      "x": -2,
      "y": 17,
      "z": 3,
      "name": "Rock_Shale"
    },
    {
      "x": -2,
      "y": 18,
      "z": 3,
      "name": "Rock_Shale"
    },
    {
      "x": -2,
      "y": 19,
      "z": 3,
      "name": "Rock_Shale"
    },
    {
      "x": -2,
      "y": 11,
      "z": 4,
      "name": "Rock_Shale"
    },
    {
      "x": -2,
      "y": 12,
      "z": 4,
      "name": "Rock_Shale"
    },
    {
      "x": -2,
      "y": 13,
      "z": 4,
      "name": "Rock_Shale"
    },
    {
      "x": -2,
      "y": 14,
      "z": 4,
      "name": "Rock_Shale"
    },
    {
      "x": -2,
      "y": 15,
      "z": 4,
      "name": "Rock_Shale"
    },
    {
      "x": -2,
      "y": 16,
      "z": 4,
      "name": "Rock_Shale"
    },
    {
      "x": -2,
      "y": 17,
      "z": 4,
      "name": "Rock_Shale"
    },
    {
      "x": -2,
      "y": 18,
      "z": 4,
      "name": "Rock_Shale"
    },
    {
      "x": -2,
      "y": 12,
      "z": 5,
      "name": "Rock_Shale"
    },
    {
      "x": -2,
      "y": 13,
      "z": 5,
      "name": "Rock_Shale"
    },
    {
      "x": -2,
      "y": 14,
      "z": 5,
      "name": "Rock_Shale"
    },
    {
      "x": -2,
      "y": 15,
      "z": 5,
      "name": "Rock_Shale"
    },
    {
      "x": -2,
      "y": 16,
      "z": 5,
      "name": "Rock_Shale"
    },
    {
      "x": -2,
      "y": 17,
      "z": 5,
      "name": "Rock_Shale"
    },
    {
      "x": -1,
      "y": 16,
      "z": -4,
      "name": "Rock_Shale"
    },
    {
      "x": -1,
      "y": 17,
      "z": -4,
      "name": "Rock_Shale"
    },
    {
      "x": -1,
      "y": 18,
      "z": -4,
      "name": "Rock_Shale"
    },
    {
      "x": -1,
      "y": 13,
      "z": -3,
      "name": "Rock_Shale"
    },
    {
      "x": -1,
      "y": 14,
      "z": -3,
      "name": "Rock_Shale"
    },
    {
      "x": -1,
      "y": 15,
      "z": -3,
      "name": "Rock_Shale"
    },
    {
      "x": -1,
      "y": 16,
      "z": -3,
      "name": "Rock_Shale"
    },
    {
      "x": -1,
      "y": 17,
      "z": -3,
      "name": "Rock_Shale"
    },
    {
      "x": -1,
      "y": 18,
      "z": -3,
      "name": "Rock_Shale"
    },
    {
      "x": -1,
      "y": 11,
      "z": -2,
      "name": "Rock_Shale"
    },
    {
      "x": -1,
      "y": 12,
      "z": -2,
      "name": "Rock_Shale"
    },
    {
      "x": -1,
      "y": 13,
      "z": -2,
      "name": "Rock_Shale"
    },
    {
      "x": -1,
      "y": 14,
      "z": -2,
      "name": "Rock_Shale"
    },
    {
      "x": -1,
      "y": 15,
      "z": -2,
      "name": "Rock_Shale"
    },
    {
      "x": -1,
      "y": 16,
      "z": -2,
      "name": "Rock_Shale"
    },
    {
      "x": -1,
      "y": 17,
      "z": -2,
      "name": "Rock_Shale"
    },
    {
      "x": -1,
      "y": 18,
      "z": -2,
      "name": "Rock_Shale"
    },
    {
      "x": -1,
      "y": 19,
      "z": -2,
      "name": "Rock_Shale"
    },
    {
      "x": -1,
      "y": 0,
      "z": -1,
      "name": "Rock_Shale"
    },
    {
      "x": -1,
      "y": 1,
      "z": -1,
      "name": "Plant_Roots_Rug_Tainted",
      "support": 15
    },
    {
      "x": -1,
      "y": 7,
      "z": -1,
      "name": "Rock_Shale_Stalactites_Large",
      "filler": 31744,
      "rotation": 8
    },
    {
      "x": -1,
      "y": 8,
      "z": -1,
      "name": "Rock_Shale_Stalactites_Large",
      "rotation": 8
    },
    {
      "x": -1,
      "y": 9,
      "z": -1,
      "name": "Rock_Shale"
    },
    {
      "x": -1,
      "y": 10,
      "z": -1,
      "name": "Rock_Shale"
    },
    {
      "x": -1,
      "y": 11,
      "z": -1,
      "name": "Rock_Shale"
    },
    {
      "x": -1,
      "y": 12,
      "z": -1,
      "name": "Rock_Shale"
    },
    {
      "x": -1,
      "y": 13,
      "z": -1,
      "name": "Rock_Shale"
    },
    {
      "x": -1,
      "y": 14,
      "z": -1,
      "name": "Rock_Shale"
    },
    {
      "x": -1,
      "y": 15,
      "z": -1,
      "name": "Rock_Shale"
    },
    {
      "x": -1,
      "y": 16,
      "z": -1,
      "name": "Rock_Shale"
    },
    {
      "x": -1,
      "y": 17,
      "z": -1,
      "name": "Rock_Shale"
    },
    {
      "x": -1,
      "y": 18,
      "z": -1,
      "name": "Rock_Shale"
    },
    {
      "x": -1,
      "y": 19,
      "z": -1,
      "name": "Rock_Shale"
    },
    {
      "x": -1,
      "y": 20,
      "z": -1,
      "name": "Rock_Shale"
    },
    {
      "x": -1,
      "y": 0,
      "z": 0,
      "name": "Rock_Shale"
    },
    {
      "x": -1,
      "y": 1,
      "z": 0,
      "name": "Rock_Shale"
    },
    {
      "x": -1,
      "y": 2,
      "z": 0,
      "name": "Plant_Mushroom_Rug_White_Mycelium",
      "support": 15
    },
    {
      "x": -1,
      "y": 8,
      "z": 0,
      "name": "Plant_Mushroom_Cave_White_Mycelium",
      "support": 15,
      "rotation": 8
    },
    {
      "x": -1,
      "y": 9,
      "z": 0,
      "name": "Wood_Giantwood_Trunk_Tainted_Full",
      "support": 15
    },
    {
      "x": -1,
      "y": 10,
      "z": 0,
      "name": "Wood_Giantwood_Trunk_Tainted_Full",
      "support": 15
    },
    {
      "x": -1,
      "y": 11,
      "z": 0,
      "name": "Wood_Giantwood_Trunk_Tainted_Full",
      "support": 15
    },
    {
      "x": -1,
      "y": 12,
      "z": 0,
      "name": "Wood_Giantwood_Trunk_Tainted_Full",
      "support": 15
    },
    {
      "x": -1,
      "y": 13,
      "z": 0,
      "name": "Wood_Giantwood_Trunk_Tainted_Full",
      "support": 15
    },
    {
      "x": -1,
      "y": 14,
      "z": 0,
      "name": "Wood_Giantwood_Trunk_Tainted_Full",
      "support": 15
    },
    {
      "x": -1,
      "y": 15,
      "z": 0,
      "name": "Wood_Giantwood_Trunk_Tainted_Full",
      "support": 15
    },
    {
      "x": -1,
      "y": 16,
      "z": 0,
      "name": "Wood_Giantwood_Trunk_Tainted_Full",
      "support": 15
    },
    {
      "x": -1,
      "y": 17,
      "z": 0,
      "name": "Rock_Shale"
    },
    {
      "x": -1,
      "y": 18,
      "z": 0,
      "name": "Rock_Shale"
    },
    {
      "x": -1,
      "y": 19,
      "z": 0,
      "name": "Rock_Shale"
    },
    {
      "x": -1,
      "y": 20,
      "z": 0,
      "name": "Rock_Shale"
    },
    {
      "x": -1,
      "y": 0,
      "z": 1,
      "name": "Rock_Shale"
    },
    {
      "x": -1,
      "y": 1,
      "z": 1,
      "name": "Rock_Shale"
    },
    {
      "x": -1,
      "y": 2,
      "z": 1,
      "name": "Rock_Shale"
    },
    {
      "x": -1,
      "y": 3,
      "z": 1,
      "name": "Plant_Roots_Rug_Tainted",
      "support": 15
    },
    {
      "x": -1,
      "y": 7,
      "z": 1,
      "name": "Plant_Mushroom_Cave_White_Mycelium",
      "support": 15,
      "rotation": 8
    },
    {
      "x": -1,
      "y": 8,
      "z": 1,
      "name": "Wood_Giantwood_Trunk_Tainted_Full",
      "support": 15
    },
    {
      "x": -1,
      "y": 9,
      "z": 1,
      "name": "Wood_Giantwood_Trunk_Tainted_Full",
      "support": 15
    },
    {
      "x": -1,
      "y": 10,
      "z": 1,
      "name": "Wood_Giantwood_Trunk_Tainted_Full",
      "support": 15
    },
    {
      "x": -1,
      "y": 11,
      "z": 1,
      "name": "Wood_Giantwood_Trunk_Tainted_Full",
      "support": 15
    },
    {
      "x": -1,
      "y": 12,
      "z": 1,
      "name": "Wood_Giantwood_Trunk_Tainted_Full",
      "support": 15
    },
    {
      "x": -1,
      "y": 13,
      "z": 1,
      "name": "Wood_Giantwood_Trunk_Tainted_Full",
      "support": 15
    },
    {
      "x": -1,
      "y": 14,
      "z": 1,
      "name": "Wood_Giantwood_Trunk_Tainted_Full",
      "support": 15
    },
    {
      "x": -1,
      "y": 15,
      "z": 1,
      "name": "Wood_Giantwood_Trunk_Tainted_Full",
      "support": 15
    },
    {
      "x": -1,
      "y": 16,
      "z": 1,
      "name": "Wood_Giantwood_Trunk_Tainted_Full",
      "support": 15
    },
    {
      "x": -1,
      "y": 17,
      "z": 1,
      "name": "Rock_Shale"
    },
    {
      "x": -1,
      "y": 18,
      "z": 1,
      "name": "Rock_Shale"
    },
    {
      "x": -1,
      "y": 19,
      "z": 1,
      "name": "Rock_Shale"
    },
    {
      "x": -1,
      "y": 20,
      "z": 1,
      "name": "Rock_Shale"
    },
    {
      "x": -1,
      "y": 0,
      "z": 2,
      "name": "Rock_Shale"
    },
    {
      "x": -1,
      "y": 1,
      "z": 2,
      "name": "Rock_Shale"
    },
    {
      "x": -1,
      "y": 2,
      "z": 2,
      "name": "Rock_Shale"
    },
    {
      "x": -1,
      "y": 3,
      "z": 2,
      "name": "Plant_Mushroom_Rug_White_Mycelium",
      "support": 15
    },
    {
      "x": -1,
      "y": 8,
      "z": 2,
      "name": "Plant_Mushroom_Cave_White_Mycelium",
      "support": 15,
      "rotation": 8
    },
    {
      "x": -1,
      "y": 9,
      "z": 2,
      "name": "Wood_Giantwood_Trunk_Tainted_Full",
      "support": 15
    },
    {
      "x": -1,
      "y": 10,
      "z": 2,
      "name": "Wood_Giantwood_Trunk_Tainted_Full",
      "support": 15
    },
    {
      "x": -1,
      "y": 11,
      "z": 2,
      "name": "Wood_Giantwood_Trunk_Tainted_Full",
      "support": 15
    },
    {
      "x": -1,
      "y": 12,
      "z": 2,
      "name": "Rock_Shale"
    },
    {
      "x": -1,
      "y": 13,
      "z": 2,
      "name": "Rock_Shale"
    },
    {
      "x": -1,
      "y": 14,
      "z": 2,
      "name": "Rock_Shale"
    },
    {
      "x": -1,
      "y": 15,
      "z": 2,
      "name": "Rock_Shale"
    },
    {
      "x": -1,
      "y": 16,
      "z": 2,
      "name": "Rock_Shale"
    },
    {
      "x": -1,
      "y": 17,
      "z": 2,
      "name": "Rock_Shale"
    },
    {
      "x": -1,
      "y": 18,
      "z": 2,
      "name": "Rock_Shale"
    },
    {
      "x": -1,
      "y": 19,
      "z": 2,
      "name": "Rock_Shale"
    },
    {
      "x": -1,
      "y": 20,
      "z": 2,
      "name": "Rock_Shale"
    },
    {
      "x": -1,
      "y": 0,
      "z": 3,
      "name": "Rock_Shale"
    },
    {
      "x": -1,
      "y": 1,
      "z": 3,
      "name": "Rock_Shale"
    },
    {
      "x": -1,
      "y": 2,
      "z": 3,
      "name": "Rock_Shale_Stalactites_Large"
    },
    {
      "x": -1,
      "y": 3,
      "z": 3,
      "name": "Rock_Shale_Stalactites_Large",
      "filler": 1024
    },
    {
      "x": -1,
      "y": 8,
      "z": 3,
      "name": "Rock_Shale_Stalactites_Small",
      "rotation": 8
    },
    {
      "x": -1,
      "y": 9,
      "z": 3,
      "name": "Rock_Shale"
    },
    {
      "x": -1,
      "y": 10,
      "z": 3,
      "name": "Rock_Shale"
    },
    {
      "x": -1,
      "y": 11,
      "z": 3,
      "name": "Rock_Shale"
    },
    {
      "x": -1,
      "y": 12,
      "z": 3,
      "name": "Rock_Shale"
    },
    {
      "x": -1,
      "y": 13,
      "z": 3,
      "name": "Rock_Shale"
    },
    {
      "x": -1,
      "y": 14,
      "z": 3,
      "name": "Rock_Shale"
    },
    {
      "x": -1,
      "y": 15,
      "z": 3,
      "name": "Rock_Shale"
    },
    {
      "x": -1,
      "y": 16,
      "z": 3,
      "name": "Rock_Shale"
    },
    {
      "x": -1,
      "y": 17,
      "z": 3,
      "name": "Rock_Shale"
    },
    {
      "x": -1,
      "y": 18,
      "z": 3,
      "name": "Rock_Shale"
    },
    {
      "x": -1,
      "y": 19,
      "z": 3,
      "name": "Rock_Shale"
    },
    {
      "x": -1,
      "y": 0,
      "z": 4,
      "name": "Rock_Shale"
    },
    {
      "x": -1,
      "y": 1,
      "z": 4,
      "name": "Plant_Roots_Rug_Tainted",
      "support": 15
    },
    {
      "x": -1,
      "y": 10,
      "z": 4,
      "name": "Rock_Shale"
    },
    {
      "x": -1,
      "y": 11,
      "z": 4,
      "name": "Rock_Shale"
    },
    {
      "x": -1,
      "y": 12,
      "z": 4,
      "name": "Rock_Shale"
    },
    {
      "x": -1,
      "y": 13,
      "z": 4,
      "name": "Rock_Shale"
    },
    {
      "x": -1,
      "y": 14,
      "z": 4,
      "name": "Rock_Shale"
    },
    {
      "x": -1,
      "y": 15,
      "z": 4,
      "name": "Rock_Shale"
    },
    {
      "x": -1,
      "y": 16,
      "z": 4,
      "name": "Rock_Shale"
    },
    {
      "x": -1,
      "y": 17,
      "z": 4,
      "name": "Rock_Shale"
    },
    {
      "x": -1,
      "y": 18,
      "z": 4,
      "name": "Rock_Shale"
    },
    {
      "x": -1,
      "y": 19,
      "z": 4,
      "name": "Rock_Shale"
    },
    {
      "x": -1,
      "y": 11,
      "z": 5,
      "name": "Rock_Shale"
    },
    {
      "x": -1,
      "y": 12,
      "z": 5,
      "name": "Rock_Shale"
    },
    {
      "x": -1,
      "y": 13,
      "z": 5,
      "name": "Rock_Shale"
    },
    {
      "x": -1,
      "y": 14,
      "z": 5,
      "name": "Rock_Shale"
    },
    {
      "x": -1,
      "y": 15,
      "z": 5,
      "name": "Rock_Shale"
    },
    {
      "x": -1,
      "y": 16,
      "z": 5,
      "name": "Rock_Shale"
    },
    {
      "x": -1,
      "y": 17,
      "z": 5,
      "name": "Rock_Shale"
    },
    {
      "x": -1,
      "y": 18,
      "z": 5,
      "name": "Rock_Shale"
    },
    {
      "x": 0,
      "y": 14,
      "z": -4,
      "name": "Rock_Shale"
    },
    {
      "x": 0,
      "y": 15,
      "z": -4,
      "name": "Rock_Shale"
    },
    {
      "x": 0,
      "y": 16,
      "z": -4,
      "name": "Rock_Shale"
    },
    {
      "x": 0,
      "y": 17,
      "z": -4,
      "name": "Rock_Shale"
    },
    {
      "x": 0,
      "y": 18,
      "z": -4,
      "name": "Rock_Shale"
    },
    {
      "x": 0,
      "y": 12,
      "z": -3,
      "name": "Rock_Shale"
    },
    {
      "x": 0,
      "y": 13,
      "z": -3,
      "name": "Rock_Shale"
    },
    {
      "x": 0,
      "y": 14,
      "z": -3,
      "name": "Rock_Shale"
    },
    {
      "x": 0,
      "y": 15,
      "z": -3,
      "name": "Rock_Shale"
    },
    {
      "x": 0,
      "y": 16,
      "z": -3,
      "name": "Rock_Shale"
    },
    {
      "x": 0,
      "y": 17,
      "z": -3,
      "name": "Rock_Shale"
    },
    {
      "x": 0,
      "y": 18,
      "z": -3,
      "name": "Rock_Shale"
    },
    {
      "x": 0,
      "y": 0,
      "z": -2,
      "name": "Rock_Shale"
    },
    {
      "x": 0,
      "y": 1,
      "z": -2,
      "name": "Plant_Mushroom_Rug_White_Mycelium",
      "support": 15
    },
    {
      "x": 0,
      "y": 10,
      "z": -2,
      "name": "Rock_Shale_Stalactites_Small",
      "rotation": 8
    },
    {
      "x": 0,
      "y": 11,
      "z": -2,
      "name": "Rock_Shale"
    },
    {
      "x": 0,
      "y": 12,
      "z": -2,
      "name": "Rock_Shale"
    },
    {
      "x": 0,
      "y": 13,
      "z": -2,
      "name": "Rock_Shale"
    },
    {
      "x": 0,
      "y": 14,
      "z": -2,
      "name": "Rock_Shale"
    },
    {
      "x": 0,
      "y": 15,
      "z": -2,
      "name": "Rock_Shale"
    },
    {
      "x": 0,
      "y": 16,
      "z": -2,
      "name": "Rock_Shale"
    },
    {
      "x": 0,
      "y": 17,
      "z": -2,
      "name": "Rock_Shale"
    },
    {
      "x": 0,
      "y": 18,
      "z": -2,
      "name": "Rock_Shale"
    },
    {
      "x": 0,
      "y": 19,
      "z": -2,
      "name": "Rock_Shale"
    },
    {
      "x": 0,
      "y": 0,
      "z": -1,
      "name": "Rock_Shale"
    },
    {
      "x": 0,
      "y": 1,
      "z": -1,
      "name": "Rock_Shale"
    },
    {
      "x": 0,
      "y": 2,
      "z": -1,
      "name": "Rock_Shale_Stalactites_Small"
    },
    {
      "x": 0,
      "y": 8,
      "z": -1,
      "name": "Plant_Mushroom_Wall_White_Mycelium",
      "support": 15,
      "rotation": 2
    },
    {
      "x": 0,
      "y": 9,
      "z": -1,
      "name": "Rock_Shale"
    },
    {
      "x": 0,
      "y": 10,
      "z": -1,
      "name": "Rock_Shale"
    },
    {
      "x": 0,
      "y": 11,
      "z": -1,
      "name": "Rock_Shale"
    },
    {
      "x": 0,
      "y": 12,
      "z": -1,
      "name": "Rock_Shale"
    },
    {
      "x": 0,
      "y": 13,
      "z": -1,
      "name": "Rock_Shale"
    },
    {
      "x": 0,
      "y": 14,
      "z": -1,
      "name": "Rock_Shale"
    },
    {
      "x": 0,
      "y": 15,
      "z": -1,
      "name": "Rock_Shale"
    },
    {
      "x": 0,
      "y": 16,
      "z": -1,
      "name": "Rock_Shale"
    },
    {
      "x": 0,
      "y": 17,
      "z": -1,
      "name": "Rock_Shale"
    },
    {
      "x": 0,
      "y": 18,
      "z": -1,
      "name": "Rock_Shale"
    },
    {
      "x": 0,
      "y": 19,
      "z": -1,
      "name": "Rock_Shale"
    },
    {
      "x": 0,
      "y": 20,
      "z": -1,
      "name": "Rock_Shale"
    },
    {
      "x": 0,
      "y": 0,
      "z": 0,
      "name": "Rock_Shale"
    },
    {
      "x": 0,
      "y": 1,
      "z": 0,
      "name": "Rock_Shale"
    },
    {
      "x": 0,
      "y": 2,
      "z": 0,
      "name": "Plant_Mushroom_Block_White_Mycelium",
      "support": 15
    },
    {
      "x": 0,
      "y": 3,
      "z": 0,
      "name": "Plant_Crop_Mushroom_Funnel_Tainted"
    },
    {
      "x": 0,
      "y": 8,
      "z": 0,
      "name": "Wood_Giantwood_Trunk_Tainted_Full",
      "support": 15
    },
    {
      "x": 0,
      "y": 9,
      "z": 0,
      "name": "Wood_Giantwood_Trunk_Tainted_Full",
      "support": 15
    },
    {
      "x": 0,
      "y": 10,
      "z": 0,
      "name": "Wood_Giantwood_Trunk_Tainted_Full",
      "support": 15
    },
    {
      "x": 0,
      "y": 11,
      "z": 0,
      "name": "Wood_Giantwood_Trunk_Tainted_Full",
      "support": 15
    },
    {
      "x": 0,
      "y": 12,
      "z": 0,
      "name": "Wood_Giantwood_Trunk_Tainted_Full",
      "support": 15
    },
    {
      "x": 0,
      "y": 13,
      "z": 0,
      "name": "Wood_Giantwood_Trunk_Tainted_Full",
      "support": 15
    },
    {
      "x": 0,
      "y": 14,
      "z": 0,
      "name": "Wood_Giantwood_Trunk_Tainted_Full",
      "support": 15
    },
    {
      "x": 0,
      "y": 15,
      "z": 0,
      "name": "Wood_Giantwood_Trunk_Tainted_Full",
      "support": 15
    },
    {
      "x": 0,
      "y": 16,
      "z": 0,
      "name": "Wood_Giantwood_Trunk_Tainted_Full",
      "support": 15
    },
    {
      "x": 0,
      "y": 17,
      "z": 0,
      "name": "Rock_Shale"
    },
    {
      "x": 0,
      "y": 18,
      "z": 0,
      "name": "Rock_Shale"
    },
    {
      "x": 0,
      "y": 19,
      "z": 0,
      "name": "Rock_Shale"
    },
    {
      "x": 0,
      "y": 20,
      "z": 0,
      "name": "Rock_Shale"
    },
    {
      "x": 0,
      "y": 0,
      "z": 1,
      "name": "Rock_Shale"
    },
    {
      "x": 0,
      "y": 1,
      "z": 1,
      "name": "Wood_Giantwood_Trunk_Tainted_Full",
      "support": 15
    },
    {
      "x": 0,
      "y": 2,
      "z": 1,
      "name": "Rock_Shale"
    },
    {
      "x": 0,
      "y": 3,
      "z": 1,
      "name": "Rock_Shale"
    },
    {
      "x": 0,
      "y": 4,
      "z": 1,
      "name": "Rock_Shale"
    },
    {
      "x": 0,
      "y": 5,
      "z": 1,
      "name": "Plant_Mushroom_Rug_White_Mycelium",
      "support": 15
    },
    {
      "x": 0,
      "y": 6,
      "z": 1,
      "name": "Wood_Giantwood_Trunk_Tainted_Full",
      "support": 15
    },
    {
      "x": 0,
      "y": 7,
      "z": 1,
      "name": "Wood_Giantwood_Trunk_Tainted_Full",
      "support": 15
    },
    {
      "x": 0,
      "y": 8,
      "z": 1,
      "name": "Wood_Giantwood_Trunk_Tainted_Full",
      "support": 15
    },
    {
      "x": 0,
      "y": 9,
      "z": 1,
      "name": "Wood_Giantwood_Trunk_Tainted_Full",
      "support": 15
    },
    {
      "x": 0,
      "y": 10,
      "z": 1,
      "name": "Wood_Giantwood_Trunk_Tainted_Full",
      "support": 15
    },
    {
      "x": 0,
      "y": 11,
      "z": 1,
      "name": "Wood_Giantwood_Trunk_Tainted_Full",
      "support": 15
    },
    {
      "x": 0,
      "y": 12,
      "z": 1,
      "name": "Wood_Giantwood_Trunk_Tainted_Full",
      "support": 15
    },
    {
      "x": 0,
      "y": 13,
      "z": 1,
      "name": "Wood_Giantwood_Trunk_Tainted_Full",
      "support": 15
    },
    {
      "x": 0,
      "y": 14,
      "z": 1,
      "name": "Wood_Giantwood_Trunk_Tainted_Full",
      "support": 15
    },
    {
      "x": 0,
      "y": 15,
      "z": 1,
      "name": "Wood_Giantwood_Trunk_Tainted_Full",
      "support": 15
    },
    {
      "x": 0,
      "y": 16,
      "z": 1,
      "name": "Wood_Giantwood_Trunk_Tainted_Full",
      "support": 15
    },
    {
      "x": 0,
      "y": 17,
      "z": 1,
      "name": "Rock_Shale"
    },
    {
      "x": 0,
      "y": 18,
      "z": 1,
      "name": "Rock_Shale"
    },
    {
      "x": 0,
      "y": 19,
      "z": 1,
      "name": "Rock_Shale"
    },
    {
      "x": 0,
      "y": 20,
      "z": 1,
      "name": "Rock_Shale"
    },
    {
      "x": 0,
      "y": 0,
      "z": 2,
      "name": "Rock_Shale"
    },
    {
      "x": 0,
      "y": 1,
      "z": 2,
      "name": "Rock_Shale"
    },
    {
      "x": 0,
      "y": 2,
      "z": 2,
      "name": "Rock_Shale"
    },
    {
      "x": 0,
      "y": 3,
      "z": 2,
      "name": "Plant_Mushroom_Block_White_Mycelium",
      "support": 15
    },
    {
      "x": 0,
      "y": 4,
      "z": 2,
      "name": "Plant_Crop_Mushroom_Funnel_Tainted"
    },
    {
      "x": 0,
      "y": 7,
      "z": 2,
      "name": "Wood_Giantwood_Trunk_Tainted_Full",
      "support": 15
    },
    {
      "x": 0,
      "y": 8,
      "z": 2,
      "name": "Wood_Giantwood_Trunk_Tainted_Full",
      "support": 15
    },
    {
      "x": 0,
      "y": 9,
      "z": 2,
      "name": "Wood_Giantwood_Trunk_Tainted_Full",
      "support": 15
    },
    {
      "x": 0,
      "y": 10,
      "z": 2,
      "name": "Wood_Giantwood_Trunk_Tainted_Full",
      "support": 15
    },
    {
      "x": 0,
      "y": 11,
      "z": 2,
      "name": "Wood_Giantwood_Trunk_Tainted_Full",
      "support": 15
    },
    {
      "x": 0,
      "y": 12,
      "z": 2,
      "name": "Wood_Giantwood_Trunk_Tainted_Full",
      "support": 15
    },
    {
      "x": 0,
      "y": 13,
      "z": 2,
      "name": "Wood_Giantwood_Trunk_Tainted_Full",
      "support": 15
    },
    {
      "x": 0,
      "y": 14,
      "z": 2,
      "name": "Wood_Giantwood_Trunk_Tainted_Full",
      "support": 15
    },
    {
      "x": 0,
      "y": 15,
      "z": 2,
      "name": "Wood_Giantwood_Trunk_Tainted_Full",
      "support": 15
    },
    {
      "x": 0,
      "y": 16,
      "z": 2,
      "name": "Wood_Giantwood_Trunk_Tainted_Full",
      "support": 15
    },
    {
      "x": 0,
      "y": 17,
      "z": 2,
      "name": "Rock_Shale"
    },
    {
      "x": 0,
      "y": 18,
      "z": 2,
      "name": "Rock_Shale"
    },
    {
      "x": 0,
      "y": 19,
      "z": 2,
      "name": "Rock_Shale"
    },
    {
      "x": 0,
      "y": 20,
      "z": 2,
      "name": "Rock_Shale"
    },
    {
      "x": 0,
      "y": 0,
      "z": 3,
      "name": "Rock_Shale"
    },
    {
      "x": 0,
      "y": 1,
      "z": 3,
      "name": "Rock_Shale"
    },
    {
      "x": 0,
      "y": 2,
      "z": 3,
      "name": "Rock_Shale"
    },
    {
      "x": 0,
      "y": 3,
      "z": 3,
      "name": "Plant_Roots_Rug_Tainted",
      "support": 15
    },
    {
      "x": 0,
      "y": 8,
      "z": 3,
      "name": "Wood_Giantwood_Trunk_Tainted_Full",
      "support": 15
    },
    {
      "x": 0,
      "y": 9,
      "z": 3,
      "name": "Wood_Giantwood_Trunk_Tainted_Full",
      "support": 15
    },
    {
      "x": 0,
      "y": 10,
      "z": 3,
      "name": "Wood_Giantwood_Trunk_Tainted_Full",
      "support": 15
    },
    {
      "x": 0,
      "y": 11,
      "z": 3,
      "name": "Rock_Shale"
    },
    {
      "x": 0,
      "y": 12,
      "z": 3,
      "name": "Rock_Shale"
    },
    {
      "x": 0,
      "y": 13,
      "z": 3,
      "name": "Rock_Shale"
    },
    {
      "x": 0,
      "y": 14,
      "z": 3,
      "name": "Rock_Shale"
    },
    {
      "x": 0,
      "y": 15,
      "z": 3,
      "name": "Rock_Shale"
    },
    {
      "x": 0,
      "y": 16,
      "z": 3,
      "name": "Rock_Shale"
    },
    {
      "x": 0,
      "y": 17,
      "z": 3,
      "name": "Rock_Shale"
    },
    {
      "x": 0,
      "y": 18,
      "z": 3,
      "name": "Rock_Shale"
    },
    {
      "x": 0,
      "y": 19,
      "z": 3,
      "name": "Rock_Shale"
    },
    {
      "x": 0,
      "y": 0,
      "z": 4,
      "name": "Rock_Shale"
    },
    {
      "x": 0,
      "y": 1,
      "z": 4,
      "name": "Rock_Shale"
    },
    {
      "x": 0,
      "y": 2,
      "z": 4,
      "name": "Plant_Mushroom_Short_White_Mycelium",
      "support": 15
    },
    {
      "x": 0,
      "y": 8,
      "z": 4,
      "name": "Plant_Mushroom_Wall_White_Mycelium",
      "support": 15
    },
    {
      "x": 0,
      "y": 9,
      "z": 4,
      "name": "Plant_Mushroom_Wall_White_Mycelium",
      "support": 15
    },
    {
      "x": 0,
      "y": 10,
      "z": 4,
      "name": "Rock_Shale"
    },
    {
      "x": 0,
      "y": 11,
      "z": 4,
      "name": "Rock_Shale"
    },
    {
      "x": 0,
      "y": 12,
      "z": 4,
      "name": "Rock_Shale"
    },
    {
      "x": 0,
      "y": 13,
      "z": 4,
      "name": "Rock_Shale"
    },
    {
      "x": 0,
      "y": 14,
      "z": 4,
      "name": "Rock_Shale"
    },
    {
      "x": 0,
      "y": 15,
      "z": 4,
      "name": "Rock_Shale"
    },
    {
      "x": 0,
      "y": 16,
      "z": 4,
      "name": "Rock_Shale"
    },
    {
      "x": 0,
      "y": 17,
      "z": 4,
      "name": "Rock_Shale"
    },
    {
      "x": 0,
      "y": 18,
      "z": 4,
      "name": "Rock_Shale"
    },
    {
      "x": 0,
      "y": 19,
      "z": 4,
      "name": "Rock_Shale"
    },
    {
      "x": 0,
      "y": 0,
      "z": 5,
      "name": "Rock_Shale"
    },
    {
      "x": 0,
      "y": 1,
      "z": 5,
      "name": "Plant_Mushroom_Rug_White_Mycelium",
      "support": 15
    },
    {
      "x": 0,
      "y": 11,
      "z": 5,
      "name": "Rock_Shale"
    },
    {
      "x": 0,
      "y": 12,
      "z": 5,
      "name": "Rock_Shale"
    },
    {
      "x": 0,
      "y": 13,
      "z": 5,
      "name": "Rock_Shale"
    },
    {
      "x": 0,
      "y": 14,
      "z": 5,
      "name": "Rock_Shale"
    },
    {
      "x": 0,
      "y": 15,
      "z": 5,
      "name": "Rock_Shale"
    },
    {
      "x": 0,
      "y": 16,
      "z": 5,
      "name": "Rock_Shale"
    },
    {
      "x": 0,
      "y": 17,
      "z": 5,
      "name": "Rock_Shale"
    },
    {
      "x": 0,
      "y": 18,
      "z": 5,
      "name": "Rock_Shale"
    },
    {
      "x": 1,
      "y": 14,
      "z": -4,
      "name": "Rock_Shale"
    },
    {
      "x": 1,
      "y": 15,
      "z": -4,
      "name": "Rock_Shale"
    },
    {
      "x": 1,
      "y": 16,
      "z": -4,
      "name": "Rock_Shale"
    },
    {
      "x": 1,
      "y": 17,
      "z": -4,
      "name": "Rock_Shale"
    },
    {
      "x": 1,
      "y": 12,
      "z": -3,
      "name": "Rock_Shale"
    },
    {
      "x": 1,
      "y": 13,
      "z": -3,
      "name": "Rock_Shale"
    },
    {
      "x": 1,
      "y": 14,
      "z": -3,
      "name": "Rock_Shale"
    },
    {
      "x": 1,
      "y": 15,
      "z": -3,
      "name": "Rock_Shale"
    },
    {
      "x": 1,
      "y": 16,
      "z": -3,
      "name": "Rock_Shale"
    },
    {
      "x": 1,
      "y": 17,
      "z": -3,
      "name": "Rock_Shale"
    },
    {
      "x": 1,
      "y": 18,
      "z": -3,
      "name": "Rock_Shale"
    },
    {
      "x": 1,
      "y": 0,
      "z": -2,
      "name": "Rock_Shale"
    },
    {
      "x": 1,
      "y": 1,
      "z": -2,
      "name": "Rock_Shale"
    },
    {
      "x": 1,
      "y": 2,
      "z": -2,
      "name": "Plant_Mushroom_Short_White_Mycelium",
      "support": 15
    },
    {
      "x": 1,
      "y": 11,
      "z": -2,
      "name": "Rock_Shale"
    },
    {
      "x": 1,
      "y": 12,
      "z": -2,
      "name": "Rock_Shale"
    },
    {
      "x": 1,
      "y": 13,
      "z": -2,
      "name": "Rock_Shale"
    },
    {
      "x": 1,
      "y": 14,
      "z": -2,
      "name": "Rock_Shale"
    },
    {
      "x": 1,
      "y": 15,
      "z": -2,
      "name": "Rock_Shale"
    },
    {
      "x": 1,
      "y": 16,
      "z": -2,
      "name": "Rock_Shale"
    },
    {
      "x": 1,
      "y": 17,
      "z": -2,
      "name": "Rock_Shale"
    },
    {
      "x": 1,
      "y": 18,
      "z": -2,
      "name": "Rock_Shale"
    },
    {
      "x": 1,
      "y": 0,
      "z": -1,
      "name": "Rock_Shale"
    },
    {
      "x": 1,
      "y": 1,
      "z": -1,
      "name": "Rock_Shale"
    },
    {
      "x": 1,
      "y": 2,
      "z": -1,
      "name": "Rock_Shale"
    },
    {
      "x": 1,
      "y": 3,
      "z": -1,
      "name": "Plant_Mushroom_Rug_White_Mycelium",
      "support": 15
    },
    {
      "x": 1,
      "y": 9,
      "z": -1,
      "name": "Plant_Mushroom_Wall_White_Mycelium",
      "support": 15,
      "rotation": 2
    },
    {
      "x": 1,
      "y": 10,
      "z": -1,
      "name": "Rock_Shale"
    },
    {
      "x": 1,
      "y": 11,
      "z": -1,
      "name": "Rock_Shale"
    },
    {
      "x": 1,
      "y": 12,
      "z": -1,
      "name": "Rock_Shale"
    },
    {
      "x": 1,
      "y": 13,
      "z": -1,
      "name": "Rock_Shale"
    },
    {
      "x": 1,
      "y": 14,
      "z": -1,
      "name": "Rock_Shale"
    },
    {
      "x": 1,
      "y": 15,
      "z": -1,
      "name": "Rock_Shale"
    },
    {
      "x": 1,
      "y": 16,
      "z": -1,
      "name": "Rock_Shale"
    },
    {
      "x": 1,
      "y": 17,
      "z": -1,
      "name": "Rock_Shale"
    },
    {
      "x": 1,
      "y": 18,
      "z": -1,
      "name": "Rock_Shale"
    },
    {
      "x": 1,
      "y": 19,
      "z": -1,
      "name": "Rock_Shale"
    },
    {
      "x": 1,
      "y": 0,
      "z": 0,
      "name": "Rock_Shale"
    },
    {
      "x": 1,
      "y": 1,
      "z": 0,
      "name": "Rock_Shale"
    },
    {
      "x": 1,
      "y": 2,
      "z": 0,
      "name": "Rock_Shale"
    },
    {
      "x": 1,
      "y": 3,
      "z": 0,
      "name": "Rock_Shale"
    },
    {
      "x": 1,
      "y": 4,
      "z": 0,
      "name": "Plant_Mushroom_Rug_White_Mycelium",
      "support": 15
    },
    {
      "x": 1,
      "y": 7,
      "z": 0,
      "name": "Plant_Mushroom_Cave_White_Mycelium",
      "support": 15,
      "rotation": 8
    },
    {
      "x": 1,
      "y": 8,
      "z": 0,
      "name": "Wood_Giantwood_Trunk_Tainted_Full",
      "support": 15
    },
    {
      "x": 1,
      "y": 9,
      "z": 0,
      "name": "Wood_Giantwood_Trunk_Tainted_Full",
      "support": 15
    },
    {
      "x": 1,
      "y": 10,
      "z": 0,
      "name": "Rock_Shale"
    },
    {
      "x": 1,
      "y": 11,
      "z": 0,
      "name": "Rock_Shale"
    },
    {
      "x": 1,
      "y": 12,
      "z": 0,
      "name": "Rock_Shale"
    },
    {
      "x": 1,
      "y": 13,
      "z": 0,
      "name": "Rock_Shale"
    },
    {
      "x": 1,
      "y": 14,
      "z": 0,
      "name": "Rock_Shale"
    },
    {
      "x": 1,
      "y": 15,
      "z": 0,
      "name": "Rock_Shale"
    },
    {
      "x": 1,
      "y": 16,
      "z": 0,
      "name": "Rock_Shale"
    },
    {
      "x": 1,
      "y": 17,
      "z": 0,
      "name": "Rock_Shale"
    },
    {
      "x": 1,
      "y": 18,
      "z": 0,
      "name": "Rock_Shale"
    },
    {
      "x": 1,
      "y": 19,
      "z": 0,
      "name": "Rock_Shale"
    },
    {
      "x": 1,
      "y": 20,
      "z": 0,
      "name": "Rock_Shale"
    },
    {
      "x": 1,
      "y": 0,
      "z": 1,
      "name": "Rock_Shale"
    },
    {
      "x": 1,
      "y": 1,
      "z": 1,
      "name": "Wood_Giantwood_Trunk_Tainted_Full",
      "support": 15
    },
    {
      "x": 1,
      "y": 2,
      "z": 1,
      "name": "Rock_Shale"
    },
    {
      "x": 1,
      "y": 3,
      "z": 1,
      "name": "Wood_Giantwood_Trunk_Tainted_Full",
      "support": 15
    },
    {
      "x": 1,
      "y": 4,
      "z": 1,
      "name": "Wood_Giantwood_Trunk_Tainted_Full",
      "support": 15
    },
    {
      "x": 1,
      "y": 5,
      "z": 1,
      "name": "Wood_Giantwood_Trunk_Tainted_Full",
      "support": 15
    },
    {
      "x": 1,
      "y": 6,
      "z": 1,
      "name": "Wood_Giantwood_Trunk_Tainted_Full",
      "support": 15
    },
    {
      "x": 1,
      "y": 7,
      "z": 1,
      "name": "Wood_Giantwood_Trunk_Tainted_Full",
      "support": 15
    },
    {
      "x": 1,
      "y": 8,
      "z": 1,
      "name": "Wood_Giantwood_Trunk_Tainted_Full",
      "support": 15
    },
    {
      "x": 1,
      "y": 9,
      "z": 1,
      "name": "Wood_Giantwood_Trunk_Tainted_Full",
      "support": 15
    },
    {
      "x": 1,
      "y": 10,
      "z": 1,
      "name": "Wood_Giantwood_Trunk_Tainted_Full",
      "support": 15
    },
    {
      "x": 1,
      "y": 11,
      "z": 1,
      "name": "Wood_Giantwood_Trunk_Tainted_Full",
      "support": 15
    },
    {
      "x": 1,
      "y": 12,
      "z": 1,
      "name": "Wood_Giantwood_Trunk_Tainted_Full",
      "support": 15
    },
    {
      "x": 1,
      "y": 13,
      "z": 1,
      "name": "Wood_Giantwood_Trunk_Tainted_Full",
      "support": 15
    },
    {
      "x": 1,
      "y": 14,
      "z": 1,
      "name": "Wood_Giantwood_Trunk_Tainted_Full",
      "support": 15
    },
    {
      "x": 1,
      "y": 15,
      "z": 1,
      "name": "Wood_Giantwood_Trunk_Tainted_Full",
      "support": 15
    },
    {
      "x": 1,
      "y": 16,
      "z": 1,
      "name": "Wood_Giantwood_Trunk_Tainted_Full",
      "support": 15
    },
    {
      "x": 1,
      "y": 17,
      "z": 1,
      "name": "Rock_Shale"
    },
    {
      "x": 1,
      "y": 18,
      "z": 1,
      "name": "Rock_Shale"
    },
    {
      "x": 1,
      "y": 19,
      "z": 1,
      "name": "Rock_Shale"
    },
    {
      "x": 1,
      "y": 20,
      "z": 1,
      "name": "Rock_Shale"
    },
    {
      "x": 1,
      "y": 0,
      "z": 2,
      "name": "Rock_Shale"
    },
    {
      "x": 1,
      "y": 1,
      "z": 2,
      "name": "Rock_Shale"
    },
    {
      "x": 1,
      "y": 2,
      "z": 2,
      "name": "Rock_Shale"
    },
    {
      "x": 1,
      "y": 3,
      "z": 2,
      "name": "Rock_Shale"
    },
    {
      "x": 1,
      "y": 4,
      "z": 2,
      "name": "Wood_Giantwood_Trunk_Tainted_Full",
      "support": 15
    },
    {
      "x": 1,
      "y": 5,
      "z": 2,
      "name": "Wood_Giantwood_Trunk_Tainted_Full",
      "support": 15
    },
    {
      "x": 1,
      "y": 6,
      "z": 2,
      "name": "Wood_Giantwood_Trunk_Tainted_Full",
      "support": 15
    },
    {
      "x": 1,
      "y": 7,
      "z": 2,
      "name": "Wood_Giantwood_Trunk_Tainted_Full",
      "support": 15
    },
    {
      "x": 1,
      "y": 8,
      "z": 2,
      "name": "Wood_Giantwood_Trunk_Tainted_Full",
      "support": 15
    },
    {
      "x": 1,
      "y": 9,
      "z": 2,
      "name": "Wood_Giantwood_Trunk_Tainted_Full",
      "support": 15
    },
    {
      "x": 1,
      "y": 10,
      "z": 2,
      "name": "Wood_Giantwood_Trunk_Tainted_Full",
      "support": 15
    },
    {
      "x": 1,
      "y": 11,
      "z": 2,
      "name": "Wood_Giantwood_Trunk_Tainted_Full",
      "support": 15
    },
    {
      "x": 1,
      "y": 12,
      "z": 2,
      "name": "Rock_Shale"
    },
    {
      "x": 1,
      "y": 13,
      "z": 2,
      "name": "Rock_Shale"
    },
    {
      "x": 1,
      "y": 14,
      "z": 2,
      "name": "Rock_Shale"
    },
    {
      "x": 1,
      "y": 15,
      "z": 2,
      "name": "Rock_Shale"
    },
    {
      "x": 1,
      "y": 16,
      "z": 2,
      "name": "Rock_Shale"
    },
    {
      "x": 1,
      "y": 17,
      "z": 2,
      "name": "Rock_Shale"
    },
    {
      "x": 1,
      "y": 18,
      "z": 2,
      "name": "Rock_Shale"
    },
    {
      "x": 1,
      "y": 19,
      "z": 2,
      "name": "Rock_Shale"
    },
    {
      "x": 1,
      "y": 20,
      "z": 2,
      "name": "Rock_Shale"
    },
    {
      "x": 1,
      "y": 0,
      "z": 3,
      "name": "Rock_Shale"
    },
    {
      "x": 1,
      "y": 1,
      "z": 3,
      "name": "Rock_Shale"
    },
    {
      "x": 1,
      "y": 2,
      "z": 3,
      "name": "Rock_Shale"
    },
    {
      "x": 1,
      "y": 3,
      "z": 3,
      "name": "Rock_Shale"
    },
    {
      "x": 1,
      "y": 4,
      "z": 3,
      "name": "Plant_Mushroom_Rug_White_Mycelium",
      "support": 15
    },
    {
      "x": 1,
      "y": 8,
      "z": 3,
      "name": "Plant_Mushroom_Cave_White_Mycelium",
      "support": 15,
      "rotation": 8
    },
    {
      "x": 1,
      "y": 9,
      "z": 3,
      "name": "Wood_Giantwood_Trunk_Tainted_Full",
      "support": 15
    },
    {
      "x": 1,
      "y": 10,
      "z": 3,
      "name": "Wood_Giantwood_Trunk_Tainted_Full",
      "support": 15
    },
    {
      "x": 1,
      "y": 11,
      "z": 3,
      "name": "Wood_Giantwood_Trunk_Tainted_Full",
      "support": 15,
      "rotation": 4
    },
    {
      "x": 1,
      "y": 12,
      "z": 3,
      "name": "Rock_Shale"
    },
    {
      "x": 1,
      "y": 13,
      "z": 3,
      "name": "Rock_Shale"
    },
    {
      "x": 1,
      "y": 14,
      "z": 3,
      "name": "Rock_Shale"
    },
    {
      "x": 1,
      "y": 15,
      "z": 3,
      "name": "Rock_Shale"
    },
    {
      "x": 1,
      "y": 16,
      "z": 3,
      "name": "Rock_Shale"
    },
    {
      "x": 1,
      "y": 17,
      "z": 3,
      "name": "Rock_Shale"
    },
    {
      "x": 1,
      "y": 18,
      "z": 3,
      "name": "Rock_Shale"
    },
    {
      "x": 1,
      "y": 19,
      "z": 3,
      "name": "Rock_Shale"
    },
    {
      "x": 1,
      "y": 0,
      "z": 4,
      "name": "Rock_Shale"
    },
    {
      "x": 1,
      "y": 1,
      "z": 4,
      "name": "Rock_Shale"
    },
    {
      "x": 1,
      "y": 2,
      "z": 4,
      "name": "Plant_Roots_Rug_Tainted",
      "support": 15
    },
    {
      "x": 1,
      "y": 9,
      "z": 4,
      "name": "Plant_Mushroom_Wall_White_Mycelium",
      "support": 15
    },
    {
      "x": 1,
      "y": 10,
      "z": 4,
      "name": "Plant_Mushroom_Wall_White_Mycelium",
      "support": 15
    },
    {
      "x": 1,
      "y": 11,
      "z": 4,
      "name": "Rock_Shale"
    },
    {
      "x": 1,
      "y": 12,
      "z": 4,
      "name": "Rock_Shale"
    },
    {
      "x": 1,
      "y": 13,
      "z": 4,
      "name": "Rock_Shale"
    },
    {
      "x": 1,
      "y": 14,
      "z": 4,
      "name": "Rock_Shale"
    },
    {
      "x": 1,
      "y": 15,
      "z": 4,
      "name": "Rock_Shale"
    },
    {
      "x": 1,
      "y": 16,
      "z": 4,
      "name": "Rock_Shale"
    },
    {
      "x": 1,
      "y": 17,
      "z": 4,
      "name": "Rock_Shale"
    },
    {
      "x": 1,
      "y": 18,
      "z": 4,
      "name": "Rock_Shale"
    },
    {
      "x": 1,
      "y": 19,
      "z": 4,
      "name": "Rock_Shale"
    },
    {
      "x": 1,
      "y": 0,
      "z": 5,
      "name": "Rock_Shale"
    },
    {
      "x": 1,
      "y": 1,
      "z": 5,
      "name": "Plant_Mushroom_Short_White_Mycelium",
      "support": 15
    },
    {
      "x": 1,
      "y": 11,
      "z": 5,
      "name": "Rock_Shale"
    },
    {
      "x": 1,
      "y": 12,
      "z": 5,
      "name": "Rock_Shale"
    },
    {
      "x": 1,
      "y": 13,
      "z": 5,
      "name": "Rock_Shale"
    },
    {
      "x": 1,
      "y": 14,
      "z": 5,
      "name": "Rock_Shale"
    },
    {
      "x": 1,
      "y": 15,
      "z": 5,
      "name": "Rock_Shale"
    },
    {
      "x": 1,
      "y": 16,
      "z": 5,
      "name": "Rock_Shale"
    },
    {
      "x": 1,
      "y": 17,
      "z": 5,
      "name": "Rock_Shale"
    },
    {
      "x": 1,
      "y": 18,
      "z": 5,
      "name": "Rock_Shale"
    },
    {
      "x": 2,
      "y": 0,
      "z": -3,
      "name": "Rock_Shale"
    },
    {
      "x": 2,
      "y": 1,
      "z": -3,
      "name": "Plant_Mushroom_Short_White_Mycelium",
      "support": 15
    },
    {
      "x": 2,
      "y": 13,
      "z": -3,
      "name": "Rock_Shale"
    },
    {
      "x": 2,
      "y": 14,
      "z": -3,
      "name": "Rock_Shale"
    },
    {
      "x": 2,
      "y": 15,
      "z": -3,
      "name": "Rock_Shale"
    },
    {
      "x": 2,
      "y": 16,
      "z": -3,
      "name": "Rock_Shale"
    },
    {
      "x": 2,
      "y": 17,
      "z": -3,
      "name": "Rock_Shale"
    },
    {
      "x": 2,
      "y": 0,
      "z": -2,
      "name": "Rock_Shale"
    },
    {
      "x": 2,
      "y": 1,
      "z": -2,
      "name": "Rock_Shale_Stalactites_Large"
    },
    {
      "x": 2,
      "y": 2,
      "z": -2,
      "name": "Rock_Shale_Stalactites_Large",
      "filler": 1024
    },
    {
      "x": 2,
      "y": 12,
      "z": -2,
      "name": "Rock_Shale"
    },
    {
      "x": 2,
      "y": 13,
      "z": -2,
      "name": "Rock_Shale"
    },
    {
      "x": 2,
      "y": 14,
      "z": -2,
      "name": "Rock_Shale"
    },
    {
      "x": 2,
      "y": 15,
      "z": -2,
      "name": "Rock_Shale"
    },
    {
      "x": 2,
      "y": 16,
      "z": -2,
      "name": "Rock_Shale"
    },
    {
      "x": 2,
      "y": 17,
      "z": -2,
      "name": "Rock_Shale"
    },
    {
      "x": 2,
      "y": 18,
      "z": -2,
      "name": "Rock_Shale"
    },
    {
      "x": 2,
      "y": 0,
      "z": -1,
      "name": "Rock_Shale"
    },
    {
      "x": 2,
      "y": 1,
      "z": -1,
      "name": "Rock_Shale"
    },
    {
      "x": 2,
      "y": 2,
      "z": -1,
      "name": "Rock_Shale"
    },
    {
      "x": 2,
      "y": 3,
      "z": -1,
      "name": "Plant_Roots_Rug_Tainted",
      "support": 15
    },
    {
      "x": 2,
      "y": 11,
      "z": -1,
      "name": "Rock_Shale"
    },
    {
      "x": 2,
      "y": 12,
      "z": -1,
      "name": "Rock_Shale"
    },
    {
      "x": 2,
      "y": 13,
      "z": -1,
      "name": "Rock_Shale"
    },
    {
      "x": 2,
      "y": 14,
      "z": -1,
      "name": "Rock_Shale"
    },
    {
      "x": 2,
      "y": 15,
      "z": -1,
      "name": "Rock_Shale"
    },
    {
      "x": 2,
      "y": 16,
      "z": -1,
      "name": "Rock_Shale"
    },
    {
      "x": 2,
      "y": 17,
      "z": -1,
      "name": "Rock_Shale"
    },
    {
      "x": 2,
      "y": 18,
      "z": -1,
      "name": "Rock_Shale"
    },
    {
      "x": 2,
      "y": 19,
      "z": -1,
      "name": "Rock_Shale"
    },
    {
      "x": 2,
      "y": 0,
      "z": 0,
      "name": "Wood_Giantwood_Trunk_Tainted_Full",
      "support": 15
    },
    {
      "x": 2,
      "y": 1,
      "z": 0,
      "name": "Rock_Shale"
    },
    {
      "x": 2,
      "y": 2,
      "z": 0,
      "name": "Rock_Shale"
    },
    {
      "x": 2,
      "y": 3,
      "z": 0,
      "name": "Wood_Giantwood_Trunk_Tainted_Full",
      "support": 15
    },
    {
      "x": 2,
      "y": 4,
      "z": 0,
      "name": "Plant_Roots_Rug_Tainted",
      "support": 15
    },
    {
      "x": 2,
      "y": 8,
      "z": 0,
      "name": "Plant_Mushroom_Wall_White_Mycelium",
      "support": 15,
      "rotation": 1
    },
    {
      "x": 2,
      "y": 9,
      "z": 0,
      "name": "Plant_Mushroom_Wall_White_Mycelium",
      "support": 15,
      "rotation": 1
    },
    {
      "x": 2,
      "y": 10,
      "z": 0,
      "name": "Rock_Shale"
    },
    {
      "x": 2,
      "y": 11,
      "z": 0,
      "name": "Rock_Shale"
    },
    {
      "x": 2,
      "y": 12,
      "z": 0,
      "name": "Rock_Shale"
    },
    {
      "x": 2,
      "y": 13,
      "z": 0,
      "name": "Rock_Shale"
    },
    {
      "x": 2,
      "y": 14,
      "z": 0,
      "name": "Rock_Shale"
    },
    {
      "x": 2,
      "y": 15,
      "z": 0,
      "name": "Rock_Shale"
    },
    {
      "x": 2,
      "y": 16,
      "z": 0,
      "name": "Rock_Shale"
    },
    {
      "x": 2,
      "y": 17,
      "z": 0,
      "name": "Rock_Shale"
    },
    {
      "x": 2,
      "y": 18,
      "z": 0,
      "name": "Rock_Shale"
    },
    {
      "x": 2,
      "y": 19,
      "z": 0,
      "name": "Rock_Shale"
    },
    {
      "x": 2,
      "y": 20,
      "z": 0,
      "name": "Rock_Shale"
    },
    {
      "x": 2,
      "y": 0,
      "z": 1,
      "name": "Rock_Shale"
    },
    {
      "x": 2,
      "y": 1,
      "z": 1,
      "name": "Rock_Shale"
    },
    {
      "x": 2,
      "y": 2,
      "z": 1,
      "name": "Wood_Giantwood_Trunk_Tainted_Full",
      "support": 15
    },
    {
      "x": 2,
      "y": 3,
      "z": 1,
      "name": "Wood_Giantwood_Trunk_Tainted_Full",
      "support": 15
    },
    {
      "x": 2,
      "y": 4,
      "z": 1,
      "name": "Wood_Giantwood_Trunk_Tainted_Full",
      "support": 15
    },
    {
      "x": 2,
      "y": 5,
      "z": 1,
      "name": "Wood_Giantwood_Trunk_Tainted_Full",
      "support": 15
    },
    {
      "x": 2,
      "y": 6,
      "z": 1,
      "name": "Wood_Giantwood_Trunk_Tainted_Full",
      "support": 15
    },
    {
      "x": 2,
      "y": 7,
      "z": 1,
      "name": "Plant_Roots_Rug_Tainted",
      "support": 15
    },
    {
      "x": 2,
      "y": 9,
      "z": 1,
      "name": "Rock_Shale"
    },
    {
      "x": 2,
      "y": 10,
      "z": 1,
      "name": "Rock_Shale"
    },
    {
      "x": 2,
      "y": 11,
      "z": 1,
      "name": "Rock_Shale"
    },
    {
      "x": 2,
      "y": 12,
      "z": 1,
      "name": "Rock_Shale"
    },
    {
      "x": 2,
      "y": 13,
      "z": 1,
      "name": "Rock_Shale"
    },
    {
      "x": 2,
      "y": 14,
      "z": 1,
      "name": "Rock_Shale"
    },
    {
      "x": 2,
      "y": 15,
      "z": 1,
      "name": "Rock_Shale"
    },
    {
      "x": 2,
      "y": 16,
      "z": 1,
      "name": "Rock_Shale"
    },
    {
      "x": 2,
      "y": 17,
      "z": 1,
      "name": "Rock_Shale"
    },
    {
      "x": 2,
      "y": 18,
      "z": 1,
      "name": "Rock_Shale"
    },
    {
      "x": 2,
      "y": 19,
      "z": 1,
      "name": "Rock_Shale"
    },
    {
      "x": 2,
      "y": 20,
      "z": 1,
      "name": "Rock_Shale"
    },
    {
      "x": 2,
      "y": 0,
      "z": 2,
      "name": "Rock_Shale"
    },
    {
      "x": 2,
      "y": 1,
      "z": 2,
      "name": "Rock_Shale"
    },
    {
      "x": 2,
      "y": 2,
      "z": 2,
      "name": "Wood_Giantwood_Trunk_Tainted_Full",
      "support": 15
    },
    {
      "x": 2,
      "y": 3,
      "z": 2,
      "name": "Wood_Giantwood_Trunk_Tainted_Full",
      "support": 15
    },
    {
      "x": 2,
      "y": 4,
      "z": 2,
      "name": "Wood_Giantwood_Trunk_Tainted_Full",
      "support": 15
    },
    {
      "x": 2,
      "y": 5,
      "z": 2,
      "name": "Plant_Roots_Rug_Tainted",
      "support": 15
    },
    {
      "x": 2,
      "y": 8,
      "z": 2,
      "name": "Plant_Mushroom_Wall_White_Mycelium",
      "support": 15,
      "rotation": 1
    },
    {
      "x": 2,
      "y": 9,
      "z": 2,
      "name": "Plant_Mushroom_Wall_White_Mycelium",
      "support": 15,
      "rotation": 1
    },
    {
      "x": 2,
      "y": 10,
      "z": 2,
      "name": "Rock_Shale"
    },
    {
      "x": 2,
      "y": 11,
      "z": 2,
      "name": "Rock_Shale"
    },
    {
      "x": 2,
      "y": 12,
      "z": 2,
      "name": "Rock_Shale"
    },
    {
      "x": 2,
      "y": 13,
      "z": 2,
      "name": "Rock_Shale"
    },
    {
      "x": 2,
      "y": 14,
      "z": 2,
      "name": "Rock_Shale"
    },
    {
      "x": 2,
      "y": 15,
      "z": 2,
      "name": "Rock_Shale"
    },
    {
      "x": 2,
      "y": 16,
      "z": 2,
      "name": "Rock_Shale"
    },
    {
      "x": 2,
      "y": 17,
      "z": 2,
      "name": "Rock_Shale"
    },
    {
      "x": 2,
      "y": 18,
      "z": 2,
      "name": "Rock_Shale"
    },
    {
      "x": 2,
      "y": 19,
      "z": 2,
      "name": "Rock_Shale"
    },
    {
      "x": 2,
      "y": 0,
      "z": 3,
      "name": "Rock_Shale"
    },
    {
      "x": 2,
      "y": 1,
      "z": 3,
      "name": "Rock_Shale"
    },
    {
      "x": 2,
      "y": 2,
      "z": 3,
      "name": "Rock_Shale_Stalactites_Small"
    },
    {
      "x": 2,
      "y": 9,
      "z": 3,
      "name": "Plant_Mushroom_Wall_White_Mycelium",
      "support": 15,
      "rotation": 1
    },
    {
      "x": 2,
      "y": 10,
      "z": 3,
      "name": "Plant_Mushroom_Wall_White_Mycelium",
      "support": 15,
      "rotation": 1
    },
    {
      "x": 2,
      "y": 11,
      "z": 3,
      "name": "Rock_Shale"
    },
    {
      "x": 2,
      "y": 12,
      "z": 3,
      "name": "Rock_Shale"
    },
    {
      "x": 2,
      "y": 13,
      "z": 3,
      "name": "Rock_Shale"
    },
    {
      "x": 2,
      "y": 14,
      "z": 3,
      "name": "Rock_Shale"
    },
    {
      "x": 2,
      "y": 15,
      "z": 3,
      "name": "Rock_Shale"
    },
    {
      "x": 2,
      "y": 16,
      "z": 3,
      "name": "Rock_Shale"
    },
    {
      "x": 2,
      "y": 17,
      "z": 3,
      "name": "Rock_Shale"
    },
    {
      "x": 2,
      "y": 18,
      "z": 3,
      "name": "Rock_Shale"
    },
    {
      "x": 2,
      "y": 19,
      "z": 3,
      "name": "Rock_Shale"
    },
    {
      "x": 2,
      "y": 0,
      "z": 4,
      "name": "Rock_Shale"
    },
    {
      "x": 2,
      "y": 1,
      "z": 4,
      "name": "Plant_Mushroom_Rug_White_Mycelium",
      "support": 15
    },
    {
      "x": 2,
      "y": 9,
      "z": 4,
      "name": "Rock_Shale_Stalactites_Large",
      "filler": 31744,
      "rotation": 8
    },
    {
      "x": 2,
      "y": 10,
      "z": 4,
      "name": "Rock_Shale_Stalactites_Large",
      "rotation": 8
    },
    {
      "x": 2,
      "y": 11,
      "z": 4,
      "name": "Rock_Shale"
    },
    {
      "x": 2,
      "y": 12,
      "z": 4,
      "name": "Rock_Shale"
    },
    {
      "x": 2,
      "y": 13,
      "z": 4,
      "name": "Rock_Shale"
    },
    {
      "x": 2,
      "y": 14,
      "z": 4,
      "name": "Rock_Shale"
    },
    {
      "x": 2,
      "y": 15,
      "z": 4,
      "name": "Rock_Shale"
    },
    {
      "x": 2,
      "y": 16,
      "z": 4,
      "name": "Rock_Shale"
    },
    {
      "x": 2,
      "y": 17,
      "z": 4,
      "name": "Rock_Shale"
    },
    {
      "x": 2,
      "y": 18,
      "z": 4,
      "name": "Rock_Shale"
    },
    {
      "x": 2,
      "y": 12,
      "z": 5,
      "name": "Rock_Shale"
    },
    {
      "x": 2,
      "y": 13,
      "z": 5,
      "name": "Rock_Shale"
    },
    {
      "x": 2,
      "y": 14,
      "z": 5,
      "name": "Rock_Shale"
    },
    {
      "x": 2,
      "y": 15,
      "z": 5,
      "name": "Rock_Shale"
    },
    {
      "x": 2,
      "y": 16,
      "z": 5,
      "name": "Rock_Shale"
    },
    {
      "x": 2,
      "y": 17,
      "z": 5,
      "name": "Rock_Shale"
    },
    {
      "x": 2,
      "y": 18,
      "z": 5,
      "name": "Rock_Shale"
    },
    {
      "x": 3,
      "y": 0,
      "z": -3,
      "name": "Rock_Shale"
    },
    {
      "x": 3,
      "y": 1,
      "z": -3,
      "name": "Plant_Mushroom_Rug_White_Mycelium",
      "support": 15
    },
    {
      "x": 3,
      "y": 0,
      "z": -2,
      "name": "Plant_Mushroom_Block_White_Mycelium",
      "support": 15
    },
    {
      "x": 3,
      "y": 1,
      "z": -2,
      "name": "Plant_Crop_Mushroom_Funnel_Tainted"
    },
    {
      "x": 3,
      "y": 13,
      "z": -2,
      "name": "Rock_Shale"
    },
    {
      "x": 3,
      "y": 14,
      "z": -2,
      "name": "Rock_Shale"
    },
    {
      "x": 3,
      "y": 15,
      "z": -2,
      "name": "Rock_Shale"
    },
    {
      "x": 3,
      "y": 16,
      "z": -2,
      "name": "Rock_Shale"
    },
    {
      "x": 3,
      "y": 17,
      "z": -2,
      "name": "Rock_Shale"
    },
    {
      "x": 3,
      "y": 18,
      "z": -2,
      "name": "Rock_Shale"
    },
    {
      "x": 3,
      "y": 0,
      "z": -1,
      "name": "Rock_Shale"
    },
    {
      "x": 3,
      "y": 1,
      "z": -1,
      "name": "Rock_Shale"
    },
    {
      "x": 3,
      "y": 2,
      "z": -1,
      "name": "Plant_Roots_Rug_Tainted",
      "support": 15
    },
    {
      "x": 3,
      "y": 12,
      "z": -1,
      "name": "Rock_Shale"
    },
    {
      "x": 3,
      "y": 13,
      "z": -1,
      "name": "Rock_Shale"
    },
    {
      "x": 3,
      "y": 14,
      "z": -1,
      "name": "Rock_Shale"
    },
    {
      "x": 3,
      "y": 15,
      "z": -1,
      "name": "Rock_Shale"
    },
    {
      "x": 3,
      "y": 16,
      "z": -1,
      "name": "Rock_Shale"
    },
    {
      "x": 3,
      "y": 17,
      "z": -1,
      "name": "Rock_Shale"
    },
    {
      "x": 3,
      "y": 18,
      "z": -1,
      "name": "Rock_Shale"
    },
    {
      "x": 3,
      "y": 19,
      "z": -1,
      "name": "Rock_Shale"
    },
    {
      "x": 3,
      "y": 0,
      "z": 0,
      "name": "Rock_Shale"
    },
    {
      "x": 3,
      "y": 1,
      "z": 0,
      "name": "Rock_Shale"
    },
    {
      "x": 3,
      "y": 2,
      "z": 0,
      "name": "Wood_Giantwood_Trunk_Tainted_Full",
      "support": 15
    },
    {
      "x": 3,
      "y": 3,
      "z": 0,
      "name": "Plant_Mushroom_Rug_White_Mycelium",
      "support": 15
    },
    {
      "x": 3,
      "y": 11,
      "z": 0,
      "name": "Rock_Shale"
    },
    {
      "x": 3,
      "y": 12,
      "z": 0,
      "name": "Rock_Shale"
    },
    {
      "x": 3,
      "y": 13,
      "z": 0,
      "name": "Rock_Shale"
    },
    {
      "x": 3,
      "y": 14,
      "z": 0,
      "name": "Rock_Shale"
    },
    {
      "x": 3,
      "y": 15,
      "z": 0,
      "name": "Rock_Shale"
    },
    {
      "x": 3,
      "y": 16,
      "z": 0,
      "name": "Rock_Shale"
    },
    {
      "x": 3,
      "y": 17,
      "z": 0,
      "name": "Rock_Shale"
    },
    {
      "x": 3,
      "y": 18,
      "z": 0,
      "name": "Rock_Shale"
    },
    {
      "x": 3,
      "y": 19,
      "z": 0,
      "name": "Rock_Shale"
    },
    {
      "x": 3,
      "y": 0,
      "z": 1,
      "name": "Rock_Shale"
    },
    {
      "x": 3,
      "y": 1,
      "z": 1,
      "name": "Wood_Giantwood_Trunk_Tainted_Full",
      "support": 15
    },
    {
      "x": 3,
      "y": 2,
      "z": 1,
      "name": "Wood_Giantwood_Trunk_Tainted_Full",
      "support": 15
    },
    {
      "x": 3,
      "y": 3,
      "z": 1,
      "name": "Wood_Giantwood_Trunk_Tainted_Full",
      "support": 15
    },
    {
      "x": 3,
      "y": 4,
      "z": 1,
      "name": "Wood_Giantwood_Trunk_Tainted_Full",
      "support": 15
    },
    {
      "x": 3,
      "y": 5,
      "z": 1,
      "name": "Plant_Mushroom_Rug_White_Mycelium",
      "support": 15
    },
    {
      "x": 3,
      "y": 10,
      "z": 1,
      "name": "Rock_Shale"
    },
    {
      "x": 3,
      "y": 11,
      "z": 1,
      "name": "Rock_Shale"
    },
    {
      "x": 3,
      "y": 12,
      "z": 1,
      "name": "Rock_Shale"
    },
    {
      "x": 3,
      "y": 13,
      "z": 1,
      "name": "Rock_Shale"
    },
    {
      "x": 3,
      "y": 14,
      "z": 1,
      "name": "Rock_Shale"
    },
    {
      "x": 3,
      "y": 15,
      "z": 1,
      "name": "Rock_Shale"
    },
    {
      "x": 3,
      "y": 16,
      "z": 1,
      "name": "Rock_Shale"
    },
    {
      "x": 3,
      "y": 17,
      "z": 1,
      "name": "Rock_Shale"
    },
    {
      "x": 3,
      "y": 18,
      "z": 1,
      "name": "Rock_Shale"
    },
    {
      "x": 3,
      "y": 19,
      "z": 1,
      "name": "Rock_Shale"
    },
    {
      "x": 3,
      "y": 0,
      "z": 2,
      "name": "Rock_Shale"
    },
    {
      "x": 3,
      "y": 1,
      "z": 2,
      "name": "Rock_Shale"
    },
    {
      "x": 3,
      "y": 2,
      "z": 2,
      "name": "Rock_Shale"
    },
    {
      "x": 3,
      "y": 3,
      "z": 2,
      "name": "Plant_Mushroom_Rug_White_Mycelium",
      "support": 15
    },
    {
      "x": 3,
      "y": 11,
      "z": 2,
      "name": "Rock_Shale"
    },
    {
      "x": 3,
      "y": 12,
      "z": 2,
      "name": "Rock_Shale"
    },
    {
      "x": 3,
      "y": 13,
      "z": 2,
      "name": "Rock_Shale"
    },
    {
      "x": 3,
      "y": 14,
      "z": 2,
      "name": "Rock_Shale"
    },
    {
      "x": 3,
      "y": 15,
      "z": 2,
      "name": "Rock_Shale"
    },
    {
      "x": 3,
      "y": 16,
      "z": 2,
      "name": "Rock_Shale"
    },
    {
      "x": 3,
      "y": 17,
      "z": 2,
      "name": "Rock_Shale"
    },
    {
      "x": 3,
      "y": 18,
      "z": 2,
      "name": "Rock_Shale"
    },
    {
      "x": 3,
      "y": 19,
      "z": 2,
      "name": "Rock_Shale"
    },
    {
      "x": 3,
      "y": 0,
      "z": 3,
      "name": "Rock_Shale"
    },
    {
      "x": 3,
      "y": 1,
      "z": 3,
      "name": "Rock_Shale"
    },
    {
      "x": 3,
      "y": 2,
      "z": 3,
      "name": "Plant_Mushroom_Rug_White_Mycelium",
      "support": 15
    },
    {
      "x": 3,
      "y": 12,
      "z": 3,
      "name": "Rock_Shale"
    },
    {
      "x": 3,
      "y": 13,
      "z": 3,
      "name": "Rock_Shale"
    },
    {
      "x": 3,
      "y": 14,
      "z": 3,
      "name": "Rock_Shale"
    },
    {
      "x": 3,
      "y": 15,
      "z": 3,
      "name": "Rock_Shale"
    },
    {
      "x": 3,
      "y": 16,
      "z": 3,
      "name": "Rock_Shale"
    },
    {
      "x": 3,
      "y": 17,
      "z": 3,
      "name": "Rock_Shale"
    },
    {
      "x": 3,
      "y": 18,
      "z": 3,
      "name": "Rock_Shale"
    },
    {
      "x": 3,
      "y": 0,
      "z": 4,
      "name": "Rock_Shale"
    },
    {
      "x": 3,
      "y": 1,
      "z": 4,
      "name": "Plant_Mushroom_Short_White_Mycelium",
      "support": 15
    },
    {
      "x": 3,
      "y": 12,
      "z": 4,
      "name": "Rock_Shale"
    },
    {
      "x": 3,
      "y": 13,
      "z": 4,
      "name": "Rock_Shale"
    },
    {
      "x": 3,
      "y": 14,
      "z": 4,
      "name": "Rock_Shale"
    },
    {
      "x": 3,
      "y": 15,
      "z": 4,
      "name": "Rock_Shale"
    },
    {
      "x": 3,
      "y": 16,
      "z": 4,
      "name": "Rock_Shale"
    },
    {
      "x": 3,
      "y": 17,
      "z": 4,
      "name": "Rock_Shale"
    },
    {
      "x": 3,
      "y": 15,
      "z": 5,
      "name": "Rock_Shale"
    },
    {
      "x": 3,
      "y": 16,
      "z": 5,
      "name": "Rock_Shale"
    },
    {
      "x": 4,
      "y": 0,
      "z": -2,
      "name": "Rock_Shale"
    },
    {
      "x": 4,
      "y": 1,
      "z": -2,
      "name": "Plant_Mushroom_Short_White_Mycelium",
      "support": 15
    },
    {
      "x": 4,
      "y": 0,
      "z": -1,
      "name": "Rock_Shale"
    },
    {
      "x": 4,
      "y": 1,
      "z": -1,
      "name": "Rock_Shale"
    },
    {
      "x": 4,
      "y": 2,
      "z": -1,
      "name": "Rock_Shale_Stalactites_Small"
    },
    {
      "x": 4,
      "y": 14,
      "z": -1,
      "name": "Rock_Shale"
    },
    {
      "x": 4,
      "y": 15,
      "z": -1,
      "name": "Rock_Shale"
    },
    {
      "x": 4,
      "y": 16,
      "z": -1,
      "name": "Rock_Shale"
    },
    {
      "x": 4,
      "y": 17,
      "z": -1,
      "name": "Rock_Shale"
    },
    {
      "x": 4,
      "y": 0,
      "z": 0,
      "name": "Rock_Shale"
    },
    {
      "x": 4,
      "y": 1,
      "z": 0,
      "name": "Rock_Shale"
    },
    {
      "x": 4,
      "y": 2,
      "z": 0,
      "name": "Rock_Shale"
    },
    {
      "x": 4,
      "y": 3,
      "z": 0,
      "name": "Rock_Shale"
    },
    {
      "x": 4,
      "y": 4,
      "z": 0,
      "name": "Rock_Shale_Stalactites_Large"
    },
    {
      "x": 4,
      "y": 5,
      "z": 0,
      "name": "Rock_Shale_Stalactites_Large",
      "filler": 1024
    },
    {
      "x": 4,
      "y": 12,
      "z": 0,
      "name": "Rock_Shale_Stalactites_Small",
      "rotation": 8
    },
    {
      "x": 4,
      "y": 13,
      "z": 0,
      "name": "Rock_Shale"
    },
    {
      "x": 4,
      "y": 14,
      "z": 0,
      "name": "Rock_Shale"
    },
    {
      "x": 4,
      "y": 15,
      "z": 0,
      "name": "Rock_Shale"
    },
    {
      "x": 4,
      "y": 16,
      "z": 0,
      "name": "Rock_Shale"
    },
    {
      "x": 4,
      "y": 17,
      "z": 0,
      "name": "Rock_Shale"
    },
    {
      "x": 4,
      "y": 18,
      "z": 0,
      "name": "Rock_Shale"
    },
    {
      "x": 4,
      "y": 0,
      "z": 1,
      "name": "Rock_Shale"
    },
    {
      "x": 4,
      "y": 1,
      "z": 1,
      "name": "Rock_Shale"
    },
    {
      "x": 4,
      "y": 2,
      "z": 1,
      "name": "Wood_Giantwood_Trunk_Tainted_Full",
      "support": 15
    },
    {
      "x": 4,
      "y": 3,
      "z": 1,
      "name": "Plant_Roots_Rug_Tainted",
      "support": 15
    },
    {
      "x": 4,
      "y": 12,
      "z": 1,
      "name": "Rock_Shale"
    },
    {
      "x": 4,
      "y": 13,
      "z": 1,
      "name": "Rock_Shale"
    },
    {
      "x": 4,
      "y": 14,
      "z": 1,
      "name": "Rock_Shale"
    },
    {
      "x": 4,
      "y": 15,
      "z": 1,
      "name": "Rock_Shale"
    },
    {
      "x": 4,
      "y": 16,
      "z": 1,
      "name": "Rock_Shale"
    },
    {
      "x": 4,
      "y": 17,
      "z": 1,
      "name": "Rock_Shale"
    },
    {
      "x": 4,
      "y": 18,
      "z": 1,
      "name": "Rock_Shale"
    },
    {
      "x": 4,
      "y": 0,
      "z": 2,
      "name": "Rock_Shale"
    },
    {
      "x": 4,
      "y": 1,
      "z": 2,
      "name": "Plant_Mushroom_Block_White_Mycelium",
      "support": 15
    },
    {
      "x": 4,
      "y": 2,
      "z": 2,
      "name": "Plant_Crop_Mushroom_Funnel_Tainted"
    },
    {
      "x": 4,
      "y": 12,
      "z": 2,
      "name": "Rock_Shale"
    },
    {
      "x": 4,
      "y": 13,
      "z": 2,
      "name": "Rock_Shale"
    },
    {
      "x": 4,
      "y": 14,
      "z": 2,
      "name": "Rock_Shale"
    },
    {
      "x": 4,
      "y": 15,
      "z": 2,
      "name": "Rock_Shale"
    },
    {
      "x": 4,
      "y": 16,
      "z": 2,
      "name": "Rock_Shale"
    },
    {
      "x": 4,
      "y": 17,
      "z": 2,
      "name": "Rock_Shale"
    },
    {
      "x": 4,
      "y": 18,
      "z": 2,
      "name": "Rock_Shale"
    },
    {
      "x": 4,
      "y": 0,
      "z": 3,
      "name": "Rock_Shale"
    },
    {
      "x": 4,
      "y": 1,
      "z": 3,
      "name": "Plant_Roots_Rug_Tainted",
      "support": 15
    },
    {
      "x": 4,
      "y": 14,
      "z": 3,
      "name": "Rock_Shale"
    },
    {
      "x": 4,
      "y": 15,
      "z": 3,
      "name": "Rock_Shale"
    },
    {
      "x": 4,
      "y": 16,
      "z": 3,
      "name": "Rock_Shale"
    },
    {
      "x": 4,
      "y": 17,
      "z": 3,
      "name": "Rock_Shale"
    },
    {
      "x": 4,
      "y": 18,
      "z": 3,
      "name": "Rock_Shale"
    },
    {
      "x": 4,
      "y": 15,
      "z": 4,
      "name": "Rock_Shale"
    },
    {
      "x": 4,
      "y": 16,
      "z": 4,
      "name": "Rock_Shale"
    },
    {
      "x": 4,
      "y": 17,
      "z": 4,
      "name": "Rock_Shale"
    },
    {
      "x": 5,
      "y": 0,
      "z": -1,
      "name": "Rock_Shale"
    },
    {
      "x": 5,
      "y": 1,
      "z": -1,
      "name": "Plant_Mushroom_Rug_White_Mycelium",
      "support": 15
    },
    {
      "x": 5,
      "y": 0,
      "z": 0,
      "name": "Rock_Shale"
    },
    {
      "x": 5,
      "y": 1,
      "z": 0,
      "name": "Rock_Shale"
    },
    {
      "x": 5,
      "y": 2,
      "z": 0,
      "name": "Plant_Roots_Rug_Tainted",
      "support": 15
    },
    {
      "x": 5,
      "y": 0,
      "z": 1,
      "name": "Rock_Shale"
    },
    {
      "x": 5,
      "y": 1,
      "z": 1,
      "name": "Rock_Shale_Stalactites_Large"
    },
    {
      "x": 5,
      "y": 2,
      "z": 1,
      "name": "Rock_Shale_Stalactites_Large",
      "filler": 1024
    },
    {
      "x": 5,
      "y": 0,
      "z": 2,
      "name": "Rock_Shale"
    },
    {
      "x": 5,
      "y": 1,
      "z": 2,
      "name": "Plant_Mushroom_Rug_White_Mycelium",
      "support": 15
    },
    {
      "x": 6,
      "y": 0,
      "z": 0,
      "name": "Rock_Shale"
    },
    {
      "x": 6,
      "y": 1,
      "z": 0,
      "name": "Plant_Mushroom_Short_White_Mycelium",
      "support": 15
    }
  ],
  "fluids": [
    {
      "x": -5,
      "y": 16,
      "z": -1,
      "name": "Empty",
      "level": 0
    },
    {
      "x": -5,
      "y": 17,
      "z": -1,
      "name": "Empty",
      "level": 0
    },
    {
      "x": -5,
      "y": 14,
      "z": 0,
      "name": "Empty",
      "level": 0
    },
    {
      "x": -5,
      "y": 15,
      "z": 0,
      "name": "Empty",
      "level": 0
    },
    {
      "x": -5,
      "y": 16,
      "z": 0,
      "name": "Empty",
      "level": 0
    },
    {
      "x": -5,
      "y": 17,
      "z": 0,
      "name": "Empty",
      "level": 0
    },
    {
      "x": -5,
      "y": 18,
      "z": 0,
      "name": "Empty",
      "level": 0
    },
    {
      "x": -5,
      "y": 13,
      "z": 1,
      "name": "Empty",
      "level": 0
    },
    {
      "x": -5,
      "y": 14,
      "z": 1,
      "name": "Empty",
      "level": 0
    },
    {
      "x": -5,
      "y": 15,
      "z": 1,
      "name": "Empty",
      "level": 0
    },
    {
      "x": -5,
      "y": 16,
      "z": 1,
      "name": "Empty",
      "level": 0
    },
    {
      "x": -5,
      "y": 17,
      "z": 1,
      "name": "Empty",
      "level": 0
    },
    {
      "x": -5,
      "y": 18,
      "z": 1,
      "name": "Empty",
      "level": 0
    },
    {
      "x": -5,
      "y": 13,
      "z": 2,
      "name": "Empty",
      "level": 0
    },
    {
      "x": -5,
      "y": 14,
      "z": 2,
      "name": "Empty",
      "level": 0
    },
    {
      "x": -5,
      "y": 15,
      "z": 2,
      "name": "Empty",
      "level": 0
    },
    {
      "x": -5,
      "y": 16,
      "z": 2,
      "name": "Empty",
      "level": 0
    },
    {
      "x": -5,
      "y": 17,
      "z": 2,
      "name": "Empty",
      "level": 0
    },
    {
      "x": -5,
      "y": 18,
      "z": 2,
      "name": "Empty",
      "level": 0
    },
    {
      "x": -5,
      "y": 15,
      "z": 3,
      "name": "Empty",
      "level": 0
    },
    {
      "x": -5,
      "y": 16,
      "z": 3,
      "name": "Empty",
      "level": 0
    },
    {
      "x": -5,
      "y": 17,
      "z": 3,
      "name": "Empty",
      "level": 0
    },
    {
      "x": -4,
      "y": 15,
      "z": -2,
      "name": "Empty",
      "level": 0
    },
    {
      "x": -4,
      "y": 16,
      "z": -2,
      "name": "Empty",
      "level": 0
    },
    {
      "x": -4,
      "y": 17,
      "z": -2,
      "name": "Empty",
      "level": 0
    },
    {
      "x": -4,
      "y": 13,
      "z": -1,
      "name": "Empty",
      "level": 0
    },
    {
      "x": -4,
      "y": 14,
      "z": -1,
      "name": "Empty",
      "level": 0
    },
    {
      "x": -4,
      "y": 15,
      "z": -1,
      "name": "Empty",
      "level": 0
    },
    {
      "x": -4,
      "y": 16,
      "z": -1,
      "name": "Empty",
      "level": 0
    },
    {
      "x": -4,
      "y": 17,
      "z": -1,
      "name": "Empty",
      "level": 0
    },
    {
      "x": -4,
      "y": 18,
      "z": -1,
      "name": "Empty",
      "level": 0
    },
    {
      "x": -4,
      "y": 12,
      "z": 0,
      "name": "Empty",
      "level": 0
    },
    {
      "x": -4,
      "y": 13,
      "z": 0,
      "name": "Empty",
      "level": 0
    },
    {
      "x": -4,
      "y": 14,
      "z": 0,
      "name": "Empty",
      "level": 0
    },
    {
      "x": -4,
      "y": 15,
      "z": 0,
      "name": "Empty",
      "level": 0
    },
    {
      "x": -4,
      "y": 16,
      "z": 0,
      "name": "Empty",
      "level": 0
    },
    {
      "x": -4,
      "y": 17,
      "z": 0,
      "name": "Empty",
      "level": 0
    },
    {
      "x": -4,
      "y": 18,
      "z": 0,
      "name": "Empty",
      "level": 0
    },
    {
      "x": -4,
      "y": 19,
      "z": 0,
      "name": "Empty",
      "level": 0
    },
    {
      "x": -4,
      "y": 12,
      "z": 1,
      "name": "Empty",
      "level": 0
    },
    {
      "x": -4,
      "y": 13,
      "z": 1,
      "name": "Empty",
      "level": 0
    },
    {
      "x": -4,
      "y": 14,
      "z": 1,
      "name": "Empty",
      "level": 0
    },
    {
      "x": -4,
      "y": 15,
      "z": 1,
      "name": "Empty",
      "level": 0
    },
    {
      "x": -4,
      "y": 16,
      "z": 1,
      "name": "Empty",
      "level": 0
    },
    {
      "x": -4,
      "y": 17,
      "z": 1,
      "name": "Empty",
      "level": 0
    },
    {
      "x": -4,
      "y": 18,
      "z": 1,
      "name": "Empty",
      "level": 0
    },
    {
      "x": -4,
      "y": 19,
      "z": 1,
      "name": "Empty",
      "level": 0
    },
    {
      "x": -4,
      "y": 11,
      "z": 2,
      "name": "Empty",
      "level": 0
    },
    {
      "x": -4,
      "y": 12,
      "z": 2,
      "name": "Empty",
      "level": 0
    },
    {
      "x": -4,
      "y": 13,
      "z": 2,
      "name": "Empty",
      "level": 0
    },
    {
      "x": -4,
      "y": 14,
      "z": 2,
      "name": "Empty",
      "level": 0
    },
    {
      "x": -4,
      "y": 15,
      "z": 2,
      "name": "Empty",
      "level": 0
    },
    {
      "x": -4,
      "y": 16,
      "z": 2,
      "name": "Empty",
      "level": 0
    },
    {
      "x": -4,
      "y": 17,
      "z": 2,
      "name": "Empty",
      "level": 0
    },
    {
      "x": -4,
      "y": 18,
      "z": 2,
      "name": "Empty",
      "level": 0
    },
    {
      "x": -4,
      "y": 19,
      "z": 2,
      "name": "Empty",
      "level": 0
    },
    {
      "x": -4,
      "y": 13,
      "z": 3,
      "name": "Empty",
      "level": 0
    },
    {
      "x": -4,
      "y": 14,
      "z": 3,
      "name": "Empty",
      "level": 0
    },
    {
      "x": -4,
      "y": 15,
      "z": 3,
      "name": "Empty",
      "level": 0
    },
    {
      "x": -4,
      "y": 16,
      "z": 3,
      "name": "Empty",
      "level": 0
    },
    {
      "x": -4,
      "y": 17,
      "z": 3,
      "name": "Empty",
      "level": 0
    },
    {
      "x": -4,
      "y": 18,
      "z": 3,
      "name": "Empty",
      "level": 0
    },
    {
      "x": -3,
      "y": 15,
      "z": -3,
      "name": "Empty",
      "level": 0
    },
    {
      "x": -3,
      "y": 16,
      "z": -3,
      "name": "Empty",
      "level": 0
    },
    {
      "x": -3,
      "y": 17,
      "z": -3,
      "name": "Empty",
      "level": 0
    },
    {
      "x": -3,
      "y": 13,
      "z": -2,
      "name": "Empty",
      "level": 0
    },
    {
      "x": -3,
      "y": 14,
      "z": -2,
      "name": "Empty",
      "level": 0
    },
    {
      "x": -3,
      "y": 15,
      "z": -2,
      "name": "Empty",
      "level": 0
    },
    {
      "x": -3,
      "y": 16,
      "z": -2,
      "name": "Empty",
      "level": 0
    },
    {
      "x": -3,
      "y": 17,
      "z": -2,
      "name": "Empty",
      "level": 0
    },
    {
      "x": -3,
      "y": 18,
      "z": -2,
      "name": "Empty",
      "level": 0
    },
    {
      "x": -3,
      "y": 11,
      "z": -1,
      "name": "Empty",
      "level": 0
    },
    {
      "x": -3,
      "y": 12,
      "z": -1,
      "name": "Empty",
      "level": 0
    },
    {
      "x": -3,
      "y": 13,
      "z": -1,
      "name": "Empty",
      "level": 0
    },
    {
      "x": -3,
      "y": 14,
      "z": -1,
      "name": "Empty",
      "level": 0
    },
    {
      "x": -3,
      "y": 15,
      "z": -1,
      "name": "Empty",
      "level": 0
    },
    {
      "x": -3,
      "y": 16,
      "z": -1,
      "name": "Empty",
      "level": 0
    },
    {
      "x": -3,
      "y": 17,
      "z": -1,
      "name": "Empty",
      "level": 0
    },
    {
      "x": -3,
      "y": 18,
      "z": -1,
      "name": "Empty",
      "level": 0
    },
    {
      "x": -3,
      "y": 19,
      "z": -1,
      "name": "Empty",
      "level": 0
    },
    {
      "x": -3,
      "y": 11,
      "z": 0,
      "name": "Empty",
      "level": 0
    },
    {
      "x": -3,
      "y": 12,
      "z": 0,
      "name": "Empty",
      "level": 0
    },
    {
      "x": -3,
      "y": 13,
      "z": 0,
      "name": "Empty",
      "level": 0
    },
    {
      "x": -3,
      "y": 14,
      "z": 0,
      "name": "Empty",
      "level": 0
    },
    {
      "x": -3,
      "y": 15,
      "z": 0,
      "name": "Empty",
      "level": 0
    },
    {
      "x": -3,
      "y": 16,
      "z": 0,
      "name": "Empty",
      "level": 0
    },
    {
      "x": -3,
      "y": 17,
      "z": 0,
      "name": "Empty",
      "level": 0
    },
    {
      "x": -3,
      "y": 18,
      "z": 0,
      "name": "Empty",
      "level": 0
    },
    {
      "x": -3,
      "y": 19,
      "z": 0,
      "name": "Empty",
      "level": 0
    },
    {
      "x": -3,
      "y": 20,
      "z": 0,
      "name": "Empty",
      "level": 0
    },
    {
      "x": -3,
      "y": 10,
      "z": 1,
      "name": "Empty",
      "level": 0
    },
    {
      "x": -3,
      "y": 11,
      "z": 1,
      "name": "Empty",
      "level": 0
    },
    {
      "x": -3,
      "y": 12,
      "z": 1,
      "name": "Empty",
      "level": 0
    },
    {
      "x": -3,
      "y": 13,
      "z": 1,
      "name": "Empty",
      "level": 0
    },
    {
      "x": -3,
      "y": 14,
      "z": 1,
      "name": "Empty",
      "level": 0
    },
    {
      "x": -3,
      "y": 15,
      "z": 1,
      "name": "Empty",
      "level": 0
    },
    {
      "x": -3,
      "y": 16,
      "z": 1,
      "name": "Empty",
      "level": 0
    },
    {
      "x": -3,
      "y": 17,
      "z": 1,
      "name": "Empty",
      "level": 0
    },
    {
      "x": -3,
      "y": 18,
      "z": 1,
      "name": "Empty",
      "level": 0
    },
    {
      "x": -3,
      "y": 19,
      "z": 1,
      "name": "Empty",
      "level": 0
    },
    {
      "x": -3,
      "y": 20,
      "z": 1,
      "name": "Empty",
      "level": 0
    },
    {
      "x": -3,
      "y": 11,
      "z": 2,
      "name": "Empty",
      "level": 0
    },
    {
      "x": -3,
      "y": 12,
      "z": 2,
      "name": "Empty",
      "level": 0
    },
    {
      "x": -3,
      "y": 13,
      "z": 2,
      "name": "Empty",
      "level": 0
    },
    {
      "x": -3,
      "y": 14,
      "z": 2,
      "name": "Empty",
      "level": 0
    },
    {
      "x": -3,
      "y": 15,
      "z": 2,
      "name": "Empty",
      "level": 0
    },
    {
      "x": -3,
      "y": 16,
      "z": 2,
      "name": "Empty",
      "level": 0
    },
    {
      "x": -3,
      "y": 17,
      "z": 2,
      "name": "Empty",
      "level": 0
    },
    {
      "x": -3,
      "y": 18,
      "z": 2,
      "name": "Empty",
      "level": 0
    },
    {
      "x": -3,
      "y": 19,
      "z": 2,
      "name": "Empty",
      "level": 0
    },
    {
      "x": -3,
      "y": 12,
      "z": 3,
      "name": "Empty",
      "level": 0
    },
    {
      "x": -3,
      "y": 13,
      "z": 3,
      "name": "Empty",
      "level": 0
    },
    {
      "x": -3,
      "y": 14,
      "z": 3,
      "name": "Empty",
      "level": 0
    },
    {
      "x": -3,
      "y": 15,
      "z": 3,
      "name": "Empty",
      "level": 0
    },
    {
      "x": -3,
      "y": 16,
      "z": 3,
      "name": "Empty",
      "level": 0
    },
    {
      "x": -3,
      "y": 17,
      "z": 3,
      "name": "Empty",
      "level": 0
    },
    {
      "x": -3,
      "y": 18,
      "z": 3,
      "name": "Empty",
      "level": 0
    },
    {
      "x": -3,
      "y": 19,
      "z": 3,
      "name": "Empty",
      "level": 0
    },
    {
      "x": -3,
      "y": 13,
      "z": 4,
      "name": "Empty",
      "level": 0
    },
    {
      "x": -3,
      "y": 14,
      "z": 4,
      "name": "Empty",
      "level": 0
    },
    {
      "x": -3,
      "y": 15,
      "z": 4,
      "name": "Empty",
      "level": 0
    },
    {
      "x": -3,
      "y": 16,
      "z": 4,
      "name": "Empty",
      "level": 0
    },
    {
      "x": -3,
      "y": 17,
      "z": 4,
      "name": "Empty",
      "level": 0
    },
    {
      "x": -3,
      "y": 13,
      "z": 5,
      "name": "Empty",
      "level": 0
    },
    {
      "x": -3,
      "y": 14,
      "z": 5,
      "name": "Empty",
      "level": 0
    },
    {
      "x": -3,
      "y": 15,
      "z": 5,
      "name": "Empty",
      "level": 0
    },
    {
      "x": -3,
      "y": 16,
      "z": 5,
      "name": "Empty",
      "level": 0
    },
    {
      "x": -3,
      "y": 17,
      "z": 5,
      "name": "Empty",
      "level": 0
    },
    {
      "x": -2,
      "y": 15,
      "z": -3,
      "name": "Empty",
      "level": 0
    },
    {
      "x": -2,
      "y": 16,
      "z": -3,
      "name": "Empty",
      "level": 0
    },
    {
      "x": -2,
      "y": 17,
      "z": -3,
      "name": "Empty",
      "level": 0
    },
    {
      "x": -2,
      "y": 18,
      "z": -3,
      "name": "Empty",
      "level": 0
    },
    {
      "x": -2,
      "y": 11,
      "z": -2,
      "name": "Empty",
      "level": 0
    },
    {
      "x": -2,
      "y": 12,
      "z": -2,
      "name": "Empty",
      "level": 0
    },
    {
      "x": -2,
      "y": 13,
      "z": -2,
      "name": "Empty",
      "level": 0
    },
    {
      "x": -2,
      "y": 14,
      "z": -2,
      "name": "Empty",
      "level": 0
    },
    {
      "x": -2,
      "y": 15,
      "z": -2,
      "name": "Empty",
      "level": 0
    },
    {
      "x": -2,
      "y": 16,
      "z": -2,
      "name": "Empty",
      "level": 0
    },
    {
      "x": -2,
      "y": 17,
      "z": -2,
      "name": "Empty",
      "level": 0
    },
    {
      "x": -2,
      "y": 18,
      "z": -2,
      "name": "Empty",
      "level": 0
    },
    {
      "x": -2,
      "y": 19,
      "z": -2,
      "name": "Empty",
      "level": 0
    },
    {
      "x": -2,
      "y": 9,
      "z": -1,
      "name": "Empty",
      "level": 0
    },
    {
      "x": -2,
      "y": 10,
      "z": -1,
      "name": "Empty",
      "level": 0
    },
    {
      "x": -2,
      "y": 11,
      "z": -1,
      "name": "Empty",
      "level": 0
    },
    {
      "x": -2,
      "y": 12,
      "z": -1,
      "name": "Empty",
      "level": 0
    },
    {
      "x": -2,
      "y": 13,
      "z": -1,
      "name": "Empty",
      "level": 0
    },
    {
      "x": -2,
      "y": 14,
      "z": -1,
      "name": "Empty",
      "level": 0
    },
    {
      "x": -2,
      "y": 15,
      "z": -1,
      "name": "Empty",
      "level": 0
    },
    {
      "x": -2,
      "y": 16,
      "z": -1,
      "name": "Empty",
      "level": 0
    },
    {
      "x": -2,
      "y": 17,
      "z": -1,
      "name": "Empty",
      "level": 0
    },
    {
      "x": -2,
      "y": 18,
      "z": -1,
      "name": "Empty",
      "level": 0
    },
    {
      "x": -2,
      "y": 19,
      "z": -1,
      "name": "Empty",
      "level": 0
    },
    {
      "x": -2,
      "y": 0,
      "z": 0,
      "name": "Empty",
      "level": 0
    },
    {
      "x": -2,
      "y": 1,
      "z": 0,
      "name": "Empty",
      "level": 0
    },
    {
      "x": -2,
      "y": 9,
      "z": 0,
      "name": "Empty",
      "level": 0
    },
    {
      "x": -2,
      "y": 10,
      "z": 0,
      "name": "Empty",
      "level": 0
    },
    {
      "x": -2,
      "y": 11,
      "z": 0,
      "name": "Empty",
      "level": 0
    },
    {
      "x": -2,
      "y": 12,
      "z": 0,
      "name": "Empty",
      "level": 0
    },
    {
      "x": -2,
      "y": 13,
      "z": 0,
      "name": "Empty",
      "level": 0
    },
    {
      "x": -2,
      "y": 14,
      "z": 0,
      "name": "Empty",
      "level": 0
    },
    {
      "x": -2,
      "y": 15,
      "z": 0,
      "name": "Empty",
      "level": 0
    },
    {
      "x": -2,
      "y": 16,
      "z": 0,
      "name": "Empty",
      "level": 0
    },
    {
      "x": -2,
      "y": 17,
      "z": 0,
      "name": "Empty",
      "level": 0
    },
    {
      "x": -2,
      "y": 18,
      "z": 0,
      "name": "Empty",
      "level": 0
    },
    {
      "x": -2,
      "y": 19,
      "z": 0,
      "name": "Empty",
      "level": 0
    },
    {
      "x": -2,
      "y": 20,
      "z": 0,
      "name": "Empty",
      "level": 0
    },
    {
      "x": -2,
      "y": 0,
      "z": 1,
      "name": "Empty",
      "level": 0
    },
    {
      "x": -2,
      "y": 1,
      "z": 1,
      "name": "Empty",
      "level": 0
    },
    {
      "x": -2,
      "y": 8,
      "z": 1,
      "name": "Empty",
      "level": 0
    },
    {
      "x": -2,
      "y": 9,
      "z": 1,
      "name": "Empty",
      "level": 0
    },
    {
      "x": -2,
      "y": 10,
      "z": 1,
      "name": "Empty",
      "level": 0
    },
    {
      "x": -2,
      "y": 11,
      "z": 1,
      "name": "Empty",
      "level": 0
    },
    {
      "x": -2,
      "y": 12,
      "z": 1,
      "name": "Empty",
      "level": 0
    },
    {
      "x": -2,
      "y": 13,
      "z": 1,
      "name": "Empty",
      "level": 0
    },
    {
      "x": -2,
      "y": 14,
      "z": 1,
      "name": "Empty",
      "level": 0
    },
    {
      "x": -2,
      "y": 15,
      "z": 1,
      "name": "Empty",
      "level": 0
    },
    {
      "x": -2,
      "y": 16,
      "z": 1,
      "name": "Empty",
      "level": 0
    },
    {
      "x": -2,
      "y": 17,
      "z": 1,
      "name": "Empty",
      "level": 0
    },
    {
      "x": -2,
      "y": 18,
      "z": 1,
      "name": "Empty",
      "level": 0
    },
    {
      "x": -2,
      "y": 19,
      "z": 1,
      "name": "Empty",
      "level": 0
    },
    {
      "x": -2,
      "y": 20,
      "z": 1,
      "name": "Empty",
      "level": 0
    },
    {
      "x": -2,
      "y": 0,
      "z": 2,
      "name": "Empty",
      "level": 0
    },
    {
      "x": -2,
      "y": 1,
      "z": 2,
      "name": "Empty",
      "level": 0
    },
    {
      "x": -2,
      "y": 2,
      "z": 2,
      "name": "Empty",
      "level": 0
    },
    {
      "x": -2,
      "y": 9,
      "z": 2,
      "name": "Empty",
      "level": 0
