{
  "version": 8,
  "blockIdVersion": 11,
  "anchorX": 0,
  "anchorY": 0,
  "anchorZ": 0,
  "blocks": [
    {
      "x": -8,
      "y": 0,
      "z": -3,
      "name": "Plant_Mushroom_Wall_White_Mycelium",
      "support": 15,
      "rotation": 2
    },
    {
      "x": -8,
      "y": 0,
      "z": -2,
      "name": "Rock_Shale"
    },
    {
      "x": -8,
      "y": 1,
      "z": -2,
      "name": "Plant_Mushroom_Rug_White_Mycelium",
      "support": 15
    },
    {
      "x": -8,
      "y": 0,
      "z": -1,
      "name": "Rock_Shale"
    },
    {
      "x": -8,
      "y": 1,
      "z": -1,
      "name": "Rock_Shale"
    },
    {
      "x": -8,
      "y": 2,
      "z": -1,
      "name": "Plant_Roots_Rug_Tainted",
      "support": 15
    },
    {
      "x": -8,
      "y": 1,
      "z": 0,
      "name": "Plant_Mushroom_Wall_White_Mycelium",
      "support": 15,
      "rotation": 3
    },
    {
      "x": -7,
      "y": 0,
      "z": -3,
      "name": "Rock_Shale"
    },
    {
      "x": -7,
      "y": 1,
      "z": -3,
      "name": "Rock_Shale_Stalactites_Small"
    },
    {
      "x": -7,
      "y": 0,
      "z": -2,
      "name": "Rock_Shale"
    },
    {
      "x": -7,
      "y": 1,
      "z": -2,
      "name": "Rock_Shale"
    },
    {
      "x": -7,
      "y": 2,
      "z": -2,
      "name": "Plant_Mushroom_Rug_White_Mycelium",
      "support": 15
    },
    {
      "x": -7,
      "y": 0,
      "z": -1,
      "name": "Rock_Shale"
    },
    {
      "x": -7,
      "y": 1,
      "z": -1,
      "name": "Rock_Shale"
    },
    {
      "x": -7,
      "y": 2,
      "z": -1,
      "name": "Rock_Shale"
    },
    {
      "x": -7,
      "y": 3,
      "z": -1,
      "name": "Rock_Shale_Stalactites_Large"
    },
    {
      "x": -7,
      "y": 4,
      "z": -1,
      "name": "Rock_Shale_Stalactites_Large",
      "filler": 1024
    },
    {
      "x": -7,
      "y": 0,
      "z": 0,
      "name": "Rock_Shale"
    },
    {
      "x": -7,
      "y": 1,
      "z": 0,
      "name": "Rock_Shale"
    },
    {
      "x": -7,
      "y": 2,
      "z": 0,
      "name": "Plant_Mushroom_Rug_White_Mycelium",
      "support": 15
    },
    {
      "x": -7,
      "y": 0,
      "z": 1,
      "name": "Rock_Shale"
    },
    {
      "x": -7,
      "y": 1,
      "z": 1,
      "name": "Plant_Mushroom_Rug_White_Mycelium",
      "support": 15
    },
    {
      "x": -6,
      "y": 25,
      "z": -4,
      "name": "Rock_Shale"
    },
    {
      "x": -6,
      "y": 26,
      "z": -4,
      "name": "Rock_Shale"
    },
    {
      "x": -6,
      "y": 0,
      "z": -3,
      "name": "Rock_Shale"
    },
    {
      "x": -6,
      "y": 1,
      "z": -3,
      "name": "Plant_Mushroom_Rug_White_Mycelium",
      "support": 15
    },
    {
      "x": -6,
      "y": 24,
      "z": -3,
      "name": "Rock_Shale"
    },
    {
      "x": -6,
      "y": 25,
      "z": -3,
      "name": "Rock_Shale"
    },
    {
      "x": -6,
      "y": 26,
      "z": -3,
      "name": "Rock_Shale"
    },
    {
      "x": -6,
      "y": 0,
      "z": -2,
      "name": "Rock_Shale"
    },
    {
      "x": -6,
      "y": 1,
      "z": -2,
      "name": "Rock_Shale"
    },
    {
      "x": -6,
      "y": 2,
      "z": -2,
      "name": "Plant_Mushroom_Short_White_Mycelium",
      "support": 15
    },
    {
      "x": -6,
      "y": 23,
      "z": -2,
      "name": "Rock_Shale"
    },
    {
      "x": -6,
      "y": 24,
      "z": -2,
      "name": "Rock_Shale"
    },
    {
      "x": -6,
      "y": 25,
      "z": -2,
      "name": "Rock_Shale"
    },
    {
      "x": -6,
      "y": 26,
      "z": -2,
      "name": "Rock_Shale"
    },
    {
      "x": -6,
      "y": 0,
      "z": -1,
      "name": "Rock_Shale"
    },
    {
      "x": -6,
      "y": 1,
      "z": -1,
      "name": "Rock_Shale"
    },
    {
      "x": -6,
      "y": 2,
      "z": -1,
      "name": "Plant_Mushroom_Rug_White_Mycelium",
      "support": 15
    },
    {
      "x": -6,
      "y": 20,
      "z": -1,
      "name": "Rock_Shale"
    },
    {
      "x": -6,
      "y": 21,
      "z": -1,
      "name": "Rock_Shale"
    },
    {
      "x": -6,
      "y": 22,
      "z": -1,
      "name": "Rock_Shale"
    },
    {
      "x": -6,
      "y": 23,
      "z": -1,
      "name": "Rock_Shale"
    },
    {
      "x": -6,
      "y": 24,
      "z": -1,
      "name": "Rock_Shale"
    },
    {
      "x": -6,
      "y": 25,
      "z": -1,
      "name": "Rock_Shale"
    },
    {
      "x": -6,
      "y": 26,
      "z": -1,
      "name": "Rock_Shale"
    },
    {
      "x": -6,
      "y": 0,
      "z": 0,
      "name": "Rock_Shale"
    },
    {
      "x": -6,
      "y": 1,
      "z": 0,
      "name": "Rock_Shale"
    },
    {
      "x": -6,
      "y": 2,
      "z": 0,
      "name": "Plant_Mushroom_Rug_White_Mycelium",
      "support": 15
    },
    {
      "x": -6,
      "y": 21,
      "z": 0,
      "name": "Rock_Shale"
    },
    {
      "x": -6,
      "y": 22,
      "z": 0,
      "name": "Rock_Shale"
    },
    {
      "x": -6,
      "y": 23,
      "z": 0,
      "name": "Rock_Shale"
    },
    {
      "x": -6,
      "y": 24,
      "z": 0,
      "name": "Rock_Shale"
    },
    {
      "x": -6,
      "y": 25,
      "z": 0,
      "name": "Rock_Shale"
    },
    {
      "x": -6,
      "y": 26,
      "z": 0,
      "name": "Rock_Shale"
    },
    {
      "x": -6,
      "y": 0,
      "z": 1,
      "name": "Rock_Shale"
    },
    {
      "x": -6,
      "y": 1,
      "z": 1,
      "name": "Rock_Shale"
    },
    {
      "x": -6,
      "y": 2,
      "z": 1,
      "name": "Rock_Shale_Stalactites_Small"
    },
    {
      "x": -6,
      "y": 22,
      "z": 1,
      "name": "Rock_Shale"
    },
    {
      "x": -6,
      "y": 23,
      "z": 1,
      "name": "Rock_Shale"
    },
    {
      "x": -6,
      "y": 24,
      "z": 1,
      "name": "Rock_Shale"
    },
    {
      "x": -6,
      "y": 25,
      "z": 1,
      "name": "Rock_Shale"
    },
    {
      "x": -6,
      "y": 26,
      "z": 1,
      "name": "Rock_Shale"
    },
    {
      "x": -6,
      "y": 0,
      "z": 2,
      "name": "Rock_Shale"
    },
    {
      "x": -6,
      "y": 1,
      "z": 2,
      "name": "Plant_Mushroom_Rug_White_Mycelium",
      "support": 15
    },
    {
      "x": -6,
      "y": 23,
      "z": 2,
      "name": "Rock_Shale"
    },
    {
      "x": -6,
      "y": 24,
      "z": 2,
      "name": "Rock_Shale"
    },
    {
      "x": -6,
      "y": 25,
      "z": 2,
      "name": "Rock_Shale"
    },
    {
      "x": -6,
      "y": 26,
      "z": 2,
      "name": "Rock_Shale"
    },
    {
      "x": -6,
      "y": 2,
      "z": 3,
      "name": "Plant_Mushroom_Wall_White_Mycelium",
      "support": 15,
      "rotation": 3
    },
    {
      "x": -5,
      "y": 22,
      "z": -5,
      "name": "Rock_Shale"
    },
    {
      "x": -5,
      "y": 23,
      "z": -5,
      "name": "Rock_Shale"
    },
    {
      "x": -5,
      "y": 24,
      "z": -5,
      "name": "Rock_Shale"
    },
    {
      "x": -5,
      "y": 25,
      "z": -5,
      "name": "Rock_Shale"
    },
    {
      "x": -5,
      "y": 26,
      "z": -5,
      "name": "Rock_Shale"
    },
    {
      "x": -5,
      "y": 0,
      "z": -4,
      "name": "Rock_Shale"
    },
    {
      "x": -5,
      "y": 20,
      "z": -4,
      "name": "Rock_Shale"
    },
    {
      "x": -5,
      "y": 21,
      "z": -4,
      "name": "Rock_Shale"
    },
    {
      "x": -5,
      "y": 22,
      "z": -4,
      "name": "Rock_Shale"
    },
    {
      "x": -5,
      "y": 23,
      "z": -4,
      "name": "Rock_Shale"
    },
    {
      "x": -5,
      "y": 24,
      "z": -4,
      "name": "Rock_Shale"
    },
    {
      "x": -5,
      "y": 25,
      "z": -4,
      "name": "Rock_Shale"
    },
    {
      "x": -5,
      "y": 26,
      "z": -4,
      "name": "Rock_Shale"
    },
    {
      "x": -5,
      "y": 0,
      "z": -3,
      "name": "Rock_Shale"
    },
    {
      "x": -5,
      "y": 1,
      "z": -3,
      "name": "Rock_Shale"
    },
    {
      "x": -5,
      "y": 21,
      "z": -3,
      "name": "Rock_Shale"
    },
    {
      "x": -5,
      "y": 22,
      "z": -3,
      "name": "Rock_Shale"
    },
    {
      "x": -5,
      "y": 23,
      "z": -3,
      "name": "Rock_Shale"
    },
    {
      "x": -5,
      "y": 24,
      "z": -3,
      "name": "Rock_Shale"
    },
    {
      "x": -5,
      "y": 25,
      "z": -3,
      "name": "Rock_Shale"
    },
    {
      "x": -5,
      "y": 26,
      "z": -3,
      "name": "Rock_Shale"
    },
    {
      "x": -5,
      "y": 27,
      "z": -3,
      "name": "Rock_Shale"
    },
    {
      "x": -5,
      "y": 0,
      "z": -2,
      "name": "Rock_Shale"
    },
    {
      "x": -5,
      "y": 1,
      "z": -2,
      "name": "Rock_Shale"
    },
    {
      "x": -5,
      "y": 2,
      "z": -2,
      "name": "Rock_Shale"
    },
    {
      "x": -5,
      "y": 3,
      "z": -2,
      "name": "Plant_Roots_Rug_Tainted",
      "support": 15
    },
    {
      "x": -5,
      "y": 19,
      "z": -2,
      "name": "Rock_Shale"
    },
    {
      "x": -5,
      "y": 20,
      "z": -2,
      "name": "Rock_Shale"
    },
    {
      "x": -5,
      "y": 21,
      "z": -2,
      "name": "Rock_Shale"
    },
    {
      "x": -5,
      "y": 22,
      "z": -2,
      "name": "Rock_Shale"
    },
    {
      "x": -5,
      "y": 23,
      "z": -2,
      "name": "Rock_Shale"
    },
    {
      "x": -5,
      "y": 24,
      "z": -2,
      "name": "Rock_Shale"
    },
    {
      "x": -5,
      "y": 25,
      "z": -2,
      "name": "Rock_Shale"
    },
    {
      "x": -5,
      "y": 26,
      "z": -2,
      "name": "Rock_Shale"
    },
    {
      "x": -5,
      "y": 27,
      "z": -2,
      "name": "Rock_Shale"
    },
    {
      "x": -5,
      "y": 0,
      "z": -1,
      "name": "Rock_Shale"
    },
    {
      "x": -5,
      "y": 1,
      "z": -1,
      "name": "Rock_Shale"
    },
    {
      "x": -5,
      "y": 2,
      "z": -1,
      "name": "Rock_Shale"
    },
    {
      "x": -5,
      "y": 3,
      "z": -1,
      "name": "Rock_Shale"
    },
    {
      "x": -5,
      "y": 4,
      "z": -1,
      "name": "Plant_Mushroom_Short_White_Mycelium",
      "support": 15
    },
    {
      "x": -5,
      "y": 18,
      "z": -1,
      "name": "Rock_Shale"
    },
    {
      "x": -5,
      "y": 19,
      "z": -1,
      "name": "Rock_Shale"
    },
    {
      "x": -5,
      "y": 20,
      "z": -1,
      "name": "Rock_Shale"
    },
    {
      "x": -5,
      "y": 21,
      "z": -1,
      "name": "Rock_Shale"
    },
    {
      "x": -5,
      "y": 22,
      "z": -1,
      "name": "Rock_Shale"
    },
    {
      "x": -5,
      "y": 23,
      "z": -1,
      "name": "Rock_Shale"
    },
    {
      "x": -5,
      "y": 24,
      "z": -1,
      "name": "Rock_Shale"
    },
    {
      "x": -5,
      "y": 25,
      "z": -1,
      "name": "Rock_Shale"
    },
    {
      "x": -5,
      "y": 26,
      "z": -1,
      "name": "Rock_Shale"
    },
    {
      "x": -5,
      "y": 27,
      "z": -1,
      "name": "Rock_Shale"
    },
    {
      "x": -5,
      "y": 0,
      "z": 0,
      "name": "Rock_Shale"
    },
    {
      "x": -5,
      "y": 1,
      "z": 0,
      "name": "Rock_Shale"
    },
    {
      "x": -5,
      "y": 2,
      "z": 0,
      "name": "Plant_Mushroom_Rug_White_Mycelium",
      "support": 15
    },
    {
      "x": -5,
      "y": 18,
      "z": 0,
      "name": "Rock_Shale"
    },
    {
      "x": -5,
      "y": 19,
      "z": 0,
      "name": "Rock_Shale"
    },
    {
      "x": -5,
      "y": 21,
      "z": 0,
      "name": "Rock_Shale"
    },
    {
      "x": -5,
      "y": 22,
      "z": 0,
      "name": "Rock_Shale"
    },
    {
      "x": -5,
      "y": 23,
      "z": 0,
      "name": "Rock_Shale"
    },
    {
      "x": -5,
      "y": 24,
      "z": 0,
      "name": "Rock_Shale"
    },
    {
      "x": -5,
      "y": 25,
      "z": 0,
      "name": "Rock_Shale"
    },
    {
      "x": -5,
      "y": 26,
      "z": 0,
      "name": "Rock_Shale"
    },
    {
      "x": -5,
      "y": 27,
      "z": 0,
      "name": "Rock_Shale"
    },
    {
      "x": -5,
      "y": 0,
      "z": 1,
      "name": "Rock_Shale"
    },
    {
      "x": -5,
      "y": 1,
      "z": 1,
      "name": "Rock_Shale"
    },
    {
      "x": -5,
      "y": 2,
      "z": 1,
      "name": "Plant_Mushroom_Rug_White_Mycelium",
      "support": 15
    },
    {
      "x": -5,
      "y": 20,
      "z": 1,
      "name": "Rock_Shale"
    },
    {
      "x": -5,
      "y": 21,
      "z": 1,
      "name": "Rock_Shale"
    },
    {
      "x": -5,
      "y": 22,
      "z": 1,
      "name": "Rock_Shale"
    },
    {
      "x": -5,
      "y": 23,
      "z": 1,
      "name": "Rock_Shale"
    },
    {
      "x": -5,
      "y": 24,
      "z": 1,
      "name": "Rock_Shale"
    },
    {
      "x": -5,
      "y": 25,
      "z": 1,
      "name": "Rock_Shale"
    },
    {
      "x": -5,
      "y": 26,
      "z": 1,
      "name": "Rock_Shale"
    },
    {
      "x": -5,
      "y": 27,
      "z": 1,
      "name": "Rock_Shale"
    },
    {
      "x": -5,
      "y": 0,
      "z": 2,
      "name": "Rock_Shale"
    },
    {
      "x": -5,
      "y": 1,
      "z": 2,
      "name": "Plant_Mushroom_Block_White_Mycelium",
      "support": 15
    },
    {
      "x": -5,
      "y": 2,
      "z": 2,
      "name": "Plant_Crop_Mushroom_Funnel_Tainted"
    },
    {
      "x": -5,
      "y": 21,
      "z": 2,
      "name": "Rock_Shale"
    },
    {
      "x": -5,
      "y": 22,
      "z": 2,
      "name": "Rock_Shale"
    },
    {
      "x": -5,
      "y": 23,
      "z": 2,
      "name": "Rock_Shale"
    },
    {
      "x": -5,
      "y": 24,
      "z": 2,
      "name": "Rock_Shale"
    },
    {
      "x": -5,
      "y": 25,
      "z": 2,
      "name": "Rock_Shale"
    },
    {
      "x": -5,
      "y": 26,
      "z": 2,
      "name": "Rock_Shale"
    },
    {
      "x": -5,
      "y": 0,
      "z": 3,
      "name": "Rock_Shale"
    },
    {
      "x": -5,
      "y": 1,
      "z": 3,
      "name": "Rock_Shale"
    },
    {
      "x": -5,
      "y": 2,
      "z": 3,
      "name": "Rock_Shale"
    },
    {
      "x": -5,
      "y": 3,
      "z": 3,
      "name": "Plant_Mushroom_Rug_White_Mycelium",
      "support": 15
    },
    {
      "x": -5,
      "y": 21,
      "z": 3,
      "name": "Rock_Shale"
    },
    {
      "x": -5,
      "y": 22,
      "z": 3,
      "name": "Rock_Shale"
    },
    {
      "x": -5,
      "y": 23,
      "z": 3,
      "name": "Rock_Shale"
    },
    {
      "x": -5,
      "y": 24,
      "z": 3,
      "name": "Rock_Shale"
    },
    {
      "x": -5,
      "y": 25,
      "z": 3,
      "name": "Rock_Shale"
    },
    {
      "x": -5,
      "y": 26,
      "z": 3,
      "name": "Rock_Shale"
    },
    {
      "x": -5,
      "y": 0,
      "z": 4,
      "name": "Rock_Shale"
    },
    {
      "x": -5,
      "y": 1,
      "z": 4,
      "name": "Rock_Shale"
    },
    {
      "x": -5,
      "y": 2,
      "z": 4,
      "name": "Rock_Shale"
    },
    {
      "x": -5,
      "y": 3,
      "z": 4,
      "name": "Plant_Roots_Rug_Tainted",
      "support": 15
    },
    {
      "x": -5,
      "y": 2,
      "z": 5,
      "name": "Plant_Mushroom_Wall_White_Mycelium",
      "support": 15,
      "rotation": 3
    },
    {
      "x": -4,
      "y": 22,
      "z": -6,
      "name": "Rock_Shale"
    },
    {
      "x": -4,
      "y": 23,
      "z": -6,
      "name": "Rock_Shale"
    },
    {
      "x": -4,
      "y": 24,
      "z": -6,
      "name": "Rock_Shale"
    },
    {
      "x": -4,
      "y": 25,
      "z": -6,
      "name": "Rock_Shale"
    },
    {
      "x": -4,
      "y": 26,
      "z": -6,
      "name": "Rock_Shale"
    },
    {
      "x": -4,
      "y": 0,
      "z": -5,
      "name": "Rock_Shale"
    },
    {
      "x": -4,
      "y": 1,
      "z": -5,
      "name": "Plant_Mushroom_Rug_White_Mycelium",
      "support": 15
    },
    {
      "x": -4,
      "y": 20,
      "z": -5,
      "name": "Rock_Shale"
    },
    {
      "x": -4,
      "y": 21,
      "z": -5,
      "name": "Rock_Shale"
    },
    {
      "x": -4,
      "y": 22,
      "z": -5,
      "name": "Rock_Shale"
    },
    {
      "x": -4,
      "y": 23,
      "z": -5,
      "name": "Rock_Shale"
    },
    {
      "x": -4,
      "y": 24,
      "z": -5,
      "name": "Rock_Shale"
    },
    {
      "x": -4,
      "y": 25,
      "z": -5,
      "name": "Rock_Shale"
    },
    {
      "x": -4,
      "y": 26,
      "z": -5,
      "name": "Rock_Shale"
    },
    {
      "x": -4,
      "y": 0,
      "z": -4,
      "name": "Rock_Shale"
    },
    {
      "x": -4,
      "y": 1,
      "z": -4,
      "name": "Rock_Shale"
    },
    {
      "x": -4,
      "y": 2,
      "z": -4,
      "name": "Plant_Mushroom_Short_White_Mycelium",
      "support": 15
    },
    {
      "x": -4,
      "y": 19,
      "z": -4,
      "name": "Rock_Shale"
    },
    {
      "x": -4,
      "y": 20,
      "z": -4,
      "name": "Rock_Shale"
    },
    {
      "x": -4,
      "y": 21,
      "z": -4,
      "name": "Rock_Shale"
    },
    {
      "x": -4,
      "y": 22,
      "z": -4,
      "name": "Rock_Shale"
    },
    {
      "x": -4,
      "y": 23,
      "z": -4,
      "name": "Rock_Shale"
    },
    {
      "x": -4,
      "y": 24,
      "z": -4,
      "name": "Rock_Shale"
    },
    {
      "x": -4,
      "y": 25,
      "z": -4,
      "name": "Rock_Shale"
    },
    {
      "x": -4,
      "y": 26,
      "z": -4,
      "name": "Rock_Shale"
    },
    {
      "x": -4,
      "y": 27,
      "z": -4,
      "name": "Rock_Shale"
    },
    {
      "x": -4,
      "y": 0,
      "z": -3,
      "name": "Rock_Shale"
    },
    {
      "x": -4,
      "y": 1,
      "z": -3,
      "name": "Rock_Shale"
    },
    {
      "x": -4,
      "y": 2,
      "z": -3,
      "name": "Rock_Shale"
    },
    {
      "x": -4,
      "y": 16,
      "z": -3,
      "name": "Rock_Shale"
    },
    {
      "x": -4,
      "y": 17,
      "z": -3,
      "name": "Rock_Shale"
    },
    {
      "x": -4,
      "y": 18,
      "z": -3,
      "name": "Rock_Shale"
    },
    {
      "x": -4,
      "y": 19,
      "z": -3,
      "name": "Rock_Shale"
    },
    {
      "x": -4,
      "y": 20,
      "z": -3,
      "name": "Rock_Shale"
    },
    {
      "x": -4,
      "y": 21,
      "z": -3,
      "name": "Rock_Shale"
    },
    {
      "x": -4,
      "y": 22,
      "z": -3,
      "name": "Rock_Shale"
    },
    {
      "x": -4,
      "y": 23,
      "z": -3,
      "name": "Rock_Shale"
    },
    {
      "x": -4,
      "y": 24,
      "z": -3,
      "name": "Rock_Shale"
    },
    {
      "x": -4,
      "y": 25,
      "z": -3,
      "name": "Rock_Shale"
    },
    {
      "x": -4,
      "y": 26,
      "z": -3,
      "name": "Rock_Shale"
    },
    {
      "x": -4,
      "y": 27,
      "z": -3,
      "name": "Rock_Shale"
    },
    {
      "x": -4,
      "y": 0,
      "z": -2,
      "name": "Rock_Shale"
    },
    {
      "x": -4,
      "y": 1,
      "z": -2,
      "name": "Rock_Shale"
    },
    {
      "x": -4,
      "y": 2,
      "z": -2,
      "name": "Rock_Shale"
    },
    {
      "x": -4,
      "y": 3,
      "z": -2,
      "name": "Rock_Shale"
    },
    {
      "x": -4,
      "y": 17,
      "z": -2,
      "name": "Rock_Shale"
    },
    {
      "x": -4,
      "y": 18,
      "z": -2,
      "name": "Rock_Shale"
    },
    {
      "x": -4,
      "y": 19,
      "z": -2,
      "name": "Rock_Shale"
    },
    {
      "x": -4,
      "y": 20,
      "z": -2,
      "name": "Rock_Shale"
    },
    {
      "x": -4,
      "y": 21,
      "z": -2,
      "name": "Rock_Shale"
    },
    {
      "x": -4,
      "y": 22,
      "z": -2,
      "name": "Rock_Shale"
    },
    {
      "x": -4,
      "y": 23,
      "z": -2,
      "name": "Rock_Shale"
    },
    {
      "x": -4,
      "y": 24,
      "z": -2,
      "name": "Rock_Shale"
    },
    {
      "x": -4,
      "y": 25,
      "z": -2,
      "name": "Rock_Shale"
    },
    {
      "x": -4,
      "y": 26,
      "z": -2,
      "name": "Rock_Shale"
    },
    {
      "x": -4,
      "y": 27,
      "z": -2,
      "name": "Rock_Shale"
    },
    {
      "x": -4,
      "y": 0,
      "z": -1,
      "name": "Rock_Shale"
    },
    {
      "x": -4,
      "y": 1,
      "z": -1,
      "name": "Rock_Shale"
    },
    {
      "x": -4,
      "y": 2,
      "z": -1,
      "name": "Rock_Shale"
    },
    {
      "x": -4,
      "y": 3,
      "z": -1,
      "name": "Rock_Shale"
    },
    {
      "x": -4,
      "y": 4,
      "z": -1,
      "name": "Rock_Shale"
    },
    {
      "x": -4,
      "y": 5,
      "z": -1,
      "name": "Rock_Shale_Stalactites_Small"
    },
    {
      "x": -4,
      "y": 17,
      "z": -1,
      "name": "Rock_Shale"
    },
    {
      "x": -4,
      "y": 18,
      "z": -1,
      "name": "Rock_Shale"
    },
    {
      "x": -4,
      "y": 19,
      "z": -1,
      "name": "Rock_Shale"
    },
    {
      "x": -4,
      "y": 20,
      "z": -1,
      "name": "Rock_Shale"
    },
    {
      "x": -4,
      "y": 21,
      "z": -1,
      "name": "Rock_Shale"
    },
    {
      "x": -4,
      "y": 22,
      "z": -1,
      "name": "Rock_Shale"
    },
    {
      "x": -4,
      "y": 23,
      "z": -1,
      "name": "Rock_Shale"
    },
    {
      "x": -4,
      "y": 24,
      "z": -1,
      "name": "Rock_Shale"
    },
    {
      "x": -4,
      "y": 25,
      "z": -1,
      "name": "Rock_Shale"
    },
    {
      "x": -4,
      "y": 26,
      "z": -1,
      "name": "Rock_Shale"
    },
    {
      "x": -4,
      "y": 27,
      "z": -1,
      "name": "Rock_Shale"
    },
    {
      "x": -4,
      "y": 28,
      "z": -1,
      "name": "Rock_Shale"
    },
    {
      "x": -4,
      "y": 0,
      "z": 0,
      "name": "Rock_Shale"
    },
    {
      "x": -4,
      "y": 1,
      "z": 0,
      "name": "Rock_Shale"
    },
    {
      "x": -4,
      "y": 2,
      "z": 0,
      "name": "Wood_Giantwood_Trunk_Tainted_Full",
      "support": 15
    },
    {
      "x": -4,
      "y": 3,
      "z": 0,
      "name": "Wood_Giantwood_Trunk_Tainted_Full",
      "support": 15
    },
    {
      "x": -4,
      "y": 4,
      "z": 0,
      "name": "Plant_Roots_Rug_Tainted",
      "support": 15
    },
    {
      "x": -4,
      "y": 15,
      "z": 0,
      "name": "Rock_Shale"
    },
    {
      "x": -4,
      "y": 16,
      "z": 0,
      "name": "Rock_Shale"
    },
    {
      "x": -4,
      "y": 17,
      "z": 0,
      "name": "Rock_Shale"
    },
    {
      "x": -4,
      "y": 18,
      "z": 0,
      "name": "Rock_Shale"
    },
    {
      "x": -4,
      "y": 19,
      "z": 0,
      "name": "Rock_Shale"
    },
    {
      "x": -4,
      "y": 20,
      "z": 0,
      "name": "Rock_Shale"
    },
    {
      "x": -4,
      "y": 21,
      "z": 0,
      "name": "Rock_Shale"
    },
    {
      "x": -4,
      "y": 22,
      "z": 0,
      "name": "Rock_Shale"
    },
    {
      "x": -4,
      "y": 23,
      "z": 0,
      "name": "Rock_Shale"
    },
    {
      "x": -4,
      "y": 24,
      "z": 0,
      "name": "Rock_Shale"
    },
    {
      "x": -4,
      "y": 25,
      "z": 0,
      "name": "Rock_Shale"
    },
    {
      "x": -4,
      "y": 26,
      "z": 0,
      "name": "Rock_Shale"
    },
    {
      "x": -4,
      "y": 27,
      "z": 0,
      "name": "Rock_Shale"
    },
    {
      "x": -4,
      "y": 28,
      "z": 0,
      "name": "Rock_Shale"
    },
    {
      "x": -4,
      "y": 0,
      "z": 1,
      "name": "Wood_Giantwood_Trunk_Tainted_Full",
      "support": 15
    },
    {
      "x": -4,
      "y": 1,
      "z": 1,
      "name": "Wood_Giantwood_Trunk_Tainted_Full",
      "support": 15
    },
    {
      "x": -4,
      "y": 2,
      "z": 1,
      "name": "Wood_Giantwood_Trunk_Tainted_Full",
      "support": 15
    },
    {
      "x": -4,
      "y": 3,
      "z": 1,
      "name": "Wood_Giantwood_Trunk_Tainted_Full",
      "support": 15
    },
    {
      "x": -4,
      "y": 4,
      "z": 1,
      "name": "Plant_Mushroom_Rug_White_Mycelium",
      "support": 15
    },
    {
      "x": -4,
      "y": 16,
      "z": 1,
      "name": "Rock_Shale"
    },
    {
      "x": -4,
      "y": 17,
      "z": 1,
      "name": "Rock_Shale"
    },
    {
      "x": -4,
      "y": 18,
      "z": 1,
      "name": "Rock_Shale"
    },
    {
      "x": -4,
      "y": 19,
      "z": 1,
      "name": "Rock_Shale"
    },
    {
      "x": -4,
      "y": 20,
      "z": 1,
      "name": "Rock_Shale"
    },
    {
      "x": -4,
      "y": 21,
      "z": 1,
      "name": "Rock_Shale"
    },
    {
      "x": -4,
      "y": 22,
      "z": 1,
      "name": "Rock_Shale"
    },
    {
      "x": -4,
      "y": 23,
      "z": 1,
      "name": "Rock_Shale"
    },
    {
      "x": -4,
      "y": 24,
      "z": 1,
      "name": "Rock_Shale"
    },
    {
      "x": -4,
      "y": 25,
      "z": 1,
      "name": "Rock_Shale"
    },
    {
      "x": -4,
      "y": 26,
      "z": 1,
      "name": "Rock_Shale"
    },
    {
      "x": -4,
      "y": 27,
      "z": 1,
      "name": "Rock_Shale"
    },
    {
      "x": -4,
      "y": 0,
      "z": 2,
      "name": "Wood_Giantwood_Trunk_Tainted_Full",
      "support": 15
    },
    {
      "x": -4,
      "y": 1,
      "z": 2,
      "name": "Wood_Giantwood_Trunk_Tainted_Full",
      "support": 15
    },
    {
      "x": -4,
      "y": 2,
      "z": 2,
      "name": "Wood_Giantwood_Trunk_Tainted_Full",
      "support": 15
    },
    {
      "x": -4,
      "y": 3,
      "z": 2,
      "name": "Plant_Mushroom_Rug_White_Mycelium",
      "support": 15
    },
    {
      "x": -4,
      "y": 4,
      "z": 2,
      "name": "Plant_Mushroom_Wall_White_Mycelium",
      "support": 15,
      "rotation": 3
    },
    {
      "x": -4,
      "y": 18,
      "z": 2,
      "name": "Rock_Shale"
    },
    {
      "x": -4,
      "y": 19,
      "z": 2,
      "name": "Rock_Shale"
    },
    {
      "x": -4,
      "y": 20,
      "z": 2,
      "name": "Rock_Shale"
    },
    {
      "x": -4,
      "y": 21,
      "z": 2,
      "name": "Rock_Shale"
    },
    {
      "x": -4,
      "y": 22,
      "z": 2,
      "name": "Rock_Shale"
    },
    {
      "x": -4,
      "y": 23,
      "z": 2,
      "name": "Rock_Shale"
    },
    {
      "x": -4,
      "y": 24,
      "z": 2,
      "name": "Rock_Shale"
    },
    {
      "x": -4,
      "y": 25,
      "z": 2,
      "name": "Rock_Shale"
    },
    {
      "x": -4,
      "y": 26,
      "z": 2,
      "name": "Rock_Shale"
    },
    {
      "x": -4,
      "y": 27,
      "z": 2,
      "name": "Rock_Shale"
    },
    {
      "x": -4,
      "y": 0,
      "z": 3,
      "name": "Rock_Shale"
    },
    {
      "x": -4,
      "y": 1,
      "z": 3,
      "name": "Rock_Shale"
    },
    {
      "x": -4,
      "y": 2,
      "z": 3,
      "name": "Rock_Shale"
    },
    {
      "x": -4,
      "y": 3,
      "z": 3,
      "name": "Rock_Shale"
    },
    {
      "x": -4,
      "y": 4,
      "z": 3,
      "name": "Plant_Mushroom_Short_White_Mycelium",
      "support": 15
    },
    {
      "x": -4,
      "y": 19,
      "z": 3,
      "name": "Rock_Shale"
    },
    {
      "x": -4,
      "y": 20,
      "z": 3,
      "name": "Rock_Shale"
    },
    {
      "x": -4,
      "y": 21,
      "z": 3,
      "name": "Rock_Shale"
    },
    {
      "x": -4,
      "y": 22,
      "z": 3,
      "name": "Rock_Shale"
    },
    {
      "x": -4,
      "y": 23,
      "z": 3,
      "name": "Rock_Shale"
    },
    {
      "x": -4,
      "y": 24,
      "z": 3,
      "name": "Rock_Shale"
    },
    {
      "x": -4,
      "y": 25,
      "z": 3,
      "name": "Rock_Shale"
    },
    {
      "x": -4,
      "y": 26,
      "z": 3,
      "name": "Rock_Shale"
    },
    {
      "x": -4,
      "y": 0,
      "z": 4,
      "name": "Rock_Shale"
    },
    {
      "x": -4,
      "y": 1,
      "z": 4,
      "name": "Rock_Shale"
    },
    {
      "x": -4,
      "y": 2,
      "z": 4,
      "name": "Rock_Shale"
    },
    {
      "x": -4,
      "y": 3,
      "z": 4,
      "name": "Rock_Shale"
    },
    {
      "x": -4,
      "y": 4,
      "z": 4,
      "name": "Rock_Shale_Stalactites_Large"
    },
    {
      "x": -4,
      "y": 5,
      "z": 4,
      "name": "Rock_Shale_Stalactites_Large",
      "filler": 1024
    },
    {
      "x": -4,
      "y": 20,
      "z": 4,
      "name": "Rock_Shale"
    },
    {
      "x": -4,
      "y": 21,
      "z": 4,
      "name": "Rock_Shale"
    },
    {
      "x": -4,
      "y": 22,
      "z": 4,
      "name": "Rock_Shale"
    },
    {
      "x": -4,
      "y": 23,
      "z": 4,
      "name": "Rock_Shale"
    },
    {
      "x": -4,
      "y": 24,
      "z": 4,
      "name": "Rock_Shale"
    },
    {
      "x": -4,
      "y": 25,
      "z": 4,
      "name": "Rock_Shale"
    },
    {
      "x": -4,
      "y": 26,
      "z": 4,
      "name": "Rock_Shale"
    },
    {
      "x": -4,
      "y": 0,
      "z": 5,
      "name": "Rock_Shale"
    },
    {
      "x": -4,
      "y": 1,
      "z": 5,
      "name": "Rock_Shale"
    },
    {
      "x": -4,
      "y": 2,
      "z": 5,
      "name": "Rock_Shale"
    },
    {
      "x": -4,
      "y": 3,
      "z": 5,
      "name": "Plant_Mushroom_Rug_White_Mycelium",
      "support": 15
    },
    {
      "x": -4,
      "y": 21,
      "z": 5,
      "name": "Rock_Shale"
    },
    {
      "x": -4,
      "y": 22,
      "z": 5,
      "name": "Rock_Shale"
    },
    {
      "x": -4,
      "y": 23,
      "z": 5,
      "name": "Rock_Shale"
    },
    {
      "x": -4,
      "y": 24,
      "z": 5,
      "name": "Rock_Shale"
    },
    {
      "x": -4,
      "y": 25,
      "z": 5,
      "name": "Rock_Shale"
    },
    {
      "x": -4,
      "y": 26,
      "z": 5,
      "name": "Rock_Shale"
    },
    {
      "x": -4,
      "y": 2,
      "z": 6,
      "name": "Plant_Mushroom_Wall_White_Mycelium",
      "support": 15
    },
    {
      "x": -4,
      "y": 22,
      "z": 6,
      "name": "Rock_Shale"
    },
    {
      "x": -4,
      "y": 23,
      "z": 6,
      "name": "Rock_Shale"
    },
    {
      "x": -4,
      "y": 24,
      "z": 6,
      "name": "Rock_Shale"
    },
    {
      "x": -4,
      "y": 25,
      "z": 6,
      "name": "Rock_Shale"
    },
    {
      "x": -4,
      "y": 26,
      "z": 6,
      "name": "Rock_Shale"
    },
    {
      "x": -3,
      "y": 25,
      "z": -7,
      "name": "Rock_Shale"
    },
    {
      "x": -3,
      "y": 26,
      "z": -7,
      "name": "Rock_Shale"
    },
    {
      "x": -3,
      "y": 21,
      "z": -6,
      "name": "Rock_Shale"
    },
    {
      "x": -3,
      "y": 22,
      "z": -6,
      "name": "Rock_Shale"
    },
    {
      "x": -3,
      "y": 23,
      "z": -6,
      "name": "Rock_Shale"
    },
    {
      "x": -3,
      "y": 24,
      "z": -6,
      "name": "Rock_Shale"
    },
    {
      "x": -3,
      "y": 25,
      "z": -6,
      "name": "Rock_Shale"
    },
    {
      "x": -3,
      "y": 26,
      "z": -6,
      "name": "Rock_Shale"
    },
    {
      "x": -3,
      "y": 19,
      "z": -5,
      "name": "Rock_Shale"
    },
    {
      "x": -3,
      "y": 20,
      "z": -5,
      "name": "Rock_Shale"
    },
    {
      "x": -3,
      "y": 21,
      "z": -5,
      "name": "Rock_Shale"
    },
    {
      "x": -3,
      "y": 22,
      "z": -5,
      "name": "Rock_Shale"
    },
    {
      "x": -3,
      "y": 23,
      "z": -5,
      "name": "Rock_Shale"
    },
    {
      "x": -3,
      "y": 24,
      "z": -5,
      "name": "Rock_Shale"
    },
    {
      "x": -3,
      "y": 25,
      "z": -5,
      "name": "Rock_Shale"
    },
    {
      "x": -3,
      "y": 26,
      "z": -5,
      "name": "Rock_Shale"
    },
    {
      "x": -3,
      "y": 27,
      "z": -5,
      "name": "Rock_Shale"
    },
    {
      "x": -3,
      "y": 0,
      "z": -4,
      "name": "Rock_Shale"
    },
    {
      "x": -3,
      "y": 1,
      "z": -4,
      "name": "Plant_Mushroom_Rug_White_Mycelium",
      "support": 15
    },
    {
      "x": -3,
      "y": 18,
      "z": -4,
      "name": "Rock_Shale"
    },
    {
      "x": -3,
      "y": 19,
      "z": -4,
      "name": "Rock_Shale"
    },
    {
      "x": -3,
      "y": 20,
      "z": -4,
      "name": "Rock_Shale"
    },
    {
      "x": -3,
      "y": 21,
      "z": -4,
      "name": "Rock_Shale"
    },
    {
      "x": -3,
      "y": 22,
      "z": -4,
      "name": "Rock_Shale"
    },
    {
      "x": -3,
      "y": 23,
      "z": -4,
      "name": "Rock_Shale"
    },
    {
      "x": -3,
      "y": 24,
      "z": -4,
      "name": "Rock_Shale"
    },
    {
      "x": -3,
      "y": 25,
      "z": -4,
      "name": "Rock_Shale"
    },
    {
      "x": -3,
      "y": 26,
      "z": -4,
      "name": "Rock_Shale"
    },
    {
      "x": -3,
      "y": 27,
      "z": -4,
      "name": "Rock_Shale"
    },
    {
      "x": -3,
      "y": 0,
      "z": -3,
      "name": "Wood_Giantwood_Trunk_Tainted_Full",
      "support": 15
    },
    {
      "x": -3,
      "y": 1,
      "z": -3,
      "name": "Wood_Giantwood_Trunk_Tainted_Full",
      "support": 15
    },
    {
      "x": -3,
      "y": 2,
      "z": -3,
      "name": "Plant_Mushroom_Rug_White_Mycelium",
      "support": 15
    },
    {
      "x": -3,
      "y": 15,
      "z": -3,
      "name": "Rock_Shale"
    },
    {
      "x": -3,
      "y": 16,
      "z": -3,
      "name": "Rock_Shale"
    },
    {
      "x": -3,
      "y": 17,
      "z": -3,
      "name": "Rock_Shale"
    },
    {
      "x": -3,
      "y": 18,
      "z": -3,
      "name": "Rock_Shale"
    },
    {
      "x": -3,
      "y": 19,
      "z": -3,
      "name": "Rock_Shale"
    },
    {
      "x": -3,
      "y": 20,
      "z": -3,
      "name": "Rock_Shale"
    },
    {
      "x": -3,
      "y": 21,
      "z": -3,
      "name": "Rock_Shale"
    },
    {
      "x": -3,
      "y": 22,
      "z": -3,
      "name": "Rock_Shale"
    },
    {
      "x": -3,
      "y": 23,
      "z": -3,
      "name": "Rock_Shale"
    },
    {
      "x": -3,
      "y": 24,
      "z": -3,
      "name": "Rock_Shale"
    },
    {
      "x": -3,
      "y": 25,
      "z": -3,
      "name": "Rock_Shale"
    },
    {
      "x": -3,
      "y": 26,
      "z": -3,
      "name": "Rock_Shale"
    },
    {
      "x": -3,
      "y": 27,
      "z": -3,
      "name": "Rock_Shale"
    },
    {
      "x": -3,
      "y": 0,
      "z": -2,
      "name": "Wood_Giantwood_Trunk_Tainted_Full",
      "support": 15
    },
    {
      "x": -3,
      "y": 1,
      "z": -2,
      "name": "Wood_Giantwood_Trunk_Tainted_Full",
      "support": 15
    },
    {
      "x": -3,
      "y": 2,
      "z": -2,
      "name": "Wood_Giantwood_Trunk_Tainted_Full",
      "support": 15,
      "rotation": 4
    },
    {
      "x": -3,
      "y": 3,
      "z": -2,
      "name": "Wood_Giantwood_Trunk_Tainted_Full",
      "support": 15
    },
    {
      "x": -3,
      "y": 4,
      "z": -2,
      "name": "Plant_Roots_Rug_Tainted",
      "support": 15
    },
    {
      "x": -3,
      "y": 15,
      "z": -2,
      "name": "Rock_Shale"
    },
    {
      "x": -3,
      "y": 16,
      "z": -2,
      "name": "Rock_Shale"
    },
    {
      "x": -3,
      "y": 17,
      "z": -2,
      "name": "Rock_Shale"
    },
    {
      "x": -3,
      "y": 18,
      "z": -2,
      "name": "Rock_Shale"
    },
    {
      "x": -3,
      "y": 19,
      "z": -2,
      "name": "Rock_Shale"
    },
    {
      "x": -3,
      "y": 20,
      "z": -2,
      "name": "Rock_Shale"
    },
    {
      "x": -3,
      "y": 21,
      "z": -2,
      "name": "Rock_Shale"
    },
    {
      "x": -3,
      "y": 22,
      "z": -2,
      "name": "Rock_Shale"
    },
    {
      "x": -3,
      "y": 23,
      "z": -2,
      "name": "Rock_Shale"
    },
    {
      "x": -3,
      "y": 24,
      "z": -2,
      "name": "Rock_Shale"
    },
    {
      "x": -3,
      "y": 25,
      "z": -2,
      "name": "Rock_Shale"
    },
    {
      "x": -3,
      "y": 26,
      "z": -2,
      "name": "Rock_Shale"
    },
    {
      "x": -3,
      "y": 27,
      "z": -2,
      "name": "Rock_Shale"
    },
    {
      "x": -3,
      "y": 28,
      "z": -2,
      "name": "Rock_Shale"
    },
    {
      "x": -3,
      "y": 0,
      "z": -1,
      "name": "Wood_Giantwood_Trunk_Tainted_Full",
      "support": 15
    },
    {
      "x": -3,
      "y": 1,
      "z": -1,
      "name": "Wood_Giantwood_Trunk_Tainted_Full",
      "support": 15
    },
    {
      "x": -3,
      "y": 2,
      "z": -1,
      "name": "Rock_Shale"
    },
    {
      "x": -3,
      "y": 3,
      "z": -1,
      "name": "Wood_Giantwood_Trunk_Tainted_Full",
      "support": 15
    },
    {
      "x": -3,
      "y": 12,
      "z": -1,
      "name": "Rock_Shale_Stalactites_Large",
      "filler": 31744,
      "rotation": 8
    },
    {
      "x": -3,
      "y": 13,
      "z": -1,
      "name": "Rock_Shale_Stalactites_Large",
      "rotation": 8
    },
    {
      "x": -3,
      "y": 14,
      "z": -1,
      "name": "Rock_Shale"
    },
    {
      "x": -3,
      "y": 15,
      "z": -1,
      "name": "Rock_Shale"
    },
    {
      "x": -3,
      "y": 16,
      "z": -1,
      "name": "Rock_Shale"
    },
    {
      "x": -3,
      "y": 17,
      "z": -1,
      "name": "Rock_Shale"
    },
    {
      "x": -3,
      "y": 18,
      "z": -1,
      "name": "Rock_Shale"
    },
    {
      "x": -3,
      "y": 19,
      "z": -1,
      "name": "Rock_Shale"
    },
    {
      "x": -3,
      "y": 20,
      "z": -1,
      "name": "Rock_Shale"
    },
    {
      "x": -3,
      "y": 21,
      "z": -1,
      "name": "Rock_Shale"
    },
    {
      "x": -3,
      "y": 22,
      "z": -1,
      "name": "Rock_Shale"
    },
    {
      "x": -3,
      "y": 23,
      "z": -1,
      "name": "Rock_Shale"
    },
    {
      "x": -3,
      "y": 24,
      "z": -1,
      "name": "Rock_Shale"
    },
    {
      "x": -3,
      "y": 25,
      "z": -1,
      "name": "Rock_Shale"
    },
    {
      "x": -3,
      "y": 26,
      "z": -1,
      "name": "Rock_Shale"
    },
    {
      "x": -3,
      "y": 27,
      "z": -1,
      "name": "Rock_Shale"
    },
    {
      "x": -3,
      "y": 28,
      "z": -1,
      "name": "Rock_Shale"
    },
    {
      "x": -3,
      "y": 0,
      "z": 0,
      "name": "Wood_Giantwood_Trunk_Tainted_Full",
      "support": 15
    },
    {
      "x": -3,
      "y": 1,
      "z": 0,
      "name": "Wood_Giantwood_Trunk_Tainted_Full",
      "support": 15
    },
    {
      "x": -3,
      "y": 2,
      "z": 0,
      "name": "Wood_Giantwood_Trunk_Tainted_Full",
      "support": 15
    },
    {
      "x": -3,
      "y": 3,
      "z": 0,
      "name": "Wood_Giantwood_Trunk_Tainted_Full",
      "support": 15
    },
    {
      "x": -3,
      "y": 4,
      "z": 0,
      "name": "Wood_Giantwood_Trunk_Tainted_Full",
      "support": 15
    },
    {
      "x": -3,
      "y": 5,
      "z": 0,
      "name": "Plant_Mushroom_Rug_White_Mycelium",
      "support": 15
    },
    {
      "x": -3,
      "y": 14,
      "z": 0,
      "name": "Rock_Shale"
    },
    {
      "x": -3,
      "y": 15,
      "z": 0,
      "name": "Rock_Shale"
    },
    {
      "x": -3,
      "y": 16,
      "z": 0,
      "name": "Rock_Shale"
    },
    {
      "x": -3,
      "y": 18,
      "z": 0,
      "name": "Rock_Shale"
    },
    {
      "x": -3,
      "y": 19,
      "z": 0,
      "name": "Rock_Shale"
    },
    {
      "x": -3,
      "y": 20,
      "z": 0,
      "name": "Rock_Shale"
    },
    {
      "x": -3,
      "y": 21,
      "z": 0,
      "name": "Rock_Shale"
    },
    {
      "x": -3,
      "y": 22,
      "z": 0,
      "name": "Rock_Shale"
    },
    {
      "x": -3,
      "y": 23,
      "z": 0,
      "name": "Rock_Shale"
    },
    {
      "x": -3,
      "y": 24,
      "z": 0,
      "name": "Rock_Shale"
    },
    {
      "x": -3,
      "y": 25,
      "z": 0,
      "name": "Rock_Shale"
    },
    {
      "x": -3,
      "y": 26,
      "z": 0,
      "name": "Rock_Shale"
    },
    {
      "x": -3,
      "y": 27,
      "z": 0,
      "name": "Rock_Shale"
    },
    {
      "x": -3,
      "y": 28,
      "z": 0,
      "name": "Rock_Shale"
    },
    {
      "x": -3,
      "y": 0,
      "z": 1,
      "name": "Wood_Giantwood_Trunk_Tainted_Full",
      "support": 15
    },
    {
      "x": -3,
      "y": 1,
      "z": 1,
      "name": "Wood_Giantwood_Trunk_Tainted_Full",
      "support": 15
    },
    {
      "x": -3,
      "y": 2,
      "z": 1,
      "name": "Wood_Giantwood_Trunk_Tainted_Full",
      "support": 15
    },
    {
      "x": -3,
      "y": 3,
      "z": 1,
      "name": "Wood_Giantwood_Trunk_Tainted_Full",
      "support": 15
    },
    {
      "x": -3,
      "y": 4,
      "z": 1,
      "name": "Plant_Mushroom_Rug_White_Mycelium",
      "support": 15
    },
    {
      "x": -3,
      "y": 13,
      "z": 1,
      "name": "Wood_Giantwood_Trunk_Tainted_Full",
      "support": 15
    },
    {
      "x": -3,
      "y": 14,
      "z": 1,
      "name": "Rock_Shale"
    },
    {
      "x": -3,
      "y": 15,
      "z": 1,
      "name": "Rock_Shale"
    },
    {
      "x": -3,
      "y": 16,
      "z": 1,
      "name": "Rock_Shale"
    },
    {
      "x": -3,
      "y": 17,
      "z": 1,
      "name": "Rock_Shale"
    },
    {
      "x": -3,
      "y": 18,
      "z": 1,
      "name": "Rock_Shale"
    },
    {
      "x": -3,
      "y": 19,
      "z": 1,
      "name": "Rock_Shale"
    },
    {
      "x": -3,
      "y": 20,
      "z": 1,
      "name": "Rock_Shale"
    },
    {
      "x": -3,
      "y": 21,
      "z": 1,
      "name": "Rock_Shale"
    },
    {
      "x": -3,
      "y": 22,
      "z": 1,
      "name": "Rock_Shale"
    },
    {
      "x": -3,
      "y": 23,
      "z": 1,
      "name": "Rock_Shale"
    },
    {
      "x": -3,
      "y": 24,
      "z": 1,
      "name": "Rock_Shale"
    },
    {
      "x": -3,
      "y": 25,
      "z": 1,
      "name": "Rock_Shale"
    },
    {
      "x": -3,
      "y": 26,
      "z": 1,
      "name": "Rock_Shale"
    },
    {
      "x": -3,
      "y": 27,
      "z": 1,
      "name": "Rock_Shale"
    },
    {
      "x": -3,
      "y": 28,
      "z": 1,
      "name": "Rock_Shale"
    },
    {
      "x": -3,
      "y": 0,
      "z": 2,
      "name": "Wood_Giantwood_Trunk_Tainted_Full",
      "support": 15
    },
    {
      "x": -3,
      "y": 1,
      "z": 2,
      "name": "Wood_Giantwood_Trunk_Tainted_Full",
      "support": 15
    },
    {
      "x": -3,
      "y": 2,
      "z": 2,
      "name": "Wood_Giantwood_Trunk_Tainted_Full",
      "support": 15
    },
    {
      "x": -3,
      "y": 3,
      "z": 2,
      "name": "Wood_Giantwood_Trunk_Tainted_Full",
      "support": 15
    },
    {
      "x": -3,
      "y": 4,
      "z": 2,
      "name": "Wood_Giantwood_Trunk_Tainted_Full",
      "support": 15
    },
    {
      "x": -3,
      "y": 5,
      "z": 2,
      "name": "Plant_Mushroom_Rug_White_Mycelium",
      "support": 15
    },
    {
      "x": -3,
      "y": 15,
      "z": 2,
      "name": "Rock_Shale"
    },
    {
      "x": -3,
      "y": 16,
      "z": 2,
      "name": "Rock_Shale"
    },
    {
      "x": -3,
      "y": 17,
      "z": 2,
      "name": "Rock_Shale"
    },
    {
      "x": -3,
      "y": 18,
      "z": 2,
      "name": "Rock_Shale"
    },
    {
      "x": -3,
      "y": 19,
      "z": 2,
      "name": "Rock_Shale"
    },
    {
      "x": -3,
      "y": 20,
      "z": 2,
      "name": "Rock_Shale"
    },
    {
      "x": -3,
      "y": 21,
      "z": 2,
      "name": "Rock_Shale"
    },
    {
      "x": -3,
      "y": 22,
      "z": 2,
      "name": "Rock_Shale"
    },
    {
      "x": -3,
      "y": 23,
      "z": 2,
      "name": "Rock_Shale"
    },
    {
      "x": -3,
      "y": 24,
      "z": 2,
      "name": "Rock_Shale"
    },
    {
      "x": -3,
      "y": 25,
      "z": 2,
      "name": "Rock_Shale"
    },
    {
      "x": -3,
      "y": 26,
      "z": 2,
      "name": "Rock_Shale"
    },
    {
      "x": -3,
      "y": 27,
      "z": 2,
      "name": "Rock_Shale"
    },
    {
      "x": -3,
      "y": 0,
      "z": 3,
      "name": "Rock_Shale"
    },
    {
      "x": -3,
      "y": 1,
      "z": 3,
      "name": "Rock_Shale"
    },
    {
      "x": -3,
      "y": 2,
      "z": 3,
      "name": "Plant_Mushroom_Block_White_Mycelium",
      "support": 15
    },
    {
      "x": -3,
      "y": 3,
      "z": 3,
      "name": "Plant_Crop_Mushroom_Funnel_Tainted"
    },
    {
      "x": -3,
      "y": 4,
      "z": 3,
      "name": "Plant_Mushroom_Wall_White_Mycelium",
      "support": 15
    },
    {
      "x": -3,
      "y": 17,
      "z": 3,
      "name": "Rock_Shale"
    },
    {
      "x": -3,
      "y": 18,
      "z": 3,
      "name": "Rock_Shale"
    },
    {
      "x": -3,
      "y": 19,
      "z": 3,
      "name": "Rock_Shale"
    },
    {
      "x": -3,
      "y": 20,
      "z": 3,
      "name": "Rock_Shale"
    },
    {
      "x": -3,
      "y": 21,
      "z": 3,
      "name": "Rock_Shale"
    },
    {
      "x": -3,
      "y": 22,
      "z": 3,
      "name": "Rock_Shale"
    },
    {
      "x": -3,
      "y": 23,
      "z": 3,
      "name": "Rock_Shale"
    },
    {
      "x": -3,
      "y": 24,
      "z": 3,
      "name": "Rock_Shale"
    },
    {
      "x": -3,
      "y": 25,
      "z": 3,
      "name": "Rock_Shale"
    },
    {
      "x": -3,
      "y": 26,
      "z": 3,
      "name": "Rock_Shale"
    },
    {
      "x": -3,
      "y": 27,
      "z": 3,
      "name": "Rock_Shale"
    },
    {
      "x": -3,
      "y": 0,
      "z": 4,
      "name": "Rock_Shale"
    },
    {
      "x": -3,
      "y": 1,
      "z": 4,
      "name": "Rock_Shale"
    },
    {
      "x": -3,
      "y": 2,
      "z": 4,
      "name": "Rock_Shale"
    },
    {
      "x": -3,
      "y": 3,
      "z": 4,
      "name": "Plant_Mushroom_Rug_White_Mycelium",
      "support": 15
    },
    {
      "x": -3,
      "y": 18,
      "z": 4,
      "name": "Rock_Shale"
    },
    {
      "x": -3,
      "y": 19,
      "z": 4,
      "name": "Rock_Shale"
    },
    {
      "x": -3,
      "y": 20,
      "z": 4,
      "name": "Rock_Shale"
    },
    {
      "x": -3,
      "y": 21,
      "z": 4,
      "name": "Rock_Shale"
    },
    {
      "x": -3,
      "y": 22,
      "z": 4,
      "name": "Rock_Shale"
    },
    {
      "x": -3,
      "y": 23,
      "z": 4,
      "name": "Rock_Shale"
    },
    {
      "x": -3,
      "y": 24,
      "z": 4,
      "name": "Rock_Shale"
    },
    {
      "x": -3,
      "y": 25,
      "z": 4,
      "name": "Rock_Shale"
    },
    {
      "x": -3,
      "y": 26,
      "z": 4,
      "name": "Rock_Shale"
    },
    {
      "x": -3,
      "y": 27,
      "z": 4,
      "name": "Rock_Shale"
    },
    {
      "x": -3,
      "y": 2,
      "z": 5,
      "name": "Plant_Mushroom_Wall_White_Mycelium",
      "support": 15,
      "rotation": 1
    },
    {
      "x": -3,
      "y": 18,
      "z": 5,
      "name": "Rock_Shale"
    },
    {
      "x": -3,
      "y": 19,
      "z": 5,
      "name": "Rock_Shale"
    },
    {
      "x": -3,
      "y": 20,
      "z": 5,
      "name": "Rock_Shale"
    },
    {
      "x": -3,
      "y": 21,
      "z": 5,
      "name": "Rock_Shale"
    },
    {
      "x": -3,
      "y": 22,
      "z": 5,
      "name": "Rock_Shale"
    },
    {
      "x": -3,
      "y": 23,
      "z": 5,
      "name": "Rock_Shale"
    },
    {
      "x": -3,
      "y": 24,
      "z": 5,
      "name": "Rock_Shale"
    },
    {
      "x": -3,
      "y": 25,
      "z": 5,
      "name": "Rock_Shale"
    },
    {
      "x": -3,
      "y": 26,
      "z": 5,
      "name": "Rock_Shale"
    },
    {
      "x": -3,
      "y": 27,
      "z": 5,
      "name": "Rock_Shale"
    },
    {
      "x": -3,
      "y": 21,
      "z": 6,
      "name": "Rock_Shale"
    },
    {
      "x": -3,
      "y": 22,
      "z": 6,
      "name": "Rock_Shale"
    },
    {
      "x": -3,
      "y": 23,
      "z": 6,
      "name": "Rock_Shale"
    },
    {
      "x": -3,
      "y": 24,
      "z": 6,
      "name": "Rock_Shale"
    },
    {
      "x": -3,
      "y": 25,
      "z": 6,
      "name": "Rock_Shale"
    },
    {
      "x": -3,
      "y": 26,
      "z": 6,
      "name": "Rock_Shale"
    },
    {
      "x": -2,
      "y": 23,
      "z": -7,
      "name": "Rock_Shale"
    },
    {
      "x": -2,
      "y": 24,
      "z": -7,
      "name": "Rock_Shale"
    },
    {
      "x": -2,
      "y": 25,
      "z": -7,
      "name": "Rock_Shale"
    },
    {
      "x": -2,
      "y": 26,
      "z": -7,
      "name": "Rock_Shale"
    },
    {
      "x": -2,
      "y": 21,
      "z": -6,
      "name": "Rock_Shale"
    },
    {
      "x": -2,
      "y": 22,
      "z": -6,
      "name": "Rock_Shale"
    },
    {
      "x": -2,
      "y": 23,
      "z": -6,
      "name": "Rock_Shale"
    },
    {
      "x": -2,
      "y": 24,
      "z": -6,
      "name": "Rock_Shale"
    },
    {
      "x": -2,
      "y": 25,
      "z": -6,
      "name": "Rock_Shale"
    },
    {
      "x": -2,
      "y": 26,
      "z": -6,
      "name": "Rock_Shale"
    },
    {
      "x": -2,
      "y": 18,
      "z": -5,
      "name": "Rock_Shale"
    },
    {
      "x": -2,
      "y": 19,
      "z": -5,
      "name": "Rock_Shale"
    },
    {
      "x": -2,
      "y": 20,
      "z": -5,
      "name": "Rock_Shale"
    },
    {
      "x": -2,
      "y": 21,
      "z": -5,
      "name": "Rock_Shale"
    },
    {
      "x": -2,
      "y": 22,
      "z": -5,
      "name": "Rock_Shale"
    },
    {
      "x": -2,
      "y": 23,
      "z": -5,
      "name": "Rock_Shale"
    },
    {
      "x": -2,
      "y": 24,
      "z": -5,
      "name": "Rock_Shale"
    },
    {
      "x": -2,
      "y": 25,
      "z": -5,
      "name": "Rock_Shale"
    },
    {
      "x": -2,
      "y": 26,
      "z": -5,
      "name": "Rock_Shale"
    },
    {
      "x": -2,
      "y": 27,
      "z": -5,
      "name": "Rock_Shale"
    },
    {
      "x": -2,
      "y": 0,
      "z": -4,
      "name": "Rock_Shale"
    },
    {
      "x": -2,
      "y": 1,
      "z": -4,
      "name": "Rock_Shale_Stalactites_Large"
    },
    {
      "x": -2,
      "y": 2,
      "z": -4,
      "name": "Rock_Shale_Stalactites_Large",
      "filler": 1024
    },
    {
      "x": -2,
      "y": 16,
      "z": -4,
      "name": "Rock_Shale"
    },
    {
      "x": -2,
      "y": 17,
      "z": -4,
      "name": "Rock_Shale"
    },
    {
      "x": -2,
      "y": 18,
      "z": -4,
      "name": "Rock_Shale"
    },
    {
      "x": -2,
      "y": 19,
      "z": -4,
      "name": "Rock_Shale"
    },
    {
      "x": -2,
      "y": 20,
      "z": -4,
      "name": "Rock_Shale"
    },
    {
      "x": -2,
      "y": 21,
      "z": -4,
      "name": "Rock_Shale"
    },
    {
      "x": -2,
      "y": 22,
      "z": -4,
      "name": "Rock_Shale"
    },
    {
      "x": -2,
      "y": 23,
      "z": -4,
      "name": "Rock_Shale"
    },
    {
      "x": -2,
      "y": 24,
      "z": -4,
      "name": "Rock_Shale"
    },
    {
      "x": -2,
      "y": 25,
      "z": -4,
      "name": "Rock_Shale"
    },
    {
      "x": -2,
      "y": 26,
      "z": -4,
      "name": "Rock_Shale"
    },
    {
      "x": -2,
      "y": 27,
      "z": -4,
      "name": "Rock_Shale"
    },
    {
      "x": -2,
      "y": 0,
      "z": -3,
      "name": "Wood_Giantwood_Trunk_Tainted_Full",
      "support": 15
    },
    {
      "x": -2,
      "y": 1,
      "z": -3,
      "name": "Wood_Giantwood_Trunk_Tainted_Full",
      "support": 15
    },
    {
      "x": -2,
      "y": 2,
      "z": -3,
      "name": "Wood_Giantwood_Trunk_Tainted_Full",
      "support": 15
    },
    {
      "x": -2,
      "y": 3,
      "z": -3,
      "name": "Plant_Mushroom_Rug_White_Mycelium",
      "support": 15
    },
    {
      "x": -2,
      "y": 15,
      "z": -3,
      "name": "Rock_Shale"
    },
    {
      "x": -2,
      "y": 16,
      "z": -3,
      "name": "Rock_Shale"
    },
    {
      "x": -2,
      "y": 17,
      "z": -3,
      "name": "Rock_Shale"
    },
    {
      "x": -2,
      "y": 18,
      "z": -3,
      "name": "Rock_Shale"
    },
    {
      "x": -2,
      "y": 19,
      "z": -3,
      "name": "Rock_Shale"
    },
    {
      "x": -2,
      "y": 20,
      "z": -3,
      "name": "Rock_Shale"
    },
    {
      "x": -2,
      "y": 21,
      "z": -3,
      "name": "Rock_Shale"
    },
    {
      "x": -2,
      "y": 22,
      "z": -3,
      "name": "Rock_Shale"
    },
    {
      "x": -2,
      "y": 23,
      "z": -3,
      "name": "Rock_Shale"
    },
    {
      "x": -2,
      "y": 24,
      "z": -3,
      "name": "Rock_Shale"
    },
    {
      "x": -2,
      "y": 25,
      "z": -3,
      "name": "Rock_Shale"
    },
    {
      "x": -2,
      "y": 26,
      "z": -3,
      "name": "Rock_Shale"
    },
    {
      "x": -2,
      "y": 27,
      "z": -3,
      "name": "Rock_Shale"
    },
    {
      "x": -2,
      "y": 28,
      "z": -3,
      "name": "Rock_Shale"
    },
    {
      "x": -2,
      "y": 0,
      "z": -2,
      "name": "Wood_Giantwood_Trunk_Tainted_Full",
      "support": 15
    },
    {
      "x": -2,
      "y": 1,
      "z": -2,
      "name": "Wood_Giantwood_Trunk_Tainted_Full",
      "support": 15
    },
    {
      "x": -2,
      "y": 2,
      "z": -2,
      "name": "Wood_Giantwood_Trunk_Tainted_Full",
      "support": 15
    },
    {
      "x": -2,
      "y": 3,
      "z": -2,
      "name": "Wood_Giantwood_Trunk_Tainted_Full",
      "support": 15
    },
    {
      "x": -2,
      "y": 4,
      "z": -2,
      "name": "Plant_Mushroom_Rug_White_Mycelium",
      "support": 15
    },
    {
      "x": -2,
      "y": 14,
      "z": -2,
      "name": "Rock_Shale"
    },
    {
      "x": -2,
      "y": 15,
      "z": -2,
      "name": "Rock_Shale"
    },
    {
      "x": -2,
      "y": 16,
      "z": -2,
      "name": "Rock_Shale"
    },
    {
      "x": -2,
      "y": 17,
      "z": -2,
      "name": "Rock_Shale"
    },
    {
      "x": -2,
      "y": 18,
      "z": -2,
      "name": "Rock_Shale"
    },
    {
      "x": -2,
      "y": 19,
      "z": -2,
      "name": "Rock_Shale"
    },
    {
      "x": -2,
      "y": 20,
      "z": -2,
      "name": "Rock_Shale"
    },
    {
      "x": -2,
      "y": 21,
      "z": -2,
      "name": "Rock_Shale"
    },
    {
      "x": -2,
      "y": 22,
      "z": -2,
      "name": "Rock_Shale"
    },
    {
      "x": -2,
      "y": 23,
      "z": -2,
      "name": "Rock_Shale"
    },
    {
      "x": -2,
      "y": 24,
      "z": -2,
      "name": "Rock_Shale"
    },
    {
      "x": -2,
      "y": 25,
      "z": -2,
      "name": "Rock_Shale"
    },
    {
      "x": -2,
      "y": 26,
      "z": -2,
      "name": "Rock_Shale"
    },
    {
      "x": -2,
      "y": 27,
      "z": -2,
      "name": "Rock_Shale"
    },
    {
      "x": -2,
      "y": 28,
      "z": -2,
      "name": "Rock_Shale"
    },
    {
      "x": -2,
      "y": 0,
      "z": -1,
      "name": "Wood_Giantwood_Trunk_Tainted_Full",
      "support": 15
    },
    {
      "x": -2,
      "y": 1,
      "z": -1,
      "name": "Wood_Giantwood_Trunk_Tainted_Full",
      "support": 15
    },
    {
      "x": -2,
      "y": 2,
      "z": -1,
      "name": "Rock_Shale"
    },
    {
      "x": -2,
      "y": 3,
      "z": -1,
      "name": "Wood_Giantwood_Trunk_Tainted_Full",
      "support": 15
    },
    {
      "x": -2,
      "y": 4,
      "z": -1,
      "name": "Wood_Giantwood_Trunk_Tainted_Full",
      "support": 15
    },
    {
      "x": -2,
      "y": 5,
      "z": -1,
      "name": "Plant_Mushroom_Short_White_Mycelium",
      "support": 15
    },
    {
      "x": -2,
      "y": 13,
      "z": -1,
      "name": "Rock_Shale"
    },
    {
      "x": -2,
      "y": 14,
      "z": -1,
      "name": "Rock_Shale"
    },
    {
      "x": -2,
      "y": 15,
      "z": -1,
      "name": "Rock_Shale"
    },
    {
      "x": -2,
      "y": 16,
      "z": -1,
      "name": "Rock_Shale"
    },
    {
      "x": -2,
      "y": 17,
      "z": -1,
      "name": "Rock_Shale"
    },
    {
      "x": -2,
      "y": 18,
      "z": -1,
      "name": "Rock_Shale"
    },
    {
      "x": -2,
      "y": 19,
      "z": -1,
      "name": "Rock_Shale"
    },
    {
      "x": -2,
      "y": 20,
      "z": -1,
      "name": "Rock_Shale"
    },
    {
      "x": -2,
      "y": 21,
      "z": -1,
      "name": "Rock_Shale"
    },
    {
      "x": -2,
      "y": 22,
      "z": -1,
      "name": "Rock_Shale"
    },
    {
      "x": -2,
      "y": 23,
      "z": -1,
      "name": "Rock_Shale"
    },
    {
      "x": -2,
      "y": 24,
      "z": -1,
      "name": "Rock_Shale"
    },
    {
      "x": -2,
      "y": 25,
      "z": -1,
      "name": "Rock_Shale"
    },
    {
      "x": -2,
      "y": 26,
      "z": -1,
      "name": "Rock_Shale"
    },
    {
      "x": -2,
      "y": 27,
      "z": -1,
      "name": "Rock_Shale"
    },
    {
      "x": -2,
      "y": 28,
      "z": -1,
      "name": "Rock_Shale"
    },
    {
      "x": -2,
      "y": 29,
      "z": -1,
      "name": "Rock_Shale"
    },
    {
      "x": -2,
      "y": 0,
      "z": 0,
      "name": "Wood_Giantwood_Trunk_Tainted_Full",
      "support": 15
    },
    {
      "x": -2,
      "y": 1,
      "z": 0,
      "name": "Wood_Giantwood_Trunk_Tainted_Full",
      "support": 15
    },
    {
      "x": -2,
      "y": 2,
      "z": 0,
      "name": "Wood_Giantwood_Trunk_Tainted_Full",
      "support": 15
    },
    {
      "x": -2,
      "y": 3,
      "z": 0,
      "name": "Wood_Giantwood_Trunk_Tainted_Full",
      "support": 15
    },
    {
      "x": -2,
      "y": 4,
      "z": 0,
      "name": "Wood_Giantwood_Trunk_Tainted_Full",
      "support": 15
    },
    {
      "x": -2,
      "y": 13,
      "z": 0,
      "name": "Wood_Giantwood_Trunk_Tainted_Full",
      "support": 15
    },
    {
      "x": -2,
      "y": 14,
      "z": 0,
      "name": "Rock_Shale"
    },
    {
      "x": -2,
      "y": 15,
      "z": 0,
      "name": "Rock_Shale"
    },
    {
      "x": -2,
      "y": 16,
      "z": 0,
      "name": "Rock_Shale"
    },
    {
      "x": -2,
      "y": 17,
      "z": 0,
      "name": "Rock_Shale"
    },
    {
      "x": -2,
      "y": 18,
      "z": 0,
      "name": "Rock_Shale"
    },
    {
      "x": -2,
      "y": 19,
      "z": 0,
      "name": "Rock_Shale"
    },
    {
      "x": -2,
      "y": 20,
      "z": 0,
      "name": "Rock_Shale"
    },
    {
      "x": -2,
      "y": 21,
      "z": 0,
      "name": "Rock_Shale"
    },
    {
      "x": -2,
      "y": 22,
      "z": 0,
      "name": "Rock_Shale"
    },
    {
      "x": -2,
      "y": 23,
      "z": 0,
      "name": "Rock_Shale"
    },
    {
      "x": -2,
      "y": 24,
      "z": 0,
      "name": "Rock_Shale"
    },
    {
      "x": -2,
      "y": 25,
      "z": 0,
      "name": "Rock_Shale"
    },
    {
      "x": -2,
      "y": 26,
      "z": 0,
      "name": "Rock_Shale"
    },
    {
      "x": -2,
      "y": 27,
      "z": 0,
      "name": "Rock_Shale"
    },
    {
      "x": -2,
      "y": 28,
      "z": 0,
      "name": "Rock_Shale"
    },
    {
      "x": -2,
      "y": 29,
      "z": 0,
      "name": "Rock_Shale"
    },
    {
      "x": -2,
      "y": 0,
      "z": 1,
      "name": "Wood_Giantwood_Trunk_Tainted_Full",
      "support": 15
    },
    {
      "x": -2,
      "y": 1,
      "z": 1,
      "name": "Wood_Giantwood_Trunk_Tainted_Full",
      "support": 15
    },
    {
      "x": -2,
      "y": 2,
      "z": 1,
      "name": "Wood_Giantwood_Trunk_Tainted_Full",
      "support": 15
    },
    {
      "x": -2,
      "y": 3,
      "z": 1,
      "name": "Wood_Giantwood_Trunk_Tainted_Full",
      "support": 15
    },
    {
      "x": -2,
      "y": 4,
      "z": 1,
      "name": "Wood_Giantwood_Trunk_Tainted_Full",
      "support": 15
    },
    {
      "x": -2,
      "y": 5,
      "z": 1,
      "name": "Wood_Giantwood_Trunk_Tainted_Full",
      "support": 15
    },
    {
      "x": -2,
      "y": 6,
      "z": 1,
      "name": "Plant_Mushroom_Rug_White_Mycelium",
      "support": 15
    },
    {
      "x": -2,
      "y": 12,
      "z": 1,
      "name": "Wood_Giantwood_Trunk_Tainted_Full",
      "support": 15
    },
    {
      "x": -2,
      "y": 13,
      "z": 1,
      "name": "Wood_Giantwood_Trunk_Tainted_Full",
      "support": 15
    },
    {
      "x": -2,
      "y": 14,
      "z": 1,
      "name": "Wood_Giantwood_Trunk_Tainted_Full",
      "support": 15
    },
    {
      "x": -2,
      "y": 15,
      "z": 1,
      "name": "Wood_Giantwood_Trunk_Tainted_Full",
      "support": 15
    },
    {
      "x": -2,
      "y": 16,
      "z": 1,
      "name": "Rock_Shale"
    },
    {
      "x": -2,
      "y": 17,
      "z": 1,
      "name": "Rock_Shale"
    },
    {
      "x": -2,
      "y": 18,
      "z": 1,
      "name": "Rock_Shale"
    },
    {
      "x": -2,
      "y": 19,
      "z": 1,
      "name": "Rock_Shale"
    },
    {
      "x": -2,
      "y": 20,
      "z": 1,
      "name": "Rock_Shale"
    },
    {
      "x": -2,
      "y": 21,
      "z": 1,
      "name": "Rock_Shale"
    },
    {
      "x": -2,
      "y": 22,
      "z": 1,
      "name": "Rock_Shale"
    },
    {
      "x": -2,
      "y": 23,
      "z": 1,
      "name": "Rock_Shale"
    },
    {
      "x": -2,
      "y": 24,
      "z": 1,
      "name": "Rock_Shale"
    },
    {
      "x": -2,
      "y": 25,
      "z": 1,
      "name": "Rock_Shale"
    },
    {
      "x": -2,
      "y": 26,
      "z": 1,
      "name": "Rock_Shale"
    },
    {
      "x": -2,
      "y": 27,
      "z": 1,
      "name": "Rock_Shale"
    },
    {
      "x": -2,
      "y": 28,
      "z": 1,
      "name": "Rock_Shale"
    },
    {
      "x": -2,
      "y": 0,
      "z": 2,
      "name": "Wood_Giantwood_Trunk_Tainted_Full",
      "support": 15
    },
    {
      "x": -2,
      "y": 1,
      "z": 2,
      "name": "Wood_Giantwood_Trunk_Tainted_Full",
      "support": 15
    },
    {
      "x": -2,
      "y": 2,
      "z": 2,
      "name": "Wood_Giantwood_Trunk_Tainted_Full",
      "support": 15
    },
    {
      "x": -2,
      "y": 3,
      "z": 2,
      "name": "Wood_Giantwood_Trunk_Tainted_Full",
      "support": 15
    },
    {
      "x": -2,
      "y": 4,
      "z": 2,
      "name": "Wood_Giantwood_Trunk_Tainted_Full",
      "support": 15
    },
    {
      "x": -2,
      "y": 5,
      "z": 2,
      "name": "Plant_Mushroom_Rug_White_Mycelium",
      "support": 15
    },
    {
      "x": -2,
      "y": 11,
      "z": 2,
      "name": "Plant_Mushroom_Wall_White_Mycelium",
      "support": 15,
      "rotation": 3
    },
    {
      "x": -2,
      "y": 12,
      "z": 2,
      "name": "Wood_Giantwood_Trunk_Tainted_Full",
      "support": 15
    },
    {
      "x": -2,
      "y": 13,
      "z": 2,
      "name": "Wood_Giantwood_Trunk_Tainted_Full",
      "support": 15
    },
    {
      "x": -2,
      "y": 14,
      "z": 2,
      "name": "Wood_Giantwood_Trunk_Tainted_Full",
      "support": 15
    },
    {
      "x": -2,
      "y": 15,
      "z": 2,
      "name": "Wood_Giantwood_Trunk_Tainted_Full",
      "support": 15
    },
    {
      "x": -2,
      "y": 16,
      "z": 2,
      "name": "Wood_Giantwood_Trunk_Tainted_Full",
      "support": 15
    },
    {
      "x": -2,
      "y": 17,
      "z": 2,
      "name": "Wood_Giantwood_Trunk_Tainted_Full"
    },
    {
      "x": -2,
      "y": 18,
      "z": 2,
      "name": "Wood_Giantwood_Trunk_Tainted_Full"
    },
    {
      "x": -2,
      "y": 19,
      "z": 2,
      "name": "Wood_Giantwood_Trunk_Tainted_Full"
    },
    {
      "x": -2,
      "y": 20,
      "z": 2,
      "name": "Rock_Shale"
    },
    {
      "x": -2,
      "y": 21,
      "z": 2,
      "name": "Rock_Shale"
    },
    {
      "x": -2,
      "y": 22,
      "z": 2,
      "name": "Rock_Shale"
    },
    {
      "x": -2,
      "y": 23,
      "z": 2,
      "name": "Rock_Shale"
    },
    {
      "x": -2,
      "y": 24,
      "z": 2,
      "name": "Rock_Shale"
    },
    {
      "x": -2,
      "y": 25,
      "z": 2,
      "name": "Rock_Shale"
    },
    {
      "x": -2,
      "y": 26,
      "z": 2,
      "name": "Rock_Shale"
    },
    {
      "x": -2,
      "y": 27,
      "z": 2,
      "name": "Rock_Shale"
    },
    {
      "x": -2,
      "y": 28,
      "z": 2,
      "name": "Rock_Shale"
    },
    {
      "x": -2,
      "y": 0,
      "z": 3,
      "name": "Rock_Shale"
    },
    {
      "x": -2,
      "y": 1,
      "z": 3,
      "name": "Rock_Shale"
    },
    {
      "x": -2,
      "y": 2,
      "z": 3,
      "name": "Rock_Shale"
    },
    {
      "x": -2,
      "y": 3,
      "z": 3,
      "name": "Plant_Mushroom_Rug_White_Mycelium",
      "support": 15
    },
    {
      "x": -2,
      "y": 13,
      "z": 3,
      "name": "Wood_Giantwood_Trunk_Tainted_Full",
      "support": 15
    },
    {
      "x": -2,
      "y": 14,
      "z": 3,
      "name": "Wood_Giantwood_Trunk_Tainted_Full",
      "support": 15
    },
    {
      "x": -2,
      "y": 15,
      "z": 3,
      "name": "Wood_Giantwood_Trunk_Tainted_Full",
      "support": 15
    },
    {
      "x": -2,
      "y": 16,
      "z": 3,
      "name": "Wood_Giantwood_Trunk_Tainted_Full",
      "support": 15
    },
    {
      "x": -2,
      "y": 17,
      "z": 3,
      "name": "Rock_Shale"
    },
    {
      "x": -2,
      "y": 18,
      "z": 3,
      "name": "Rock_Shale"
    },
    {
      "x": -2,
      "y": 19,
      "z": 3,
      "name": "Rock_Shale"
    },
    {
      "x": -2,
      "y": 20,
      "z": 3,
      "name": "Rock_Shale"
    },
    {
      "x": -2,
      "y": 21,
      "z": 3,
      "name": "Rock_Shale"
    },
    {
      "x": -2,
      "y": 22,
      "z": 3,
      "name": "Rock_Shale"
    },
    {
      "x": -2,
      "y": 23,
      "z": 3,
      "name": "Rock_Shale"
    },
    {
      "x": -2,
      "y": 24,
      "z": 3,
      "name": "Rock_Shale"
    },
    {
      "x": -2,
      "y": 25,
      "z": 3,
      "name": "Rock_Shale"
    },
    {
      "x": -2,
      "y": 26,
      "z": 3,
      "name": "Rock_Shale"
    },
    {
      "x": -2,
      "y": 27,
      "z": 3,
      "name": "Rock_Shale"
    },
    {
      "x": -2,
      "y": 0,
      "z": 4,
      "name": "Rock_Shale"
    },
    {
      "x": -2,
      "y": 1,
      "z": 4,
      "name": "Plant_Mushroom_Rug_White_Mycelium",
      "support": 15
    },
    {
      "x": -2,
      "y": 2,
      "z": 4,
      "name": "Plant_Mushroom_Wall_White_Mycelium",
      "support": 15
    },
    {
      "x": -2,
      "y": 16,
      "z": 4,
      "name": "Rock_Shale"
    },
    {
      "x": -2,
      "y": 17,
      "z": 4,
      "name": "Rock_Shale"
    },
    {
      "x": -2,
      "y": 18,
      "z": 4,
      "name": "Rock_Shale"
    },
    {
      "x": -2,
      "y": 19,
      "z": 4,
      "name": "Rock_Shale"
    },
    {
      "x": -2,
      "y": 20,
      "z": 4,
      "name": "Rock_Shale"
    },
    {
      "x": -2,
      "y": 21,
      "z": 4,
      "name": "Rock_Shale"
    },
    {
      "x": -2,
      "y": 22,
      "z": 4,
      "name": "Rock_Shale"
    },
    {
      "x": -2,
      "y": 23,
      "z": 4,
      "name": "Rock_Shale"
    },
    {
      "x": -2,
      "y": 24,
      "z": 4,
      "name": "Rock_Shale"
    },
    {
      "x": -2,
      "y": 25,
      "z": 4,
      "name": "Rock_Shale"
    },
    {
      "x": -2,
      "y": 26,
      "z": 4,
      "name": "Rock_Shale"
    },
    {
      "x": -2,
      "y": 27,
      "z": 4,
      "name": "Rock_Shale"
    },
    {
      "x": -2,
      "y": 0,
      "z": 5,
      "name": "Rock_Shale"
    },
    {
      "x": -2,
      "y": 1,
      "z": 5,
      "name": "Plant_Mushroom_Rug_White_Mycelium",
      "support": 15
    },
    {
      "x": -2,
      "y": 19,
      "z": 5,
      "name": "Rock_Shale"
    },
    {
      "x": -2,
      "y": 20,
      "z": 5,
      "name": "Rock_Shale"
    },
    {
      "x": -2,
      "y": 21,
      "z": 5,
      "name": "Rock_Shale"
    },
    {
      "x": -2,
      "y": 23,
      "z": 5,
      "name": "Rock_Shale"
    },
    {
      "x": -2,
      "y": 24,
      "z": 5,
      "name": "Rock_Shale"
    },
    {
      "x": -2,
      "y": 25,
      "z": 5,
      "name": "Rock_Shale"
    },
    {
      "x": -2,
      "y": 26,
      "z": 5,
      "name": "Rock_Shale"
    },
    {
      "x": -2,
      "y": 27,
      "z": 5,
      "name": "Rock_Shale"
    },
    {
      "x": -2,
      "y": 20,
      "z": 6,
      "name": "Rock_Shale"
    },
    {
      "x": -2,
      "y": 21,
      "z": 6,
      "name": "Rock_Shale"
    },
    {
      "x": -2,
      "y": 22,
      "z": 6,
      "name": "Rock_Shale"
    },
    {
      "x": -2,
      "y": 23,
      "z": 6,
      "name": "Rock_Shale"
    },
    {
      "x": -2,
      "y": 24,
      "z": 6,
      "name": "Rock_Shale"
    },
    {
      "x": -2,
      "y": 25,
      "z": 6,
      "name": "Rock_Shale"
    },
    {
      "x": -2,
      "y": 26,
      "z": 6,
      "name": "Rock_Shale"
    },
    {
      "x": -2,
      "y": 21,
      "z": 7,
      "name": "Rock_Shale"
    },
    {
      "x": -2,
      "y": 22,
      "z": 7,
      "name": "Rock_Shale"
    },
    {
      "x": -2,
      "y": 23,
      "z": 7,
      "name": "Rock_Shale"
    },
    {
      "x": -2,
      "y": 24,
      "z": 7,
      "name": "Rock_Shale"
    },
    {
      "x": -2,
      "y": 25,
      "z": 7,
      "name": "Rock_Shale"
    },
    {
      "x": -2,
      "y": 26,
      "z": 7,
      "name": "Rock_Shale"
    },
    {
      "x": -1,
      "y": 21,
      "z": -7,
      "name": "Rock_Shale"
    },
    {
      "x": -1,
      "y": 22,
      "z": -7,
      "name": "Rock_Shale"
    },
    {
      "x": -1,
      "y": 23,
      "z": -7,
      "name": "Rock_Shale"
    },
    {
      "x": -1,
      "y": 24,
      "z": -7,
      "name": "Rock_Shale"
    },
    {
      "x": -1,
      "y": 25,
      "z": -7,
      "name": "Rock_Shale"
    },
    {
      "x": -1,
      "y": 26,
      "z": -7,
      "name": "Rock_Shale"
    },
    {
      "x": -1,
      "y": 19,
      "z": -6,
      "name": "Rock_Shale"
    },
    {
      "x": -1,
      "y": 20,
      "z": -6,
      "name": "Rock_Shale"
    },
    {
      "x": -1,
      "y": 21,
      "z": -6,
      "name": "Rock_Shale"
    },
    {
      "x": -1,
      "y": 22,
      "z": -6,
      "name": "Rock_Shale"
    },
    {
      "x": -1,
      "y": 23,
      "z": -6,
      "name": "Rock_Shale"
    },
    {
      "x": -1,
      "y": 24,
      "z": -6,
      "name": "Rock_Shale"
    },
    {
      "x": -1,
      "y": 25,
      "z": -6,
      "name": "Rock_Shale"
    },
    {
      "x": -1,
      "y": 26,
      "z": -6,
      "name": "Rock_Shale"
    },
    {
      "x": -1,
      "y": 27,
      "z": -6,
      "name": "Rock_Shale"
    },
    {
      "x": -1,
      "y": 0,
      "z": -5,
      "name": "Rock_Shale"
    },
    {
      "x": -1,
      "y": 1,
      "z": -5,
      "name": "Plant_Mushroom_Rug_White_Mycelium",
      "support": 15
    },
    {
      "x": -1,
      "y": 17,
      "z": -5,
      "name": "Rock_Shale"
    },
    {
      "x": -1,
      "y": 18,
      "z": -5,
      "name": "Rock_Shale"
    },
    {
      "x": -1,
      "y": 19,
      "z": -5,
      "name": "Rock_Shale"
    },
    {
      "x": -1,
      "y": 20,
      "z": -5,
      "name": "Rock_Shale"
    },
    {
      "x": -1,
      "y": 21,
      "z": -5,
      "name": "Rock_Shale"
    },
    {
      "x": -1,
      "y": 22,
      "z": -5,
      "name": "Rock_Shale"
    },
    {
      "x": -1,
      "y": 23,
      "z": -5,
      "name": "Rock_Shale"
    },
    {
      "x": -1,
      "y": 24,
      "z": -5,
      "name": "Rock_Shale"
    },
    {
      "x": -1,
      "y": 25,
      "z": -5,
      "name": "Rock_Shale"
    },
    {
      "x": -1,
      "y": 26,
      "z": -5,
      "name": "Rock_Shale"
    },
    {
      "x": -1,
      "y": 27,
      "z": -5,
      "name": "Rock_Shale"
    },
    {
      "x": -1,
      "y": 0,
      "z": -4,
      "name": "Rock_Shale"
    },
    {
      "x": -1,
      "y": 1,
      "z": -4,
      "name": "Plant_Mushroom_Block_White_Mycelium",
      "support": 15
    },
    {
      "x": -1,
      "y": 2,
      "z": -4,
      "name": "Plant_Roots_Rug_Tainted",
      "support": 15
    },
    {
      "x": -1,
      "y": 15,
      "z": -4,
      "name": "Rock_Shale"
    },
    {
      "x": -1,
      "y": 16,
      "z": -4,
      "name": "Rock_Shale"
    },
    {
      "x": -1,
      "y": 17,
      "z": -4,
      "name": "Rock_Shale"
    },
    {
      "x": -1,
      "y": 18,
      "z": -4,
      "name": "Rock_Shale"
    },
    {
      "x": -1,
      "y": 19,
      "z": -4,
      "name": "Rock_Shale"
    },
    {
      "x": -1,
      "y": 20,
      "z": -4,
      "name": "Rock_Shale"
    },
    {
      "x": -1,
      "y": 21,
      "z": -4,
      "name": "Rock_Shale"
    },
    {
      "x": -1,
      "y": 22,
      "z": -4,
      "name": "Rock_Shale"
    },
    {
      "x": -1,
      "y": 23,
      "z": -4,
      "name": "Rock_Shale"
    },
    {
      "x": -1,
      "y": 24,
      "z": -4,
      "name": "Rock_Shale"
    },
    {
      "x": -1,
      "y": 25,
      "z": -4,
      "name": "Rock_Shale"
    },
    {
      "x": -1,
      "y": 26,
      "z": -4,
      "name": "Rock_Shale"
    },
    {
      "x": -1,
      "y": 27,
      "z": -4,
      "name": "Rock_Shale"
    },
    {
      "x": -1,
      "y": 28,
      "z": -4,
      "name": "Rock_Shale"
    },
    {
      "x": -1,
      "y": 0,
      "z": -3,
      "name": "Rock_Shale"
    },
    {
      "x": -1,
      "y": 1,
      "z": -3,
      "name": "Rock_Shale"
    },
    {
      "x": -1,
      "y": 2,
      "z": -3,
      "name": "Plant_Mushroom_Short_White_Mycelium",
      "support": 15
    },
    {
      "x": -1,
      "y": 14,
      "z": -3,
      "name": "Rock_Shale"
    },
    {
      "x": -1,
      "y": 15,
      "z": -3,
      "name": "Rock_Shale"
    },
    {
      "x": -1,
      "y": 16,
      "z": -3,
      "name": "Rock_Shale"
    },
    {
      "x": -1,
      "y": 17,
      "z": -3,
      "name": "Rock_Shale"
    },
    {
      "x": -1,
      "y": 18,
      "z": -3,
      "name": "Rock_Shale"
    },
    {
      "x": -1,
      "y": 19,
      "z": -3,
      "name": "Rock_Shale"
    },
    {
      "x": -1,
      "y": 20,
      "z": -3,
      "name": "Rock_Shale"
    },
    {
      "x": -1,
      "y": 21,
      "z": -3,
      "name": "Rock_Shale"
    },
    {
      "x": -1,
      "y": 22,
      "z": -3,
      "name": "Rock_Shale"
    },
    {
      "x": -1,
      "y": 23,
      "z": -3,
      "name": "Rock_Shale"
    },
    {
      "x": -1,
      "y": 24,
      "z": -3,
      "name": "Rock_Shale"
    },
    {
      "x": -1,
      "y": 25,
      "z": -3,
      "name": "Rock_Shale"
    },
    {
      "x": -1,
      "y": 26,
      "z": -3,
      "name": "Rock_Shale"
    },
    {
      "x": -1,
      "y": 27,
      "z": -3,
      "name": "Rock_Shale"
    },
    {
      "x": -1,
      "y": 28,
      "z": -3,
      "name": "Rock_Shale"
    },
    {
      "x": -1,
      "y": 0,
      "z": -2,
      "name": "Wood_Giantwood_Trunk_Tainted_Full",
      "support": 15
    },
    {
      "x": -1,
      "y": 1,
      "z": -2,
      "name": "Wood_Giantwood_Trunk_Tainted_Full",
      "support": 15
    },
    {
      "x": -1,
      "y": 2,
      "z": -2,
      "name": "Wood_Giantwood_Trunk_Tainted_Full",
      "support": 15
    },
    {
      "x": -1,
      "y": 3,
      "z": -2,
      "name": "Wood_Giantwood_Trunk_Tainted_Full",
      "support": 15
    },
    {
      "x": -1,
      "y": 4,
      "z": -2,
      "name": "Wood_Giantwood_Trunk_Tainted_Full",
      "support": 15
    },
    {
      "x": -1,
      "y": 5,
      "z": -2,
      "name": "Plant_Mushroom_Rug_White_Mycelium",
      "support": 15
    },
    {
      "x": -1,
      "y": 12,
      "z": -2,
      "name": "Plant_Mushroom_Wall_White_Mycelium",
      "support": 15,
      "rotation": 3
    },
    {
      "x": -1,
      "y": 13,
      "z": -2,
      "name": "Rock_Shale"
    },
    {
      "x": -1,
      "y": 14,
      "z": -2,
      "name": "Rock_Shale"
    },
    {
      "x": -1,
      "y": 15,
      "z": -2,
      "name": "Rock_Shale"
    },
    {
      "x": -1,
      "y": 16,
      "z": -2,
      "name": "Rock_Shale"
    },
    {
      "x": -1,
      "y": 17,
      "z": -2,
      "name": "Rock_Shale"
    },
    {
      "x": -1,
      "y": 18,
      "z": -2,
      "name": "Rock_Shale"
    },
    {
      "x": -1,
      "y": 19,
      "z": -2,
      "name": "Rock_Shale"
    },
    {
      "x": -1,
      "y": 20,
      "z": -2,
      "name": "Rock_Shale"
    },
    {
      "x": -1,
      "y": 21,
      "z": -2,
      "name": "Rock_Shale"
    },
    {
      "x": -1,
      "y": 22,
      "z": -2,
      "name": "Rock_Shale"
    },
    {
      "x": -1,
      "y": 23,
      "z": -2,
      "name": "Rock_Shale"
    },
    {
      "x": -1,
      "y": 24,
      "z": -2,
      "name": "Rock_Shale"
    },
    {
      "x": -1,
      "y": 25,
      "z": -2,
      "name": "Rock_Shale"
    },
    {
      "x": -1,
      "y": 26,
      "z": -2,
      "name": "Rock_Shale"
    },
    {
      "x": -1,
      "y": 27,
      "z": -2,
      "name": "Rock_Shale"
    },
    {
      "x": -1,
      "y": 28,
      "z": -2,
      "name": "Rock_Shale"
    },
    {
      "x": -1,
      "y": 29,
      "z": -2,
      "name": "Rock_Shale"
    },
    {
      "x": -1,
      "y": 0,
      "z": -1,
      "name": "Wood_Giantwood_Trunk_Tainted_Full",
      "support": 15
    },
    {
      "x": -1,
      "y": 1,
      "z": -1,
      "name": "Wood_Giantwood_Trunk_Tainted_Full",
      "support": 15
    },
    {
      "x": -1,
      "y": 2,
      "z": -1,
      "name": "Wood_Giantwood_Trunk_Tainted_Full",
      "support": 15
    },
    {
      "x": -1,
      "y": 3,
      "z": -1,
      "name": "Wood_Giantwood_Trunk_Tainted_Full",
      "support": 15
    },
    {
      "x": -1,
      "y": 4,
      "z": -1,
      "name": "Wood_Giantwood_Trunk_Tainted_Full",
      "support": 15
    },
    {
      "x": -1,
      "y": 5,
      "z": -1,
      "name": "Wood_Giantwood_Trunk_Tainted_Full",
      "support": 15
    },
    {
      "x": -1,
      "y": 6,
      "z": -1,
      "name": "Plant_Mushroom_Rug_White_Mycelium",
      "support": 15
    },
    {
      "x": -1,
      "y": 11,
      "z": -1,
      "name": "Plant_Mushroom_Wall_White_Mycelium",
      "support": 15,
      "rotation": 3
    },
    {
      "x": -1,
      "y": 12,
      "z": -1,
      "name": "Rock_Shale"
    },
    {
      "x": -1,
      "y": 13,
      "z": -1,
      "name": "Rock_Shale"
    },
    {
      "x": -1,
      "y": 14,
      "z": -1,
      "name": "Rock_Shale"
    },
    {
      "x": -1,
      "y": 15,
      "z": -1,
      "name": "Rock_Shale"
    },
    {
      "x": -1,
      "y": 16,
      "z": -1,
      "name": "Rock_Shale"
    },
    {
      "x": -1,
      "y": 17,
      "z": -1,
      "name": "Rock_Shale"
    },
    {
      "x": -1,
      "y": 18,
      "z": -1,
      "name": "Rock_Shale"
    },
    {
      "x": -1,
      "y": 19,
      "z": -1,
      "name": "Rock_Shale"
    },
    {
      "x": -1,
      "y": 20,
      "z": -1,
      "name": "Rock_Shale"
    },
    {
      "x": -1,
      "y": 21,
      "z": -1,
      "name": "Rock_Shale"
    },
    {
      "x": -1,
      "y": 22,
      "z": -1,
      "name": "Rock_Shale"
    },
    {
      "x": -1,
      "y": 23,
      "z": -1,
      "name": "Rock_Shale"
    },
    {
      "x": -1,
      "y": 24,
      "z": -1,
      "name": "Rock_Shale"
    },
    {
      "x": -1,
      "y": 25,
      "z": -1,
      "name": "Rock_Shale"
    },
    {
      "x": -1,
      "y": 26,
      "z": -1,
      "name": "Rock_Shale"
    },
    {
      "x": -1,
      "y": 27,
      "z": -1,
      "name": "Rock_Shale"
    },
    {
      "x": -1,
      "y": 28,
      "z": -1,
      "name": "Rock_Shale"
    },
    {
      "x": -1,
      "y": 29,
      "z": -1,
      "name": "Rock_Shale"
    },
    {
      "x": -1,
      "y": 0,
      "z": 0,
      "name": "Wood_Giantwood_Trunk_Tainted_Full",
      "support": 15
    },
    {
      "x": -1,
      "y": 1,
      "z": 0,
      "name": "Wood_Giantwood_Trunk_Tainted_Full",
      "support": 15
    },
    {
      "x": -1,
      "y": 2,
      "z": 0,
      "name": "Wood_Giantwood_Trunk_Tainted_Full",
      "support": 15
    },
    {
      "x": -1,
      "y": 3,
      "z": 0,
      "name": "Wood_Giantwood_Trunk_Tainted_Full",
      "support": 15
    },
    {
      "x": -1,
      "y": 4,
      "z": 0,
      "name": "Wood_Giantwood_Trunk_Tainted_Full",
      "support": 15
    },
    {
      "x": -1,
      "y": 5,
      "z": 0,
      "name": "Wood_Giantwood_Trunk_Tainted_Full",
      "support": 15
    },
    {
      "x": -1,
      "y": 6,
      "z": 0,
      "name": "Wood_Giantwood_Trunk_Tainted_Full",
      "support": 15
    },
    {
      "x": -1,
      "y": 7,
      "z": 0,
      "name": "Plant_Mushroom_Short_White_Mycelium",
      "support": 15
    },
    {
      "x": -1,
      "y": 10,
      "z": 0,
      "name": "Wood_Giantwood_Trunk_Tainted_Full",
      "support": 15
    },
    {
      "x": -1,
      "y": 11,
      "z": 0,
      "name": "Wood_Giantwood_Trunk_Tainted_Full",
      "support": 15
    },
    {
      "x": -1,
      "y": 12,
      "z": 0,
      "name": "Wood_Giantwood_Trunk_Tainted_Full",
      "support": 15
    },
    {
      "x": -1,
      "y": 13,
      "z": 0,
      "name": "Wood_Giantwood_Trunk_Tainted_Full",
      "support": 15
    },
    {
      "x": -1,
      "y": 14,
      "z": 0,
      "name": "Wood_Giantwood_Trunk_Tainted_Full",
      "support": 15
    },
    {
      "x": -1,
      "y": 15,
      "z": 0,
      "name": "Wood_Giantwood_Trunk_Tainted_Full",
      "support": 15
    },
    {
      "x": -1,
      "y": 16,
      "z": 0,
      "name": "Wood_Giantwood_Trunk_Tainted_Full",
      "support": 15
    },
    {
      "x": -1,
      "y": 17,
      "z": 0,
      "name": "Wood_Giantwood_Trunk_Tainted_Full"
    },
    {
      "x": -1,
      "y": 18,
      "z": 0,
      "name": "Wood_Giantwood_Trunk_Tainted_Full"
    },
    {
      "x": -1,
      "y": 19,
      "z": 0,
      "name": "Wood_Giantwood_Trunk_Tainted_Full"
    },
    {
      "x": -1,
      "y": 20,
      "z": 0,
      "name": "Wood_Giantwood_Trunk_Tainted_Full"
    },
    {
      "x": -1,
      "y": 21,
      "z": 0,
      "name": "Wood_Giantwood_Trunk_Tainted_Full"
    },
    {
      "x": -1,
      "y": 22,
      "z": 0,
      "name": "Wood_Giantwood_Trunk_Tainted_Full"
    },
    {
      "x": -1,
      "y": 23,
      "z": 0,
      "name": "Rock_Shale"
    },
    {
      "x": -1,
      "y": 24,
      "z": 0,
      "name": "Rock_Shale"
    },
    {
      "x": -1,
      "y": 25,
      "z": 0,
      "name": "Rock_Shale"
    },
    {
      "x": -1,
      "y": 26,
      "z": 0,
      "name": "Rock_Shale"
    },
    {
      "x": -1,
      "y": 27,
      "z": 0,
      "name": "Rock_Shale"
    },
    {
      "x": -1,
      "y": 28,
      "z": 0,
      "name": "Rock_Shale"
    },
    {
      "x": -1,
      "y": 29,
      "z": 0,
      "name": "Rock_Shale"
    },
    {
      "x": -1,
      "y": 0,
      "z": 1,
      "name": "Wood_Giantwood_Trunk_Tainted_Full",
      "support": 15
    },
    {
      "x": -1,
      "y": 1,
      "z": 1,
      "name": "Wood_Giantwood_Trunk_Tainted_Full",
      "support": 15
    },
    {
      "x": -1,
      "y": 2,
      "z": 1,
      "name": "Wood_Giantwood_Trunk_Tainted_Full",
      "support": 15
    },
    {
      "x": -1,
      "y": 3,
      "z": 1,
      "name": "Wood_Giantwood_Trunk_Tainted_Full",
      "support": 15
    },
    {
      "x": -1,
      "y": 4,
      "z": 1,
      "name": "Wood_Giantwood_Trunk_Tainted_Full",
      "support": 15
    },
    {
      "x": -1,
      "y": 5,
      "z": 1,
      "name": "Wood_Giantwood_Trunk_Tainted_Full",
      "support": 15
    },
    {
      "x": -1,
      "y": 6,
      "z": 1,
      "name": "Wood_Giantwood_Trunk_Tainted_Full",
      "support": 15
    },
    {
      "x": -1,
      "y": 7,
      "z": 1,
      "name": "Plant_Mushroom_Rug_White_Mycelium",
      "support": 15
    },
    {
      "x": -1,
      "y": 11,
      "z": 1,
      "name": "Wood_Giantwood_Trunk_Tainted_Full",
      "support": 15
    },
    {
      "x": -1,
      "y": 12,
      "z": 1,
      "name": "Wood_Giantwood_Trunk_Tainted_Full",
      "support": 15
    },
    {
      "x": -1,
      "y": 13,
      "z": 1,
      "name": "Wood_Giantwood_Trunk_Tainted_Full",
      "support": 15
    },
    {
      "x": -1,
      "y": 14,
      "z": 1,
      "name": "Wood_Giantwood_Trunk_Tainted_Full",
      "support": 15
    },
    {
      "x": -1,
      "y": 15,
      "z": 1,
      "name": "Wood_Giantwood_Trunk_Tainted_Full",
      "support": 15
    },
    {
      "x": -1,
      "y": 16,
      "z": 1,
      "name": "Wood_Giantwood_Trunk_Tainted_Full",
      "support": 15
    },
    {
      "x": -1,
      "y": 17,
      "z": 1,
      "name": "Wood_Giantwood_Trunk_Tainted_Full"
    },
    {
      "x": -1,
      "y": 18,
      "z": 1,
      "name": "Wood_Giantwood_Trunk_Tainted_Full"
    },
    {
      "x": -1,
      "y": 19,
      "z": 1,
      "name": "Wood_Giantwood_Trunk_Tainted_Full"
    },
    {
      "x": -1,
      "y": 20,
      "z": 1,
      "name": "Wood_Giantwood_Trunk_Tainted_Full"
    },
    {
      "x": -1,
      "y": 21,
      "z": 1,
      "name": "Wood_Giantwood_Trunk_Tainted_Full"
    },
    {
      "x": -1,
      "y": 22,
      "z": 1,
      "name": "Rock_Shale"
    },
    {
      "x": -1,
      "y": 23,
      "z": 1,
      "name": "Rock_Shale"
    },
    {
      "x": -1,
      "y": 24,
      "z": 1,
      "name": "Rock_Shale"
    },
    {
      "x": -1,
      "y": 25,
      "z": 1,
      "name": "Rock_Shale"
    },
    {
      "x": -1,
      "y": 26,
      "z": 1,
      "name": "Rock_Shale"
    },
    {
      "x": -1,
      "y": 27,
      "z": 1,
      "name": "Rock_Shale"
    },
    {
      "x": -1,
      "y": 28,
      "z": 1,
      "name": "Rock_Shale"
    },
    {
      "x": -1,
      "y": 29,
      "z": 1,
      "name": "Rock_Shale"
    },
    {
      "x": -1,
      "y": 0,
      "z": 2,
      "name": "Wood_Giantwood_Trunk_Tainted_Full",
      "support": 15
    },
    {
      "x": -1,
      "y": 1,
      "z": 2,
      "name": "Wood_Giantwood_Trunk_Tainted_Full",
      "support": 15
    },
    {
      "x": -1,
      "y": 2,
      "z": 2,
      "name": "Wood_Giantwood_Trunk_Tainted_Full",
      "support": 15
    },
    {
      "x": -1,
      "y": 3,
      "z": 2,
      "name": "Wood_Giantwood_Trunk_Tainted_Full",
      "support": 15
    },
    {
      "x": -1,
      "y": 4,
      "z": 2,
      "name": "Wood_Giantwood_Trunk_Tainted_Full",
      "support": 15
    },
    {
      "x": -1,
      "y": 5,
      "z": 2,
      "name": "Wood_Giantwood_Trunk_Tainted_Full",
      "support": 15
    },
    {
      "x": -1,
      "y": 6,
      "z": 2,
      "name": "Plant_Mushroom_Rug_White_Mycelium",
      "support": 15
    },
    {
      "x": -1,
      "y": 10,
      "z": 2,
      "name": "Plant_Mushroom_Cave_White_Mycelium",
      "support": 15,
      "rotation": 8
    },
    {
      "x": -1,
      "y": 11,
      "z": 2,
      "name": "Wood_Giantwood_Trunk_Tainted_Full",
      "support": 15
    },
    {
      "x": -1,
      "y": 12,
      "z": 2,
      "name": "Wood_Giantwood_Trunk_Tainted_Full",
      "support": 15
    },
    {
      "x": -1,
      "y": 13,
      "z": 2,
      "name": "Wood_Giantwood_Trunk_Tainted_Full",
      "support": 15
    },
    {
      "x": -1,
      "y": 14,
      "z": 2,
      "name": "Wood_Giantwood_Trunk_Tainted_Full",
      "support": 15
    },
    {
      "x": -1,
      "y": 15,
      "z": 2,
      "name": "Wood_Giantwood_Trunk_Tainted_Full",
      "support": 15
    },
    {
      "x": -1,
      "y": 16,
      "z": 2,
      "name": "Wood_Giantwood_Trunk_Tainted_Full",
      "support": 15
    },
    {
      "x": -1,
      "y": 17,
      "z": 2,
      "name": "Wood_Giantwood_Trunk_Tainted_Full"
    },
    {
      "x": -1,
      "y": 18,
      "z": 2,
      "name": "Wood_Giantwood_Trunk_Tainted_Full"
    },
    {
      "x": -1,
      "y": 19,
      "z": 2,
      "name": "Wood_Giantwood_Trunk_Tainted_Full"
    },
    {
      "x": -1,
      "y": 20,
      "z": 2,
      "name": "Wood_Giantwood_Trunk_Tainted_Full"
    },
    {
      "x": -1,
      "y": 21,
      "z": 2,
      "name": "Rock_Shale"
    },
    {
      "x": -1,
      "y": 22,
      "z": 2,
      "name": "Rock_Shale"
    },
    {
      "x": -1,
      "y": 23,
      "z": 2,
      "name": "Rock_Shale"
    },
    {
      "x": -1,
      "y": 24,
      "z": 2,
      "name": "Rock_Shale"
    },
    {
      "x": -1,
      "y": 25,
      "z": 2,
      "name": "Rock_Shale"
    },
    {
      "x": -1,
      "y": 26,
      "z": 2,
      "name": "Rock_Shale"
    },
    {
      "x": -1,
      "y": 27,
      "z": 2,
      "name": "Rock_Shale"
    },
    {
      "x": -1,
      "y": 28,
      "z": 2,
      "name": "Rock_Shale"
    },
    {
      "x": -1,
      "y": 0,
      "z": 3,
      "name": "Rock_Shale"
    },
    {
      "x": -1,
      "y": 1,
      "z": 3,
      "name": "Rock_Shale"
    },
    {
      "x": -1,
      "y": 4,
      "z": 3,
      "name": "Plant_Mushroom_Wall_White_Mycelium",
      "support": 15
    },
    {
      "x": -1,
      "y": 5,
      "z": 3,
      "name": "Plant_Mushroom_Wall_White_Mycelium",
      "support": 15
    },
    {
      "x": -1,
      "y": 11,
      "z": 3,
      "name": "Plant_Mushroom_Wall_White_Mycelium",
      "support": 15
    },
    {
      "x": -1,
      "y": 12,
      "z": 3,
      "name": "Wood_Giantwood_Trunk_Tainted_Full",
      "support": 15
    },
    {
      "x": -1,
      "y": 13,
      "z": 3,
      "name": "Wood_Giantwood_Trunk_Tainted_Full",
      "support": 15
    },
    {
      "x": -1,
      "y": 14,
      "z": 3,
      "name": "Wood_Giantwood_Trunk_Tainted_Full",
      "support": 15
    },
    {
      "x": -1,
      "y": 15,
      "z": 3,
      "name": "Wood_Giantwood_Trunk_Tainted_Full",
      "support": 15
    },
    {
      "x": -1,
      "y": 16,
      "z": 3,
      "name": "Wood_Giantwood_Trunk_Tainted_Full",
      "support": 15
    },
    {
      "x": -1,
      "y": 17,
      "z": 3,
      "name": "Wood_Giantwood_Trunk_Tainted_Full"
    },
    {
      "x": -1,
      "y": 18,
      "z": 3,
      "name": "Wood_Giantwood_Trunk_Tainted_Full"
    },
    {
      "x": -1,
      "y": 19,
      "z": 3,
      "name": "Wood_Giantwood_Trunk_Tainted_Full"
    },
    {
      "x": -1,
      "y": 20,
      "z": 3,
      "name": "Rock_Shale"
    },
    {
      "x": -1,
      "y": 21,
      "z": 3,
      "name": "Rock_Shale"
    },
    {
      "x": -1,
      "y": 22,
      "z": 3,
      "name": "Rock_Shale"
    },
    {
      "x": -1,
      "y": 23,
      "z": 3,
      "name": "Rock_Shale"
    },
    {
      "x": -1,
      "y": 24,
      "z": 3,
      "name": "Rock_Shale"
    },
    {
      "x": -1,
      "y": 25,
      "z": 3,
      "name": "Rock_Shale"
    },
    {
      "x": -1,
      "y": 26,
      "z": 3,
      "name": "Rock_Shale"
    },
    {
      "x": -1,
      "y": 27,
      "z": 3,
      "name": "Rock_Shale"
    },
    {
      "x": -1,
      "y": 28,
      "z": 3,
      "name": "Rock_Shale"
    },
    {
      "x": -1,
      "y": 0,
      "z": 4,
      "name": "Rock_Shale"
    },
    {
      "x": -1,
      "y": 1,
      "z": 4,
      "name": "Rock_Shale"
    },
    {
      "x": -1,
      "y": 2,
      "z": 4,
      "name": "Plant_Mushroom_Rug_White_Mycelium",
      "support": 15
    },
    {
      "x": -1,
      "y": 13,
      "z": 4,
      "name": "Plant_Mushroom_Wall_White_Mycelium",
      "support": 15,
      "rotation": 3
    },
    {
      "x": -1,
      "y": 14,
      "z": 4,
      "name": "Rock_Shale"
    },
    {
      "x": -1,
      "y": 15,
      "z": 4,
      "name": "Rock_Shale"
    },
    {
      "x": -1,
      "y": 16,
      "z": 4,
      "name": "Rock_Shale"
    },
    {
      "x": -1,
      "y": 17,
      "z": 4,
      "name": "Rock_Shale"
    },
    {
      "x": -1,
      "y": 18,
      "z": 4,
      "name": "Rock_Shale"
    },
    {
      "x": -1,
      "y": 19,
      "z": 4,
      "name": "Rock_Shale"
    },
    {
      "x": -1,
      "y": 20,
      "z": 4,
      "name": "Rock_Shale"
    },
    {
      "x": -1,
      "y": 21,
      "z": 4,
      "name": "Rock_Shale"
    },
    {
      "x": -1,
      "y": 22,
      "z": 4,
      "name": "Rock_Shale"
    },
    {
      "x": -1,
      "y": 23,
      "z": 4,
      "name": "Rock_Shale"
    },
    {
      "x": -1,
      "y": 24,
      "z": 4,
      "name": "Rock_Shale"
    },
    {
      "x": -1,
      "y": 25,
      "z": 4,
      "name": "Rock_Shale"
    },
    {
      "x": -1,
      "y": 26,
      "z": 4,
      "name": "Rock_Shale"
    },
    {
      "x": -1,
      "y": 27,
      "z": 4,
      "name": "Rock_Shale"
    },
    {
      "x": -1,
      "y": 0,
      "z": 5,
      "name": "Rock_Shale"
    },
    {
      "x": -1,
      "y": 1,
      "z": 5,
      "name": "Plant_Mushroom_Rug_White_Mycelium",
      "support": 15
    },
    {
      "x": -1,
      "y": 18,
      "z": 5,
      "name": "Rock_Shale"
    },
    {
      "x": -1,
      "y": 19,
      "z": 5,
      "name": "Rock_Shale"
    },
    {
      "x": -1,
      "y": 20,
      "z": 5,
      "name": "Rock_Shale"
    },
    {
      "x": -1,
      "y": 21,
      "z": 5,
      "name": "Rock_Shale"
    },
    {
      "x": -1,
      "y": 22,
      "z": 5,
      "name": "Rock_Shale"
    },
    {
      "x": -1,
      "y": 23,
      "z": 5,
      "name": "Rock_Shale"
    },
    {
      "x": -1,
      "y": 24,
      "z": 5,
      "name": "Rock_Shale"
    },
    {
      "x": -1,
      "y": 25,
      "z": 5,
      "name": "Rock_Shale"
    },
    {
      "x": -1,
      "y": 26,
      "z": 5,
      "name": "Rock_Shale"
    },
    {
      "x": -1,
      "y": 27,
      "z": 5,
      "name": "Rock_Shale"
    },
    {
      "x": -1,
      "y": 19,
      "z": 6,
      "name": "Rock_Shale"
    },
    {
      "x": -1,
      "y": 20,
      "z": 6,
      "name": "Rock_Shale"
    },
    {
      "x": -1,
      "y": 21,
      "z": 6,
      "name": "Rock_Shale"
    },
    {
      "x": -1,
      "y": 22,
      "z": 6,
      "name": "Rock_Shale"
    },
    {
      "x": -1,
      "y": 23,
      "z": 6,
      "name": "Rock_Shale"
    },
    {
      "x": -1,
      "y": 24,
      "z": 6,
      "name": "Rock_Shale"
    },
    {
      "x": -1,
      "y": 25,
      "z": 6,
      "name": "Rock_Shale"
    },
    {
      "x": -1,
      "y": 26,
      "z": 6,
      "name": "Rock_Shale"
    },
    {
      "x": -1,
      "y": 27,
      "z": 6,
      "name": "Rock_Shale"
    },
    {
      "x": -1,
      "y": 20,
      "z": 7,
      "name": "Rock_Shale"
    },
    {
      "x": -1,
      "y": 21,
      "z": 7,
      "name": "Rock_Shale"
    },
    {
      "x": -1,
      "y": 22,
      "z": 7,
      "name": "Rock_Shale"
    },
    {
      "x": -1,
      "y": 23,
      "z": 7,
      "name": "Rock_Shale"
    },
    {
      "x": -1,
      "y": 24,
      "z": 7,
      "name": "Rock_Shale"
    },
    {
      "x": -1,
      "y": 25,
      "z": 7,
      "name": "Rock_Shale"
    },
    {
      "x": -1,
      "y": 26,
      "z": 7,
      "name": "Rock_Shale"
    },
    {
      "x": -1,
      "y": 24,
      "z": 8,
      "name": "Rock_Shale"
    },
    {
      "x": -1,
      "y": 25,
      "z": 8,
      "name": "Rock_Shale"
    },
    {
      "x": -1,
      "y": 26,
      "z": 8,
      "name": "Rock_Shale"
    },
    {
      "x": 0,
      "y": 22,
      "z": -7,
      "name": "Rock_Shale"
    },
    {
      "x": 0,
      "y": 23,
      "z": -7,
      "name": "Rock_Shale"
    },
    {
      "x": 0,
      "y": 24,
      "z": -7,
      "name": "Rock_Shale"
    },
    {
      "x": 0,
      "y": 25,
      "z": -7,
      "name": "Rock_Shale"
    },
    {
      "x": 0,
      "y": 26,
      "z": -7,
      "name": "Rock_Shale"
    },
    {
      "x": 0,
      "y": 17,
      "z": -6,
      "name": "Rock_Shale"
    },
    {
      "x": 0,
      "y": 18,
      "z": -6,
      "name": "Rock_Shale"
    },
    {
      "x": 0,
      "y": 19,
      "z": -6,
      "name": "Rock_Shale"
    },
    {
      "x": 0,
      "y": 20,
      "z": -6,
      "name": "Rock_Shale"
    },
    {
      "x": 0,
      "y": 21,
      "z": -6,
      "name": "Rock_Shale"
    },
    {
      "x": 0,
      "y": 22,
      "z": -6,
      "name": "Rock_Shale"
    },
    {
      "x": 0,
      "y": 23,
      "z": -6,
      "name": "Rock_Shale"
    },
    {
      "x": 0,
      "y": 24,
      "z": -6,
      "name": "Rock_Shale"
    },
    {
      "x": 0,
      "y": 25,
      "z": -6,
      "name": "Rock_Shale"
    },
    {
      "x": 0,
      "y": 26,
      "z": -6,
      "name": "Rock_Shale"
    },
    {
      "x": 0,
      "y": 27,
      "z": -6,
      "name": "Rock_Shale"
    },
    {
      "x": 0,
      "y": 16,
      "z": -5,
      "name": "Rock_Shale"
    },
    {
      "x": 0,
      "y": 17,
      "z": -5,
      "name": "Rock_Shale"
    },
    {
      "x": 0,
      "y": 18,
      "z": -5,
      "name": "Rock_Shale"
    },
    {
      "x": 0,
      "y": 19,
      "z": -5,
      "name": "Rock_Shale"
    },
    {
      "x": 0,
      "y": 20,
      "z": -5,
      "name": "Rock_Shale"
    },
    {
      "x": 0,
      "y": 21,
      "z": -5,
      "name": "Rock_Shale"
    },
    {
      "x": 0,
      "y": 22,
      "z": -5,
      "name": "Rock_Shale"
    },
    {
      "x": 0,
      "y": 23,
      "z": -5,
      "name": "Rock_Shale"
    },
    {
      "x": 0,
      "y": 24,
      "z": -5,
      "name": "Rock_Shale"
    },
    {
      "x": 0,
      "y": 25,
      "z": -5,
      "name": "Rock_Shale"
    },
    {
      "x": 0,
      "y": 26,
      "z": -5,
      "name": "Rock_Shale"
    },
    {
      "x": 0,
      "y": 27,
      "z": -5,
      "name": "Rock_Shale"
    },
    {
      "x": 0,
      "y": 0,
      "z": -4,
      "name": "Rock_Shale"
    },
    {
      "x": 0,
      "y": 15,
      "z": -4,
      "name": "Rock_Shale"
    },
    {
      "x": 0,
      "y": 16,
      "z": -4,
      "name": "Rock_Shale"
    },
    {
      "x": 0,
      "y": 17,
      "z": -4,
      "name": "Rock_Shale"
    },
    {
      "x": 0,
      "y": 18,
      "z": -4,
      "name": "Rock_Shale"
    },
    {
      "x": 0,
      "y": 19,
      "z": -4,
      "name": "Rock_Shale"
    },
    {
      "x": 0,
      "y": 20,
      "z": -4,
      "name": "Rock_Shale"
    },
    {
      "x": 0,
      "y": 21,
      "z": -4,
      "name": "Rock_Shale"
    },
    {
      "x": 0,
      "y": 22,
      "z": -4,
      "name": "Rock_Shale"
    },
    {
      "x": 0,
      "y": 23,
      "z": -4,
      "name": "Rock_Shale"
    },
    {
      "x": 0,
      "y": 24,
      "z": -4,
      "name": "Rock_Shale"
    },
    {
      "x": 0,
      "y": 25,
      "z": -4,
      "name": "Rock_Shale"
    },
    {
      "x": 0,
      "y": 26,
      "z": -4,
      "name": "Rock_Shale"
    },
    {
      "x": 0,
      "y": 27,
      "z": -4,
      "name": "Rock_Shale"
    },
    {
      "x": 0,
      "y": 28,
      "z": -4,
      "name": "Rock_Shale"
    },
    {
      "x": 0,
      "y": 0,
      "z": -3,
      "name": "Rock_Shale"
    },
    {
      "x": 0,
      "y": 1,
      "z": -3,
      "name": "Rock_Shale"
    },
    {
      "x": 0,
      "y": 12,
      "z": -3,
      "name": "Plant_Mushroom_Wall_White_Mycelium",
      "support": 15,
      "rotation": 2
    },
    {
      "x": 0,
      "y": 14,
      "z": -3,
      "name": "Rock_Shale"
    },
    {
      "x": 0,
      "y": 15,
      "z": -3,
      "name": "Rock_Shale"
    },
    {
      "x": 0,
      "y": 16,
      "z": -3,
      "name": "Rock_Shale"
    },
    {
      "x": 0,
      "y": 17,
      "z": -3,
      "name": "Rock_Shale"
    },
    {
      "x": 0,
      "y": 18,
      "z": -3,
      "name": "Rock_Shale"
    },
    {
      "x": 0,
      "y": 19,
      "z": -3,
      "name": "Rock_Shale"
    },
    {
      "x": 0,
      "y": 20,
      "z": -3,
      "name": "Rock_Shale"
    },
    {
      "x": 0,
      "y": 21,
      "z": -3,
      "name": "Rock_Shale"
    },
    {
      "x": 0,
      "y": 22,
      "z": -3,
      "name": "Rock_Shale"
    },
    {
      "x": 0,
      "y": 23,
      "z": -3,
      "name": "Rock_Shale"
