{
  "version": 8,
  "blockIdVersion": 11,
  "anchorX": 0,
  "anchorY": 0,
  "anchorZ": 0,
  "blocks": [
    {
      "x": -16,
      "y": 0,
      "z": 0,
      "name": "Rock_Shale"
    },
    {
      "x": -15,
      "y": 0,
      "z": -1,
      "name": "Rock_Shale"
    },
    {
      "x": -15,
      "y": 0,
      "z": 0,
      "name": "Rock_Shale"
    },
    {
      "x": -15,
      "y": 0,
      "z": 1,
      "name": "Rock_Shale"
    },
    {
      "x": -14,
      "y": 0,
      "z": -2,
      "name": "Rock_Shale"
    },
    {
      "x": -14,
      "y": 0,
      "z": -1,
      "name": "Rock_Shale"
    },
    {
      "x": -14,
      "y": 1,
      "z": -1,
      "name": "Rock_Shale"
    },
    {
      "x": -14,
      "y": 0,
      "z": 0,
      "name": "Rock_Shale"
    },
    {
      "x": -14,
      "y": 0,
      "z": 1,
      "name": "Rock_Shale"
    },
    {
      "x": -13,
      "y": 0,
      "z": -4,
      "name": "Rock_Shale"
    },
    {
      "x": -13,
      "y": 0,
      "z": -3,
      "name": "Rock_Shale"
    },
    {
      "x": -13,
      "y": 0,
      "z": -2,
      "name": "Rock_Shale"
    },
    {
      "x": -13,
      "y": 1,
      "z": -2,
      "name": "Rock_Shale"
    },
    {
      "x": -13,
      "y": 0,
      "z": -1,
      "name": "Rock_Shale"
    },
    {
      "x": -13,
      "y": 1,
      "z": -1,
      "name": "Rock_Shale"
    },
    {
      "x": -13,
      "y": 0,
      "z": 0,
      "name": "Rock_Shale"
    },
    {
      "x": -13,
      "y": 1,
      "z": 0,
      "name": "Rock_Shale"
    },
    {
      "x": -13,
      "y": 0,
      "z": 1,
      "name": "Rock_Shale"
    },
    {
      "x": -13,
      "y": 1,
      "z": 1,
      "name": "Rock_Shale"
    },
    {
      "x": -13,
      "y": 0,
      "z": 2,
      "name": "Rock_Shale"
    },
    {
      "x": -13,
      "y": 0,
      "z": 3,
      "name": "Rock_Shale"
    },
    {
      "x": -13,
      "y": 0,
      "z": 4,
      "name": "Rock_Shale"
    },
    {
      "x": -13,
      "y": 0,
      "z": 5,
      "name": "Rock_Shale"
    },
    {
      "x": -12,
      "y": 0,
      "z": -5,
      "name": "Rock_Shale"
    },
    {
      "x": -12,
      "y": 0,
      "z": -4,
      "name": "Rock_Shale"
    },
    {
      "x": -12,
      "y": 0,
      "z": -3,
      "name": "Rock_Shale"
    },
    {
      "x": -12,
      "y": 43,
      "z": -3,
      "name": "Rock_Shale"
    },
    {
      "x": -12,
      "y": 0,
      "z": -2,
      "name": "Rock_Shale"
    },
    {
      "x": -12,
      "y": 1,
      "z": -2,
      "name": "Rock_Shale"
    },
    {
      "x": -12,
      "y": 42,
      "z": -2,
      "name": "Rock_Shale"
    },
    {
      "x": -12,
      "y": 43,
      "z": -2,
      "name": "Rock_Shale"
    },
    {
      "x": -12,
      "y": 0,
      "z": -1,
      "name": "Rock_Shale"
    },
    {
      "x": -12,
      "y": 1,
      "z": -1,
      "name": "Rock_Shale"
    },
    {
      "x": -12,
      "y": 41,
      "z": -1,
      "name": "Rock_Shale"
    },
    {
      "x": -12,
      "y": 42,
      "z": -1,
      "name": "Rock_Shale"
    },
    {
      "x": -12,
      "y": 43,
      "z": -1,
      "name": "Rock_Shale"
    },
    {
      "x": -12,
      "y": 0,
      "z": 0,
      "name": "Rock_Shale"
    },
    {
      "x": -12,
      "y": 1,
      "z": 0,
      "name": "Rock_Shale"
    },
    {
      "x": -12,
      "y": 2,
      "z": 0,
      "name": "Rock_Shale"
    },
    {
      "x": -12,
      "y": 41,
      "z": 0,
      "name": "Rock_Shale"
    },
    {
      "x": -12,
      "y": 42,
      "z": 0,
      "name": "Rock_Shale"
    },
    {
      "x": -12,
      "y": 43,
      "z": 0,
      "name": "Rock_Shale"
    },
    {
      "x": -12,
      "y": 0,
      "z": 1,
      "name": "Rock_Shale"
    },
    {
      "x": -12,
      "y": 1,
      "z": 1,
      "name": "Rock_Shale"
    },
    {
      "x": -12,
      "y": 2,
      "z": 1,
      "name": "Rock_Shale"
    },
    {
      "x": -12,
      "y": 42,
      "z": 1,
      "name": "Rock_Shale"
    },
    {
      "x": -12,
      "y": 43,
      "z": 1,
      "name": "Rock_Shale"
    },
    {
      "x": -12,
      "y": 0,
      "z": 2,
      "name": "Rock_Shale"
    },
    {
      "x": -12,
      "y": 1,
      "z": 2,
      "name": "Rock_Shale"
    },
    {
      "x": -12,
      "y": 0,
      "z": 3,
      "name": "Rock_Shale"
    },
    {
      "x": -12,
      "y": 1,
      "z": 3,
      "name": "Rock_Shale"
    },
    {
      "x": -12,
      "y": 2,
      "z": 3,
      "name": "Rock_Shale"
    },
    {
      "x": -12,
      "y": 0,
      "z": 4,
      "name": "Rock_Shale"
    },
    {
      "x": -12,
      "y": 0,
      "z": 5,
      "name": "Rock_Shale"
    },
    {
      "x": -12,
      "y": 1,
      "z": 5,
      "name": "Rock_Shale"
    },
    {
      "x": -12,
      "y": 0,
      "z": 6,
      "name": "Rock_Shale"
    },
    {
      "x": -12,
      "y": 0,
      "z": 7,
      "name": "Rock_Shale"
    },
    {
      "x": -12,
      "y": 0,
      "z": 8,
      "name": "Rock_Shale"
    },
    {
      "x": -12,
      "y": 1,
      "z": 8,
      "name": "Wood_Giantwood_Trunk_Tainted_Full"
    },
    {
      "x": -11,
      "y": 0,
      "z": -5,
      "name": "Rock_Shale"
    },
    {
      "x": -11,
      "y": 0,
      "z": -4,
      "name": "Rock_Shale"
    },
    {
      "x": -11,
      "y": 42,
      "z": -4,
      "name": "Rock_Shale"
    },
    {
      "x": -11,
      "y": 43,
      "z": -4,
      "name": "Rock_Shale"
    },
    {
      "x": -11,
      "y": 0,
      "z": -3,
      "name": "Rock_Shale"
    },
    {
      "x": -11,
      "y": 1,
      "z": -3,
      "name": "Rock_Shale"
    },
    {
      "x": -11,
      "y": 41,
      "z": -3,
      "name": "Rock_Shale"
    },
    {
      "x": -11,
      "y": 42,
      "z": -3,
      "name": "Rock_Shale"
    },
    {
      "x": -11,
      "y": 43,
      "z": -3,
      "name": "Rock_Shale"
    },
    {
      "x": -11,
      "y": 0,
      "z": -2,
      "name": "Rock_Shale"
    },
    {
      "x": -11,
      "y": 1,
      "z": -2,
      "name": "Rock_Shale"
    },
    {
      "x": -11,
      "y": 40,
      "z": -2,
      "name": "Rock_Shale"
    },
    {
      "x": -11,
      "y": 41,
      "z": -2,
      "name": "Rock_Shale"
    },
    {
      "x": -11,
      "y": 42,
      "z": -2,
      "name": "Rock_Shale"
    },
    {
      "x": -11,
      "y": 43,
      "z": -2,
      "name": "Rock_Shale"
    },
    {
      "x": -11,
      "y": 0,
      "z": -1,
      "name": "Rock_Shale"
    },
    {
      "x": -11,
      "y": 1,
      "z": -1,
      "name": "Rock_Shale"
    },
    {
      "x": -11,
      "y": 2,
      "z": -1,
      "name": "Rock_Shale"
    },
    {
      "x": -11,
      "y": 39,
      "z": -1,
      "name": "Rock_Shale"
    },
    {
      "x": -11,
      "y": 40,
      "z": -1,
      "name": "Rock_Shale"
    },
    {
      "x": -11,
      "y": 41,
      "z": -1,
      "name": "Rock_Shale"
    },
    {
      "x": -11,
      "y": 42,
      "z": -1,
      "name": "Rock_Shale"
    },
    {
      "x": -11,
      "y": 43,
      "z": -1,
      "name": "Rock_Shale"
    },
    {
      "x": -11,
      "y": 44,
      "z": -1,
      "name": "Rock_Shale"
    },
    {
      "x": -11,
      "y": 0,
      "z": 0,
      "name": "Rock_Shale"
    },
    {
      "x": -11,
      "y": 1,
      "z": 0,
      "name": "Rock_Shale"
    },
    {
      "x": -11,
      "y": 2,
      "z": 0,
      "name": "Rock_Shale"
    },
    {
      "x": -11,
      "y": 39,
      "z": 0,
      "name": "Rock_Shale"
    },
    {
      "x": -11,
      "y": 40,
      "z": 0,
      "name": "Rock_Shale"
    },
    {
      "x": -11,
      "y": 41,
      "z": 0,
      "name": "Rock_Shale"
    },
    {
      "x": -11,
      "y": 42,
      "z": 0,
      "name": "Rock_Shale"
    },
    {
      "x": -11,
      "y": 43,
      "z": 0,
      "name": "Rock_Shale"
    },
    {
      "x": -11,
      "y": 44,
      "z": 0,
      "name": "Rock_Shale"
    },
    {
      "x": -11,
      "y": 0,
      "z": 1,
      "name": "Rock_Shale"
    },
    {
      "x": -11,
      "y": 1,
      "z": 1,
      "name": "Rock_Shale"
    },
    {
      "x": -11,
      "y": 2,
      "z": 1,
      "name": "Rock_Shale"
    },
    {
      "x": -11,
      "y": 40,
      "z": 1,
      "name": "Rock_Shale"
    },
    {
      "x": -11,
      "y": 41,
      "z": 1,
      "name": "Rock_Shale"
    },
    {
      "x": -11,
      "y": 42,
      "z": 1,
      "name": "Rock_Shale"
    },
    {
      "x": -11,
      "y": 43,
      "z": 1,
      "name": "Rock_Shale"
    },
    {
      "x": -11,
      "y": 0,
      "z": 2,
      "name": "Rock_Shale"
    },
    {
      "x": -11,
      "y": 1,
      "z": 2,
      "name": "Rock_Shale"
    },
    {
      "x": -11,
      "y": 2,
      "z": 2,
      "name": "Rock_Shale"
    },
    {
      "x": -11,
      "y": 3,
      "z": 2,
      "name": "Rock_Shale"
    },
    {
      "x": -11,
      "y": 41,
      "z": 2,
      "name": "Rock_Shale"
    },
    {
      "x": -11,
      "y": 42,
      "z": 2,
      "name": "Rock_Shale"
    },
    {
      "x": -11,
      "y": 43,
      "z": 2,
      "name": "Rock_Shale"
    },
    {
      "x": -11,
      "y": 0,
      "z": 3,
      "name": "Rock_Shale"
    },
    {
      "x": -11,
      "y": 1,
      "z": 3,
      "name": "Rock_Shale"
    },
    {
      "x": -11,
      "y": 2,
      "z": 3,
      "name": "Rock_Shale"
    },
    {
      "x": -11,
      "y": 0,
      "z": 4,
      "name": "Rock_Shale"
    },
    {
      "x": -11,
      "y": 1,
      "z": 4,
      "name": "Rock_Shale"
    },
    {
      "x": -11,
      "y": 2,
      "z": 4,
      "name": "Rock_Shale"
    },
    {
      "x": -11,
      "y": 0,
      "z": 5,
      "name": "Rock_Shale"
    },
    {
      "x": -11,
      "y": 1,
      "z": 5,
      "name": "Rock_Shale"
    },
    {
      "x": -11,
      "y": 2,
      "z": 5,
      "name": "Rock_Shale"
    },
    {
      "x": -11,
      "y": 0,
      "z": 6,
      "name": "Rock_Shale"
    },
    {
      "x": -11,
      "y": 1,
      "z": 6,
      "name": "Rock_Shale"
    },
    {
      "x": -11,
      "y": 2,
      "z": 6,
      "name": "Wood_Giantwood_Trunk_Tainted_Full"
    },
    {
      "x": -11,
      "y": 0,
      "z": 7,
      "name": "Rock_Shale"
    },
    {
      "x": -11,
      "y": 1,
      "z": 7,
      "name": "Wood_Giantwood_Trunk_Tainted_Full"
    },
    {
      "x": -11,
      "y": 2,
      "z": 7,
      "name": "Wood_Giantwood_Trunk_Tainted_Full"
    },
    {
      "x": -11,
      "y": 0,
      "z": 8,
      "name": "Rock_Shale"
    },
    {
      "x": -11,
      "y": 1,
      "z": 8,
      "name": "Wood_Giantwood_Trunk_Tainted_Full"
    },
    {
      "x": -11,
      "y": 2,
      "z": 8,
      "name": "Wood_Giantwood_Trunk_Tainted_Full"
    },
    {
      "x": -11,
      "y": 0,
      "z": 9,
      "name": "Rock_Shale"
    },
    {
      "x": -11,
      "y": 1,
      "z": 9,
      "name": "Wood_Giantwood_Trunk_Tainted_Full"
    },
    {
      "x": -10,
      "y": 42,
      "z": -6,
      "name": "Rock_Shale"
    },
    {
      "x": -10,
      "y": 43,
      "z": -6,
      "name": "Rock_Shale"
    },
    {
      "x": -10,
      "y": 0,
      "z": -5,
      "name": "Rock_Shale"
    },
    {
      "x": -10,
      "y": 41,
      "z": -5,
      "name": "Rock_Shale"
    },
    {
      "x": -10,
      "y": 42,
      "z": -5,
      "name": "Rock_Shale"
    },
    {
      "x": -10,
      "y": 43,
      "z": -5,
      "name": "Rock_Shale"
    },
    {
      "x": -10,
      "y": 0,
      "z": -4,
      "name": "Rock_Shale"
    },
    {
      "x": -10,
      "y": 40,
      "z": -4,
      "name": "Rock_Shale"
    },
    {
      "x": -10,
      "y": 41,
      "z": -4,
      "name": "Rock_Shale"
    },
    {
      "x": -10,
      "y": 42,
      "z": -4,
      "name": "Rock_Shale"
    },
    {
      "x": -10,
      "y": 43,
      "z": -4,
      "name": "Rock_Shale"
    },
    {
      "x": -10,
      "y": 0,
      "z": -3,
      "name": "Rock_Shale"
    },
    {
      "x": -10,
      "y": 1,
      "z": -3,
      "name": "Rock_Shale"
    },
    {
      "x": -10,
      "y": 39,
      "z": -3,
      "name": "Rock_Shale"
    },
    {
      "x": -10,
      "y": 40,
      "z": -3,
      "name": "Rock_Shale"
    },
    {
      "x": -10,
      "y": 41,
      "z": -3,
      "name": "Rock_Shale"
    },
    {
      "x": -10,
      "y": 42,
      "z": -3,
      "name": "Rock_Shale"
    },
    {
      "x": -10,
      "y": 43,
      "z": -3,
      "name": "Rock_Shale"
    },
    {
      "x": -10,
      "y": 44,
      "z": -3,
      "name": "Rock_Shale"
    },
    {
      "x": -10,
      "y": 0,
      "z": -2,
      "name": "Rock_Shale"
    },
    {
      "x": -10,
      "y": 1,
      "z": -2,
      "name": "Rock_Shale"
    },
    {
      "x": -10,
      "y": 2,
      "z": -2,
      "name": "Rock_Shale"
    },
    {
      "x": -10,
      "y": 38,
      "z": -2,
      "name": "Rock_Shale"
    },
    {
      "x": -10,
      "y": 39,
      "z": -2,
      "name": "Rock_Shale"
    },
    {
      "x": -10,
      "y": 40,
      "z": -2,
      "name": "Rock_Shale"
    },
    {
      "x": -10,
      "y": 41,
      "z": -2,
      "name": "Rock_Shale"
    },
    {
      "x": -10,
      "y": 42,
      "z": -2,
      "name": "Rock_Shale"
    },
    {
      "x": -10,
      "y": 43,
      "z": -2,
      "name": "Rock_Shale"
    },
    {
      "x": -10,
      "y": 44,
      "z": -2,
      "name": "Rock_Shale"
    },
    {
      "x": -10,
      "y": 0,
      "z": -1,
      "name": "Rock_Shale"
    },
    {
      "x": -10,
      "y": 1,
      "z": -1,
      "name": "Rock_Shale"
    },
    {
      "x": -10,
      "y": 2,
      "z": -1,
      "name": "Rock_Shale"
    },
    {
      "x": -10,
      "y": 37,
      "z": -1,
      "name": "Rock_Shale"
    },
    {
      "x": -10,
      "y": 38,
      "z": -1,
      "name": "Rock_Shale"
    },
    {
      "x": -10,
      "y": 39,
      "z": -1,
      "name": "Rock_Shale"
    },
    {
      "x": -10,
      "y": 40,
      "z": -1,
      "name": "Rock_Shale"
    },
    {
      "x": -10,
      "y": 41,
      "z": -1,
      "name": "Rock_Shale"
    },
    {
      "x": -10,
      "y": 42,
      "z": -1,
      "name": "Rock_Shale"
    },
    {
      "x": -10,
      "y": 43,
      "z": -1,
      "name": "Rock_Shale"
    },
    {
      "x": -10,
      "y": 44,
      "z": -1,
      "name": "Rock_Shale"
    },
    {
      "x": -10,
      "y": 0,
      "z": 0,
      "name": "Rock_Shale"
    },
    {
      "x": -10,
      "y": 1,
      "z": 0,
      "name": "Rock_Shale"
    },
    {
      "x": -10,
      "y": 2,
      "z": 0,
      "name": "Rock_Shale"
    },
    {
      "x": -10,
      "y": 3,
      "z": 0,
      "name": "Rock_Shale"
    },
    {
      "x": -10,
      "y": 37,
      "z": 0,
      "name": "Rock_Shale"
    },
    {
      "x": -10,
      "y": 38,
      "z": 0,
      "name": "Rock_Shale"
    },
    {
      "x": -10,
      "y": 39,
      "z": 0,
      "name": "Rock_Shale"
    },
    {
      "x": -10,
      "y": 40,
      "z": 0,
      "name": "Rock_Shale"
    },
    {
      "x": -10,
      "y": 41,
      "z": 0,
      "name": "Rock_Shale"
    },
    {
      "x": -10,
      "y": 42,
      "z": 0,
      "name": "Rock_Shale"
    },
    {
      "x": -10,
      "y": 43,
      "z": 0,
      "name": "Rock_Shale"
    },
    {
      "x": -10,
      "y": 44,
      "z": 0,
      "name": "Rock_Shale"
    },
    {
      "x": -10,
      "y": 0,
      "z": 1,
      "name": "Rock_Shale"
    },
    {
      "x": -10,
      "y": 1,
      "z": 1,
      "name": "Rock_Shale"
    },
    {
      "x": -10,
      "y": 2,
      "z": 1,
      "name": "Rock_Shale"
    },
    {
      "x": -10,
      "y": 3,
      "z": 1,
      "name": "Rock_Shale"
    },
    {
      "x": -10,
      "y": 38,
      "z": 1,
      "name": "Rock_Shale"
    },
    {
      "x": -10,
      "y": 39,
      "z": 1,
      "name": "Rock_Shale"
    },
    {
      "x": -10,
      "y": 40,
      "z": 1,
      "name": "Rock_Shale"
    },
    {
      "x": -10,
      "y": 41,
      "z": 1,
      "name": "Rock_Shale"
    },
    {
      "x": -10,
      "y": 42,
      "z": 1,
      "name": "Rock_Shale"
    },
    {
      "x": -10,
      "y": 43,
      "z": 1,
      "name": "Rock_Shale"
    },
    {
      "x": -10,
      "y": 44,
      "z": 1,
      "name": "Rock_Shale"
    },
    {
      "x": -10,
      "y": 0,
      "z": 2,
      "name": "Rock_Shale"
    },
    {
      "x": -10,
      "y": 1,
      "z": 2,
      "name": "Rock_Shale"
    },
    {
      "x": -10,
      "y": 2,
      "z": 2,
      "name": "Rock_Shale"
    },
    {
      "x": -10,
      "y": 3,
      "z": 2,
      "name": "Rock_Shale"
    },
    {
      "x": -10,
      "y": 39,
      "z": 2,
      "name": "Rock_Shale"
    },
    {
      "x": -10,
      "y": 40,
      "z": 2,
      "name": "Rock_Shale"
    },
    {
      "x": -10,
      "y": 41,
      "z": 2,
      "name": "Rock_Shale"
    },
    {
      "x": -10,
      "y": 42,
      "z": 2,
      "name": "Rock_Shale"
    },
    {
      "x": -10,
      "y": 43,
      "z": 2,
      "name": "Rock_Shale"
    },
    {
      "x": -10,
      "y": 0,
      "z": 3,
      "name": "Rock_Shale"
    },
    {
      "x": -10,
      "y": 1,
      "z": 3,
      "name": "Rock_Shale"
    },
    {
      "x": -10,
      "y": 2,
      "z": 3,
      "name": "Rock_Shale"
    },
    {
      "x": -10,
      "y": 3,
      "z": 3,
      "name": "Rock_Shale"
    },
    {
      "x": -10,
      "y": 40,
      "z": 3,
      "name": "Rock_Shale"
    },
    {
      "x": -10,
      "y": 41,
      "z": 3,
      "name": "Rock_Shale"
    },
    {
      "x": -10,
      "y": 42,
      "z": 3,
      "name": "Rock_Shale"
    },
    {
      "x": -10,
      "y": 43,
      "z": 3,
      "name": "Rock_Shale"
    },
    {
      "x": -10,
      "y": 0,
      "z": 4,
      "name": "Rock_Shale"
    },
    {
      "x": -10,
      "y": 1,
      "z": 4,
      "name": "Rock_Shale"
    },
    {
      "x": -10,
      "y": 2,
      "z": 4,
      "name": "Rock_Shale"
    },
    {
      "x": -10,
      "y": 0,
      "z": 5,
      "name": "Rock_Shale"
    },
    {
      "x": -10,
      "y": 1,
      "z": 5,
      "name": "Rock_Shale"
    },
    {
      "x": -10,
      "y": 2,
      "z": 5,
      "name": "Rock_Shale"
    },
    {
      "x": -10,
      "y": 3,
      "z": 5,
      "name": "Wood_Giantwood_Trunk_Tainted_Full"
    },
    {
      "x": -10,
      "y": 0,
      "z": 6,
      "name": "Rock_Shale"
    },
    {
      "x": -10,
      "y": 1,
      "z": 6,
      "name": "Rock_Shale"
    },
    {
      "x": -10,
      "y": 2,
      "z": 6,
      "name": "Rock_Shale"
    },
    {
      "x": -10,
      "y": 3,
      "z": 6,
      "name": "Wood_Giantwood_Trunk_Tainted_Full"
    },
    {
      "x": -10,
      "y": 0,
      "z": 7,
      "name": "Rock_Shale"
    },
    {
      "x": -10,
      "y": 1,
      "z": 7,
      "name": "Rock_Shale"
    },
    {
      "x": -10,
      "y": 2,
      "z": 7,
      "name": "Wood_Giantwood_Trunk_Tainted_Full"
    },
    {
      "x": -10,
      "y": 3,
      "z": 7,
      "name": "Wood_Giantwood_Trunk_Tainted_Full"
    },
    {
      "x": -10,
      "y": 0,
      "z": 8,
      "name": "Rock_Shale"
    },
    {
      "x": -10,
      "y": 1,
      "z": 8,
      "name": "Wood_Giantwood_Trunk_Tainted_Full"
    },
    {
      "x": -10,
      "y": 2,
      "z": 8,
      "name": "Wood_Giantwood_Trunk_Tainted_Full"
    },
    {
      "x": -10,
      "y": 0,
      "z": 9,
      "name": "Rock_Shale"
    },
    {
      "x": -10,
      "y": 1,
      "z": 9,
      "name": "Rock_Shale"
    },
    {
      "x": -9,
      "y": 42,
      "z": -8,
      "name": "Rock_Shale"
    },
    {
      "x": -9,
      "y": 43,
      "z": -8,
      "name": "Rock_Shale"
    },
    {
      "x": -9,
      "y": 41,
      "z": -7,
      "name": "Rock_Shale"
    },
    {
      "x": -9,
      "y": 42,
      "z": -7,
      "name": "Rock_Shale"
    },
    {
      "x": -9,
      "y": 43,
      "z": -7,
      "name": "Rock_Shale"
    },
    {
      "x": -9,
      "y": 40,
      "z": -6,
      "name": "Rock_Shale"
    },
    {
      "x": -9,
      "y": 41,
      "z": -6,
      "name": "Rock_Shale"
    },
    {
      "x": -9,
      "y": 42,
      "z": -6,
      "name": "Rock_Shale"
    },
    {
      "x": -9,
      "y": 43,
      "z": -6,
      "name": "Rock_Shale"
    },
    {
      "x": -9,
      "y": 0,
      "z": -5,
      "name": "Rock_Shale"
    },
    {
      "x": -9,
      "y": 40,
      "z": -5,
      "name": "Rock_Shale"
    },
    {
      "x": -9,
      "y": 41,
      "z": -5,
      "name": "Rock_Shale"
    },
    {
      "x": -9,
      "y": 42,
      "z": -5,
      "name": "Rock_Shale"
    },
    {
      "x": -9,
      "y": 43,
      "z": -5,
      "name": "Rock_Shale"
    },
    {
      "x": -9,
      "y": 0,
      "z": -4,
      "name": "Rock_Shale"
    },
    {
      "x": -9,
      "y": 1,
      "z": -4,
      "name": "Rock_Shale"
    },
    {
      "x": -9,
      "y": 38,
      "z": -4,
      "name": "Rock_Shale"
    },
    {
      "x": -9,
      "y": 39,
      "z": -4,
      "name": "Rock_Shale"
    },
    {
      "x": -9,
      "y": 40,
      "z": -4,
      "name": "Rock_Shale"
    },
    {
      "x": -9,
      "y": 41,
      "z": -4,
      "name": "Rock_Shale"
    },
    {
      "x": -9,
      "y": 42,
      "z": -4,
      "name": "Rock_Shale"
    },
    {
      "x": -9,
      "y": 43,
      "z": -4,
      "name": "Rock_Shale"
    },
    {
      "x": -9,
      "y": 44,
      "z": -4,
      "name": "Rock_Shale"
    },
    {
      "x": -9,
      "y": 0,
      "z": -3,
      "name": "Rock_Shale"
    },
    {
      "x": -9,
      "y": 1,
      "z": -3,
      "name": "Rock_Shale"
    },
    {
      "x": -9,
      "y": 37,
      "z": -3,
      "name": "Rock_Shale"
    },
    {
      "x": -9,
      "y": 38,
      "z": -3,
      "name": "Rock_Shale"
    },
    {
      "x": -9,
      "y": 39,
      "z": -3,
      "name": "Rock_Shale"
    },
    {
      "x": -9,
      "y": 40,
      "z": -3,
      "name": "Rock_Shale"
    },
    {
      "x": -9,
      "y": 41,
      "z": -3,
      "name": "Rock_Shale"
    },
    {
      "x": -9,
      "y": 42,
      "z": -3,
      "name": "Rock_Shale"
    },
    {
      "x": -9,
      "y": 43,
      "z": -3,
      "name": "Rock_Shale"
    },
    {
      "x": -9,
      "y": 44,
      "z": -3,
      "name": "Rock_Shale"
    },
    {
      "x": -9,
      "y": 0,
      "z": -2,
      "name": "Rock_Shale"
    },
    {
      "x": -9,
      "y": 1,
      "z": -2,
      "name": "Rock_Shale"
    },
    {
      "x": -9,
      "y": 2,
      "z": -2,
      "name": "Rock_Shale"
    },
    {
      "x": -9,
      "y": 36,
      "z": -2,
      "name": "Rock_Shale"
    },
    {
      "x": -9,
      "y": 37,
      "z": -2,
      "name": "Rock_Shale"
    },
    {
      "x": -9,
      "y": 38,
      "z": -2,
      "name": "Rock_Shale"
    },
    {
      "x": -9,
      "y": 39,
      "z": -2,
      "name": "Rock_Shale"
    },
    {
      "x": -9,
      "y": 40,
      "z": -2,
      "name": "Rock_Shale"
    },
    {
      "x": -9,
      "y": 41,
      "z": -2,
      "name": "Rock_Shale"
    },
    {
      "x": -9,
      "y": 42,
      "z": -2,
      "name": "Rock_Shale"
    },
    {
      "x": -9,
      "y": 43,
      "z": -2,
      "name": "Rock_Shale"
    },
    {
      "x": -9,
      "y": 44,
      "z": -2,
      "name": "Rock_Shale"
    },
    {
      "x": -9,
      "y": 0,
      "z": -1,
      "name": "Rock_Shale"
    },
    {
      "x": -9,
      "y": 1,
      "z": -1,
      "name": "Rock_Shale"
    },
    {
      "x": -9,
      "y": 2,
      "z": -1,
      "name": "Rock_Shale"
    },
    {
      "x": -9,
      "y": 36,
      "z": -1,
      "name": "Rock_Shale"
    },
    {
      "x": -9,
      "y": 37,
      "z": -1,
      "name": "Rock_Shale"
    },
    {
      "x": -9,
      "y": 38,
      "z": -1,
      "name": "Rock_Shale"
    },
    {
      "x": -9,
      "y": 39,
      "z": -1,
      "name": "Rock_Shale"
    },
    {
      "x": -9,
      "y": 40,
      "z": -1,
      "name": "Rock_Shale"
    },
    {
      "x": -9,
      "y": 41,
      "z": -1,
      "name": "Rock_Shale"
    },
    {
      "x": -9,
      "y": 42,
      "z": -1,
      "name": "Rock_Shale"
    },
    {
      "x": -9,
      "y": 43,
      "z": -1,
      "name": "Rock_Shale"
    },
    {
      "x": -9,
      "y": 44,
      "z": -1,
      "name": "Rock_Shale"
    },
    {
      "x": -9,
      "y": 45,
      "z": -1,
      "name": "Rock_Shale"
    },
    {
      "x": -9,
      "y": 0,
      "z": 0,
      "name": "Rock_Shale"
    },
    {
      "x": -9,
      "y": 1,
      "z": 0,
      "name": "Rock_Shale"
    },
    {
      "x": -9,
      "y": 2,
      "z": 0,
      "name": "Rock_Shale"
    },
    {
      "x": -9,
      "y": 3,
      "z": 0,
      "name": "Rock_Shale"
    },
    {
      "x": -9,
      "y": 36,
      "z": 0,
      "name": "Rock_Shale"
    },
    {
      "x": -9,
      "y": 37,
      "z": 0,
      "name": "Rock_Shale"
    },
    {
      "x": -9,
      "y": 38,
      "z": 0,
      "name": "Rock_Shale"
    },
    {
      "x": -9,
      "y": 39,
      "z": 0,
      "name": "Rock_Shale"
    },
    {
      "x": -9,
      "y": 40,
      "z": 0,
      "name": "Rock_Shale"
    },
    {
      "x": -9,
      "y": 41,
      "z": 0,
      "name": "Rock_Shale"
    },
    {
      "x": -9,
      "y": 42,
      "z": 0,
      "name": "Rock_Shale"
    },
    {
      "x": -9,
      "y": 43,
      "z": 0,
      "name": "Rock_Shale"
    },
    {
      "x": -9,
      "y": 44,
      "z": 0,
      "name": "Rock_Shale"
    },
    {
      "x": -9,
      "y": 45,
      "z": 0,
      "name": "Rock_Shale"
    },
    {
      "x": -9,
      "y": 0,
      "z": 1,
      "name": "Rock_Shale"
    },
    {
      "x": -9,
      "y": 1,
      "z": 1,
      "name": "Rock_Shale"
    },
    {
      "x": -9,
      "y": 2,
      "z": 1,
      "name": "Rock_Shale"
    },
    {
      "x": -9,
      "y": 3,
      "z": 1,
      "name": "Rock_Shale"
    },
    {
      "x": -9,
      "y": 36,
      "z": 1,
      "name": "Rock_Shale"
    },
    {
      "x": -9,
      "y": 37,
      "z": 1,
      "name": "Rock_Shale"
    },
    {
      "x": -9,
      "y": 38,
      "z": 1,
      "name": "Rock_Shale"
    },
    {
      "x": -9,
      "y": 39,
      "z": 1,
      "name": "Rock_Shale"
    },
    {
      "x": -9,
      "y": 40,
      "z": 1,
      "name": "Rock_Shale"
    },
    {
      "x": -9,
      "y": 41,
      "z": 1,
      "name": "Rock_Shale"
    },
    {
      "x": -9,
      "y": 42,
      "z": 1,
      "name": "Rock_Shale"
    },
    {
      "x": -9,
      "y": 43,
      "z": 1,
      "name": "Rock_Shale"
    },
    {
      "x": -9,
      "y": 44,
      "z": 1,
      "name": "Rock_Shale"
    },
    {
      "x": -9,
      "y": 0,
      "z": 2,
      "name": "Rock_Shale"
    },
    {
      "x": -9,
      "y": 1,
      "z": 2,
      "name": "Rock_Shale"
    },
    {
      "x": -9,
      "y": 2,
      "z": 2,
      "name": "Rock_Shale"
    },
    {
      "x": -9,
      "y": 3,
      "z": 2,
      "name": "Rock_Shale"
    },
    {
      "x": -9,
      "y": 36,
      "z": 2,
      "name": "Rock_Shale"
    },
    {
      "x": -9,
      "y": 37,
      "z": 2,
      "name": "Rock_Shale"
    },
    {
      "x": -9,
      "y": 38,
      "z": 2,
      "name": "Rock_Shale"
    },
    {
      "x": -9,
      "y": 39,
      "z": 2,
      "name": "Rock_Shale"
    },
    {
      "x": -9,
      "y": 40,
      "z": 2,
      "name": "Rock_Shale"
    },
    {
      "x": -9,
      "y": 41,
      "z": 2,
      "name": "Rock_Shale"
    },
    {
      "x": -9,
      "y": 42,
      "z": 2,
      "name": "Rock_Shale"
    },
    {
      "x": -9,
      "y": 43,
      "z": 2,
      "name": "Rock_Shale"
    },
    {
      "x": -9,
      "y": 44,
      "z": 2,
      "name": "Rock_Shale"
    },
    {
      "x": -9,
      "y": 0,
      "z": 3,
      "name": "Rock_Shale"
    },
    {
      "x": -9,
      "y": 1,
      "z": 3,
      "name": "Rock_Shale"
    },
    {
      "x": -9,
      "y": 2,
      "z": 3,
      "name": "Rock_Shale"
    },
    {
      "x": -9,
      "y": 3,
      "z": 3,
      "name": "Wood_Giantwood_Trunk_Tainted_Full",
      "support": 15
    },
    {
      "x": -9,
      "y": 4,
      "z": 3,
      "name": "Wood_Giantwood_Trunk_Tainted_Full",
      "support": 15
    },
    {
      "x": -9,
      "y": 37,
      "z": 3,
      "name": "Rock_Shale"
    },
    {
      "x": -9,
      "y": 38,
      "z": 3,
      "name": "Rock_Shale"
    },
    {
      "x": -9,
      "y": 39,
      "z": 3,
      "name": "Rock_Shale"
    },
    {
      "x": -9,
      "y": 40,
      "z": 3,
      "name": "Rock_Shale"
    },
    {
      "x": -9,
      "y": 41,
      "z": 3,
      "name": "Rock_Shale"
    },
    {
      "x": -9,
      "y": 42,
      "z": 3,
      "name": "Rock_Shale"
    },
    {
      "x": -9,
      "y": 43,
      "z": 3,
      "name": "Rock_Shale"
    },
    {
      "x": -9,
      "y": 0,
      "z": 4,
      "name": "Rock_Shale"
    },
    {
      "x": -9,
      "y": 1,
      "z": 4,
      "name": "Rock_Shale"
    },
    {
      "x": -9,
      "y": 2,
      "z": 4,
      "name": "Rock_Shale"
    },
    {
      "x": -9,
      "y": 3,
      "z": 4,
      "name": "Wood_Giantwood_Trunk_Tainted_Full",
      "support": 15
    },
    {
      "x": -9,
      "y": 4,
      "z": 4,
      "name": "Wood_Giantwood_Trunk_Tainted_Full",
      "support": 15
    },
    {
      "x": -9,
      "y": 39,
      "z": 4,
      "name": "Rock_Shale"
    },
    {
      "x": -9,
      "y": 40,
      "z": 4,
      "name": "Rock_Shale"
    },
    {
      "x": -9,
      "y": 41,
      "z": 4,
      "name": "Rock_Shale"
    },
    {
      "x": -9,
      "y": 42,
      "z": 4,
      "name": "Rock_Shale"
    },
    {
      "x": -9,
      "y": 43,
      "z": 4,
      "name": "Rock_Shale"
    },
    {
      "x": -9,
      "y": 0,
      "z": 5,
      "name": "Rock_Shale"
    },
    {
      "x": -9,
      "y": 1,
      "z": 5,
      "name": "Rock_Shale"
    },
    {
      "x": -9,
      "y": 2,
      "z": 5,
      "name": "Rock_Shale"
    },
    {
      "x": -9,
      "y": 3,
      "z": 5,
      "name": "Rock_Shale"
    },
    {
      "x": -9,
      "y": 4,
      "z": 5,
      "name": "Wood_Giantwood_Trunk_Tainted_Full"
    },
    {
      "x": -9,
      "y": 0,
      "z": 6,
      "name": "Rock_Shale"
    },
    {
      "x": -9,
      "y": 1,
      "z": 6,
      "name": "Rock_Shale"
    },
    {
      "x": -9,
      "y": 2,
      "z": 6,
      "name": "Rock_Shale"
    },
    {
      "x": -9,
      "y": 3,
      "z": 6,
      "name": "Wood_Giantwood_Trunk_Tainted_Full"
    },
    {
      "x": -9,
      "y": 0,
      "z": 7,
      "name": "Rock_Shale"
    },
    {
      "x": -9,
      "y": 1,
      "z": 7,
      "name": "Rock_Shale"
    },
    {
      "x": -9,
      "y": 2,
      "z": 7,
      "name": "Wood_Giantwood_Trunk_Tainted_Full"
    },
    {
      "x": -9,
      "y": 3,
      "z": 7,
      "name": "Wood_Giantwood_Trunk_Tainted_Full"
    },
    {
      "x": -9,
      "y": 0,
      "z": 8,
      "name": "Rock_Shale"
    },
    {
      "x": -9,
      "y": 1,
      "z": 8,
      "name": "Rock_Shale"
    },
    {
      "x": -9,
      "y": 2,
      "z": 8,
      "name": "Wood_Giantwood_Trunk_Tainted_Full"
    },
    {
      "x": -9,
      "y": 0,
      "z": 9,
      "name": "Rock_Shale"
    },
    {
      "x": -9,
      "y": 0,
      "z": 10,
      "name": "Rock_Shale"
    },
    {
      "x": -8,
      "y": 43,
      "z": -10,
      "name": "Rock_Shale"
    },
    {
      "x": -8,
      "y": 41,
      "z": -9,
      "name": "Rock_Shale"
    },
    {
      "x": -8,
      "y": 42,
      "z": -9,
      "name": "Rock_Shale"
    },
    {
      "x": -8,
      "y": 43,
      "z": -9,
      "name": "Rock_Shale"
    },
    {
      "x": -8,
      "y": 40,
      "z": -8,
      "name": "Rock_Shale"
    },
    {
      "x": -8,
      "y": 41,
      "z": -8,
      "name": "Rock_Shale"
    },
    {
      "x": -8,
      "y": 42,
      "z": -8,
      "name": "Rock_Shale"
    },
    {
      "x": -8,
      "y": 43,
      "z": -8,
      "name": "Rock_Shale"
    },
    {
      "x": -8,
      "y": 39,
      "z": -7,
      "name": "Rock_Shale"
    },
    {
      "x": -8,
      "y": 40,
      "z": -7,
      "name": "Rock_Shale"
    },
    {
      "x": -8,
      "y": 41,
      "z": -7,
      "name": "Rock_Shale"
    },
    {
      "x": -8,
      "y": 42,
      "z": -7,
      "name": "Rock_Shale"
    },
    {
      "x": -8,
      "y": 43,
      "z": -7,
      "name": "Rock_Shale"
    },
    {
      "x": -8,
      "y": 38,
      "z": -6,
      "name": "Rock_Shale"
    },
    {
      "x": -8,
      "y": 39,
      "z": -6,
      "name": "Rock_Shale"
    },
    {
      "x": -8,
      "y": 40,
      "z": -6,
      "name": "Rock_Shale"
    },
    {
      "x": -8,
      "y": 41,
      "z": -6,
      "name": "Rock_Shale"
    },
    {
      "x": -8,
      "y": 42,
      "z": -6,
      "name": "Rock_Shale"
    },
    {
      "x": -8,
      "y": 43,
      "z": -6,
      "name": "Rock_Shale"
    },
    {
      "x": -8,
      "y": 44,
      "z": -6,
      "name": "Rock_Shale"
    },
    {
      "x": -8,
      "y": 0,
      "z": -5,
      "name": "Rock_Shale"
    },
    {
      "x": -8,
      "y": 1,
      "z": -5,
      "name": "Wood_Giantwood_Trunk_Tainted_Full"
    },
    {
      "x": -8,
      "y": 36,
      "z": -5,
      "name": "Rock_Shale"
    },
    {
      "x": -8,
      "y": 37,
      "z": -5,
      "name": "Rock_Shale"
    },
    {
      "x": -8,
      "y": 38,
      "z": -5,
      "name": "Rock_Shale"
    },
    {
      "x": -8,
      "y": 39,
      "z": -5,
      "name": "Rock_Shale"
    },
    {
      "x": -8,
      "y": 40,
      "z": -5,
      "name": "Rock_Shale"
    },
    {
      "x": -8,
      "y": 41,
      "z": -5,
      "name": "Rock_Shale"
    },
    {
      "x": -8,
      "y": 42,
      "z": -5,
      "name": "Rock_Shale"
    },
    {
      "x": -8,
      "y": 43,
      "z": -5,
      "name": "Rock_Shale"
    },
    {
      "x": -8,
      "y": 44,
      "z": -5,
      "name": "Rock_Shale"
    },
    {
      "x": -8,
      "y": 0,
      "z": -4,
      "name": "Rock_Shale"
    },
    {
      "x": -8,
      "y": 1,
      "z": -4,
      "name": "Wood_Giantwood_Trunk_Tainted_Full"
    },
    {
      "x": -8,
      "y": 2,
      "z": -4,
      "name": "Wood_Giantwood_Trunk_Tainted_Full"
    },
    {
      "x": -8,
      "y": 35,
      "z": -4,
      "name": "Rock_Shale"
    },
    {
      "x": -8,
      "y": 36,
      "z": -4,
      "name": "Rock_Shale"
    },
    {
      "x": -8,
      "y": 37,
      "z": -4,
      "name": "Rock_Shale"
    },
    {
      "x": -8,
      "y": 38,
      "z": -4,
      "name": "Rock_Shale"
    },
    {
      "x": -8,
      "y": 39,
      "z": -4,
      "name": "Rock_Shale"
    },
    {
      "x": -8,
      "y": 40,
      "z": -4,
      "name": "Rock_Shale"
    },
    {
      "x": -8,
      "y": 41,
      "z": -4,
      "name": "Rock_Shale"
    },
    {
      "x": -8,
      "y": 42,
      "z": -4,
      "name": "Rock_Shale"
    },
    {
      "x": -8,
      "y": 43,
      "z": -4,
      "name": "Rock_Shale"
    },
    {
      "x": -8,
      "y": 44,
      "z": -4,
      "name": "Rock_Shale"
    },
    {
      "x": -8,
      "y": 0,
      "z": -3,
      "name": "Rock_Shale"
    },
    {
      "x": -8,
      "y": 1,
      "z": -3,
      "name": "Rock_Shale"
    },
    {
      "x": -8,
      "y": 2,
      "z": -3,
      "name": "Wood_Giantwood_Trunk_Tainted_Full"
    },
    {
      "x": -8,
      "y": 3,
      "z": -3,
      "name": "Wood_Giantwood_Trunk_Tainted_Full"
    },
    {
      "x": -8,
      "y": 36,
      "z": -3,
      "name": "Rock_Shale"
    },
    {
      "x": -8,
      "y": 37,
      "z": -3,
      "name": "Rock_Shale"
    },
    {
      "x": -8,
      "y": 38,
      "z": -3,
      "name": "Rock_Shale"
    },
    {
      "x": -8,
      "y": 39,
      "z": -3,
      "name": "Rock_Shale"
    },
    {
      "x": -8,
      "y": 40,
      "z": -3,
      "name": "Rock_Shale"
    },
    {
      "x": -8,
      "y": 41,
      "z": -3,
      "name": "Rock_Shale"
    },
    {
      "x": -8,
      "y": 42,
      "z": -3,
      "name": "Rock_Shale"
    },
    {
      "x": -8,
      "y": 43,
      "z": -3,
      "name": "Rock_Shale"
    },
    {
      "x": -8,
      "y": 44,
      "z": -3,
      "name": "Rock_Shale"
    },
    {
      "x": -8,
      "y": 45,
      "z": -3,
      "name": "Rock_Shale"
    },
    {
      "x": -8,
      "y": 0,
      "z": -2,
      "name": "Rock_Shale"
    },
    {
      "x": -8,
      "y": 1,
      "z": -2,
      "name": "Rock_Shale"
    },
    {
      "x": -8,
      "y": 2,
      "z": -2,
      "name": "Rock_Shale"
    },
    {
      "x": -8,
      "y": 36,
      "z": -2,
      "name": "Rock_Shale"
    },
    {
      "x": -8,
      "y": 37,
      "z": -2,
      "name": "Rock_Shale"
    },
    {
      "x": -8,
      "y": 38,
      "z": -2,
      "name": "Rock_Shale"
    },
    {
      "x": -8,
      "y": 39,
      "z": -2,
      "name": "Rock_Shale"
    },
    {
      "x": -8,
      "y": 40,
      "z": -2,
      "name": "Rock_Shale"
    },
    {
      "x": -8,
      "y": 41,
      "z": -2,
      "name": "Rock_Shale"
    },
    {
      "x": -8,
      "y": 42,
      "z": -2,
      "name": "Rock_Shale"
    },
    {
      "x": -8,
      "y": 43,
      "z": -2,
      "name": "Rock_Shale"
    },
    {
      "x": -8,
      "y": 44,
      "z": -2,
      "name": "Rock_Shale"
    },
    {
      "x": -8,
      "y": 45,
      "z": -2,
      "name": "Rock_Shale"
    },
    {
      "x": -8,
      "y": 0,
      "z": -1,
      "name": "Rock_Shale"
    },
    {
      "x": -8,
      "y": 1,
      "z": -1,
      "name": "Rock_Shale"
    },
    {
      "x": -8,
      "y": 2,
      "z": -1,
      "name": "Rock_Shale"
    },
    {
      "x": -8,
      "y": 3,
      "z": -1,
      "name": "Rock_Shale"
    },
    {
      "x": -8,
      "y": 35,
      "z": -1,
      "name": "Rock_Shale"
    },
    {
      "x": -8,
      "y": 36,
      "z": -1,
      "name": "Rock_Shale"
    },
    {
      "x": -8,
      "y": 37,
      "z": -1,
      "name": "Rock_Shale"
    },
    {
      "x": -8,
      "y": 38,
      "z": -1,
      "name": "Rock_Shale"
    },
    {
      "x": -8,
      "y": 39,
      "z": -1,
      "name": "Rock_Shale"
    },
    {
      "x": -8,
      "y": 40,
      "z": -1,
      "name": "Rock_Shale"
    },
    {
      "x": -8,
      "y": 41,
      "z": -1,
      "name": "Rock_Shale"
    },
    {
      "x": -8,
      "y": 42,
      "z": -1,
      "name": "Rock_Shale"
    },
    {
      "x": -8,
      "y": 43,
      "z": -1,
      "name": "Rock_Shale"
    },
    {
      "x": -8,
      "y": 44,
      "z": -1,
      "name": "Rock_Shale"
    },
    {
      "x": -8,
      "y": 45,
      "z": -1,
      "name": "Rock_Shale"
    },
    {
      "x": -8,
      "y": 0,
      "z": 0,
      "name": "Rock_Shale"
    },
    {
      "x": -8,
      "y": 1,
      "z": 0,
      "name": "Rock_Shale"
    },
    {
      "x": -8,
      "y": 2,
      "z": 0,
      "name": "Rock_Shale"
    },
    {
      "x": -8,
      "y": 3,
      "z": 0,
      "name": "Rock_Shale"
    },
    {
      "x": -8,
      "y": 35,
      "z": 0,
      "name": "Rock_Shale"
    },
    {
      "x": -8,
      "y": 36,
      "z": 0,
      "name": "Rock_Shale"
    },
    {
      "x": -8,
      "y": 37,
      "z": 0,
      "name": "Rock_Shale"
    },
    {
      "x": -8,
      "y": 38,
      "z": 0,
      "name": "Rock_Shale"
    },
    {
      "x": -8,
      "y": 39,
      "z": 0,
      "name": "Rock_Shale"
    },
    {
      "x": -8,
      "y": 40,
      "z": 0,
      "name": "Rock_Shale"
    },
    {
      "x": -8,
      "y": 41,
      "z": 0,
      "name": "Rock_Shale"
    },
    {
      "x": -8,
      "y": 42,
      "z": 0,
      "name": "Rock_Shale"
    },
    {
      "x": -8,
      "y": 43,
      "z": 0,
      "name": "Rock_Shale"
    },
    {
      "x": -8,
      "y": 44,
      "z": 0,
      "name": "Rock_Shale"
    },
    {
      "x": -8,
      "y": 45,
      "z": 0,
      "name": "Rock_Shale"
    },
    {
      "x": -8,
      "y": 0,
      "z": 1,
      "name": "Rock_Shale"
    },
    {
      "x": -8,
      "y": 1,
      "z": 1,
      "name": "Rock_Shale"
    },
    {
      "x": -8,
      "y": 2,
      "z": 1,
      "name": "Rock_Shale"
    },
    {
      "x": -8,
      "y": 3,
      "z": 1,
      "name": "Rock_Shale"
    },
    {
      "x": -8,
      "y": 4,
      "z": 1,
      "name": "Rock_Shale"
    },
    {
      "x": -8,
      "y": 5,
      "z": 1,
      "name": "Wood_Giantwood_Trunk_Tainted_Full"
    },
    {
      "x": -8,
      "y": 6,
      "z": 1,
      "name": "Wood_Giantwood_Trunk_Tainted_Full"
    },
    {
      "x": -8,
      "y": 34,
      "z": 1,
      "name": "Rock_Shale"
    },
    {
      "x": -8,
      "y": 35,
      "z": 1,
      "name": "Rock_Shale"
    },
    {
      "x": -8,
      "y": 36,
      "z": 1,
      "name": "Rock_Shale"
    },
    {
      "x": -8,
      "y": 37,
      "z": 1,
      "name": "Rock_Shale"
    },
    {
      "x": -8,
      "y": 38,
      "z": 1,
      "name": "Rock_Shale"
    },
    {
      "x": -8,
      "y": 39,
      "z": 1,
      "name": "Rock_Shale"
    },
    {
      "x": -8,
      "y": 40,
      "z": 1,
      "name": "Rock_Shale"
    },
    {
      "x": -8,
      "y": 41,
      "z": 1,
      "name": "Rock_Shale"
    },
    {
      "x": -8,
      "y": 42,
      "z": 1,
      "name": "Rock_Shale"
    },
    {
      "x": -8,
      "y": 43,
      "z": 1,
      "name": "Rock_Shale"
    },
    {
      "x": -8,
      "y": 44,
      "z": 1,
      "name": "Rock_Shale"
    },
    {
      "x": -8,
      "y": 45,
      "z": 1,
      "name": "Rock_Shale"
    },
    {
      "x": -8,
      "y": 0,
      "z": 2,
      "name": "Rock_Shale"
    },
    {
      "x": -8,
      "y": 1,
      "z": 2,
      "name": "Rock_Shale"
    },
    {
      "x": -8,
      "y": 2,
      "z": 2,
      "name": "Rock_Shale"
    },
    {
      "x": -8,
      "y": 3,
      "z": 2,
      "name": "Rock_Shale"
    },
    {
      "x": -8,
      "y": 4,
      "z": 2,
      "name": "Wood_Giantwood_Trunk_Tainted_Full",
      "support": 15
    },
    {
      "x": -8,
      "y": 5,
      "z": 2,
      "name": "Wood_Giantwood_Trunk_Tainted_Full",
      "support": 15
    },
    {
      "x": -8,
      "y": 35,
      "z": 2,
      "name": "Rock_Shale"
    },
    {
      "x": -8,
      "y": 36,
      "z": 2,
      "name": "Rock_Shale"
    },
    {
      "x": -8,
      "y": 37,
      "z": 2,
      "name": "Rock_Shale"
    },
    {
      "x": -8,
      "y": 38,
      "z": 2,
      "name": "Rock_Shale"
    },
    {
      "x": -8,
      "y": 39,
      "z": 2,
      "name": "Rock_Shale"
    },
    {
      "x": -8,
      "y": 40,
      "z": 2,
      "name": "Rock_Shale"
    },
    {
      "x": -8,
      "y": 41,
      "z": 2,
      "name": "Rock_Shale"
    },
    {
      "x": -8,
      "y": 42,
      "z": 2,
      "name": "Rock_Shale"
    },
    {
      "x": -8,
      "y": 43,
      "z": 2,
      "name": "Rock_Shale"
    },
    {
      "x": -8,
      "y": 44,
      "z": 2,
      "name": "Rock_Shale"
    },
    {
      "x": -8,
      "y": 0,
      "z": 3,
      "name": "Rock_Shale"
    },
    {
      "x": -8,
      "y": 1,
      "z": 3,
      "name": "Rock_Shale"
    },
    {
      "x": -8,
      "y": 2,
      "z": 3,
      "name": "Rock_Shale"
    },
    {
      "x": -8,
      "y": 3,
      "z": 3,
      "name": "Rock_Shale"
    },
    {
      "x": -8,
      "y": 4,
      "z": 3,
      "name": "Rock_Shale"
    },
    {
      "x": -8,
      "y": 5,
      "z": 3,
      "name": "Wood_Giantwood_Trunk_Tainted_Full"
    },
    {
      "x": -8,
      "y": 6,
      "z": 3,
      "name": "Wood_Giantwood_Trunk_Tainted_Full"
    },
    {
      "x": -8,
      "y": 36,
      "z": 3,
      "name": "Rock_Shale"
    },
    {
      "x": -8,
      "y": 37,
      "z": 3,
      "name": "Rock_Shale"
    },
    {
      "x": -8,
      "y": 38,
      "z": 3,
      "name": "Rock_Shale"
    },
    {
      "x": -8,
      "y": 39,
      "z": 3,
      "name": "Rock_Shale"
    },
    {
      "x": -8,
      "y": 40,
      "z": 3,
      "name": "Rock_Shale"
    },
    {
      "x": -8,
      "y": 41,
      "z": 3,
      "name": "Rock_Shale"
    },
    {
      "x": -8,
      "y": 42,
      "z": 3,
      "name": "Rock_Shale"
    },
    {
      "x": -8,
      "y": 43,
      "z": 3,
      "name": "Rock_Shale"
    },
    {
      "x": -8,
      "y": 44,
      "z": 3,
      "name": "Rock_Shale"
    },
    {
      "x": -8,
      "y": 0,
      "z": 4,
      "name": "Rock_Shale"
    },
    {
      "x": -8,
      "y": 1,
      "z": 4,
      "name": "Rock_Shale"
    },
    {
      "x": -8,
      "y": 2,
      "z": 4,
      "name": "Rock_Shale"
    },
    {
      "x": -8,
      "y": 3,
      "z": 4,
      "name": "Rock_Shale"
    },
    {
      "x": -8,
      "y": 4,
      "z": 4,
      "name": "Wood_Giantwood_Trunk_Tainted_Full"
    },
    {
      "x": -8,
      "y": 5,
      "z": 4,
      "name": "Wood_Giantwood_Trunk_Tainted_Full"
    },
    {
      "x": -8,
      "y": 36,
      "z": 4,
      "name": "Rock_Shale"
    },
    {
      "x": -8,
      "y": 37,
      "z": 4,
      "name": "Rock_Shale"
    },
    {
      "x": -8,
      "y": 38,
      "z": 4,
      "name": "Rock_Shale"
    },
    {
      "x": -8,
      "y": 39,
      "z": 4,
      "name": "Rock_Shale"
    },
    {
      "x": -8,
      "y": 40,
      "z": 4,
      "name": "Rock_Shale"
    },
    {
      "x": -8,
      "y": 41,
      "z": 4,
      "name": "Rock_Shale"
    },
    {
      "x": -8,
      "y": 42,
      "z": 4,
      "name": "Rock_Shale"
    },
    {
      "x": -8,
      "y": 43,
      "z": 4,
      "name": "Rock_Shale"
    },
    {
      "x": -8,
      "y": 0,
      "z": 5,
      "name": "Rock_Shale"
    },
    {
      "x": -8,
      "y": 1,
      "z": 5,
      "name": "Rock_Shale"
    },
    {
      "x": -8,
      "y": 2,
      "z": 5,
      "name": "Rock_Shale"
    },
    {
      "x": -8,
      "y": 3,
      "z": 5,
      "name": "Rock_Shale"
    },
    {
      "x": -8,
      "y": 4,
      "z": 5,
      "name": "Wood_Giantwood_Trunk_Tainted_Full"
    },
    {
      "x": -8,
      "y": 5,
      "z": 5,
      "name": "Wood_Giantwood_Trunk_Tainted_Full"
    },
    {
      "x": -8,
      "y": 37,
      "z": 5,
      "name": "Rock_Shale"
    },
    {
      "x": -8,
      "y": 38,
      "z": 5,
      "name": "Rock_Shale"
    },
    {
      "x": -8,
      "y": 39,
      "z": 5,
      "name": "Rock_Shale"
    },
    {
      "x": -8,
      "y": 40,
      "z": 5,
      "name": "Rock_Shale"
    },
    {
      "x": -8,
      "y": 41,
      "z": 5,
      "name": "Rock_Shale"
    },
    {
      "x": -8,
      "y": 42,
      "z": 5,
      "name": "Rock_Shale"
    },
    {
      "x": -8,
      "y": 43,
      "z": 5,
      "name": "Rock_Shale"
    },
    {
      "x": -8,
      "y": 0,
      "z": 6,
      "name": "Rock_Shale"
    },
    {
      "x": -8,
      "y": 1,
      "z": 6,
      "name": "Rock_Shale"
    },
    {
      "x": -8,
      "y": 2,
      "z": 6,
      "name": "Rock_Shale"
    },
    {
      "x": -8,
      "y": 3,
      "z": 6,
      "name": "Rock_Shale"
    },
    {
      "x": -8,
      "y": 4,
      "z": 6,
      "name": "Wood_Giantwood_Trunk_Tainted_Full"
    },
    {
      "x": -8,
      "y": 38,
      "z": 6,
      "name": "Rock_Shale"
    },
    {
      "x": -8,
      "y": 39,
      "z": 6,
      "name": "Rock_Shale"
    },
    {
      "x": -8,
      "y": 40,
      "z": 6,
      "name": "Rock_Shale"
    },
    {
      "x": -8,
      "y": 41,
      "z": 6,
      "name": "Rock_Shale"
    },
    {
      "x": -8,
      "y": 42,
      "z": 6,
      "name": "Rock_Shale"
    },
    {
      "x": -8,
      "y": 43,
      "z": 6,
      "name": "Rock_Shale"
    },
    {
      "x": -8,
      "y": 0,
      "z": 7,
      "name": "Rock_Shale"
    },
    {
      "x": -8,
      "y": 1,
      "z": 7,
      "name": "Rock_Shale"
    },
    {
      "x": -8,
      "y": 2,
      "z": 7,
      "name": "Wood_Giantwood_Trunk_Tainted_Full",
      "support": 15
    },
    {
      "x": -8,
      "y": 3,
      "z": 7,
      "name": "Wood_Giantwood_Trunk_Tainted_Full"
    },
    {
      "x": -8,
      "y": 0,
      "z": 8,
      "name": "Rock_Shale"
    },
    {
      "x": -8,
      "y": 1,
      "z": 8,
      "name": "Rock_Shale"
    },
    {
      "x": -8,
      "y": 0,
      "z": 9,
      "name": "Rock_Shale"
    },
    {
      "x": -8,
      "y": 0,
      "z": 10,
      "name": "Rock_Shale"
    },
    {
      "x": -8,
      "y": 0,
      "z": 11,
      "name": "Rock_Shale"
    },
    {
      "x": -7,
      "y": 42,
      "z": -10,
      "name": "Rock_Shale"
    },
    {
      "x": -7,
      "y": 43,
      "z": -10,
      "name": "Rock_Shale"
    },
    {
      "x": -7,
      "y": 40,
      "z": -9,
      "name": "Rock_Shale"
    },
    {
      "x": -7,
      "y": 41,
      "z": -9,
      "name": "Rock_Shale"
    },
    {
      "x": -7,
      "y": 42,
      "z": -9,
      "name": "Rock_Shale"
    },
    {
      "x": -7,
      "y": 43,
      "z": -9,
      "name": "Rock_Shale"
    },
    {
      "x": -7,
      "y": 44,
      "z": -9,
      "name": "Rock_Shale"
    },
    {
      "x": -7,
      "y": 39,
      "z": -8,
      "name": "Rock_Shale"
    },
    {
      "x": -7,
      "y": 40,
      "z": -8,
      "name": "Rock_Shale"
    },
    {
      "x": -7,
      "y": 41,
      "z": -8,
      "name": "Rock_Shale"
    },
    {
      "x": -7,
      "y": 42,
      "z": -8,
      "name": "Rock_Shale"
    },
    {
      "x": -7,
      "y": 43,
      "z": -8,
      "name": "Rock_Shale"
    },
    {
      "x": -7,
      "y": 44,
      "z": -8,
      "name": "Rock_Shale"
    },
    {
      "x": -7,
      "y": 36,
      "z": -7,
      "name": "Rock_Shale"
    },
    {
      "x": -7,
      "y": 37,
      "z": -7,
      "name": "Rock_Shale"
    },
    {
      "x": -7,
      "y": 38,
      "z": -7,
      "name": "Rock_Shale"
    },
    {
      "x": -7,
      "y": 39,
      "z": -7,
      "name": "Rock_Shale"
    },
    {
      "x": -7,
      "y": 40,
      "z": -7,
      "name": "Rock_Shale"
    },
    {
      "x": -7,
      "y": 41,
      "z": -7,
      "name": "Rock_Shale"
    },
    {
      "x": -7,
      "y": 42,
      "z": -7,
      "name": "Rock_Shale"
    },
    {
      "x": -7,
      "y": 43,
      "z": -7,
      "name": "Rock_Shale"
    },
    {
      "x": -7,
      "y": 44,
      "z": -7,
      "name": "Rock_Shale"
    },
    {
      "x": -7,
      "y": 35,
      "z": -6,
      "name": "Rock_Shale"
    },
    {
      "x": -7,
      "y": 36,
      "z": -6,
      "name": "Rock_Shale"
    },
    {
      "x": -7,
      "y": 37,
      "z": -6,
      "name": "Rock_Shale"
    },
    {
      "x": -7,
      "y": 38,
      "z": -6,
      "name": "Rock_Shale"
    },
    {
      "x": -7,
      "y": 39,
      "z": -6,
      "name": "Rock_Shale"
    },
    {
      "x": -7,
      "y": 40,
      "z": -6,
      "name": "Rock_Shale"
    },
    {
      "x": -7,
      "y": 41,
      "z": -6,
      "name": "Rock_Shale"
    },
    {
      "x": -7,
      "y": 42,
      "z": -6,
      "name": "Rock_Shale"
    },
    {
      "x": -7,
      "y": 43,
      "z": -6,
      "name": "Rock_Shale"
    },
    {
      "x": -7,
      "y": 44,
      "z": -6,
      "name": "Rock_Shale"
    },
    {
      "x": -7,
      "y": 35,
      "z": -5,
      "name": "Rock_Shale"
    },
    {
      "x": -7,
      "y": 36,
      "z": -5,
      "name": "Rock_Shale"
    },
    {
      "x": -7,
      "y": 37,
      "z": -5,
      "name": "Rock_Shale"
    },
    {
      "x": -7,
      "y": 38,
      "z": -5,
      "name": "Rock_Shale"
    },
    {
      "x": -7,
      "y": 39,
      "z": -5,
      "name": "Rock_Shale"
    },
    {
      "x": -7,
      "y": 40,
      "z": -5,
      "name": "Rock_Shale"
    },
    {
      "x": -7,
      "y": 41,
      "z": -5,
      "name": "Rock_Shale"
    },
    {
      "x": -7,
      "y": 42,
      "z": -5,
      "name": "Rock_Shale"
    },
    {
      "x": -7,
      "y": 43,
      "z": -5,
      "name": "Rock_Shale"
    },
    {
      "x": -7,
      "y": 44,
      "z": -5,
      "name": "Rock_Shale"
    },
    {
      "x": -7,
      "y": 0,
      "z": -4,
      "name": "Rock_Shale"
    },
    {
      "x": -7,
      "y": 1,
      "z": -4,
      "name": "Rock_Shale"
    },
    {
      "x": -7,
      "y": 2,
      "z": -4,
      "name": "Wood_Giantwood_Trunk_Tainted_Full"
    },
    {
      "x": -7,
      "y": 3,
      "z": -4,
      "name": "Wood_Giantwood_Trunk_Tainted_Full"
    },
    {
      "x": -7,
      "y": 35,
      "z": -4,
      "name": "Rock_Shale"
    },
    {
      "x": -7,
      "y": 36,
      "z": -4,
      "name": "Rock_Shale"
    },
    {
      "x": -7,
      "y": 37,
      "z": -4,
      "name": "Rock_Shale"
    },
    {
      "x": -7,
      "y": 38,
      "z": -4,
      "name": "Rock_Shale"
    },
    {
      "x": -7,
      "y": 39,
      "z": -4,
      "name": "Rock_Shale"
    },
    {
      "x": -7,
      "y": 40,
      "z": -4,
      "name": "Rock_Shale"
    },
    {
      "x": -7,
      "y": 41,
      "z": -4,
      "name": "Rock_Shale"
    },
    {
      "x": -7,
      "y": 42,
      "z": -4,
      "name": "Rock_Shale"
    },
    {
      "x": -7,
      "y": 43,
      "z": -4,
      "name": "Rock_Shale"
    },
    {
      "x": -7,
      "y": 44,
      "z": -4,
      "name": "Rock_Shale"
    },
    {
      "x": -7,
      "y": 45,
      "z": -4,
      "name": "Rock_Shale"
    },
    {
      "x": -7,
      "y": 0,
      "z": -3,
      "name": "Rock_Shale"
    },
    {
      "x": -7,
      "y": 1,
      "z": -3,
      "name": "Rock_Shale"
    },
    {
      "x": -7,
      "y": 2,
      "z": -3,
      "name": "Rock_Shale"
    },
    {
      "x": -7,
      "y": 3,
      "z": -3,
      "name": "Wood_Giantwood_Trunk_Tainted_Full"
    },
    {
      "x": -7,
      "y": 4,
      "z": -3,
      "name": "Wood_Giantwood_Trunk_Tainted_Full"
    },
    {
      "x": -7,
      "y": 35,
      "z": -3,
      "name": "Rock_Shale"
    },
    {
      "x": -7,
      "y": 36,
      "z": -3,
      "name": "Rock_Shale"
    },
    {
      "x": -7,
      "y": 37,
      "z": -3,
      "name": "Rock_Shale"
    },
    {
      "x": -7,
      "y": 38,
      "z": -3,
      "name": "Rock_Shale"
    },
    {
      "x": -7,
      "y": 39,
      "z": -3,
      "name": "Rock_Shale"
    },
    {
      "x": -7,
      "y": 40,
      "z": -3,
      "name": "Rock_Shale"
    },
    {
      "x": -7,
      "y": 41,
      "z": -3,
      "name": "Rock_Shale"
    },
    {
      "x": -7,
      "y": 42,
      "z": -3,
      "name": "Rock_Shale"
    },
    {
      "x": -7,
      "y": 43,
      "z": -3,
      "name": "Rock_Shale"
    },
    {
      "x": -7,
      "y": 44,
      "z": -3,
      "name": "Rock_Shale"
    },
    {
      "x": -7,
      "y": 45,
      "z": -3,
      "name": "Rock_Shale"
    },
    {
      "x": -7,
      "y": 0,
      "z": -2,
      "name": "Rock_Shale"
    },
    {
      "x": -7,
      "y": 1,
      "z": -2,
      "name": "Rock_Shale"
    },
    {
      "x": -7,
      "y": 2,
      "z": -2,
      "name": "Rock_Shale"
    },
    {
      "x": -7,
      "y": 3,
      "z": -2,
      "name": "Wood_Giantwood_Trunk_Tainted_Full",
      "support": 15
    },
    {
      "x": -7,
      "y": 4,
      "z": -2,
      "name": "Wood_Giantwood_Trunk_Tainted_Full"
    },
    {
      "x": -7,
      "y": 35,
      "z": -2,
      "name": "Rock_Shale"
    },
    {
      "x": -7,
      "y": 36,
      "z": -2,
      "name": "Rock_Shale"
    },
    {
      "x": -7,
      "y": 37,
      "z": -2,
      "name": "Rock_Shale"
    },
    {
      "x": -7,
      "y": 38,
      "z": -2,
      "name": "Rock_Shale"
    },
    {
      "x": -7,
      "y": 39,
      "z": -2,
      "name": "Rock_Shale"
    },
    {
      "x": -7,
      "y": 40,
      "z": -2,
      "name": "Rock_Shale"
    },
    {
      "x": -7,
      "y": 41,
      "z": -2,
      "name": "Rock_Shale"
    },
    {
      "x": -7,
      "y": 42,
      "z": -2,
      "name": "Rock_Shale"
    },
    {
      "x": -7,
      "y": 43,
      "z": -2,
      "name": "Rock_Shale"
    },
    {
      "x": -7,
      "y": 44,
      "z": -2,
      "name": "Rock_Shale"
    },
    {
      "x": -7,
      "y": 45,
      "z": -2,
      "name": "Rock_Shale"
    },
    {
      "x": -7,
      "y": 0,
      "z": -1,
      "name": "Rock_Shale"
    },
    {
      "x": -7,
      "y": 1,
      "z": -1,
      "name": "Rock_Shale"
    },
    {
      "x": -7,
      "y": 2,
      "z": -1,
      "name": "Rock_Shale"
    },
    {
      "x": -7,
      "y": 3,
      "z": -1,
      "name": "Rock_Shale"
    },
    {
      "x": -7,
      "y": 34,
      "z": -1,
      "name": "Rock_Shale"
    },
    {
      "x": -7,
      "y": 35,
      "z": -1,
      "name": "Rock_Shale"
    },
    {
      "x": -7,
      "y": 36,
      "z": -1,
      "name": "Rock_Shale"
    },
    {
      "x": -7,
      "y": 37,
      "z": -1,
      "name": "Rock_Shale"
    },
    {
      "x": -7,
      "y": 38,
      "z": -1,
      "name": "Rock_Shale"
    },
    {
      "x": -7,
      "y": 39,
      "z": -1,
      "name": "Rock_Shale"
    },
    {
      "x": -7,
      "y": 40,
      "z": -1,
      "name": "Rock_Shale"
    },
    {
      "x": -7,
      "y": 41,
      "z": -1,
      "name": "Rock_Shale"
    },
    {
      "x": -7,
      "y": 42,
      "z": -1,
      "name": "Rock_Shale"
    },
    {
      "x": -7,
      "y": 43,
      "z": -1,
      "name": "Rock_Shale"
    },
    {
      "x": -7,
      "y": 44,
      "z": -1,
      "name": "Rock_Shale"
    },
    {
      "x": -7,
      "y": 45,
      "z": -1,
      "name": "Rock_Shale"
    },
    {
      "x": -7,
      "y": 46,
      "z": -1,
      "name": "Rock_Shale"
    },
    {
      "x": -7,
      "y": 0,
      "z": 0,
      "name": "Rock_Shale"
    },
    {
      "x": -7,
      "y": 1,
      "z": 0,
      "name": "Rock_Shale"
    },
    {
      "x": -7,
      "y": 2,
      "z": 0,
      "name": "Rock_Shale"
    },
    {
      "x": -7,
      "y": 3,
      "z": 0,
      "name": "Rock_Shale"
    },
    {
      "x": -7,
      "y": 4,
      "z": 0,
      "name": "Wood_Giantwood_Trunk_Tainted_Full",
      "support": 15
    },
    {
      "x": -7,
      "y": 5,
      "z": 0,
      "name": "Wood_Giantwood_Trunk_Tainted_Full"
    },
    {
      "x": -7,
      "y": 33,
      "z": 0,
      "name": "Rock_Shale"
    },
    {
      "x": -7,
      "y": 34,
      "z": 0,
      "name": "Rock_Shale"
    },
    {
      "x": -7,
      "y": 35,
      "z": 0,
      "name": "Rock_Shale"
    },
    {
      "x": -7,
      "y": 36,
      "z": 0,
      "name": "Rock_Shale"
    },
    {
      "x": -7,
      "y": 37,
      "z": 0,
      "name": "Rock_Shale"
    },
    {
      "x": -7,
      "y": 38,
      "z": 0,
      "name": "Rock_Shale"
    },
    {
      "x": -7,
      "y": 39,
      "z": 0,
      "name": "Rock_Shale"
    },
    {
      "x": -7,
      "y": 40,
      "z": 0,
      "name": "Rock_Shale"
    },
    {
      "x": -7,
      "y": 41,
      "z": 0,
      "name": "Rock_Shale"
    },
    {
      "x": -7,
      "y": 42,
      "z": 0,
      "name": "Rock_Shale"
    },
    {
      "x": -7,
      "y": 43,
      "z": 0,
      "name": "Rock_Shale"
    },
    {
      "x": -7,
      "y": 44,
      "z": 0,
      "name": "Rock_Shale"
    },
    {
      "x": -7,
      "y": 45,
      "z": 0,
      "name": "Rock_Shale"
    },
    {
      "x": -7,
      "y": 46,
      "z": 0,
      "name": "Rock_Shale"
    },
    {
      "x": -7,
      "y": 0,
      "z": 1,
      "name": "Rock_Shale"
    },
    {
      "x": -7,
      "y": 1,
      "z": 1,
      "name": "Rock_Shale"
    },
    {
      "x": -7,
      "y": 2,
      "z": 1,
      "name": "Rock_Shale"
    },
    {
      "x": -7,
      "y": 3,
      "z": 1,
      "name": "Rock_Shale"
    },
    {
      "x": -7,
      "y": 4,
      "z": 1,
      "name": "Rock_Shale"
    },
    {
      "x": -7,
      "y": 5,
      "z": 1,
      "name": "Wood_Giantwood_Trunk_Tainted_Full"
    },
    {
      "x": -7,
      "y": 6,
      "z": 1,
      "name": "Wood_Giantwood_Trunk_Tainted_Full"
    },
    {
      "x": -7,
      "y": 7,
      "z": 1,
      "name": "Wood_Giantwood_Trunk_Tainted_Full"
    },
    {
      "x": -7,
      "y": 34,
      "z": 1,
      "name": "Rock_Shale"
    },
    {
      "x": -7,
      "y": 35,
      "z": 1,
      "name": "Rock_Shale"
    },
    {
      "x": -7,
      "y": 36,
      "z": 1,
      "name": "Rock_Shale"
    },
    {
      "x": -7,
      "y": 37,
      "z": 1,
      "name": "Rock_Shale"
    },
    {
      "x": -7,
      "y": 38,
      "z": 1,
      "name": "Rock_Shale"
    },
    {
      "x": -7,
      "y": 39,
      "z": 1,
      "name": "Rock_Shale"
    },
    {
      "x": -7,
      "y": 40,
      "z": 1,
      "name": "Rock_Shale"
    },
    {
      "x": -7,
      "y": 41,
      "z": 1,
      "name": "Rock_Shale"
    },
    {
      "x": -7,
      "y": 42,
      "z": 1,
      "name": "Rock_Shale"
    },
    {
      "x": -7,
      "y": 43,
      "z": 1,
      "name": "Rock_Shale"
    },
    {
      "x": -7,
      "y": 44,
      "z": 1,
      "name": "Rock_Shale"
    },
    {
      "x": -7,
      "y": 45,
      "z": 1,
      "name": "Rock_Shale"
    },
    {
      "x": -7,
      "y": 0,
      "z": 2,
      "name": "Rock_Shale"
    },
    {
      "x": -7,
      "y": 1,
      "z": 2,
      "name": "Rock_Shale"
    },
    {
      "x": -7,
      "y": 2,
      "z": 2,
      "name": "Rock_Shale"
    },
    {
      "x": -7,
      "y": 3,
      "z": 2,
      "name": "Rock_Shale"
    },
    {
      "x": -7,
      "y": 4,
      "z": 2,
      "name": "Rock_Shale"
    },
    {
      "x": -7,
      "y": 5,
      "z": 2,
      "name": "Wood_Giantwood_Trunk_Tainted_Full"
    },
    {
      "x": -7,
      "y": 6,
      "z": 2,
      "name": "Wood_Giantwood_Trunk_Tainted_Full"
    },
    {
      "x": -7,
      "y": 34,
      "z": 2,
      "name": "Rock_Shale"
    },
    {
      "x": -7,
      "y": 35,
      "z": 2,
      "name": "Rock_Shale"
    },
    {
      "x": -7,
      "y": 36,
      "z": 2,
      "name": "Rock_Shale"
    },
    {
      "x": -7,
      "y": 37,
      "z": 2,
      "name": "Rock_Shale"
    },
    {
      "x": -7,
      "y": 38,
      "z": 2,
      "name": "Rock_Shale"
    },
    {
      "x": -7,
      "y": 39,
      "z": 2,
      "name": "Rock_Shale"
    },
    {
      "x": -7,
      "y": 40,
      "z": 2,
      "name": "Rock_Shale"
    },
    {
      "x": -7,
      "y": 41,
      "z": 2,
      "name": "Rock_Shale"
    },
    {
      "x": -7,
      "y": 42,
      "z": 2,
      "name": "Rock_Shale"
    },
    {
      "x": -7,
      "y": 43,
      "z": 2,
      "name": "Rock_Shale"
    },
    {
      "x": -7,
      "y": 44,
      "z": 2,
      "name": "Rock_Shale"
    },
    {
      "x": -7,
      "y": 45,
      "z": 2,
      "name": "Rock_Shale"
    },
    {
      "x": -7,
      "y": 0,
      "z": 3,
      "name": "Rock_Shale"
    },
    {
      "x": -7,
      "y": 1,
      "z": 3,
      "name": "Rock_Shale"
    },
    {
      "x": -7,
      "y": 2,
      "z": 3,
      "name": "Rock_Shale"
    },
    {
      "x": -7,
      "y": 3,
      "z": 3,
      "name": "Rock_Shale"
    },
    {
      "x": -7,
      "y": 4,
      "z": 3,
      "name": "Rock_Shale"
    },
    {
      "x": -7,
      "y": 5,
      "z": 3,
      "name": "Wood_Giantwood_Trunk_Tainted_Full"
    },
    {
      "x": -7,
      "y": 6,
      "z": 3,
      "name": "Wood_Giantwood_Trunk_Tainted_Full"
    },
    {
      "x": -7,
      "y": 34,
      "z": 3,
      "name": "Rock_Shale"
    },
    {
      "x": -7,
      "y": 35,
      "z": 3,
      "name": "Rock_Shale"
    },
    {
      "x": -7,
      "y": 36,
      "z": 3,
      "name": "Rock_Shale"
    },
    {
      "x": -7,
      "y": 37,
      "z": 3,
      "name": "Rock_Shale"
    },
    {
      "x": -7,
      "y": 38,
      "z": 3,
      "name": "Rock_Shale"
    },
    {
      "x": -7,
      "y": 39,
      "z": 3,
      "name": "Rock_Shale"
    },
    {
      "x": -7,
      "y": 40,
      "z": 3,
      "name": "Rock_Shale"
    },
    {
      "x": -7,
      "y": 41,
      "z": 3,
      "name": "Rock_Shale"
    },
    {
      "x": -7,
      "y": 42,
      "z": 3,
      "name": "Rock_Shale"
    },
    {
      "x": -7,
      "y": 43,
      "z": 3,
      "name": "Rock_Shale"
    },
    {
      "x": -7,
      "y": 44,
      "z": 3,
      "name": "Rock_Shale"
    },
    {
      "x": -7,
      "y": 0,
      "z": 4,
      "name": "Rock_Shale"
    },
    {
      "x": -7,
      "y": 1,
      "z": 4,
      "name": "Rock_Shale"
    },
    {
      "x": -7,
      "y": 2,
      "z": 4,
      "name": "Rock_Shale"
    },
    {
      "x": -7,
      "y": 3,
      "z": 4,
      "name": "Rock_Shale"
    },
    {
      "x": -7,
      "y": 4,
      "z": 4,
      "name": "Wood_Giantwood_Trunk_Tainted_Full"
    },
    {
      "x": -7,
      "y": 5,
      "z": 4,
      "name": "Wood_Giantwood_Trunk_Tainted_Full"
    },
    {
      "x": -7,
      "y": 6,
      "z": 4,
      "name": "Wood_Giantwood_Trunk_Tainted_Full"
    },
    {
      "x": -7,
      "y": 35,
      "z": 4,
      "name": "Rock_Shale"
    },
    {
      "x": -7,
      "y": 36,
      "z": 4,
      "name": "Rock_Shale"
    },
    {
      "x": -7,
      "y": 37,
      "z": 4,
      "name": "Rock_Shale"
    },
    {
      "x": -7,
      "y": 38,
      "z": 4,
      "name": "Rock_Shale"
    },
    {
      "x": -7,
      "y": 39,
      "z": 4,
      "name": "Rock_Shale"
    },
    {
      "x": -7,
      "y": 40,
      "z": 4,
      "name": "Rock_Shale"
    },
    {
      "x": -7,
      "y": 41,
      "z": 4,
      "name": "Rock_Shale"
    },
    {
      "x": -7,
      "y": 42,
      "z": 4,
      "name": "Rock_Shale"
    },
    {
      "x": -7,
      "y": 43,
      "z": 4,
      "name": "Rock_Shale"
    },
    {
      "x": -7,
      "y": 44,
      "z": 4,
      "name": "Rock_Shale"
    },
    {
      "x": -7,
      "y": 0,
      "z": 5,
      "name": "Rock_Shale"
    },
    {
      "x": -7,
      "y": 1,
      "z": 5,
      "name": "Rock_Shale"
    },
    {
      "x": -7,
      "y": 2,
      "z": 5,
      "name": "Rock_Shale"
    },
    {
      "x": -7,
      "y": 3,
      "z": 5,
      "name": "Rock_Shale"
    },
    {
      "x": -7,
      "y": 4,
      "z": 5,
      "name": "Wood_Giantwood_Trunk_Tainted_Full"
    },
    {
      "x": -7,
      "y": 5,
      "z": 5,
      "name": "Wood_Giantwood_Trunk_Tainted_Full"
    },
    {
      "x": -7,
      "y": 35,
      "z": 5,
      "name": "Rock_Shale"
    },
    {
      "x": -7,
      "y": 36,
      "z": 5,
      "name": "Rock_Shale"
    },
    {
      "x": -7,
      "y": 37,
      "z": 5,
      "name": "Rock_Shale"
    },
    {
      "x": -7,
      "y": 38,
      "z": 5,
      "name": "Rock_Shale"
    },
    {
      "x": -7,
      "y": 39,
      "z": 5,
      "name": "Rock_Shale"
    },
    {
      "x": -7,
      "y": 40,
      "z": 5,
      "name": "Rock_Shale"
    },
    {
      "x": -7,
      "y": 41,
      "z": 5,
      "name": "Rock_Shale"
    },
    {
      "x": -7,
      "y": 42,
      "z": 5,
      "name": "Rock_Shale"
    },
    {
      "x": -7,
      "y": 43,
      "z": 5,
      "name": "Rock_Shale"
    },
    {
      "x": -7,
      "y": 0,
      "z": 6,
      "name": "Rock_Shale"
    },
    {
      "x": -7,
      "y": 1,
      "z": 6,
      "name": "Rock_Shale"
    },
    {
      "x": -7,
      "y": 2,
      "z": 6,
      "name": "Rock_Shale"
    },
    {
      "x": -7,
      "y": 3,
      "z": 6,
      "name": "Rock_Shale"
    },
    {
      "x": -7,
      "y": 4,
      "z": 6,
      "name": "Wood_Giantwood_Trunk_Tainted_Full"
    },
    {
      "x": -7,
      "y": 5,
      "z": 6,
      "name": "Wood_Giantwood_Trunk_Tainted_Full"
    },
    {
      "x": -7,
      "y": 36,
      "z": 6,
      "name": "Rock_Shale"
    },
    {
      "x": -7,
      "y": 37,
      "z": 6,
      "name": "Rock_Shale"
    },
    {
      "x": -7,
      "y": 38,
      "z": 6,
      "name": "Rock_Shale"
    },
    {
      "x": -7,
      "y": 39,
      "z": 6,
      "name": "Rock_Shale"
    },
    {
      "x": -7,
      "y": 40,
      "z": 6,
      "name": "Rock_Shale"
    },
    {
      "x": -7,
      "y": 41,
      "z": 6,
      "name": "Rock_Shale"
    },
    {
      "x": -7,
      "y": 42,
      "z": 6,
      "name": "Rock_Shale"
    },
    {
      "x": -7,
      "y": 43,
      "z": 6,
      "name": "Rock_Shale"
    },
    {
      "x": -7,
      "y": 0,
      "z": 7,
      "name": "Rock_Shale"
    },
    {
      "x": -7,
      "y": 1,
      "z": 7,
      "name": "Rock_Shale"
    },
    {
      "x": -7,
      "y": 2,
      "z": 7,
      "name": "Rock_Shale"
    },
    {
      "x": -7,
      "y": 37,
      "z": 7,
      "name": "Rock_Shale"
    },
    {
      "x": -7,
      "y": 38,
      "z": 7,
      "name": "Rock_Shale"
    },
    {
      "x": -7,
      "y": 39,
      "z": 7,
      "name": "Rock_Shale"
    },
    {
      "x": -7,
      "y": 40,
      "z": 7,
      "name": "Rock_Shale"
    },
    {
      "x": -7,
      "y": 41,
      "z": 7,
      "name": "Rock_Shale"
    },
    {
      "x": -7,
      "y": 42,
      "z": 7,
      "name": "Rock_Shale"
    },
    {
      "x": -7,
      "y": 43,
      "z": 7,
      "name": "Rock_Shale"
    },
    {
      "x": -7,
      "y": 0,
      "z": 8,
      "name": "Rock_Shale"
    },
    {
      "x": -7,
      "y": 1,
      "z": 8,
      "name": "Rock_Shale"
    },
    {
      "x": -7,
      "y": 2,
      "z": 8,
      "name": "Rock_Shale"
    },
    {
      "x": -7,
      "y": 0,
      "z": 9,
      "name": "Rock_Shale"
    },
    {
      "x": -7,
      "y": 1,
      "z": 9,
      "name": "Rock_Shale"
    },
    {
      "x": -7,
      "y": 0,
      "z": 10,
      "name": "Rock_Shale"
    },
    {
      "x": -7,
      "y": 0,
      "z": 11,
      "name": "Rock_Shale"
    },
    {
      "x": -7,
      "y": 0,
      "z": 12,
      "name": "Rock_Shale"
    },
    {
      "x": -6,
      "y": 42,
      "z": -10,
      "name": "Rock_Shale"
    },
    {
      "x": -6,
      "y": 43,
      "z": -10,
      "name": "Rock_Shale"
    },
    {
      "x": -6,
      "y": 39,
      "z": -9,
      "name": "Rock_Shale"
    },
    {
      "x": -6,
      "y": 40,
      "z": -9,
      "name": "Rock_Shale"
    },
    {
      "x": -6,
      "y": 41,
      "z": -9,
      "name": "Rock_Shale"
    },
    {
      "x": -6,
      "y": 42,
      "z": -9,
      "name": "Rock_Shale"
    },
    {
      "x": -6,
      "y": 43,
      "z": -9,
      "name": "Rock_Shale"
    },
    {
      "x": -6,
      "y": 44,
      "z": -9,
      "name": "Rock_Shale"
    },
    {
      "x": -6,
      "y": 37,
      "z": -8,
      "name": "Rock_Shale"
    },
    {
      "x": -6,
      "y": 38,
      "z": -8,
      "name": "Rock_Shale"
    },
    {
      "x": -6,
      "y": 39,
      "z": -8,
      "name": "Rock_Shale"
    },
    {
      "x": -6,
      "y": 40,
      "z": -8,
      "name": "Rock_Shale"
    },
    {
      "x": -6,
      "y": 41,
      "z": -8,
      "name": "Rock_Shale"
    },
    {
      "x": -6,
      "y": 42,
      "z": -8,
      "name": "Rock_Shale"
    },
    {
      "x": -6,
      "y": 43,
      "z": -8,
      "name": "Rock_Shale"
    },
    {
      "x": -6,
      "y": 44,
      "z": -8,
      "name": "Rock_Shale"
    },
    {
      "x": -6,
      "y": 35,
      "z": -7,
      "name": "Rock_Shale"
    },
    {
      "x": -6,
      "y": 36,
      "z": -7,
      "name": "Rock_Shale"
    },
    {
      "x": -6,
      "y": 37,
      "z": -7,
      "name": "Rock_Shale"
    },
    {
      "x": -6,
      "y": 38,
      "z": -7,
      "name": "Rock_Shale"
    },
    {
      "x": -6,
      "y": 39,
      "z": -7,
      "name": "Rock_Shale"
    },
    {
      "x": -6,
      "y": 40,
      "z": -7,
      "name": "Rock_Shale"
    },
    {
      "x": -6,
      "y": 41,
      "z": -7,
      "name": "Rock_Shale"
    },
    {
      "x": -6,
      "y": 42,
      "z": -7,
      "name": "Rock_Shale"
    },
    {
      "x": -6,
      "y": 43,
      "z": -7,
      "name": "Rock_Shale"
    },
    {
      "x": -6,
      "y": 44,
      "z": -7,
      "name": "Rock_Shale"
    },
    {
      "x": -6,
      "y": 35,
      "z": -6,
      "name": "Rock_Shale"
    },
    {
      "x": -6,
      "y": 36,
      "z": -6,
      "name": "Rock_Shale"
    },
    {
      "x": -6,
      "y": 37,
      "z": -6,
      "name": "Rock_Shale"
    },
    {
      "x": -6,
      "y": 38,
      "z": -6,
      "name": "Rock_Shale"
    },
    {
      "x": -6,
      "y": 39,
      "z": -6,
      "name": "Rock_Shale"
    },
    {
      "x": -6,
      "y": 40,
      "z": -6,
      "name": "Rock_Shale"
    },
    {
      "x": -6,
      "y": 41,
      "z": -6,
      "name": "Rock_Shale"
    },
    {
      "x": -6,
      "y": 42,
      "z": -6,
      "name": "Rock_Shale"
    },
    {
      "x": -6,
      "y": 43,
      "z": -6,
      "name": "Rock_Shale"
    },
    {
      "x": -6,
      "y": 44,
      "z": -6,
      "name": "Rock_Shale"
    },
    {
      "x": -6,
      "y": 45,
      "z": -6,
      "name": "Rock_Shale"
    },
    {
      "x": -6,
      "y": 34,
      "z": -5,
      "name": "Rock_Shale"
    },
    {
      "x": -6,
      "y": 35,
      "z": -5,
      "name": "Rock_Shale"
    },
    {
      "x": -6,
      "y": 36,
      "z": -5,
      "name": "Rock_Shale"
    },
    {
      "x": -6,
      "y": 37,
      "z": -5,
      "name": "Rock_Shale"
    },
    {
      "x": -6,
      "y": 38,
      "z": -5,
      "name": "Rock_Shale"
    },
    {
      "x": -6,
      "y": 39,
      "z": -5,
      "name": "Rock_Shale"
    },
    {
      "x": -6,
      "y": 40,
      "z": -5,
      "name": "Rock_Shale"
    },
    {
      "x": -6,
      "y": 41,
      "z": -5,
      "name": "Rock_Shale"
    },
    {
      "x": -6,
      "y": 42,
      "z": -5,
      "name": "Rock_Shale"
    },
    {
      "x": -6,
      "y": 43,
      "z": -5,
      "name": "Rock_Shale"
    },
    {
      "x": -6,
      "y": 44,
      "z": -5,
      "name": "Rock_Shale"
    },
    {
      "x": -6,
      "y": 45,
      "z": -5,
      "name": "Rock_Shale"
    },
    {
      "x": -6,
      "y": 0,
      "z": -4,
      "name": "Rock_Shale"
    },
    {
      "x": -6,
      "y": 1,
      "z": -4,
      "name": "Rock_Shale"
    },
    {
      "x": -6,
      "y": 34,
      "z": -4,
      "name": "Rock_Shale"
    },
    {
      "x": -6,
      "y": 35,
      "z": -4,
      "name": "Rock_Shale"
    },
    {
      "x": -6,
      "y": 36,
      "z": -4,
      "name": "Rock_Shale"
    },
    {
      "x": -6,
      "y": 37,
      "z": -4,
      "name": "Rock_Shale"
    },
    {
      "x": -6,
      "y": 38,
      "z": -4,
      "name": "Rock_Shale"
    },
    {
      "x": -6,
      "y": 39,
      "z": -4,
      "name": "Rock_Shale"
    },
    {
      "x": -6,
      "y": 40,
      "z": -4,
      "name": "Rock_Shale"
    },
    {
      "x": -6,
      "y": 41,
      "z": -4,
      "name": "Rock_Shale"
    },
    {
      "x": -6,
      "y": 42,
      "z": -4,
      "name": "Rock_Shale"
    },
    {
      "x": -6,
      "y": 43,
      "z": -4,
      "name": "Rock_Shale"
    },
    {
      "x": -6,
      "y": 44,
      "z": -4,
      "name": "Rock_Shale"
    },
    {
      "x": -6,
      "y": 45,
      "z": -4,
      "name": "Rock_Shale"
    },
    {
      "x": -6,
      "y": 0,
      "z": -3,
      "name": "Rock_Shale"
    },
    {
      "x": -6,
      "y": 1,
      "z": -3,
      "name": "Rock_Shale"
    },
    {
      "x": -6,
      "y": 2,
      "z": -3,
      "name": "Rock_Shale"
    },
    {
      "x": -6,
      "y": 3,
      "z": -3,
      "name": "Wood_Giantwood_Trunk_Tainted_Full"
    },
    {
      "x": -6,
      "y": 4,
      "z": -3,
      "name": "Wood_Giantwood_Trunk_Tainted_Full"
    },
    {
      "x": -6,
      "y": 34,
      "z": -3,
      "name": "Rock_Shale"
    },
    {
      "x": -6,
      "y": 35,
      "z": -3,
      "name": "Rock_Shale"
    },
    {
      "x": -6,
      "y": 36,
      "z": -3,
      "name": "Rock_Shale"
    },
    {
      "x": -6,
      "y": 37,
      "z": -3,
      "name": "Rock_Shale"
    },
    {
      "x": -6,
      "y": 38,
      "z": -3,
      "name": "Rock_Shale"
    },
    {
      "x": -6,
      "y": 39,
      "z": -3,
      "name": "Rock_Shale"
    },
    {
      "x": -6,
      "y": 40,
      "z": -3,
      "name": "Rock_Shale"
    },
    {
      "x": -6,
      "y": 41,
      "z": -3,
      "name": "Rock_Shale"
    },
    {
      "x": -6,
      "y": 42,
      "z": -3,
      "name": "Rock_Shale"
    },
    {
      "x": -6,
      "y": 43,
      "z": -3,
      "name": "Rock_Shale"
    },
    {
      "x": -6,
      "y": 44,
      "z": -3,
      "name": "Rock_Shale"
    },
    {
      "x": -6,
      "y": 45,
      "z": -3,
      "name": "Rock_Shale"
    },
    {
      "x": -6,
      "y": 46,
      "z": -3,
      "name": "Rock_Shale"
    },
    {
      "x": -6,
      "y": 0,
      "z": -2,
      "name": "Rock_Shale"
    },
    {
      "x": -6,
      "y": 1,
      "z": -2,
      "name": "Rock_Shale"
    },
    {
      "x": -6,
      "y": 2,
      "z": -2,
      "name": "Rock_Shale"
    },
    {
      "x": -6,
      "y": 3,
      "z": -2,
      "name": "Rock_Shale"
    },
    {
      "x": -6,
      "y": 4,
      "z": -2,
      "name": "Wood_Giantwood_Trunk_Tainted_Full"
    },
    {
      "x": -6,
      "y": 5,
      "z": -2,
      "name": "Wood_Giantwood_Trunk_Tainted_Full"
    },
    {
      "x": -6,
      "y": 33,
      "z": -2,
      "name": "Rock_Shale"
    },
    {
      "x": -6,
      "y": 34,
      "z": -2,
      "name": "Rock_Shale"
    },
    {
      "x": -6,
      "y": 35,
      "z": -2,
      "name": "Rock_Shale"
    },
    {
      "x": -6,
      "y": 36,
      "z": -2,
      "name": "Rock_Shale"
    },
    {
      "x": -6,
      "y": 37,
      "z": -2,
      "name": "Rock_Shale"
    },
    {
      "x": -6,
      "y": 38,
      "z": -2,
      "name": "Rock_Shale"
    },
    {
      "x": -6,
      "y": 39,
      "z": -2,
      "name": "Rock_Shale"
    },
    {
      "x": -6,
      "y": 40,
      "z": -2,
      "name": "Rock_Shale"
    },
    {
      "x": -6,
      "y": 41,
      "z": -2,
      "name": "Rock_Shale"
    },
    {
      "x": -6,
      "y": 42,
      "z": -2,
      "name": "Rock_Shale"
    },
    {
      "x": -6,
      "y": 43,
      "z": -2,
      "name": "Rock_Shale"
    },
    {
      "x": -6,
      "y": 44,
      "z": -2,
      "name": "Rock_Shale"
    },
    {
      "x": -6,
      "y": 45,
      "z": -2,
      "name": "Rock_Shale"
    },
    {
      "x": -6,
      "y": 46,
      "z": -2,
      "name": "Rock_Shale"
    },
    {
      "x": -6,
      "y": 0,
      "z": -1,
      "name": "Rock_Shale"
    },
    {
      "x": -6,
      "y": 1,
      "z": -1,
      "name": "Rock_Shale"
    },
    {
      "x": -6,
      "y": 2,
      "z": -1,
      "name": "Rock_Shale"
    },
    {
      "x": -6,
      "y": 3,
      "z": -1,
      "name": "Rock_Shale"
    },
    {
      "x": -6,
      "y": 4,
      "z": -1,
      "name": "Wood_Giantwood_Trunk_Tainted_Full"
    },
    {
      "x": -6,
      "y": 5,
      "z": -1,
      "name": "Wood_Giantwood_Trunk_Tainted_Full",
      "support": 15
    },
    {
      "x": -6,
      "y": 33,
      "z": -1,
      "name": "Rock_Shale"
    },
    {
      "x": -6,
      "y": 34,
      "z": -1,
      "name": "Rock_Shale"
    },
    {
      "x": -6,
      "y": 35,
      "z": -1,
      "name": "Rock_Shale"
    },
    {
      "x": -6,
      "y": 36,
      "z": -1,
      "name": "Rock_Shale"
    },
    {
      "x": -6,
      "y": 37,
      "z": -1,
      "name": "Rock_Shale"
    },
    {
      "x": -6,
      "y": 38,
      "z": -1,
      "name": "Rock_Shale"
    },
    {
      "x": -6,
      "y": 39,
      "z": -1,
      "name": "Rock_Shale"
    },
    {
      "x": -6,
      "y": 40,
      "z": -1,
      "name": "Rock_Shale"
    },
    {
      "x": -6,
      "y": 41,
      "z": -1,
      "name": "Rock_Shale"
    },
    {
      "x": -6,
      "y": 42,
      "z": -1,
      "name": "Rock_Shale"
    },
    {
      "x": -6,
      "y": 43,
      "z": -1,
      "name": "Rock_Shale"
    },
    {
      "x": -6,
      "y": 44,
      "z": -1,
      "name": "Rock_Shale"
    },
    {
      "x": -6,
      "y": 45,
      "z": -1,
      "name": "Rock_Shale"
    },
    {
      "x": -6,
      "y": 46,
      "z": -1,
      "name": "Rock_Shale"
    },
    {
      "x": -6,
      "y": 0,
      "z": 0,
      "name": "Rock_Shale"
    },
    {
      "x": -6,
      "y": 1,
      "z": 0,
      "name": "Rock_Shale"
    },
    {
      "x": -6,
      "y": 2,
      "z": 0,
      "name": "Rock_Shale"
    },
    {
      "x": -6,
      "y": 3,
      "z": 0,
      "name": "Rock_Shale"
    },
    {
      "x": -6,
      "y": 4,
      "z": 0,
      "name": "Rock_Shale"
    },
    {
      "x": -6,
      "y": 5,
      "z": 0,
      "name": "Wood_Giantwood_Trunk_Tainted_Full"
    },
    {
      "x": -6,
      "y": 6,
      "z": 0,
      "name": "Wood_Giantwood_Trunk_Tainted_Full",
      "support": 15
    },
    {
      "x": -6,
      "y": 7,
      "z": 0,
      "name": "Wood_Giantwood_Trunk_Tainted_Full",
      "support": 15
    },
    {
      "x": -6,
      "y": 33,
      "z": 0,
      "name": "Rock_Shale"
    },
    {
      "x": -6,
      "y": 34,
      "z": 0,
      "name": "Rock_Shale"
    },
    {
      "x": -6,
      "y": 35,
      "z": 0,
      "name": "Rock_Shale"
    },
    {
      "x": -6,
      "y": 36,
      "z": 0,
      "name": "Rock_Shale"
    },
    {
      "x": -6,
      "y": 37,
      "z": 0,
      "name": "Rock_Shale"
    },
    {
      "x": -6,
      "y": 38,
      "z": 0,
      "name": "Rock_Shale"
    },
    {
      "x": -6,
      "y": 39,
      "z": 0,
      "name": "Rock_Shale"
    },
    {
      "x": -6,
      "y": 40,
      "z": 0,
      "name": "Rock_Shale"
    },
    {
      "x": -6,
      "y": 41,
      "z": 0,
      "name": "Rock_Shale"
    },
    {
      "x": -6,
      "y": 42,
      "z": 0,
      "name": "Rock_Shale"
    },
    {
      "x": -6,
      "y": 43,
      "z": 0,
      "name": "Rock_Shale"
    },
    {
      "x": -6,
      "y": 44,
      "z": 0,
      "name": "Rock_Shale"
    },
    {
      "x": -6,
      "y": 45,
      "z": 0,
      "name": "Rock_Shale"
    },
    {
      "x": -6,
      "y": 46,
      "z": 0,
      "name": "Rock_Shale"
    },
    {
      "x": -6,
      "y": 0,
      "z": 1,
      "name": "Rock_Shale"
    },
    {
      "x": -6,
      "y": 1,
      "z": 1,
      "name": "Rock_Shale"
    },
    {
      "x": -6,
      "y": 2,
      "z": 1,
      "name": "Rock_Shale"
    },
    {
      "x": -6,
      "y": 3,
      "z": 1,
      "name": "Rock_Shale"
    },
    {
      "x": -6,
      "y": 4,
      "z": 1,
      "name": "Rock_Shale"
    },
    {
      "x": -6,
      "y": 5,
      "z": 1,
      "name": "Wood_Giantwood_Trunk_Tainted_Full"
    },
    {
      "x": -6,
      "y": 6,
      "z": 1,
      "name": "Wood_Giantwood_Trunk_Tainted_Full"
    },
    {
      "x": -6,
      "y": 7,
      "z": 1,
      "name": "Wood_Giantwood_Trunk_Tainted_Full"
    },
    {
      "x": -6,
      "y": 8,
      "z": 1,
      "name": "Wood_Giantwood_Trunk_Tainted_Full"
    },
    {
      "x": -6,
      "y": 32,
      "z": 1,
      "name": "Rock_Shale"
    },
    {
      "x": -6,
      "y": 33,
      "z": 1,
      "name": "Rock_Shale"
    },
    {
      "x": -6,
      "y": 34,
      "z": 1,
      "name": "Rock_Shale"
    },
    {
      "x": -6,
      "y": 35,
      "z": 1,
      "name": "Rock_Shale"
    },
    {
      "x": -6,
      "y": 36,
      "z": 1,
      "name": "Rock_Shale"
    },
    {
      "x": -6,
      "y": 37,
      "z": 1,
      "name": "Rock_Shale"
    },
    {
      "x": -6,
      "y": 38,
      "z": 1,
      "name": "Rock_Shale"
    },
    {
      "x": -6,
      "y": 39,
      "z": 1,
      "name": "Rock_Shale"
    },
    {
      "x": -6,
      "y": 40,
      "z": 1,
      "name": "Rock_Shale"
    },
    {
      "x": -6,
      "y": 41,
      "z": 1,
      "name": "Rock_Shale"
    },
    {
      "x": -6,
      "y": 42,
      "z": 1,
      "name": "Rock_Shale"
    },
    {
      "x": -6,
      "y": 43,
      "z": 1,
      "name": "Rock_Shale"
    },
    {
      "x": -6,
      "y": 44,
      "z": 1,
      "name": "Rock_Shale"
    },
    {
      "x": -6,
      "y": 45,
      "z": 1,
      "name": "Rock_Shale"
    },
    {
      "x": -6,
      "y": 46,
      "z": 1,
      "name": "Rock_Shale"
    },
    {
      "x": -6,
      "y": 0,
      "z": 2,
      "name": "Rock_Shale"
    },
    {
      "x": -6,
      "y": 1,
      "z": 2,
      "name": "Rock_Shale"
    },
    {
      "x": -6,
      "y": 2,
      "z": 2,
      "name": "Rock_Shale"
    },
    {
      "x": -6,
      "y": 3,
      "z": 2,
      "name": "Rock_Shale"
    },
    {
      "x": -6,
      "y": 4,
      "z": 2,
      "name": "Rock_Shale"
    },
    {
      "x": -6,
      "y": 5,
      "z": 2,
      "name": "Wood_Giantwood_Trunk_Tainted_Full"
    },
    {
      "x": -6,
      "y": 6,
      "z": 2,
      "name": "Wood_Giantwood_Trunk_Tainted_Full",
      "support": 15
    },
    {
      "x": -6,
      "y": 7,
      "z": 2,
      "name": "Wood_Giantwood_Trunk_Tainted_Full",
      "support": 15
    },
    {
      "x": -6,
      "y": 33,
      "z": 2,
      "name": "Rock_Shale"
    },
    {
      "x": -6,
      "y": 34,
      "z": 2,
      "name": "Rock_Shale"
    },
    {
      "x": -6,
      "y": 35,
      "z": 2,
      "name": "Rock_Shale"
    },
    {
      "x": -6,
      "y": 36,
      "z": 2,
      "name": "Rock_Shale"
    },
    {
      "x": -6,
      "y": 37,
      "z": 2,
      "name": "Rock_Shale"
    },
    {
      "x": -6,
      "y": 38,
      "z": 2,
      "name": "Rock_Shale"
    },
    {
      "x": -6,
      "y": 39,
      "z": 2,
      "name": "Rock_Shale"
    },
    {
      "x": -6,
      "y": 40,
      "z": 2,
      "name": "Rock_Shale"
    },
    {
      "x": -6,
      "y": 41,
      "z": 2,
      "name": "Rock_Shale"
    },
    {
      "x": -6,
      "y": 42,
      "z": 2,
      "name": "Rock_Shale"
    },
    {
      "x": -6,
      "y": 43,
      "z": 2,
      "name": "Rock_Shale"
    },
    {
      "x": -6,
      "y": 44,
      "z": 2,
      "name": "Rock_Shale"
    },
    {
      "x": -6,
      "y": 45,
      "z": 2,
      "name": "Rock_Shale"
    },
    {
      "x": -6,
      "y": 0,
      "z": 3,
      "name": "Rock_Shale"
    },
    {
      "x": -6,
      "y": 1,
      "z": 3,
      "name": "Rock_Shale"
    },
    {
      "x": -6,
      "y": 2,
      "z": 3,
      "name": "Rock_Shale"
    },
    {
      "x": -6,
      "y": 3,
      "z": 3,
      "name": "Rock_Shale"
    },
    {
      "x": -6,
      "y": 4,
      "z": 3,
      "name": "Rock_Shale"
    },
    {
      "x": -6,
      "y": 5,
      "z": 3,
      "name": "Wood_Giantwood_Trunk_Tainted_Full"
    },
    {
      "x": -6,
      "y": 6,
      "z": 3,
      "name": "Wood_Giantwood_Trunk_Tainted_Full"
    },
    {
      "x": -6,
      "y": 34,
      "z": 3,
      "name": "Rock_Shale"
    },
    {
      "x": -6,
      "y": 35,
      "z": 3,
      "name": "Rock_Shale"
    },
    {
      "x": -6,
      "y": 36,
      "z": 3,
      "name": "Rock_Shale"
    },
    {
      "x": -6,
      "y": 37,
      "z": 3,
      "name": "Rock_Shale"
    },
    {
      "x": -6,
      "y": 38,
      "z": 3,
      "name": "Rock_Shale"
    },
    {
      "x": -6,
      "y": 39,
      "z": 3,
      "name": "Rock_Shale"
    },
    {
      "x": -6,
      "y": 40,
      "z": 3,
      "name": "Rock_Shale"
    },
    {
      "x": -6,
      "y": 41,
      "z": 3,
      "name": "Rock_Shale"
    },
    {
      "x": -6,
      "y": 42,
      "z": 3,
      "name": "Rock_Shale"
    },
    {
      "x": -6,
      "y": 43,
      "z": 3,
      "name": "Rock_Shale"
    },
    {
      "x": -6,
      "y": 44,
      "z": 3,
      "name": "Rock_Shale"
    },
    {
      "x": -6,
      "y": 45,
      "z": 3,
      "name": "Rock_Shale"
    },
    {
      "x": -6,
      "y": 0,
      "z": 4,
      "name": "Rock_Shale"
    },
    {
      "x": -6,
      "y": 1,
      "z": 4,
      "name": "Rock_Shale"
    },
    {
      "x": -6,
      "y": 2,
      "z": 4,
      "name": "Rock_Shale"
    },
    {
      "x": -6,
      "y": 3,
      "z": 4,
      "name": "Rock_Shale"
    },
    {
      "x": -6,
      "y": 4,
      "z": 4,
      "name": "Rock_Shale"
    },
    {
      "x": -6,
      "y": 5,
      "z": 4,
      "name": "Wood_Giantwood_Trunk_Tainted_Full"
    },
    {
      "x": -6,
      "y": 6,
      "z": 4,
      "name": "Wood_Giantwood_Trunk_Tainted_Full",
      "support": 15
    },
    {
      "x": -6,
      "y": 30,
      "z": 4,
      "name": "Wood_Giantwood_Trunk_Tainted_Full"
    },
    {
      "x": -6,
      "y": 31,
      "z": 4,
      "name": "Wood_Giantwood_Trunk_Tainted_Full"
    },
    {
      "x": -6,
      "y": 32,
      "z": 4,
      "name": "Wood_Giantwood_Trunk_Tainted_Full"
    },
    {
      "x": -6,
      "y": 34,
      "z": 4,
      "name": "Rock_Shale"
    },
    {
      "x": -6,
      "y": 35,
      "z": 4,
      "name": "Rock_Shale"
    },
    {
      "x": -6,
      "y": 36,
      "z": 4,
      "name": "Rock_Shale"
    },
    {
      "x": -6,
      "y": 37,
      "z": 4,
      "name": "Rock_Shale"
    },
    {
      "x": -6,
      "y": 38,
      "z": 4,
      "name": "Rock_Shale"
    },
    {
      "x": -6,
      "y": 39,
      "z": 4,
      "name": "Rock_Shale"
    },
    {
      "x": -6,
      "y": 40,
      "z": 4,
      "name": "Rock_Shale"
    },
    {
      "x": -6,
      "y": 41,
      "z": 4,
      "name": "Rock_Shale"
    },
    {
      "x": -6,
      "y": 42,
      "z": 4,
      "name": "Rock_Shale"
    },
    {
      "x": -6,
      "y": 43,
      "z": 4,
      "name": "Rock_Shale"
    },
    {
      "x": -6,
      "y": 44,
      "z": 4,
      "name": "Rock_Shale"
    },
    {
      "x": -6,
      "y": 0,
      "z": 5,
      "name": "Rock_Shale"
    },
    {
      "x": -6,
      "y": 1,
      "z": 5,
      "name": "Rock_Shale"
    },
    {
      "x": -6,
      "y": 2,
      "z": 5,
      "name": "Rock_Shale"
    },
    {
      "x": -6,
      "y": 3,
      "z": 5,
      "name": "Rock_Shale"
    },
    {
      "x": -6,
      "y": 4,
      "z": 5,
      "name": "Wood_Giantwood_Trunk_Tainted_Full"
    },
    {
      "x": -6,
      "y": 5,
      "z": 5,
      "name": "Wood_Giantwood_Trunk_Tainted_Full"
    },
    {
      "x": -6,
      "y": 35,
      "z": 5,
      "name": "Rock_Shale"
    },
    {
      "x": -6,
      "y": 36,
      "z": 5,
      "name": "Rock_Shale"
    },
    {
      "x": -6,
      "y": 37,
      "z": 5,
      "name": "Rock_Shale"
    },
    {
      "x": -6,
      "y": 38,
      "z": 5,
      "name": "Rock_Shale"
    },
    {
      "x": -6,
      "y": 39,
      "z": 5,
      "name": "Rock_Shale"
    },
    {
      "x": -6,
      "y": 40,
      "z": 5,
      "name": "Rock_Shale"
    },
    {
      "x": -6,
      "y": 41,
      "z": 5,
      "name": "Rock_Shale"
    },
    {
      "x": -6,
      "y": 42,
      "z": 5,
      "name": "Rock_Shale"
    },
    {
      "x": -6,
      "y": 43,
      "z": 5,
      "name": "Rock_Shale"
    },
    {
      "x": -6,
      "y": 44,
      "z": 5,
      "name": "Rock_Shale"
    },
    {
      "x": -6,
      "y": 0,
      "z": 6,
      "name": "Rock_Shale"
    },
    {
      "x": -6,
      "y": 1,
      "z": 6,
      "name": "Rock_Shale"
    },
    {
      "x": -6,
      "y": 2,
      "z": 6,
      "name": "Rock_Shale"
    },
    {
      "x": -6,
      "y": 3,
      "z": 6,
      "name": "Rock_Shale"
    },
    {
      "x": -6,
      "y": 4,
      "z": 6,
      "name": "Wood_Giantwood_Trunk_Tainted_Full",
      "support": 15
    },
    {
      "x": -6,
      "y": 5,
      "z": 6,
      "name": "Wood_Giantwood_Trunk_Tainted_Full",
      "support": 15
    },
    {
      "x": -6,
      "y": 35,
      "z": 6,
      "name": "Rock_Shale"
    },
    {
      "x": -6,
      "y": 36,
      "z": 6,
      "name": "Rock_Shale"
    },
    {
      "x": -6,
      "y": 37,
      "z": 6,
      "name": "Rock_Shale"
    },
    {
      "x": -6,
      "y": 38,
      "z": 6,
      "name": "Rock_Shale"
    },
    {
      "x": -6,
      "y": 39,
      "z": 6,
      "name": "Rock_Shale"
    },
    {
      "x": -6,
      "y": 40,
      "z": 6,
      "name": "Rock_Shale"
    },
    {
      "x": -6,
      "y": 41,
      "z": 6,
      "name": "Rock_Shale"
    },
    {
      "x": -6,
      "y": 42,
      "z": 6,
      "name": "Rock_Shale"
    },
    {
      "x": -6,
      "y": 43,
      "z": 6,
      "name": "Rock_Shale"
    },
    {
      "x": -6,
      "y": 0,
      "z": 7,
      "name": "Rock_Shale"
    },
    {
      "x": -6,
      "y": 1,
      "z": 7,
      "name": "Rock_Shale"
    },
    {
      "x": -6,
      "y": 2,
      "z": 7,
      "name": "Rock_Shale"
    },
    {
      "x": -6,
      "y": 3,
      "z": 7,
      "name": "Rock_Shale"
    },
    {
      "x": -6,
      "y": 35,
      "z": 7,
      "name": "Rock_Shale"
    },
    {
      "x": -6,
      "y": 36,
      "z": 7,
      "name": "Rock_Shale"
    },
    {
      "x": -6,
      "y": 37,
      "z": 7,
      "name": "Rock_Shale"
    },
    {
      "x": -6,
      "y": 38,
      "z": 7,
      "name": "Rock_Shale"
    },
    {
      "x": -6,
      "y": 39,
      "z": 7,
      "name": "Rock_Shale"
    },
    {
      "x": -6,
      "y": 40,
      "z": 7,
      "name": "Rock_Shale"
    },
    {
      "x": -6,
      "y": 41,
      "z": 7,
      "name": "Rock_Shale"
    },
    {
      "x": -6,
      "y": 42,
      "z": 7,
      "name": "Rock_Shale"
    },
    {
      "x": -6,
      "y": 43,
      "z": 7,
      "name": "Rock_Shale"
    },
    {
      "x": -6,
      "y": 0,
      "z": 8,
      "name": "Rock_Shale"
    },
    {
      "x": -6,
      "y": 1,
      "z": 8,
      "name": "Rock_Shale"
    },
    {
      "x": -6,
      "y": 2,
      "z": 8,
      "name": "Rock_Shale"
    },
    {
      "x": -6,
      "y": 36,
      "z": 8,
      "name": "Rock_Shale"
    },
    {
      "x": -6,
      "y": 37,
      "z": 8,
      "name": "Rock_Shale"
    },
    {
      "x": -6,
      "y": 38,
      "z": 8,
      "name": "Rock_Shale"
    },
    {
      "x": -6,
      "y": 39,
      "z": 8,
      "name": "Rock_Shale"
    },
    {
      "x": -6,
      "y": 40,
      "z": 8,
      "name": "Rock_Shale"
    },
    {
      "x": -6,
      "y": 41,
      "z": 8,
      "name": "Rock_Shale"
    },
    {
      "x": -6,
      "y": 42,
      "z": 8,
      "name": "Rock_Shale"
    },
    {
      "x": -6,
      "y": 43,
      "z": 8,
      "name": "Rock_Shale"
    },
    {
      "x": -6,
      "y": 0,
      "z": 9,
      "name": "Rock_Shale"
    },
    {
      "x": -6,
      "y": 1,
      "z": 9,
      "name": "Rock_Shale"
    },
    {
      "x": -6,
      "y": 2,
      "z": 9,
      "name": "Rock_Shale"
    },
    {
      "x": -6,
      "y": 0,
      "z": 10,
      "name": "Rock_Shale"
    },
    {
      "x": -6,
      "y": 1,
      "z": 10,
      "name": "Rock_Shale"
    },
    {
      "x": -6,
      "y": 2,
      "z": 10,
      "name": "Rock_Shale"
    },
    {
      "x": -6,
      "y": 0,
      "z": 11,
      "name": "Rock_Shale"
    },
    {
      "x": -6,
      "y": 1,
      "z": 11,
      "name": "Rock_Shale"
    },
    {
      "x": -6,
      "y": 0,
      "z": 12,
      "name": "Rock_Shale"
    },
    {
      "x": -6,
      "y": 0,
      "z": 13,
      "name": "Rock_Shale"
    },
    {
      "x": -5,
      "y": 41,
      "z": -10,
      "name": "Rock_Shale"
    },
    {
      "x": -5,
      "y": 42,
      "z": -10,
      "name": "Rock_Shale"
    },
    {
      "x": -5,
      "y": 43,
      "z": -10,
      "name": "Rock_Shale"
    },
    {
      "x": -5,
      "y": 38,
      "z": -9,
      "name": "Rock_Shale"
    },
    {
      "x": -5,
      "y": 39,
      "z": -9,
      "name": "Rock_Shale"
    },
    {
      "x": -5,
      "y": 40,
      "z": -9,
      "name": "Rock_Shale"
    },
    {
      "x": -5,
      "y": 41,
      "z": -9,
      "name": "Rock_Shale"
    },
    {
      "x": -5,
      "y": 42,
      "z": -9,
      "name": "Rock_Shale"
    },
    {
      "x": -5,
      "y": 43,
      "z": -9,
      "name": "Rock_Shale"
    },
    {
      "x": -5,
      "y": 44,
      "z": -9,
      "name": "Rock_Shale"
    },
    {
      "x": -5,
      "y": 36,
      "z": -8,
      "name": "Rock_Shale"
    },
    {
      "x": -5,
      "y": 37,
      "z": -8,
      "name": "Rock_Shale"
    },
    {
      "x": -5,
      "y": 38,
      "z": -8,
      "name": "Rock_Shale"
    },
    {
      "x": -5,
      "y": 39,
      "z": -8,
      "name": "Rock_Shale"
    },
    {
      "x": -5,
      "y": 40,
      "z": -8,
      "name": "Rock_Shale"
    },
    {
      "x": -5,
      "y": 41,
      "z": -8,
      "name": "Rock_Shale"
    },
    {
      "x": -5,
      "y": 42,
      "z": -8,
      "name": "Rock_Shale"
    },
    {
      "x": -5,
      "y": 43,
      "z": -8,
      "name": "Rock_Shale"
    },
    {
      "x": -5,
      "y": 44,
      "z": -8,
      "name": "Rock_Shale"
    },
    {
      "x": -5,
      "y": 45,
      "z": -8,
      "name": "Rock_Shale"
    },
    {
      "x": -5,
      "y": 35,
      "z": -7,
      "name": "Rock_Shale"
    },
    {
      "x": -5,
      "y": 36,
      "z": -7,
      "name": "Rock_Shale"
    },
    {
      "x": -5,
      "y": 37,
      "z": -7,
      "name": "Rock_Shale"
    },
    {
      "x": -5,
      "y": 38,
      "z": -7,
      "name": "Rock_Shale"
    },
    {
      "x": -5,
      "y": 39,
      "z": -7,
      "name": "Rock_Shale"
    },
    {
      "x": -5,
      "y": 40,
      "z": -7,
      "name": "Rock_Shale"
    },
    {
      "x": -5,
      "y": 41,
      "z": -7,
      "name": "Rock_Shale"
    },
    {
      "x": -5,
      "y": 42,
      "z": -7,
      "name": "Rock_Shale"
    },
    {
      "x": -5,
      "y": 43,
      "z": -7,
      "name": "Rock_Shale"
    },
    {
      "x": -5,
      "y": 44,
      "z": -7,
      "name": "Rock_Shale"
    },
    {
      "x": -5,
      "y": 45,
      "z": -7,
      "name": "Rock_Shale"
    },
    {
      "x": -5,
      "y": 34,
      "z": -6,
      "name": "Rock_Shale"
    },
    {
      "x": -5,
      "y": 35,
      "z": -6,
      "name": "Rock_Shale"
    },
    {
      "x": -5,
      "y": 36,
      "z": -6,
      "name": "Rock_Shale"
    },
    {
      "x": -5,
      "y": 37,
      "z": -6,
      "name": "Rock_Shale"
    },
    {
      "x": -5,
      "y": 38,
      "z": -6,
      "name": "Rock_Shale"
    },
    {
      "x": -5,
      "y": 39,
      "z": -6,
      "name": "Rock_Shale"
    },
    {
      "x": -5,
      "y": 40,
      "z": -6,
      "name": "Rock_Shale"
    },
    {
      "x": -5,
      "y": 41,
      "z": -6,
      "name": "Rock_Shale"
    },
    {
      "x": -5,
      "y": 42,
      "z": -6,
      "name": "Rock_Shale"
    },
    {
      "x": -5,
      "y": 43,
      "z": -6,
      "name": "Rock_Shale"
    },
    {
      "x": -5,
      "y": 44,
      "z": -6,
      "name": "Rock_Shale"
    },
    {
      "x": -5,
      "y": 45,
      "z": -6,
      "name": "Rock_Shale"
    },
    {
      "x": -5,
      "y": 0,
      "z": -5,
      "name": "Rock_Shale"
    },
    {
      "x": -5,
      "y": 34,
      "z": -5,
      "name": "Rock_Shale"
    },
    {
      "x": -5,
      "y": 35,
      "z": -5,
      "name": "Rock_Shale"
    },
    {
      "x": -5,
      "y": 36,
      "z": -5,
      "name": "Rock_Shale"
    },
    {
      "x": -5,
      "y": 37,
      "z": -5,
      "name": "Rock_Shale"
    },
    {
      "x": -5,
      "y": 38,
      "z": -5,
      "name": "Rock_Shale"
    },
    {
      "x": -5,
      "y": 39,
      "z": -5,
      "name": "Rock_Shale"
    },
    {
      "x": -5,
      "y": 40,
      "z": -5,
      "name": "Rock_Shale"
    },
    {
      "x": -5,
      "y": 41,
      "z": -5,
      "name": "Rock_Shale"
    },
    {
      "x": -5,
      "y": 42,
      "z": -5,
      "name": "Rock_Shale"
    },
    {
      "x": -5,
      "y": 43,
