{
  "version": 8,
  "blockIdVersion": 11,
  "anchorX": 0,
  "anchorY": 0,
  "anchorZ": 0,
  "blocks": [
    {
      "x": -15,
      "y": -13,
      "z": -2,
      "name": "Rock_Shale"
    },
    {
      "x": -15,
      "y": -12,
      "z": -2,
      "name": "Rock_Shale"
    },
    {
      "x": -15,
      "y": -11,
      "z": -2,
      "name": "Rock_Shale"
    },
    {
      "x": -15,
      "y": -10,
      "z": -2,
      "name": "Rock_Shale"
    },
    {
      "x": -15,
      "y": -9,
      "z": -2,
      "name": "Rock_Shale"
    },
    {
      "x": -15,
      "y": -8,
      "z": -2,
      "name": "Rock_Shale"
    },
    {
      "x": -15,
      "y": -7,
      "z": -2,
      "name": "Rock_Shale"
    },
    {
      "x": -15,
      "y": -6,
      "z": -2,
      "name": "Rock_Shale"
    },
    {
      "x": -15,
      "y": -5,
      "z": -2,
      "name": "Rock_Shale"
    },
    {
      "x": -15,
      "y": -13,
      "z": -1,
      "name": "Rock_Shale"
    },
    {
      "x": -15,
      "y": -12,
      "z": -1,
      "name": "Rock_Shale"
    },
    {
      "x": -15,
      "y": -11,
      "z": -1,
      "name": "Rock_Shale"
    },
    {
      "x": -15,
      "y": -10,
      "z": -1,
      "name": "Rock_Shale"
    },
    {
      "x": -15,
      "y": -9,
      "z": -1,
      "name": "Rock_Shale"
    },
    {
      "x": -15,
      "y": -8,
      "z": -1,
      "name": "Rock_Shale"
    },
    {
      "x": -15,
      "y": -7,
      "z": -1,
      "name": "Rock_Shale"
    },
    {
      "x": -15,
      "y": -6,
      "z": -1,
      "name": "Rock_Shale"
    },
    {
      "x": -15,
      "y": -5,
      "z": -1,
      "name": "Rock_Shale"
    },
    {
      "x": -15,
      "y": -4,
      "z": -1,
      "name": "Rock_Shale"
    },
    {
      "x": -15,
      "y": -3,
      "z": -1,
      "name": "Rock_Shale"
    },
    {
      "x": -15,
      "y": -2,
      "z": -1,
      "name": "Rock_Shale"
    },
    {
      "x": -15,
      "y": -1,
      "z": -1,
      "name": "Rock_Shale"
    },
    {
      "x": -15,
      "y": 0,
      "z": -1,
      "name": "Plant_Mushroom_Block_White_Mycelium",
      "support": 15
    },
    {
      "x": -15,
      "y": 1,
      "z": -1,
      "name": "Plant_Roots_Rug_Tainted",
      "support": 15
    },
    {
      "x": -15,
      "y": -11,
      "z": 0,
      "name": "Rock_Shale"
    },
    {
      "x": -15,
      "y": -10,
      "z": 0,
      "name": "Rock_Shale"
    },
    {
      "x": -15,
      "y": -9,
      "z": 0,
      "name": "Rock_Shale"
    },
    {
      "x": -15,
      "y": -8,
      "z": 0,
      "name": "Rock_Shale"
    },
    {
      "x": -15,
      "y": -7,
      "z": 0,
      "name": "Rock_Shale"
    },
    {
      "x": -15,
      "y": -6,
      "z": 0,
      "name": "Rock_Shale"
    },
    {
      "x": -15,
      "y": -5,
      "z": 0,
      "name": "Rock_Shale"
    },
    {
      "x": -15,
      "y": -4,
      "z": 0,
      "name": "Rock_Shale"
    },
    {
      "x": -15,
      "y": -3,
      "z": 0,
      "name": "Rock_Shale"
    },
    {
      "x": -15,
      "y": -2,
      "z": 0,
      "name": "Rock_Shale"
    },
    {
      "x": -15,
      "y": -1,
      "z": 0,
      "name": "Rock_Shale"
    },
    {
      "x": -15,
      "y": 0,
      "z": 0,
      "name": "Plant_Mushroom_Block_White_Mycelium",
      "support": 15
    },
    {
      "x": -15,
      "y": 1,
      "z": 0,
      "name": "Plant_Mushroom_Rug_White_Mycelium",
      "support": 15
    },
    {
      "x": -15,
      "y": -10,
      "z": 1,
      "name": "Rock_Shale"
    },
    {
      "x": -15,
      "y": -9,
      "z": 1,
      "name": "Rock_Shale"
    },
    {
      "x": -15,
      "y": -8,
      "z": 1,
      "name": "Rock_Shale"
    },
    {
      "x": -15,
      "y": -7,
      "z": 1,
      "name": "Rock_Shale"
    },
    {
      "x": -15,
      "y": -6,
      "z": 1,
      "name": "Rock_Shale"
    },
    {
      "x": -14,
      "y": -10,
      "z": -3,
      "name": "Rock_Shale"
    },
    {
      "x": -14,
      "y": -9,
      "z": -3,
      "name": "Rock_Shale"
    },
    {
      "x": -14,
      "y": -8,
      "z": -3,
      "name": "Rock_Shale"
    },
    {
      "x": -14,
      "y": -7,
      "z": -3,
      "name": "Rock_Shale"
    },
    {
      "x": -14,
      "y": -6,
      "z": -3,
      "name": "Rock_Shale"
    },
    {
      "x": -14,
      "y": -5,
      "z": -3,
      "name": "Rock_Shale"
    },
    {
      "x": -14,
      "y": -13,
      "z": -2,
      "name": "Rock_Shale"
    },
    {
      "x": -14,
      "y": -12,
      "z": -2,
      "name": "Rock_Shale"
    },
    {
      "x": -14,
      "y": -11,
      "z": -2,
      "name": "Rock_Shale"
    },
    {
      "x": -14,
      "y": -10,
      "z": -2,
      "name": "Rock_Shale"
    },
    {
      "x": -14,
      "y": -9,
      "z": -2,
      "name": "Rock_Shale"
    },
    {
      "x": -14,
      "y": -8,
      "z": -2,
      "name": "Rock_Shale"
    },
    {
      "x": -14,
      "y": -7,
      "z": -2,
      "name": "Rock_Shale"
    },
    {
      "x": -14,
      "y": -6,
      "z": -2,
      "name": "Rock_Shale"
    },
    {
      "x": -14,
      "y": -5,
      "z": -2,
      "name": "Rock_Shale"
    },
    {
      "x": -14,
      "y": -4,
      "z": -2,
      "name": "Rock_Shale"
    },
    {
      "x": -14,
      "y": -3,
      "z": -2,
      "name": "Rock_Shale"
    },
    {
      "x": -14,
      "y": -2,
      "z": -2,
      "name": "Rock_Shale"
    },
    {
      "x": -14,
      "y": -1,
      "z": -2,
      "name": "Rock_Shale"
    },
    {
      "x": -14,
      "y": 0,
      "z": -2,
      "name": "Rock_Shale"
    },
    {
      "x": -14,
      "y": 1,
      "z": -2,
      "name": "Plant_Mushroom_Short_White_Mycelium",
      "support": 15
    },
    {
      "x": -14,
      "y": -13,
      "z": -1,
      "name": "Rock_Shale"
    },
    {
      "x": -14,
      "y": -12,
      "z": -1,
      "name": "Rock_Shale"
    },
    {
      "x": -14,
      "y": -11,
      "z": -1,
      "name": "Rock_Shale"
    },
    {
      "x": -14,
      "y": -10,
      "z": -1,
      "name": "Rock_Shale"
    },
    {
      "x": -14,
      "y": -9,
      "z": -1,
      "name": "Rock_Shale"
    },
    {
      "x": -14,
      "y": -8,
      "z": -1,
      "name": "Rock_Shale"
    },
    {
      "x": -14,
      "y": -7,
      "z": -1,
      "name": "Rock_Shale"
    },
    {
      "x": -14,
      "y": -6,
      "z": -1,
      "name": "Rock_Shale"
    },
    {
      "x": -14,
      "y": -5,
      "z": -1,
      "name": "Rock_Shale"
    },
    {
      "x": -14,
      "y": -4,
      "z": -1,
      "name": "Rock_Shale"
    },
    {
      "x": -14,
      "y": -3,
      "z": -1,
      "name": "Rock_Shale"
    },
    {
      "x": -14,
      "y": -2,
      "z": -1,
      "name": "Rock_Shale"
    },
    {
      "x": -14,
      "y": -1,
      "z": -1,
      "name": "Rock_Shale"
    },
    {
      "x": -14,
      "y": 0,
      "z": -1,
      "name": "Rock_Shale"
    },
    {
      "x": -14,
      "y": 1,
      "z": -1,
      "name": "Rock_Shale"
    },
    {
      "x": -14,
      "y": 2,
      "z": -1,
      "name": "Rock_Shale_Stalactites_Small"
    },
    {
      "x": -14,
      "y": -13,
      "z": 0,
      "name": "Rock_Shale"
    },
    {
      "x": -14,
      "y": -12,
      "z": 0,
      "name": "Rock_Shale"
    },
    {
      "x": -14,
      "y": -11,
      "z": 0,
      "name": "Rock_Shale"
    },
    {
      "x": -14,
      "y": -10,
      "z": 0,
      "name": "Rock_Shale"
    },
    {
      "x": -14,
      "y": -9,
      "z": 0,
      "name": "Rock_Shale"
    },
    {
      "x": -14,
      "y": -8,
      "z": 0,
      "name": "Rock_Shale"
    },
    {
      "x": -14,
      "y": -7,
      "z": 0,
      "name": "Rock_Shale"
    },
    {
      "x": -14,
      "y": -6,
      "z": 0,
      "name": "Rock_Shale"
    },
    {
      "x": -14,
      "y": -5,
      "z": 0,
      "name": "Rock_Shale"
    },
    {
      "x": -14,
      "y": -4,
      "z": 0,
      "name": "Rock_Shale"
    },
    {
      "x": -14,
      "y": -3,
      "z": 0,
      "name": "Rock_Shale"
    },
    {
      "x": -14,
      "y": -2,
      "z": 0,
      "name": "Rock_Shale"
    },
    {
      "x": -14,
      "y": -1,
      "z": 0,
      "name": "Rock_Shale"
    },
    {
      "x": -14,
      "y": 0,
      "z": 0,
      "name": "Plant_Mushroom_Block_White_Mycelium",
      "support": 15
    },
    {
      "x": -14,
      "y": 1,
      "z": 0,
      "name": "Plant_Mushroom_Rug_White_Mycelium",
      "support": 15
    },
    {
      "x": -14,
      "y": -11,
      "z": 1,
      "name": "Rock_Shale"
    },
    {
      "x": -14,
      "y": -10,
      "z": 1,
      "name": "Rock_Shale"
    },
    {
      "x": -14,
      "y": -9,
      "z": 1,
      "name": "Rock_Shale"
    },
    {
      "x": -14,
      "y": -8,
      "z": 1,
      "name": "Rock_Shale"
    },
    {
      "x": -14,
      "y": -7,
      "z": 1,
      "name": "Rock_Shale"
    },
    {
      "x": -14,
      "y": -6,
      "z": 1,
      "name": "Rock_Shale"
    },
    {
      "x": -14,
      "y": -5,
      "z": 1,
      "name": "Rock_Shale"
    },
    {
      "x": -14,
      "y": -4,
      "z": 1,
      "name": "Rock_Shale"
    },
    {
      "x": -14,
      "y": -3,
      "z": 1,
      "name": "Rock_Shale"
    },
    {
      "x": -14,
      "y": -2,
      "z": 1,
      "name": "Rock_Shale"
    },
    {
      "x": -14,
      "y": -1,
      "z": 1,
      "name": "Rock_Shale"
    },
    {
      "x": -14,
      "y": 0,
      "z": 1,
      "name": "Plant_Mushroom_Block_White_Mycelium",
      "support": 15
    },
    {
      "x": -14,
      "y": 1,
      "z": 1,
      "name": "Plant_Mushroom_Rug_White_Mycelium",
      "support": 15
    },
    {
      "x": -14,
      "y": -9,
      "z": 2,
      "name": "Rock_Shale"
    },
    {
      "x": -14,
      "y": -8,
      "z": 2,
      "name": "Rock_Shale"
    },
    {
      "x": -14,
      "y": -7,
      "z": 2,
      "name": "Rock_Shale"
    },
    {
      "x": -14,
      "y": -6,
      "z": 2,
      "name": "Rock_Shale"
    },
    {
      "x": -14,
      "y": -5,
      "z": 2,
      "name": "Rock_Shale"
    },
    {
      "x": -13,
      "y": -10,
      "z": -4,
      "name": "Rock_Shale"
    },
    {
      "x": -13,
      "y": -9,
      "z": -4,
      "name": "Rock_Shale"
    },
    {
      "x": -13,
      "y": -8,
      "z": -4,
      "name": "Rock_Shale"
    },
    {
      "x": -13,
      "y": -7,
      "z": -4,
      "name": "Rock_Shale"
    },
    {
      "x": -13,
      "y": -6,
      "z": -4,
      "name": "Rock_Shale"
    },
    {
      "x": -13,
      "y": -2,
      "z": -4,
      "name": "Rock_Shale"
    },
    {
      "x": -13,
      "y": -1,
      "z": -4,
      "name": "Rock_Shale"
    },
    {
      "x": -13,
      "y": 0,
      "z": -4,
      "name": "Rock_Shale"
    },
    {
      "x": -13,
      "y": -12,
      "z": -3,
      "name": "Rock_Shale"
    },
    {
      "x": -13,
      "y": -11,
      "z": -3,
      "name": "Rock_Shale"
    },
    {
      "x": -13,
      "y": -10,
      "z": -3,
      "name": "Rock_Shale"
    },
    {
      "x": -13,
      "y": -9,
      "z": -3,
      "name": "Rock_Shale"
    },
    {
      "x": -13,
      "y": -8,
      "z": -3,
      "name": "Rock_Shale"
    },
    {
      "x": -13,
      "y": -7,
      "z": -3,
      "name": "Rock_Shale"
    },
    {
      "x": -13,
      "y": -6,
      "z": -3,
      "name": "Rock_Shale"
    },
    {
      "x": -13,
      "y": -5,
      "z": -3,
      "name": "Rock_Shale"
    },
    {
      "x": -13,
      "y": -4,
      "z": -3,
      "name": "Rock_Shale"
    },
    {
      "x": -13,
      "y": -3,
      "z": -3,
      "name": "Rock_Shale"
    },
    {
      "x": -13,
      "y": -2,
      "z": -3,
      "name": "Rock_Shale"
    },
    {
      "x": -13,
      "y": -1,
      "z": -3,
      "name": "Rock_Shale"
    },
    {
      "x": -13,
      "y": 0,
      "z": -3,
      "name": "Rock_Shale"
    },
    {
      "x": -13,
      "y": -14,
      "z": -2,
      "name": "Rock_Shale"
    },
    {
      "x": -13,
      "y": -13,
      "z": -2,
      "name": "Rock_Shale"
    },
    {
      "x": -13,
      "y": -12,
      "z": -2,
      "name": "Rock_Shale"
    },
    {
      "x": -13,
      "y": -11,
      "z": -2,
      "name": "Rock_Shale"
    },
    {
      "x": -13,
      "y": -10,
      "z": -2,
      "name": "Rock_Shale"
    },
    {
      "x": -13,
      "y": -9,
      "z": -2,
      "name": "Rock_Shale"
    },
    {
      "x": -13,
      "y": -8,
      "z": -2,
      "name": "Rock_Shale"
    },
    {
      "x": -13,
      "y": -7,
      "z": -2,
      "name": "Rock_Shale"
    },
    {
      "x": -13,
      "y": -6,
      "z": -2,
      "name": "Rock_Shale"
    },
    {
      "x": -13,
      "y": -5,
      "z": -2,
      "name": "Rock_Shale"
    },
    {
      "x": -13,
      "y": -4,
      "z": -2,
      "name": "Rock_Shale"
    },
    {
      "x": -13,
      "y": -3,
      "z": -2,
      "name": "Rock_Shale"
    },
    {
      "x": -13,
      "y": -2,
      "z": -2,
      "name": "Rock_Shale"
    },
    {
      "x": -13,
      "y": -1,
      "z": -2,
      "name": "Rock_Shale"
    },
    {
      "x": -13,
      "y": 0,
      "z": -2,
      "name": "Rock_Shale"
    },
    {
      "x": -13,
      "y": 1,
      "z": -2,
      "name": "Rock_Shale"
    },
    {
      "x": -13,
      "y": -14,
      "z": -1,
      "name": "Rock_Shale"
    },
    {
      "x": -13,
      "y": -13,
      "z": -1,
      "name": "Rock_Shale"
    },
    {
      "x": -13,
      "y": -12,
      "z": -1,
      "name": "Rock_Shale"
    },
    {
      "x": -13,
      "y": -11,
      "z": -1,
      "name": "Rock_Shale"
    },
    {
      "x": -13,
      "y": -10,
      "z": -1,
      "name": "Rock_Shale"
    },
    {
      "x": -13,
      "y": -9,
      "z": -1,
      "name": "Rock_Shale"
    },
    {
      "x": -13,
      "y": -8,
      "z": -1,
      "name": "Rock_Shale"
    },
    {
      "x": -13,
      "y": -7,
      "z": -1,
      "name": "Rock_Shale"
    },
    {
      "x": -13,
      "y": -6,
      "z": -1,
      "name": "Rock_Shale"
    },
    {
      "x": -13,
      "y": -5,
      "z": -1,
      "name": "Rock_Shale"
    },
    {
      "x": -13,
      "y": -4,
      "z": -1,
      "name": "Rock_Shale"
    },
    {
      "x": -13,
      "y": -3,
      "z": -1,
      "name": "Rock_Shale"
    },
    {
      "x": -13,
      "y": -2,
      "z": -1,
      "name": "Rock_Shale"
    },
    {
      "x": -13,
      "y": -1,
      "z": -1,
      "name": "Rock_Shale"
    },
    {
      "x": -13,
      "y": 0,
      "z": -1,
      "name": "Rock_Shale"
    },
    {
      "x": -13,
      "y": 1,
      "z": -1,
      "name": "Rock_Shale"
    },
    {
      "x": -13,
      "y": 2,
      "z": -1,
      "name": "Plant_Mushroom_Short_White_Mycelium",
      "support": 15
    },
    {
      "x": -13,
      "y": -14,
      "z": 0,
      "name": "Rock_Shale"
    },
    {
      "x": -13,
      "y": -13,
      "z": 0,
      "name": "Rock_Shale"
    },
    {
      "x": -13,
      "y": -12,
      "z": 0,
      "name": "Rock_Shale"
    },
    {
      "x": -13,
      "y": -11,
      "z": 0,
      "name": "Rock_Shale"
    },
    {
      "x": -13,
      "y": -10,
      "z": 0,
      "name": "Rock_Shale"
    },
    {
      "x": -13,
      "y": -9,
      "z": 0,
      "name": "Rock_Shale"
    },
    {
      "x": -13,
      "y": -8,
      "z": 0,
      "name": "Rock_Shale"
    },
    {
      "x": -13,
      "y": -7,
      "z": 0,
      "name": "Rock_Shale"
    },
    {
      "x": -13,
      "y": -6,
      "z": 0,
      "name": "Rock_Shale"
    },
    {
      "x": -13,
      "y": -5,
      "z": 0,
      "name": "Rock_Shale"
    },
    {
      "x": -13,
      "y": -4,
      "z": 0,
      "name": "Rock_Shale"
    },
    {
      "x": -13,
      "y": -3,
      "z": 0,
      "name": "Rock_Shale"
    },
    {
      "x": -13,
      "y": -2,
      "z": 0,
      "name": "Rock_Shale"
    },
    {
      "x": -13,
      "y": -1,
      "z": 0,
      "name": "Rock_Shale"
    },
    {
      "x": -13,
      "y": 0,
      "z": 0,
      "name": "Rock_Shale"
    },
    {
      "x": -13,
      "y": 1,
      "z": 0,
      "name": "Plant_Mushroom_Block_White_Mycelium",
      "support": 15
    },
    {
      "x": -13,
      "y": 2,
      "z": 0,
      "name": "Plant_Mushroom_Rug_White_Mycelium",
      "support": 15
    },
    {
      "x": -13,
      "y": -15,
      "z": 1,
      "name": "Rock_Shale"
    },
    {
      "x": -13,
      "y": -14,
      "z": 1,
      "name": "Rock_Shale"
    },
    {
      "x": -13,
      "y": -13,
      "z": 1,
      "name": "Rock_Shale"
    },
    {
      "x": -13,
      "y": -12,
      "z": 1,
      "name": "Rock_Shale"
    },
    {
      "x": -13,
      "y": -11,
      "z": 1,
      "name": "Rock_Shale"
    },
    {
      "x": -13,
      "y": -10,
      "z": 1,
      "name": "Rock_Shale"
    },
    {
      "x": -13,
      "y": -9,
      "z": 1,
      "name": "Rock_Shale"
    },
    {
      "x": -13,
      "y": -8,
      "z": 1,
      "name": "Rock_Shale"
    },
    {
      "x": -13,
      "y": -7,
      "z": 1,
      "name": "Rock_Shale"
    },
    {
      "x": -13,
      "y": -6,
      "z": 1,
      "name": "Rock_Shale"
    },
    {
      "x": -13,
      "y": -5,
      "z": 1,
      "name": "Rock_Shale"
    },
    {
      "x": -13,
      "y": -4,
      "z": 1,
      "name": "Rock_Shale"
    },
    {
      "x": -13,
      "y": -3,
      "z": 1,
      "name": "Rock_Shale"
    },
    {
      "x": -13,
      "y": -2,
      "z": 1,
      "name": "Rock_Shale"
    },
    {
      "x": -13,
      "y": -1,
      "z": 1,
      "name": "Rock_Shale"
    },
    {
      "x": -13,
      "y": 0,
      "z": 1,
      "name": "Rock_Shale"
    },
    {
      "x": -13,
      "y": 1,
      "z": 1,
      "name": "Plant_Mushroom_Block_White_Mycelium",
      "support": 15
    },
    {
      "x": -13,
      "y": 2,
      "z": 1,
      "name": "Plant_Mushroom_Rug_White_Mycelium",
      "support": 15
    },
    {
      "x": -13,
      "y": -14,
      "z": 2,
      "name": "Rock_Shale"
    },
    {
      "x": -13,
      "y": -13,
      "z": 2,
      "name": "Rock_Shale"
    },
    {
      "x": -13,
      "y": -12,
      "z": 2,
      "name": "Rock_Shale"
    },
    {
      "x": -13,
      "y": -11,
      "z": 2,
      "name": "Rock_Shale"
    },
    {
      "x": -13,
      "y": -10,
      "z": 2,
      "name": "Rock_Shale"
    },
    {
      "x": -13,
      "y": -9,
      "z": 2,
      "name": "Rock_Shale"
    },
    {
      "x": -13,
      "y": -8,
      "z": 2,
      "name": "Rock_Shale"
    },
    {
      "x": -13,
      "y": -7,
      "z": 2,
      "name": "Rock_Shale"
    },
    {
      "x": -13,
      "y": -6,
      "z": 2,
      "name": "Rock_Shale"
    },
    {
      "x": -13,
      "y": -5,
      "z": 2,
      "name": "Rock_Shale"
    },
    {
      "x": -13,
      "y": -4,
      "z": 2,
      "name": "Rock_Shale"
    },
    {
      "x": -13,
      "y": -3,
      "z": 2,
      "name": "Rock_Shale"
    },
    {
      "x": -13,
      "y": -2,
      "z": 2,
      "name": "Rock_Shale"
    },
    {
      "x": -13,
      "y": -1,
      "z": 2,
      "name": "Rock_Shale"
    },
    {
      "x": -13,
      "y": 0,
      "z": 2,
      "name": "Rock_Shale"
    },
    {
      "x": -13,
      "y": 1,
      "z": 2,
      "name": "Plant_Mushroom_Rug_White_Mycelium",
      "support": 15
    },
    {
      "x": -13,
      "y": -13,
      "z": 3,
      "name": "Rock_Shale"
    },
    {
      "x": -13,
      "y": -12,
      "z": 3,
      "name": "Rock_Shale"
    },
    {
      "x": -13,
      "y": -11,
      "z": 3,
      "name": "Rock_Shale"
    },
    {
      "x": -13,
      "y": -10,
      "z": 3,
      "name": "Rock_Shale"
    },
    {
      "x": -13,
      "y": -9,
      "z": 3,
      "name": "Rock_Shale"
    },
    {
      "x": -13,
      "y": -8,
      "z": 3,
      "name": "Rock_Shale"
    },
    {
      "x": -13,
      "y": -7,
      "z": 3,
      "name": "Rock_Shale"
    },
    {
      "x": -13,
      "y": -6,
      "z": 3,
      "name": "Rock_Shale"
    },
    {
      "x": -13,
      "y": -5,
      "z": 3,
      "name": "Rock_Shale"
    },
    {
      "x": -13,
      "y": -4,
      "z": 3,
      "name": "Rock_Shale"
    },
    {
      "x": -13,
      "y": -3,
      "z": 3,
      "name": "Rock_Shale"
    },
    {
      "x": -13,
      "y": -2,
      "z": 3,
      "name": "Rock_Shale"
    },
    {
      "x": -13,
      "y": -1,
      "z": 3,
      "name": "Rock_Shale"
    },
    {
      "x": -13,
      "y": 0,
      "z": 3,
      "name": "Rock_Shale"
    },
    {
      "x": -13,
      "y": 1,
      "z": 3,
      "name": "Plant_Mushroom_Short_White_Mycelium",
      "support": 15
    },
    {
      "x": -13,
      "y": -12,
      "z": 4,
      "name": "Rock_Shale"
    },
    {
      "x": -13,
      "y": -11,
      "z": 4,
      "name": "Rock_Shale"
    },
    {
      "x": -13,
      "y": -10,
      "z": 4,
      "name": "Rock_Shale"
    },
    {
      "x": -13,
      "y": -9,
      "z": 4,
      "name": "Rock_Shale"
    },
    {
      "x": -13,
      "y": -8,
      "z": 4,
      "name": "Rock_Shale"
    },
    {
      "x": -13,
      "y": -7,
      "z": 4,
      "name": "Rock_Shale"
    },
    {
      "x": -13,
      "y": -6,
      "z": 4,
      "name": "Rock_Shale"
    },
    {
      "x": -13,
      "y": -5,
      "z": 4,
      "name": "Rock_Shale"
    },
    {
      "x": -13,
      "y": -4,
      "z": 4,
      "name": "Rock_Shale"
    },
    {
      "x": -13,
      "y": -3,
      "z": 4,
      "name": "Rock_Shale"
    },
    {
      "x": -13,
      "y": -2,
      "z": 4,
      "name": "Rock_Shale"
    },
    {
      "x": -13,
      "y": -1,
      "z": 4,
      "name": "Rock_Shale"
    },
    {
      "x": -13,
      "y": 0,
      "z": 4,
      "name": "Rock_Shale"
    },
    {
      "x": -13,
      "y": -11,
      "z": 5,
      "name": "Rock_Shale"
    },
    {
      "x": -13,
      "y": -10,
      "z": 5,
      "name": "Rock_Shale"
    },
    {
      "x": -13,
      "y": -9,
      "z": 5,
      "name": "Rock_Shale"
    },
    {
      "x": -13,
      "y": -8,
      "z": 5,
      "name": "Rock_Shale"
    },
    {
      "x": -13,
      "y": -7,
      "z": 5,
      "name": "Rock_Shale"
    },
    {
      "x": -13,
      "y": -6,
      "z": 5,
      "name": "Rock_Shale"
    },
    {
      "x": -13,
      "y": -5,
      "z": 5,
      "name": "Rock_Shale"
    },
    {
      "x": -13,
      "y": -4,
      "z": 5,
      "name": "Rock_Shale"
    },
    {
      "x": -13,
      "y": -3,
      "z": 5,
      "name": "Rock_Shale"
    },
    {
      "x": -13,
      "y": -2,
      "z": 5,
      "name": "Rock_Shale"
    },
    {
      "x": -13,
      "y": -1,
      "z": 5,
      "name": "Rock_Shale"
    },
    {
      "x": -13,
      "y": 0,
      "z": 5,
      "name": "Rock_Shale"
    },
    {
      "x": -13,
      "y": -13,
      "z": 7,
      "name": "Rock_Shale"
    },
    {
      "x": -13,
      "y": -12,
      "z": 7,
      "name": "Rock_Shale"
    },
    {
      "x": -13,
      "y": -11,
      "z": 7,
      "name": "Rock_Shale"
    },
    {
      "x": -13,
      "y": -10,
      "z": 7,
      "name": "Rock_Shale"
    },
    {
      "x": -13,
      "y": -9,
      "z": 7,
      "name": "Rock_Shale"
    },
    {
      "x": -13,
      "y": -14,
      "z": 8,
      "name": "Rock_Shale"
    },
    {
      "x": -13,
      "y": -13,
      "z": 8,
      "name": "Rock_Shale"
    },
    {
      "x": -13,
      "y": -12,
      "z": 8,
      "name": "Rock_Shale"
    },
    {
      "x": -13,
      "y": -11,
      "z": 8,
      "name": "Rock_Shale"
    },
    {
      "x": -13,
      "y": -10,
      "z": 8,
      "name": "Rock_Shale"
    },
    {
      "x": -13,
      "y": -9,
      "z": 8,
      "name": "Rock_Shale"
    },
    {
      "x": -13,
      "y": -8,
      "z": 8,
      "name": "Rock_Shale"
    },
    {
      "x": -13,
      "y": -11,
      "z": 9,
      "name": "Rock_Shale"
    },
    {
      "x": -13,
      "y": -10,
      "z": 9,
      "name": "Rock_Shale"
    },
    {
      "x": -13,
      "y": -9,
      "z": 9,
      "name": "Rock_Shale"
    },
    {
      "x": -12,
      "y": -10,
      "z": -5,
      "name": "Rock_Shale"
    },
    {
      "x": -12,
      "y": -9,
      "z": -5,
      "name": "Rock_Shale"
    },
    {
      "x": -12,
      "y": -8,
      "z": -5,
      "name": "Rock_Shale"
    },
    {
      "x": -12,
      "y": -7,
      "z": -5,
      "name": "Rock_Shale"
    },
    {
      "x": -12,
      "y": -6,
      "z": -5,
      "name": "Rock_Shale"
    },
    {
      "x": -12,
      "y": -1,
      "z": -5,
      "name": "Rock_Shale"
    },
    {
      "x": -12,
      "y": 0,
      "z": -5,
      "name": "Rock_Shale"
    },
    {
      "x": -12,
      "y": -12,
      "z": -4,
      "name": "Rock_Shale"
    },
    {
      "x": -12,
      "y": -11,
      "z": -4,
      "name": "Rock_Shale"
    },
    {
      "x": -12,
      "y": -10,
      "z": -4,
      "name": "Rock_Shale"
    },
    {
      "x": -12,
      "y": -9,
      "z": -4,
      "name": "Rock_Shale"
    },
    {
      "x": -12,
      "y": -8,
      "z": -4,
      "name": "Rock_Shale"
    },
    {
      "x": -12,
      "y": -7,
      "z": -4,
      "name": "Rock_Shale"
    },
    {
      "x": -12,
      "y": -6,
      "z": -4,
      "name": "Rock_Shale"
    },
    {
      "x": -12,
      "y": -5,
      "z": -4,
      "name": "Rock_Shale"
    },
    {
      "x": -12,
      "y": -4,
      "z": -4,
      "name": "Rock_Shale"
    },
    {
      "x": -12,
      "y": -3,
      "z": -4,
      "name": "Rock_Shale"
    },
    {
      "x": -12,
      "y": -2,
      "z": -4,
      "name": "Rock_Shale"
    },
    {
      "x": -12,
      "y": -1,
      "z": -4,
      "name": "Rock_Shale"
    },
    {
      "x": -12,
      "y": 0,
      "z": -4,
      "name": "Rock_Shale"
    },
    {
      "x": -12,
      "y": -13,
      "z": -3,
      "name": "Rock_Shale"
    },
    {
      "x": -12,
      "y": -12,
      "z": -3,
      "name": "Rock_Shale"
    },
    {
      "x": -12,
      "y": -11,
      "z": -3,
      "name": "Rock_Shale"
    },
    {
      "x": -12,
      "y": -10,
      "z": -3,
      "name": "Rock_Shale"
    },
    {
      "x": -12,
      "y": -9,
      "z": -3,
      "name": "Rock_Shale"
    },
    {
      "x": -12,
      "y": -8,
      "z": -3,
      "name": "Rock_Shale"
    },
    {
      "x": -12,
      "y": -7,
      "z": -3,
      "name": "Rock_Shale"
    },
    {
      "x": -12,
      "y": -6,
      "z": -3,
      "name": "Rock_Shale"
    },
    {
      "x": -12,
      "y": -5,
      "z": -3,
      "name": "Rock_Shale"
    },
    {
      "x": -12,
      "y": -4,
      "z": -3,
      "name": "Rock_Shale"
    },
    {
      "x": -12,
      "y": -3,
      "z": -3,
      "name": "Rock_Shale"
    },
    {
      "x": -12,
      "y": -2,
      "z": -3,
      "name": "Rock_Shale"
    },
    {
      "x": -12,
      "y": -1,
      "z": -3,
      "name": "Rock_Shale"
    },
    {
      "x": -12,
      "y": 0,
      "z": -3,
      "name": "Rock_Shale"
    },
    {
      "x": -12,
      "y": 1,
      "z": -3,
      "name": "Plant_Roots_Rug_Tainted",
      "support": 15
    },
    {
      "x": -12,
      "y": 43,
      "z": -3,
      "name": "Rock_Shale"
    },
    {
      "x": -12,
      "y": -15,
      "z": -2,
      "name": "Rock_Shale"
    },
    {
      "x": -12,
      "y": -14,
      "z": -2,
      "name": "Rock_Shale"
    },
    {
      "x": -12,
      "y": -13,
      "z": -2,
      "name": "Rock_Shale"
    },
    {
      "x": -12,
      "y": -12,
      "z": -2,
      "name": "Rock_Shale"
    },
    {
      "x": -12,
      "y": -11,
      "z": -2,
      "name": "Rock_Shale"
    },
    {
      "x": -12,
      "y": -10,
      "z": -2,
      "name": "Rock_Shale"
    },
    {
      "x": -12,
      "y": -9,
      "z": -2,
      "name": "Rock_Shale"
    },
    {
      "x": -12,
      "y": -8,
      "z": -2,
      "name": "Rock_Shale"
    },
    {
      "x": -12,
      "y": -7,
      "z": -2,
      "name": "Rock_Shale"
    },
    {
      "x": -12,
      "y": -6,
      "z": -2,
      "name": "Rock_Shale"
    },
    {
      "x": -12,
      "y": -5,
      "z": -2,
      "name": "Rock_Shale"
    },
    {
      "x": -12,
      "y": -4,
      "z": -2,
      "name": "Rock_Shale"
    },
    {
      "x": -12,
      "y": -3,
      "z": -2,
      "name": "Rock_Shale"
    },
    {
      "x": -12,
      "y": -2,
      "z": -2,
      "name": "Rock_Shale"
    },
    {
      "x": -12,
      "y": -1,
      "z": -2,
      "name": "Rock_Shale"
    },
    {
      "x": -12,
      "y": 0,
      "z": -2,
      "name": "Rock_Shale"
    },
    {
      "x": -12,
      "y": 1,
      "z": -2,
      "name": "Rock_Shale"
    },
    {
      "x": -12,
      "y": 2,
      "z": -2,
      "name": "Plant_Roots_Rug_Tainted",
      "support": 15
    },
    {
      "x": -12,
      "y": 42,
      "z": -2,
      "name": "Rock_Shale"
    },
    {
      "x": -12,
      "y": 43,
      "z": -2,
      "name": "Rock_Shale"
    },
    {
      "x": -12,
      "y": -15,
      "z": -1,
      "name": "Rock_Shale"
    },
    {
      "x": -12,
      "y": -14,
      "z": -1,
      "name": "Rock_Shale"
    },
    {
      "x": -12,
      "y": -13,
      "z": -1,
      "name": "Rock_Shale"
    },
    {
      "x": -12,
      "y": -12,
      "z": -1,
      "name": "Rock_Shale"
    },
    {
      "x": -12,
      "y": -11,
      "z": -1,
      "name": "Rock_Shale"
    },
    {
      "x": -12,
      "y": -10,
      "z": -1,
      "name": "Rock_Shale"
    },
    {
      "x": -12,
      "y": -9,
      "z": -1,
      "name": "Rock_Shale"
    },
    {
      "x": -12,
      "y": -8,
      "z": -1,
      "name": "Rock_Shale"
    },
    {
      "x": -12,
      "y": -7,
      "z": -1,
      "name": "Rock_Shale"
    },
    {
      "x": -12,
      "y": -6,
      "z": -1,
      "name": "Rock_Shale"
    },
    {
      "x": -12,
      "y": -5,
      "z": -1,
      "name": "Rock_Shale"
    },
    {
      "x": -12,
      "y": -4,
      "z": -1,
      "name": "Rock_Shale"
    },
    {
      "x": -12,
      "y": -3,
      "z": -1,
      "name": "Rock_Shale"
    },
    {
      "x": -12,
      "y": -2,
      "z": -1,
      "name": "Rock_Shale"
    },
    {
      "x": -12,
      "y": -1,
      "z": -1,
      "name": "Rock_Shale"
    },
    {
      "x": -12,
      "y": 0,
      "z": -1,
      "name": "Rock_Shale"
    },
    {
      "x": -12,
      "y": 1,
      "z": -1,
      "name": "Rock_Shale"
    },
    {
      "x": -12,
      "y": 41,
      "z": -1,
      "name": "Rock_Shale"
    },
    {
      "x": -12,
      "y": 42,
      "z": -1,
      "name": "Rock_Shale"
    },
    {
      "x": -12,
      "y": 43,
      "z": -1,
      "name": "Rock_Shale"
    },
    {
      "x": -12,
      "y": -15,
      "z": 0,
      "name": "Rock_Shale"
    },
    {
      "x": -12,
      "y": -14,
      "z": 0,
      "name": "Rock_Shale"
    },
    {
      "x": -12,
      "y": -13,
      "z": 0,
      "name": "Rock_Shale"
    },
    {
      "x": -12,
      "y": -12,
      "z": 0,
      "name": "Rock_Shale"
    },
    {
      "x": -12,
      "y": -11,
      "z": 0,
      "name": "Rock_Shale"
    },
    {
      "x": -12,
      "y": -10,
      "z": 0,
      "name": "Rock_Shale"
    },
    {
      "x": -12,
      "y": -9,
      "z": 0,
      "name": "Rock_Shale"
    },
    {
      "x": -12,
      "y": -8,
      "z": 0,
      "name": "Rock_Shale"
    },
    {
      "x": -12,
      "y": -7,
      "z": 0,
      "name": "Rock_Shale"
    },
    {
      "x": -12,
      "y": -6,
      "z": 0,
      "name": "Rock_Shale"
    },
    {
      "x": -12,
      "y": -5,
      "z": 0,
      "name": "Rock_Shale"
    },
    {
      "x": -12,
      "y": -4,
      "z": 0,
      "name": "Rock_Shale"
    },
    {
      "x": -12,
      "y": -3,
      "z": 0,
      "name": "Rock_Shale"
    },
    {
      "x": -12,
      "y": -2,
      "z": 0,
      "name": "Rock_Shale"
    },
    {
      "x": -12,
      "y": -1,
      "z": 0,
      "name": "Rock_Shale"
    },
    {
      "x": -12,
      "y": 0,
      "z": 0,
      "name": "Rock_Shale"
    },
    {
      "x": -12,
      "y": 1,
      "z": 0,
      "name": "Rock_Shale"
    },
    {
      "x": -12,
      "y": 2,
      "z": 0,
      "name": "Rock_Shale"
    },
    {
      "x": -12,
      "y": 3,
      "z": 0,
      "name": "Plant_Mushroom_Short_White_Mycelium",
      "support": 15
    },
    {
      "x": -12,
      "y": 41,
      "z": 0,
      "name": "Rock_Shale"
    },
    {
      "x": -12,
      "y": 42,
      "z": 0,
      "name": "Rock_Shale"
    },
    {
      "x": -12,
      "y": 43,
      "z": 0,
      "name": "Rock_Shale"
    },
    {
      "x": -12,
      "y": -15,
      "z": 1,
      "name": "Rock_Shale"
    },
    {
      "x": -12,
      "y": -14,
      "z": 1,
      "name": "Rock_Shale"
    },
    {
      "x": -12,
      "y": -13,
      "z": 1,
      "name": "Rock_Shale"
    },
    {
      "x": -12,
      "y": -12,
      "z": 1,
      "name": "Rock_Shale"
    },
    {
      "x": -12,
      "y": -11,
      "z": 1,
      "name": "Rock_Shale"
    },
    {
      "x": -12,
      "y": -10,
      "z": 1,
      "name": "Rock_Shale"
    },
    {
      "x": -12,
      "y": -9,
      "z": 1,
      "name": "Rock_Shale"
    },
    {
      "x": -12,
      "y": -8,
      "z": 1,
      "name": "Rock_Shale"
    },
    {
      "x": -12,
      "y": -7,
      "z": 1,
      "name": "Rock_Shale"
    },
    {
      "x": -12,
      "y": -6,
      "z": 1,
      "name": "Rock_Shale"
    },
    {
      "x": -12,
      "y": -5,
      "z": 1,
      "name": "Rock_Shale"
    },
    {
      "x": -12,
      "y": -4,
      "z": 1,
      "name": "Rock_Shale"
    },
    {
      "x": -12,
      "y": -3,
      "z": 1,
      "name": "Rock_Shale"
    },
    {
      "x": -12,
      "y": -2,
      "z": 1,
      "name": "Rock_Shale"
    },
    {
      "x": -12,
      "y": -1,
      "z": 1,
      "name": "Rock_Shale"
    },
    {
      "x": -12,
      "y": 0,
      "z": 1,
      "name": "Rock_Shale"
    },
    {
      "x": -12,
      "y": 1,
      "z": 1,
      "name": "Rock_Shale"
    },
    {
      "x": -12,
      "y": 2,
      "z": 1,
      "name": "Plant_Mushroom_Block_White_Mycelium",
      "support": 15
    },
    {
      "x": -12,
      "y": 3,
      "z": 1,
      "name": "Plant_Mushroom_Rug_White_Mycelium",
      "support": 15
    },
    {
      "x": -12,
      "y": 42,
      "z": 1,
      "name": "Rock_Shale"
    },
    {
      "x": -12,
      "y": 43,
      "z": 1,
      "name": "Rock_Shale"
    },
    {
      "x": -12,
      "y": -15,
      "z": 2,
      "name": "Rock_Shale"
    },
    {
      "x": -12,
      "y": -14,
      "z": 2,
      "name": "Rock_Shale"
    },
    {
      "x": -12,
      "y": -13,
      "z": 2,
      "name": "Rock_Shale"
    },
    {
      "x": -12,
      "y": -12,
      "z": 2,
      "name": "Rock_Shale"
    },
    {
      "x": -12,
      "y": -11,
      "z": 2,
      "name": "Rock_Shale"
    },
    {
      "x": -12,
      "y": -10,
      "z": 2,
      "name": "Rock_Shale"
    },
    {
      "x": -12,
      "y": -9,
      "z": 2,
      "name": "Rock_Shale"
    },
    {
      "x": -12,
      "y": -8,
      "z": 2,
      "name": "Rock_Shale"
    },
    {
      "x": -12,
      "y": -7,
      "z": 2,
      "name": "Rock_Shale"
    },
    {
      "x": -12,
      "y": -6,
      "z": 2,
      "name": "Rock_Shale"
    },
    {
      "x": -12,
      "y": -5,
      "z": 2,
      "name": "Rock_Shale"
    },
    {
      "x": -12,
      "y": -4,
      "z": 2,
      "name": "Rock_Shale"
    },
    {
      "x": -12,
      "y": -3,
      "z": 2,
      "name": "Rock_Shale"
    },
    {
      "x": -12,
      "y": -2,
      "z": 2,
      "name": "Rock_Shale"
    },
    {
      "x": -12,
      "y": -1,
      "z": 2,
      "name": "Rock_Shale"
    },
    {
      "x": -12,
      "y": 0,
      "z": 2,
      "name": "Rock_Shale"
    },
    {
      "x": -12,
      "y": 1,
      "z": 2,
      "name": "Plant_Mushroom_Block_White_Mycelium",
      "support": 15
    },
    {
      "x": -12,
      "y": 2,
      "z": 2,
      "name": "Plant_Mushroom_Rug_White_Mycelium",
      "support": 15
    },
    {
      "x": -12,
      "y": -15,
      "z": 3,
      "name": "Rock_Shale"
    },
    {
      "x": -12,
      "y": -14,
      "z": 3,
      "name": "Rock_Shale"
    },
    {
      "x": -12,
      "y": -13,
      "z": 3,
      "name": "Rock_Shale"
    },
    {
      "x": -12,
      "y": -12,
      "z": 3,
      "name": "Rock_Shale"
    },
    {
      "x": -12,
      "y": -11,
      "z": 3,
      "name": "Rock_Shale"
    },
    {
      "x": -12,
      "y": -10,
      "z": 3,
      "name": "Rock_Shale"
    },
    {
      "x": -12,
      "y": -9,
      "z": 3,
      "name": "Rock_Shale"
    },
    {
      "x": -12,
      "y": -8,
      "z": 3,
      "name": "Rock_Shale"
    },
    {
      "x": -12,
      "y": -7,
      "z": 3,
      "name": "Rock_Shale"
    },
    {
      "x": -12,
      "y": -6,
      "z": 3,
      "name": "Rock_Shale"
    },
    {
      "x": -12,
      "y": -5,
      "z": 3,
      "name": "Rock_Shale"
    },
    {
      "x": -12,
      "y": -4,
      "z": 3,
      "name": "Rock_Shale"
    },
    {
      "x": -12,
      "y": -3,
      "z": 3,
      "name": "Rock_Shale"
    },
    {
      "x": -12,
      "y": -2,
      "z": 3,
      "name": "Rock_Shale"
    },
    {
      "x": -12,
      "y": -1,
      "z": 3,
      "name": "Rock_Shale"
    },
    {
      "x": -12,
      "y": 0,
      "z": 3,
      "name": "Rock_Shale"
    },
    {
      "x": -12,
      "y": 1,
      "z": 3,
      "name": "Rock_Shale"
    },
    {
      "x": -12,
      "y": 2,
      "z": 3,
      "name": "Plant_Mushroom_Rug_White_Mycelium",
      "support": 15
    },
    {
      "x": -12,
      "y": -14,
      "z": 4,
      "name": "Rock_Shale"
    },
    {
      "x": -12,
      "y": -13,
      "z": 4,
      "name": "Rock_Shale"
    },
    {
      "x": -12,
      "y": -12,
      "z": 4,
      "name": "Rock_Shale"
    },
    {
      "x": -12,
      "y": -11,
      "z": 4,
      "name": "Rock_Shale"
    },
    {
      "x": -12,
      "y": -10,
      "z": 4,
      "name": "Rock_Shale"
    },
    {
      "x": -12,
      "y": -9,
      "z": 4,
      "name": "Rock_Shale"
    },
    {
      "x": -12,
      "y": -8,
      "z": 4,
      "name": "Rock_Shale"
    },
    {
      "x": -12,
      "y": -7,
      "z": 4,
      "name": "Rock_Shale"
    },
    {
      "x": -12,
      "y": -6,
      "z": 4,
      "name": "Rock_Shale"
    },
    {
      "x": -12,
      "y": -5,
      "z": 4,
      "name": "Rock_Shale"
    },
    {
      "x": -12,
      "y": -4,
      "z": 4,
      "name": "Rock_Shale"
    },
    {
      "x": -12,
      "y": -3,
      "z": 4,
      "name": "Rock_Shale"
    },
    {
      "x": -12,
      "y": -2,
      "z": 4,
      "name": "Rock_Shale"
    },
    {
      "x": -12,
      "y": -1,
      "z": 4,
      "name": "Rock_Shale"
    },
    {
      "x": -12,
      "y": 0,
      "z": 4,
      "name": "Rock_Shale"
    },
    {
      "x": -12,
      "y": 1,
      "z": 4,
      "name": "Plant_Mushroom_Short_White_Mycelium",
      "support": 15
    },
    {
      "x": -12,
      "y": -12,
      "z": 5,
      "name": "Rock_Shale"
    },
    {
      "x": -12,
      "y": -11,
      "z": 5,
      "name": "Rock_Shale"
    },
    {
      "x": -12,
      "y": -10,
      "z": 5,
      "name": "Rock_Shale"
    },
    {
      "x": -12,
      "y": -9,
      "z": 5,
      "name": "Rock_Shale"
    },
    {
      "x": -12,
      "y": -8,
      "z": 5,
      "name": "Rock_Shale"
    },
    {
      "x": -12,
      "y": -7,
      "z": 5,
      "name": "Rock_Shale"
    },
    {
      "x": -12,
      "y": -6,
      "z": 5,
      "name": "Rock_Shale"
    },
    {
      "x": -12,
      "y": -5,
      "z": 5,
      "name": "Rock_Shale"
    },
    {
      "x": -12,
      "y": -4,
      "z": 5,
      "name": "Rock_Shale"
    },
    {
      "x": -12,
      "y": -3,
      "z": 5,
      "name": "Rock_Shale"
    },
    {
      "x": -12,
      "y": -2,
      "z": 5,
      "name": "Rock_Shale"
    },
    {
      "x": -12,
      "y": -1,
      "z": 5,
      "name": "Rock_Shale"
    },
    {
      "x": -12,
      "y": 0,
      "z": 5,
      "name": "Rock_Shale"
    },
    {
      "x": -12,
      "y": 1,
      "z": 5,
      "name": "Rock_Shale"
    },
    {
      "x": -12,
      "y": 2,
      "z": 5,
      "name": "Plant_Mushroom_Rug_White_Mycelium",
      "support": 15
    },
    {
      "x": -12,
      "y": -12,
      "z": 6,
      "name": "Rock_Shale"
    },
    {
      "x": -12,
      "y": -11,
      "z": 6,
      "name": "Rock_Shale"
    },
    {
      "x": -12,
      "y": -10,
      "z": 6,
      "name": "Rock_Shale"
    },
    {
      "x": -12,
      "y": -9,
      "z": 6,
      "name": "Rock_Shale"
    },
    {
      "x": -12,
      "y": -8,
      "z": 6,
      "name": "Rock_Shale"
    },
    {
      "x": -12,
      "y": -7,
      "z": 6,
      "name": "Rock_Shale"
    },
    {
      "x": -12,
      "y": -6,
      "z": 6,
      "name": "Rock_Shale"
    },
    {
      "x": -12,
      "y": -5,
      "z": 6,
      "name": "Rock_Shale"
    },
    {
      "x": -12,
      "y": -4,
      "z": 6,
      "name": "Rock_Shale"
    },
    {
      "x": -12,
      "y": -3,
      "z": 6,
      "name": "Rock_Shale"
    },
    {
      "x": -12,
      "y": -2,
      "z": 6,
      "name": "Rock_Shale"
    },
    {
      "x": -12,
      "y": -1,
      "z": 6,
      "name": "Rock_Shale"
    },
    {
      "x": -12,
      "y": 0,
      "z": 6,
      "name": "Rock_Shale"
    },
    {
      "x": -12,
      "y": -13,
      "z": 7,
      "name": "Rock_Shale"
    },
    {
      "x": -12,
      "y": -12,
      "z": 7,
      "name": "Rock_Shale"
    },
    {
      "x": -12,
      "y": -11,
      "z": 7,
      "name": "Rock_Shale"
    },
    {
      "x": -12,
      "y": -10,
      "z": 7,
      "name": "Rock_Shale"
    },
    {
      "x": -12,
      "y": -9,
      "z": 7,
      "name": "Rock_Shale"
    },
    {
      "x": -12,
      "y": -8,
      "z": 7,
      "name": "Rock_Shale"
    },
    {
      "x": -12,
      "y": -7,
      "z": 7,
      "name": "Rock_Shale"
    },
    {
      "x": -12,
      "y": -6,
      "z": 7,
      "name": "Rock_Shale"
    },
    {
      "x": -12,
      "y": -5,
      "z": 7,
      "name": "Rock_Shale"
    },
    {
      "x": -12,
      "y": -4,
      "z": 7,
      "name": "Rock_Shale"
    },
    {
      "x": -12,
      "y": -3,
      "z": 7,
      "name": "Rock_Shale"
    },
    {
      "x": -12,
      "y": -2,
      "z": 7,
      "name": "Rock_Shale"
    },
    {
      "x": -12,
      "y": -1,
      "z": 7,
      "name": "Rock_Shale"
    },
    {
      "x": -12,
      "y": 0,
      "z": 7,
      "name": "Rock_Shale"
    },
    {
      "x": -12,
      "y": -14,
      "z": 8,
      "name": "Rock_Shale"
    },
    {
      "x": -12,
      "y": -13,
      "z": 8,
      "name": "Rock_Shale"
    },
    {
      "x": -12,
      "y": -12,
      "z": 8,
      "name": "Rock_Shale"
    },
    {
      "x": -12,
      "y": -11,
      "z": 8,
      "name": "Rock_Shale"
    },
    {
      "x": -12,
      "y": -10,
      "z": 8,
      "name": "Rock_Shale"
    },
    {
      "x": -12,
      "y": -9,
      "z": 8,
      "name": "Rock_Shale"
    },
    {
      "x": -12,
      "y": -8,
      "z": 8,
      "name": "Rock_Shale"
    },
    {
      "x": -12,
      "y": -7,
      "z": 8,
      "name": "Rock_Shale"
    },
    {
      "x": -12,
      "y": -6,
      "z": 8,
      "name": "Rock_Shale"
    },
    {
      "x": -12,
      "y": -5,
      "z": 8,
      "name": "Rock_Shale"
    },
    {
      "x": -12,
      "y": -4,
      "z": 8,
      "name": "Rock_Shale"
    },
    {
      "x": -12,
      "y": -3,
      "z": 8,
      "name": "Rock_Shale"
    },
    {
      "x": -12,
      "y": -2,
      "z": 8,
      "name": "Rock_Shale"
    },
    {
      "x": -12,
      "y": -1,
      "z": 8,
      "name": "Rock_Shale"
    },
    {
      "x": -12,
      "y": 0,
      "z": 8,
      "name": "Rock_Shale"
    },
    {
      "x": -12,
      "y": 1,
      "z": 8,
      "name": "Wood_Giantwood_Trunk_Tainted_Full"
    },
    {
      "x": -12,
      "y": 2,
      "z": 8,
      "name": "Plant_Mushroom_Short_White_Mycelium",
      "support": 15
    },
    {
      "x": -12,
      "y": -14,
      "z": 9,
      "name": "Rock_Shale"
    },
    {
      "x": -12,
      "y": -13,
      "z": 9,
      "name": "Rock_Shale"
    },
    {
      "x": -12,
      "y": -12,
      "z": 9,
      "name": "Rock_Shale"
    },
    {
      "x": -12,
      "y": -11,
      "z": 9,
      "name": "Rock_Shale"
    },
    {
      "x": -12,
      "y": -10,
      "z": 9,
      "name": "Rock_Shale"
    },
    {
      "x": -12,
      "y": -9,
      "z": 9,
      "name": "Rock_Shale"
    },
    {
      "x": -12,
      "y": -8,
      "z": 9,
      "name": "Rock_Shale"
    },
    {
      "x": -12,
      "y": -7,
      "z": 9,
      "name": "Rock_Shale"
    },
    {
      "x": -12,
      "y": -6,
      "z": 9,
      "name": "Rock_Shale"
    },
    {
      "x": -12,
      "y": -5,
      "z": 9,
      "name": "Rock_Shale"
    },
    {
      "x": -12,
      "y": -4,
      "z": 9,
      "name": "Rock_Shale"
    },
    {
      "x": -12,
      "y": -3,
      "z": 9,
      "name": "Rock_Shale"
    },
    {
      "x": -12,
      "y": -2,
      "z": 9,
      "name": "Rock_Shale"
    },
    {
      "x": -12,
      "y": -13,
      "z": 10,
      "name": "Rock_Shale"
    },
    {
      "x": -12,
      "y": -12,
      "z": 10,
      "name": "Rock_Shale"
    },
    {
      "x": -12,
      "y": -11,
      "z": 10,
      "name": "Rock_Shale"
    },
    {
      "x": -12,
      "y": -10,
      "z": 10,
      "name": "Rock_Shale"
    },
    {
      "x": -12,
      "y": -9,
      "z": 10,
      "name": "Rock_Shale"
    },
    {
      "x": -12,
      "y": -8,
      "z": 10,
      "name": "Rock_Shale"
    },
    {
      "x": -12,
      "y": -7,
      "z": 10,
      "name": "Rock_Shale"
    },
    {
      "x": -12,
      "y": -6,
      "z": 10,
      "name": "Rock_Shale"
    },
    {
      "x": -12,
      "y": -8,
      "z": 11,
      "name": "Rock_Shale"
    },
    {
      "x": -12,
      "y": -7,
      "z": 11,
      "name": "Rock_Shale"
    },
    {
      "x": -11,
      "y": -9,
      "z": -6,
      "name": "Rock_Shale"
    },
    {
      "x": -11,
      "y": -8,
      "z": -6,
      "name": "Rock_Shale"
    },
    {
      "x": -11,
      "y": -7,
      "z": -6,
      "name": "Rock_Shale"
    },
    {
      "x": -11,
      "y": -6,
      "z": -6,
      "name": "Rock_Shale"
    },
    {
      "x": -11,
      "y": -11,
      "z": -5,
      "name": "Rock_Shale"
    },
    {
      "x": -11,
      "y": -10,
      "z": -5,
      "name": "Rock_Shale"
    },
    {
      "x": -11,
      "y": -9,
      "z": -5,
      "name": "Rock_Shale"
    },
    {
      "x": -11,
      "y": -8,
      "z": -5,
      "name": "Rock_Shale"
    },
    {
      "x": -11,
      "y": -7,
      "z": -5,
      "name": "Rock_Shale"
    },
    {
      "x": -11,
      "y": -6,
      "z": -5,
      "name": "Rock_Shale"
    },
    {
      "x": -11,
      "y": -5,
      "z": -5,
      "name": "Rock_Shale"
    },
    {
      "x": -11,
      "y": -4,
      "z": -5,
      "name": "Rock_Shale"
    },
    {
      "x": -11,
      "y": -3,
      "z": -5,
      "name": "Rock_Shale"
    },
    {
      "x": -11,
      "y": -2,
      "z": -5,
      "name": "Rock_Shale"
    },
    {
      "x": -11,
      "y": -1,
      "z": -5,
      "name": "Rock_Shale"
    },
    {
      "x": -11,
      "y": 0,
      "z": -5,
      "name": "Rock_Shale"
    },
    {
      "x": -11,
      "y": -13,
      "z": -4,
      "name": "Rock_Shale"
    },
    {
      "x": -11,
      "y": -12,
      "z": -4,
      "name": "Rock_Shale"
    },
    {
      "x": -11,
      "y": -11,
      "z": -4,
      "name": "Rock_Shale"
    },
    {
      "x": -11,
      "y": -10,
      "z": -4,
      "name": "Rock_Shale"
    },
    {
      "x": -11,
      "y": -9,
      "z": -4,
      "name": "Rock_Shale"
    },
    {
      "x": -11,
      "y": -8,
      "z": -4,
      "name": "Rock_Shale"
    },
    {
      "x": -11,
      "y": -7,
      "z": -4,
      "name": "Rock_Shale"
    },
    {
      "x": -11,
      "y": -6,
      "z": -4,
      "name": "Rock_Shale"
    },
    {
      "x": -11,
      "y": -5,
      "z": -4,
      "name": "Rock_Shale"
    },
    {
      "x": -11,
      "y": -4,
      "z": -4,
      "name": "Rock_Shale"
    },
    {
      "x": -11,
      "y": -3,
      "z": -4,
      "name": "Rock_Shale"
    },
    {
      "x": -11,
      "y": -2,
      "z": -4,
      "name": "Rock_Shale"
    },
    {
      "x": -11,
      "y": -1,
      "z": -4,
      "name": "Rock_Shale"
    },
    {
      "x": -11,
      "y": 0,
      "z": -4,
      "name": "Rock_Shale"
    },
    {
      "x": -11,
      "y": 42,
      "z": -4,
      "name": "Rock_Shale"
    },
    {
      "x": -11,
      "y": 43,
      "z": -4,
      "name": "Rock_Shale"
    },
    {
      "x": -11,
      "y": -14,
      "z": -3,
      "name": "Rock_Shale"
    },
    {
      "x": -11,
      "y": -13,
      "z": -3,
      "name": "Rock_Shale"
    },
    {
      "x": -11,
      "y": -12,
      "z": -3,
      "name": "Rock_Shale"
    },
    {
      "x": -11,
      "y": -11,
      "z": -3,
      "name": "Rock_Shale"
    },
    {
      "x": -11,
      "y": -10,
      "z": -3,
      "name": "Rock_Shale"
    },
    {
      "x": -11,
      "y": -9,
      "z": -3,
      "name": "Rock_Shale"
    },
    {
      "x": -11,
      "y": -8,
      "z": -3,
      "name": "Rock_Shale"
    },
    {
      "x": -11,
      "y": -7,
      "z": -3,
      "name": "Rock_Shale"
    },
    {
      "x": -11,
      "y": -6,
      "z": -3,
      "name": "Rock_Shale"
    },
    {
      "x": -11,
      "y": -5,
      "z": -3,
      "name": "Rock_Shale"
    },
    {
      "x": -11,
      "y": -4,
      "z": -3,
      "name": "Rock_Shale"
    },
    {
      "x": -11,
      "y": -3,
      "z": -3,
      "name": "Rock_Shale"
    },
    {
      "x": -11,
      "y": -2,
      "z": -3,
      "name": "Rock_Shale"
    },
    {
      "x": -11,
      "y": -1,
      "z": -3,
      "name": "Rock_Shale"
    },
    {
      "x": -11,
      "y": 0,
      "z": -3,
      "name": "Rock_Shale"
    },
    {
      "x": -11,
      "y": 1,
      "z": -3,
      "name": "Rock_Shale"
    },
    {
      "x": -11,
      "y": 2,
      "z": -3,
      "name": "Plant_Roots_Rug_Tainted",
      "support": 15
    },
    {
      "x": -11,
      "y": 41,
      "z": -3,
      "name": "Rock_Shale"
    },
    {
      "x": -11,
      "y": 42,
      "z": -3,
      "name": "Rock_Shale"
    },
    {
      "x": -11,
      "y": 43,
      "z": -3,
      "name": "Rock_Shale"
    },
    {
      "x": -11,
      "y": -15,
      "z": -2,
      "name": "Rock_Shale"
    },
    {
      "x": -11,
      "y": -14,
      "z": -2,
      "name": "Rock_Shale"
    },
    {
      "x": -11,
      "y": -13,
      "z": -2,
      "name": "Rock_Shale"
    },
    {
      "x": -11,
      "y": -12,
      "z": -2,
      "name": "Rock_Shale"
    },
    {
      "x": -11,
      "y": -11,
      "z": -2,
      "name": "Rock_Shale"
    },
    {
      "x": -11,
      "y": -10,
      "z": -2,
      "name": "Rock_Shale"
    },
    {
      "x": -11,
      "y": -9,
      "z": -2,
      "name": "Rock_Shale"
    },
    {
      "x": -11,
      "y": -8,
      "z": -2,
      "name": "Rock_Shale"
    },
    {
      "x": -11,
      "y": -7,
      "z": -2,
      "name": "Rock_Shale"
    },
    {
      "x": -11,
      "y": -6,
      "z": -2,
      "name": "Rock_Shale"
    },
    {
      "x": -11,
      "y": -5,
      "z": -2,
      "name": "Rock_Shale"
    },
    {
      "x": -11,
      "y": -4,
      "z": -2,
      "name": "Rock_Shale"
    },
    {
      "x": -11,
      "y": -3,
      "z": -2,
      "name": "Rock_Shale"
    },
    {
      "x": -11,
      "y": -2,
      "z": -2,
      "name": "Rock_Shale"
    },
    {
      "x": -11,
      "y": -1,
      "z": -2,
      "name": "Rock_Shale"
    },
    {
      "x": -11,
      "y": 0,
      "z": -2,
      "name": "Rock_Shale"
    },
    {
      "x": -11,
      "y": 1,
      "z": -2,
      "name": "Rock_Shale"
    },
    {
      "x": -11,
      "y": 2,
      "z": -2,
      "name": "Plant_Roots_Rug_Tainted",
      "support": 15
    },
    {
      "x": -11,
      "y": 40,
      "z": -2,
      "name": "Rock_Shale"
    },
    {
      "x": -11,
      "y": 41,
      "z": -2,
      "name": "Rock_Shale"
    },
    {
      "x": -11,
      "y": 42,
      "z": -2,
      "name": "Rock_Shale"
    },
    {
      "x": -11,
      "y": 43,
      "z": -2,
      "name": "Rock_Shale"
    },
    {
      "x": -11,
      "y": -15,
      "z": -1,
      "name": "Rock_Shale"
    },
    {
      "x": -11,
      "y": -14,
      "z": -1,
      "name": "Rock_Shale"
    },
    {
      "x": -11,
      "y": -13,
      "z": -1,
      "name": "Rock_Shale"
    },
    {
      "x": -11,
      "y": -12,
      "z": -1,
      "name": "Rock_Shale"
    },
    {
      "x": -11,
      "y": -11,
      "z": -1,
      "name": "Rock_Shale"
    },
    {
      "x": -11,
      "y": -10,
      "z": -1,
      "name": "Rock_Shale"
    },
    {
      "x": -11,
      "y": -9,
      "z": -1,
      "name": "Rock_Shale"
    },
    {
      "x": -11,
      "y": -8,
      "z": -1,
      "name": "Rock_Shale"
    },
    {
      "x": -11,
      "y": -7,
      "z": -1,
      "name": "Rock_Shale"
    },
    {
      "x": -11,
      "y": -6,
      "z": -1,
      "name": "Rock_Shale"
    },
    {
      "x": -11,
      "y": -5,
      "z": -1,
      "name": "Rock_Shale"
    },
    {
      "x": -11,
      "y": -4,
      "z": -1,
      "name": "Rock_Shale"
    },
    {
      "x": -11,
      "y": -3,
      "z": -1,
      "name": "Rock_Shale"
    },
    {
      "x": -11,
      "y": -2,
      "z": -1,
      "name": "Rock_Shale"
    },
    {
      "x": -11,
      "y": -1,
      "z": -1,
      "name": "Rock_Shale"
    },
    {
      "x": -11,
      "y": 0,
      "z": -1,
      "name": "Rock_Shale"
    },
    {
      "x": -11,
      "y": 1,
      "z": -1,
      "name": "Rock_Shale"
    },
    {
      "x": -11,
      "y": 2,
      "z": -1,
      "name": "Rock_Shale"
    },
    {
      "x": -11,
      "y": 39,
      "z": -1,
      "name": "Rock_Shale"
    },
    {
      "x": -11,
      "y": 40,
      "z": -1,
      "name": "Rock_Shale"
    },
    {
      "x": -11,
      "y": 41,
      "z": -1,
      "name": "Rock_Shale"
    },
    {
      "x": -11,
      "y": 42,
      "z": -1,
      "name": "Rock_Shale"
    },
    {
      "x": -11,
      "y": 43,
      "z": -1,
      "name": "Rock_Shale"
    },
    {
      "x": -11,
      "y": 44,
      "z": -1,
      "name": "Rock_Shale"
    },
    {
      "x": -11,
      "y": -15,
      "z": 0,
      "name": "Rock_Shale"
    },
    {
      "x": -11,
      "y": -14,
      "z": 0,
      "name": "Rock_Shale"
    },
    {
      "x": -11,
      "y": -13,
      "z": 0,
      "name": "Rock_Shale"
    },
    {
      "x": -11,
      "y": -12,
      "z": 0,
      "name": "Rock_Shale"
    },
    {
      "x": -11,
      "y": -11,
      "z": 0,
      "name": "Rock_Shale"
    },
    {
      "x": -11,
      "y": -10,
      "z": 0,
      "name": "Rock_Shale"
    },
    {
      "x": -11,
      "y": -9,
      "z": 0,
      "name": "Rock_Shale"
    },
    {
      "x": -11,
      "y": -8,
      "z": 0,
      "name": "Rock_Shale"
    },
    {
      "x": -11,
      "y": -7,
      "z": 0,
      "name": "Rock_Shale"
    },
    {
      "x": -11,
      "y": -6,
      "z": 0,
      "name": "Rock_Shale"
    },
    {
      "x": -11,
      "y": -5,
      "z": 0,
      "name": "Rock_Shale"
    },
    {
      "x": -11,
      "y": -4,
      "z": 0,
      "name": "Rock_Shale"
    },
    {
      "x": -11,
      "y": -3,
      "z": 0,
      "name": "Rock_Shale"
    },
    {
      "x": -11,
      "y": -2,
      "z": 0,
      "name": "Rock_Shale"
    },
    {
      "x": -11,
      "y": -1,
      "z": 0,
      "name": "Rock_Shale"
    },
    {
      "x": -11,
      "y": 0,
      "z": 0,
      "name": "Rock_Shale"
    },
    {
      "x": -11,
      "y": 1,
      "z": 0,
      "name": "Rock_Shale"
    },
    {
      "x": -11,
      "y": 2,
      "z": 0,
      "name": "Rock_Shale"
    },
    {
      "x": -11,
      "y": 3,
      "z": 0,
      "name": "Rock_Shale"
    },
    {
      "x": -11,
      "y": 4,
      "z": 0,
      "name": "Plant_Mushroom_Short_White_Mycelium",
      "support": 15
    },
    {
      "x": -11,
      "y": 37,
      "z": 0,
      "name": "Rock_Shale"
    },
    {
      "x": -11,
      "y": 38,
      "z": 0,
      "name": "Rock_Shale"
    },
    {
      "x": -11,
      "y": 39,
      "z": 0,
      "name": "Rock_Shale"
    },
    {
      "x": -11,
      "y": 40,
      "z": 0,
      "name": "Rock_Shale"
    },
    {
      "x": -11,
      "y": 41,
      "z": 0,
      "name": "Rock_Shale"
    },
    {
      "x": -11,
      "y": 42,
      "z": 0,
      "name": "Rock_Shale"
    },
    {
      "x": -11,
      "y": 43,
      "z": 0,
      "name": "Rock_Shale"
    },
    {
      "x": -11,
      "y": 44,
      "z": 0,
      "name": "Rock_Shale"
    },
    {
      "x": -11,
      "y": -15,
      "z": 1,
      "name": "Rock_Shale"
    },
    {
      "x": -11,
      "y": -14,
      "z": 1,
      "name": "Rock_Shale"
    },
    {
      "x": -11,
      "y": -13,
      "z": 1,
      "name": "Rock_Shale"
    },
    {
      "x": -11,
      "y": -12,
      "z": 1,
      "name": "Rock_Shale"
    },
    {
      "x": -11,
      "y": -11,
      "z": 1,
      "name": "Rock_Shale"
    },
    {
      "x": -11,
      "y": -10,
      "z": 1,
      "name": "Rock_Shale"
    },
    {
      "x": -11,
      "y": -9,
      "z": 1,
      "name": "Rock_Shale"
    },
    {
      "x": -11,
      "y": -8,
      "z": 1,
      "name": "Rock_Shale"
    },
    {
      "x": -11,
      "y": -7,
      "z": 1,
      "name": "Rock_Shale"
    },
    {
      "x": -11,
      "y": -6,
      "z": 1,
      "name": "Rock_Shale"
    },
    {
      "x": -11,
      "y": -5,
      "z": 1,
      "name": "Rock_Shale"
    },
    {
      "x": -11,
      "y": -4,
      "z": 1,
      "name": "Rock_Shale"
    },
    {
      "x": -11,
      "y": -3,
      "z": 1,
      "name": "Rock_Shale"
    },
    {
      "x": -11,
      "y": -2,
      "z": 1,
      "name": "Rock_Shale"
    },
    {
      "x": -11,
      "y": -1,
      "z": 1,
      "name": "Rock_Shale"
    },
    {
      "x": -11,
      "y": 0,
      "z": 1,
      "name": "Rock_Shale"
    },
    {
      "x": -11,
      "y": 1,
      "z": 1,
      "name": "Rock_Shale"
    },
    {
      "x": -11,
      "y": 2,
      "z": 1,
      "name": "Plant_Mushroom_Block_White_Mycelium",
      "support": 15
    },
    {
      "x": -11,
      "y": 3,
      "z": 1,
      "name": "Plant_Crop_Mushroom_Funnel_Tainted"
    },
    {
      "x": -11,
      "y": 40,
      "z": 1,
      "name": "Rock_Shale"
    },
    {
      "x": -11,
      "y": 41,
      "z": 1,
      "name": "Rock_Shale"
    },
    {
      "x": -11,
      "y": 42,
      "z": 1,
      "name": "Rock_Shale"
    },
    {
      "x": -11,
      "y": 43,
      "z": 1,
      "name": "Rock_Shale"
    },
    {
      "x": -11,
      "y": -15,
      "z": 2,
      "name": "Rock_Shale"
    },
    {
      "x": -11,
      "y": -14,
      "z": 2,
      "name": "Rock_Shale"
    },
    {
      "x": -11,
      "y": -13,
      "z": 2,
      "name": "Rock_Shale"
    },
    {
      "x": -11,
      "y": -12,
      "z": 2,
      "name": "Rock_Shale"
    },
    {
      "x": -11,
      "y": -11,
      "z": 2,
      "name": "Rock_Shale"
    },
    {
      "x": -11,
      "y": -10,
      "z": 2,
      "name": "Rock_Shale"
    },
    {
      "x": -11,
      "y": -9,
      "z": 2,
      "name": "Rock_Shale"
    },
    {
      "x": -11,
      "y": -8,
      "z": 2,
      "name": "Rock_Shale"
    },
    {
      "x": -11,
      "y": -7,
      "z": 2,
      "name": "Rock_Shale"
    },
    {
      "x": -11,
      "y": -6,
      "z": 2,
      "name": "Rock_Shale"
    },
    {
      "x": -11,
      "y": -5,
      "z": 2,
      "name": "Rock_Shale"
    },
    {
      "x": -11,
      "y": -4,
      "z": 2,
      "name": "Rock_Shale"
    },
    {
      "x": -11,
      "y": -3,
      "z": 2,
      "name": "Rock_Shale"
    },
    {
      "x": -11,
      "y": -2,
      "z": 2,
      "name": "Rock_Shale"
    },
    {
      "x": -11,
      "y": -1,
      "z": 2,
      "name": "Rock_Shale"
    },
    {
      "x": -11,
      "y": 0,
      "z": 2,
      "name": "Rock_Shale"
    },
    {
      "x": -11,
      "y": 1,
      "z": 2,
      "name": "Rock_Shale"
    },
    {
      "x": -11,
      "y": 2,
      "z": 2,
      "name": "Plant_Mushroom_Block_White_Mycelium",
      "support": 15
    },
    {
      "x": -11,
      "y": 3,
      "z": 2,
      "name": "Plant_Mushroom_Rug_White_Mycelium",
      "support": 15
    },
    {
      "x": -11,
      "y": 41,
      "z": 2,
      "name": "Rock_Shale"
    },
    {
      "x": -11,
      "y": 42,
      "z": 2,
      "name": "Rock_Shale"
    },
    {
      "x": -11,
      "y": 43,
      "z": 2,
      "name": "Rock_Shale"
    },
    {
      "x": -11,
      "y": -15,
      "z": 3,
      "name": "Rock_Shale"
    },
    {
      "x": -11,
      "y": -14,
      "z": 3,
      "name": "Rock_Shale"
    },
    {
      "x": -11,
      "y": -13,
      "z": 3,
      "name": "Rock_Shale"
    },
    {
      "x": -11,
      "y": -12,
      "z": 3,
      "name": "Rock_Shale"
    },
    {
      "x": -11,
      "y": -11,
      "z": 3,
      "name": "Rock_Shale"
    },
    {
      "x": -11,
      "y": -10,
      "z": 3,
      "name": "Rock_Shale"
    },
    {
      "x": -11,
      "y": -9,
      "z": 3,
      "name": "Rock_Shale"
    },
    {
      "x": -11,
      "y": -8,
      "z": 3,
      "name": "Rock_Shale"
    },
    {
      "x": -11,
      "y": -7,
      "z": 3,
      "name": "Rock_Shale"
    },
    {
      "x": -11,
      "y": -6,
      "z": 3,
      "name": "Rock_Shale"
    },
    {
      "x": -11,
      "y": -5,
      "z": 3,
      "name": "Rock_Shale"
    },
    {
      "x": -11,
      "y": -4,
      "z": 3,
      "name": "Rock_Shale"
    },
    {
      "x": -11,
      "y": -3,
      "z": 3,
      "name": "Rock_Shale"
    },
    {
      "x": -11,
      "y": -2,
      "z": 3,
      "name": "Rock_Shale"
    },
    {
      "x": -11,
      "y": -1,
      "z": 3,
      "name": "Rock_Shale"
    },
    {
      "x": -11,
      "y": 0,
      "z": 3,
      "name": "Rock_Shale"
    },
    {
      "x": -11,
      "y": 1,
      "z": 3,
      "name": "Rock_Shale"
    },
    {
      "x": -11,
      "y": 2,
      "z": 3,
      "name": "Rock_Shale"
    },
    {
      "x": -11,
      "y": 3,
      "z": 3,
      "name": "Plant_Mushroom_Rug_White_Mycelium",
      "support": 15
    },
    {
      "x": -11,
      "y": -15,
      "z": 4,
      "name": "Rock_Shale"
    },
    {
      "x": -11,
      "y": -14,
      "z": 4,
      "name": "Rock_Shale"
    },
    {
      "x": -11,
      "y": -13,
      "z": 4,
      "name": "Rock_Shale"
    },
    {
      "x": -11,
      "y": -12,
      "z": 4,
      "name": "Rock_Shale"
    },
    {
      "x": -11,
      "y": -11,
      "z": 4,
      "name": "Rock_Shale"
    },
    {
      "x": -11,
      "y": -10,
      "z": 4,
      "name": "Rock_Shale"
    },
    {
      "x": -11,
      "y": -9,
      "z": 4,
      "name": "Rock_Shale"
    },
    {
      "x": -11,
      "y": -8,
      "z": 4,
      "name": "Rock_Shale"
    },
    {
      "x": -11,
      "y": -7,
      "z": 4,
      "name": "Rock_Shale"
    },
    {
      "x": -11,
      "y": -6,
      "z": 4,
      "name": "Rock_Shale"
    },
    {
      "x": -11,
      "y": -5,
      "z": 4,
      "name": "Rock_Shale"
    },
    {
      "x": -11,
      "y": -4,
      "z": 4,
      "name": "Rock_Shale"
    },
    {
      "x": -11,
      "y": -3,
      "z": 4,
      "name": "Rock_Shale"
    },
    {
      "x": -11,
      "y": -2,
      "z": 4,
      "name": "Rock_Shale"
    },
    {
      "x": -11,
      "y": -1,
      "z": 4,
      "name": "Rock_Shale"
    },
    {
      "x": -11,
      "y": 0,
      "z": 4,
      "name": "Rock_Shale"
    },
    {
      "x": -11,
      "y": 1,
      "z": 4,
      "name": "Rock_Shale"
    },
    {
      "x": -11,
      "y": 2,
      "z": 4,
      "name": "Rock_Shale"
    },
    {
      "x": -11,
      "y": 3,
      "z": 4,
      "name": "Plant_Mushroom_Short_White_Mycelium",
      "support": 15
    },
    {
      "x": -11,
      "y": -14,
      "z": 5,
      "name": "Rock_Shale"
    },
    {
      "x": -11,
      "y": -13,
      "z": 5,
      "name": "Rock_Shale"
    },
    {
      "x": -11,
      "y": -12,
      "z": 5,
      "name": "Rock_Shale"
    },
    {
      "x": -11,
      "y": -11,
      "z": 5,
      "name": "Rock_Shale"
    },
    {
      "x": -11,
      "y": -10,
      "z": 5,
      "name": "Rock_Shale"
    },
    {
      "x": -11,
      "y": -9,
      "z": 5,
      "name": "Rock_Shale"
    },
    {
      "x": -11,
      "y": -8,
      "z": 5,
      "name": "Rock_Shale"
    },
    {
      "x": -11,
      "y": -7,
      "z": 5,
      "name": "Rock_Shale"
    },
    {
      "x": -11,
      "y": -6,
      "z": 5,
      "name": "Rock_Shale"
    },
    {
      "x": -11,
      "y": -5,
      "z": 5,
      "name": "Rock_Shale"
    },
    {
      "x": -11,
      "y": -4,
      "z": 5,
      "name": "Rock_Shale"
    },
    {
      "x": -11,
      "y": -3,
      "z": 5,
      "name": "Rock_Shale"
    },
    {
      "x": -11,
      "y": -2,
      "z": 5,
      "name": "Rock_Shale"
    },
    {
      "x": -11,
      "y": -1,
      "z": 5,
      "name": "Rock_Shale"
    },
    {
      "x": -11,
      "y": 0,
      "z": 5,
      "name": "Rock_Shale"
    },
    {
      "x": -11,
      "y": 1,
      "z": 5,
      "name": "Rock_Shale"
    },
    {
      "x": -11,
      "y": 2,
      "z": 5,
      "name": "Rock_Shale"
    },
    {
      "x": -11,
      "y": 3,
      "z": 5,
      "name": "Plant_Roots_Rug_Tainted",
      "support": 15
    },
    {
      "x": -11,
      "y": -13,
      "z": 6,
      "name": "Rock_Shale"
    },
    {
      "x": -11,
      "y": -12,
      "z": 6,
      "name": "Rock_Shale"
    },
    {
      "x": -11,
      "y": -11,
      "z": 6,
      "name": "Rock_Shale"
    },
    {
      "x": -11,
      "y": -10,
      "z": 6,
      "name": "Rock_Shale"
    },
    {
      "x": -11,
      "y": -9,
      "z": 6,
      "name": "Rock_Shale"
    },
    {
      "x": -11,
      "y": -8,
      "z": 6,
      "name": "Rock_Shale"
    },
    {
      "x": -11,
      "y": -7,
      "z": 6,
      "name": "Rock_Shale"
    },
    {
      "x": -11,
      "y": -6,
      "z": 6,
      "name": "Rock_Shale"
    },
    {
      "x": -11,
      "y": -5,
      "z": 6,
      "name": "Rock_Shale"
    },
    {
      "x": -11,
      "y": -4,
      "z": 6,
      "name": "Rock_Shale"
    },
    {
      "x": -11,
      "y": -3,
      "z": 6,
      "name": "Rock_Shale"
    },
    {
      "x": -11,
      "y": -2,
      "z": 6,
      "name": "Rock_Shale"
    },
    {
      "x": -11,
      "y": -1,
      "z": 6,
      "name": "Rock_Shale"
    },
    {
      "x": -11,
      "y": 0,
      "z": 6,
      "name": "Rock_Shale"
    },
    {
      "x": -11,
      "y": 1,
      "z": 6,
      "name": "Rock_Shale"
    },
    {
      "x": -11,
      "y": 2,
      "z": 6,
      "name": "Wood_Giantwood_Trunk_Tainted_Full"
    },
    {
      "x": -11,
      "y": 3,
      "z": 6,
      "name": "Plant_Mushroom_Rug_White_Mycelium",
      "support": 15
    },
    {
      "x": -11,
      "y": -14,
      "z": 7,
      "name": "Rock_Shale"
    },
    {
      "x": -11,
      "y": -13,
      "z": 7,
      "name": "Rock_Shale"
    },
    {
      "x": -11,
      "y": -12,
      "z": 7,
      "name": "Rock_Shale"
    },
    {
      "x": -11,
      "y": -11,
      "z": 7,
      "name": "Rock_Shale"
    },
    {
      "x": -11,
      "y": -10,
      "z": 7,
      "name": "Rock_Shale"
    },
    {
      "x": -11,
      "y": -9,
      "z": 7,
      "name": "Rock_Shale"
    },
    {
      "x": -11,
      "y": -8,
      "z": 7,
      "name": "Rock_Shale"
    },
    {
      "x": -11,
      "y": -7,
      "z": 7,
      "name": "Rock_Shale"
    },
    {
      "x": -11,
      "y": -6,
      "z": 7,
      "name": "Rock_Shale"
    },
    {
      "x": -11,
      "y": -5,
      "z": 7,
      "name": "Rock_Shale"
    },
    {
      "x": -11,
      "y": -4,
      "z": 7,
      "name": "Rock_Shale"
    },
    {
      "x": -11,
      "y": -3,
      "z": 7,
      "name": "Rock_Shale"
    },
    {
      "x": -11,
      "y": -2,
      "z": 7,
      "name": "Rock_Shale"
    },
    {
      "x": -11,
      "y": -1,
      "z": 7,
      "name": "Rock_Shale"
    },
    {
      "x": -11,
      "y": 0,
      "z": 7,
      "name": "Rock_Shale"
    },
    {
      "x": -11,
      "y": 1,
      "z": 7,
      "name": "Wood_Giantwood_Trunk_Tainted_Full"
    },
    {
      "x": -11,
      "y": 2,
      "z": 7,
      "name": "Wood_Giantwood_Trunk_Tainted_Full"
    },
    {
      "x": -11,
      "y": 3,
      "z": 7,
      "name": "Plant_Roots_Rug_Tainted",
      "support": 15
    },
    {
      "x": -11,
      "y": -15,
      "z": 8,
      "name": "Rock_Shale"
    },
    {
      "x": -11,
      "y": -14,
      "z": 8,
      "name": "Rock_Shale"
    },
    {
      "x": -11,
      "y": -13,
      "z": 8,
      "name": "Rock_Shale"
    },
    {
      "x": -11,
      "y": -12,
      "z": 8,
      "name": "Rock_Shale"
    },
    {
      "x": -11,
      "y": -11,
      "z": 8,
      "name": "Rock_Shale"
    },
    {
      "x": -11,
      "y": -10,
      "z": 8,
      "name": "Rock_Shale"
    },
    {
      "x": -11,
      "y": -9,
      "z": 8,
      "name": "Rock_Shale"
    },
    {
      "x": -11,
      "y": -8,
      "z": 8,
      "name": "Rock_Shale"
    },
    {
      "x": -11,
      "y": -7,
      "z": 8,
      "name": "Rock_Shale"
    },
    {
      "x": -11,
      "y": -6,
      "z": 8,
      "name": "Rock_Shale"
    },
    {
      "x": -11,
      "y": -5,
      "z": 8,
      "name": "Rock_Shale"
    },
    {
      "x": -11,
      "y": -4,
      "z": 8,
      "name": "Rock_Shale"
    },
    {
      "x": -11,
      "y": -3,
      "z": 8,
      "name": "Rock_Shale"
    },
    {
      "x": -11,
      "y": -2,
      "z": 8,
      "name": "Rock_Shale"
    },
    {
      "x": -11,
      "y": -1,
      "z": 8,
      "name": "Rock_Shale"
    },
    {
      "x": -11,
      "y": 0,
      "z": 8,
      "name": "Rock_Shale"
    },
    {
      "x": -11,
      "y": 1,
      "z": 8,
      "name": "Wood_Giantwood_Trunk_Tainted_Full"
    },
    {
      "x": -11,
      "y": 2,
      "z": 8,
      "name": "Wood_Giantwood_Trunk_Tainted_Full"
    },
    {
      "x": -11,
      "y": 3,
      "z": 8,
      "name": "Plant_Mushroom_Rug_White_Mycelium",
      "support": 15
    },
    {
      "x": -11,
      "y": -15,
      "z": 9,
      "name": "Rock_Shale"
    },
    {
      "x": -11,
      "y": -14,
      "z": 9,
      "name": "Rock_Shale"
    },
    {
      "x": -11,
      "y": -13,
      "z": 9,
      "name": "Rock_Shale"
    },
    {
      "x": -11,
      "y": -12,
      "z": 9,
      "name": "Rock_Shale"
    },
    {
      "x": -11,
      "y": -11,
      "z": 9,
      "name": "Rock_Shale"
    },
    {
      "x": -11,
      "y": -10,
      "z": 9,
      "name": "Rock_Shale"
    },
    {
      "x": -11,
      "y": -9,
      "z": 9,
      "name": "Rock_Shale"
    },
    {
      "x": -11,
      "y": -8,
      "z": 9,
      "name": "Rock_Shale"
    },
    {
      "x": -11,
      "y": -7,
      "z": 9,
      "name": "Rock_Shale"
    },
    {
      "x": -11,
      "y": -6,
      "z": 9,
      "name": "Rock_Shale"
    },
    {
      "x": -11,
      "y": -5,
      "z": 9,
      "name": "Rock_Shale"
    },
    {
      "x": -11,
      "y": -4,
      "z": 9,
      "name": "Rock_Shale"
    },
    {
      "x": -11,
      "y": -3,
      "z": 9,
      "name": "Rock_Shale"
    },
    {
      "x": -11,
      "y": -2,
      "z": 9,
      "name": "Rock_Shale"
    },
    {
      "x": -11,
      "y": -1,
      "z": 9,
      "name": "Rock_Shale"
    },
    {
      "x": -11,
      "y": 0,
      "z": 9,
      "name": "Rock_Shale"
    },
    {
      "x": -11,
      "y": 1,
      "z": 9,
      "name": "Wood_Giantwood_Trunk_Tainted_Full"
    },
    {
      "x": -11,
      "y": 2,
      "z": 9,
      "name": "Plant_Mushroom_Rug_White_Mycelium",
      "support": 15
    },
    {
      "x": -11,
      "y": -14,
      "z": 10,
      "name": "Rock_Shale"
    },
    {
      "x": -11,
      "y": -13,
      "z": 10,
      "name": "Rock_Shale"
    },
    {
      "x": -11,
      "y": -12,
      "z": 10,
      "name": "Rock_Shale"
    },
    {
      "x": -11,
      "y": -11,
      "z": 10,
      "name": "Rock_Shale"
    },
    {
      "x": -11,
      "y": -10,
      "z": 10,
      "name": "Rock_Shale"
    },
    {
      "x": -11,
      "y": -9,
      "z": 10,
      "name": "Rock_Shale"
    },
    {
      "x": -11,
      "y": -8,
      "z": 10,
      "name": "Rock_Shale"
    },
    {
      "x": -11,
      "y": -7,
      "z": 10,
      "name": "Rock_Shale"
    },
    {
      "x": -11,
      "y": -6,
      "z": 10,
      "name": "Rock_Shale"
    },
    {
      "x": -11,
      "y": -5,
      "z": 10,
      "name": "Rock_Shale"
    },
    {
      "x": -11,
      "y": -4,
      "z": 10,
      "name": "Rock_Shale"
    },
    {
      "x": -11,
      "y": -3,
      "z": 10,
      "name": "Rock_Shale"
    },
    {
      "x": -11,
      "y": -2,
      "z": 10,
      "name": "Rock_Shale"
    },
    {
      "x": -11,
      "y": -13,
      "z": 11,
      "name": "Rock_Shale"
    },
    {
      "x": -11,
      "y": -12,
      "z": 11,
      "name": "Rock_Shale"
    },
    {
      "x": -11,
      "y": -11,
      "z": 11,
      "name": "Rock_Shale"
    },
    {
      "x": -11,
      "y": -10,
      "z": 11,
      "name": "Rock_Shale"
    },
    {
      "x": -11,
      "y": -9,
      "z": 11,
      "name": "Rock_Shale"
    },
    {
      "x": -11,
      "y": -8,
      "z": 11,
      "name": "Rock_Shale"
    },
    {
      "x": -11,
      "y": -7,
      "z": 11,
      "name": "Rock_Shale"
    },
    {
      "x": -11,
      "y": -6,
      "z": 11,
      "name": "Rock_Shale"
    },
    {
      "x": -10,
      "y": -9,
      "z": -6,
      "name": "Rock_Shale"
    },
    {
      "x": -10,
      "y": -8,
      "z": -6,
      "name": "Rock_Shale"
    },
    {
      "x": -10,
      "y": -7,
      "z": -6,
      "name": "Rock_Shale"
    },
    {
      "x": -10,
      "y": -6,
      "z": -6,
      "name": "Rock_Shale"
    },
    {
      "x": -10,
      "y": -5,
      "z": -6,
      "name": "Rock_Shale"
    },
    {
      "x": -10,
      "y": 42,
      "z": -6,
      "name": "Rock_Shale"
    },
    {
      "x": -10,
      "y": 43,
      "z": -6,
      "name": "Rock_Shale"
    },
    {
      "x": -10,
      "y": -12,
      "z": -5,
      "name": "Rock_Shale"
    },
    {
      "x": -10,
      "y": -11,
      "z": -5,
      "name": "Rock_Shale"
    },
    {
      "x": -10,
      "y": -10,
      "z": -5,
      "name": "Rock_Shale"
    },
    {
      "x": -10,
      "y": -9,
      "z": -5,
      "name": "Rock_Shale"
    },
    {
      "x": -10,
      "y": -8,
      "z": -5,
      "name": "Rock_Shale"
    },
    {
      "x": -10,
      "y": -7,
      "z": -5,
      "name": "Rock_Shale"
    },
    {
      "x": -10,
      "y": -6,
      "z": -5,
      "name": "Rock_Shale"
    },
    {
      "x": -10,
      "y": -5,
      "z": -5,
      "name": "Rock_Shale"
    },
    {
      "x": -10,
      "y": -4,
      "z": -5,
      "name": "Rock_Shale"
    },
    {
      "x": -10,
      "y": -3,
      "z": -5,
      "name": "Rock_Shale"
    },
    {
      "x": -10,
      "y": -2,
      "z": -5,
      "name": "Rock_Shale"
    },
    {
      "x": -10,
      "y": -1,
      "z": -5,
      "name": "Rock_Shale"
    },
    {
      "x": -10,
      "y": 0,
      "z": -5,
      "name": "Rock_Shale"
    },
    {
      "x": -10,
      "y": 41,
      "z": -5,
      "name": "Rock_Shale"
    },
    {
      "x": -10,
      "y": 42,
      "z": -5,
      "name": "Rock_Shale"
    },
    {
      "x": -10,
      "y": 43,
      "z": -5,
      "name": "Rock_Shale"
    },
    {
      "x": -10,
      "y": -13,
      "z": -4,
      "name": "Rock_Shale"
    },
    {
      "x": -10,
      "y": -12,
      "z": -4,
      "name": "Rock_Shale"
    },
    {
      "x": -10,
      "y": -11,
      "z": -4,
      "name": "Rock_Shale"
    },
    {
      "x": -10,
      "y": -10,
      "z": -4,
      "name": "Rock_Shale"
    },
    {
      "x": -10,
      "y": -9,
      "z": -4,
      "name": "Rock_Shale"
    },
    {
      "x": -10,
      "y": -8,
      "z": -4,
      "name": "Rock_Shale"
    },
    {
      "x": -10,
      "y": -7,
      "z": -4,
      "name": "Rock_Shale"
    },
    {
      "x": -10,
      "y": -6,
      "z": -4,
      "name": "Rock_Shale"
    },
    {
      "x": -10,
      "y": -5,
      "z": -4,
      "name": "Rock_Shale"
    },
    {
      "x": -10,
      "y": -4,
      "z": -4,
      "name": "Rock_Shale"
    },
    {
      "x": -10,
      "y": -3,
      "z": -4,
      "name": "Rock_Shale"
    },
    {
      "x": -10,
      "y": -2,
      "z": -4,
      "name": "Rock_Shale"
    },
    {
      "x": -10,
      "y": -1,
      "z": -4,
      "name": "Rock_Shale"
    },
    {
      "x": -10,
      "y": 0,
      "z": -4,
      "name": "Rock_Shale"
    },
    {
      "x": -10,
      "y": 1,
      "z": -4,
      "name": "Rock_Shale"
    },
    {
      "x": -10,
      "y": 2,
      "z": -4,
      "name": "Rock_Shale"
    },
    {
      "x": -10,
      "y": 3,
      "z": -4,
      "name": "Rock_Shale_Stalactites_Small"
    },
    {
      "x": -10,
      "y": 40,
      "z": -4,
      "name": "Rock_Shale"
    },
    {
      "x": -10,
      "y": 41,
      "z": -4,
      "name": "Rock_Shale"
    },
    {
      "x": -10,
      "y": 42,
      "z": -4,
      "name": "Rock_Shale"
    },
    {
      "x": -10,
      "y": 43,
      "z": -4,
      "name": "Rock_Shale"
    },
    {
      "x": -10,
      "y": -15,
      "z": -3,
      "name": "Rock_Shale"
    },
    {
      "x": -10,
      "y": -14,
      "z": -3,
      "name": "Rock_Shale"
    },
    {
      "x": -10,
      "y": -13,
      "z": -3,
      "name": "Rock_Shale"
    },
    {
      "x": -10,
      "y": -12,
      "z": -3,
      "name": "Rock_Shale"
    },
    {
      "x": -10,
      "y": -11,
      "z": -3,
      "name": "Rock_Shale"
    },
    {
      "x": -10,
      "y": -10,
      "z": -3,
      "name": "Rock_Shale"
    },
    {
      "x": -10,
      "y": -9,
      "z": -3,
      "name": "Rock_Shale"
    },
    {
      "x": -10,
      "y": -8,
      "z": -3,
      "name": "Rock_Shale"
    },
    {
      "x": -10,
      "y": -7,
      "z": -3,
      "name": "Rock_Shale"
    },
    {
      "x": -10,
      "y": -6,
      "z": -3,
      "name": "Rock_Shale"
    },
    {
      "x": -10,
      "y": -5,
      "z": -3,
      "name": "Rock_Shale"
    },
    {
      "x": -10,
      "y": -4,
      "z": -3,
      "name": "Rock_Shale"
    },
    {
      "x": -10,
      "y": -3,
      "z": -3,
      "name": "Rock_Shale"
    },
    {
      "x": -10,
      "y": -2,
      "z": -3,
      "name": "Rock_Shale"
    },
    {
      "x": -10,
      "y": -1,
      "z": -3,
      "name": "Rock_Shale"
    },
    {
      "x": -10,
      "y": 0,
      "z": -3,
      "name": "Rock_Shale"
    },
    {
      "x": -10,
      "y": 1,
      "z": -3,
      "name": "Rock_Shale"
    },
    {
      "x": -10,
      "y": 39,
      "z": -3,
      "name": "Rock_Shale"
    },
    {
      "x": -10,
      "y": 40,
      "z": -3,
      "name": "Rock_Shale"
    },
    {
      "x": -10,
      "y": 41,
      "z": -3,
      "name": "Rock_Shale"
    },
    {
      "x": -10,
      "y": 42,
      "z": -3,
      "name": "Rock_Shale"
    },
    {
      "x": -10,
      "y": 43,
      "z": -3,
      "name": "Rock_Shale"
    },
    {
      "x": -10,
      "y": 44,
      "z": -3,
      "name": "Rock_Shale"
    },
    {
      "x": -10,
      "y": -15,
      "z": -2,
      "name": "Rock_Shale"
    },
    {
      "x": -10,
      "y": -14,
      "z": -2,
      "name": "Rock_Shale"
    },
    {
      "x": -10,
      "y": -13,
      "z": -2,
      "name": "Rock_Shale"
    },
    {
      "x": -10,
      "y": -12,
      "z": -2,
      "name": "Rock_Shale"
    },
    {
      "x": -10,
      "y": -11,
      "z": -2,
      "name": "Rock_Shale"
    },
    {
      "x": -10,
      "y": -10,
      "z": -2,
      "name": "Rock_Shale"
    },
    {
      "x": -10,
      "y": -9,
      "z": -2,
      "name": "Rock_Shale"
    },
    {
      "x": -10,
      "y": -8,
      "z": -2,
      "name": "Rock_Shale"
    },
    {
      "x": -10,
      "y": -7,
      "z": -2,
      "name": "Rock_Shale"
    },
    {
      "x": -10,
      "y": -6,
      "z": -2,
      "name": "Rock_Shale"
    },
    {
      "x": -10,
      "y": -5,
      "z": -2,
      "name": "Rock_Shale"
    },
    {
      "x": -10,
      "y": -4,
      "z": -2,
      "name": "Rock_Shale"
    },
    {
      "x": -10,
      "y": -3,
      "z": -2,
      "name": "Rock_Shale"
    },
    {
      "x": -10,
      "y": -2,
      "z": -2,
      "name": "Rock_Shale"
    },
    {
      "x": -10,
      "y": -1,
      "z": -2,
      "name": "Rock_Shale"
    },
    {
      "x": -10,
      "y": 0,
      "z": -2,
      "name": "Rock_Shale"
    },
    {
      "x": -10,
      "y": 1,
      "z": -2,
      "name": "Rock_Shale"
    },
    {
      "x": -10,
      "y": 2,
      "z": -2,
      "name": "Rock_Shale"
    },
    {
      "x": -10,
      "y": 38,
      "z": -2,
      "name": "Rock_Shale"
    },
    {
      "x": -10,
      "y": 39,
      "z": -2,
      "name": "Rock_Shale"
    },
    {
      "x": -10,
      "y": 40,
      "z": -2,
      "name": "Rock_Shale"
    },
    {
      "x": -10,
      "y": 41,
      "z": -2,
      "name": "Rock_Shale"
    },
    {
      "x": -10,
      "y": 42,
      "z": -2,
      "name": "Rock_Shale"
    },
    {
      "x": -10,
      "y": 43,
      "z": -2,
      "name": "Rock_Shale"
    },
    {
      "x": -10,
      "y": 44,
      "z": -2,
      "name": "Rock_Shale"
    },
    {
      "x": -10,
      "y": -15,
      "z": -1,
      "name": "Rock_Shale"
    },
    {
      "x": -10,
      "y": -14,
      "z": -1,
      "name": "Rock_Shale"
    },
    {
      "x": -10,
      "y": -13,
      "z": -1,
      "name": "Rock_Shale"
    },
    {
      "x": -10,
      "y": -12,
      "z": -1,
      "name": "Rock_Shale"
    },
    {
      "x": -10,
      "y": -11,
      "z": -1,
      "name": "Rock_Shale"
    },
    {
      "x": -10,
      "y": -10,
      "z": -1,
      "name": "Rock_Shale"
    },
    {
      "x": -10,
      "y": -9,
      "z": -1,
      "name": "Rock_Shale"
    },
    {
      "x": -10,
      "y": -8,
      "z": -1,
      "name": "Rock_Shale"
    },
    {
      "x": -10,
      "y": -7,
      "z": -1,
      "name": "Rock_Shale"
    },
    {
      "x": -10,
      "y": -6,
      "z": -1,
      "name": "Rock_Shale"
    },
    {
      "x": -10,
      "y": -5,
      "z": -1,
      "name": "Rock_Shale"
    },
    {
      "x": -10,
      "y": -4,
      "z": -1,
      "name": "Rock_Shale"
    },
    {
      "x": -10,
      "y": -3,
      "z": -1,
      "name": "Rock_Shale"
    },
    {
      "x": -10,
      "y": -2,
      "z": -1,
      "name": "Rock_Shale"
    },
    {
      "x": -10,
      "y": -1,
      "z": -1,
      "name": "Rock_Shale"
    },
    {
      "x": -10,
      "y": 0,
      "z": -1,
      "name": "Rock_Shale"
    },
    {
      "x": -10,
      "y": 1,
      "z": -1,
      "name": "Rock_Shale"
    },
    {
      "x": -10,
      "y": 2,
      "z": -1,
      "name": "Rock_Shale"
    },
    {
      "x": -10,
      "y": 3,
      "z": -1,
      "name": "Rock_Shale"
    },
    {
      "x": -10,
      "y": 36,
      "z": -1,
      "name": "Rock_Shale"
    },
    {
      "x": -10,
      "y": 37,
      "z": -1,
      "name": "Rock_Shale"
    },
    {
      "x": -10,
      "y": 38,
      "z": -1,
      "name": "Rock_Shale"
    },
    {
      "x": -10,
      "y": 39,
      "z": -1,
      "name": "Rock_Shale"
    },
    {
      "x": -10,
      "y": 40,
      "z": -1,
      "name": "Rock_Shale"
    },
    {
      "x": -10,
      "y": 41,
      "z": -1,
      "name": "Rock_Shale"
    },
    {
      "x": -10,
      "y": 42,
      "z": -1,
      "name": "Rock_Shale"
    },
    {
      "x": -10,
      "y": 43,
      "z": -1,
      "name": "Rock_Shale"
    },
    {
      "x": -10,
      "y": 44,
      "z": -1,
      "name": "Rock_Shale"
    },
    {
      "x": -10,
      "y": -15,
      "z": 0,
      "name": "Rock_Shale"
    },
    {
      "x": -10,
      "y": -14,
      "z": 0,
      "name": "Rock_Shale"
    },
    {
      "x": -10,
      "y": -13,
      "z": 0,
      "name": "Rock_Shale"
    },
    {
      "x": -10,
      "y": -12,
      "z": 0,
      "name": "Rock_Shale"
    },
    {
      "x": -10,
      "y": -11,
      "z": 0,
      "name": "Rock_Shale"
    },
    {
      "x": -10,
      "y": -10,
      "z": 0,
      "name": "Rock_Shale"
    },
    {
      "x": -10,
      "y": -9,
      "z": 0,
      "name": "Rock_Shale"
    },
    {
      "x": -10,
      "y": -8,
      "z": 0,
      "name": "Rock_Shale"
    },
    {
      "x": -10,
      "y": -7,
      "z": 0,
      "name": "Rock_Shale"
    },
    {
      "x": -10,
      "y": -6,
      "z": 0,
      "name": "Rock_Shale"
    },
    {
      "x": -10,
      "y": -5,
      "z": 0,
      "name": "Rock_Shale"
    },
    {
      "x": -10,
      "y": -4,
      "z": 0,
      "name": "Rock_Shale"
    },
    {
      "x": -10,
      "y": -3,
      "z": 0,
      "name": "Rock_Shale"
    },
    {
      "x": -10,
      "y": -2,
      "z": 0,
      "name": "Rock_Shale"
    },
    {
      "x": -10,
      "y": -1,
      "z": 0,
      "name": "Rock_Shale"
    },
    {
      "x": -10,
      "y": 0,
      "z": 0,
      "name": "Rock_Shale"
    },
    {
      "x": -10,
      "y": 1,
      "z": 0,
      "name": "Rock_Shale"
    },
    {
      "x": -10,
      "y": 2,
      "z": 0,
      "name": "Rock_Shale"
    },
    {
      "x": -10,
      "y": 3,
      "z": 0,
      "name": "Rock_Shale"
    },
    {
      "x": -10,
      "y": 4,
      "z": 0,
      "name": "Rock_Shale"
    },
    {
      "x": -10,
      "y": 5,
      "z": 0,
      "name": "Rock_Shale_Stalactites_Large"
    },
    {
      "x": -10,
      "y": 6,
      "z": 0,
      "name": "Rock_Shale_Stalactites_Large",
      "filler": 1024
    },
    {
      "x": -10,
      "y": 32,
      "z": 0,
      "name": "Rock_Shale_Stalactites_Large",
      "filler": 31744,
      "rotation": 8
    },
    {
      "x": -10,
      "y": 33,
      "z": 0,
      "name": "Rock_Shale_Stalactites_Large",
      "rotation": 8
    },
    {
      "x": -10,
      "y": 34,
      "z": 0,
      "name": "Rock_Shale"
    },
    {
      "x": -10,
      "y": 35,
      "z": 0,
      "name": "Rock_Shale"
    },
    {
      "x": -10,
      "y": 36,
      "z": 0,
      "name": "Rock_Shale"
    },
    {
      "x": -10,
      "y": 37,
      "z": 0,
      "name": "Rock_Shale"
    },
    {
      "x": -10,
      "y": 38,
      "z": 0,
      "name": "Rock_Shale"
    },
    {
      "x": -10,
      "y": 39,
      "z": 0,
      "name": "Rock_Shale"
    },
    {
      "x": -10,
      "y": 40,
      "z": 0,
      "name": "Rock_Shale"
    },
    {
      "x": -10,
      "y": 41,
      "z": 0,
      "name": "Rock_Shale"
    },
    {
      "x": -10,
      "y": 42,
      "z": 0,
      "name": "Rock_Shale"
    },
    {
      "x": -10,
      "y": 43,
      "z": 0,
      "name": "Rock_Shale"
    },
    {
      "x": -10,
      "y": 44,
      "z": 0,
      "name": "Rock_Shale"
    },
    {
      "x": -10,
      "y": -15,
      "z": 1,
      "name": "Rock_Shale"
    },
    {
      "x": -10,
      "y": -14,
      "z": 1,
      "name": "Rock_Shale"
    },
    {
      "x": -10,
      "y": -13,
      "z": 1,
      "name": "Rock_Shale"
    },
    {
      "x": -10,
      "y": -12,
      "z": 1,
      "name": "Rock_Shale"
    },
    {
      "x": -10,
      "y": -11,
      "z": 1,
      "name": "Rock_Shale"
    },
    {
      "x": -10,
      "y": -10,
      "z": 1,
      "name": "Rock_Shale"
    },
    {
      "x": -10,
      "y": -9,
      "z": 1,
      "name": "Rock_Shale"
    },
    {
      "x": -10,
      "y": -8,
      "z": 1,
      "name": "Rock_Shale"
    },
    {
      "x": -10,
      "y": -7,
      "z": 1,
      "name": "Rock_Shale"
    },
    {
      "x": -10,
      "y": -6,
      "z": 1,
      "name": "Rock_Shale"
    },
    {
      "x": -10,
      "y": -5,
      "z": 1,
      "name": "Rock_Shale"
    },
    {
      "x": -10,
      "y": -4,
      "z": 1,
      "name": "Rock_Shale"
    },
    {
      "x": -10,
      "y": -3,
      "z": 1,
      "name": "Rock_Shale"
    },
    {
      "x": -10,
      "y": -2,
      "z": 1,
      "name": "Rock_Shale"
    },
    {
      "x": -10,
      "y": -1,
      "z": 1,
      "name": "Rock_Shale"
    },
    {
      "x": -10,
      "y": 0,
      "z": 1,
      "name": "Rock_Shale"
    },
    {
      "x": -10,
      "y": 1,
      "z": 1,
      "name": "Rock_Shale"
    },
    {
      "x": -10,
      "y": 2,
      "z": 1,
      "name": "Rock_Shale"
    },
    {
      "x": -10,
      "y": 3,
      "z": 1,
      "name": "Plant_Mushroom_Block_White_Mycelium",
      "support": 15
    },
    {
      "x": -10,
      "y": 4,
      "z": 1,
      "name": "Plant_Roots_Rug_Tainted",
      "support": 15
    },
    {
      "x": -10,
      "y": 36,
      "z": 1,
      "name": "Rock_Shale"
    },
    {
      "x": -10,
      "y": 37,
      "z": 1,
      "name": "Rock_Shale"
    },
    {
      "x": -10,
      "y": 38,
      "z": 1,
      "name": "Rock_Shale"
    },
    {
      "x": -10,
      "y": 39,
      "z": 1,
      "name": "Rock_Shale"
    },
    {
      "x": -10,
      "y": 40,
      "z": 1,
      "name": "Rock_Shale"
    },
    {
      "x": -10,
      "y": 41,
      "z": 1,
      "name": "Rock_Shale"
    },
    {
      "x": -10,
      "y": 42,
      "z": 1,
      "name": "Rock_Shale"
    },
    {
      "x": -10,
      "y": 43,
      "z": 1,
      "name": "Rock_Shale"
    },
    {
      "x": -10,
      "y": 44,
      "z": 1,
      "name": "Rock_Shale"
    },
    {
      "x": -10,
      "y": -15,
      "z": 2,
      "name": "Rock_Shale"
    },
    {
      "x": -10,
      "y": -14,
      "z": 2,
      "name": "Rock_Shale"
    },
    {
      "x": -10,
      "y": -13,
      "z": 2,
      "name": "Rock_Shale"
    },
    {
      "x": -10,
      "y": -12,
      "z": 2,
      "name": "Rock_Shale"
    },
    {
      "x": -10,
      "y": -11,
      "z": 2,
      "name": "Rock_Shale"
    },
    {
      "x": -10,
      "y": -10,
      "z": 2,
      "name": "Rock_Shale"
    },
    {
      "x": -10,
      "y": -9,
      "z": 2,
      "name": "Rock_Shale"
    },
    {
      "x": -10,
      "y": -8,
      "z": 2,
      "name": "Rock_Shale"
    },
    {
      "x": -10,
      "y": -7,
      "z": 2,
      "name": "Rock_Shale"
    },
    {
      "x": -10,
      "y": -6,
      "z": 2,
      "name": "Rock_Shale"
    },
    {
      "x": -10,
      "y": -5,
      "z": 2,
      "name": "Rock_Shale"
    },
    {
      "x": -10,
      "y": -4,
      "z": 2,
      "name": "Rock_Shale"
    },
    {
      "x": -10,
      "y": -3,
      "z": 2,
      "name": "Rock_Shale"
    },
    {
      "x": -10,
      "y": -2,
      "z": 2,
      "name": "Rock_Shale"
    },
    {
      "x": -10,
      "y": -1,
      "z": 2,
      "name": "Rock_Shale"
    },
    {
      "x": -10,
      "y": 0,
      "z": 2,
      "name": "Rock_Shale"
    },
    {
      "x": -10,
      "y": 1,
      "z": 2,
      "name": "Rock_Shale"
    },
    {
      "x": -10,
      "y": 2,
      "z": 2,
      "name": "Rock_Shale"
    },
    {
      "x": -10,
      "y": 3,
      "z": 2,
      "name": "Plant_Mushroom_Block_White_Mycelium",
      "support": 15
    },
    {
      "x": -10,
      "y": 4,
      "z": 2,
      "name": "Plant_Roots_Rug_Tainted",
      "support": 15
    },
    {
      "x": -10,
      "y": 39,
      "z": 2,
      "name": "Rock_Shale"
    },
    {
      "x": -10,
      "y": 40,
      "z": 2,
      "name": "Rock_Shale"
    },
    {
      "x": -10,
      "y": 41,
      "z": 2,
      "name": "Rock_Shale"
    },
    {
      "x": -10,
      "y": 42,
      "z": 2,
      "name": "Rock_Shale"
    },
    {
      "x": -10,
      "y": 43,
      "z": 2,
      "name": "Rock_Shale"
    },
    {
      "x": -10,
      "y": -15,
      "z": 3,
      "name": "Rock_Shale"
    },
    {
      "x": -10,
      "y": -14,
      "z": 3,
      "name": "Rock_Shale"
    },
    {
      "x": -10,
      "y": -13,
      "z": 3,
      "name": "Rock_Shale"
    },
    {
      "x": -10,
      "y": -12,
      "z": 3,
      "name": "Rock_Shale"
    },
    {
      "x": -10,
      "y": -11,
      "z": 3,
      "name": "Rock_Shale"
    },
    {
      "x": -10,
      "y": -10,
      "z": 3,
      "name": "Rock_Shale"
    },
    {
      "x": -10,
      "y": -9,
      "z": 3,
      "name": "Rock_Shale"
    },
    {
      "x": -10,
      "y": -8,
      "z": 3,
      "name": "Rock_Shale"
    },
    {
      "x": -10,
      "y": -7,
      "z": 3,
      "name": "Rock_Shale"
    },
    {
      "x": -10,
      "y": -6,
      "z": 3,
      "name": "Rock_Shale"
    },
    {
      "x": -10,
      "y": -5,
      "z": 3,
      "name": "Rock_Shale"
    },
    {
      "x": -10,
      "y": -4,
      "z": 3,
      "name": "Rock_Shale"
    },
    {
      "x": -10,
      "y": -3,
      "z": 3,
      "name": "Rock_Shale"
    },
    {
      "x": -10,
      "y": -2,
      "z": 3,
      "name": "Rock_Shale"
    },
    {
      "x": -10,
      "y": -1,
      "z": 3,
      "name": "Rock_Shale"
    },
    {
      "x": -10,
      "y": 0,
      "z": 3,
      "name": "Rock_Shale"
    },
    {
      "x": -10,
      "y": 1,
      "z": 3,
      "name": "Rock_Shale"
    },
    {
      "x": -10,
      "y": 2,
      "z": 3,
      "name": "Rock_Shale"
    },
    {
      "x": -10,
      "y": 3,
      "z": 3,
      "name": "Rock_Shale"
    },
    {
      "x": -10,
      "y": 4,
      "z": 3,
      "name": "Plant_Mushroom_Rug_White_Mycelium",
      "support": 15
    },
    {
      "x": -10,
      "y": 40,
      "z": 3,
      "name": "Rock_Shale"
    },
    {
      "x": -10,
      "y": 41,
      "z": 3,
      "name": "Rock_Shale"
    },
    {
      "x": -10,
      "y": 42,
      "z": 3,
      "name": "Rock_Shale"
    },
    {
      "x": -10,
      "y": 43,
      "z": 3,
      "name": "Rock_Shale"
    },
    {
      "x": -10,
      "y": -15,
      "z": 4,
      "name": "Rock_Shale"
    },
    {
      "x": -10,
      "y": -14,
      "z": 4,
      "name": "Rock_Shale"
    },
    {
      "x": -10,
      "y": -13,
      "z": 4,
      "name": "Rock_Shale"
    },
    {
      "x": -10,
      "y": -12,
      "z": 4,
      "name": "Rock_Shale"
    },
    {
      "x": -10,
      "y": -11,
      "z": 4,
      "name": "Rock_Shale"
    },
    {
      "x": -10,
      "y": -10,
      "z": 4,
      "name": "Rock_Shale"
    },
    {
      "x": -10,
      "y": -9,
      "z": 4,
      "name": "Rock_Shale"
    },
    {
      "x": -10,
      "y": -8,
      "z": 4,
      "name": "Rock_Shale"
    },
    {
      "x": -10,
      "y": -7,
      "z": 4,
      "name": "Rock_Shale"
    },
    {
      "x": -10,
      "y": -6,
      "z": 4,
      "name": "Rock_Shale"
    },
    {
      "x": -10,
      "y": -5,
      "z": 4,
      "name": "Rock_Shale"
    },
    {
      "x": -10,
      "y": -4,
      "z": 4,
      "name": "Rock_Shale"
    },
    {
      "x": -10,
      "y": -3,
      "z": 4,
      "name": "Rock_Shale"
    },
    {
      "x": -10,
      "y": -2,
      "z": 4,
      "name": "Rock_Shale"
    },
    {
      "x": -10,
      "y": -1,
      "z": 4,
      "name": "Rock_Shale"
    },
    {
      "x": -10,
      "y": 0,
      "z": 4,
      "name": "Rock_Shale"
    },
    {
      "x": -10,
      "y": 1,
      "z": 4,
      "name": "Rock_Shale"
    },
    {
      "x": -10,
      "y": 2,
      "z": 4,
      "name": "Rock_Shale"
    },
    {
      "x": -10,
      "y": 3,
      "z": 4,
      "name": "Plant_Mushroom_Rug_White_Mycelium",
      "support": 15
    },
    {
      "x": -10,
      "y": -15,
      "z": 5,
      "name": "Rock_Shale"
    },
    {
      "x": -10,
      "y": -14,
      "z": 5,
      "name": "Rock_Shale"
    },
    {
      "x": -10,
      "y": -13,
      "z": 5,
      "name": "Rock_Shale"
    },
    {
      "x": -10,
      "y": -12,
      "z": 5,
      "name": "Rock_Shale"
    },
    {
      "x": -10,
      "y": -11,
      "z": 5,
      "name": "Rock_Shale"
    },
    {
      "x": -10,
      "y": -10,
      "z": 5,
      "name": "Rock_Shale"
    },
    {
      "x": -10,
      "y": -9,
      "z": 5,
      "name": "Rock_Shale"
    },
    {
      "x": -10,
      "y": -8,
      "z": 5,
      "name": "Rock_Shale"
    },
    {
      "x": -10,
      "y": -7,
      "z": 5,
      "name": "Rock_Shale"
    },
    {
      "x": -10,
      "y": -6,
      "z": 5,
      "name": "Rock_Shale"
    },
    {
      "x": -10,
      "y": -5,
      "z": 5,
      "name": "Rock_Shale"
    },
    {
      "x": -10,
      "y": -4,
      "z": 5,
      "name": "Rock_Shale"
    },
    {
      "x": -10,
      "y": -3,
      "z": 5,
      "name": "Rock_Shale"
    },
    {
      "x": -10,
      "y": -2,
      "z": 5,
      "name": "Rock_Shale"
    },
    {
      "x": -10,
      "y": -1,
      "z": 5,
      "name": "Rock_Shale"
    },
    {
      "x": -10,
      "y": 0,
      "z": 5,
      "name": "Rock_Shale"
    },
    {
      "x": -10,
      "y": 1,
      "z": 5,
      "name": "Rock_Shale"
    },
    {
      "x": -10,
      "y": 2,
      "z": 5,
      "name": "Rock_Shale"
    },
    {
      "x": -10,
      "y": 3,
      "z": 5,
      "name": "Wood_Giantwood_Trunk_Tainted_Full"
    },
    {
      "x": -10,
      "y": 4,
      "z": 5,
      "name": "Plant_Mushroom_Rug_White_Mycelium",
      "support": 15
    },
    {
      "x": -10,
      "y": -15,
      "z": 6,
      "name": "Rock_Shale"
    },
    {
      "x": -10,
      "y": -14,
      "z": 6,
      "name": "Rock_Shale"
    },
    {
      "x": -10,
      "y": -13,
      "z": 6,
      "name": "Rock_Shale"
    },
    {
      "x": -10,
      "y": -12,
      "z": 6,
      "name": "Rock_Shale"
    },
    {
      "x": -10,
      "y": -11,
      "z": 6,
      "name": "Rock_Shale"
    },
    {
      "x": -10,
      "y": -10,
      "z": 6,
      "name": "Rock_Shale"
    },
    {
      "x": -10,
      "y": -9,
      "z": 6,
      "name": "Rock_Shale"
    },
    {
      "x": -10,
      "y": -8,
      "z": 6,
      "name": "Rock_Shale"
    },
    {
      "x": -10,
      "y": -7,
      "z": 6,
      "name": "Rock_Shale"
    },
    {
      "x": -10,
      "y": -6,
      "z": 6,
      "name": "Rock_Shale"
    },
    {
      "x": -10,
      "y": -5,
      "z": 6,
      "name": "Rock_Shale"
    },
    {
      "x": -10,
      "y": -4,
      "z": 6,
      "name": "Rock_Shale"
    },
    {
      "x": -10,
      "y": -3,
      "z": 6,
      "name": "Rock_Shale"
    },
    {
      "x": -10,
      "y": -2,
      "z": 6,
      "name": "Rock_Shale"
    },
    {
      "x": -10,
      "y": -1,
      "z": 6,
      "name": "Rock_Shale"
    },
    {
      "x": -10,
      "y": 0,
      "z": 6,
      "name": "Rock_Shale"
    },
    {
      "x": -10,
      "y": 1,
      "z": 6,
      "name": "Rock_Shale"
    },
    {
      "x": -10,
      "y": 2,
      "z": 6,
      "name": "Rock_Shale"
    },
    {
      "x": -10,
      "y": 3,
      "z": 6,
      "name": "Wood_Giantwood_Trunk_Tainted_Full"
    },
    {
      "x": -10,
      "y": 4,
      "z": 6,
      "name": "Plant_Mushroom_Rug_White_Mycelium",
      "support": 15
    },
    {
      "x": -10,
      "y": -15,
      "z": 7,
      "name": "Rock_Shale"
    },
    {
      "x": -10,
      "y": -14,
      "z": 7,
      "name": "Rock_Shale"
    },
    {
