{
  "version": 8,
  "blockIdVersion": 11,
  "anchorX": 0,
  "anchorY": 0,
  "anchorZ": 0,
  "blocks": [
    {
      "x": -2,
      "y": 3,
      "z": 0,
      "name": "Plant_Crop_Mushroom_Block_Tainted_Glow"
    },
    {
      "x": -2,
      "y": 4,
      "z": 0,
      "name": "Plant_Crop_Mushroom_Block_Tainted_Half",
      "rotation": 7
    },
    {
      "x": -2,
      "y": 3,
      "z": 1,
      "name": "Plant_Crop_Mushroom_Block_Tainted_Glow"
    },
    {
      "x": -2,
      "y": 4,
      "z": 1,
      "name": "Plant_Crop_Mushroom_Block_Tainted_Half",
      "rotation": 7
    },
    {
      "x": -1,
      "y": 3,
      "z": -1,
      "name": "Plant_Crop_Mushroom_Block_Tainted_Glow"
    },
    {
      "x": -1,
      "y": 3,
      "z": 0,
      "name": "Plant_Moss_Tainted_Glow",
      "support": 15,
      "rotation": 8
    },
    {
      "x": -1,
      "y": 4,
      "z": 0,
      "name": "Plant_Crop_Mushroom_Block_Tainted"
    },
    {
      "x": -1,
      "y": 5,
      "z": 0,
      "name": "Plant_Crop_Mushroom_Tainted_Stairs",
      "rotation": 3
    },
    {
      "x": -1,
      "y": 3,
      "z": 1,
      "name": "Plant_Moss_Tainted_Glow",
      "support": 15,
      "rotation": 8
    },
    {
      "x": -1,
      "y": 4,
      "z": 1,
      "name": "Plant_Crop_Mushroom_Block_Tainted"
    },
    {
      "x": -1,
      "y": 5,
      "z": 1,
      "name": "Plant_Crop_Mushroom_Tainted_Stairs",
      "rotation": 3
    },
    {
      "x": -1,
      "y": 3,
      "z": 2,
      "name": "Plant_Crop_Mushroom_Block_Tainted_Glow"
    },
    {
      "x": -1,
      "y": 4,
      "z": 2,
      "name": "Plant_Crop_Mushroom_Block_Tainted_Half"
    },
    {
      "x": 0,
      "y": 3,
      "z": -2,
      "name": "Plant_Crop_Mushroom_Block_Tainted_Glow"
    },
    {
      "x": 0,
      "y": 4,
      "z": -2,
      "name": "Plant_Crop_Mushroom_Block_Tainted_Half",
      "rotation": 6
    },
    {
      "x": 0,
      "y": 3,
      "z": -1,
      "name": "Plant_Moss_Tainted_Glow",
      "support": 15,
      "rotation": 8
    },
    {
      "x": 0,
      "y": 4,
      "z": -1,
      "name": "Plant_Crop_Mushroom_Block_Tainted"
    },
    {
      "x": 0,
      "y": 5,
      "z": -1,
      "name": "Plant_Crop_Mushroom_Tainted_Stairs",
      "rotation": 2
    },
    {
      "x": 0,
      "y": -2,
      "z": 0,
      "name": "Plant_Crop_Mushroom_Block_Purple_Trunk"
    },
    {
      "x": 0,
      "y": -1,
      "z": 0,
      "name": "Plant_Crop_Mushroom_Block_Purple_Trunk"
    },
    {
      "x": 0,
      "y": 0,
      "z": 0,
      "name": "Plant_Crop_Mushroom_Block_Purple_Trunk"
    },
    {
      "x": 0,
      "y": 1,
      "z": 0,
      "name": "Plant_Crop_Mushroom_Block_Purple_Trunk"
    },
    {
      "x": 0,
      "y": 2,
      "z": 0,
      "name": "Plant_Crop_Mushroom_Block_Purple_Trunk"
    },
    {
      "x": 0,
      "y": 3,
      "z": 0,
      "name": "Plant_Crop_Mushroom_Block_Purple_Trunk"
    },
    {
      "x": 0,
      "y": 4,
      "z": 0,
      "name": "Plant_Crop_Mushroom_Block_Tainted"
    },
    {
      "x": 0,
      "y": 5,
      "z": 0,
      "name": "Plant_Crop_Mushroom_Block_Tainted"
    },
    {
      "x": 0,
      "y": 6,
      "z": 0,
      "name": "Plant_Crop_Mushroom_Block_Tainted_Half"
    },
    {
      "x": 0,
      "y": -2,
      "z": 1,
      "name": "Plant_Crop_Mushroom_Block_Purple_Trunk"
    },
    {
      "x": 0,
      "y": -1,
      "z": 1,
      "name": "Plant_Crop_Mushroom_Block_Purple_Trunk"
    },
    {
      "x": 0,
      "y": 0,
      "z": 1,
      "name": "Plant_Crop_Mushroom_Block_Purple_Trunk"
    },
    {
      "x": 0,
      "y": 1,
      "z": 1,
      "name": "Plant_Crop_Mushroom_Block_Purple_Trunk"
    },
    {
      "x": 0,
      "y": 2,
      "z": 1,
      "name": "Plant_Crop_Mushroom_Block_Purple_Trunk"
    },
    {
      "x": 0,
      "y": 3,
      "z": 1,
      "name": "Plant_Crop_Mushroom_Block_Purple_Trunk"
    },
    {
      "x": 0,
      "y": 4,
      "z": 1,
      "name": "Plant_Crop_Mushroom_Block_Tainted"
    },
    {
      "x": 0,
      "y": 5,
      "z": 1,
      "name": "Plant_Crop_Mushroom_Block_Tainted"
    },
    {
      "x": 0,
      "y": 6,
      "z": 1,
      "name": "Plant_Crop_Mushroom_Block_Tainted_Half"
    },
    {
      "x": 0,
      "y": 3,
      "z": 2,
      "name": "Plant_Moss_Tainted_Glow",
      "support": 15,
      "rotation": 8
    },
    {
      "x": 0,
      "y": 4,
      "z": 2,
      "name": "Plant_Crop_Mushroom_Block_Tainted"
    },
    {
      "x": 0,
      "y": 5,
      "z": 2,
      "name": "Plant_Crop_Mushroom_Tainted_Stairs"
    },
    {
      "x": 0,
      "y": 3,
      "z": 3,
      "name": "Plant_Crop_Mushroom_Block_Tainted_Glow"
    },
    {
      "x": 0,
      "y": 4,
      "z": 3,
      "name": "Plant_Crop_Mushroom_Block_Tainted_Half",
      "rotation": 4
    },
    {
      "x": 1,
      "y": 3,
      "z": -2,
      "name": "Plant_Crop_Mushroom_Block_Tainted_Glow"
    },
    {
      "x": 1,
      "y": 4,
      "z": -2,
      "name": "Plant_Crop_Mushroom_Block_Tainted_Half",
      "rotation": 6
    },
    {
      "x": 1,
      "y": 3,
      "z": -1,
      "name": "Plant_Moss_Tainted_Glow",
      "support": 15,
      "rotation": 8
    },
    {
      "x": 1,
      "y": 4,
      "z": -1,
      "name": "Plant_Crop_Mushroom_Block_Tainted"
    },
    {
      "x": 1,
      "y": 5,
      "z": -1,
      "name": "Plant_Crop_Mushroom_Tainted_Stairs",
      "rotation": 2
    },
    {
      "x": 1,
      "y": -1,
      "z": 0,
      "name": "Plant_Crop_Mushroom_Block_Purple_Trunk"
    },
    {
      "x": 1,
      "y": 0,
      "z": 0,
      "name": "Plant_Crop_Mushroom_Block_Purple_Trunk"
    },
    {
      "x": 1,
      "y": 1,
      "z": 0,
      "name": "Plant_Crop_Mushroom_Block_Purple_Trunk"
    },
    {
      "x": 1,
      "y": 2,
      "z": 0,
      "name": "Plant_Crop_Mushroom_Block_Purple_Trunk"
    },
    {
      "x": 1,
      "y": 3,
      "z": 0,
      "name": "Plant_Crop_Mushroom_Block_Purple_Trunk"
    },
    {
      "x": 1,
      "y": 4,
      "z": 0,
      "name": "Plant_Crop_Mushroom_Block_Tainted"
    },
    {
      "x": 1,
      "y": 5,
      "z": 0,
      "name": "Plant_Crop_Mushroom_Block_Tainted"
    },
    {
      "x": 1,
      "y": 6,
      "z": 0,
      "name": "Plant_Crop_Mushroom_Block_Tainted_Half"
    },
    {
      "x": 1,
      "y": -1,
      "z": 1,
      "name": "Plant_Crop_Mushroom_Block_Purple_Trunk"
    },
    {
      "x": 1,
      "y": 0,
      "z": 1,
      "name": "Plant_Crop_Mushroom_Block_Purple_Trunk"
    },
    {
      "x": 1,
      "y": 1,
      "z": 1,
      "name": "Plant_Crop_Mushroom_Block_Purple_Trunk"
    },
    {
      "x": 1,
      "y": 2,
      "z": 1,
      "name": "Plant_Crop_Mushroom_Block_Purple_Trunk"
    },
    {
      "x": 1,
      "y": 3,
      "z": 1,
      "name": "Plant_Crop_Mushroom_Block_Purple_Trunk"
    },
    {
      "x": 1,
      "y": 4,
      "z": 1,
      "name": "Plant_Crop_Mushroom_Block_Tainted"
    },
    {
      "x": 1,
      "y": 5,
      "z": 1,
      "name": "Plant_Crop_Mushroom_Block_Tainted"
    },
    {
      "x": 1,
      "y": 6,
      "z": 1,
      "name": "Plant_Crop_Mushroom_Block_Tainted_Half"
    },
    {
      "x": 1,
      "y": 3,
      "z": 2,
      "name": "Plant_Moss_Tainted_Glow",
      "support": 15,
      "rotation": 8
    },
    {
      "x": 1,
      "y": 4,
      "z": 2,
      "name": "Plant_Crop_Mushroom_Block_Tainted"
    },
    {
      "x": 1,
      "y": 5,
      "z": 2,
      "name": "Plant_Crop_Mushroom_Tainted_Stairs"
    },
    {
      "x": 1,
      "y": 3,
      "z": 3,
      "name": "Plant_Crop_Mushroom_Block_Tainted_Glow"
    },
    {
      "x": 1,
      "y": 4,
      "z": 3,
      "name": "Plant_Crop_Mushroom_Block_Tainted_Half",
      "rotation": 4
    },
    {
      "x": 2,
      "y": 3,
      "z": -1,
      "name": "Plant_Crop_Mushroom_Block_Tainted_Glow"
    },
    {
      "x": 2,
      "y": 4,
      "z": -1,
      "name": "Plant_Crop_Mushroom_Block_Tainted_Half"
    },
    {
      "x": 2,
      "y": 3,
      "z": 0,
      "name": "Plant_Moss_Tainted_Glow",
      "support": 15,
      "rotation": 8
    },
    {
      "x": 2,
      "y": 4,
      "z": 0,
      "name": "Plant_Crop_Mushroom_Block_Tainted"
    },
    {
      "x": 2,
      "y": 5,
      "z": 0,
      "name": "Plant_Crop_Mushroom_Tainted_Stairs",
      "rotation": 1
    },
    {
      "x": 2,
      "y": 3,
      "z": 1,
      "name": "Plant_Moss_Tainted_Glow",
      "support": 15,
      "rotation": 8
    },
    {
      "x": 2,
      "y": 4,
      "z": 1,
      "name": "Plant_Crop_Mushroom_Block_Tainted"
    },
    {
      "x": 2,
      "y": 5,
      "z": 1,
      "name": "Plant_Crop_Mushroom_Tainted_Stairs",
      "rotation": 1
    },
    {
      "x": 2,
      "y": 3,
      "z": 2,
      "name": "Plant_Crop_Mushroom_Block_Tainted_Glow"
    },
    {
      "x": 2,
      "y": 4,
      "z": 2,
      "name": "Plant_Crop_Mushroom_Block_Tainted_Half"
    },
    {
      "x": 3,
      "y": 3,
      "z": 0,
      "name": "Plant_Crop_Mushroom_Block_Tainted_Glow"
    },
    {
      "x": 3,
      "y": 4,
      "z": 0,
      "name": "Plant_Crop_Mushroom_Block_Tainted_Half",
      "rotation": 5
    },
    {
      "x": 3,
      "y": 3,
      "z": 1,
      "name": "Plant_Crop_Mushroom_Block_Tainted_Glow"
    },
    {
      "x": 3,
      "y": 4,
      "z": 1,
      "name": "Plant_Crop_Mushroom_Block_Tainted_Half",
      "rotation": 5
    }
  ]
}