{
  "version": 8,
  "blockIdVersion": 11,
  "anchorX": 0,
  "anchorY": 0,
  "anchorZ": 0,
  "blocks": [
    {
      "x": -3,
      "y": 6,
      "z": -3,
      "name": "Plant_Crop_Mushroom_Block_Red"
    },
    {
      "x": -3,
      "y": 6,
      "z": -2,
      "name": "Plant_Crop_Mushroom_Block_Red"
    },
    {
      "x": -3,
      "y": 6,
      "z": -1,
      "name": "Plant_Crop_Mushroom_Block_Red"
    },
    {
      "x": -3,
      "y": 6,
      "z": 0,
      "name": "Plant_Crop_Mushroom_Block_Red"
    },
    {
      "x": -3,
      "y": 6,
      "z": 1,
      "name": "Plant_Crop_Mushroom_Block_Red"
    },
    {
      "x": -3,
      "y": 6,
      "z": 2,
      "name": "Plant_Crop_Mushroom_Block_Red"
    },
    {
      "x": -2,
      "y": 6,
      "z": -4,
      "name": "Plant_Crop_Mushroom_Block_Red"
    },
    {
      "x": -2,
      "y": 6,
      "z": -3,
      "name": "Plant_Crop_Mushroom_Block_Red"
    },
    {
      "x": -2,
      "y": 7,
      "z": -2,
      "name": "Plant_Crop_Mushroom_Block_Red"
    },
    {
      "x": -2,
      "y": 7,
      "z": -1,
      "name": "Plant_Crop_Mushroom_Block_Red"
    },
    {
      "x": -2,
      "y": 7,
      "z": 0,
      "name": "Plant_Crop_Mushroom_Block_Red"
    },
    {
      "x": -2,
      "y": 7,
      "z": 1,
      "name": "Plant_Crop_Mushroom_Block_Red"
    },
    {
      "x": -2,
      "y": 6,
      "z": 2,
      "name": "Plant_Crop_Mushroom_Block_Red"
    },
    {
      "x": -2,
      "y": 7,
      "z": 2,
      "name": "Plant_Crop_Mushroom_Block_Red"
    },
    {
      "x": -2,
      "y": 6,
      "z": 3,
      "name": "Plant_Crop_Mushroom_Block_Red"
    },
    {
      "x": -2,
      "y": 6,
      "z": 4,
      "name": "Plant_Crop_Mushroom_Block_Red"
    },
    {
      "x": -1,
      "y": 6,
      "z": -4,
      "name": "Plant_Crop_Mushroom_Block_Red"
    },
    {
      "x": -1,
      "y": 7,
      "z": -3,
      "name": "Plant_Crop_Mushroom_Block_Red"
    },
    {
      "x": -1,
      "y": 7,
      "z": -2,
      "name": "Plant_Crop_Mushroom_Block_Red"
    },
    {
      "x": -1,
      "y": 8,
      "z": -2,
      "name": "Plant_Crop_Mushroom_Block_Red"
    },
    {
      "x": -1,
      "y": 7,
      "z": -1,
      "name": "Plant_Crop_Mushroom_Block_Red"
    },
    {
      "x": -1,
      "y": 8,
      "z": -1,
      "name": "Plant_Crop_Mushroom_Block_Red"
    },
    {
      "x": -1,
      "y": 7,
      "z": 0,
      "name": "Plant_Crop_Mushroom_Block_Red"
    },
    {
      "x": -1,
      "y": 7,
      "z": 1,
      "name": "Plant_Crop_Mushroom_Block_Red"
    },
    {
      "x": -1,
      "y": 7,
      "z": 2,
      "name": "Plant_Crop_Mushroom_Block_Red"
    },
    {
      "x": -1,
      "y": 6,
      "z": 3,
      "name": "Plant_Crop_Mushroom_Block_Red"
    },
    {
      "x": -1,
      "y": 6,
      "z": 4,
      "name": "Plant_Crop_Mushroom_Block_Red"
    },
    {
      "x": 0,
      "y": 6,
      "z": -4,
      "name": "Plant_Crop_Mushroom_Block_Red"
    },
    {
      "x": 0,
      "y": 7,
      "z": -3,
      "name": "Plant_Crop_Mushroom_Block_Red"
    },
    {
      "x": 0,
      "y": -1,
      "z": -2,
      "name": "Plant_Crop_Mushroom_Block_White_Trunk"
    },
    {
      "x": 0,
      "y": 0,
      "z": -2,
      "name": "Plant_Crop_Mushroom_Block_White_Trunk"
    },
    {
      "x": 0,
      "y": 1,
      "z": -2,
      "name": "Plant_Crop_Mushroom_Block_White_Trunk"
    },
    {
      "x": 0,
      "y": 7,
      "z": -2,
      "name": "Plant_Crop_Mushroom_Block_Red"
    },
    {
      "x": 0,
      "y": 8,
      "z": -2,
      "name": "Plant_Crop_Mushroom_Block_Red"
    },
    {
      "x": 0,
      "y": -2,
      "z": -1,
      "name": "Plant_Crop_Mushroom_Block_White_Trunk"
    },
    {
      "x": 0,
      "y": -1,
      "z": -1,
      "name": "Plant_Crop_Mushroom_Block_White_Trunk"
    },
    {
      "x": 0,
      "y": 0,
      "z": -1,
      "name": "Plant_Crop_Mushroom_Block_White_Trunk"
    },
    {
      "x": 0,
      "y": 1,
      "z": -1,
      "name": "Plant_Crop_Mushroom_Block_White_Trunk"
    },
    {
      "x": 0,
      "y": 2,
      "z": -1,
      "name": "Plant_Crop_Mushroom_Block_White_Trunk"
    },
    {
      "x": 0,
      "y": 3,
      "z": -1,
      "name": "Plant_Crop_Mushroom_Block_White_Trunk"
    },
    {
      "x": 0,
      "y": 4,
      "z": -1,
      "name": "Plant_Crop_Mushroom_Block_White_Trunk"
    },
    {
      "x": 0,
      "y": 5,
      "z": -1,
      "name": "Plant_Crop_Mushroom_Block_White_Trunk"
    },
    {
      "x": 0,
      "y": 6,
      "z": -1,
      "name": "Plant_Crop_Mushroom_Block_White_Trunk"
    },
    {
      "x": 0,
      "y": 7,
      "z": -1,
      "name": "Plant_Crop_Mushroom_Block_White_Trunk"
    },
    {
      "x": 0,
      "y": 8,
      "z": -1,
      "name": "Plant_Crop_Mushroom_Block_Red"
    },
    {
      "x": 0,
      "y": -1,
      "z": 0,
      "name": "Plant_Crop_Mushroom_Block_White_Trunk"
    },
    {
      "x": 0,
      "y": 0,
      "z": 0,
      "name": "Plant_Crop_Mushroom_Block_White_Trunk"
    },
    {
      "x": 0,
      "y": 1,
      "z": 0,
      "name": "Plant_Crop_Mushroom_Block_White_Trunk"
    },
    {
      "x": 0,
      "y": 2,
      "z": 0,
      "name": "Plant_Crop_Mushroom_Block_White_Trunk"
    },
    {
      "x": 0,
      "y": 3,
      "z": 0,
      "name": "Plant_Crop_Mushroom_Block_White_Trunk"
    },
    {
      "x": 0,
      "y": 7,
      "z": 0,
      "name": "Plant_Crop_Mushroom_Block_Red"
    },
    {
      "x": 0,
      "y": 8,
      "z": 0,
      "name": "Plant_Crop_Mushroom_Block_Red"
    },
    {
      "x": 0,
      "y": 7,
      "z": 1,
      "name": "Plant_Crop_Mushroom_Block_Red"
    },
    {
      "x": 0,
      "y": 8,
      "z": 1,
      "name": "Plant_Crop_Mushroom_Block_Red"
    },
    {
      "x": 0,
      "y": 7,
      "z": 2,
      "name": "Plant_Crop_Mushroom_Block_Red"
    },
    {
      "x": 0,
      "y": 7,
      "z": 3,
      "name": "Plant_Crop_Mushroom_Block_Red"
    },
    {
      "x": 0,
      "y": 6,
      "z": 4,
      "name": "Plant_Crop_Mushroom_Block_Red"
    },
    {
      "x": 1,
      "y": 6,
      "z": -4,
      "name": "Plant_Crop_Mushroom_Block_Red"
    },
    {
      "x": 1,
      "y": 7,
      "z": -3,
      "name": "Plant_Crop_Mushroom_Block_Red"
    },
    {
      "x": 1,
      "y": 7,
      "z": -2,
      "name": "Plant_Crop_Mushroom_Block_Red"
    },
    {
      "x": 1,
      "y": 8,
      "z": -2,
      "name": "Plant_Crop_Mushroom_Block_Red"
    },
    {
      "x": 1,
      "y": -1,
      "z": -1,
      "name": "Plant_Crop_Mushroom_Block_White_Trunk"
    },
    {
      "x": 1,
      "y": 0,
      "z": -1,
      "name": "Plant_Crop_Mushroom_Block_White_Trunk"
    },
    {
      "x": 1,
      "y": 1,
      "z": -1,
      "name": "Plant_Crop_Mushroom_Block_White_Trunk"
    },
    {
      "x": 1,
      "y": 2,
      "z": -1,
      "name": "Plant_Crop_Mushroom_Block_White_Trunk"
    },
    {
      "x": 1,
      "y": 6,
      "z": -1,
      "name": "Plant_Crop_Mushroom_Block_White_Trunk"
    },
    {
      "x": 1,
      "y": 7,
      "z": -1,
      "name": "Plant_Crop_Mushroom_Block_White_Trunk"
    },
    {
      "x": 1,
      "y": 8,
      "z": -1,
      "name": "Plant_Crop_Mushroom_Block_Red"
    },
    {
      "x": 1,
      "y": 7,
      "z": 0,
      "name": "Plant_Crop_Mushroom_Block_Red"
    },
    {
      "x": 1,
      "y": 8,
      "z": 0,
      "name": "Plant_Crop_Mushroom_Block_Red"
    },
    {
      "x": 1,
      "y": 7,
      "z": 1,
      "name": "Plant_Crop_Mushroom_Block_Red"
    },
    {
      "x": 1,
      "y": 8,
      "z": 1,
      "name": "Plant_Crop_Mushroom_Block_Red"
    },
    {
      "x": 1,
      "y": 7,
      "z": 2,
      "name": "Plant_Crop_Mushroom_Block_Red"
    },
    {
      "x": 1,
      "y": 7,
      "z": 3,
      "name": "Plant_Crop_Mushroom_Block_Red"
    },
    {
      "x": 1,
      "y": 6,
      "z": 4,
      "name": "Plant_Crop_Mushroom_Block_Red"
    },
    {
      "x": 2,
      "y": 6,
      "z": -4,
      "name": "Plant_Crop_Mushroom_Block_Red"
    },
    {
      "x": 2,
      "y": 6,
      "z": -3,
      "name": "Plant_Crop_Mushroom_Block_Red"
    },
    {
      "x": 2,
      "y": 7,
      "z": -2,
      "name": "Plant_Crop_Mushroom_Block_Red"
    },
    {
      "x": 2,
      "y": 7,
      "z": -1,
      "name": "Plant_Crop_Mushroom_Block_Red"
    },
    {
      "x": 2,
      "y": 8,
      "z": -1,
      "name": "Plant_Crop_Mushroom_Block_Red"
    },
    {
      "x": 2,
      "y": 7,
      "z": 0,
      "name": "Plant_Crop_Mushroom_Block_Red"
    },
    {
      "x": 2,
      "y": 8,
      "z": 0,
      "name": "Plant_Crop_Mushroom_Block_Red"
    },
    {
      "x": 2,
      "y": 7,
      "z": 1,
      "name": "Plant_Crop_Mushroom_Block_Red"
    },
    {
      "x": 2,
      "y": 8,
      "z": 1,
      "name": "Plant_Crop_Mushroom_Block_Red"
    },
    {
      "x": 2,
      "y": 7,
      "z": 2,
      "name": "Plant_Crop_Mushroom_Block_Red"
    },
    {
      "x": 2,
      "y": 6,
      "z": 3,
      "name": "Plant_Crop_Mushroom_Block_Red"
    },
    {
      "x": 2,
      "y": 6,
      "z": 4,
      "name": "Plant_Crop_Mushroom_Block_Red"
    },
    {
      "x": 3,
      "y": 6,
      "z": -3,
      "name": "Plant_Crop_Mushroom_Block_Red"
    },
    {
      "x": 3,
      "y": 6,
      "z": -2,
      "name": "Plant_Crop_Mushroom_Block_Red"
    },
    {
      "x": 3,
      "y": 7,
      "z": -2,
      "name": "Plant_Crop_Mushroom_Block_Red"
    },
    {
      "x": 3,
      "y": 7,
      "z": -1,
      "name": "Plant_Crop_Mushroom_Block_Red"
    },
    {
      "x": 3,
      "y": 7,
      "z": 0,
      "name": "Plant_Crop_Mushroom_Block_Red"
    },
    {
      "x": 3,
      "y": 7,
      "z": 1,
      "name": "Plant_Crop_Mushroom_Block_Red"
    },
    {
      "x": 3,
      "y": 7,
      "z": 2,
      "name": "Plant_Crop_Mushroom_Block_Red"
    },
    {
      "x": 3,
      "y": 6,
      "z": 3,
      "name": "Plant_Crop_Mushroom_Block_Red"
    },
    {
      "x": 4,
      "y": 6,
      "z": -2,
      "name": "Plant_Crop_Mushroom_Block_Red"
    },
    {
      "x": 4,
      "y": 6,
      "z": -1,
      "name": "Plant_Crop_Mushroom_Block_Red"
    },
    {
      "x": 4,
      "y": 6,
      "z": 0,
      "name": "Plant_Crop_Mushroom_Block_Red"
    },
    {
      "x": 4,
      "y": 7,
      "z": 0,
      "name": "Plant_Crop_Mushroom_Block_Red"
    },
    {
      "x": 4,
      "y": 6,
      "z": 1,
      "name": "Plant_Crop_Mushroom_Block_Red"
    },
    {
      "x": 4,
      "y": 7,
      "z": 1,
      "name": "Plant_Crop_Mushroom_Block_Red"
    },
    {
      "x": 4,
      "y": 6,
      "z": 2,
      "name": "Plant_Crop_Mushroom_Block_Red"
    },
    {
      "x": 4,
      "y": 6,
      "z": 3,
      "name": "Plant_Crop_Mushroom_Block_Red"
    }
  ]
}