{
  "version": 8,
  "blockIdVersion": 11,
  "anchorX": 0,
  "anchorY": 0,
  "anchorZ": 0,
  "blocks": [
    {
      "x": -2,
      "y": 3,
      "z": -1,
      "name": "Plant_Crop_Mushroom_Block_Yellow_Spotted_Half",
      "rotation": 7
    },
    {
      "x": -2,
      "y": 3,
      "z": 0,
      "name": "Plant_Crop_Mushroom_Block_Yellow_Spotted"
    },
    {
      "x": -2,
      "y": 4,
      "z": 0,
      "name": "Plant_Crop_Mushroom_Block_Yellow_Spotted_Half",
      "rotation": 7
    },
    {
      "x": -2,
      "y": 3,
      "z": 1,
      "name": "Plant_Crop_Mushroom_Block_Yellow_Spotted"
    },
    {
      "x": -2,
      "y": 4,
      "z": 1,
      "name": "Plant_Crop_Mushroom_Block_Yellow_Spotted_Half",
      "rotation": 7
    },
    {
      "x": -2,
      "y": 3,
      "z": 2,
      "name": "Plant_Crop_Mushroom_Block_Yellow_Spotted_Half",
      "rotation": 7
    },
    {
      "x": -1,
      "y": 3,
      "z": -2,
      "name": "Plant_Crop_Mushroom_Block_Yellow_Spotted_Half",
      "rotation": 6
    },
    {
      "x": -1,
      "y": 3,
      "z": -1,
      "name": "Plant_Crop_Mushroom_Block_Yellow_Spotted"
    },
    {
      "x": -1,
      "y": 4,
      "z": -1,
      "name": "Plant_Crop_Mushroom_Block_Yellow_Spotted"
    },
    {
      "x": -1,
      "y": 5,
      "z": -1,
      "name": "Plant_Crop_Mushroom_Yellow_Spotted_Stairs",
      "rotation": 2
    },
    {
      "x": -1,
      "y": 3,
      "z": 0,
      "name": "Plant_Crop_Mushroom_Block_Red_Mycelium"
    },
    {
      "x": -1,
      "y": 4,
      "z": 0,
      "name": "Plant_Crop_Mushroom_Block_Yellow_Spotted"
    },
    {
      "x": -1,
      "y": 5,
      "z": 0,
      "name": "Plant_Crop_Mushroom_Block_Yellow_Spotted"
    },
    {
      "x": -1,
      "y": 6,
      "z": 0,
      "name": "Plant_Crop_Mushroom_Block_Yellow_Spotted_Half",
      "rotation": 7
    },
    {
      "x": -1,
      "y": 3,
      "z": 1,
      "name": "Plant_Crop_Mushroom_Block_Red_Mycelium"
    },
    {
      "x": -1,
      "y": 4,
      "z": 1,
      "name": "Plant_Crop_Mushroom_Block_Yellow_Spotted"
    },
    {
      "x": -1,
      "y": 5,
      "z": 1,
      "name": "Plant_Crop_Mushroom_Block_Yellow_Spotted"
    },
    {
      "x": -1,
      "y": 6,
      "z": 1,
      "name": "Plant_Crop_Mushroom_Block_Yellow_Spotted_Half",
      "rotation": 7
    },
    {
      "x": -1,
      "y": 3,
      "z": 2,
      "name": "Plant_Crop_Mushroom_Block_Yellow_Spotted"
    },
    {
      "x": -1,
      "y": 4,
      "z": 2,
      "name": "Plant_Crop_Mushroom_Block_Yellow_Spotted"
    },
    {
      "x": -1,
      "y": 5,
      "z": 2,
      "name": "Plant_Crop_Mushroom_Yellow_Spotted_Stairs"
    },
    {
      "x": -1,
      "y": 3,
      "z": 3,
      "name": "Plant_Crop_Mushroom_Block_Yellow_Spotted_Half",
      "rotation": 4
    },
    {
      "x": 0,
      "y": 3,
      "z": -2,
      "name": "Plant_Crop_Mushroom_Block_Yellow_Spotted"
    },
    {
      "x": 0,
      "y": 4,
      "z": -2,
      "name": "Plant_Crop_Mushroom_Block_Yellow_Spotted_Half",
      "rotation": 6
    },
    {
      "x": 0,
      "y": 3,
      "z": -1,
      "name": "Plant_Crop_Mushroom_Block_Red_Mycelium"
    },
    {
      "x": 0,
      "y": 4,
      "z": -1,
      "name": "Plant_Crop_Mushroom_Block_Yellow_Spotted"
    },
    {
      "x": 0,
      "y": 5,
      "z": -1,
      "name": "Plant_Crop_Mushroom_Block_Yellow_Spotted"
    },
    {
      "x": 0,
      "y": 6,
      "z": -1,
      "name": "Plant_Crop_Mushroom_Block_Yellow_Spotted_Half",
      "rotation": 6
    },
    {
      "x": 0,
      "y": -2,
      "z": 0,
      "name": "Plant_Crop_Mushroom_Block_Yellow_Trunk"
    },
    {
      "x": 0,
      "y": -1,
      "z": 0,
      "name": "Plant_Crop_Mushroom_Block_Yellow_Trunk"
    },
    {
      "x": 0,
      "y": 0,
      "z": 0,
      "name": "Plant_Crop_Mushroom_Block_Yellow_Trunk"
    },
    {
      "x": 0,
      "y": 1,
      "z": 0,
      "name": "Plant_Crop_Mushroom_Block_Yellow_Trunk"
    },
    {
      "x": 0,
      "y": 2,
      "z": 0,
      "name": "Plant_Crop_Mushroom_Block_Yellow_Trunk"
    },
    {
      "x": 0,
      "y": 3,
      "z": 0,
      "name": "Plant_Crop_Mushroom_Block_Yellow_Trunk"
    },
    {
      "x": 0,
      "y": 4,
      "z": 0,
      "name": "Plant_Crop_Mushroom_Block_Yellow_Spotted"
    },
    {
      "x": 0,
      "y": 5,
      "z": 0,
      "name": "Plant_Crop_Mushroom_Block_Yellow_Spotted"
    },
    {
      "x": 0,
      "y": 6,
      "z": 0,
      "name": "Plant_Crop_Mushroom_Block_Yellow_Spotted_Glow"
    },
    {
      "x": 0,
      "y": 7,
      "z": 0,
      "name": "*Plant_Crop_Mushroom_Yellow_Spotted_Stairs_State_Definitions_Corner_Right",
      "rotation": 3
    },
    {
      "x": 0,
      "y": -1,
      "z": 1,
      "name": "Plant_Crop_Mushroom_Block_Yellow_Trunk"
    },
    {
      "x": 0,
      "y": 0,
      "z": 1,
      "name": "Plant_Crop_Mushroom_Block_Yellow_Trunk"
    },
    {
      "x": 0,
      "y": 1,
      "z": 1,
      "name": "Plant_Crop_Mushroom_Block_Yellow_Trunk"
    },
    {
      "x": 0,
      "y": 2,
      "z": 1,
      "name": "Plant_Crop_Mushroom_Block_Yellow_Trunk"
    },
    {
      "x": 0,
      "y": 3,
      "z": 1,
      "name": "Plant_Crop_Mushroom_Block_Yellow_Trunk"
    },
    {
      "x": 0,
      "y": 4,
      "z": 1,
      "name": "Plant_Crop_Mushroom_Block_Yellow_Spotted"
    },
    {
      "x": 0,
      "y": 5,
      "z": 1,
      "name": "Plant_Crop_Mushroom_Block_Yellow_Spotted"
    },
    {
      "x": 0,
      "y": 6,
      "z": 1,
      "name": "Plant_Crop_Mushroom_Block_Yellow_Spotted"
    },
    {
      "x": 0,
      "y": 7,
      "z": 1,
      "name": "*Plant_Crop_Mushroom_Yellow_Spotted_Stairs_State_Definitions_Corner_Right"
    },
    {
      "x": 0,
      "y": 3,
      "z": 2,
      "name": "Plant_Crop_Mushroom_Block_Red_Mycelium"
    },
    {
      "x": 0,
      "y": 4,
      "z": 2,
      "name": "Plant_Crop_Mushroom_Block_Yellow_Spotted"
    },
    {
      "x": 0,
      "y": 5,
      "z": 2,
      "name": "Plant_Crop_Mushroom_Block_Yellow_Spotted"
    },
    {
      "x": 0,
      "y": 6,
      "z": 2,
      "name": "Plant_Crop_Mushroom_Block_Yellow_Spotted_Half",
      "rotation": 4
    },
    {
      "x": 0,
      "y": 3,
      "z": 3,
      "name": "Plant_Crop_Mushroom_Block_Yellow_Spotted"
    },
    {
      "x": 0,
      "y": 4,
      "z": 3,
      "name": "Plant_Crop_Mushroom_Block_Yellow_Spotted_Half",
      "rotation": 4
    },
    {
      "x": 1,
      "y": 3,
      "z": -2,
      "name": "Plant_Crop_Mushroom_Block_Yellow_Spotted"
    },
    {
      "x": 1,
      "y": 4,
      "z": -2,
      "name": "Plant_Crop_Mushroom_Block_Yellow_Spotted_Half",
      "rotation": 6
    },
    {
      "x": 1,
      "y": 3,
      "z": -1,
      "name": "Plant_Crop_Mushroom_Block_Red_Mycelium"
    },
    {
      "x": 1,
      "y": 4,
      "z": -1,
      "name": "Plant_Crop_Mushroom_Block_Yellow_Spotted"
    },
    {
      "x": 1,
      "y": 5,
      "z": -1,
      "name": "Plant_Crop_Mushroom_Block_Yellow_Spotted"
    },
    {
      "x": 1,
      "y": 6,
      "z": -1,
      "name": "Plant_Crop_Mushroom_Block_Yellow_Spotted_Half",
      "rotation": 6
    },
    {
      "x": 1,
      "y": -1,
      "z": 0,
      "name": "Plant_Crop_Mushroom_Block_Yellow_Trunk"
    },
    {
      "x": 1,
      "y": 0,
      "z": 0,
      "name": "Plant_Crop_Mushroom_Block_Yellow_Trunk"
    },
    {
      "x": 1,
      "y": 1,
      "z": 0,
      "name": "Plant_Crop_Mushroom_Block_Yellow_Trunk"
    },
    {
      "x": 1,
      "y": 2,
      "z": 0,
      "name": "Plant_Crop_Mushroom_Block_Yellow_Trunk"
    },
    {
      "x": 1,
      "y": 3,
      "z": 0,
      "name": "Plant_Crop_Mushroom_Block_Yellow_Trunk"
    },
    {
      "x": 1,
      "y": 4,
      "z": 0,
      "name": "Plant_Crop_Mushroom_Block_Yellow_Spotted"
    },
    {
      "x": 1,
      "y": 5,
      "z": 0,
      "name": "Plant_Crop_Mushroom_Block_Yellow_Spotted"
    },
    {
      "x": 1,
      "y": 6,
      "z": 0,
      "name": "Plant_Crop_Mushroom_Block_Yellow_Spotted"
    },
    {
      "x": 1,
      "y": 7,
      "z": 0,
      "name": "Plant_Crop_Mushroom_Yellow_Spotted_Stairs",
      "rotation": 2
    },
    {
      "x": 1,
      "y": -1,
      "z": 1,
      "name": "Plant_Crop_Mushroom_Block_Yellow_Trunk"
    },
    {
      "x": 1,
      "y": 0,
      "z": 1,
      "name": "Plant_Crop_Mushroom_Block_Yellow_Trunk"
    },
    {
      "x": 1,
      "y": 1,
      "z": 1,
      "name": "Plant_Crop_Mushroom_Block_Yellow_Trunk"
    },
    {
      "x": 1,
      "y": 2,
      "z": 1,
      "name": "Plant_Crop_Mushroom_Block_Yellow_Trunk"
    },
    {
      "x": 1,
      "y": 3,
      "z": 1,
      "name": "Plant_Crop_Mushroom_Block_Yellow_Trunk"
    },
    {
      "x": 1,
      "y": 4,
      "z": 1,
      "name": "Plant_Crop_Mushroom_Block_Yellow_Spotted"
    },
    {
      "x": 1,
      "y": 5,
      "z": 1,
      "name": "Plant_Crop_Mushroom_Block_Yellow_Spotted"
    },
    {
      "x": 1,
      "y": 6,
      "z": 1,
      "name": "Plant_Crop_Mushroom_Block_Yellow_Spotted_Glow"
    },
    {
      "x": 1,
      "y": 7,
      "z": 1,
      "name": "Plant_Crop_Mushroom_Yellow_Spotted_Stairs"
    },
    {
      "x": 1,
      "y": 3,
      "z": 2,
      "name": "Plant_Crop_Mushroom_Block_Red_Mycelium"
    },
    {
      "x": 1,
      "y": 4,
      "z": 2,
      "name": "Plant_Crop_Mushroom_Block_Yellow_Spotted"
    },
    {
      "x": 1,
      "y": 5,
      "z": 2,
      "name": "Plant_Crop_Mushroom_Block_Yellow_Spotted"
    },
    {
      "x": 1,
      "y": 6,
      "z": 2,
      "name": "Plant_Crop_Mushroom_Block_Yellow_Spotted_Half",
      "rotation": 4
    },
    {
      "x": 1,
      "y": 3,
      "z": 3,
      "name": "Plant_Crop_Mushroom_Block_Yellow_Spotted"
    },
    {
      "x": 1,
      "y": 4,
      "z": 3,
      "name": "Plant_Crop_Mushroom_Block_Yellow_Spotted_Half",
      "rotation": 4
    },
    {
      "x": 2,
      "y": 3,
      "z": -2,
      "name": "Plant_Crop_Mushroom_Block_Yellow_Spotted_Half",
      "rotation": 6
    },
    {
      "x": 2,
      "y": 3,
      "z": -1,
      "name": "Plant_Crop_Mushroom_Block_Yellow_Spotted"
    },
    {
      "x": 2,
      "y": 4,
      "z": -1,
      "name": "Plant_Crop_Mushroom_Block_Yellow_Spotted"
    },
    {
      "x": 2,
      "y": 5,
      "z": -1,
      "name": "Plant_Crop_Mushroom_Yellow_Spotted_Stairs",
      "rotation": 2
    },
    {
      "x": 2,
      "y": 3,
      "z": 0,
      "name": "Plant_Crop_Mushroom_Block_Red_Mycelium"
    },
    {
      "x": 2,
      "y": 4,
      "z": 0,
      "name": "Plant_Crop_Mushroom_Block_Yellow_Spotted"
    },
    {
      "x": 2,
      "y": 5,
      "z": 0,
      "name": "Plant_Crop_Mushroom_Block_Yellow_Spotted"
    },
    {
      "x": 2,
      "y": 6,
      "z": 0,
      "name": "Plant_Crop_Mushroom_Block_Yellow_Spotted_Half",
      "rotation": 5
    },
    {
      "x": 2,
      "y": 3,
      "z": 1,
      "name": "Plant_Crop_Mushroom_Block_Yellow_Spotted_Half",
      "rotation": 8
    },
    {
      "x": 2,
      "y": 4,
      "z": 1,
      "name": "Plant_Crop_Mushroom_Block_Yellow_Spotted"
    },
    {
      "x": 2,
      "y": 5,
      "z": 1,
      "name": "Plant_Crop_Mushroom_Block_Yellow_Spotted"
    },
    {
      "x": 2,
      "y": 6,
      "z": 1,
      "name": "Plant_Crop_Mushroom_Block_Yellow_Spotted_Half",
      "rotation": 5
    },
    {
      "x": 2,
      "y": 3,
      "z": 2,
      "name": "Plant_Crop_Mushroom_Block_Yellow_Spotted"
    },
    {
      "x": 2,
      "y": 4,
      "z": 2,
      "name": "Plant_Crop_Mushroom_Block_Yellow_Spotted"
    },
    {
      "x": 2,
      "y": 5,
      "z": 2,
      "name": "Plant_Crop_Mushroom_Yellow_Spotted_Stairs"
    },
    {
      "x": 2,
      "y": 3,
      "z": 3,
      "name": "Plant_Crop_Mushroom_Block_Yellow_Spotted_Half",
      "rotation": 4
    },
    {
      "x": 3,
      "y": 3,
      "z": -1,
      "name": "Plant_Crop_Mushroom_Block_Yellow_Spotted_Half",
      "rotation": 5
    },
    {
      "x": 3,
      "y": 3,
      "z": 0,
      "name": "Plant_Crop_Mushroom_Block_Yellow_Spotted"
    },
    {
      "x": 3,
      "y": 4,
      "z": 0,
      "name": "Plant_Crop_Mushroom_Block_Yellow_Spotted_Half",
      "rotation": 5
    },
    {
      "x": 3,
      "y": 3,
      "z": 1,
      "name": "Plant_Crop_Mushroom_Block_Yellow_Spotted"
    },
    {
      "x": 3,
      "y": 4,
      "z": 1,
      "name": "Plant_Crop_Mushroom_Block_Yellow_Spotted_Half",
      "rotation": 5
    },
    {
      "x": 3,
      "y": 3,
      "z": 2,
      "name": "Plant_Crop_Mushroom_Block_Yellow_Spotted_Half",
      "rotation": 5
    }
  ]
}